{"type":"received","order_id":"15dd4a58-6007-4a35-95b8-6c28f68e54d2","order_type":"limit","size":"0.90000000","price":"794.61000000","side":"sell","client_oid":"e18ceeb3-fb94-423e-997e-783b64c39972","product_id":"BCH-USD","sequence":4839270665,"time":"2018-07-27T01:32:38.139000Z"}
{"type":"open","side":"sell","price":"794.61000000","order_id":"15dd4a58-6007-4a35-95b8-6c28f68e54d2","remaining_size":"0.90000000","product_id":"BCH-USD","sequence":4839270666,"time":"2018-07-27T01:32:38.139000Z"}
{"type":"received","order_id":"3c08e4c8-5bec-4cef-bf65-e2e86f5d34e5","order_type":"limit","size":"0.90000000","price":"794.61000000","side":"sell","client_oid":"1d6f68ed-17c3-42d0-9758-a6a77ef1b38e","product_id":"BCH-USD","sequence":4839270667,"time":"2018-07-27T01:32:38.141000Z"}
{"type":"open","side":"sell","price":"794.61000000","order_id":"3c08e4c8-5bec-4cef-bf65-e2e86f5d34e5","remaining_size":"0.90000000","product_id":"BCH-USD","sequence":4839270668,"time":"2018-07-27T01:32:38.141000Z"}
{"type":"received","order_id":"23657cb0-20f5-416d-9809-08e5e07af607","order_type":"limit","size":"1.90000000","price":"795.19000000","side":"sell","client_oid":"678bb746-5785-49b4-9dcb-abead30c1de6","product_id":"BCH-USD","sequence":4839270669,"time":"2018-07-27T01:32:38.143000Z"}
{"type":"received","order_id":"77e63dcb-9ee1-440c-93e4-0245cef7338e","order_type":"limit","size":"0.01000000","price":"471.97000000","side":"sell","client_oid":"eff6bbf0-913c-11e8-94af-bf43831653af","product_id":"ETH-USD","sequence":4469354695,"time":"2018-07-27T01:32:38.144000Z"}
{"type":"open","side":"sell","price":"795.19000000","order_id":"23657cb0-20f5-416d-9809-08e5e07af607","remaining_size":"1.90000000","product_id":"BCH-USD","sequence":4839270670,"time":"2018-07-27T01:32:38.143000Z"}
{"type":"open","side":"sell","price":"471.97000000","order_id":"77e63dcb-9ee1-440c-93e4-0245cef7338e","remaining_size":"0.01000000","product_id":"ETH-USD","sequence":4469354696,"time":"2018-07-27T01:32:38.144000Z"}
{"type":"done","side":"sell","order_id":"15dd4a58-6007-4a35-95b8-6c28f68e54d2","reason":"canceled","product_id":"BCH-USD","price":"794.61000000","remaining_size":"0.90000000","sequence":4839270671,"time":"2018-07-27T01:32:38.145000Z"}
{"type":"done","side":"sell","order_id":"3c08e4c8-5bec-4cef-bf65-e2e86f5d34e5","reason":"canceled","product_id":"BCH-USD","price":"794.61000000","remaining_size":"0.90000000","sequence":4839270672,"time":"2018-07-27T01:32:38.146000Z"}
{"type":"received","order_id":"9d278a33-0906-427c-b621-406fe9e98858","order_type":"limit","size":"4.50000000","price":"794.64000000","side":"sell","client_oid":"e65dc507-563a-4730-92c2-8d1ff3a9ec5c","product_id":"BCH-USD","sequence":4839270673,"time":"2018-07-27T01:32:38.147000Z"}
{"type":"open","side":"sell","price":"794.64000000","order_id":"9d278a33-0906-427c-b621-406fe9e98858","remaining_size":"4.50000000","product_id":"BCH-USD","sequence":4839270674,"time":"2018-07-27T01:32:38.147000Z"}
{"type":"received","order_id":"6b1f762b-f32f-49e6-b4a0-705527f4e0e3","order_type":"limit","size":"4.50000000","price":"795.29000000","side":"sell","client_oid":"f5577174-72a6-4549-8d18-ab8f47d9a037","product_id":"BCH-USD","sequence":4839270675,"time":"2018-07-27T01:32:38.148000Z"}
{"type":"open","side":"sell","price":"795.29000000","order_id":"6b1f762b-f32f-49e6-b4a0-705527f4e0e3","remaining_size":"4.50000000","product_id":"BCH-USD","sequence":4839270676,"time":"2018-07-27T01:32:38.148000Z"}
{"type":"done","side":"sell","order_id":"9a785211-c6bd-489b-b150-3be3f1775a3f","reason":"canceled","product_id":"LTC-USD","price":"83.30000000","remaining_size":"7.44874862","sequence":2423271492,"time":"2018-07-27T01:32:38.152000Z"}
{"type":"received","order_id":"965ab4a3-326e-4877-bdda-48970e6abd61","order_type":"limit","size":"0.90000000","price":"794.62000000","side":"sell","client_oid":"1ee36b18-79b4-4e13-a993-21d79f4b4c5b","product_id":"BCH-USD","sequence":4839270677,"time":"2018-07-27T01:32:38.150000Z"}
{"type":"open","side":"sell","price":"794.62000000","order_id":"965ab4a3-326e-4877-bdda-48970e6abd61","remaining_size":"0.90000000","product_id":"BCH-USD","sequence":4839270678,"time":"2018-07-27T01:32:38.150000Z"}
{"type":"received","order_id":"ca5f3e8d-c2f8-461d-906a-689c9ad35bc7","order_type":"limit","size":"0.90000000","price":"794.64000000","side":"sell","client_oid":"29f949dd-7096-48a7-8535-e501f2a57a14","product_id":"BCH-USD","sequence":4839270679,"time":"2018-07-27T01:32:38.151000Z"}
{"type":"open","side":"sell","price":"794.64000000","order_id":"ca5f3e8d-c2f8-461d-906a-689c9ad35bc7","remaining_size":"0.90000000","product_id":"BCH-USD","sequence":4839270680,"time":"2018-07-27T01:32:38.151000Z"}
{"type":"done","side":"sell","order_id":"965ab4a3-326e-4877-bdda-48970e6abd61","reason":"canceled","product_id":"BCH-USD","price":"794.62000000","remaining_size":"0.90000000","sequence":4839270681,"time":"2018-07-27T01:32:38.156000Z"}
{"type":"received","order_id":"17e78648-bc63-468a-992c-4962be4e396a","order_type":"limit","size":"7.44874862","price":"83.34000000","side":"sell","client_oid":"26984082-506e-4d7f-8000-009b43f58fc4","product_id":"LTC-USD","sequence":2423271493,"time":"2018-07-27T01:32:38.160000Z"}
{"type":"open","side":"sell","price":"83.34000000","order_id":"17e78648-bc63-468a-992c-4962be4e396a","remaining_size":"7.44874862","product_id":"LTC-USD","sequence":2423271494,"time":"2018-07-27T01:32:38.160000Z"}
{"type":"done","side":"sell","order_id":"ca5f3e8d-c2f8-461d-906a-689c9ad35bc7","reason":"canceled","product_id":"BCH-USD","price":"794.64000000","remaining_size":"0.90000000","sequence":4839270682,"time":"2018-07-27T01:32:38.162000Z"}
{"type":"done","side":"sell","order_id":"9d278a33-0906-427c-b621-406fe9e98858","reason":"canceled","product_id":"BCH-USD","price":"794.64000000","remaining_size":"4.50000000","sequence":4839270683,"time":"2018-07-27T01:32:38.162000Z"}
{"type":"done","side":"buy","order_id":"3e5517c4-9771-4e7c-af8d-165120d97b89","reason":"canceled","product_id":"LTC-USD","price":"82.98000000","remaining_size":"20.00000000","sequence":2423271495,"time":"2018-07-27T01:32:38.169000Z"}
{"type":"received","order_id":"c1108069-d49f-4572-bd73-70cfc6cc224f","order_type":"limit","size":"0.90000000","price":"794.63000000","side":"sell","client_oid":"77a4aa22-a868-467a-96ff-30d397afc384","product_id":"BCH-USD","sequence":4839270684,"time":"2018-07-27T01:32:38.170000Z"}
{"type":"open","side":"sell","price":"794.63000000","order_id":"c1108069-d49f-4572-bd73-70cfc6cc224f","remaining_size":"0.90000000","product_id":"BCH-USD","sequence":4839270685,"time":"2018-07-27T01:32:38.170000Z"}
{"type":"received","order_id":"756dcf22-dabe-4257-a14b-e37beda0b79f","order_type":"limit","size":"0.90000000","price":"794.63000000","side":"sell","client_oid":"6ecc1c5b-ffcb-4da2-9ad3-79cadc2b169e","product_id":"BCH-USD","sequence":4839270686,"time":"2018-07-27T01:32:38.170000Z"}
{"type":"open","side":"sell","price":"794.63000000","order_id":"756dcf22-dabe-4257-a14b-e37beda0b79f","remaining_size":"0.90000000","product_id":"BCH-USD","sequence":4839270687,"time":"2018-07-27T01:32:38.170000Z"}
{"type":"done","side":"sell","order_id":"92599928-66a1-4ba2-89ea-e46ec09af6fa","reason":"canceled","product_id":"BCH-USD","price":"794.63000000","remaining_size":"1.90000000","sequence":4839270688,"time":"2018-07-27T01:32:38.172000Z"}
{"type":"done","side":"sell","order_id":"c1108069-d49f-4572-bd73-70cfc6cc224f","reason":"canceled","product_id":"BCH-USD","price":"794.63000000","remaining_size":"0.90000000","sequence":4839270689,"time":"2018-07-27T01:32:38.173000Z"}
{"type":"received","order_id":"dff8c7d5-9962-4633-9974-875520fe0f6c","order_type":"limit","size":"4.50000000","price":"794.63000000","side":"sell","client_oid":"202c7b06-43f5-4196-8204-14b663d4f298","product_id":"BCH-USD","sequence":4839270690,"time":"2018-07-27T01:32:38.176000Z"}
{"type":"open","side":"sell","price":"794.63000000","order_id":"dff8c7d5-9962-4633-9974-875520fe0f6c","remaining_size":"4.50000000","product_id":"BCH-USD","sequence":4839270691,"time":"2018-07-27T01:32:38.176000Z"}
{"type":"done","side":"sell","order_id":"23657cb0-20f5-416d-9809-08e5e07af607","reason":"canceled","product_id":"BCH-USD","price":"795.19000000","remaining_size":"1.90000000","sequence":4839270692,"time":"2018-07-27T01:32:38.176000Z"}
{"type":"done","side":"sell","order_id":"756dcf22-dabe-4257-a14b-e37beda0b79f","reason":"canceled","product_id":"BCH-USD","price":"794.63000000","remaining_size":"0.90000000","sequence":4839270693,"time":"2018-07-27T01:32:38.177000Z"}
{"type":"received","order_id":"f1d54367-17b1-4f0e-ac48-803d9f8a8deb","order_type":"limit","size":"20.00000000","price":"82.99000000","side":"buy","client_oid":"bc106ee0-c8ed-4206-94eb-6ffd4054b7b1","product_id":"LTC-USD","sequence":2423271496,"time":"2018-07-27T01:32:38.179000Z"}
{"type":"open","side":"buy","price":"82.99000000","order_id":"f1d54367-17b1-4f0e-ac48-803d9f8a8deb","remaining_size":"20.00000000","product_id":"LTC-USD","sequence":2423271497,"time":"2018-07-27T01:32:38.179000Z"}
{"type":"done","side":"sell","order_id":"dff8c7d5-9962-4633-9974-875520fe0f6c","reason":"canceled","product_id":"BCH-USD","price":"794.63000000","remaining_size":"4.50000000","sequence":4839270694,"time":"2018-07-27T01:32:38.181000Z"}
{"type":"done","side":"sell","order_id":"635a0681-9bb9-459d-82e8-b80eea2f1e45","reason":"canceled","product_id":"LTC-USD","price":"83.38000000","remaining_size":"7.44874862","sequence":2423271498,"time":"2018-07-27T01:32:38.184000Z"}
{"type":"received","order_id":"8b804499-a6ea-4e73-a154-8330d47a38f2","order_type":"limit","size":"0.90000000","price":"794.64000000","side":"sell","client_oid":"57775534-61d0-4b9d-b8d2-7d8ea9d0f4af","product_id":"BCH-USD","sequence":4839270695,"time":"2018-07-27T01:32:38.184000Z"}
{"type":"open","side":"sell","price":"794.64000000","order_id":"8b804499-a6ea-4e73-a154-8330d47a38f2","remaining_size":"0.90000000","product_id":"BCH-USD","sequence":4839270696,"time":"2018-07-27T01:32:38.184000Z"}
{"type":"received","order_id":"6c8d0aa7-acd7-4ec1-8b0f-b9a9edb76770","order_type":"limit","size":"1.90000000","price":"795.18000000","side":"sell","client_oid":"254c5736-4ba8-4cd9-a820-e63efb120b5f","product_id":"BCH-USD","sequence":4839270697,"time":"2018-07-27T01:32:38.187000Z"}
{"type":"open","side":"sell","price":"795.18000000","order_id":"6c8d0aa7-acd7-4ec1-8b0f-b9a9edb76770","remaining_size":"1.90000000","product_id":"BCH-USD","sequence":4839270698,"time":"2018-07-27T01:32:38.187000Z"}
{"type":"received","order_id":"2247e7d7-0d0a-4a23-98dc-210f4523f9a1","order_type":"limit","size":"1.90000000","price":"794.64000000","side":"sell","client_oid":"711ee617-7785-435c-8327-0e5017418ec8","product_id":"BCH-USD","sequence":4839270699,"time":"2018-07-27T01:32:38.187000Z"}
{"type":"open","side":"sell","price":"794.64000000","order_id":"2247e7d7-0d0a-4a23-98dc-210f4523f9a1","remaining_size":"1.90000000","product_id":"BCH-USD","sequence":4839270700,"time":"2018-07-27T01:32:38.187000Z"}
{"type":"done","side":"buy","order_id":"cb6780e3-0fcd-4d9c-ab6b-34be941f1791","reason":"canceled","product_id":"LTC-USD","price":"83.22000000","remaining_size":"20.00000000","sequence":2423271499,"time":"2018-07-27T01:32:38.192000Z"}
{"type":"received","order_id":"c59acd14-29a3-45cc-84cd-5b1e30af59c9","order_type":"limit","size":"37.00000000","price":"794.00000000","side":"sell","client_oid":"8bccb0fb-d63a-43fc-aa4b-8a72430273b9","product_id":"BCH-USD","sequence":4839270701,"time":"2018-07-27T01:32:38.190000Z"}
{"type":"open","side":"sell","price":"794.00000000","order_id":"c59acd14-29a3-45cc-84cd-5b1e30af59c9","remaining_size":"37.00000000","product_id":"BCH-USD","sequence":4839270702,"time":"2018-07-27T01:32:38.190000Z"}
{"type":"done","side":"sell","order_id":"6c8d0aa7-acd7-4ec1-8b0f-b9a9edb76770","reason":"canceled","product_id":"BCH-USD","price":"795.18000000","remaining_size":"1.90000000","sequence":4839270703,"time":"2018-07-27T01:32:38.191000Z"}
{"type":"done","side":"sell","order_id":"6b1f762b-f32f-49e6-b4a0-705527f4e0e3","reason":"canceled","product_id":"BCH-USD","price":"795.29000000","remaining_size":"4.50000000","sequence":4839270704,"time":"2018-07-27T01:32:38.191000Z"}
{"type":"done","side":"sell","order_id":"44bc937b-dd48-45a6-867e-d2d8a073384c","reason":"canceled","product_id":"ETH-USD","price":"464.50000000","remaining_size":"8.29703000","sequence":4469354697,"time":"2018-07-27T01:32:38.195000Z"}
{"type":"received","order_id":"a6248f9c-e32c-4f29-9266-699d854132dc","order_type":"limit","size":"7.44874862","price":"83.30000000","side":"sell","client_oid":"e3cd77ee-a0fb-4417-8000-002b9404158a","product_id":"LTC-USD","sequence":2423271500,"time":"2018-07-27T01:32:38.199000Z"}
{"type":"open","side":"sell","price":"83.30000000","order_id":"a6248f9c-e32c-4f29-9266-699d854132dc","remaining_size":"7.44874862","product_id":"LTC-USD","sequence":2423271501,"time":"2018-07-27T01:32:38.199000Z"}
{"type":"done","side":"sell","order_id":"53af97cb-4f4c-4887-9573-343f1d72b965","reason":"canceled","product_id":"BCH-USD","price":"796.04000000","remaining_size":"28.00000000","sequence":4839270705,"time":"2018-07-27T01:32:38.200000Z"}
{"type":"done","side":"buy","order_id":"4c3f93be-ef68-4bca-855d-fc41945aeb03","reason":"canceled","product_id":"BCH-USD","price":"792.37000000","remaining_size":"2.00000000","sequence":4839270706,"time":"2018-07-27T01:32:38.203000Z"}
{"type":"received","order_id":"8ec2bb93-612c-4ced-b453-b5ac1f570e77","order_type":"limit","size":"1.90000000","price":"795.28000000","side":"sell","client_oid":"a78599c1-f3e9-47d3-bee6-eb75f710fd61","product_id":"BCH-USD","sequence":4839270707,"time":"2018-07-27T01:32:38.204000Z"}
{"type":"open","side":"sell","price":"795.28000000","order_id":"8ec2bb93-612c-4ced-b453-b5ac1f570e77","remaining_size":"1.90000000","product_id":"BCH-USD","sequence":4839270708,"time":"2018-07-27T01:32:38.204000Z"}
{"type":"received","order_id":"a1830e98-eba3-4515-aeeb-9fdc6fe583fb","order_type":"limit","size":"0.90000000","price":"794.64000000","side":"sell","client_oid":"afe2e4b1-091e-4a18-80b8-976de751f4f7","product_id":"BCH-USD","sequence":4839270709,"time":"2018-07-27T01:32:38.205000Z"}
{"type":"open","side":"sell","price":"794.64000000","order_id":"a1830e98-eba3-4515-aeeb-9fdc6fe583fb","remaining_size":"0.90000000","product_id":"BCH-USD","sequence":4839270710,"time":"2018-07-27T01:32:38.205000Z"}
{"type":"done","side":"sell","order_id":"8ec2bb93-612c-4ced-b453-b5ac1f570e77","reason":"canceled","product_id":"BCH-USD","price":"795.28000000","remaining_size":"1.90000000","sequence":4839270711,"time":"2018-07-27T01:32:38.208000Z"}
{"type":"received","order_id":"a4b89133-e021-41bd-9384-e1fb60d5cafd","order_type":"limit","size":"4.50000000","price":"795.28000000","side":"sell","client_oid":"c7c106ea-2e79-4f8f-ab72-c84390198d2c","product_id":"BCH-USD","sequence":4839270712,"time":"2018-07-27T01:32:38.209000Z"}
{"type":"open","side":"sell","price":"795.28000000","order_id":"a4b89133-e021-41bd-9384-e1fb60d5cafd","remaining_size":"4.50000000","product_id":"BCH-USD","sequence":4839270713,"time":"2018-07-27T01:32:38.209000Z"}
{"type":"received","order_id":"91510744-8924-43f0-9585-aa74b417a531","order_type":"limit","size":"4.50000000","price":"794.64000000","side":"sell","client_oid":"f30ee37b-25fb-4ded-94cf-066cbe3531a2","product_id":"BCH-USD","sequence":4839270714,"time":"2018-07-27T01:32:38.211000Z"}
{"type":"open","side":"sell","price":"794.64000000","order_id":"91510744-8924-43f0-9585-aa74b417a531","remaining_size":"4.50000000","product_id":"BCH-USD","sequence":4839270715,"time":"2018-07-27T01:32:38.211000Z"}
{"type":"received","order_id":"8ef4c37f-505a-4c10-9dbd-5493450eeabf","order_type":"limit","size":"1.90000000","price":"795.29000000","side":"sell","client_oid":"22e46a95-9028-40c9-997e-e8e8edbaaf24","product_id":"BCH-USD","sequence":4839270716,"time":"2018-07-27T01:32:38.216000Z"}
{"type":"open","side":"sell","price":"795.29000000","order_id":"8ef4c37f-505a-4c10-9dbd-5493450eeabf","remaining_size":"1.90000000","product_id":"BCH-USD","sequence":4839270717,"time":"2018-07-27T01:32:38.216000Z"}
{"type":"done","side":"sell","order_id":"8b804499-a6ea-4e73-a154-8330d47a38f2","reason":"canceled","product_id":"BCH-USD","price":"794.64000000","remaining_size":"0.90000000","sequence":4839270718,"time":"2018-07-27T01:32:38.217000Z"}
{"type":"done","side":"buy","order_id":"f1d54367-17b1-4f0e-ac48-803d9f8a8deb","reason":"canceled","product_id":"LTC-USD","price":"82.99000000","remaining_size":"20.00000000","sequence":2423271502,"time":"2018-07-27T01:32:38.219000Z"}
{"type":"done","side":"sell","order_id":"a1830e98-eba3-4515-aeeb-9fdc6fe583fb","reason":"canceled","product_id":"BCH-USD","price":"794.64000000","remaining_size":"0.90000000","sequence":4839270719,"time":"2018-07-27T01:32:38.217000Z"}
{"type":"done","side":"sell","order_id":"8ef4c37f-505a-4c10-9dbd-5493450eeabf","reason":"canceled","product_id":"BCH-USD","price":"795.29000000","remaining_size":"1.90000000","sequence":4839270720,"time":"2018-07-27T01:32:38.221000Z"}
{"type":"done","side":"sell","order_id":"2247e7d7-0d0a-4a23-98dc-210f4523f9a1","reason":"canceled","product_id":"BCH-USD","price":"794.64000000","remaining_size":"1.90000000","sequence":4839270721,"time":"2018-07-27T01:32:38.222000Z"}
{"type":"done","side":"sell","order_id":"91510744-8924-43f0-9585-aa74b417a531","reason":"canceled","product_id":"BCH-USD","price":"794.64000000","remaining_size":"4.50000000","sequence":4839270722,"time":"2018-07-27T01:32:38.222000Z"}
{"type":"received","order_id":"75976596-13ea-4f0b-a57e-ba144088d394","order_type":"limit","size":"0.90000000","price":"794.63000000","side":"sell","client_oid":"24c0bccd-9e37-43d6-898e-f3e558ef9194","product_id":"BCH-USD","sequence":4839270723,"time":"2018-07-27T01:32:38.223000Z"}
{"type":"open","side":"sell","price":"794.63000000","order_id":"75976596-13ea-4f0b-a57e-ba144088d394","remaining_size":"0.90000000","product_id":"BCH-USD","sequence":4839270724,"time":"2018-07-27T01:32:38.223000Z"}
{"type":"received","order_id":"fe8b944e-8920-42da-9c8e-b8c633f215ee","order_type":"limit","size":"20.00000000","price":"82.98000000","side":"buy","client_oid":"dd3cf6fc-1800-415a-96e3-74bb8833a47c","product_id":"LTC-USD","sequence":2423271503,"time":"2018-07-27T01:32:38.226000Z"}
{"type":"open","side":"buy","price":"82.98000000","order_id":"fe8b944e-8920-42da-9c8e-b8c633f215ee","remaining_size":"20.00000000","product_id":"LTC-USD","sequence":2423271504,"time":"2018-07-27T01:32:38.226000Z"}
{"type":"received","order_id":"0f45f862-ed83-421f-9c47-d05cd379ca76","order_type":"limit","size":"1.90000000","price":"794.63000000","side":"sell","client_oid":"72728976-d7c5-428c-8bd9-eade559d97a0","product_id":"BCH-USD","sequence":4839270725,"time":"2018-07-27T01:32:38.226000Z"}
{"type":"open","side":"sell","price":"794.63000000","order_id":"0f45f862-ed83-421f-9c47-d05cd379ca76","remaining_size":"1.90000000","product_id":"BCH-USD","sequence":4839270726,"time":"2018-07-27T01:32:38.226000Z"}
{"type":"done","side":"sell","order_id":"17e78648-bc63-468a-992c-4962be4e396a","reason":"canceled","product_id":"LTC-USD","price":"83.34000000","remaining_size":"7.44874862","sequence":2423271505,"time":"2018-07-27T01:32:38.230000Z"}
{"type":"received","order_id":"6480964b-56a9-4e85-822c-b692ef3a5f5c","order_type":"limit","size":"1.90000000","price":"795.27000000","side":"sell","client_oid":"1b69d26e-c5b0-449d-9476-38239910a9e7","product_id":"BCH-USD","sequence":4839270727,"time":"2018-07-27T01:32:38.229000Z"}
{"type":"open","side":"sell","price":"795.27000000","order_id":"6480964b-56a9-4e85-822c-b692ef3a5f5c","remaining_size":"1.90000000","product_id":"BCH-USD","sequence":4839270728,"time":"2018-07-27T01:32:38.229000Z"}
{"type":"done","side":"sell","order_id":"75976596-13ea-4f0b-a57e-ba144088d394","reason":"canceled","product_id":"BCH-USD","price":"794.63000000","remaining_size":"0.90000000","sequence":4839270729,"time":"2018-07-27T01:32:38.231000Z"}
{"type":"received","order_id":"e24a4024-531d-4584-93a8-5b2c0f2d7c2b","order_type":"limit","size":"0.90000000","price":"794.63000000","side":"sell","client_oid":"e9690762-1d58-4657-8241-5c899f23aeac","product_id":"BCH-USD","sequence":4839270730,"time":"2018-07-27T01:32:38.233000Z"}
{"type":"open","side":"sell","price":"794.63000000","order_id":"e24a4024-531d-4584-93a8-5b2c0f2d7c2b","remaining_size":"0.90000000","product_id":"BCH-USD","sequence":4839270731,"time":"2018-07-27T01:32:38.233000Z"}
{"type":"done","side":"sell","order_id":"6480964b-56a9-4e85-822c-b692ef3a5f5c","reason":"canceled","product_id":"BCH-USD","price":"795.27000000","remaining_size":"1.90000000","sequence":4839270732,"time":"2018-07-27T01:32:38.237000Z"}
{"type":"received","order_id":"08269105-6257-4a93-8d48-19f2e25a51ae","order_type":"limit","size":"4.50000000","price":"794.63000000","side":"sell","client_oid":"4c4e0a7b-1339-4b08-a241-27397ef67383","product_id":"BCH-USD","sequence":4839270733,"time":"2018-07-27T01:32:38.237000Z"}
{"type":"open","side":"sell","price":"794.63000000","order_id":"08269105-6257-4a93-8d48-19f2e25a51ae","remaining_size":"4.50000000","product_id":"BCH-USD","sequence":4839270734,"time":"2018-07-27T01:32:38.237000Z"}
{"type":"done","side":"sell","order_id":"e24a4024-531d-4584-93a8-5b2c0f2d7c2b","reason":"canceled","product_id":"BCH-USD","price":"794.63000000","remaining_size":"0.90000000","sequence":4839270735,"time":"2018-07-27T01:32:38.240000Z"}
{"type":"received","order_id":"fe7d7d9e-a6ed-4085-9b17-003eaa1316ad","order_type":"limit","size":"0.90000000","price":"794.64000000","side":"sell","client_oid":"fd195239-1449-4b5e-a661-45b88876db58","product_id":"BCH-USD","sequence":4839270736,"time":"2018-07-27T01:32:38.240000Z"}
{"type":"open","side":"sell","price":"794.64000000","order_id":"fe7d7d9e-a6ed-4085-9b17-003eaa1316ad","remaining_size":"0.90000000","product_id":"BCH-USD","sequence":4839270737,"time":"2018-07-27T01:32:38.240000Z"}
{"type":"received","order_id":"06c71748-ead6-4f7d-b577-2868cae78a65","order_type":"limit","size":"7.44874862","price":"83.38000000","side":"sell","client_oid":"d2996fd9-cd3e-4c5b-8000-00c3007a840d","product_id":"LTC-USD","sequence":2423271506,"time":"2018-07-27T01:32:38.246000Z"}
{"type":"received","order_id":"854fc4f6-761e-4065-a25e-749e1e05e73f","order_type":"limit","size":"1.90000000","price":"795.26000000","side":"sell","client_oid":"a38d0ec2-83e0-4bdb-a476-94b17cd7755f","product_id":"BCH-USD","sequence":4839270738,"time":"2018-07-27T01:32:38.246000Z"}
{"type":"open","side":"sell","price":"795.26000000","order_id":"854fc4f6-761e-4065-a25e-749e1e05e73f","remaining_size":"1.90000000","product_id":"BCH-USD","sequence":4839270739,"time":"2018-07-27T01:32:38.246000Z"}
{"type":"done","side":"sell","order_id":"fe7d7d9e-a6ed-4085-9b17-003eaa1316ad","reason":"canceled","product_id":"BCH-USD","price":"794.64000000","remaining_size":"0.90000000","sequence":4839270740,"time":"2018-07-27T01:32:38.247000Z"}
{"type":"open","side":"sell","price":"83.38000000","order_id":"06c71748-ead6-4f7d-b577-2868cae78a65","remaining_size":"7.44874862","product_id":"LTC-USD","sequence":2423271507,"time":"2018-07-27T01:32:38.246000Z"}
{"type":"done","side":"sell","order_id":"a4b89133-e021-41bd-9384-e1fb60d5cafd","reason":"canceled","product_id":"BCH-USD","price":"795.28000000","remaining_size":"4.50000000","sequence":4839270741,"time":"2018-07-27T01:32:38.250000Z"}
{"type":"done","side":"sell","order_id":"854fc4f6-761e-4065-a25e-749e1e05e73f","reason":"canceled","product_id":"BCH-USD","price":"795.26000000","remaining_size":"1.90000000","sequence":4839270742,"time":"2018-07-27T01:32:38.250000Z"}
{"type":"received","order_id":"1e038df5-e19d-470d-bbb3-bf00a99b9f05","order_type":"limit","size":"0.90000000","price":"794.62000000","side":"sell","client_oid":"bcebf362-c97a-4acd-a985-cdc64ea9ba54","product_id":"BCH-USD","sequence":4839270743,"time":"2018-07-27T01:32:38.253000Z"}
{"type":"open","side":"sell","price":"794.62000000","order_id":"1e038df5-e19d-470d-bbb3-bf00a99b9f05","remaining_size":"0.90000000","product_id":"BCH-USD","sequence":4839270744,"time":"2018-07-27T01:32:38.253000Z"}
{"type":"received","order_id":"526bc19b-0a09-46c1-ad79-fc01629702be","order_type":"limit","size":"0.90000000","price":"794.64000000","side":"sell","client_oid":"b3a494f9-66ed-4db2-811f-39ec8a97a49c","product_id":"BCH-USD","sequence":4839270745,"time":"2018-07-27T01:32:38.256000Z"}
{"type":"open","side":"sell","price":"794.64000000","order_id":"526bc19b-0a09-46c1-ad79-fc01629702be","remaining_size":"0.90000000","product_id":"BCH-USD","sequence":4839270746,"time":"2018-07-27T01:32:38.256000Z"}
{"type":"received","order_id":"ef7ad20d-6a05-434e-acca-4363419c4758","order_type":"limit","size":"4.50000000","price":"795.27000000","side":"sell","client_oid":"f550c704-ac64-46d3-b6a2-11443614dbec","product_id":"BCH-USD","sequence":4839270747,"time":"2018-07-27T01:32:38.258000Z"}
{"type":"open","side":"sell","price":"795.27000000","order_id":"ef7ad20d-6a05-434e-acca-4363419c4758","remaining_size":"4.50000000","product_id":"BCH-USD","sequence":4839270748,"time":"2018-07-27T01:32:38.258000Z"}
{"type":"done","side":"sell","order_id":"526bc19b-0a09-46c1-ad79-fc01629702be","reason":"canceled","product_id":"BCH-USD","price":"794.64000000","remaining_size":"0.90000000","sequence":4839270749,"time":"2018-07-27T01:32:38.260000Z"}
{"type":"received","order_id":"b85c92fb-e6ce-47ff-9251-d22ef9160b11","order_type":"limit","size":"1.90000000","price":"795.27000000","side":"sell","client_oid":"1f0e8cec-d519-4711-b281-f5271ba15459","product_id":"BCH-USD","sequence":4839270750,"time":"2018-07-27T01:32:38.261000Z"}
{"type":"open","side":"sell","price":"795.27000000","order_id":"b85c92fb-e6ce-47ff-9251-d22ef9160b11","remaining_size":"1.90000000","product_id":"BCH-USD","sequence":4839270751,"time":"2018-07-27T01:32:38.261000Z"}
{"type":"done","side":"sell","order_id":"0f45f862-ed83-421f-9c47-d05cd379ca76","reason":"canceled","product_id":"BCH-USD","price":"794.63000000","remaining_size":"1.90000000","sequence":4839270752,"time":"2018-07-27T01:32:38.264000Z"}
{"type":"done","side":"sell","order_id":"08269105-6257-4a93-8d48-19f2e25a51ae","reason":"canceled","product_id":"BCH-USD","price":"794.63000000","remaining_size":"4.50000000","sequence":4839270753,"time":"2018-07-27T01:32:38.267000Z"}
{"type":"received","order_id":"4e344936-ec7d-45f4-b63f-62ef13e2036c","order_type":"limit","size":"0.90000000","price":"794.62000000","side":"sell","client_oid":"b56eff66-7566-41ee-bf83-1b5e58990c31","product_id":"BCH-USD","sequence":4839270754,"time":"2018-07-27T01:32:38.267000Z"}
{"type":"open","side":"sell","price":"794.62000000","order_id":"4e344936-ec7d-45f4-b63f-62ef13e2036c","remaining_size":"0.90000000","product_id":"BCH-USD","sequence":4839270755,"time":"2018-07-27T01:32:38.267000Z"}
{"type":"received","order_id":"b6935e81-e05d-44ec-bad3-876b5310d1a4","order_type":"limit","size":"1.90000000","price":"794.62000000","side":"sell","client_oid":"0ae45486-aaf2-4966-af84-17e904624e25","product_id":"BCH-USD","sequence":4839270756,"time":"2018-07-27T01:32:38.271000Z"}
{"type":"open","side":"sell","price":"794.62000000","order_id":"b6935e81-e05d-44ec-bad3-876b5310d1a4","remaining_size":"1.90000000","product_id":"BCH-USD","sequence":4839270757,"time":"2018-07-27T01:32:38.271000Z"}
{"type":"done","side":"sell","order_id":"ef7ad20d-6a05-434e-acca-4363419c4758","reason":"canceled","product_id":"BCH-USD","price":"795.27000000","remaining_size":"4.50000000","sequence":4839270758,"time":"2018-07-27T01:32:38.271000Z"}
{"type":"done","side":"sell","order_id":"b85c92fb-e6ce-47ff-9251-d22ef9160b11","reason":"canceled","product_id":"BCH-USD","price":"795.27000000","remaining_size":"1.90000000","sequence":4839270759,"time":"2018-07-27T01:32:38.272000Z"}
{"type":"done","side":"sell","order_id":"b6935e81-e05d-44ec-bad3-876b5310d1a4","reason":"canceled","product_id":"BCH-USD","price":"794.62000000","remaining_size":"1.90000000","sequence":4839270760,"time":"2018-07-27T01:32:38.273000Z"}
{"type":"done","side":"sell","order_id":"4e344936-ec7d-45f4-b63f-62ef13e2036c","reason":"canceled","product_id":"BCH-USD","price":"794.62000000","remaining_size":"0.90000000","sequence":4839270761,"time":"2018-07-27T01:32:38.275000Z"}
{"type":"received","order_id":"dc2299f1-bd19-48e1-bbd8-0757c2b699ed","order_type":"limit","size":"1.90000000","price":"795.29000000","side":"sell","client_oid":"fdd9ff8d-9921-485c-a0f4-17875309a59a","product_id":"BCH-USD","sequence":4839270762,"time":"2018-07-27T01:32:38.280000Z"}
{"type":"open","side":"sell","price":"795.29000000","order_id":"dc2299f1-bd19-48e1-bbd8-0757c2b699ed","remaining_size":"1.90000000","product_id":"BCH-USD","sequence":4839270763,"time":"2018-07-27T01:32:38.280000Z"}
{"type":"received","order_id":"7fff0301-624a-440d-8534-94167812dc92","order_type":"limit","size":"4.50000000","price":"794.62000000","side":"sell","client_oid":"156f818b-65e5-40d0-b7a4-0fb8b72010f1","product_id":"BCH-USD","sequence":4839270764,"time":"2018-07-27T01:32:38.281000Z"}
{"type":"open","side":"sell","price":"794.62000000","order_id":"7fff0301-624a-440d-8534-94167812dc92","remaining_size":"4.50000000","product_id":"BCH-USD","sequence":4839270765,"time":"2018-07-27T01:32:38.281000Z"}
{"type":"done","side":"sell","order_id":"dc2299f1-bd19-48e1-bbd8-0757c2b699ed","reason":"canceled","product_id":"BCH-USD","price":"795.29000000","remaining_size":"1.90000000","sequence":4839270766,"time":"2018-07-27T01:32:38.283000Z"}
{"type":"received","order_id":"e2a16b5f-f4cc-4a05-9991-233957455558","order_type":"limit","size":"4.50000000","price":"795.29000000","side":"sell","client_oid":"05213007-de82-4d92-a08b-ff19cf8bc4ae","product_id":"BCH-USD","sequence":4839270767,"time":"2018-07-27T01:32:38.287000Z"}
{"type":"open","side":"sell","price":"795.29000000","order_id":"e2a16b5f-f4cc-4a05-9991-233957455558","remaining_size":"4.50000000","product_id":"BCH-USD","sequence":4839270768,"time":"2018-07-27T01:32:38.287000Z"}
{"type":"done","side":"sell","order_id":"1e038df5-e19d-470d-bbb3-bf00a99b9f05","reason":"canceled","product_id":"BCH-USD","price":"794.62000000","remaining_size":"0.90000000","sequence":4839270769,"time":"2018-07-27T01:32:38.288000Z"}
{"type":"done","side":"sell","order_id":"7fff0301-624a-440d-8534-94167812dc92","reason":"canceled","product_id":"BCH-USD","price":"794.62000000","remaining_size":"4.50000000","sequence":4839270770,"time":"2018-07-27T01:32:38.289000Z"}
{"type":"received","order_id":"c309706a-36e8-4181-af11-9dcc21f24d53","order_type":"limit","size":"1.90000000","price":"794.64000000","side":"sell","client_oid":"544997af-e598-499d-9a8f-894deb56112f","product_id":"BCH-USD","sequence":4839270771,"time":"2018-07-27T01:32:38.290000Z"}
{"type":"open","side":"sell","price":"794.64000000","order_id":"c309706a-36e8-4181-af11-9dcc21f24d53","remaining_size":"1.90000000","product_id":"BCH-USD","sequence":4839270772,"time":"2018-07-27T01:32:38.290000Z"}
{"type":"done","side":"sell","order_id":"e2a16b5f-f4cc-4a05-9991-233957455558","reason":"canceled","product_id":"BCH-USD","price":"795.29000000","remaining_size":"4.50000000","sequence":4839270773,"time":"2018-07-27T01:32:38.292000Z"}
{"type":"done","side":"sell","order_id":"c309706a-36e8-4181-af11-9dcc21f24d53","reason":"canceled","product_id":"BCH-USD","price":"794.64000000","remaining_size":"1.90000000","sequence":4839270774,"time":"2018-07-27T01:32:38.294000Z"}
{"type":"received","order_id":"1d2c8238-8447-47d3-8483-d617a0dd02bf","order_type":"limit","size":"1.90000000","price":"795.26000000","side":"sell","client_oid":"bfb89604-edab-452d-82f6-87f909bd3f10","product_id":"BCH-USD","sequence":4839270775,"time":"2018-07-27T01:32:38.296000Z"}
{"type":"open","side":"sell","price":"795.26000000","order_id":"1d2c8238-8447-47d3-8483-d617a0dd02bf","remaining_size":"1.90000000","product_id":"BCH-USD","sequence":4839270776,"time":"2018-07-27T01:32:38.296000Z"}
{"type":"received","order_id":"e2de6dec-203e-434e-a7cf-3354fd8a9e5a","order_type":"limit","size":"0.90000000","price":"794.64000000","side":"sell","client_oid":"bb44bda6-7bf7-4927-8def-3772eb7e4145","product_id":"BCH-USD","sequence":4839270777,"time":"2018-07-27T01:32:38.298000Z"}
{"type":"open","side":"sell","price":"794.64000000","order_id":"e2de6dec-203e-434e-a7cf-3354fd8a9e5a","remaining_size":"0.90000000","product_id":"BCH-USD","sequence":4839270778,"time":"2018-07-27T01:32:38.298000Z"}
{"type":"received","order_id":"8e8512a4-2fc3-4bb9-aa78-f5605be0f029","order_type":"limit","size":"0.90000000","price":"794.64000000","side":"sell","client_oid":"4ef39ab4-a8ce-4bca-ba64-bf4e20837f9f","product_id":"BCH-USD","sequence":4839270779,"time":"2018-07-27T01:32:38.300000Z"}
{"type":"open","side":"sell","price":"794.64000000","order_id":"8e8512a4-2fc3-4bb9-aa78-f5605be0f029","remaining_size":"0.90000000","product_id":"BCH-USD","sequence":4839270780,"time":"2018-07-27T01:32:38.300000Z"}
{"type":"received","order_id":"d51753a7-95d2-4c58-adca-9b26fe7fd5bf","order_type":"limit","size":"4.50000000","price":"794.64000000","side":"sell","client_oid":"8502e9da-17b4-47c2-af98-a87837085323","product_id":"BCH-USD","sequence":4839270781,"time":"2018-07-27T01:32:38.303000Z"}
{"type":"open","side":"sell","price":"794.64000000","order_id":"d51753a7-95d2-4c58-adca-9b26fe7fd5bf","remaining_size":"4.50000000","product_id":"BCH-USD","sequence":4839270782,"time":"2018-07-27T01:32:38.303000Z"}
{"type":"received","order_id":"c1800498-417a-4d45-9306-4631e153e964","order_type":"limit","size":"4.50000000","price":"795.28000000","side":"sell","client_oid":"02bcf801-159a-46b1-99cf-f09bfdbf40d4","product_id":"BCH-USD","sequence":4839270783,"time":"2018-07-27T01:32:38.309000Z"}
{"type":"open","side":"sell","price":"795.28000000","order_id":"c1800498-417a-4d45-9306-4631e153e964","remaining_size":"4.50000000","product_id":"BCH-USD","sequence":4839270784,"time":"2018-07-27T01:32:38.309000Z"}
{"type":"done","side":"sell","order_id":"e2de6dec-203e-434e-a7cf-3354fd8a9e5a","reason":"canceled","product_id":"BCH-USD","price":"794.64000000","remaining_size":"0.90000000","sequence":4839270785,"time":"2018-07-27T01:32:38.312000Z"}
{"type":"done","side":"buy","order_id":"6bac1df9-434c-45b3-b6f0-01f517f6d921","reason":"canceled","product_id":"ETH-USD","price":"460.27000000","remaining_size":"3.48357000","sequence":4469354698,"time":"2018-07-27T01:32:38.314000Z"}
{"type":"done","side":"sell","order_id":"c1800498-417a-4d45-9306-4631e153e964","reason":"canceled","product_id":"BCH-USD","price":"795.28000000","remaining_size":"4.50000000","sequence":4839270786,"time":"2018-07-27T01:32:38.314000Z"}
{"type":"done","side":"sell","order_id":"8e8512a4-2fc3-4bb9-aa78-f5605be0f029","reason":"canceled","product_id":"BCH-USD","price":"794.64000000","remaining_size":"0.90000000","sequence":4839270787,"time":"2018-07-27T01:32:38.314000Z"}
{"type":"done","side":"sell","order_id":"d51753a7-95d2-4c58-adca-9b26fe7fd5bf","reason":"canceled","product_id":"BCH-USD","price":"794.64000000","remaining_size":"4.50000000","sequence":4839270788,"time":"2018-07-27T01:32:38.314000Z"}
{"type":"received","order_id":"dd2bc36d-9a73-402a-a5b0-940eb8c1d22d","order_type":"limit","size":"1.90000000","price":"794.61000000","side":"sell","client_oid":"0466d05e-dfa0-4c39-8846-c55a674406f9","product_id":"BCH-USD","sequence":4839270789,"time":"2018-07-27T01:32:38.316000Z"}
{"type":"open","side":"sell","price":"794.61000000","order_id":"dd2bc36d-9a73-402a-a5b0-940eb8c1d22d","remaining_size":"1.90000000","product_id":"BCH-USD","sequence":4839270790,"time":"2018-07-27T01:32:38.316000Z"}
{"type":"received","order_id":"b30a3b04-b931-4a6d-a9b7-15e6e83e9a76","order_type":"limit","size":"0.90000000","price":"794.63000000","side":"sell","client_oid":"b53029b0-8b7b-4372-bebf-b7fb199b288f","product_id":"BCH-USD","sequence":4839270791,"time":"2018-07-27T01:32:38.319000Z"}
{"type":"open","side":"sell","price":"794.63000000","order_id":"b30a3b04-b931-4a6d-a9b7-15e6e83e9a76","remaining_size":"0.90000000","product_id":"BCH-USD","sequence":4839270792,"time":"2018-07-27T01:32:38.319000Z"}
{"type":"done","side":"sell","order_id":"dd2bc36d-9a73-402a-a5b0-940eb8c1d22d","reason":"canceled","product_id":"BCH-USD","price":"794.61000000","remaining_size":"1.90000000","sequence":4839270793,"time":"2018-07-27T01:32:38.322000Z"}
{"type":"received","order_id":"f172d009-6fee-48ed-940d-622d7f7cac36","order_type":"limit","size":"0.90000000","price":"794.63000000","side":"sell","client_oid":"eb4dd20c-51a7-427d-a8c3-2d0df0ce4872","product_id":"BCH-USD","sequence":4839270794,"time":"2018-07-27T01:32:38.322000Z"}
{"type":"open","side":"sell","price":"794.63000000","order_id":"f172d009-6fee-48ed-940d-622d7f7cac36","remaining_size":"0.90000000","product_id":"BCH-USD","sequence":4839270795,"time":"2018-07-27T01:32:38.322000Z"}
{"type":"received","order_id":"da48dbc4-7efb-46fd-8fa3-0b9356bbab0a","order_type":"limit","size":"4.50000000","price":"795.25000000","side":"sell","client_oid":"816a3e81-037c-4345-90a9-e8905abb047b","product_id":"BCH-USD","sequence":4839270796,"time":"2018-07-27T01:32:38.323000Z"}
{"type":"open","side":"sell","price":"795.25000000","order_id":"da48dbc4-7efb-46fd-8fa3-0b9356bbab0a","remaining_size":"4.50000000","product_id":"BCH-USD","sequence":4839270797,"time":"2018-07-27T01:32:38.323000Z"}
{"type":"done","side":"sell","order_id":"b30a3b04-b931-4a6d-a9b7-15e6e83e9a76","reason":"canceled","product_id":"BCH-USD","price":"794.63000000","remaining_size":"0.90000000","sequence":4839270798,"time":"2018-07-27T01:32:38.324000Z"}
{"type":"done","side":"sell","order_id":"f172d009-6fee-48ed-940d-622d7f7cac36","reason":"canceled","product_id":"BCH-USD","price":"794.63000000","remaining_size":"0.90000000","sequence":4839270799,"time":"2018-07-27T01:32:38.325000Z"}
{"type":"received","order_id":"90bc9fcd-5321-4b5b-a1cf-33799c0fc039","order_type":"limit","size":"4.50000000","price":"794.63000000","side":"sell","client_oid":"e3f257cb-c434-48a8-823c-ac872d9c5a2a","product_id":"BCH-USD","sequence":4839270800,"time":"2018-07-27T01:32:38.326000Z"}
{"type":"open","side":"sell","price":"794.63000000","order_id":"90bc9fcd-5321-4b5b-a1cf-33799c0fc039","remaining_size":"4.50000000","product_id":"BCH-USD","sequence":4839270801,"time":"2018-07-27T01:32:38.326000Z"}
{"type":"done","side":"sell","order_id":"90bc9fcd-5321-4b5b-a1cf-33799c0fc039","reason":"canceled","product_id":"BCH-USD","price":"794.63000000","remaining_size":"4.50000000","sequence":4839270802,"time":"2018-07-27T01:32:38.332000Z"}
{"type":"done","side":"sell","order_id":"da48dbc4-7efb-46fd-8fa3-0b9356bbab0a","reason":"canceled","product_id":"BCH-USD","price":"795.25000000","remaining_size":"4.50000000","sequence":4839270803,"time":"2018-07-27T01:32:38.333000Z"}
{"type":"done","side":"sell","order_id":"1d2c8238-8447-47d3-8483-d617a0dd02bf","reason":"canceled","product_id":"BCH-USD","price":"795.26000000","remaining_size":"1.90000000","sequence":4839270804,"time":"2018-07-27T01:32:38.334000Z"}
{"type":"received","order_id":"770ddce9-909c-4735-9229-71b7a55bb9ca","order_type":"limit","size":"1.90000000","price":"794.63000000","side":"sell","client_oid":"1e123584-4ad2-4df5-a633-f3b9760c1726","product_id":"BCH-USD","sequence":4839270805,"time":"2018-07-27T01:32:38.335000Z"}
{"type":"open","side":"sell","price":"794.63000000","order_id":"770ddce9-909c-4735-9229-71b7a55bb9ca","remaining_size":"1.90000000","product_id":"BCH-USD","sequence":4839270806,"time":"2018-07-27T01:32:38.335000Z"}
{"type":"done","side":"sell","order_id":"770ddce9-909c-4735-9229-71b7a55bb9ca","reason":"canceled","product_id":"BCH-USD","price":"794.63000000","remaining_size":"1.90000000","sequence":4839270807,"time":"2018-07-27T01:32:38.339000Z"}
{"type":"received","order_id":"16c1c8f1-7b35-42c7-806e-a346d89ab21e","order_type":"limit","size":"1.90000000","price":"795.25000000","side":"sell","client_oid":"c7b8bbb9-0d9b-477a-97dc-4ed8d5687188","product_id":"BCH-USD","sequence":4839270808,"time":"2018-07-27T01:32:38.339000Z"}
{"type":"open","side":"sell","price":"795.25000000","order_id":"16c1c8f1-7b35-42c7-806e-a346d89ab21e","remaining_size":"1.90000000","product_id":"BCH-USD","sequence":4839270809,"time":"2018-07-27T01:32:38.339000Z"}
{"type":"received","order_id":"3dc567fe-a550-4723-a9ff-df09481921de","order_type":"limit","size":"4.50000000","price":"795.24000000","side":"sell","client_oid":"ef6263d8-0bc6-4002-a15b-df5a5b7e3fd4","product_id":"BCH-USD","sequence":4839270810,"time":"2018-07-27T01:32:38.343000Z"}
{"type":"open","side":"sell","price":"795.24000000","order_id":"3dc567fe-a550-4723-a9ff-df09481921de","remaining_size":"4.50000000","product_id":"BCH-USD","sequence":4839270811,"time":"2018-07-27T01:32:38.343000Z"}
{"type":"received","order_id":"4cb3ac71-7cc2-4f98-9845-1dbfbd2d8edc","order_type":"limit","size":"0.90000000","price":"794.64000000","side":"sell","client_oid":"ce02bc0c-25b3-4486-bb56-f782a794c7ac","product_id":"BCH-USD","sequence":4839270812,"time":"2018-07-27T01:32:38.345000Z"}
{"type":"open","side":"sell","price":"794.64000000","order_id":"4cb3ac71-7cc2-4f98-9845-1dbfbd2d8edc","remaining_size":"0.90000000","product_id":"BCH-USD","sequence":4839270813,"time":"2018-07-27T01:32:38.345000Z"}
{"type":"done","side":"sell","order_id":"3dc567fe-a550-4723-a9ff-df09481921de","reason":"canceled","product_id":"BCH-USD","price":"795.24000000","remaining_size":"4.50000000","sequence":4839270814,"time":"2018-07-27T01:32:38.346000Z"}
{"type":"received","order_id":"6a8e2a03-7c9a-46d5-9df6-26f880cc36fb","order_type":"limit","size":"4.50000000","price":"794.64000000","side":"sell","client_oid":"20de40e6-a0ee-40c8-b6d6-f4ac22d9667a","product_id":"BCH-USD","sequence":4839270815,"time":"2018-07-27T01:32:38.348000Z"}
{"type":"open","side":"sell","price":"794.64000000","order_id":"6a8e2a03-7c9a-46d5-9df6-26f880cc36fb","remaining_size":"4.50000000","product_id":"BCH-USD","sequence":4839270816,"time":"2018-07-27T01:32:38.348000Z"}
{"type":"received","order_id":"fae54957-5971-4de9-8322-c3245f61ad79","order_type":"limit","size":"1.90000000","price":"794.64000000","side":"sell","client_oid":"4b7ea8ec-4477-410a-9f8c-c6ac9f8e063e","product_id":"BCH-USD","sequence":4839270817,"time":"2018-07-27T01:32:38.353000Z"}
{"type":"open","side":"sell","price":"794.64000000","order_id":"fae54957-5971-4de9-8322-c3245f61ad79","remaining_size":"1.90000000","product_id":"BCH-USD","sequence":4839270818,"time":"2018-07-27T01:32:38.353000Z"}
{"type":"received","order_id":"7c88d795-8107-46a4-9a8d-94fdf5d3a2ae","order_type":"limit","size":"4.50000000","price":"795.29000000","side":"sell","client_oid":"55abfc12-e47d-43e6-bf4f-24c21918786d","product_id":"BCH-USD","sequence":4839270819,"time":"2018-07-27T01:32:38.353000Z"}
{"type":"open","side":"sell","price":"795.29000000","order_id":"7c88d795-8107-46a4-9a8d-94fdf5d3a2ae","remaining_size":"4.50000000","product_id":"BCH-USD","sequence":4839270820,"time":"2018-07-27T01:32:38.353000Z"}
{"type":"done","side":"sell","order_id":"7c88d795-8107-46a4-9a8d-94fdf5d3a2ae","reason":"canceled","product_id":"BCH-USD","price":"795.29000000","remaining_size":"4.50000000","sequence":4839270821,"time":"2018-07-27T01:32:38.357000Z"}
{"type":"done","side":"buy","order_id":"1bf58b04-a0f9-4c46-a457-241760e938d6","reason":"canceled","product_id":"ETH-USD","price":"461.95000000","remaining_size":"1.21150000","sequence":4469354699,"time":"2018-07-27T01:32:38.359000Z"}
{"type":"done","side":"sell","order_id":"fae54957-5971-4de9-8322-c3245f61ad79","reason":"canceled","product_id":"BCH-USD","price":"794.64000000","remaining_size":"1.90000000","sequence":4839270822,"time":"2018-07-27T01:32:38.362000Z"}
{"type":"done","side":"sell","order_id":"6a8e2a03-7c9a-46d5-9df6-26f880cc36fb","reason":"canceled","product_id":"BCH-USD","price":"794.64000000","remaining_size":"4.50000000","sequence":4839270823,"time":"2018-07-27T01:32:38.364000Z"}
{"type":"received","order_id":"684bcc6f-4573-4f0d-bcab-01d83aa069bc","order_type":"limit","size":"20.00000000","price":"83.22000000","side":"buy","client_oid":"290bc648-3f8e-4b59-afd3-154d76225eb0","product_id":"LTC-USD","sequence":2423271508,"time":"2018-07-27T01:32:38.368000Z"}
{"type":"received","order_id":"41da1814-f610-44f4-9472-396bbc549a15","order_type":"limit","size":"4.50000000","price":"794.63000000","side":"sell","client_oid":"1a4e6ba5-321d-4b82-befa-9b01803dbd02","product_id":"BCH-USD","sequence":4839270824,"time":"2018-07-27T01:32:38.367000Z"}
{"type":"open","side":"sell","price":"794.63000000","order_id":"41da1814-f610-44f4-9472-396bbc549a15","remaining_size":"4.50000000","product_id":"BCH-USD","sequence":4839270825,"time":"2018-07-27T01:32:38.367000Z"}
{"type":"open","side":"buy","price":"83.22000000","order_id":"684bcc6f-4573-4f0d-bcab-01d83aa069bc","remaining_size":"20.00000000","product_id":"LTC-USD","sequence":2423271509,"time":"2018-07-27T01:32:38.368000Z"}
{"type":"received","order_id":"8b4fa7df-9728-4a44-8ac3-1ab5978892e3","order_type":"limit","size":"1.90000000","price":"794.63000000","side":"sell","client_oid":"7a4f4311-6387-4ee3-9858-cfad8fdee2e8","product_id":"BCH-USD","sequence":4839270826,"time":"2018-07-27T01:32:38.370000Z"}
{"type":"open","side":"sell","price":"794.63000000","order_id":"8b4fa7df-9728-4a44-8ac3-1ab5978892e3","remaining_size":"1.90000000","product_id":"BCH-USD","sequence":4839270827,"time":"2018-07-27T01:32:38.370000Z"}
{"type":"received","order_id":"be9a8c3e-77c3-4ddf-9514-ba5d81399ba1","order_type":"limit","size":"0.90000000","price":"794.64000000","side":"sell","client_oid":"7427eefd-ca68-41da-a849-f3e129fa676b","product_id":"BCH-USD","sequence":4839270828,"time":"2018-07-27T01:32:38.373000Z"}
{"type":"open","side":"sell","price":"794.64000000","order_id":"be9a8c3e-77c3-4ddf-9514-ba5d81399ba1","remaining_size":"0.90000000","product_id":"BCH-USD","sequence":4839270829,"time":"2018-07-27T01:32:38.373000Z"}
{"type":"done","side":"sell","order_id":"16c1c8f1-7b35-42c7-806e-a346d89ab21e","reason":"canceled","product_id":"BCH-USD","price":"795.25000000","remaining_size":"1.90000000","sequence":4839270830,"time":"2018-07-27T01:32:38.377000Z"}
{"type":"done","side":"sell","order_id":"41da1814-f610-44f4-9472-396bbc549a15","reason":"canceled","product_id":"BCH-USD","price":"794.63000000","remaining_size":"4.50000000","sequence":4839270831,"time":"2018-07-27T01:32:38.379000Z"}
{"type":"done","side":"sell","order_id":"be9a8c3e-77c3-4ddf-9514-ba5d81399ba1","reason":"canceled","product_id":"BCH-USD","price":"794.64000000","remaining_size":"0.90000000","sequence":4839270832,"time":"2018-07-27T01:32:38.379000Z"}
{"type":"done","side":"sell","order_id":"a6248f9c-e32c-4f29-9266-699d854132dc","reason":"canceled","product_id":"LTC-USD","price":"83.30000000","remaining_size":"7.44874862","sequence":2423271510,"time":"2018-07-27T01:32:38.383000Z"}
{"type":"done","side":"sell","order_id":"8b4fa7df-9728-4a44-8ac3-1ab5978892e3","reason":"canceled","product_id":"BCH-USD","price":"794.63000000","remaining_size":"1.90000000","sequence":4839270833,"time":"2018-07-27T01:32:38.382000Z"}
{"type":"done","side":"sell","order_id":"4cb3ac71-7cc2-4f98-9845-1dbfbd2d8edc","reason":"canceled","product_id":"BCH-USD","price":"794.64000000","remaining_size":"0.90000000","sequence":4839270834,"time":"2018-07-27T01:32:38.382000Z"}
{"type":"received","order_id":"aad5a78a-3178-4977-80d8-c702c1b8e611","order_type":"limit","size":"0.90000000","price":"794.63000000","side":"sell","client_oid":"9ace5db9-96de-49f1-ba05-87e38be4b8f5","product_id":"BCH-USD","sequence":4839270835,"time":"2018-07-27T01:32:38.384000Z"}
{"type":"done","side":"buy","order_id":"eb915621-e9e9-471e-bc3b-a3d23a57c0ac","reason":"canceled","product_id":"BTC-USD","price":"7872.67000000","remaining_size":"0.00100000","sequence":6418130187,"time":"2018-07-27T01:32:38.387000Z"}
{"type":"open","side":"sell","price":"794.63000000","order_id":"aad5a78a-3178-4977-80d8-c702c1b8e611","remaining_size":"0.90000000","product_id":"BCH-USD","sequence":4839270836,"time":"2018-07-27T01:32:38.384000Z"}
{"type":"received","order_id":"35682bfb-6080-4ded-997c-5d34e0d4e747","order_type":"limit","size":"2.00000000","price":"792.37000000","side":"buy","client_oid":"8297a114-8abb-41f6-b9bf-5d3026347adf","product_id":"BCH-USD","sequence":4839270837,"time":"2018-07-27T01:32:38.385000Z"}
{"type":"open","side":"buy","price":"792.37000000","order_id":"35682bfb-6080-4ded-997c-5d34e0d4e747","remaining_size":"2.00000000","product_id":"BCH-USD","sequence":4839270838,"time":"2018-07-27T01:32:38.385000Z"}
{"type":"received","order_id":"3a863a2e-3565-4a45-9fb5-bf5a019ca3a2","order_type":"limit","size":"4.50000000","price":"794.62000000","side":"sell","client_oid":"69fed5ce-a508-4af7-bc23-5bb1752eb7f0","product_id":"BCH-USD","sequence":4839270839,"time":"2018-07-27T01:32:38.386000Z"}
{"type":"open","side":"sell","price":"794.62000000","order_id":"3a863a2e-3565-4a45-9fb5-bf5a019ca3a2","remaining_size":"4.50000000","product_id":"BCH-USD","sequence":4839270840,"time":"2018-07-27T01:32:38.386000Z"}
{"type":"received","order_id":"90b9a880-39b5-41a4-9027-eef83f54462c","order_type":"limit","size":"1.21150000","price":"461.95000000","side":"buy","client_oid":"6642ef63-6aa0-43cf-8c7e-92d54d8f5036","product_id":"ETH-USD","sequence":4469354700,"time":"2018-07-27T01:32:38.390000Z"}
{"type":"open","side":"buy","price":"461.95000000","order_id":"90b9a880-39b5-41a4-9027-eef83f54462c","remaining_size":"1.21150000","product_id":"ETH-USD","sequence":4469354701,"time":"2018-07-27T01:32:38.390000Z"}
{"type":"received","order_id":"9b18b25d-934d-4dd8-8b9a-4868c094f7c9","order_type":"limit","size":"1.90000000","price":"794.62000000","side":"sell","client_oid":"9fc16620-f9e9-43a4-bc28-59034612d74d","product_id":"BCH-USD","sequence":4839270841,"time":"2018-07-27T01:32:38.392000Z"}
{"type":"open","side":"sell","price":"794.62000000","order_id":"9b18b25d-934d-4dd8-8b9a-4868c094f7c9","remaining_size":"1.90000000","product_id":"BCH-USD","sequence":4839270842,"time":"2018-07-27T01:32:38.392000Z"}
{"type":"received","order_id":"bd22a14f-4317-4caa-bdb1-5e7a427d7c89","order_type":"limit","size":"0.90000000","price":"794.62000000","side":"sell","client_oid":"b13eb006-f6ae-4fde-98b5-f6e70d0cf81f","product_id":"BCH-USD","sequence":4839270843,"time":"2018-07-27T01:32:38.395000Z"}
{"type":"open","side":"sell","price":"794.62000000","order_id":"bd22a14f-4317-4caa-bdb1-5e7a427d7c89","remaining_size":"0.90000000","product_id":"BCH-USD","sequence":4839270844,"time":"2018-07-27T01:32:38.395000Z"}
{"type":"done","side":"sell","order_id":"9b18b25d-934d-4dd8-8b9a-4868c094f7c9","reason":"canceled","product_id":"BCH-USD","price":"794.62000000","remaining_size":"1.90000000","sequence":4839270845,"time":"2018-07-27T01:32:38.399000Z"}
{"type":"done","side":"sell","order_id":"bd22a14f-4317-4caa-bdb1-5e7a427d7c89","reason":"canceled","product_id":"BCH-USD","price":"794.62000000","remaining_size":"0.90000000","sequence":4839270846,"time":"2018-07-27T01:32:38.401000Z"}
{"type":"received","order_id":"ad8d22f2-9d42-4a41-aabb-b08f5faf7e44","order_type":"limit","size":"7.44874862","price":"83.34000000","side":"sell","client_oid":"f10be0f2-f500-44d7-8000-001714aa8794","product_id":"LTC-USD","sequence":2423271511,"time":"2018-07-27T01:32:38.405000Z"}
{"type":"open","side":"sell","price":"83.34000000","order_id":"ad8d22f2-9d42-4a41-aabb-b08f5faf7e44","remaining_size":"7.44874862","product_id":"LTC-USD","sequence":2423271512,"time":"2018-07-27T01:32:38.405000Z"}
{"type":"done","side":"buy","order_id":"fb9848ca-ab96-454e-98a3-f2a45d49000a","reason":"canceled","product_id":"BTC-USD","price":"6697.79000000","remaining_size":"0.00150000","sequence":6418130188,"time":"2018-07-27T01:32:38.409000Z"}
{"type":"received","order_id":"433407d6-9e63-409d-8a58-4314275711de","order_type":"limit","size":"6.04200000","price":"462.51000000","side":"buy","product_id":"ETH-USD","sequence":4469354702,"time":"2018-07-27T01:32:38.410000Z"}
{"type":"match","trade_id":37930049,"maker_order_id":"dc99fe95-2fed-4fe4-90a1-6f1dd8b6c5fd","taker_order_id":"433407d6-9e63-409d-8a58-4314275711de","side":"sell","size":"6.04200000","price":"462.51000000","product_id":"ETH-USD","sequence":4469354703,"time":"2018-07-27T01:32:38.410000Z"}
{"type":"done","side":"buy","order_id":"433407d6-9e63-409d-8a58-4314275711de","reason":"filled","product_id":"ETH-USD","price":"462.51000000","remaining_size":"0.00000000","sequence":4469354704,"time":"2018-07-27T01:32:38.410000Z"}
{"type":"done","side":"buy","order_id":"fe8b944e-8920-42da-9c8e-b8c633f215ee","reason":"canceled","product_id":"LTC-USD","price":"82.98000000","remaining_size":"20.00000000","sequence":2423271513,"time":"2018-07-27T01:32:38.415000Z"}
{"type":"received","order_id":"066d142b-93fe-4c67-9e98-3f8ff73f6438","order_type":"limit","size":"1.90000000","price":"794.64000000","side":"sell","client_oid":"481ccde9-9c64-4afc-812b-993bb4678f50","product_id":"BCH-USD","sequence":4839270847,"time":"2018-07-27T01:32:38.415000Z"}
{"type":"open","side":"sell","price":"794.64000000","order_id":"066d142b-93fe-4c67-9e98-3f8ff73f6438","remaining_size":"1.90000000","product_id":"BCH-USD","sequence":4839270848,"time":"2018-07-27T01:32:38.415000Z"}
{"type":"received","order_id":"394ede43-93fd-4352-a6b1-bff5e49e9d7b","order_type":"limit","size":"0.90000000","price":"794.64000000","side":"sell","client_oid":"c8889a80-e144-4d6e-b472-b6fdb693f74f","product_id":"BCH-USD","sequence":4839270849,"time":"2018-07-27T01:32:38.417000Z"}
{"type":"open","side":"sell","price":"794.64000000","order_id":"394ede43-93fd-4352-a6b1-bff5e49e9d7b","remaining_size":"0.90000000","product_id":"BCH-USD","sequence":4839270850,"time":"2018-07-27T01:32:38.417000Z"}
{"type":"done","side":"buy","order_id":"35682bfb-6080-4ded-997c-5d34e0d4e747","reason":"canceled","product_id":"BCH-USD","price":"792.37000000","remaining_size":"2.00000000","sequence":4839270851,"time":"2018-07-27T01:32:38.419000Z"}
{"type":"done","side":"sell","order_id":"394ede43-93fd-4352-a6b1-bff5e49e9d7b","reason":"canceled","product_id":"BCH-USD","price":"794.64000000","remaining_size":"0.90000000","sequence":4839270852,"time":"2018-07-27T01:32:38.421000Z"}
{"type":"done","side":"sell","order_id":"3a863a2e-3565-4a45-9fb5-bf5a019ca3a2","reason":"canceled","product_id":"BCH-USD","price":"794.62000000","remaining_size":"4.50000000","sequence":4839270853,"time":"2018-07-27T01:32:38.423000Z"}
{"type":"done","side":"sell","order_id":"066d142b-93fe-4c67-9e98-3f8ff73f6438","reason":"canceled","product_id":"BCH-USD","price":"794.64000000","remaining_size":"1.90000000","sequence":4839270854,"time":"2018-07-27T01:32:38.423000Z"}
{"type":"done","side":"sell","order_id":"ad8d22f2-9d42-4a41-aabb-b08f5faf7e44","reason":"canceled","product_id":"LTC-USD","price":"83.34000000","remaining_size":"7.44874862","sequence":2423271514,"time":"2018-07-27T01:32:38.426000Z"}
{"type":"done","side":"sell","order_id":"aad5a78a-3178-4977-80d8-c702c1b8e611","reason":"canceled","product_id":"BCH-USD","price":"794.63000000","remaining_size":"0.90000000","sequence":4839270855,"time":"2018-07-27T01:32:38.424000Z"}
{"type":"received","order_id":"b02d4dc9-1b4e-4df4-9571-88eb0b3c2590","order_type":"limit","size":"20.00000000","price":"82.99000000","side":"buy","client_oid":"475bd97f-0dcc-4f53-8eb6-ce281d4347de","product_id":"LTC-USD","sequence":2423271515,"time":"2018-07-27T01:32:38.430000Z"}
{"type":"open","side":"buy","price":"82.99000000","order_id":"b02d4dc9-1b4e-4df4-9571-88eb0b3c2590","remaining_size":"20.00000000","product_id":"LTC-USD","sequence":2423271516,"time":"2018-07-27T01:32:38.430000Z"}
{"type":"done","side":"buy","order_id":"c50f1eca-f22d-4931-9ccb-8d9e5f7f7fee","reason":"canceled","product_id":"ETH-USD","price":"441.20000000","remaining_size":"0.12000000","sequence":4469354705,"time":"2018-07-27T01:32:38.432000Z"}
{"type":"received","order_id":"8ca9859c-3c24-4741-b51b-439c26df3bfc","order_type":"limit","size":"0.90000000","price":"794.61000000","side":"sell","client_oid":"2e5fa455-7200-4927-8582-7a2fa1dca027","product_id":"BCH-USD","sequence":4839270856,"time":"2018-07-27T01:32:38.432000Z"}
{"type":"open","side":"sell","price":"794.61000000","order_id":"8ca9859c-3c24-4741-b51b-439c26df3bfc","remaining_size":"0.90000000","product_id":"BCH-USD","sequence":4839270857,"time":"2018-07-27T01:32:38.432000Z"}
{"type":"received","order_id":"41efdb1c-a05e-4b07-b3de-40511c5611b5","order_type":"limit","size":"1.90000000","price":"794.61000000","side":"sell","client_oid":"92ca1519-0a55-4865-867e-d35495da218f","product_id":"BCH-USD","sequence":4839270858,"time":"2018-07-27T01:32:38.432000Z"}
{"type":"open","side":"sell","price":"794.61000000","order_id":"41efdb1c-a05e-4b07-b3de-40511c5611b5","remaining_size":"1.90000000","product_id":"BCH-USD","sequence":4839270859,"time":"2018-07-27T01:32:38.432000Z"}
{"type":"done","side":"sell","order_id":"7794b90d-ede9-499a-8cae-f48df4d44a90","reason":"canceled","product_id":"ETH-USD","price":"484.72000000","remaining_size":"0.01000000","sequence":4469354706,"time":"2018-07-27T01:32:38.434000Z"}
{"type":"received","order_id":"c9162dd4-9968-4136-a94e-4030fc477c66","order_type":"limit","size":"0.90000000","price":"794.61000000","side":"sell","client_oid":"393f34a4-19c2-4442-acee-081f53bda25a","product_id":"BCH-USD","sequence":4839270860,"time":"2018-07-27T01:32:38.436000Z"}
{"type":"open","side":"sell","price":"794.61000000","order_id":"c9162dd4-9968-4136-a94e-4030fc477c66","remaining_size":"0.90000000","product_id":"BCH-USD","sequence":4839270861,"time":"2018-07-27T01:32:38.436000Z"}
{"type":"done","side":"sell","order_id":"8ca9859c-3c24-4741-b51b-439c26df3bfc","reason":"canceled","product_id":"BCH-USD","price":"794.61000000","remaining_size":"0.90000000","sequence":4839270862,"time":"2018-07-27T01:32:38.440000Z"}
{"type":"done","side":"sell","order_id":"c9162dd4-9968-4136-a94e-4030fc477c66","reason":"canceled","product_id":"BCH-USD","price":"794.61000000","remaining_size":"0.90000000","sequence":4839270863,"time":"2018-07-27T01:32:38.441000Z"}
{"type":"received","order_id":"be37048d-7f31-4374-a466-32e36d3fca29","order_type":"limit","size":"0.90000000","price":"794.64000000","side":"sell","client_oid":"5d370671-0ae2-4180-b3cd-b291787c8cf2","product_id":"BCH-USD","sequence":4839270864,"time":"2018-07-27T01:32:38.443000Z"}
{"type":"open","side":"sell","price":"794.64000000","order_id":"be37048d-7f31-4374-a466-32e36d3fca29","remaining_size":"0.90000000","product_id":"BCH-USD","sequence":4839270865,"time":"2018-07-27T01:32:38.443000Z"}
{"type":"done","side":"sell","order_id":"be37048d-7f31-4374-a466-32e36d3fca29","reason":"canceled","product_id":"BCH-USD","price":"794.64000000","remaining_size":"0.90000000","sequence":4839270866,"time":"2018-07-27T01:32:38.445000Z"}
{"type":"received","order_id":"0422b0ca-ce57-4a60-bea9-ec6bf87800b6","order_type":"limit","size":"7.44874862","price":"83.30000000","side":"sell","client_oid":"92cc9370-13a1-44c3-8000-00589bef9cb3","product_id":"LTC-USD","sequence":2423271517,"time":"2018-07-27T01:32:38.448000Z"}
{"type":"open","side":"sell","price":"83.30000000","order_id":"0422b0ca-ce57-4a60-bea9-ec6bf87800b6","remaining_size":"7.44874862","product_id":"LTC-USD","sequence":2423271518,"time":"2018-07-27T01:32:38.448000Z"}
{"type":"done","side":"buy","order_id":"90b9a880-39b5-41a4-9027-eef83f54462c","reason":"canceled","product_id":"ETH-USD","price":"461.95000000","remaining_size":"1.21150000","sequence":4469354707,"time":"2018-07-27T01:32:38.450000Z"}
{"type":"received","order_id":"66d64b3e-cce4-44f1-9479-2a744bfeeffe","order_type":"limit","size":"4.50000000","price":"794.61000000","side":"sell","client_oid":"3e6dc29a-2731-49d0-9cf2-ea3ff7b23107","product_id":"BCH-USD","sequence":4839270867,"time":"2018-07-27T01:32:38.449000Z"}
{"type":"open","side":"sell","price":"794.61000000","order_id":"66d64b3e-cce4-44f1-9479-2a744bfeeffe","remaining_size":"4.50000000","product_id":"BCH-USD","sequence":4839270868,"time":"2018-07-27T01:32:38.449000Z"}
{"type":"received","order_id":"dcd993a1-5db3-4f94-9fd8-c0897ab49016","order_type":"limit","size":"4.50000000","price":"795.24000000","side":"sell","client_oid":"a8136920-bf05-4762-92a0-0e38b963dddd","product_id":"BCH-USD","sequence":4839270869,"time":"2018-07-27T01:32:38.452000Z"}
{"type":"open","side":"sell","price":"795.24000000","order_id":"dcd993a1-5db3-4f94-9fd8-c0897ab49016","remaining_size":"4.50000000","product_id":"BCH-USD","sequence":4839270870,"time":"2018-07-27T01:32:38.452000Z"}
{"type":"done","side":"buy","order_id":"b02d4dc9-1b4e-4df4-9571-88eb0b3c2590","reason":"canceled","product_id":"LTC-USD","price":"82.99000000","remaining_size":"20.00000000","sequence":2423271519,"time":"2018-07-27T01:32:38.455000Z"}
{"type":"received","order_id":"513b59f2-e84f-449e-98b4-65e4f1aa22a9","order_type":"limit","size":"1.90000000","price":"795.24000000","side":"sell","client_oid":"51bf6378-5479-4a23-8b2d-0405593014f3","product_id":"BCH-USD","sequence":4839270871,"time":"2018-07-27T01:32:38.454000Z"}
{"type":"open","side":"sell","price":"795.24000000","order_id":"513b59f2-e84f-449e-98b4-65e4f1aa22a9","remaining_size":"1.90000000","product_id":"BCH-USD","sequence":4839270872,"time":"2018-07-27T01:32:38.454000Z"}
{"type":"received","order_id":"9314b24a-6f89-44ec-8759-6597f4dc8753","order_type":"limit","size":"0.90000000","price":"794.64000000","side":"sell","client_oid":"ad6e2843-ecb5-4c34-abbc-ac2404ef820f","product_id":"BCH-USD","sequence":4839270873,"time":"2018-07-27T01:32:38.455000Z"}
{"type":"open","side":"sell","price":"794.64000000","order_id":"9314b24a-6f89-44ec-8759-6597f4dc8753","remaining_size":"0.90000000","product_id":"BCH-USD","sequence":4839270874,"time":"2018-07-27T01:32:38.455000Z"}
{"type":"done","side":"sell","order_id":"dcd993a1-5db3-4f94-9fd8-c0897ab49016","reason":"canceled","product_id":"BCH-USD","price":"795.24000000","remaining_size":"4.50000000","sequence":4839270875,"time":"2018-07-27T01:32:38.458000Z"}
{"type":"received","order_id":"bfadc978-6858-4698-b30f-35a957665348","order_type":"limit","size":"0.01000000","price":"486.55000000","side":"sell","client_oid":"2e16182a-e642-4e83-8000-00494bb6eaa3","product_id":"ETH-USD","sequence":4469354708,"time":"2018-07-27T01:32:38.459000Z"}
{"type":"open","side":"sell","price":"486.55000000","order_id":"bfadc978-6858-4698-b30f-35a957665348","remaining_size":"0.01000000","product_id":"ETH-USD","sequence":4469354709,"time":"2018-07-27T01:32:38.459000Z"}
{"type":"done","side":"sell","order_id":"9314b24a-6f89-44ec-8759-6597f4dc8753","reason":"canceled","product_id":"BCH-USD","price":"794.64000000","remaining_size":"0.90000000","sequence":4839270876,"time":"2018-07-27T01:32:38.461000Z"}
{"type":"done","side":"sell","order_id":"513b59f2-e84f-449e-98b4-65e4f1aa22a9","reason":"canceled","product_id":"BCH-USD","price":"795.24000000","remaining_size":"1.90000000","sequence":4839270877,"time":"2018-07-27T01:32:38.461000Z"}
{"type":"received","order_id":"b7d9c1ea-59db-4ae0-8893-75745ce41482","order_type":"limit","size":"20.00000000","price":"82.98000000","side":"buy","client_oid":"0b762d52-0a0f-4e76-b41f-545796103540","product_id":"LTC-USD","sequence":2423271520,"time":"2018-07-27T01:32:38.465000Z"}
{"type":"open","side":"buy","price":"82.98000000","order_id":"b7d9c1ea-59db-4ae0-8893-75745ce41482","remaining_size":"20.00000000","product_id":"LTC-USD","sequence":2423271521,"time":"2018-07-27T01:32:38.465000Z"}
{"type":"received","order_id":"b0119790-437a-4611-84de-7405bc90c445","order_type":"limit","size":"4.50000000","price":"795.29000000","side":"sell","client_oid":"67c8365e-8e50-45b4-b6a6-9a975f409c0e","product_id":"BCH-USD","sequence":4839270878,"time":"2018-07-27T01:32:38.465000Z"}
{"type":"open","side":"sell","price":"795.29000000","order_id":"b0119790-437a-4611-84de-7405bc90c445","remaining_size":"4.50000000","product_id":"BCH-USD","sequence":4839270879,"time":"2018-07-27T01:32:38.465000Z"}
{"type":"done","side":"sell","order_id":"41efdb1c-a05e-4b07-b3de-40511c5611b5","reason":"canceled","product_id":"BCH-USD","price":"794.61000000","remaining_size":"1.90000000","sequence":4839270880,"time":"2018-07-27T01:32:38.466000Z"}
{"type":"done","side":"sell","order_id":"66d64b3e-cce4-44f1-9479-2a744bfeeffe","reason":"canceled","product_id":"BCH-USD","price":"794.61000000","remaining_size":"4.50000000","sequence":4839270881,"time":"2018-07-27T01:32:38.468000Z"}
{"type":"received","order_id":"425851ed-f7e0-4d10-815e-ac6e312dd2ef","order_type":"limit","size":"1.90000000","price":"795.29000000","side":"sell","client_oid":"53dd1ecb-1c21-4555-a580-8b9cd75fdfa9","product_id":"BCH-USD","sequence":4839270882,"time":"2018-07-27T01:32:38.469000Z"}
{"type":"open","side":"sell","price":"795.29000000","order_id":"425851ed-f7e0-4d10-815e-ac6e312dd2ef","remaining_size":"1.90000000","product_id":"BCH-USD","sequence":4839270883,"time":"2018-07-27T01:32:38.469000Z"}
{"type":"done","side":"sell","order_id":"0422b0ca-ce57-4a60-bea9-ec6bf87800b6","reason":"canceled","product_id":"LTC-USD","price":"83.30000000","remaining_size":"7.44874862","sequence":2423271522,"time":"2018-07-27T01:32:38.475000Z"}
{"type":"received","order_id":"18cd118a-472f-4021-a3e5-92e1ef5684c9","order_type":"limit","size":"0.90000000","price":"794.60000000","side":"sell","client_oid":"4a3c4a42-6cac-4f4a-82eb-f2562b85d116","product_id":"BCH-USD","sequence":4839270884,"time":"2018-07-27T01:32:38.474000Z"}
{"type":"open","side":"sell","price":"794.60000000","order_id":"18cd118a-472f-4021-a3e5-92e1ef5684c9","remaining_size":"0.90000000","product_id":"BCH-USD","sequence":4839270885,"time":"2018-07-27T01:32:38.474000Z"}
{"type":"done","side":"buy","order_id":"684bcc6f-4573-4f0d-bcab-01d83aa069bc","reason":"canceled","product_id":"LTC-USD","price":"83.22000000","remaining_size":"20.00000000","sequence":2423271523,"time":"2018-07-27T01:32:38.480000Z"}
{"type":"done","side":"sell","order_id":"18cd118a-472f-4021-a3e5-92e1ef5684c9","reason":"canceled","product_id":"BCH-USD","price":"794.60000000","remaining_size":"0.90000000","sequence":4839270886,"time":"2018-07-27T01:32:38.480000Z"}
{"type":"received","order_id":"dc4edbcb-56fb-4232-a440-797a2fbcf716","order_type":"limit","size":"4.50000000","price":"794.60000000","side":"sell","client_oid":"ad08e37b-c542-445e-ad91-d99aa636c151","product_id":"BCH-USD","sequence":4839270887,"time":"2018-07-27T01:32:38.483000Z"}
{"type":"open","side":"sell","price":"794.60000000","order_id":"dc4edbcb-56fb-4232-a440-797a2fbcf716","remaining_size":"4.50000000","product_id":"BCH-USD","sequence":4839270888,"time":"2018-07-27T01:32:38.483000Z"}
{"type":"done","side":"buy","order_id":"b7d9c1ea-59db-4ae0-8893-75745ce41482","reason":"canceled","product_id":"LTC-USD","price":"82.98000000","remaining_size":"20.00000000","sequence":2423271524,"time":"2018-07-27T01:32:38.486000Z"}
{"type":"received","order_id":"7791c0ed-69a9-491d-8e5d-9ced0eb7124e","order_type":"limit","size":"2.00000000","price":"792.37000000","side":"buy","client_oid":"23d68753-ff9b-44bb-a627-67b9f74a4f1b","product_id":"BCH-USD","sequence":4839270889,"time":"2018-07-27T01:32:38.486000Z"}
{"type":"open","side":"buy","price":"792.37000000","order_id":"7791c0ed-69a9-491d-8e5d-9ced0eb7124e","remaining_size":"2.00000000","product_id":"BCH-USD","sequence":4839270890,"time":"2018-07-27T01:32:38.486000Z"}
{"type":"received","order_id":"07a8f2f4-e558-4b6d-902d-c776ab9a25a8","order_type":"limit","size":"1.90000000","price":"794.60000000","side":"sell","client_oid":"0230b1fa-d606-4b86-90b9-ef3aff302017","product_id":"BCH-USD","sequence":4839270891,"time":"2018-07-27T01:32:38.487000Z"}
{"type":"received","order_id":"594a0f88-0e47-41f9-ac6c-98aa2413070c","order_type":"limit","size":"1.21150000","price":"462.00000000","side":"buy","client_oid":"9489220e-d147-4704-833c-c76632947c6a","product_id":"ETH-USD","sequence":4469354710,"time":"2018-07-27T01:32:38.488000Z"}
{"type":"received","order_id":"cce14871-490b-4ed0-862f-2103c7bfed71","order_type":"limit","size":"0.10000000","price":"83.34000000","side":"sell","client_oid":"f258ef3a-913c-11e8-8d2c-16be7828d23e","product_id":"LTC-USD","sequence":2423271525,"time":"2018-07-27T01:32:38.489000Z"}
{"type":"open","side":"sell","price":"794.60000000","order_id":"07a8f2f4-e558-4b6d-902d-c776ab9a25a8","remaining_size":"1.90000000","product_id":"BCH-USD","sequence":4839270892,"time":"2018-07-27T01:32:38.487000Z"}
{"type":"open","side":"buy","price":"462.00000000","order_id":"594a0f88-0e47-41f9-ac6c-98aa2413070c","remaining_size":"1.21150000","product_id":"ETH-USD","sequence":4469354711,"time":"2018-07-27T01:32:38.488000Z"}
{"type":"done","side":"sell","order_id":"cce14871-490b-4ed0-862f-2103c7bfed71","reason":"canceled","product_id":"LTC-USD","price":"83.34000000","remaining_size":"0.10000000","sequence":2423271526,"time":"2018-07-27T01:32:38.489000Z"}
{"type":"done","side":"sell","order_id":"dc4edbcb-56fb-4232-a440-797a2fbcf716","reason":"canceled","product_id":"BCH-USD","price":"794.60000000","remaining_size":"4.50000000","sequence":4839270893,"time":"2018-07-27T01:32:38.490000Z"}
{"type":"received","order_id":"45483c8b-edb8-44ae-a21d-4496f0bd202f","order_type":"limit","size":"7.44874862","price":"83.34000000","side":"sell","client_oid":"3313cc1c-2e70-43dc-8000-00fe3e93ab9d","product_id":"LTC-USD","sequence":2423271527,"time":"2018-07-27T01:32:38.494000Z"}
{"type":"done","side":"buy","order_id":"7791c0ed-69a9-491d-8e5d-9ced0eb7124e","reason":"canceled","product_id":"BCH-USD","price":"792.37000000","remaining_size":"2.00000000","sequence":4839270894,"time":"2018-07-27T01:32:38.493000Z"}
{"type":"open","side":"sell","price":"83.34000000","order_id":"45483c8b-edb8-44ae-a21d-4496f0bd202f","remaining_size":"7.44874862","product_id":"LTC-USD","sequence":2423271528,"time":"2018-07-27T01:32:38.494000Z"}
{"type":"received","order_id":"4e864d7b-dd8c-4eb3-ad47-d9b69dda5162","order_type":"limit","size":"0.90000000","price":"794.64000000","side":"sell","client_oid":"fca1f109-841f-4ba9-91c2-054beca8f0b2","product_id":"BCH-USD","sequence":4839270895,"time":"2018-07-27T01:32:38.495000Z"}
{"type":"open","side":"sell","price":"794.64000000","order_id":"4e864d7b-dd8c-4eb3-ad47-d9b69dda5162","remaining_size":"0.90000000","product_id":"BCH-USD","sequence":4839270896,"time":"2018-07-27T01:32:38.495000Z"}
{"type":"received","order_id":"10e4227a-34f4-43a2-8451-760a15af0dfd","order_type":"limit","size":"20.00000000","price":"83.22000000","side":"buy","client_oid":"829582ca-0e1f-4daf-bf3c-3fca130e4912","product_id":"LTC-USD","sequence":2423271529,"time":"2018-07-27T01:32:38.498000Z"}
{"type":"open","side":"buy","price":"83.22000000","order_id":"10e4227a-34f4-43a2-8451-760a15af0dfd","remaining_size":"20.00000000","product_id":"LTC-USD","sequence":2423271530,"time":"2018-07-27T01:32:38.498000Z"}
{"type":"received","order_id":"55a0bfbf-f975-49f3-8644-6e3dd6c1b8cc","order_type":"limit","size":"20.00000000","price":"82.99000000","side":"buy","client_oid":"d7e70a45-9a48-4fb1-84d3-2053960324bf","product_id":"LTC-USD","sequence":2423271531,"time":"2018-07-27T01:32:38.501000Z"}
{"type":"open","side":"buy","price":"82.99000000","order_id":"55a0bfbf-f975-49f3-8644-6e3dd6c1b8cc","remaining_size":"20.00000000","product_id":"LTC-USD","sequence":2423271532,"time":"2018-07-27T01:32:38.501000Z"}
{"type":"done","side":"sell","order_id":"06c71748-ead6-4f7d-b577-2868cae78a65","reason":"canceled","product_id":"LTC-USD","price":"83.38000000","remaining_size":"7.44874862","sequence":2423271533,"time":"2018-07-27T01:32:38.505000Z"}
{"type":"received","order_id":"0e6a23a8-8db0-4bcc-adde-8be64d30d8b3","order_type":"limit","size":"0.00150000","price":"6663.24000000","side":"buy","client_oid":"75a0112b-c54c-4a02-8000-030286681240","product_id":"BTC-USD","sequence":6418130189,"time":"2018-07-27T01:32:38.506000Z"}
{"type":"open","side":"buy","price":"6663.24000000","order_id":"0e6a23a8-8db0-4bcc-adde-8be64d30d8b3","remaining_size":"0.00150000","product_id":"BTC-USD","sequence":6418130190,"time":"2018-07-27T01:32:38.506000Z"}
{"type":"received","order_id":"e4f37b1e-5fa7-4e62-bbdd-47ede618d53c","order_type":"limit","size":"4.50000000","price":"794.64000000","side":"sell","client_oid":"2e03bd0a-ff4f-4535-a755-813797a7c511","product_id":"BCH-USD","sequence":4839270897,"time":"2018-07-27T01:32:38.506000Z"}
{"type":"open","side":"sell","price":"794.64000000","order_id":"e4f37b1e-5fa7-4e62-bbdd-47ede618d53c","remaining_size":"4.50000000","product_id":"BCH-USD","sequence":4839270898,"time":"2018-07-27T01:32:38.506000Z"}
{"type":"done","side":"sell","order_id":"b0119790-437a-4611-84de-7405bc90c445","reason":"canceled","product_id":"BCH-USD","price":"795.29000000","remaining_size":"4.50000000","sequence":4839270899,"time":"2018-07-27T01:32:38.506000Z"}
{"type":"received","order_id":"e22b2ef9-63ce-42a2-baf2-ff2304399da5","order_type":"limit","size":"0.90000000","price":"794.60000000","side":"sell","client_oid":"96a88776-b64e-4443-8111-8a270ab8c46b","product_id":"BCH-USD","sequence":4839270900,"time":"2018-07-27T01:32:38.507000Z"}
{"type":"open","side":"sell","price":"794.60000000","order_id":"e22b2ef9-63ce-42a2-baf2-ff2304399da5","remaining_size":"0.90000000","product_id":"BCH-USD","sequence":4839270901,"time":"2018-07-27T01:32:38.507000Z"}
{"type":"done","side":"sell","order_id":"425851ed-f7e0-4d10-815e-ac6e312dd2ef","reason":"canceled","product_id":"BCH-USD","price":"795.29000000","remaining_size":"1.90000000","sequence":4839270902,"time":"2018-07-27T01:32:38.508000Z"}
{"type":"done","side":"sell","order_id":"07a8f2f4-e558-4b6d-902d-c776ab9a25a8","reason":"canceled","product_id":"BCH-USD","price":"794.60000000","remaining_size":"1.90000000","sequence":4839270903,"time":"2018-07-27T01:32:38.509000Z"}
{"type":"received","order_id":"898e0b3c-6b10-4e97-ad17-0ff782fad979","order_type":"limit","size":"7.44874862","price":"83.30000000","side":"sell","client_oid":"b7d7bd86-3ec5-4734-8000-002240779acf","product_id":"LTC-USD","sequence":2423271534,"time":"2018-07-27T01:32:38.514000Z"}
{"type":"done","side":"sell","order_id":"e22b2ef9-63ce-42a2-baf2-ff2304399da5","reason":"canceled","product_id":"BCH-USD","price":"794.60000000","remaining_size":"0.90000000","sequence":4839270904,"time":"2018-07-27T01:32:38.512000Z"}
{"type":"open","side":"sell","price":"83.30000000","order_id":"898e0b3c-6b10-4e97-ad17-0ff782fad979","remaining_size":"7.44874862","product_id":"LTC-USD","sequence":2423271535,"time":"2018-07-27T01:32:38.514000Z"}
{"type":"received","order_id":"ebe299a4-d0ea-49c9-82b4-e90caf5a2205","order_type":"limit","size":"4.50000000","price":"795.28000000","side":"sell","client_oid":"23febcae-7c9d-47ce-93ff-816469fdef0e","product_id":"BCH-USD","sequence":4839270905,"time":"2018-07-27T01:32:38.514000Z"}
{"type":"open","side":"sell","price":"795.28000000","order_id":"ebe299a4-d0ea-49c9-82b4-e90caf5a2205","remaining_size":"4.50000000","product_id":"BCH-USD","sequence":4839270906,"time":"2018-07-27T01:32:38.514000Z"}
{"type":"received","order_id":"7b41ce88-8b73-4095-a260-8a4500b6813b","order_type":"limit","size":"1.90000000","price":"794.64000000","side":"sell","client_oid":"77dff364-698e-4243-8fc2-a65a0c993da6","product_id":"BCH-USD","sequence":4839270907,"time":"2018-07-27T01:32:38.517000Z"}
{"type":"open","side":"sell","price":"794.64000000","order_id":"7b41ce88-8b73-4095-a260-8a4500b6813b","remaining_size":"1.90000000","product_id":"BCH-USD","sequence":4839270908,"time":"2018-07-27T01:32:38.517000Z"}
{"type":"received","order_id":"2160716e-92a4-4033-97b3-0cb9b005cbb7","order_type":"limit","size":"1.90000000","price":"795.28000000","side":"sell","client_oid":"c13b638d-580b-4d71-8ede-b2316fc5520d","product_id":"BCH-USD","sequence":4839270909,"time":"2018-07-27T01:32:38.518000Z"}
{"type":"open","side":"sell","price":"795.28000000","order_id":"2160716e-92a4-4033-97b3-0cb9b005cbb7","remaining_size":"1.90000000","product_id":"BCH-USD","sequence":4839270910,"time":"2018-07-27T01:32:38.518000Z"}
{"type":"done","side":"sell","order_id":"e4f37b1e-5fa7-4e62-bbdd-47ede618d53c","reason":"canceled","product_id":"BCH-USD","price":"794.64000000","remaining_size":"4.50000000","sequence":4839270911,"time":"2018-07-27T01:32:38.521000Z"}
{"type":"received","order_id":"f4e163e6-3247-4be6-8def-a43b5a98b474","order_type":"limit","size":"8.29703000","price":"464.31000000","side":"sell","client_oid":"090c2d60-4d51-4072-abc1-1dedc7f595b1","product_id":"ETH-USD","sequence":4469354712,"time":"2018-07-27T01:32:38.523000Z"}
{"type":"open","side":"sell","price":"464.31000000","order_id":"f4e163e6-3247-4be6-8def-a43b5a98b474","remaining_size":"8.29703000","product_id":"ETH-USD","sequence":4469354713,"time":"2018-07-27T01:32:38.523000Z"}
{"type":"received","order_id":"c3b7f996-1656-4ad8-8bc6-fa963a7c8ba3","order_type":"limit","size":"0.90000000","price":"794.59000000","side":"sell","client_oid":"577dfe4a-0086-4b7a-bcf5-983ecdb46452","product_id":"BCH-USD","sequence":4839270912,"time":"2018-07-27T01:32:38.528000Z"}
{"type":"open","side":"sell","price":"794.59000000","order_id":"c3b7f996-1656-4ad8-8bc6-fa963a7c8ba3","remaining_size":"0.90000000","product_id":"BCH-USD","sequence":4839270913,"time":"2018-07-27T01:32:38.528000Z"}
{"type":"done","side":"sell","order_id":"45483c8b-edb8-44ae-a21d-4496f0bd202f","reason":"canceled","product_id":"LTC-USD","price":"83.34000000","remaining_size":"7.44874862","sequence":2423271536,"time":"2018-07-27T01:32:38.531000Z"}
{"type":"done","side":"sell","order_id":"c3b7f996-1656-4ad8-8bc6-fa963a7c8ba3","reason":"canceled","product_id":"BCH-USD","price":"794.59000000","remaining_size":"0.90000000","sequence":4839270914,"time":"2018-07-27T01:32:38.530000Z"}
{"type":"done","side":"buy","order_id":"cb3616ce-c709-41ea-896c-7f8b16c7cdae","reason":"canceled","product_id":"LTC-USD","price":"83.05000000","remaining_size":"3.07815000","sequence":2423271537,"time":"2018-07-27T01:32:38.535000Z"}
{"type":"done","side":"buy","order_id":"8a1ea9b9-7e7e-48a7-9d85-6c698215ab94","reason":"canceled","product_id":"LTC-USD","price":"83.03000000","remaining_size":"4.69751400","sequence":2423271538,"time":"2018-07-27T01:32:38.539000Z"}
{"type":"received","order_id":"becf816b-755a-421a-a4ca-9eb0041e5f0d","order_type":"limit","size":"0.90000000","price":"794.64000000","side":"sell","client_oid":"0c946017-1eeb-4fae-8230-b354bef09ff9","product_id":"BCH-USD","sequence":4839270915,"time":"2018-07-27T01:32:38.538000Z"}
{"type":"open","side":"sell","price":"794.64000000","order_id":"becf816b-755a-421a-a4ca-9eb0041e5f0d","remaining_size":"0.90000000","product_id":"BCH-USD","sequence":4839270916,"time":"2018-07-27T01:32:38.538000Z"}
{"type":"done","side":"buy","order_id":"f5ef489b-607f-425b-a3f2-5eaf95d99c5c","reason":"canceled","product_id":"LTC-USD","price":"83.01000000","remaining_size":"7.75122000","sequence":2423271539,"time":"2018-07-27T01:32:38.542000Z"}
{"type":"received","order_id":"bea50510-4b5d-4bf2-bb8d-7fd2db2079fd","order_type":"limit","size":"7.44874862","price":"83.38000000","side":"sell","client_oid":"61f56c52-7f56-4dbc-8000-00950bf1c1d5","product_id":"LTC-USD","sequence":2423271540,"time":"2018-07-27T01:32:38.546000Z"}
{"type":"done","side":"sell","order_id":"becf816b-755a-421a-a4ca-9eb0041e5f0d","reason":"canceled","product_id":"BCH-USD","price":"794.64000000","remaining_size":"0.90000000","sequence":4839270917,"time":"2018-07-27T01:32:38.545000Z"}
{"type":"open","side":"sell","price":"83.38000000","order_id":"bea50510-4b5d-4bf2-bb8d-7fd2db2079fd","remaining_size":"7.44874862","product_id":"LTC-USD","sequence":2423271541,"time":"2018-07-27T01:32:38.546000Z"}
{"type":"done","side":"buy","order_id":"57092f7a-ce40-4f31-86c7-9e1c5724da47","reason":"canceled","product_id":"LTC-USD","price":"82.95000000","remaining_size":"21.09598200","sequence":2423271542,"time":"2018-07-27T01:32:38.547000Z"}
{"type":"done","side":"sell","order_id":"ebe299a4-d0ea-49c9-82b4-e90caf5a2205","reason":"canceled","product_id":"BCH-USD","price":"795.28000000","remaining_size":"4.50000000","sequence":4839270918,"time":"2018-07-27T01:32:38.545000Z"}
{"type":"done","side":"sell","order_id":"2160716e-92a4-4033-97b3-0cb9b005cbb7","reason":"canceled","product_id":"BCH-USD","price":"795.28000000","remaining_size":"1.90000000","sequence":4839270919,"time":"2018-07-27T01:32:38.546000Z"}
{"type":"received","order_id":"4421577a-c827-45d6-aead-05a2279770f2","order_type":"limit","size":"0.01000000","price":"461.00000000","side":"buy","product_id":"ETH-USD","sequence":4469354714,"time":"2018-07-27T01:32:38.547000Z"}
{"type":"open","side":"buy","price":"461.00000000","order_id":"4421577a-c827-45d6-aead-05a2279770f2","remaining_size":"0.01000000","product_id":"ETH-USD","sequence":4469354715,"time":"2018-07-27T01:32:38.547000Z"}
{"type":"received","order_id":"6cb44533-14dd-4f42-8e03-79187c837722","order_type":"limit","size":"3.48364000","price":"460.26000000","side":"buy","client_oid":"f72a041e-406b-46b9-81ae-d58a65a8e44b","product_id":"ETH-USD","sequence":4469354716,"time":"2018-07-27T01:32:38.549000Z"}
{"type":"open","side":"buy","price":"460.26000000","order_id":"6cb44533-14dd-4f42-8e03-79187c837722","remaining_size":"3.48364000","product_id":"ETH-USD","sequence":4469354717,"time":"2018-07-27T01:32:38.549000Z"}
{"type":"done","side":"buy","order_id":"ff406f00-8e9f-4bac-b6cc-e872b11c9349","reason":"canceled","product_id":"LTC-USD","price":"82.93000000","remaining_size":"126.99006900","sequence":2423271543,"time":"2018-07-27T01:32:38.551000Z"}
{"type":"done","side":"buy","order_id":"55a0bfbf-f975-49f3-8644-6e3dd6c1b8cc","reason":"canceled","product_id":"LTC-USD","price":"82.99000000","remaining_size":"20.00000000","sequence":2423271544,"time":"2018-07-27T01:32:38.553000Z"}
{"type":"received","order_id":"579d4131-9038-4294-9659-0a39804a11b6","order_type":"limit","size":"0.90000000","price":"794.63000000","side":"sell","client_oid":"91cbd2e8-1191-4960-acbe-cf73014ff687","product_id":"BCH-USD","sequence":4839270920,"time":"2018-07-27T01:32:38.553000Z"}
{"type":"open","side":"sell","price":"794.63000000","order_id":"579d4131-9038-4294-9659-0a39804a11b6","remaining_size":"0.90000000","product_id":"BCH-USD","sequence":4839270921,"time":"2018-07-27T01:32:38.553000Z"}
{"type":"done","side":"sell","order_id":"7b41ce88-8b73-4095-a260-8a4500b6813b","reason":"canceled","product_id":"BCH-USD","price":"794.64000000","remaining_size":"1.90000000","sequence":4839270922,"time":"2018-07-27T01:32:38.554000Z"}
{"type":"received","order_id":"92a9708f-3c28-4436-87ff-81f6d669df77","order_type":"limit","size":"4.50000000","price":"795.29000000","side":"sell","client_oid":"a5d745dc-817c-45ba-8a42-6766f8ff1663","product_id":"BCH-USD","sequence":4839270923,"time":"2018-07-27T01:32:38.555000Z"}
{"type":"done","side":"buy","order_id":"c0073a68-21c1-45f8-85c7-e75ae7bb4aa4","reason":"canceled","product_id":"LTC-USD","price":"82.91000000","remaining_size":"106.46131500","sequence":2423271545,"time":"2018-07-27T01:32:38.557000Z"}
{"type":"open","side":"sell","price":"795.29000000","order_id":"92a9708f-3c28-4436-87ff-81f6d669df77","remaining_size":"4.50000000","product_id":"BCH-USD","sequence":4839270924,"time":"2018-07-27T01:32:38.555000Z"}
{"type":"received","order_id":"3b9df3f7-c8bb-4b0d-ae4a-6a4ee42b9f55","order_type":"limit","size":"1.90000000","price":"795.29000000","side":"sell","client_oid":"94656190-d357-43c9-935b-a6a6a3c7a14c","product_id":"BCH-USD","sequence":4839270925,"time":"2018-07-27T01:32:38.559000Z"}
{"type":"open","side":"sell","price":"795.29000000","order_id":"3b9df3f7-c8bb-4b0d-ae4a-6a4ee42b9f55","remaining_size":"1.90000000","product_id":"BCH-USD","sequence":4839270926,"time":"2018-07-27T01:32:38.559000Z"}
{"type":"done","side":"sell","order_id":"37cdd726-0410-499b-a9d1-06c1351fd83a","reason":"canceled","product_id":"LTC-USD","price":"83.29000000","remaining_size":"20.10895200","sequence":2423271546,"time":"2018-07-27T01:32:38.562000Z"}
{"type":"done","side":"sell","order_id":"3b9df3f7-c8bb-4b0d-ae4a-6a4ee42b9f55","reason":"canceled","product_id":"BCH-USD","price":"795.29000000","remaining_size":"1.90000000","sequence":4839270927,"time":"2018-07-27T01:32:38.563000Z"}
{"type":"done","side":"sell","order_id":"a781feb8-5b40-4ffa-823c-9a0afc681a59","reason":"canceled","product_id":"LTC-USD","price":"83.30000000","remaining_size":"19.80943900","sequence":2423271547,"time":"2018-07-27T01:32:38.565000Z"}
{"type":"done","side":"sell","order_id":"579d4131-9038-4294-9659-0a39804a11b6","reason":"canceled","product_id":"BCH-USD","price":"794.63000000","remaining_size":"0.90000000","sequence":4839270928,"time":"2018-07-27T01:32:38.565000Z"}
{"type":"received","order_id":"921ca931-958e-4430-88ba-0a7c910b23c8","order_type":"limit","size":"1.90000000","price":"794.63000000","side":"sell","client_oid":"4a4d462b-5007-4da4-bf08-64ca513955f1","product_id":"BCH-USD","sequence":4839270929,"time":"2018-07-27T01:32:38.566000Z"}
{"type":"open","side":"sell","price":"794.63000000","order_id":"921ca931-958e-4430-88ba-0a7c910b23c8","remaining_size":"1.90000000","product_id":"BCH-USD","sequence":4839270930,"time":"2018-07-27T01:32:38.566000Z"}
{"type":"done","side":"sell","order_id":"cbf8d589-004f-491a-9736-e3aecb87d132","reason":"canceled","product_id":"LTC-USD","price":"83.32000000","remaining_size":"18.47750100","sequence":2423271548,"time":"2018-07-27T01:32:38.570000Z"}
{"type":"done","side":"sell","order_id":"921ca931-958e-4430-88ba-0a7c910b23c8","reason":"canceled","product_id":"BCH-USD","price":"794.63000000","remaining_size":"1.90000000","sequence":4839270931,"time":"2018-07-27T01:32:38.569000Z"}
{"type":"received","order_id":"09e58da7-f5cf-4594-b8b1-caf49c14fcca","order_type":"limit","size":"1.90000000","price":"795.27000000","side":"sell","client_oid":"44d37fc8-430e-4aea-a9e9-b9fde01da05b","product_id":"BCH-USD","sequence":4839270932,"time":"2018-07-27T01:32:38.571000Z"}
{"type":"done","side":"sell","order_id":"efa3e4b0-7257-4473-9a15-807afbd48a40","reason":"canceled","product_id":"LTC-USD","price":"83.34000000","remaining_size":"111.34605500","sequence":2423271549,"time":"2018-07-27T01:32:38.573000Z"}
{"type":"open","side":"sell","price":"795.27000000","order_id":"09e58da7-f5cf-4594-b8b1-caf49c14fcca","remaining_size":"1.90000000","product_id":"BCH-USD","sequence":4839270933,"time":"2018-07-27T01:32:38.571000Z"}
{"type":"done","side":"sell","order_id":"898e0b3c-6b10-4e97-ad17-0ff782fad979","reason":"canceled","product_id":"LTC-USD","price":"83.30000000","remaining_size":"7.44874862","sequence":2423271550,"time":"2018-07-27T01:32:38.575000Z"}
{"type":"received","order_id":"b82c891c-b5c4-4441-b948-9bb5d4bf7b1b","order_type":"limit","size":"0.90000000","price":"794.64000000","side":"sell","client_oid":"1e90ce49-e338-48a8-9d7c-62106c7f2ea4","product_id":"BCH-USD","sequence":4839270934,"time":"2018-07-27T01:32:38.575000Z"}
{"type":"done","side":"sell","order_id":"f61fbbfb-ba7d-48bb-a41b-96ad0eccb663","reason":"canceled","product_id":"LTC-USD","price":"83.37000000","remaining_size":"17.87971100","sequence":2423271551,"time":"2018-07-27T01:32:38.578000Z"}
{"type":"open","side":"sell","price":"794.64000000","order_id":"b82c891c-b5c4-4441-b948-9bb5d4bf7b1b","remaining_size":"0.90000000","product_id":"BCH-USD","sequence":4839270935,"time":"2018-07-27T01:32:38.575000Z"}
{"type":"done","side":"sell","order_id":"09e58da7-f5cf-4594-b8b1-caf49c14fcca","reason":"canceled","product_id":"BCH-USD","price":"795.27000000","remaining_size":"1.90000000","sequence":4839270936,"time":"2018-07-27T01:32:38.577000Z"}
{"type":"received","order_id":"f3020d28-92c1-4e47-baa9-5890fc8e3048","order_type":"limit","size":"1.90000000","price":"794.64000000","side":"sell","client_oid":"066764e1-b2f9-483d-b879-bd0610a22485","product_id":"BCH-USD","sequence":4839270937,"time":"2018-07-27T01:32:38.577000Z"}
{"type":"open","side":"sell","price":"794.64000000","order_id":"f3020d28-92c1-4e47-baa9-5890fc8e3048","remaining_size":"1.90000000","product_id":"BCH-USD","sequence":4839270938,"time":"2018-07-27T01:32:38.577000Z"}
{"type":"done","side":"sell","order_id":"0013304d-29ad-4f90-85f6-fb57fe1726c8","reason":"canceled","product_id":"BCH-USD","price":"794.72000000","remaining_size":"4.11700000","sequence":4839270939,"time":"2018-07-27T01:32:38.580000Z"}
{"type":"received","order_id":"8933bd65-5d5f-40bc-ab12-d1c5da6536cc","order_type":"limit","size":"1.90000000","price":"795.29000000","side":"sell","client_oid":"5ea3503b-60c0-4973-ae6d-05ec49698673","product_id":"BCH-USD","sequence":4839270940,"time":"2018-07-27T01:32:38.585000Z"}
{"type":"open","side":"sell","price":"795.29000000","order_id":"8933bd65-5d5f-40bc-ab12-d1c5da6536cc","remaining_size":"1.90000000","product_id":"BCH-USD","sequence":4839270941,"time":"2018-07-27T01:32:38.585000Z"}
{"type":"received","order_id":"f07563d4-ce76-4ad7-97db-516da60c45dd","order_type":"limit","size":"7.44874862","price":"83.34000000","side":"sell","client_oid":"14807450-238d-4235-8000-00317f4d0d53","product_id":"LTC-USD","sequence":2423271552,"time":"2018-07-27T01:32:38.588000Z"}
{"type":"open","side":"sell","price":"83.34000000","order_id":"f07563d4-ce76-4ad7-97db-516da60c45dd","remaining_size":"7.44874862","product_id":"LTC-USD","sequence":2423271553,"time":"2018-07-27T01:32:38.588000Z"}
{"type":"done","side":"sell","order_id":"f3020d28-92c1-4e47-baa9-5890fc8e3048","reason":"canceled","product_id":"BCH-USD","price":"794.64000000","remaining_size":"1.90000000","sequence":4839270942,"time":"2018-07-27T01:32:38.587000Z"}
{"type":"done","side":"sell","order_id":"4e864d7b-dd8c-4eb3-ad47-d9b69dda5162","reason":"canceled","product_id":"BCH-USD","price":"794.64000000","remaining_size":"0.90000000","sequence":4839270943,"time":"2018-07-27T01:32:38.589000Z"}
{"type":"done","side":"sell","order_id":"92a9708f-3c28-4436-87ff-81f6d669df77","reason":"canceled","product_id":"BCH-USD","price":"795.29000000","remaining_size":"4.50000000","sequence":4839270944,"time":"2018-07-27T01:32:38.591000Z"}
{"type":"done","side":"buy","order_id":"4c2d4d0d-6273-4480-a0f2-1d78b14f050c","reason":"canceled","product_id":"ETH-USD","price":"439.00000000","remaining_size":"0.01000000","sequence":4469354718,"time":"2018-07-27T01:32:38.597000Z"}
{"type":"done","side":"sell","order_id":"8933bd65-5d5f-40bc-ab12-d1c5da6536cc","reason":"canceled","product_id":"BCH-USD","price":"795.29000000","remaining_size":"1.90000000","sequence":4839270945,"time":"2018-07-27T01:32:38.596000Z"}
{"type":"received","order_id":"ede2a9c0-5cbc-4371-9024-232cab3bbb54","order_type":"limit","size":"4.50000000","price":"795.28000000","side":"sell","client_oid":"6311263c-0f00-4982-a25b-e8e3ea6959c7","product_id":"BCH-USD","sequence":4839270946,"time":"2018-07-27T01:32:38.600000Z"}
{"type":"open","side":"sell","price":"795.28000000","order_id":"ede2a9c0-5cbc-4371-9024-232cab3bbb54","remaining_size":"4.50000000","product_id":"BCH-USD","sequence":4839270947,"time":"2018-07-27T01:32:38.600000Z"}
{"type":"received","order_id":"ac344194-bf2e-4e7e-aeda-406894da3914","order_type":"limit","size":"20.00000000","price":"82.98000000","side":"buy","client_oid":"ba119ba5-0c81-458c-8f53-984e3939700c","product_id":"LTC-USD","sequence":2423271554,"time":"2018-07-27T01:32:38.604000Z"}
{"type":"received","order_id":"9227fb2d-68d1-4ae3-8ebd-d41b86e1390a","order_type":"limit","size":"6.21300000","price":"795.88000000","side":"sell","client_oid":"3fa2b30b-b476-3292-af62-09673693f812","product_id":"BCH-USD","sequence":4839270948,"time":"2018-07-27T01:32:38.602000Z"}
{"type":"open","side":"sell","price":"795.88000000","order_id":"9227fb2d-68d1-4ae3-8ebd-d41b86e1390a","remaining_size":"6.21300000","product_id":"BCH-USD","sequence":4839270949,"time":"2018-07-27T01:32:38.602000Z"}
{"type":"open","side":"buy","price":"82.98000000","order_id":"ac344194-bf2e-4e7e-aeda-406894da3914","remaining_size":"20.00000000","product_id":"LTC-USD","sequence":2423271555,"time":"2018-07-27T01:32:38.604000Z"}
{"type":"received","order_id":"5a27a07b-b40f-4020-87f4-f198c74820e5","order_type":"limit","size":"1.90000000","price":"795.28000000","side":"sell","client_oid":"e40619c3-0662-447b-a07c-37fa1473aa27","product_id":"BCH-USD","sequence":4839270950,"time":"2018-07-27T01:32:38.603000Z"}
{"type":"open","side":"sell","price":"795.28000000","order_id":"5a27a07b-b40f-4020-87f4-f198c74820e5","remaining_size":"1.90000000","product_id":"BCH-USD","sequence":4839270951,"time":"2018-07-27T01:32:38.603000Z"}
{"type":"done","side":"sell","order_id":"ede2a9c0-5cbc-4371-9024-232cab3bbb54","reason":"canceled","product_id":"BCH-USD","price":"795.28000000","remaining_size":"4.50000000","sequence":4839270952,"time":"2018-07-27T01:32:38.605000Z"}
{"type":"received","order_id":"e9801be0-e7f7-4894-96ef-a24f510d2f1a","order_type":"limit","size":"4.50000000","price":"794.63000000","side":"sell","client_oid":"9047c18e-b9bd-46cb-93a5-f31ed4e25005","product_id":"BCH-USD","sequence":4839270953,"time":"2018-07-27T01:32:38.606000Z"}
{"type":"open","side":"sell","price":"794.63000000","order_id":"e9801be0-e7f7-4894-96ef-a24f510d2f1a","remaining_size":"4.50000000","product_id":"BCH-USD","sequence":4839270954,"time":"2018-07-27T01:32:38.606000Z"}
{"type":"done","side":"sell","order_id":"5a27a07b-b40f-4020-87f4-f198c74820e5","reason":"canceled","product_id":"BCH-USD","price":"795.28000000","remaining_size":"1.90000000","sequence":4839270955,"time":"2018-07-27T01:32:38.607000Z"}
{"type":"done","side":"sell","order_id":"bea50510-4b5d-4bf2-bb8d-7fd2db2079fd","reason":"canceled","product_id":"LTC-USD","price":"83.38000000","remaining_size":"7.44874862","sequence":2423271556,"time":"2018-07-27T01:32:38.610000Z"}
{"type":"received","order_id":"b54757fc-a5c0-4e86-a456-080538d13e47","order_type":"limit","size":"1.90000000","price":"794.63000000","side":"sell","client_oid":"5dfee21a-273a-40f0-9d2f-e328e243d0aa","product_id":"BCH-USD","sequence":4839270956,"time":"2018-07-27T01:32:38.608000Z"}
{"type":"open","side":"sell","price":"794.63000000","order_id":"b54757fc-a5c0-4e86-a456-080538d13e47","remaining_size":"1.90000000","product_id":"BCH-USD","sequence":4839270957,"time":"2018-07-27T01:32:38.608000Z"}
{"type":"received","order_id":"125b4090-c46f-4dfd-ac1e-fb74f385e033","order_type":"limit","size":"3.04869500","price":"83.05000000","side":"buy","client_oid":"421311f8-7606-47a9-8753-1e1e1e68e214","product_id":"LTC-USD","sequence":2423271557,"time":"2018-07-27T01:32:38.611000Z"}
{"type":"received","order_id":"381bd592-37fd-41df-ae8f-48bdab43b222","order_type":"limit","size":"0.90000000","price":"794.59000000","side":"sell","client_oid":"916df9a2-f506-4aa6-995a-310d66a2b7ce","product_id":"BCH-USD","sequence":4839270958,"time":"2018-07-27T01:32:38.609000Z"}
{"type":"open","side":"buy","price":"83.05000000","order_id":"125b4090-c46f-4dfd-ac1e-fb74f385e033","remaining_size":"3.04869500","product_id":"LTC-USD","sequence":2423271558,"time":"2018-07-27T01:32:38.611000Z"}
{"type":"open","side":"sell","price":"794.59000000","order_id":"381bd592-37fd-41df-ae8f-48bdab43b222","remaining_size":"0.90000000","product_id":"BCH-USD","sequence":4839270959,"time":"2018-07-27T01:32:38.609000Z"}
{"type":"received","order_id":"6b13efb3-33a5-46a1-aca8-d18b3b94c2e7","order_type":"limit","size":"0.12000000","price":"441.20000000","side":"buy","product_id":"ETH-USD","sequence":4469354719,"time":"2018-07-27T01:32:38.612000Z"}
{"type":"open","side":"buy","price":"441.20000000","order_id":"6b13efb3-33a5-46a1-aca8-d18b3b94c2e7","remaining_size":"0.12000000","product_id":"ETH-USD","sequence":4469354720,"time":"2018-07-27T01:32:38.612000Z"}
{"type":"done","side":"sell","order_id":"e9801be0-e7f7-4894-96ef-a24f510d2f1a","reason":"canceled","product_id":"BCH-USD","price":"794.63000000","remaining_size":"4.50000000","sequence":4839270960,"time":"2018-07-27T01:32:38.612000Z"}
{"type":"received","order_id":"64e262bb-dd1a-4af2-b91a-1724411045a6","order_type":"limit","size":"4.50000000","price":"795.26000000","side":"sell","client_oid":"34fccc64-6b19-4548-961c-47f95f26e461","product_id":"BCH-USD","sequence":4839270961,"time":"2018-07-27T01:32:38.613000Z"}
{"type":"open","side":"sell","price":"795.26000000","order_id":"64e262bb-dd1a-4af2-b91a-1724411045a6","remaining_size":"4.50000000","product_id":"BCH-USD","sequence":4839270962,"time":"2018-07-27T01:32:38.613000Z"}
{"type":"done","side":"sell","order_id":"b82c891c-b5c4-4441-b948-9bb5d4bf7b1b","reason":"canceled","product_id":"BCH-USD","price":"794.64000000","remaining_size":"0.90000000","sequence":4839270963,"time":"2018-07-27T01:32:38.613000Z"}
{"type":"received","order_id":"48edfd40-9132-41f5-9e0b-0abc3b722193","order_type":"limit","size":"1.90000000","price":"795.26000000","side":"sell","client_oid":"d55da359-828c-41cb-8979-24fbbeb3254f","product_id":"BCH-USD","sequence":4839270964,"time":"2018-07-27T01:32:38.615000Z"}
{"type":"open","side":"sell","price":"795.26000000","order_id":"48edfd40-9132-41f5-9e0b-0abc3b722193","remaining_size":"1.90000000","product_id":"BCH-USD","sequence":4839270965,"time":"2018-07-27T01:32:38.615000Z"}
{"type":"done","side":"sell","order_id":"64e262bb-dd1a-4af2-b91a-1724411045a6","reason":"canceled","product_id":"BCH-USD","price":"795.26000000","remaining_size":"4.50000000","sequence":4839270966,"time":"2018-07-27T01:32:38.616000Z"}
{"type":"done","side":"buy","order_id":"ac344194-bf2e-4e7e-aeda-406894da3914","reason":"canceled","product_id":"LTC-USD","price":"82.98000000","remaining_size":"20.00000000","sequence":2423271559,"time":"2018-07-27T01:32:38.619000Z"}
{"type":"done","side":"sell","order_id":"381bd592-37fd-41df-ae8f-48bdab43b222","reason":"canceled","product_id":"BCH-USD","price":"794.59000000","remaining_size":"0.90000000","sequence":4839270967,"time":"2018-07-27T01:32:38.618000Z"}
{"type":"done","side":"sell","order_id":"48edfd40-9132-41f5-9e0b-0abc3b722193","reason":"canceled","product_id":"BCH-USD","price":"795.26000000","remaining_size":"1.90000000","sequence":4839270968,"time":"2018-07-27T01:32:38.619000Z"}
{"type":"done","side":"sell","order_id":"b54757fc-a5c0-4e86-a456-080538d13e47","reason":"canceled","product_id":"BCH-USD","price":"794.63000000","remaining_size":"1.90000000","sequence":4839270969,"time":"2018-07-27T01:32:38.620000Z"}
{"type":"received","order_id":"878ff427-8472-4103-8ff6-cdb353efa7d3","order_type":"limit","size":"4.50000000","price":"794.64000000","side":"sell","client_oid":"5cafac43-ef0a-412a-9b0b-3ae37b895c59","product_id":"BCH-USD","sequence":4839270970,"time":"2018-07-27T01:32:38.622000Z"}
{"type":"open","side":"sell","price":"794.64000000","order_id":"878ff427-8472-4103-8ff6-cdb353efa7d3","remaining_size":"4.50000000","product_id":"BCH-USD","sequence":4839270971,"time":"2018-07-27T01:32:38.622000Z"}
{"type":"received","order_id":"de5a0c83-217c-4a92-a57f-96dd5fb60da8","order_type":"limit","size":"2.00000000","price":"792.37000000","side":"buy","client_oid":"c34f1d8a-23b6-4e16-bdc3-ce010c4b7fdf","product_id":"BCH-USD","sequence":4839270972,"time":"2018-07-27T01:32:38.623000Z"}
{"type":"open","side":"buy","price":"792.37000000","order_id":"de5a0c83-217c-4a92-a57f-96dd5fb60da8","remaining_size":"2.00000000","product_id":"BCH-USD","sequence":4839270973,"time":"2018-07-27T01:32:38.623000Z"}
{"type":"received","order_id":"70b0e358-4e53-458e-af97-8fd678db5a65","order_type":"limit","size":"4.56965600","price":"83.03000000","side":"buy","client_oid":"8c9c6995-1976-4f15-8173-6a82b7114ddc","product_id":"LTC-USD","sequence":2423271560,"time":"2018-07-27T01:32:38.625000Z"}
{"type":"open","side":"buy","price":"83.03000000","order_id":"70b0e358-4e53-458e-af97-8fd678db5a65","remaining_size":"4.56965600","product_id":"LTC-USD","sequence":2423271561,"time":"2018-07-27T01:32:38.625000Z"}
{"type":"received","order_id":"cabbb100-a22c-4937-a519-5f99b80f3ab6","order_type":"limit","size":"1.90000000","price":"794.64000000","side":"sell","client_oid":"9ce8be3d-c776-4bdd-8593-f50ccb3d7b7b","product_id":"BCH-USD","sequence":4839270974,"time":"2018-07-27T01:32:38.625000Z"}
{"type":"received","order_id":"0be8fa97-7634-4a8e-bbc4-4d1489f96f13","order_type":"limit","size":"7.44874862","price":"83.30000000","side":"sell","client_oid":"3c645940-c540-404e-8000-00d023937ed5","product_id":"LTC-USD","sequence":2423271562,"time":"2018-07-27T01:32:38.627000Z"}
{"type":"open","side":"sell","price":"83.30000000","order_id":"0be8fa97-7634-4a8e-bbc4-4d1489f96f13","remaining_size":"7.44874862","product_id":"LTC-USD","sequence":2423271563,"time":"2018-07-27T01:32:38.627000Z"}
{"type":"open","side":"sell","price":"794.64000000","order_id":"cabbb100-a22c-4937-a519-5f99b80f3ab6","remaining_size":"1.90000000","product_id":"BCH-USD","sequence":4839270975,"time":"2018-07-27T01:32:38.625000Z"}
{"type":"received","order_id":"787683ed-0bf1-4ce7-8b97-599fff7612fa","order_type":"limit","size":"0.90000000","price":"794.63000000","side":"sell","client_oid":"b7627aad-3296-4a95-94ac-c544d2b82136","product_id":"BCH-USD","sequence":4839270976,"time":"2018-07-27T01:32:38.626000Z"}
{"type":"received","order_id":"46ea32b2-1fe9-42c8-b585-4e998363ec5c","order_type":"limit","size":"20.00000000","price":"82.99000000","side":"buy","client_oid":"5c1e65f2-5cb5-46d3-bb39-472752d6843a","product_id":"LTC-USD","sequence":2423271564,"time":"2018-07-27T01:32:38.628000Z"}
{"type":"open","side":"sell","price":"794.63000000","order_id":"787683ed-0bf1-4ce7-8b97-599fff7612fa","remaining_size":"0.90000000","product_id":"BCH-USD","sequence":4839270977,"time":"2018-07-27T01:32:38.626000Z"}
{"type":"open","side":"buy","price":"82.99000000","order_id":"46ea32b2-1fe9-42c8-b585-4e998363ec5c","remaining_size":"20.00000000","product_id":"LTC-USD","sequence":2423271565,"time":"2018-07-27T01:32:38.628000Z"}
{"type":"done","side":"sell","order_id":"878ff427-8472-4103-8ff6-cdb353efa7d3","reason":"canceled","product_id":"BCH-USD","price":"794.64000000","remaining_size":"4.50000000","sequence":4839270978,"time":"2018-07-27T01:32:38.629000Z"}
{"type":"received","order_id":"00e94ce3-5a63-465e-ab6d-49c82c419a61","order_type":"limit","size":"4.50000000","price":"795.29000000","side":"sell","client_oid":"1b7ea1fb-1686-4ca1-97f0-0168c88c72db","product_id":"BCH-USD","sequence":4839270979,"time":"2018-07-27T01:32:38.632000Z"}
{"type":"open","side":"sell","price":"795.29000000","order_id":"00e94ce3-5a63-465e-ab6d-49c82c419a61","remaining_size":"4.50000000","product_id":"BCH-USD","sequence":4839270980,"time":"2018-07-27T01:32:38.632000Z"}
{"type":"received","order_id":"1074220f-2709-413b-ab14-0b4fa1b75623","order_type":"limit","size":"1.90000000","price":"795.29000000","side":"sell","client_oid":"cbbfd062-7079-4820-9498-2bd13d8d2e53","product_id":"BCH-USD","sequence":4839270981,"time":"2018-07-27T01:32:38.634000Z"}
{"type":"received","order_id":"9bd98e4b-444e-4768-8d2d-c23347678907","order_type":"limit","size":"9.38632400","price":"83.01000000","side":"buy","client_oid":"0cd134ca-a216-42df-b627-35b75d54c9e1","product_id":"LTC-USD","sequence":2423271566,"time":"2018-07-27T01:32:38.636000Z"}
{"type":"open","side":"sell","price":"795.29000000","order_id":"1074220f-2709-413b-ab14-0b4fa1b75623","remaining_size":"1.90000000","product_id":"BCH-USD","sequence":4839270982,"time":"2018-07-27T01:32:38.634000Z"}
{"type":"received","order_id":"76fcf4b2-d04c-4ddd-84cb-7d263c43be84","order_type":"limit","size":"0.90000000","price":"794.62000000","side":"sell","client_oid":"6d8c142f-cf0c-4990-8692-0f774ded4a4c","product_id":"BCH-USD","sequence":4839270983,"time":"2018-07-27T01:32:38.635000Z"}
{"type":"open","side":"buy","price":"83.01000000","order_id":"9bd98e4b-444e-4768-8d2d-c23347678907","remaining_size":"9.38632400","product_id":"LTC-USD","sequence":2423271567,"time":"2018-07-27T01:32:38.636000Z"}
{"type":"open","side":"sell","price":"794.62000000","order_id":"76fcf4b2-d04c-4ddd-84cb-7d263c43be84","remaining_size":"0.90000000","product_id":"BCH-USD","sequence":4839270984,"time":"2018-07-27T01:32:38.635000Z"}
{"type":"received","order_id":"08d349ec-377f-4208-844b-eb303cbcfefc","order_type":"limit","size":"4.50000000","price":"794.63000000","side":"sell","client_oid":"5a5065e7-2f9f-407a-afcb-c93369a254b3","product_id":"BCH-USD","sequence":4839270985,"time":"2018-07-27T01:32:38.642000Z"}
{"type":"open","side":"sell","price":"794.63000000","order_id":"08d349ec-377f-4208-844b-eb303cbcfefc","remaining_size":"4.50000000","product_id":"BCH-USD","sequence":4839270986,"time":"2018-07-27T01:32:38.642000Z"}
{"type":"done","side":"buy","order_id":"10e4227a-34f4-43a2-8451-760a15af0dfd","reason":"canceled","product_id":"LTC-USD","price":"83.22000000","remaining_size":"20.00000000","sequence":2423271568,"time":"2018-07-27T01:32:38.646000Z"}
{"type":"received","order_id":"b01c4e2d-d6d3-4383-b6c9-60725de8cb9a","order_type":"limit","size":"27.41547700","price":"82.95000000","side":"buy","client_oid":"45632e51-032b-4940-b6c5-d434b2465f34","product_id":"LTC-USD","sequence":2423271569,"time":"2018-07-27T01:32:38.647000Z"}
{"type":"open","side":"buy","price":"82.95000000","order_id":"b01c4e2d-d6d3-4383-b6c9-60725de8cb9a","remaining_size":"27.41547700","product_id":"LTC-USD","sequence":2423271570,"time":"2018-07-27T01:32:38.647000Z"}
{"type":"done","side":"buy","order_id":"de5a0c83-217c-4a92-a57f-96dd5fb60da8","reason":"canceled","product_id":"BCH-USD","price":"792.37000000","remaining_size":"2.00000000","sequence":4839270987,"time":"2018-07-27T01:32:38.645000Z"}
{"type":"done","side":"sell","order_id":"f07563d4-ce76-4ad7-97db-516da60c45dd","reason":"canceled","product_id":"LTC-USD","price":"83.34000000","remaining_size":"7.44874862","sequence":2423271571,"time":"2018-07-27T01:32:38.650000Z"}
{"type":"done","side":"sell","order_id":"08d349ec-377f-4208-844b-eb303cbcfefc","reason":"canceled","product_id":"BCH-USD","price":"794.63000000","remaining_size":"4.50000000","sequence":4839270988,"time":"2018-07-27T01:32:38.653000Z"}
{"type":"done","side":"sell","order_id":"cabbb100-a22c-4937-a519-5f99b80f3ab6","reason":"canceled","product_id":"BCH-USD","price":"794.64000000","remaining_size":"1.90000000","sequence":4839270989,"time":"2018-07-27T01:32:38.655000Z"}
{"type":"done","side":"sell","order_id":"00e94ce3-5a63-465e-ab6d-49c82c419a61","reason":"canceled","product_id":"BCH-USD","price":"795.29000000","remaining_size":"4.50000000","sequence":4839270990,"time":"2018-07-27T01:32:38.656000Z"}
{"type":"done","side":"sell","order_id":"787683ed-0bf1-4ce7-8b97-599fff7612fa","reason":"canceled","product_id":"BCH-USD","price":"794.63000000","remaining_size":"0.90000000","sequence":4839270991,"time":"2018-07-27T01:32:38.657000Z"}
{"type":"done","side":"sell","order_id":"1074220f-2709-413b-ab14-0b4fa1b75623","reason":"canceled","product_id":"BCH-USD","price":"795.29000000","remaining_size":"1.90000000","sequence":4839270992,"time":"2018-07-27T01:32:38.658000Z"}
{"type":"received","order_id":"c7d1a752-12c9-4896-89e8-49c2717d211d","order_type":"limit","size":"120.20633300","price":"82.93000000","side":"buy","client_oid":"245fe56e-c727-4dd9-a56a-7db3e235991b","product_id":"LTC-USD","sequence":2423271572,"time":"2018-07-27T01:32:38.661000Z"}
{"type":"open","side":"buy","price":"82.93000000","order_id":"c7d1a752-12c9-4896-89e8-49c2717d211d","remaining_size":"120.20633300","product_id":"LTC-USD","sequence":2423271573,"time":"2018-07-27T01:32:38.661000Z"}
{"type":"received","order_id":"2cc18c58-8e6b-45cb-b06c-32a710daff13","order_type":"limit","size":"4.50000000","price":"794.62000000","side":"sell","client_oid":"0889e640-c36c-424e-b5d0-ce41e90119d4","product_id":"BCH-USD","sequence":4839270993,"time":"2018-07-27T01:32:38.661000Z"}
{"type":"open","side":"sell","price":"794.62000000","order_id":"2cc18c58-8e6b-45cb-b06c-32a710daff13","remaining_size":"4.50000000","product_id":"BCH-USD","sequence":4839270994,"time":"2018-07-27T01:32:38.661000Z"}
{"type":"received","order_id":"9b33b019-bc65-44e3-80fb-835815d6c774","order_type":"limit","size":"1.90000000","price":"795.28000000","side":"sell","client_oid":"ba9b6fb7-b9c3-4290-b34c-fc00488522d2","product_id":"BCH-USD","sequence":4839270995,"time":"2018-07-27T01:32:38.663000Z"}
{"type":"open","side":"sell","price":"795.28000000","order_id":"9b33b019-bc65-44e3-80fb-835815d6c774","remaining_size":"1.90000000","product_id":"BCH-USD","sequence":4839270996,"time":"2018-07-27T01:32:38.663000Z"}
{"type":"done","side":"sell","order_id":"76fcf4b2-d04c-4ddd-84cb-7d263c43be84","reason":"canceled","product_id":"BCH-USD","price":"794.62000000","remaining_size":"0.90000000","sequence":4839270997,"time":"2018-07-27T01:32:38.663000Z"}
{"type":"received","order_id":"f8883cc9-2111-4ce3-b3e2-51e5400e646a","order_type":"limit","size":"7.44874862","price":"83.38000000","side":"sell","client_oid":"9761759f-2cee-4c6a-8000-002d074d006c","product_id":"LTC-USD","sequence":2423271574,"time":"2018-07-27T01:32:38.666000Z"}
{"type":"open","side":"sell","price":"83.38000000","order_id":"f8883cc9-2111-4ce3-b3e2-51e5400e646a","remaining_size":"7.44874862","product_id":"LTC-USD","sequence":2423271575,"time":"2018-07-27T01:32:38.666000Z"}
{"type":"received","order_id":"04025a3e-bb30-4668-a29e-d1960dd833d8","order_type":"limit","size":"1.90000000","price":"794.62000000","side":"sell","client_oid":"d44840d8-8661-4637-a5c5-bf8644643473","product_id":"BCH-USD","sequence":4839270998,"time":"2018-07-27T01:32:38.666000Z"}
{"type":"open","side":"sell","price":"794.62000000","order_id":"04025a3e-bb30-4668-a29e-d1960dd833d8","remaining_size":"1.90000000","product_id":"BCH-USD","sequence":4839270999,"time":"2018-07-27T01:32:38.666000Z"}
{"type":"received","order_id":"ab4c15f4-54be-45aa-887a-758ca0a489e8","order_type":"limit","size":"0.90000000","price":"794.64000000","side":"sell","client_oid":"cded2183-9006-40fc-a5d1-4e8c12af031e","product_id":"BCH-USD","sequence":4839271000,"time":"2018-07-27T01:32:38.667000Z"}
{"type":"open","side":"sell","price":"794.64000000","order_id":"ab4c15f4-54be-45aa-887a-758ca0a489e8","remaining_size":"0.90000000","product_id":"BCH-USD","sequence":4839271001,"time":"2018-07-27T01:32:38.667000Z"}
{"type":"received","order_id":"e374479a-9703-44e8-9e49-c15b5e087011","order_type":"limit","size":"4.50000000","price":"795.28000000","side":"sell","client_oid":"601a0292-4505-4e26-a100-6a1f97511be9","product_id":"BCH-USD","sequence":4839271002,"time":"2018-07-27T01:32:38.669000Z"}
{"type":"open","side":"sell","price":"795.28000000","order_id":"e374479a-9703-44e8-9e49-c15b5e087011","remaining_size":"4.50000000","product_id":"BCH-USD","sequence":4839271003,"time":"2018-07-27T01:32:38.669000Z"}
{"type":"done","side":"sell","order_id":"ab4c15f4-54be-45aa-887a-758ca0a489e8","reason":"canceled","product_id":"BCH-USD","price":"794.64000000","remaining_size":"0.90000000","sequence":4839271004,"time":"2018-07-27T01:32:38.672000Z"}
{"type":"done","side":"sell","order_id":"04025a3e-bb30-4668-a29e-d1960dd833d8","reason":"canceled","product_id":"BCH-USD","price":"794.62000000","remaining_size":"1.90000000","sequence":4839271005,"time":"2018-07-27T01:32:38.672000Z"}
{"type":"received","order_id":"d2defc07-2bcd-4a60-84ff-6ba02fd6a431","order_type":"limit","size":"0.90000000","price":"794.63000000","side":"sell","client_oid":"c83ea8c7-a999-4b8f-8b6e-aa6767d4ab2a","product_id":"BCH-USD","sequence":4839271006,"time":"2018-07-27T01:32:38.674000Z"}
{"type":"received","order_id":"a0d0a0cb-793e-4e8e-a48b-d3b6fb112cbd","order_type":"limit","size":"105.44461500","price":"82.91000000","side":"buy","client_oid":"f1167837-9fc0-41a7-a19a-f1bbd5bce0b9","product_id":"LTC-USD","sequence":2423271576,"time":"2018-07-27T01:32:38.676000Z"}
{"type":"open","side":"sell","price":"794.63000000","order_id":"d2defc07-2bcd-4a60-84ff-6ba02fd6a431","remaining_size":"0.90000000","product_id":"BCH-USD","sequence":4839271007,"time":"2018-07-27T01:32:38.674000Z"}
{"type":"open","side":"buy","price":"82.91000000","order_id":"a0d0a0cb-793e-4e8e-a48b-d3b6fb112cbd","remaining_size":"105.44461500","product_id":"LTC-USD","sequence":2423271577,"time":"2018-07-27T01:32:38.676000Z"}
{"type":"done","side":"sell","order_id":"9b33b019-bc65-44e3-80fb-835815d6c774","reason":"canceled","product_id":"BCH-USD","price":"795.28000000","remaining_size":"1.90000000","sequence":4839271008,"time":"2018-07-27T01:32:38.676000Z"}
{"type":"done","side":"sell","order_id":"0be8fa97-7634-4a8e-bbc4-4d1489f96f13","reason":"canceled","product_id":"LTC-USD","price":"83.30000000","remaining_size":"7.44874862","sequence":2423271578,"time":"2018-07-27T01:32:38.680000Z"}
{"type":"received","order_id":"e54532b8-07de-4a67-9b3d-d9671e975736","order_type":"limit","size":"1.90000000","price":"794.64000000","side":"sell","client_oid":"c054e4f6-fe2a-4c73-9cc9-2ecd216a8f18","product_id":"BCH-USD","sequence":4839271009,"time":"2018-07-27T01:32:38.680000Z"}
{"type":"open","side":"sell","price":"794.64000000","order_id":"e54532b8-07de-4a67-9b3d-d9671e975736","remaining_size":"1.90000000","product_id":"BCH-USD","sequence":4839271010,"time":"2018-07-27T01:32:38.680000Z"}
{"type":"received","order_id":"1184f6b7-9493-49d0-b091-a673f49fddd8","order_type":"limit","size":"0.90000000","price":"794.62000000","side":"sell","client_oid":"266276b7-01c5-4405-bedd-3876860c97b2","product_id":"BCH-USD","sequence":4839271011,"time":"2018-07-27T01:32:38.682000Z"}
{"type":"open","side":"sell","price":"794.62000000","order_id":"1184f6b7-9493-49d0-b091-a673f49fddd8","remaining_size":"0.90000000","product_id":"BCH-USD","sequence":4839271012,"time":"2018-07-27T01:32:38.683000Z"}
{"type":"done","side":"sell","order_id":"e54532b8-07de-4a67-9b3d-d9671e975736","reason":"canceled","product_id":"BCH-USD","price":"794.64000000","remaining_size":"1.90000000","sequence":4839271013,"time":"2018-07-27T01:32:38.685000Z"}
{"type":"done","side":"sell","order_id":"1184f6b7-9493-49d0-b091-a673f49fddd8","reason":"canceled","product_id":"BCH-USD","price":"794.62000000","remaining_size":"0.90000000","sequence":4839271014,"time":"2018-07-27T01:32:38.685000Z"}
{"type":"received","order_id":"08c0a027-0437-46d0-a4ec-c69992029ac6","order_type":"limit","size":"21.22678200","price":"83.29000000","side":"sell","client_oid":"bd9e025f-120f-491d-a40c-3fb7cc19e1e4","product_id":"LTC-USD","sequence":2423271579,"time":"2018-07-27T01:32:38.689000Z"}
{"type":"open","side":"sell","price":"83.29000000","order_id":"08c0a027-0437-46d0-a4ec-c69992029ac6","remaining_size":"21.22678200","product_id":"LTC-USD","sequence":2423271580,"time":"2018-07-27T01:32:38.689000Z"}
{"type":"received","order_id":"53c74660-c31e-41b7-9a0f-41536dbe141d","order_type":"limit","size":"1.90000000","price":"795.29000000","side":"sell","client_oid":"dca19af2-20d6-498e-8064-6c1ddf3248a7","product_id":"BCH-USD","sequence":4839271015,"time":"2018-07-27T01:32:38.689000Z"}
{"type":"open","side":"sell","price":"795.29000000","order_id":"53c74660-c31e-41b7-9a0f-41536dbe141d","remaining_size":"1.90000000","product_id":"BCH-USD","sequence":4839271016,"time":"2018-07-27T01:32:38.689000Z"}
{"type":"done","side":"sell","order_id":"2cc18c58-8e6b-45cb-b06c-32a710daff13","reason":"canceled","product_id":"BCH-USD","price":"794.62000000","remaining_size":"4.50000000","sequence":4839271017,"time":"2018-07-27T01:32:38.692000Z"}
{"type":"done","side":"sell","order_id":"53c74660-c31e-41b7-9a0f-41536dbe141d","reason":"canceled","product_id":"BCH-USD","price":"795.29000000","remaining_size":"1.90000000","sequence":4839271018,"time":"2018-07-27T01:32:38.693000Z"}
{"type":"received","order_id":"d40a7258-6dde-4af5-ac58-0d2dd1c56536","order_type":"limit","size":"1.90000000","price":"794.61000000","side":"sell","client_oid":"6b784aad-d823-4558-a7d7-f8027a46c713","product_id":"BCH-USD","sequence":4839271019,"time":"2018-07-27T01:32:38.694000Z"}
{"type":"open","side":"sell","price":"794.61000000","order_id":"d40a7258-6dde-4af5-ac58-0d2dd1c56536","remaining_size":"1.90000000","product_id":"BCH-USD","sequence":4839271020,"time":"2018-07-27T01:32:38.694000Z"}
{"type":"received","order_id":"cb625716-5c88-4339-ab2a-7cbef408b5b5","order_type":"limit","size":"0.90000000","price":"794.64000000","side":"sell","client_oid":"c34fd399-0cf6-449e-bbdc-cd07c99c5311","product_id":"BCH-USD","sequence":4839271021,"time":"2018-07-27T01:32:38.697000Z"}
{"type":"done","side":"buy","order_id":"46ea32b2-1fe9-42c8-b585-4e998363ec5c","reason":"canceled","product_id":"LTC-USD","price":"82.99000000","remaining_size":"20.00000000","sequence":2423271581,"time":"2018-07-27T01:32:38.699000Z"}
{"type":"open","side":"sell","price":"794.64000000","order_id":"cb625716-5c88-4339-ab2a-7cbef408b5b5","remaining_size":"0.90000000","product_id":"BCH-USD","sequence":4839271022,"time":"2018-07-27T01:32:38.697000Z"}
{"type":"received","order_id":"068faa05-dfba-40d5-ac1d-ec99d4be65e7","order_type":"limit","size":"7.44874862","price":"83.34000000","side":"sell","client_oid":"4f450c63-2c96-4567-8000-00d9d0099156","product_id":"LTC-USD","sequence":2423271582,"time":"2018-07-27T01:32:38.700000Z"}
{"type":"open","side":"sell","price":"83.34000000","order_id":"068faa05-dfba-40d5-ac1d-ec99d4be65e7","remaining_size":"7.44874862","product_id":"LTC-USD","sequence":2423271583,"time":"2018-07-27T01:32:38.700000Z"}
{"type":"received","order_id":"833d924c-93ba-441f-8bf8-79fa5c3bb535","order_type":"limit","size":"4.50000000","price":"794.61000000","side":"sell","client_oid":"6372a1a8-7528-4d99-a442-9d4ddbe4c4ee","product_id":"BCH-USD","sequence":4839271023,"time":"2018-07-27T01:32:38.699000Z"}
{"type":"received","order_id":"5f269e15-efe5-47d9-964b-9c246e0b3859","order_type":"limit","size":"21.27450500","price":"83.30000000","side":"sell","client_oid":"04199255-827a-4bfa-9314-818e68c837a3","product_id":"LTC-USD","sequence":2423271584,"time":"2018-07-27T01:32:38.701000Z"}
{"type":"open","side":"sell","price":"794.61000000","order_id":"833d924c-93ba-441f-8bf8-79fa5c3bb535","remaining_size":"4.50000000","product_id":"BCH-USD","sequence":4839271024,"time":"2018-07-27T01:32:38.699000Z"}
{"type":"done","side":"sell","order_id":"d40a7258-6dde-4af5-ac58-0d2dd1c56536","reason":"canceled","product_id":"BCH-USD","price":"794.61000000","remaining_size":"1.90000000","sequence":4839271025,"time":"2018-07-27T01:32:38.700000Z"}
{"type":"open","side":"sell","price":"83.30000000","order_id":"5f269e15-efe5-47d9-964b-9c246e0b3859","remaining_size":"21.27450500","product_id":"LTC-USD","sequence":2423271585,"time":"2018-07-27T01:32:38.701000Z"}
{"type":"done","side":"sell","order_id":"cb625716-5c88-4339-ab2a-7cbef408b5b5","reason":"canceled","product_id":"BCH-USD","price":"794.64000000","remaining_size":"0.90000000","sequence":4839271026,"time":"2018-07-27T01:32:38.701000Z"}
{"type":"done","side":"sell","order_id":"e374479a-9703-44e8-9e49-c15b5e087011","reason":"canceled","product_id":"BCH-USD","price":"795.28000000","remaining_size":"4.50000000","sequence":4839271027,"time":"2018-07-27T01:32:38.701000Z"}
{"type":"received","order_id":"4489b1f4-34a9-4654-a095-fe8bbc0b03bc","order_type":"limit","size":"1.90000000","price":"795.27000000","side":"sell","client_oid":"f2fbe008-598f-42d1-a7e1-cfe3f2f7e3af","product_id":"BCH-USD","sequence":4839271028,"time":"2018-07-27T01:32:38.702000Z"}
{"type":"open","side":"sell","price":"795.27000000","order_id":"4489b1f4-34a9-4654-a095-fe8bbc0b03bc","remaining_size":"1.90000000","product_id":"BCH-USD","sequence":4839271029,"time":"2018-07-27T01:32:38.702000Z"}
{"type":"received","order_id":"454f0430-5cdd-4941-b758-dde61ccb50ca","order_type":"limit","size":"20.00000000","price":"82.98000000","side":"buy","client_oid":"c0d9cd0f-bc0a-4c3b-a9cc-30a6ee41fc7c","product_id":"LTC-USD","sequence":2423271586,"time":"2018-07-27T01:32:38.705000Z"}
{"type":"done","side":"sell","order_id":"833d924c-93ba-441f-8bf8-79fa5c3bb535","reason":"canceled","product_id":"BCH-USD","price":"794.61000000","remaining_size":"4.50000000","sequence":4839271030,"time":"2018-07-27T01:32:38.703000Z"}
{"type":"open","side":"buy","price":"82.98000000","order_id":"454f0430-5cdd-4941-b758-dde61ccb50ca","remaining_size":"20.00000000","product_id":"LTC-USD","sequence":2423271587,"time":"2018-07-27T01:32:38.705000Z"}
{"type":"received","order_id":"34096ea9-5bcf-4848-b0dd-f4673bf7d7e6","order_type":"limit","size":"2.00000000","price":"792.37000000","side":"buy","client_oid":"2a98c71c-8426-480f-b13f-7d4ab463a4c6","product_id":"BCH-USD","sequence":4839271031,"time":"2018-07-27T01:32:38.706000Z"}
{"type":"open","side":"buy","price":"792.37000000","order_id":"34096ea9-5bcf-4848-b0dd-f4673bf7d7e6","remaining_size":"2.00000000","product_id":"BCH-USD","sequence":4839271032,"time":"2018-07-27T01:32:38.706000Z"}
{"type":"done","side":"sell","order_id":"4489b1f4-34a9-4654-a095-fe8bbc0b03bc","reason":"canceled","product_id":"BCH-USD","price":"795.27000000","remaining_size":"1.90000000","sequence":4839271033,"time":"2018-07-27T01:32:38.707000Z"}
{"type":"received","order_id":"9708e76b-ef41-4fbc-819e-c471921451bf","order_type":"limit","size":"20.00000000","price":"83.23000000","side":"buy","client_oid":"04b0e3a1-b20d-441d-8079-37d77444c3b5","product_id":"LTC-USD","sequence":2423271588,"time":"2018-07-27T01:32:38.709000Z"}
{"type":"open","side":"buy","price":"83.23000000","order_id":"9708e76b-ef41-4fbc-819e-c471921451bf","remaining_size":"20.00000000","product_id":"LTC-USD","sequence":2423271589,"time":"2018-07-27T01:32:38.709000Z"}
{"type":"received","order_id":"6aacfa0e-bf85-4da8-b4cc-f5e9fae7bb6d","order_type":"limit","size":"4.50000000","price":"795.27000000","side":"sell","client_oid":"46cd92d6-dd40-45cd-aad8-3ab02fade3f6","product_id":"BCH-USD","sequence":4839271034,"time":"2018-07-27T01:32:38.708000Z"}
{"type":"open","side":"sell","price":"795.27000000","order_id":"6aacfa0e-bf85-4da8-b4cc-f5e9fae7bb6d","remaining_size":"4.50000000","product_id":"BCH-USD","sequence":4839271035,"time":"2018-07-27T01:32:38.708000Z"}
{"type":"done","side":"sell","order_id":"d2defc07-2bcd-4a60-84ff-6ba02fd6a431","reason":"canceled","product_id":"BCH-USD","price":"794.63000000","remaining_size":"0.90000000","sequence":4839271036,"time":"2018-07-27T01:32:38.710000Z"}
{"type":"received","order_id":"8a5b04ef-27b9-46e9-9116-86921f42f4ef","order_type":"limit","size":"0.90000000","price":"794.61000000","side":"sell","client_oid":"3e5a2cc2-fc17-4864-bb6c-6ab32384ff93","product_id":"BCH-USD","sequence":4839271037,"time":"2018-07-27T01:32:38.711000Z"}
{"type":"open","side":"sell","price":"794.61000000","order_id":"8a5b04ef-27b9-46e9-9116-86921f42f4ef","remaining_size":"0.90000000","product_id":"BCH-USD","sequence":4839271038,"time":"2018-07-27T01:32:38.711000Z"}
{"type":"done","side":"buy","order_id":"454f0430-5cdd-4941-b758-dde61ccb50ca","reason":"canceled","product_id":"LTC-USD","price":"82.98000000","remaining_size":"20.00000000","sequence":2423271590,"time":"2018-07-27T01:32:38.714000Z"}
{"type":"done","side":"sell","order_id":"6aacfa0e-bf85-4da8-b4cc-f5e9fae7bb6d","reason":"canceled","product_id":"BCH-USD","price":"795.27000000","remaining_size":"4.50000000","sequence":4839271039,"time":"2018-07-27T01:32:38.712000Z"}
{"type":"received","order_id":"f76418dd-6d70-48e0-bcbf-eb2e61a9e9ca","order_type":"limit","size":"18.05683200","price":"83.32000000","side":"sell","client_oid":"a4e231cb-be32-4c04-b71e-8a979b1961d6","product_id":"LTC-USD","sequence":2423271591,"time":"2018-07-27T01:32:38.716000Z"}
{"type":"received","order_id":"a3ed3014-7a72-4c9c-bb5c-a20fa6a88f24","order_type":"limit","size":"1.90000000","price":"794.64000000","side":"sell","client_oid":"13f517f1-459d-4a41-9a69-bbc55ba42456","product_id":"BCH-USD","sequence":4839271040,"time":"2018-07-27T01:32:38.714000Z"}
{"type":"open","side":"sell","price":"794.64000000","order_id":"a3ed3014-7a72-4c9c-bb5c-a20fa6a88f24","remaining_size":"1.90000000","product_id":"BCH-USD","sequence":4839271041,"time":"2018-07-27T01:32:38.714000Z"}
{"type":"open","side":"sell","price":"83.32000000","order_id":"f76418dd-6d70-48e0-bcbf-eb2e61a9e9ca","remaining_size":"18.05683200","product_id":"LTC-USD","sequence":2423271592,"time":"2018-07-27T01:32:38.716000Z"}
{"type":"done","side":"sell","order_id":"f8883cc9-2111-4ce3-b3e2-51e5400e646a","reason":"canceled","product_id":"LTC-USD","price":"83.38000000","remaining_size":"7.44874862","sequence":2423271593,"time":"2018-07-27T01:32:38.718000Z"}
{"type":"received","order_id":"dcf1f1a1-0d1b-42c0-9245-ef22983a8aad","order_type":"limit","size":"20.00000000","price":"82.99000000","side":"buy","client_oid":"fe34e654-7539-495a-973d-503393e264fc","product_id":"LTC-USD","sequence":2423271594,"time":"2018-07-27T01:32:38.722000Z"}
{"type":"open","side":"buy","price":"82.99000000","order_id":"dcf1f1a1-0d1b-42c0-9245-ef22983a8aad","remaining_size":"20.00000000","product_id":"LTC-USD","sequence":2423271595,"time":"2018-07-27T01:32:38.722000Z"}
{"type":"received","order_id":"0b03cb33-6cef-4b14-a844-5d6a2b72aa12","order_type":"limit","size":"4.50000000","price":"795.28000000","side":"sell","client_oid":"6b5d67dc-5191-4a8d-a2fd-3641a205dce7","product_id":"BCH-USD","sequence":4839271042,"time":"2018-07-27T01:32:38.729000Z"}
{"type":"open","side":"sell","price":"795.28000000","order_id":"0b03cb33-6cef-4b14-a844-5d6a2b72aa12","remaining_size":"4.50000000","product_id":"BCH-USD","sequence":4839271043,"time":"2018-07-27T01:32:38.729000Z"}
{"type":"received","order_id":"f244a892-cf8d-4ef2-bc9a-69f1c22dfc47","order_type":"limit","size":"7.44874862","price":"83.30000000","side":"sell","client_oid":"c6eb34f1-c981-4d1a-8000-00b6694b1bc0","product_id":"LTC-USD","sequence":2423271596,"time":"2018-07-27T01:32:38.734000Z"}
{"type":"done","side":"sell","order_id":"0b03cb33-6cef-4b14-a844-5d6a2b72aa12","reason":"canceled","product_id":"BCH-USD","price":"795.28000000","remaining_size":"4.50000000","sequence":4839271044,"time":"2018-07-27T01:32:38.732000Z"}
{"type":"received","order_id":"72016e94-05d6-4686-97de-02b8b24c7947","order_type":"limit","size":"0.90000000","price":"794.64000000","side":"sell","client_oid":"59ac140a-15f2-4674-97d7-0b1383b62f0c","product_id":"BCH-USD","sequence":4839271045,"time":"2018-07-27T01:32:38.734000Z"}
{"type":"open","side":"sell","price":"794.64000000","order_id":"72016e94-05d6-4686-97de-02b8b24c7947","remaining_size":"0.90000000","product_id":"BCH-USD","sequence":4839271046,"time":"2018-07-27T01:32:38.734000Z"}
{"type":"open","side":"sell","price":"83.30000000","order_id":"f244a892-cf8d-4ef2-bc9a-69f1c22dfc47","remaining_size":"7.44874862","product_id":"LTC-USD","sequence":2423271597,"time":"2018-07-27T01:32:38.734000Z"}
{"type":"received","order_id":"41d160e1-18b9-4352-8277-b30021cbdcea","order_type":"limit","size":"1.90000000","price":"795.29000000","side":"sell","client_oid":"d3b70924-858a-446b-8e68-c05e2fba0a57","product_id":"BCH-USD","sequence":4839271047,"time":"2018-07-27T01:32:38.740000Z"}
{"type":"open","side":"sell","price":"795.29000000","order_id":"41d160e1-18b9-4352-8277-b30021cbdcea","remaining_size":"1.90000000","product_id":"BCH-USD","sequence":4839271048,"time":"2018-07-27T01:32:38.740000Z"}
{"type":"received","order_id":"5fd46d00-0d0a-4c1f-9dc7-ad398c4797dc","order_type":"limit","size":"4.50000000","price":"795.29000000","side":"sell","client_oid":"1111f13e-0a6d-425b-8a29-f39b84ea273e","product_id":"BCH-USD","sequence":4839271049,"time":"2018-07-27T01:32:38.740000Z"}
{"type":"open","side":"sell","price":"795.29000000","order_id":"5fd46d00-0d0a-4c1f-9dc7-ad398c4797dc","remaining_size":"4.50000000","product_id":"BCH-USD","sequence":4839271050,"time":"2018-07-27T01:32:38.740000Z"}
{"type":"received","order_id":"017f3956-186b-43e2-96e7-88a160adcb2e","order_type":"limit","size":"4.50000000","price":"794.64000000","side":"sell","client_oid":"9dc026a5-5c74-43ee-94b9-61dea394bb01","product_id":"BCH-USD","sequence":4839271051,"time":"2018-07-27T01:32:38.741000Z"}
{"type":"open","side":"sell","price":"794.64000000","order_id":"017f3956-186b-43e2-96e7-88a160adcb2e","remaining_size":"4.50000000","product_id":"BCH-USD","sequence":4839271052,"time":"2018-07-27T01:32:38.741000Z"}
{"type":"received","order_id":"8609db74-a377-4fb1-bfb8-67ec4d54d52d","order_type":"limit","size":"104.37178200","price":"83.34000000","side":"sell","client_oid":"94acac0e-67e6-413d-bbcb-6830488d3e16","product_id":"LTC-USD","sequence":2423271598,"time":"2018-07-27T01:32:38.745000Z"}
{"type":"open","side":"sell","price":"83.34000000","order_id":"8609db74-a377-4fb1-bfb8-67ec4d54d52d","remaining_size":"104.37178200","product_id":"LTC-USD","sequence":2423271599,"time":"2018-07-27T01:32:38.745000Z"}
{"type":"done","side":"sell","order_id":"8a5b04ef-27b9-46e9-9116-86921f42f4ef","reason":"canceled","product_id":"BCH-USD","price":"794.61000000","remaining_size":"0.90000000","sequence":4839271053,"time":"2018-07-27T01:32:38.744000Z"}
{"type":"done","side":"sell","order_id":"72016e94-05d6-4686-97de-02b8b24c7947","reason":"canceled","product_id":"BCH-USD","price":"794.64000000","remaining_size":"0.90000000","sequence":4839271054,"time":"2018-07-27T01:32:38.744000Z"}
{"type":"done","side":"buy","order_id":"34096ea9-5bcf-4848-b0dd-f4673bf7d7e6","reason":"canceled","product_id":"BCH-USD","price":"792.37000000","remaining_size":"2.00000000","sequence":4839271055,"time":"2018-07-27T01:32:38.748000Z"}
{"type":"done","side":"buy","order_id":"53046af6-eed5-4bde-9b78-7aa62f074517","reason":"canceled","product_id":"BCH-USD","price":"782.58000000","remaining_size":"9.07530000","sequence":4839271056,"time":"2018-07-27T01:32:38.749000Z"}
{"type":"received","order_id":"aab32778-c2cc-445e-9f29-e47edf0bad7d","order_type":"limit","size":"0.00100000","price":"8116.29000000","side":"sell","client_oid":"94502221-8dc9-498e-8000-006f5d8353d1","product_id":"BTC-USD","sequence":6418130191,"time":"2018-07-27T01:32:38.753000Z"}
{"type":"open","side":"sell","price":"8116.29000000","order_id":"aab32778-c2cc-445e-9f29-e47edf0bad7d","remaining_size":"0.00100000","product_id":"BTC-USD","sequence":6418130192,"time":"2018-07-27T01:32:38.753000Z"}
{"type":"done","side":"sell","order_id":"9ebba5f3-d648-41b1-94ca-3d6431962016","reason":"canceled","product_id":"BTC-USD","price":"8115.29000000","remaining_size":"0.00100000","sequence":6418130193,"time":"2018-07-27T01:32:38.757000Z"}
{"type":"done","side":"sell","order_id":"017f3956-186b-43e2-96e7-88a160adcb2e","reason":"canceled","product_id":"BCH-USD","price":"794.64000000","remaining_size":"4.50000000","sequence":4839271057,"time":"2018-07-27T01:32:38.754000Z"}
{"type":"done","side":"sell","order_id":"a82dcee5-cec4-40c2-aa1a-675e9d7f167e","reason":"canceled","product_id":"BTC-USD","price":"8114.29000000","remaining_size":"0.00100000","sequence":6418130194,"time":"2018-07-27T01:32:38.758000Z"}
{"type":"done","side":"sell","order_id":"a3ed3014-7a72-4c9c-bb5c-a20fa6a88f24","reason":"canceled","product_id":"BCH-USD","price":"794.64000000","remaining_size":"1.90000000","sequence":4839271058,"time":"2018-07-27T01:32:38.757000Z"}
{"type":"done","side":"buy","order_id":"dcf1f1a1-0d1b-42c0-9245-ef22983a8aad","reason":"canceled","product_id":"LTC-USD","price":"82.99000000","remaining_size":"20.00000000","sequence":2423271600,"time":"2018-07-27T01:32:38.759000Z"}
{"type":"received","order_id":"9ee1ed0b-19d6-4efd-8d59-ccba69c8f7ce","order_type":"limit","size":"0.90000000","price":"794.64000000","side":"sell","client_oid":"f93ebeb8-c4da-452a-97bf-e0ec11a3da27","product_id":"BCH-USD","sequence":4839271059,"time":"2018-07-27T01:32:38.758000Z"}
{"type":"open","side":"sell","price":"794.64000000","order_id":"9ee1ed0b-19d6-4efd-8d59-ccba69c8f7ce","remaining_size":"0.90000000","product_id":"BCH-USD","sequence":4839271060,"time":"2018-07-27T01:32:38.758000Z"}
{"type":"done","side":"sell","order_id":"068faa05-dfba-40d5-ac1d-ec99d4be65e7","reason":"canceled","product_id":"LTC-USD","price":"83.34000000","remaining_size":"7.44874862","sequence":2423271601,"time":"2018-07-27T01:32:38.760000Z"}
{"type":"received","order_id":"64ec3f35-5ad2-47d8-bfb1-f2769a5d46b3","order_type":"limit","size":"1.90000000","price":"794.63000000","side":"sell","client_oid":"221a8b55-86bd-45c9-b3dc-7f27698700ef","product_id":"BCH-USD","sequence":4839271061,"time":"2018-07-27T01:32:38.761000Z"}
{"type":"open","side":"sell","price":"794.63000000","order_id":"64ec3f35-5ad2-47d8-bfb1-f2769a5d46b3","remaining_size":"1.90000000","product_id":"BCH-USD","sequence":4839271062,"time":"2018-07-27T01:32:38.761000Z"}
{"type":"received","order_id":"8184b547-f68e-4a0c-9744-31a13ef69100","order_type":"limit","size":"0.90000000","price":"794.63000000","side":"sell","client_oid":"2be8f92e-846d-462c-9786-176a9cd50f64","product_id":"BCH-USD","sequence":4839271063,"time":"2018-07-27T01:32:38.762000Z"}
{"type":"open","side":"sell","price":"794.63000000","order_id":"8184b547-f68e-4a0c-9744-31a13ef69100","remaining_size":"0.90000000","product_id":"BCH-USD","sequence":4839271064,"time":"2018-07-27T01:32:38.762000Z"}
{"type":"done","side":"sell","order_id":"9ee1ed0b-19d6-4efd-8d59-ccba69c8f7ce","reason":"canceled","product_id":"BCH-USD","price":"794.64000000","remaining_size":"0.90000000","sequence":4839271065,"time":"2018-07-27T01:32:38.762000Z"}
{"type":"received","order_id":"abb2556b-c9fe-4d4c-b3f7-e3895e7f8ec4","order_type":"limit","size":"14.23750300","price":"83.37000000","side":"sell","client_oid":"b02df90b-1b50-49a6-a18f-d26ede490e5d","product_id":"LTC-USD","sequence":2423271602,"time":"2018-07-27T01:32:38.765000Z"}
{"type":"open","side":"sell","price":"83.37000000","order_id":"abb2556b-c9fe-4d4c-b3f7-e3895e7f8ec4","remaining_size":"14.23750300","product_id":"LTC-USD","sequence":2423271603,"time":"2018-07-27T01:32:38.765000Z"}
{"type":"done","side":"sell","order_id":"41d160e1-18b9-4352-8277-b30021cbdcea","reason":"canceled","product_id":"BCH-USD","price":"795.29000000","remaining_size":"1.90000000","sequence":4839271066,"time":"2018-07-27T01:32:38.767000Z"}
{"type":"done","side":"sell","order_id":"5fd46d00-0d0a-4c1f-9dc7-ad398c4797dc","reason":"canceled","product_id":"BCH-USD","price":"795.29000000","remaining_size":"4.50000000","sequence":4839271067,"time":"2018-07-27T01:32:38.767000Z"}
{"type":"done","side":"sell","order_id":"8184b547-f68e-4a0c-9744-31a13ef69100","reason":"canceled","product_id":"BCH-USD","price":"794.63000000","remaining_size":"0.90000000","sequence":4839271068,"time":"2018-07-27T01:32:38.775000Z"}
{"type":"done","side":"sell","order_id":"f244a892-cf8d-4ef2-bc9a-69f1c22dfc47","reason":"canceled","product_id":"LTC-USD","price":"83.30000000","remaining_size":"7.44874862","sequence":2423271604,"time":"2018-07-27T01:32:38.796000Z"}
{"type":"done","side":"sell","order_id":"64ec3f35-5ad2-47d8-bfb1-f2769a5d46b3","reason":"canceled","product_id":"BCH-USD","price":"794.63000000","remaining_size":"1.90000000","sequence":4839271069,"time":"2018-07-27T01:32:38.800000Z"}
{"type":"done","side":"sell","order_id":"eedc5d3e-1a7b-4eb5-a1da-1250ca880849","reason":"canceled","product_id":"LTC-USD","price":"85.39000000","remaining_size":"0.10000000","sequence":2423271605,"time":"2018-07-27T01:32:38.818000Z"}
{"type":"done","side":"sell","order_id":"688a8be6-75d4-4c4d-aa1e-b75f3bb52e7f","reason":"canceled","product_id":"LTC-USD","price":"86.38000000","remaining_size":"0.10000000","sequence":2423271606,"time":"2018-07-27T01:32:38.821000Z"}
{"type":"received","order_id":"ce536471-4c0d-4713-947a-a87a628e0b01","order_type":"limit","size":"0.00100000","price":"8117.27000000","side":"sell","client_oid":"76e04317-9896-43fc-8000-009ef2b190aa","product_id":"BTC-USD","sequence":6418130195,"time":"2018-07-27T01:32:38.938000Z"}
{"type":"received","order_id":"522660be-8e52-4898-9817-0e1e1d53cad1","order_type":"limit","size":"20.00000000","price":"82.98000000","side":"buy","client_oid":"90782cd3-c420-4dd2-84c7-e1089d391260","product_id":"LTC-USD","sequence":2423271607,"time":"2018-07-27T01:32:38.937000Z"}
{"type":"open","side":"sell","price":"8117.27000000","order_id":"ce536471-4c0d-4713-947a-a87a628e0b01","remaining_size":"0.00100000","product_id":"BTC-USD","sequence":6418130196,"time":"2018-07-27T01:32:38.938000Z"}
{"type":"open","side":"buy","price":"82.98000000","order_id":"522660be-8e52-4898-9817-0e1e1d53cad1","remaining_size":"20.00000000","product_id":"LTC-USD","sequence":2423271608,"time":"2018-07-27T01:32:38.937000Z"}
{"type":"received","order_id":"00d914d2-d0fe-461d-b62e-5751e68c69e9","order_type":"limit","size":"2.00000000","price":"792.53000000","side":"buy","client_oid":"46bc02d2-bb55-43a9-b414-9a4df9878d64","product_id":"BCH-USD","sequence":4839271070,"time":"2018-07-27T01:32:38.938000Z"}
{"type":"open","side":"buy","price":"792.53000000","order_id":"00d914d2-d0fe-461d-b62e-5751e68c69e9","remaining_size":"2.00000000","product_id":"BCH-USD","sequence":4839271071,"time":"2018-07-27T01:32:38.938000Z"}
{"type":"received","order_id":"32458cd3-3db4-4d49-bb02-b96e90e11f2a","order_type":"limit","size":"8.45425500","price":"83.40000000","side":"sell","client_oid":"5df84cf2-85e7-43bb-84c7-8ba5addf5a71","product_id":"LTC-USD","sequence":2423271609,"time":"2018-07-27T01:32:38.941000Z"}
{"type":"received","order_id":"626ea344-f2bf-48e1-a408-5d0d0192d406","order_type":"limit","size":"9.98620000","price":"782.31000000","side":"buy","product_id":"BCH-USD","sequence":4839271072,"time":"2018-07-27T01:32:38.939000Z"}
{"type":"open","side":"buy","price":"782.31000000","order_id":"626ea344-f2bf-48e1-a408-5d0d0192d406","remaining_size":"9.98620000","product_id":"BCH-USD","sequence":4839271073,"time":"2018-07-27T01:32:38.939000Z"}
{"type":"received","order_id":"366c2004-b8b1-40bf-8141-a3541b3867ab","order_type":"limit","size":"4.50000000","price":"794.63000000","side":"sell","client_oid":"c4ce28dc-ab3c-4801-82bb-ba32a9087c90","product_id":"BCH-USD","sequence":4839271074,"time":"2018-07-27T01:32:38.940000Z"}
{"type":"open","side":"sell","price":"83.40000000","order_id":"32458cd3-3db4-4d49-bb02-b96e90e11f2a","remaining_size":"8.45425500","product_id":"LTC-USD","sequence":2423271610,"time":"2018-07-27T01:32:38.941000Z"}
{"type":"received","order_id":"a23aeee0-6c90-4b9c-ba5e-afdb7aaa35e0","order_type":"limit","size":"7.44874862","price":"83.38000000","side":"sell","client_oid":"4c6ab994-789f-43b1-8000-086fcfb988d0","product_id":"LTC-USD","sequence":2423271611,"time":"2018-07-27T01:32:38.942000Z"}
{"type":"open","side":"sell","price":"83.38000000","order_id":"a23aeee0-6c90-4b9c-ba5e-afdb7aaa35e0","remaining_size":"7.44874862","product_id":"LTC-USD","sequence":2423271612,"time":"2018-07-27T01:32:38.942000Z"}
{"type":"open","side":"sell","price":"794.63000000","order_id":"366c2004-b8b1-40bf-8141-a3541b3867ab","remaining_size":"4.50000000","product_id":"BCH-USD","sequence":4839271075,"time":"2018-07-27T01:32:38.940000Z"}
{"type":"done","side":"buy","order_id":"522660be-8e52-4898-9817-0e1e1d53cad1","reason":"canceled","product_id":"LTC-USD","price":"82.98000000","remaining_size":"20.00000000","sequence":2423271613,"time":"2018-07-27T01:32:38.944000Z"}
{"type":"received","order_id":"0a603b6a-0756-4e2f-9714-1900e77ce41a","order_type":"limit","size":"0.90000000","price":"794.63000000","side":"sell","client_oid":"86797660-dbfa-41e2-b03f-7d6c96c1f6d5","product_id":"BCH-USD","sequence":4839271076,"time":"2018-07-27T01:32:38.945000Z"}
{"type":"open","side":"sell","price":"794.63000000","order_id":"0a603b6a-0756-4e2f-9714-1900e77ce41a","remaining_size":"0.90000000","product_id":"BCH-USD","sequence":4839271077,"time":"2018-07-27T01:32:38.945000Z"}
{"type":"done","side":"buy","order_id":"e434d8b0-30e0-4453-8889-ff371f9b759f","reason":"canceled","product_id":"BCH-USD","price":"790.64000000","remaining_size":"0.16628700","sequence":4839271078,"time":"2018-07-27T01:32:38.945000Z"}
{"type":"done","side":"buy","order_id":"00d914d2-d0fe-461d-b62e-5751e68c69e9","reason":"canceled","product_id":"BCH-USD","price":"792.53000000","remaining_size":"2.00000000","sequence":4839271079,"time":"2018-07-27T01:32:38.945000Z"}
{"type":"received","order_id":"8ce7cca7-a306-4161-9b3d-ad42e25890d8","order_type":"limit","size":"4.50000000","price":"795.28000000","side":"sell","client_oid":"e76f1c37-d8bc-4e91-8014-5a6147ada6bf","product_id":"BCH-USD","sequence":4839271080,"time":"2018-07-27T01:32:38.946000Z"}
{"type":"open","side":"sell","price":"795.28000000","order_id":"8ce7cca7-a306-4161-9b3d-ad42e25890d8","remaining_size":"4.50000000","product_id":"BCH-USD","sequence":4839271081,"time":"2018-07-27T01:32:38.946000Z"}
{"type":"received","order_id":"f640845c-da9e-47ff-9934-07883bb5524e","order_type":"limit","size":"1.90000000","price":"795.28000000","side":"sell","client_oid":"70a586de-3ab2-4ddf-94b0-b38ac910accd","product_id":"BCH-USD","sequence":4839271082,"time":"2018-07-27T01:32:38.948000Z"}
{"type":"open","side":"sell","price":"795.28000000","order_id":"f640845c-da9e-47ff-9934-07883bb5524e","remaining_size":"1.90000000","product_id":"BCH-USD","sequence":4839271083,"time":"2018-07-27T01:32:38.948000Z"}
{"type":"done","side":"buy","order_id":"14d3ee0f-2353-4bd5-bd9d-e9d64e7304a5","reason":"canceled","product_id":"BCH-USD","price":"790.16000000","remaining_size":"0.46509700","sequence":4839271084,"time":"2018-07-27T01:32:38.948000Z"}
{"type":"received","order_id":"fd8e0703-2a3e-481b-bc8a-c049a26ff1cd","order_type":"limit","size":"0.10000000","price":"88.38000000","side":"sell","client_oid":"bf80ef23-4c54-4e5d-8000-00b686208dd7","product_id":"LTC-USD","sequence":2423271614,"time":"2018-07-27T01:32:38.951000Z"}
{"type":"done","side":"sell","order_id":"0a603b6a-0756-4e2f-9714-1900e77ce41a","reason":"canceled","product_id":"BCH-USD","price":"794.63000000","remaining_size":"0.90000000","sequence":4839271085,"time":"2018-07-27T01:32:38.949000Z"}
{"type":"open","side":"sell","price":"88.38000000","order_id":"fd8e0703-2a3e-481b-bc8a-c049a26ff1cd","remaining_size":"0.10000000","product_id":"LTC-USD","sequence":2423271615,"time":"2018-07-27T01:32:38.951000Z"}
{"type":"done","side":"sell","order_id":"8ce7cca7-a306-4161-9b3d-ad42e25890d8","reason":"canceled","product_id":"BCH-USD","price":"795.28000000","remaining_size":"4.50000000","sequence":4839271086,"time":"2018-07-27T01:32:38.950000Z"}
{"type":"done","side":"sell","order_id":"366c2004-b8b1-40bf-8141-a3541b3867ab","reason":"canceled","product_id":"BCH-USD","price":"794.63000000","remaining_size":"4.50000000","sequence":4839271087,"time":"2018-07-27T01:32:38.950000Z"}
{"type":"received","order_id":"504f862f-a309-465e-84d8-a809c284506b","order_type":"limit","size":"20.00000000","price":"82.99000000","side":"buy","client_oid":"d40a0069-b7d1-466e-9084-a1ffa6212866","product_id":"LTC-USD","sequence":2423271616,"time":"2018-07-27T01:32:38.954000Z"}
{"type":"done","side":"buy","order_id":"1ddf80f1-3a7c-42a8-8153-5adaecfef9ea","reason":"canceled","product_id":"BCH-USD","price":"789.92000000","remaining_size":"0.43148900","sequence":4839271088,"time":"2018-07-27T01:32:38.952000Z"}
{"type":"open","side":"buy","price":"82.99000000","order_id":"504f862f-a309-465e-84d8-a809c284506b","remaining_size":"20.00000000","product_id":"LTC-USD","sequence":2423271617,"time":"2018-07-27T01:32:38.954000Z"}
{"type":"done","side":"buy","order_id":"d4596275-2e5e-4ecc-8682-0b9fb6e76a14","reason":"canceled","product_id":"BCH-USD","price":"789.68000000","remaining_size":"0.23088300","sequence":4839271089,"time":"2018-07-27T01:32:38.955000Z"}
{"type":"received","order_id":"dbdcb2a8-0ef4-4a6e-80c7-7094de3574fe","order_type":"limit","size":"0.90000000","price":"794.64000000","side":"sell","client_oid":"3108b027-eda0-418e-a248-46eae675025a","product_id":"BCH-USD","sequence":4839271090,"time":"2018-07-27T01:32:38.955000Z"}
{"type":"open","side":"sell","price":"794.64000000","order_id":"dbdcb2a8-0ef4-4a6e-80c7-7094de3574fe","remaining_size":"0.90000000","product_id":"BCH-USD","sequence":4839271091,"time":"2018-07-27T01:32:38.955000Z"}
{"type":"received","order_id":"9185dba1-cf40-4ee3-acc7-1b363d2be8b3","order_type":"limit","size":"1.90000000","price":"794.64000000","side":"sell","client_oid":"77c411a9-a26d-42b6-8873-d148a7ef8545","product_id":"BCH-USD","sequence":4839271092,"time":"2018-07-27T01:32:38.956000Z"}
{"type":"open","side":"sell","price":"794.64000000","order_id":"9185dba1-cf40-4ee3-acc7-1b363d2be8b3","remaining_size":"1.90000000","product_id":"BCH-USD","sequence":4839271093,"time":"2018-07-27T01:32:38.956000Z"}
{"type":"done","side":"buy","order_id":"b0359e91-ca47-4888-ae1c-2cade7132411","reason":"canceled","product_id":"BCH-USD","price":"789.20000000","remaining_size":"0.35215800","sequence":4839271094,"time":"2018-07-27T01:32:38.958000Z"}
{"type":"received","order_id":"f786d793-c177-4d78-acf5-3ba92e4364c7","order_type":"limit","size":"0.90000000","price":"794.64000000","side":"sell","client_oid":"a4cc93a0-05da-4dbe-b750-c37bc1d930b1","product_id":"BCH-USD","sequence":4839271095,"time":"2018-07-27T01:32:38.959000Z"}
{"type":"open","side":"sell","price":"794.64000000","order_id":"f786d793-c177-4d78-acf5-3ba92e4364c7","remaining_size":"0.90000000","product_id":"BCH-USD","sequence":4839271096,"time":"2018-07-27T01:32:38.959000Z"}
{"type":"done","side":"sell","order_id":"dbdcb2a8-0ef4-4a6e-80c7-7094de3574fe","reason":"canceled","product_id":"BCH-USD","price":"794.64000000","remaining_size":"0.90000000","sequence":4839271097,"time":"2018-07-27T01:32:38.960000Z"}
{"type":"done","side":"buy","order_id":"f0b7eaac-1954-4074-b5b7-27591f348628","reason":"canceled","product_id":"BCH-USD","price":"788.96000000","remaining_size":"0.25510300","sequence":4839271098,"time":"2018-07-27T01:32:38.960000Z"}
{"type":"done","side":"sell","order_id":"f640845c-da9e-47ff-9934-07883bb5524e","reason":"canceled","product_id":"BCH-USD","price":"795.28000000","remaining_size":"1.90000000","sequence":4839271099,"time":"2018-07-27T01:32:38.961000Z"}
{"type":"received","order_id":"d2c0f038-71d5-4ce1-b208-e70af93f4c5e","order_type":"limit","size":"2.00000000","price":"792.80000000","side":"buy","client_oid":"a1d6648f-1129-4926-9346-2dbdeb0629d4","product_id":"BCH-USD","sequence":4839271100,"time":"2018-07-27T01:32:38.961000Z"}
{"type":"open","side":"buy","price":"792.80000000","order_id":"d2c0f038-71d5-4ce1-b208-e70af93f4c5e","remaining_size":"2.00000000","product_id":"BCH-USD","sequence":4839271101,"time":"2018-07-27T01:32:38.961000Z"}
{"type":"done","side":"sell","order_id":"f786d793-c177-4d78-acf5-3ba92e4364c7","reason":"canceled","product_id":"BCH-USD","price":"794.64000000","remaining_size":"0.90000000","sequence":4839271102,"time":"2018-07-27T01:32:38.963000Z"}
{"type":"done","side":"sell","order_id":"9185dba1-cf40-4ee3-acc7-1b363d2be8b3","reason":"canceled","product_id":"BCH-USD","price":"794.64000000","remaining_size":"1.90000000","sequence":4839271103,"time":"2018-07-27T01:32:38.964000Z"}
{"type":"received","order_id":"aec64a3f-874d-4586-9e0e-70892275565f","order_type":"limit","size":"4.50000000","price":"795.29000000","side":"sell","client_oid":"44096d20-7af1-40c1-88fc-c4081cf58228","product_id":"BCH-USD","sequence":4839271104,"time":"2018-07-27T01:32:38.964000Z"}
{"type":"open","side":"sell","price":"795.29000000","order_id":"aec64a3f-874d-4586-9e0e-70892275565f","remaining_size":"4.50000000","product_id":"BCH-USD","sequence":4839271105,"time":"2018-07-27T01:32:38.964000Z"}
{"type":"done","side":"buy","order_id":"5782b9ba-1340-41ae-afba-f3aef62d06f0","reason":"canceled","product_id":"BCH-USD","price":"788.72000000","remaining_size":"0.52660300","sequence":4839271106,"time":"2018-07-27T01:32:38.965000Z"}
{"type":"done","side":"buy","order_id":"1ed9c4a1-ec18-4505-8b58-57541b963b1c","reason":"canceled","product_id":"BCH-USD","price":"788.48000000","remaining_size":"0.49770400","sequence":4839271107,"time":"2018-07-27T01:32:38.967000Z"}
{"type":"received","order_id":"c9908dee-78e6-4333-811c-8a20f2b4ad56","order_type":"limit","size":"4.50000000","price":"794.64000000","side":"sell","client_oid":"970a106a-7ada-4e4d-a2da-75cf9b4d1145","product_id":"BCH-USD","sequence":4839271108,"time":"2018-07-27T01:32:38.968000Z"}
{"type":"open","side":"sell","price":"794.64000000","order_id":"c9908dee-78e6-4333-811c-8a20f2b4ad56","remaining_size":"4.50000000","product_id":"BCH-USD","sequence":4839271109,"time":"2018-07-27T01:32:38.968000Z"}
{"type":"received","order_id":"51e41c2e-b7f9-484e-9a42-8ba52ce134ed","order_type":"limit","size":"1.90000000","price":"795.29000000","side":"sell","client_oid":"a80b381d-9398-4a44-988f-cd15cecf980e","product_id":"BCH-USD","sequence":4839271110,"time":"2018-07-27T01:32:38.969000Z"}
{"type":"open","side":"sell","price":"795.29000000","order_id":"51e41c2e-b7f9-484e-9a42-8ba52ce134ed","remaining_size":"1.90000000","product_id":"BCH-USD","sequence":4839271111,"time":"2018-07-27T01:32:38.969000Z"}
{"type":"done","side":"buy","order_id":"594d8e94-3838-4997-85be-26889fcaeea0","reason":"canceled","product_id":"BCH-USD","price":"788.24000000","remaining_size":"2.02699300","sequence":4839271112,"time":"2018-07-27T01:32:38.970000Z"}
{"type":"done","side":"sell","order_id":"55bc5840-2767-4ca3-828a-128923c38922","reason":"canceled","product_id":"BCH-USD","price":"795.67000000","remaining_size":"1.13693600","sequence":4839271113,"time":"2018-07-27T01:32:38.972000Z"}
{"type":"received","order_id":"b0dc30b9-e7c5-4f25-a5df-43c6be1ac7a5","order_type":"limit","size":"7.44874862","price":"83.30000000","side":"sell","client_oid":"0edf9113-91f5-4318-8000-00de7e7d5533","product_id":"LTC-USD","sequence":2423271618,"time":"2018-07-27T01:32:38.974000Z"}
{"type":"open","side":"sell","price":"83.30000000","order_id":"b0dc30b9-e7c5-4f25-a5df-43c6be1ac7a5","remaining_size":"7.44874862","product_id":"LTC-USD","sequence":2423271619,"time":"2018-07-27T01:32:38.974000Z"}
{"type":"done","side":"sell","order_id":"c9908dee-78e6-4333-811c-8a20f2b4ad56","reason":"canceled","product_id":"BCH-USD","price":"794.64000000","remaining_size":"4.50000000","sequence":4839271114,"time":"2018-07-27T01:32:38.974000Z"}
{"type":"received","order_id":"4648264e-c24d-4746-b2a9-3fbb69b09ff4","order_type":"limit","size":"0.90000000","price":"794.62000000","side":"sell","client_oid":"26652cf7-cab1-4717-be16-dd63eeb26acd","product_id":"BCH-USD","sequence":4839271115,"time":"2018-07-27T01:32:38.976000Z"}
{"type":"open","side":"sell","price":"794.62000000","order_id":"4648264e-c24d-4746-b2a9-3fbb69b09ff4","remaining_size":"0.90000000","product_id":"BCH-USD","sequence":4839271116,"time":"2018-07-27T01:32:38.976000Z"}
{"type":"received","order_id":"954b2137-19cf-4e7e-830f-d9a74f393cd0","order_type":"limit","size":"0.90000000","price":"794.62000000","side":"sell","client_oid":"c375171d-7796-4520-9a04-c75e6d9c0b8d","product_id":"BCH-USD","sequence":4839271117,"time":"2018-07-27T01:32:38.977000Z"}
{"type":"open","side":"sell","price":"794.62000000","order_id":"954b2137-19cf-4e7e-830f-d9a74f393cd0","remaining_size":"0.90000000","product_id":"BCH-USD","sequence":4839271118,"time":"2018-07-27T01:32:38.977000Z"}
{"type":"done","side":"sell","order_id":"4648264e-c24d-4746-b2a9-3fbb69b09ff4","reason":"canceled","product_id":"BCH-USD","price":"794.62000000","remaining_size":"0.90000000","sequence":4839271119,"time":"2018-07-27T01:32:38.980000Z"}
{"type":"done","side":"sell","order_id":"a23aeee0-6c90-4b9c-ba5e-afdb7aaa35e0","reason":"canceled","product_id":"LTC-USD","price":"83.38000000","remaining_size":"7.44874862","sequence":2423271620,"time":"2018-07-27T01:32:38.988000Z"}
{"type":"received","order_id":"0a494da7-8da2-4519-824e-a132c5314a49","order_type":"limit","size":"0.90000000","price":"794.64000000","side":"sell","client_oid":"26d91eba-769a-404f-9257-9efa077e83fd","product_id":"BCH-USD","sequence":4839271120,"time":"2018-07-27T01:32:38.988000Z"}
{"type":"open","side":"sell","price":"794.64000000","order_id":"0a494da7-8da2-4519-824e-a132c5314a49","remaining_size":"0.90000000","product_id":"BCH-USD","sequence":4839271121,"time":"2018-07-27T01:32:38.988000Z"}
{"type":"received","order_id":"c8e650a5-3a4e-4f7e-adc6-2585b705acf8","order_type":"limit","size":"4.50000000","price":"794.62000000","side":"sell","client_oid":"d20ea7a1-0c8a-4c5b-9594-3458634b759d","product_id":"BCH-USD","sequence":4839271122,"time":"2018-07-27T01:32:38.988000Z"}
{"type":"open","side":"sell","price":"794.62000000","order_id":"c8e650a5-3a4e-4f7e-adc6-2585b705acf8","remaining_size":"4.50000000","product_id":"BCH-USD","sequence":4839271123,"time":"2018-07-27T01:32:38.988000Z"}
{"type":"done","side":"buy","order_id":"504f862f-a309-465e-84d8-a809c284506b","reason":"canceled","product_id":"LTC-USD","price":"82.99000000","remaining_size":"20.00000000","sequence":2423271621,"time":"2018-07-27T01:32:38.992000Z"}
{"type":"received","order_id":"05a38906-4a99-43f9-aa61-f99146df290e","order_type":"limit","size":"1.90000000","price":"794.62000000","side":"sell","client_oid":"6c6a4dfb-23e8-4096-883c-decfabad7215","product_id":"BCH-USD","sequence":4839271124,"time":"2018-07-27T01:32:38.993000Z"}
{"type":"open","side":"sell","price":"794.62000000","order_id":"05a38906-4a99-43f9-aa61-f99146df290e","remaining_size":"1.90000000","product_id":"BCH-USD","sequence":4839271125,"time":"2018-07-27T01:32:38.993000Z"}
{"type":"done","side":"buy","order_id":"d2c0f038-71d5-4ce1-b208-e70af93f4c5e","reason":"canceled","product_id":"BCH-USD","price":"792.80000000","remaining_size":"2.00000000","sequence":4839271126,"time":"2018-07-27T01:32:38.995000Z"}
{"type":"received","order_id":"adff1c95-66a0-4f00-adbb-b3da4b2b4061","order_type":"limit","size":"20.00000000","price":"82.98000000","side":"buy","client_oid":"0d65fc74-1467-41f7-be09-3b0490fe77d5","product_id":"LTC-USD","sequence":2423271622,"time":"2018-07-27T01:32:39.001000Z"}
{"type":"open","side":"buy","price":"82.98000000","order_id":"adff1c95-66a0-4f00-adbb-b3da4b2b4061","remaining_size":"20.00000000","product_id":"LTC-USD","sequence":2423271623,"time":"2018-07-27T01:32:39.001000Z"}
{"type":"received","order_id":"61178d22-babe-463f-b377-d162e866ce9b","order_type":"limit","size":"7.44874862","price":"83.34000000","side":"sell","client_oid":"0851e38e-6a0f-4394-8000-003bcf360020","product_id":"LTC-USD","sequence":2423271624,"time":"2018-07-27T01:32:39.003000Z"}
{"type":"open","side":"sell","price":"83.34000000","order_id":"61178d22-babe-463f-b377-d162e866ce9b","remaining_size":"7.44874862","product_id":"LTC-USD","sequence":2423271625,"time":"2018-07-27T01:32:39.003000Z"}
{"type":"done","side":"buy","order_id":"66a8baf7-d8fa-485d-92f7-005f605924a7","reason":"canceled","product_id":"BCH-USD","price":"789.82000000","remaining_size":"0.01000000","sequence":4839271127,"time":"2018-07-27T01:32:39.002000Z"}
{"type":"received","order_id":"eab17fc5-86e8-48a1-a2df-43a4decc2e9d","order_type":"limit","size":"0.26091200","price":"790.16000000","side":"buy","client_oid":"df1e62d8-b72c-4b41-bc34-c42130806e28","product_id":"BCH-USD","sequence":4839271128,"time":"2018-07-27T01:32:39.002000Z"}
{"type":"open","side":"buy","price":"790.16000000","order_id":"eab17fc5-86e8-48a1-a2df-43a4decc2e9d","remaining_size":"0.26091200","product_id":"BCH-USD","sequence":4839271129,"time":"2018-07-27T01:32:39.002000Z"}
{"type":"done","side":"sell","order_id":"aec64a3f-874d-4586-9e0e-70892275565f","reason":"canceled","product_id":"BCH-USD","price":"795.29000000","remaining_size":"4.50000000","sequence":4839271130,"time":"2018-07-27T01:32:39.006000Z"}
{"type":"done","side":"sell","order_id":"51e41c2e-b7f9-484e-9a42-8ba52ce134ed","reason":"canceled","product_id":"BCH-USD","price":"795.29000000","remaining_size":"1.90000000","sequence":4839271131,"time":"2018-07-27T01:32:39.007000Z"}
{"type":"received","order_id":"c57c4366-4123-4315-988a-049524345691","order_type":"limit","size":"2.00000000","price":"792.53000000","side":"buy","client_oid":"01cb3dc6-a298-40ac-864f-13d454cf6fa3","product_id":"BCH-USD","sequence":4839271132,"time":"2018-07-27T01:32:39.008000Z"}
{"type":"open","side":"buy","price":"792.53000000","order_id":"c57c4366-4123-4315-988a-049524345691","remaining_size":"2.00000000","product_id":"BCH-USD","sequence":4839271133,"time":"2018-07-27T01:32:39.008000Z"}
{"type":"received","order_id":"8c7efa92-6992-4500-ae19-c864f17f438d","order_type":"limit","size":"4.50000000","price":"795.28000000","side":"sell","client_oid":"8863909b-9a0b-4de8-be78-bf4f2b1df61f","product_id":"BCH-USD","sequence":4839271134,"time":"2018-07-27T01:32:39.012000Z"}
{"type":"open","side":"sell","price":"795.28000000","order_id":"8c7efa92-6992-4500-ae19-c864f17f438d","remaining_size":"4.50000000","product_id":"BCH-USD","sequence":4839271135,"time":"2018-07-27T01:32:39.012000Z"}
{"type":"received","order_id":"94e111bb-e407-46cf-b23b-edef2acf85c7","order_type":"limit","size":"0.24356000","price":"789.92000000","side":"buy","client_oid":"92354d43-0506-42a0-ae5d-8d55dfa8cd6c","product_id":"BCH-USD","sequence":4839271136,"time":"2018-07-27T01:32:39.015000Z"}
{"type":"open","side":"buy","price":"789.92000000","order_id":"94e111bb-e407-46cf-b23b-edef2acf85c7","remaining_size":"0.24356000","product_id":"BCH-USD","sequence":4839271137,"time":"2018-07-27T01:32:39.015000Z"}
{"type":"received","order_id":"c8299904-4e26-4b25-8d32-2c7ff1bb729f","order_type":"limit","size":"1.90000000","price":"795.28000000","side":"sell","client_oid":"0952d54a-5bbc-4c5f-b0e8-4d535bf8cb82","product_id":"BCH-USD","sequence":4839271138,"time":"2018-07-27T01:32:39.018000Z"}
{"type":"open","side":"sell","price":"795.28000000","order_id":"c8299904-4e26-4b25-8d32-2c7ff1bb729f","remaining_size":"1.90000000","product_id":"BCH-USD","sequence":4839271139,"time":"2018-07-27T01:32:39.018000Z"}
{"type":"done","side":"sell","order_id":"0a494da7-8da2-4519-824e-a132c5314a49","reason":"canceled","product_id":"BCH-USD","price":"794.64000000","remaining_size":"0.90000000","sequence":4839271140,"time":"2018-07-27T01:32:39.020000Z"}
{"type":"done","side":"sell","order_id":"8c7efa92-6992-4500-ae19-c864f17f438d","reason":"canceled","product_id":"BCH-USD","price":"795.28000000","remaining_size":"4.50000000","sequence":4839271141,"time":"2018-07-27T01:32:39.025000Z"}
{"type":"received","order_id":"36d1a06d-fc18-4f26-8f6f-13cc3873b763","order_type":"limit","size":"0.90000000","price":"794.61000000","side":"sell","client_oid":"7b05cf51-14a8-4d89-8d55-140e2dea7ee7","product_id":"BCH-USD","sequence":4839271142,"time":"2018-07-27T01:32:39.028000Z"}
{"type":"open","side":"sell","price":"794.61000000","order_id":"36d1a06d-fc18-4f26-8f6f-13cc3873b763","remaining_size":"0.90000000","product_id":"BCH-USD","sequence":4839271143,"time":"2018-07-27T01:32:39.028000Z"}
{"type":"done","side":"sell","order_id":"c8299904-4e26-4b25-8d32-2c7ff1bb729f","reason":"canceled","product_id":"BCH-USD","price":"795.28000000","remaining_size":"1.90000000","sequence":4839271144,"time":"2018-07-27T01:32:39.031000Z"}
{"type":"received","order_id":"4e41bbf7-6afd-45f3-b1a0-3f5e45d4bf3c","order_type":"limit","size":"0.13292500","price":"789.68000000","side":"buy","client_oid":"6e34d023-98e7-496f-9311-1af2ad5c2134","product_id":"BCH-USD","sequence":4839271145,"time":"2018-07-27T01:32:39.033000Z"}
{"type":"open","side":"buy","price":"789.68000000","order_id":"4e41bbf7-6afd-45f3-b1a0-3f5e45d4bf3c","remaining_size":"0.13292500","product_id":"BCH-USD","sequence":4839271146,"time":"2018-07-27T01:32:39.033000Z"}
{"type":"received","order_id":"69b42a19-145c-486a-9ecb-9ceaecb2ebb8","order_type":"limit","size":"1.90000000","price":"795.29000000","side":"sell","client_oid":"fb9e2e10-7e9e-4b2e-8f8c-dbd9b8211261","product_id":"BCH-USD","sequence":4839271147,"time":"2018-07-27T01:32:39.034000Z"}
{"type":"open","side":"sell","price":"795.29000000","order_id":"69b42a19-145c-486a-9ecb-9ceaecb2ebb8","remaining_size":"1.90000000","product_id":"BCH-USD","sequence":4839271148,"time":"2018-07-27T01:32:39.034000Z"}
{"type":"received","order_id":"824081f3-e052-4f84-9ae4-7f749b01bdfb","order_type":"limit","size":"4.50000000","price":"795.29000000","side":"sell","client_oid":"37b56c98-206e-482b-8c0b-70dc3eb1dd0a","product_id":"BCH-USD","sequence":4839271149,"time":"2018-07-27T01:32:39.035000Z"}
{"type":"open","side":"sell","price":"795.29000000","order_id":"824081f3-e052-4f84-9ae4-7f749b01bdfb","remaining_size":"4.50000000","product_id":"BCH-USD","sequence":4839271150,"time":"2018-07-27T01:32:39.035000Z"}
{"type":"done","side":"sell","order_id":"69b42a19-145c-486a-9ecb-9ceaecb2ebb8","reason":"canceled","product_id":"BCH-USD","price":"795.29000000","remaining_size":"1.90000000","sequence":4839271151,"time":"2018-07-27T01:32:39.038000Z"}
{"type":"done","side":"sell","order_id":"824081f3-e052-4f84-9ae4-7f749b01bdfb","reason":"canceled","product_id":"BCH-USD","price":"795.29000000","remaining_size":"4.50000000","sequence":4839271152,"time":"2018-07-27T01:32:39.040000Z"}
{"type":"done","side":"sell","order_id":"b0dc30b9-e7c5-4f25-a5df-43c6be1ac7a5","reason":"canceled","product_id":"LTC-USD","price":"83.30000000","remaining_size":"7.44874862","sequence":2423271626,"time":"2018-07-27T01:32:39.044000Z"}
{"type":"received","order_id":"9787d530-8ef6-4cf2-9a03-72b702ef3613","order_type":"limit","size":"0.20120600","price":"789.20000000","side":"buy","client_oid":"18fc4ae1-2ae4-4994-a60b-6ba4d7fb1f69","product_id":"BCH-USD","sequence":4839271153,"time":"2018-07-27T01:32:39.043000Z"}
{"type":"open","side":"buy","price":"789.20000000","order_id":"9787d530-8ef6-4cf2-9a03-72b702ef3613","remaining_size":"0.20120600","product_id":"BCH-USD","sequence":4839271154,"time":"2018-07-27T01:32:39.043000Z"}
{"type":"received","order_id":"f749d22e-2049-4ce4-8744-69af44df15bf","order_type":"limit","size":"7.44874862","price":"83.38000000","side":"sell","client_oid":"e319efa2-d929-4eaf-8000-0080ab497f31","product_id":"LTC-USD","sequence":2423271627,"time":"2018-07-27T01:32:39.050000Z"}
{"type":"received","order_id":"a3a4af6b-84af-4d6e-9090-cb600574d8a9","order_type":"limit","size":"1.90000000","price":"795.27000000","side":"sell","client_oid":"4b312ee1-516e-4590-a1ee-3c92efa53122","product_id":"BCH-USD","sequence":4839271155,"time":"2018-07-27T01:32:39.048000Z"}
{"type":"open","side":"sell","price":"795.27000000","order_id":"a3a4af6b-84af-4d6e-9090-cb600574d8a9","remaining_size":"1.90000000","product_id":"BCH-USD","sequence":4839271156,"time":"2018-07-27T01:32:39.048000Z"}
{"type":"open","side":"sell","price":"83.38000000","order_id":"f749d22e-2049-4ce4-8744-69af44df15bf","remaining_size":"7.44874862","product_id":"LTC-USD","sequence":2423271628,"time":"2018-07-27T01:32:39.050000Z"}
{"type":"done","side":"buy","order_id":"adff1c95-66a0-4f00-adbb-b3da4b2b4061","reason":"canceled","product_id":"LTC-USD","price":"82.98000000","remaining_size":"20.00000000","sequence":2423271629,"time":"2018-07-27T01:32:39.053000Z"}
{"type":"done","side":"sell","order_id":"a3a4af6b-84af-4d6e-9090-cb600574d8a9","reason":"canceled","product_id":"BCH-USD","price":"795.27000000","remaining_size":"1.90000000","sequence":4839271157,"time":"2018-07-27T01:32:39.052000Z"}
{"type":"received","order_id":"f458748f-22ee-4c51-a014-49f1bd8c8d9f","order_type":"limit","size":"0.16068500","price":"788.96000000","side":"buy","client_oid":"8f76148b-8af7-4460-94b4-3acfd7ee74d3","product_id":"BCH-USD","sequence":4839271158,"time":"2018-07-27T01:32:39.054000Z"}
{"type":"open","side":"buy","price":"788.96000000","order_id":"f458748f-22ee-4c51-a014-49f1bd8c8d9f","remaining_size":"0.16068500","product_id":"BCH-USD","sequence":4839271159,"time":"2018-07-27T01:32:39.054000Z"}
{"type":"received","order_id":"b835154b-799a-4b7e-a1a4-802501ea1870","order_type":"limit","size":"4.50000000","price":"795.27000000","side":"sell","client_oid":"1e514ba0-ea44-43d4-aa7e-1ecd2fdbaac1","product_id":"BCH-USD","sequence":4839271160,"time":"2018-07-27T01:32:39.055000Z"}
{"type":"open","side":"sell","price":"795.27000000","order_id":"b835154b-799a-4b7e-a1a4-802501ea1870","remaining_size":"4.50000000","product_id":"BCH-USD","sequence":4839271161,"time":"2018-07-27T01:32:39.055000Z"}
{"type":"received","order_id":"ecf2cbb5-31da-4220-9834-b32d8d56b32e","order_type":"limit","size":"1.90000000","price":"795.29000000","side":"sell","client_oid":"fff35964-177e-4c58-831c-5df9ccfe500b","product_id":"BCH-USD","sequence":4839271162,"time":"2018-07-27T01:32:39.062000Z"}
{"type":"open","side":"sell","price":"795.29000000","order_id":"ecf2cbb5-31da-4220-9834-b32d8d56b32e","remaining_size":"1.90000000","product_id":"BCH-USD","sequence":4839271163,"time":"2018-07-27T01:32:39.062000Z"}
{"type":"received","order_id":"ffde1876-8bcc-407a-a748-d307b58c2c62","order_type":"limit","size":"0.34862100","price":"788.72000000","side":"buy","client_oid":"84db4230-6c5c-41b9-beee-56978998b1bb","product_id":"BCH-USD","sequence":4839271164,"time":"2018-07-27T01:32:39.064000Z"}
{"type":"received","order_id":"51215ac5-9aee-4ae5-a0e3-981278de7f49","order_type":"limit","size":"20.00000000","price":"82.99000000","side":"buy","client_oid":"7a19b0dc-c8c5-4719-938c-0d89712a0e00","product_id":"LTC-USD","sequence":2423271630,"time":"2018-07-27T01:32:39.066000Z"}
{"type":"open","side":"buy","price":"788.72000000","order_id":"ffde1876-8bcc-407a-a748-d307b58c2c62","remaining_size":"0.34862100","product_id":"BCH-USD","sequence":4839271165,"time":"2018-07-27T01:32:39.064000Z"}
{"type":"open","side":"buy","price":"82.99000000","order_id":"51215ac5-9aee-4ae5-a0e3-981278de7f49","remaining_size":"20.00000000","product_id":"LTC-USD","sequence":2423271631,"time":"2018-07-27T01:32:39.066000Z"}
{"type":"done","side":"sell","order_id":"954b2137-19cf-4e7e-830f-d9a74f393cd0","reason":"canceled","product_id":"BCH-USD","price":"794.62000000","remaining_size":"0.90000000","sequence":4839271166,"time":"2018-07-27T01:32:39.068000Z"}
{"type":"done","side":"sell","order_id":"c8e650a5-3a4e-4f7e-adc6-2585b705acf8","reason":"canceled","product_id":"BCH-USD","price":"794.62000000","remaining_size":"4.50000000","sequence":4839271167,"time":"2018-07-27T01:32:39.068000Z"}
{"type":"done","side":"sell","order_id":"ecf2cbb5-31da-4220-9834-b32d8d56b32e","reason":"canceled","product_id":"BCH-USD","price":"795.29000000","remaining_size":"1.90000000","sequence":4839271168,"time":"2018-07-27T01:32:39.070000Z"}
{"type":"done","side":"sell","order_id":"05a38906-4a99-43f9-aa61-f99146df290e","reason":"canceled","product_id":"BCH-USD","price":"794.62000000","remaining_size":"1.90000000","sequence":4839271169,"time":"2018-07-27T01:32:39.071000Z"}
{"type":"received","order_id":"1d937f6a-766f-40b4-b0b5-be2695fefd69","order_type":"limit","size":"0.40003100","price":"788.48000000","side":"buy","client_oid":"449761d4-5ca9-48f0-b57f-8dbbd973baa3","product_id":"BCH-USD","sequence":4839271170,"time":"2018-07-27T01:32:39.073000Z"}
{"type":"open","side":"buy","price":"788.48000000","order_id":"1d937f6a-766f-40b4-b0b5-be2695fefd69","remaining_size":"0.40003100","product_id":"BCH-USD","sequence":4839271171,"time":"2018-07-27T01:32:39.073000Z"}
{"type":"received","order_id":"758b647d-c505-4bb9-8681-efb14f2e9714","order_type":"limit","size":"1.90000000","price":"794.61000000","side":"sell","client_oid":"4937dd51-8c35-42d2-99f4-21e3d52dcab7","product_id":"BCH-USD","sequence":4839271172,"time":"2018-07-27T01:32:39.075000Z"}
{"type":"open","side":"sell","price":"794.61000000","order_id":"758b647d-c505-4bb9-8681-efb14f2e9714","remaining_size":"1.90000000","product_id":"BCH-USD","sequence":4839271173,"time":"2018-07-27T01:32:39.075000Z"}
{"type":"done","side":"sell","order_id":"36d1a06d-fc18-4f26-8f6f-13cc3873b763","reason":"canceled","product_id":"BCH-USD","price":"794.61000000","remaining_size":"0.90000000","sequence":4839271174,"time":"2018-07-27T01:32:39.076000Z"}
{"type":"received","order_id":"7be1aaac-f288-4f97-9101-138cd37694ff","order_type":"limit","size":"1.90000000","price":"795.28000000","side":"sell","client_oid":"801d2bbe-cc8e-4a82-949a-3c6849e292e8","product_id":"BCH-USD","sequence":4839271175,"time":"2018-07-27T01:32:39.079000Z"}
{"type":"open","side":"sell","price":"795.28000000","order_id":"7be1aaac-f288-4f97-9101-138cd37694ff","remaining_size":"1.90000000","product_id":"BCH-USD","sequence":4839271176,"time":"2018-07-27T01:32:39.079000Z"}
{"type":"received","order_id":"14e9100b-94a7-41fb-9437-83805e6c4897","order_type":"limit","size":"4.50000000","price":"794.61000000","side":"sell","client_oid":"ac00d2d9-6fe7-422d-b503-c3b5554e7990","product_id":"BCH-USD","sequence":4839271177,"time":"2018-07-27T01:32:39.079000Z"}
{"type":"open","side":"sell","price":"794.61000000","order_id":"14e9100b-94a7-41fb-9437-83805e6c4897","remaining_size":"4.50000000","product_id":"BCH-USD","sequence":4839271178,"time":"2018-07-27T01:32:39.079000Z"}
{"type":"done","side":"sell","order_id":"7be1aaac-f288-4f97-9101-138cd37694ff","reason":"canceled","product_id":"BCH-USD","price":"795.28000000","remaining_size":"1.90000000","sequence":4839271179,"time":"2018-07-27T01:32:39.083000Z"}
{"type":"received","order_id":"9bee12bf-3a65-46f6-913c-c93748677cf3","order_type":"limit","size":"3.20636900","price":"788.24000000","side":"buy","client_oid":"848fef9b-ede5-41ae-93fc-910e883c9068","product_id":"BCH-USD","sequence":4839271180,"time":"2018-07-27T01:32:39.083000Z"}
{"type":"open","side":"buy","price":"788.24000000","order_id":"9bee12bf-3a65-46f6-913c-c93748677cf3","remaining_size":"3.20636900","product_id":"BCH-USD","sequence":4839271181,"time":"2018-07-27T01:32:39.083000Z"}
{"type":"received","order_id":"de5302fa-6949-4d9b-9585-d4c191221571","order_type":"limit","size":"0.90000000","price":"794.61000000","side":"sell","client_oid":"38e26b42-9fbf-48b5-a9e8-21ec5ea295ec","product_id":"BCH-USD","sequence":4839271182,"time":"2018-07-27T01:32:39.083000Z"}
{"type":"open","side":"sell","price":"794.61000000","order_id":"de5302fa-6949-4d9b-9585-d4c191221571","remaining_size":"0.90000000","product_id":"BCH-USD","sequence":4839271183,"time":"2018-07-27T01:32:39.083000Z"}
{"type":"done","side":"buy","order_id":"2a9fedef-3e7b-49e7-b24d-50da11cca642","reason":"canceled","product_id":"ETH-USD","price":"461.42000000","remaining_size":"6.00000000","sequence":4469354721,"time":"2018-07-27T01:32:39.088000Z"}
{"type":"received","order_id":"b4d808c0-46ef-43e6-8921-1faf04167812","order_type":"limit","size":"0.90000000","price":"794.64000000","side":"sell","client_oid":"f6b4b4b8-d7bb-4d5e-b229-cdf5771a88be","product_id":"BCH-USD","sequence":4839271184,"time":"2018-07-27T01:32:39.087000Z"}
{"type":"open","side":"sell","price":"794.64000000","order_id":"b4d808c0-46ef-43e6-8921-1faf04167812","remaining_size":"0.90000000","product_id":"BCH-USD","sequence":4839271185,"time":"2018-07-27T01:32:39.087000Z"}
{"type":"done","side":"sell","order_id":"61178d22-babe-463f-b377-d162e866ce9b","reason":"canceled","product_id":"LTC-USD","price":"83.34000000","remaining_size":"7.44874862","sequence":2423271632,"time":"2018-07-27T01:32:39.090000Z"}
{"type":"done","side":"sell","order_id":"758b647d-c505-4bb9-8681-efb14f2e9714","reason":"canceled","product_id":"BCH-USD","price":"794.61000000","remaining_size":"1.90000000","sequence":4839271186,"time":"2018-07-27T01:32:39.089000Z"}
{"type":"done","side":"buy","order_id":"654c0283-e5cc-4ac1-baee-f796b307c7b8","reason":"canceled","product_id":"ETH-USD","price":"461.39000000","remaining_size":"1.89103900","sequence":4469354722,"time":"2018-07-27T01:32:39.093000Z"}
{"type":"received","order_id":"477d9231-c697-4015-be3e-b9274c99f1d1","order_type":"limit","size":"1.90000000","price":"795.29000000","side":"sell","client_oid":"f4122a15-e1b1-48d0-a777-bb2acc9e56bc","product_id":"BCH-USD","sequence":4839271187,"time":"2018-07-27T01:32:39.094000Z"}
{"type":"open","side":"sell","price":"795.29000000","order_id":"477d9231-c697-4015-be3e-b9274c99f1d1","remaining_size":"1.90000000","product_id":"BCH-USD","sequence":4839271188,"time":"2018-07-27T01:32:39.094000Z"}
{"type":"received","order_id":"f225697b-9193-4ef3-90b9-eb4c63e0d28a","order_type":"limit","size":"0.26569600","price":"794.00000000","side":"sell","client_oid":"cff8f9c8-106c-4158-9565-633fa81ee4eb","product_id":"BCH-USD","sequence":4839271189,"time":"2018-07-27T01:32:39.094000Z"}
{"type":"open","side":"sell","price":"794.00000000","order_id":"f225697b-9193-4ef3-90b9-eb4c63e0d28a","remaining_size":"0.26569600","product_id":"BCH-USD","sequence":4839271190,"time":"2018-07-27T01:32:39.094000Z"}
{"type":"done","side":"sell","order_id":"b835154b-799a-4b7e-a1a4-802501ea1870","reason":"canceled","product_id":"BCH-USD","price":"795.27000000","remaining_size":"4.50000000","sequence":4839271191,"time":"2018-07-27T01:32:39.096000Z"}
{"type":"done","side":"sell","order_id":"b4d808c0-46ef-43e6-8921-1faf04167812","reason":"canceled","product_id":"BCH-USD","price":"794.64000000","remaining_size":"0.90000000","sequence":4839271192,"time":"2018-07-27T01:32:39.096000Z"}
{"type":"done","side":"sell","order_id":"de5302fa-6949-4d9b-9585-d4c191221571","reason":"canceled","product_id":"BCH-USD","price":"794.61000000","remaining_size":"0.90000000","sequence":4839271193,"time":"2018-07-27T01:32:39.096000Z"}
{"type":"done","side":"buy","order_id":"b690ab08-0b21-499d-b164-c1f53e757315","reason":"canceled","product_id":"ETH-USD","price":"461.25000000","remaining_size":"4.27174600","sequence":4469354723,"time":"2018-07-27T01:32:39.098000Z"}
{"type":"received","order_id":"efb5a54a-ea35-437b-bffa-60b8c346458f","order_type":"limit","size":"1.90000000","price":"794.64000000","side":"sell","client_oid":"09ee72f8-2dac-4a61-883f-dca2af36b194","product_id":"BCH-USD","sequence":4839271194,"time":"2018-07-27T01:32:39.099000Z"}
{"type":"open","side":"sell","price":"794.64000000","order_id":"efb5a54a-ea35-437b-bffa-60b8c346458f","remaining_size":"1.90000000","product_id":"BCH-USD","sequence":4839271195,"time":"2018-07-27T01:32:39.099000Z"}
{"type":"done","side":"sell","order_id":"14e9100b-94a7-41fb-9437-83805e6c4897","reason":"canceled","product_id":"BCH-USD","price":"794.61000000","remaining_size":"4.50000000","sequence":4839271196,"time":"2018-07-27T01:32:39.100000Z"}
{"type":"received","order_id":"1faa752a-feed-4eb8-9836-708e8aa70c43","order_type":"limit","size":"0.90000000","price":"794.60000000","side":"sell","client_oid":"d156581e-921a-43b3-ada7-8f9af852d15a","product_id":"BCH-USD","sequence":4839271197,"time":"2018-07-27T01:32:39.103000Z"}
{"type":"open","side":"sell","price":"794.60000000","order_id":"1faa752a-feed-4eb8-9836-708e8aa70c43","remaining_size":"0.90000000","product_id":"BCH-USD","sequence":4839271198,"time":"2018-07-27T01:32:39.103000Z"}
{"type":"done","side":"sell","order_id":"efb5a54a-ea35-437b-bffa-60b8c346458f","reason":"canceled","product_id":"BCH-USD","price":"794.64000000","remaining_size":"1.90000000","sequence":4839271199,"time":"2018-07-27T01:32:39.104000Z"}
{"type":"done","side":"buy","order_id":"e8c3b8be-1023-401e-9265-fc8629a3b9c8","reason":"canceled","product_id":"ETH-USD","price":"461.11000000","remaining_size":"12.33489100","sequence":4469354724,"time":"2018-07-27T01:32:39.105000Z"}
{"type":"received","order_id":"88cad714-ef69-42de-a095-31fe1c3a1f3b","order_type":"limit","size":"0.87123900","price":"795.67000000","side":"sell","client_oid":"a817a965-021a-43ec-88cc-c5257b84eb26","product_id":"BCH-USD","sequence":4839271200,"time":"2018-07-27T01:32:39.105000Z"}
{"type":"open","side":"sell","price":"795.67000000","order_id":"88cad714-ef69-42de-a095-31fe1c3a1f3b","remaining_size":"0.87123900","product_id":"BCH-USD","sequence":4839271201,"time":"2018-07-27T01:32:39.105000Z"}
{"type":"received","order_id":"c7613388-9cad-420a-abd5-69fc82cf25d0","order_type":"limit","size":"7.44874862","price":"83.30000000","side":"sell","client_oid":"c36ed21b-e6f7-4d35-8000-0050f45ceae8","product_id":"LTC-USD","sequence":2423271633,"time":"2018-07-27T01:32:39.110000Z"}
{"type":"received","order_id":"251dcdd1-d6c3-481e-be87-e719040df265","order_type":"limit","size":"0.90000000","price":"794.64000000","side":"sell","client_oid":"04a1a59d-6138-4109-9221-43beac06a8d0","product_id":"BCH-USD","sequence":4839271202,"time":"2018-07-27T01:32:39.109000Z"}
{"type":"open","side":"sell","price":"794.64000000","order_id":"251dcdd1-d6c3-481e-be87-e719040df265","remaining_size":"0.90000000","product_id":"BCH-USD","sequence":4839271203,"time":"2018-07-27T01:32:39.109000Z"}
{"type":"open","side":"sell","price":"83.30000000","order_id":"c7613388-9cad-420a-abd5-69fc82cf25d0","remaining_size":"7.44874862","product_id":"LTC-USD","sequence":2423271634,"time":"2018-07-27T01:32:39.110000Z"}
{"type":"done","side":"sell","order_id":"2d52ba0a-ce18-4154-b467-88b037a53752","reason":"canceled","product_id":"BCH-USD","price":"800.09000000","remaining_size":"7.40550000","sequence":4839271204,"time":"2018-07-27T01:32:39.109000Z"}
{"type":"received","order_id":"c74d1ba2-d4a0-40ca-ad8f-53f7c93adbe8","order_type":"limit","size":"4.50000000","price":"795.29000000","side":"sell","client_oid":"f4933807-db3a-4591-8939-751cdccaaadb","product_id":"BCH-USD","sequence":4839271205,"time":"2018-07-27T01:32:39.114000Z"}
{"type":"open","side":"sell","price":"795.29000000","order_id":"c74d1ba2-d4a0-40ca-ad8f-53f7c93adbe8","remaining_size":"4.50000000","product_id":"BCH-USD","sequence":4839271206,"time":"2018-07-27T01:32:39.114000Z"}
{"type":"done","side":"sell","order_id":"1faa752a-feed-4eb8-9836-708e8aa70c43","reason":"canceled","product_id":"BCH-USD","price":"794.60000000","remaining_size":"0.90000000","sequence":4839271207,"time":"2018-07-27T01:32:39.116000Z"}
{"type":"done","side":"sell","order_id":"c7613388-9cad-420a-abd5-69fc82cf25d0","reason":"canceled","product_id":"LTC-USD","price":"83.30000000","remaining_size":"7.44874862","sequence":2423271635,"time":"2018-07-27T01:32:39.135000Z"}
{"type":"done","side":"sell","order_id":"477d9231-c697-4015-be3e-b9274c99f1d1","reason":"canceled","product_id":"BCH-USD","price":"795.29000000","remaining_size":"1.90000000","sequence":4839271208,"time":"2018-07-27T01:32:39.137000Z"}
{"type":"done","side":"sell","order_id":"c74d1ba2-d4a0-40ca-ad8f-53f7c93adbe8","reason":"canceled","product_id":"BCH-USD","price":"795.29000000","remaining_size":"4.50000000","sequence":4839271209,"time":"2018-07-27T01:32:39.144000Z"}
{"type":"done","side":"buy","order_id":"51215ac5-9aee-4ae5-a0e3-981278de7f49","reason":"canceled","product_id":"LTC-USD","price":"82.99000000","remaining_size":"20.00000000","sequence":2423271636,"time":"2018-07-27T01:32:39.177000Z"}
{"type":"received","order_id":"75131fc2-fc5e-4729-8532-bfdc6427e21d","order_type":"limit","size":"1.90000000","price":"794.60000000","side":"sell","client_oid":"10c9407b-febc-4381-9ebb-aea7ead6ff99","product_id":"BCH-USD","sequence":4839271210,"time":"2018-07-27T01:32:39.178000Z"}
{"type":"open","side":"sell","price":"794.60000000","order_id":"75131fc2-fc5e-4729-8532-bfdc6427e21d","remaining_size":"1.90000000","product_id":"BCH-USD","sequence":4839271211,"time":"2018-07-27T01:32:39.178000Z"}
{"type":"done","side":"buy","order_id":"9de2f16d-0010-42b4-8b29-e879ecbc8ba5","reason":"canceled","product_id":"ETH-USD","price":"460.92000000","remaining_size":"14.24999000","sequence":4469354725,"time":"2018-07-27T01:32:39.180000Z"}
{"type":"received","order_id":"502b75aa-091d-4a1a-af3f-33e816c4cffd","order_type":"limit","size":"4.50000000","price":"794.64000000","side":"sell","client_oid":"55db905e-2d70-492a-aa5e-0397e01b8031","product_id":"BCH-USD","sequence":4839271212,"time":"2018-07-27T01:32:39.180000Z"}
{"type":"open","side":"sell","price":"794.64000000","order_id":"502b75aa-091d-4a1a-af3f-33e816c4cffd","remaining_size":"4.50000000","product_id":"BCH-USD","sequence":4839271213,"time":"2018-07-27T01:32:39.180000Z"}
{"type":"received","order_id":"e932c9e7-8444-433d-a34b-9291a6b96cdd","order_type":"limit","size":"0.90000000","price":"794.64000000","side":"sell","client_oid":"86354d03-b5bc-497b-906c-b58a40b26fdd","product_id":"BCH-USD","sequence":4839271214,"time":"2018-07-27T01:32:39.181000Z"}
{"type":"open","side":"sell","price":"794.64000000","order_id":"e932c9e7-8444-433d-a34b-9291a6b96cdd","remaining_size":"0.90000000","product_id":"BCH-USD","sequence":4839271215,"time":"2018-07-27T01:32:39.181000Z"}
{"type":"done","side":"sell","order_id":"b3f625e6-21fb-4d74-a6ed-3d3ba96c8548","reason":"canceled","product_id":"BCH-USD","price":"795.81000000","remaining_size":"74.00000000","sequence":4839271216,"time":"2018-07-27T01:32:39.182000Z"}
{"type":"received","order_id":"4a80b21a-a189-440a-8016-20958d7837fa","order_type":"limit","size":"7.44874862","price":"83.34000000","side":"sell","client_oid":"629b8fdf-a4dc-4998-8000-003e9043864c","product_id":"LTC-USD","sequence":2423271637,"time":"2018-07-27T01:32:39.184000Z"}
{"type":"received","order_id":"df3ebdcb-b91a-425a-aba7-179801f95b0b","order_type":"limit","size":"6.00000000","price":"461.27000000","side":"buy","client_oid":"8d2242b3-1efc-4996-8142-1eaebbecc964","product_id":"ETH-USD","sequence":4469354726,"time":"2018-07-27T01:32:39.183000Z"}
{"type":"open","side":"buy","price":"461.27000000","order_id":"df3ebdcb-b91a-425a-aba7-179801f95b0b","remaining_size":"6.00000000","product_id":"ETH-USD","sequence":4469354727,"time":"2018-07-27T01:32:39.183000Z"}
{"type":"open","side":"sell","price":"83.34000000","order_id":"4a80b21a-a189-440a-8016-20958d7837fa","remaining_size":"7.44874862","product_id":"LTC-USD","sequence":2423271638,"time":"2018-07-27T01:32:39.184000Z"}
{"type":"received","order_id":"d7d793ab-3d73-4f44-8ac1-ad21f4c17bb3","order_type":"limit","size":"1.93580600","price":"461.39000000","side":"buy","client_oid":"8effe240-17aa-4093-b75b-349430786a20","product_id":"ETH-USD","sequence":4469354728,"time":"2018-07-27T01:32:39.184000Z"}
{"type":"open","side":"buy","price":"461.39000000","order_id":"d7d793ab-3d73-4f44-8ac1-ad21f4c17bb3","remaining_size":"1.93580600","product_id":"ETH-USD","sequence":4469354729,"time":"2018-07-27T01:32:39.184000Z"}
{"type":"received","order_id":"706b8c9a-2233-4bfa-bd01-d24bca88fc11","order_type":"limit","size":"20.00000000","price":"82.98000000","side":"buy","client_oid":"267e105b-6983-42dc-9ebc-16a0c8d34dfd","product_id":"LTC-USD","sequence":2423271639,"time":"2018-07-27T01:32:39.186000Z"}
{"type":"open","side":"buy","price":"82.98000000","order_id":"706b8c9a-2233-4bfa-bd01-d24bca88fc11","remaining_size":"20.00000000","product_id":"LTC-USD","sequence":2423271640,"time":"2018-07-27T01:32:39.186000Z"}
{"type":"done","side":"sell","order_id":"75131fc2-fc5e-4729-8532-bfdc6427e21d","reason":"canceled","product_id":"BCH-USD","price":"794.60000000","remaining_size":"1.90000000","sequence":4839271217,"time":"2018-07-27T01:32:39.186000Z"}
{"type":"received","order_id":"d71f5be1-f13f-4987-89f0-64110864b2ff","order_type":"limit","size":"1.90000000","price":"795.28000000","side":"sell","client_oid":"72dd64d5-2b73-4c6f-ae7f-0de534791a0b","product_id":"BCH-USD","sequence":4839271218,"time":"2018-07-27T01:32:39.186000Z"}
{"type":"open","side":"sell","price":"795.28000000","order_id":"d71f5be1-f13f-4987-89f0-64110864b2ff","remaining_size":"1.90000000","product_id":"BCH-USD","sequence":4839271219,"time":"2018-07-27T01:32:39.186000Z"}
{"type":"received","order_id":"97f2981b-5f92-49c1-ac48-bc8d0818fd8c","order_type":"limit","size":"28.00000000","price":"794.00000000","side":"sell","client_oid":"16d0611a-c6c7-4239-922e-39daf3b92b66","product_id":"BCH-USD","sequence":4839271220,"time":"2018-07-27T01:32:39.189000Z"}
{"type":"open","side":"sell","price":"794.00000000","order_id":"97f2981b-5f92-49c1-ac48-bc8d0818fd8c","remaining_size":"28.00000000","product_id":"BCH-USD","sequence":4839271221,"time":"2018-07-27T01:32:39.189000Z"}
{"type":"received","order_id":"5cfd17c2-ab20-43b0-915c-769455a9409c","order_type":"limit","size":"4.50000000","price":"795.28000000","side":"sell","client_oid":"ebaf10e5-b8ff-420b-ae94-825130af339b","product_id":"BCH-USD","sequence":4839271222,"time":"2018-07-27T01:32:39.189000Z"}
{"type":"open","side":"sell","price":"795.28000000","order_id":"5cfd17c2-ab20-43b0-915c-769455a9409c","remaining_size":"4.50000000","product_id":"BCH-USD","sequence":4839271223,"time":"2018-07-27T01:32:39.189000Z"}
{"type":"done","side":"sell","order_id":"f749d22e-2049-4ce4-8744-69af44df15bf","reason":"canceled","product_id":"LTC-USD","price":"83.38000000","remaining_size":"7.44874862","sequence":2423271641,"time":"2018-07-27T01:32:39.192000Z"}
{"type":"done","side":"sell","order_id":"d71f5be1-f13f-4987-89f0-64110864b2ff","reason":"canceled","product_id":"BCH-USD","price":"795.28000000","remaining_size":"1.90000000","sequence":4839271224,"time":"2018-07-27T01:32:39.191000Z"}
{"type":"done","side":"buy","order_id":"706b8c9a-2233-4bfa-bd01-d24bca88fc11","reason":"canceled","product_id":"LTC-USD","price":"82.98000000","remaining_size":"20.00000000","sequence":2423271642,"time":"2018-07-27T01:32:39.194000Z"}
{"type":"done","side":"sell","order_id":"251dcdd1-d6c3-481e-be87-e719040df265","reason":"canceled","product_id":"BCH-USD","price":"794.64000000","remaining_size":"0.90000000","sequence":4839271225,"time":"2018-07-27T01:32:39.193000Z"}
{"type":"done","side":"sell","order_id":"5cfd17c2-ab20-43b0-915c-769455a9409c","reason":"canceled","product_id":"BCH-USD","price":"795.28000000","remaining_size":"4.50000000","sequence":4839271226,"time":"2018-07-27T01:32:39.194000Z"}
{"type":"done","side":"buy","order_id":"c57c4366-4123-4315-988a-049524345691","reason":"canceled","product_id":"BCH-USD","price":"792.53000000","remaining_size":"2.00000000","sequence":4839271227,"time":"2018-07-27T01:32:39.195000Z"}
{"type":"done","side":"sell","order_id":"f225697b-9193-4ef3-90b9-eb4c63e0d28a","reason":"canceled","product_id":"BCH-USD","price":"794.00000000","remaining_size":"0.26569600","sequence":4839271228,"time":"2018-07-27T01:32:39.195000Z"}
{"type":"received","order_id":"5c08cc3c-be1d-4979-b175-d2848b603d9d","order_type":"limit","size":"1.90000000","price":"794.64000000","side":"sell","client_oid":"77990daf-59e2-4f22-8b81-b424fd5d81d3","product_id":"BCH-USD","sequence":4839271229,"time":"2018-07-27T01:32:39.197000Z"}
{"type":"open","side":"sell","price":"794.64000000","order_id":"5c08cc3c-be1d-4979-b175-d2848b603d9d","remaining_size":"1.90000000","product_id":"BCH-USD","sequence":4839271230,"time":"2018-07-27T01:32:39.197000Z"}
{"type":"done","side":"sell","order_id":"e932c9e7-8444-433d-a34b-9291a6b96cdd","reason":"canceled","product_id":"BCH-USD","price":"794.64000000","remaining_size":"0.90000000","sequence":4839271231,"time":"2018-07-27T01:32:39.198000Z"}
{"type":"received","order_id":"8dd71629-8c32-427d-8252-d866e0703a91","order_type":"limit","size":"4.35140500","price":"461.25000000","side":"buy","client_oid":"23d9c95f-a8b5-4ba6-b43b-6565dc646dd8","product_id":"ETH-USD","sequence":4469354730,"time":"2018-07-27T01:32:39.199000Z"}
{"type":"received","order_id":"13d64a62-97ea-474f-8289-a3b308d986c6","order_type":"limit","size":"7.44874862","price":"83.30000000","side":"sell","client_oid":"3a370ad3-7428-4da9-8000-00f8af7e4599","product_id":"LTC-USD","sequence":2423271643,"time":"2018-07-27T01:32:39.200000Z"}
{"type":"open","side":"buy","price":"461.25000000","order_id":"8dd71629-8c32-427d-8252-d866e0703a91","remaining_size":"4.35140500","product_id":"ETH-USD","sequence":4469354731,"time":"2018-07-27T01:32:39.199000Z"}
{"type":"open","side":"sell","price":"83.30000000","order_id":"13d64a62-97ea-474f-8289-a3b308d986c6","remaining_size":"7.44874862","product_id":"LTC-USD","sequence":2423271644,"time":"2018-07-27T01:32:39.200000Z"}
{"type":"done","side":"sell","order_id":"88cad714-ef69-42de-a095-31fe1c3a1f3b","reason":"canceled","product_id":"BCH-USD","price":"795.67000000","remaining_size":"0.87123900","sequence":4839271232,"time":"2018-07-27T01:32:39.199000Z"}
{"type":"received","order_id":"2abbb8db-8eb0-4d79-9a27-27e062ec25ee","order_type":"limit","size":"20.00000000","price":"82.99000000","side":"buy","client_oid":"aa0f83e4-7162-4538-b531-9c52d28cda8d","product_id":"LTC-USD","sequence":2423271645,"time":"2018-07-27T01:32:39.205000Z"}
{"type":"received","order_id":"92e2cc2c-7332-43f6-8a29-1cec7380dfd7","order_type":"limit","size":"1.90000000","price":"795.29000000","side":"sell","client_oid":"4e36a5ae-8f71-4818-9730-28930eea1f67","product_id":"BCH-USD","sequence":4839271233,"time":"2018-07-27T01:32:39.203000Z"}
{"type":"open","side":"sell","price":"795.29000000","order_id":"92e2cc2c-7332-43f6-8a29-1cec7380dfd7","remaining_size":"1.90000000","product_id":"BCH-USD","sequence":4839271234,"time":"2018-07-27T01:32:39.203000Z"}
{"type":"open","side":"buy","price":"82.99000000","order_id":"2abbb8db-8eb0-4d79-9a27-27e062ec25ee","remaining_size":"20.00000000","product_id":"LTC-USD","sequence":2423271646,"time":"2018-07-27T01:32:39.205000Z"}
{"type":"done","side":"sell","order_id":"5c08cc3c-be1d-4979-b175-d2848b603d9d","reason":"canceled","product_id":"BCH-USD","price":"794.64000000","remaining_size":"1.90000000","sequence":4839271235,"time":"2018-07-27T01:32:39.205000Z"}
{"type":"done","side":"sell","order_id":"502b75aa-091d-4a1a-af3f-33e816c4cffd","reason":"canceled","product_id":"BCH-USD","price":"794.64000000","remaining_size":"4.50000000","sequence":4839271236,"time":"2018-07-27T01:32:39.205000Z"}
{"type":"received","order_id":"55505d68-21e4-4557-8d10-add5495dedbe","order_type":"limit","size":"12.21041400","price":"461.11000000","side":"buy","client_oid":"7efa56a6-efd5-457a-87c9-8e3228c448b6","product_id":"ETH-USD","sequence":4469354732,"time":"2018-07-27T01:32:39.209000Z"}
{"type":"open","side":"buy","price":"461.11000000","order_id":"55505d68-21e4-4557-8d10-add5495dedbe","remaining_size":"12.21041400","product_id":"ETH-USD","sequence":4469354733,"time":"2018-07-27T01:32:39.209000Z"}
{"type":"received","order_id":"cf0cf9e7-4e27-4992-897e-f0bac6a823e3","order_type":"limit","size":"4.50000000","price":"795.29000000","side":"sell","client_oid":"39d92ecf-28ea-48c4-891d-c11604110be8","product_id":"BCH-USD","sequence":4839271237,"time":"2018-07-27T01:32:39.209000Z"}
{"type":"open","side":"sell","price":"795.29000000","order_id":"cf0cf9e7-4e27-4992-897e-f0bac6a823e3","remaining_size":"4.50000000","product_id":"BCH-USD","sequence":4839271238,"time":"2018-07-27T01:32:39.209000Z"}
{"type":"received","order_id":"2bf2ef8c-fd1f-4312-b7c2-02c835c8f62d","order_type":"limit","size":"0.90000000","price":"794.63000000","side":"sell","client_oid":"9f68c719-68be-4cf6-a2c5-8809955b0809","product_id":"BCH-USD","sequence":4839271239,"time":"2018-07-27T01:32:39.210000Z"}
{"type":"open","side":"sell","price":"794.63000000","order_id":"2bf2ef8c-fd1f-4312-b7c2-02c835c8f62d","remaining_size":"0.90000000","product_id":"BCH-USD","sequence":4839271240,"time":"2018-07-27T01:32:39.210000Z"}
{"type":"received","order_id":"b3cca186-e593-4451-ac97-d53693473bb6","order_type":"limit","size":"2.00000000","price":"792.37000000","side":"buy","client_oid":"c97a48f9-3580-45ec-ac3c-9e88d2ce9384","product_id":"BCH-USD","sequence":4839271241,"time":"2018-07-27T01:32:39.211000Z"}
{"type":"open","side":"buy","price":"792.37000000","order_id":"b3cca186-e593-4451-ac97-d53693473bb6","remaining_size":"2.00000000","product_id":"BCH-USD","sequence":4839271242,"time":"2018-07-27T01:32:39.211000Z"}
{"type":"done","side":"sell","order_id":"4a80b21a-a189-440a-8016-20958d7837fa","reason":"canceled","product_id":"LTC-USD","price":"83.34000000","remaining_size":"7.44874862","sequence":2423271647,"time":"2018-07-27T01:32:39.214000Z"}
{"type":"done","side":"buy","order_id":"2abbb8db-8eb0-4d79-9a27-27e062ec25ee","reason":"canceled","product_id":"LTC-USD","price":"82.99000000","remaining_size":"20.00000000","sequence":2423271648,"time":"2018-07-27T01:32:39.216000Z"}
{"type":"received","order_id":"fcab52f8-dd6c-4b38-8cf2-feef5a6cce3d","order_type":"limit","size":"1.90000000","price":"794.63000000","side":"sell","client_oid":"a68fc5f8-0664-4988-aa3b-06d110ecfb5b","product_id":"BCH-USD","sequence":4839271243,"time":"2018-07-27T01:32:39.214000Z"}
{"type":"open","side":"sell","price":"794.63000000","order_id":"fcab52f8-dd6c-4b38-8cf2-feef5a6cce3d","remaining_size":"1.90000000","product_id":"BCH-USD","sequence":4839271244,"time":"2018-07-27T01:32:39.214000Z"}
{"type":"done","side":"buy","order_id":"b3cca186-e593-4451-ac97-d53693473bb6","reason":"canceled","product_id":"BCH-USD","price":"792.37000000","remaining_size":"2.00000000","sequence":4839271245,"time":"2018-07-27T01:32:39.215000Z"}
{"type":"received","order_id":"a45b0d21-2e0b-425e-b5b6-26ff0d8e9824","order_type":"limit","size":"0.90000000","price":"794.63000000","side":"sell","client_oid":"204abbc8-f614-463f-9a43-c2b772fb77bb","product_id":"BCH-USD","sequence":4839271246,"time":"2018-07-27T01:32:39.220000Z"}
{"type":"open","side":"sell","price":"794.63000000","order_id":"a45b0d21-2e0b-425e-b5b6-26ff0d8e9824","remaining_size":"0.90000000","product_id":"BCH-USD","sequence":4839271247,"time":"2018-07-27T01:32:39.220000Z"}
{"type":"received","order_id":"cc5ad262-332f-46bd-9ce1-b45889d3c000","order_type":"limit","size":"4.50000000","price":"794.63000000","side":"sell","client_oid":"e02feb40-a2da-4b74-b254-7f8da9b5c60b","product_id":"BCH-USD","sequence":4839271248,"time":"2018-07-27T01:32:39.220000Z"}
{"type":"open","side":"sell","price":"794.63000000","order_id":"cc5ad262-332f-46bd-9ce1-b45889d3c000","remaining_size":"4.50000000","product_id":"BCH-USD","sequence":4839271249,"time":"2018-07-27T01:32:39.220000Z"}
{"type":"received","order_id":"f18ded87-d573-413c-88b3-a16a2c7fe888","order_type":"limit","size":"2.00000000","price":"792.53000000","side":"buy","client_oid":"6056be85-0129-4b47-af86-51f74b700181","product_id":"BCH-USD","sequence":4839271250,"time":"2018-07-27T01:32:39.224000Z"}
{"type":"open","side":"buy","price":"792.53000000","order_id":"f18ded87-d573-413c-88b3-a16a2c7fe888","remaining_size":"2.00000000","product_id":"BCH-USD","sequence":4839271251,"time":"2018-07-27T01:32:39.224000Z"}
{"type":"received","order_id":"8a9ff45e-aede-4b44-8d00-35b147f59b1f","order_type":"limit","size":"20.00000000","price":"82.98000000","side":"buy","client_oid":"8787630d-202c-4922-8e8a-4a16f3b3eb0a","product_id":"LTC-USD","sequence":2423271649,"time":"2018-07-27T01:32:39.226000Z"}
{"type":"open","side":"buy","price":"82.98000000","order_id":"8a9ff45e-aede-4b44-8d00-35b147f59b1f","remaining_size":"20.00000000","product_id":"LTC-USD","sequence":2423271650,"time":"2018-07-27T01:32:39.226000Z"}
{"type":"received","order_id":"cc953afc-dcaf-44a0-95e5-9d5b457275b0","order_type":"limit","size":"7.44874862","price":"83.38000000","side":"sell","client_oid":"aaef2599-00b4-4dd6-8000-005ac2d863bf","product_id":"LTC-USD","sequence":2423271651,"time":"2018-07-27T01:32:39.228000Z"}
{"type":"done","side":"buy","order_id":"f18ded87-d573-413c-88b3-a16a2c7fe888","reason":"canceled","product_id":"BCH-USD","price":"792.53000000","remaining_size":"2.00000000","sequence":4839271252,"time":"2018-07-27T01:32:39.227000Z"}
{"type":"open","side":"sell","price":"83.38000000","order_id":"cc953afc-dcaf-44a0-95e5-9d5b457275b0","remaining_size":"7.44874862","product_id":"LTC-USD","sequence":2423271652,"time":"2018-07-27T01:32:39.228000Z"}
{"type":"done","side":"sell","order_id":"cc5ad262-332f-46bd-9ce1-b45889d3c000","reason":"canceled","product_id":"BCH-USD","price":"794.63000000","remaining_size":"4.50000000","sequence":4839271253,"time":"2018-07-27T01:32:39.236000Z"}
{"type":"done","side":"buy","order_id":"9708e76b-ef41-4fbc-819e-c471921451bf","reason":"canceled","product_id":"LTC-USD","price":"83.23000000","remaining_size":"20.00000000","sequence":2423271653,"time":"2018-07-27T01:32:39.241000Z"}
{"type":"done","side":"sell","order_id":"2bf2ef8c-fd1f-4312-b7c2-02c835c8f62d","reason":"canceled","product_id":"BCH-USD","price":"794.63000000","remaining_size":"0.90000000","sequence":4839271254,"time":"2018-07-27T01:32:39.240000Z"}
{"type":"done","side":"buy","order_id":"9c8760f9-48d1-48c0-a5a4-b9238a51befb","reason":"canceled","product_id":"BTC-USD","price":"7891.01000000","remaining_size":"0.20000000","sequence":6418130197,"time":"2018-07-27T01:32:39.242000Z"}
{"type":"received","order_id":"ca9833a9-0cbf-4ec1-8851-850b45f1bce0","order_type":"limit","size":"2.00000000","price":"792.37000000","side":"buy","client_oid":"797a073c-e55f-4644-a0d6-f240bfe9fb82","product_id":"BCH-USD","sequence":4839271255,"time":"2018-07-27T01:32:39.241000Z"}
{"type":"open","side":"buy","price":"792.37000000","order_id":"ca9833a9-0cbf-4ec1-8851-850b45f1bce0","remaining_size":"2.00000000","product_id":"BCH-USD","sequence":4839271256,"time":"2018-07-27T01:32:39.241000Z"}
{"type":"done","side":"sell","order_id":"a45b0d21-2e0b-425e-b5b6-26ff0d8e9824","reason":"canceled","product_id":"BCH-USD","price":"794.63000000","remaining_size":"0.90000000","sequence":4839271257,"time":"2018-07-27T01:32:39.242000Z"}
{"type":"done","side":"sell","order_id":"92e2cc2c-7332-43f6-8a29-1cec7380dfd7","reason":"canceled","product_id":"BCH-USD","price":"795.29000000","remaining_size":"1.90000000","sequence":4839271258,"time":"2018-07-27T01:32:39.244000Z"}
{"type":"done","side":"sell","order_id":"cf0cf9e7-4e27-4992-897e-f0bac6a823e3","reason":"canceled","product_id":"BCH-USD","price":"795.29000000","remaining_size":"4.50000000","sequence":4839271259,"time":"2018-07-27T01:32:39.244000Z"}
{"type":"received","order_id":"55f69e71-a9a9-4a2e-918e-9098a4d26e8f","order_type":"limit","size":"4.50000000","price":"794.62000000","side":"sell","client_oid":"d65995f2-c1c9-4cc2-b2c0-d83297d90401","product_id":"BCH-USD","sequence":4839271260,"time":"2018-07-27T01:32:39.246000Z"}
{"type":"open","side":"sell","price":"794.62000000","order_id":"55f69e71-a9a9-4a2e-918e-9098a4d26e8f","remaining_size":"4.50000000","product_id":"BCH-USD","sequence":4839271261,"time":"2018-07-27T01:32:39.246000Z"}
{"type":"received","order_id":"20926f14-30cf-4c85-9225-0285c2bddc93","order_type":"limit","size":"0.90000000","price":"794.62000000","side":"sell","client_oid":"ac9ce176-6b30-44ee-a330-3b3a77e8dc39","product_id":"BCH-USD","sequence":4839271262,"time":"2018-07-27T01:32:39.247000Z"}
{"type":"open","side":"sell","price":"794.62000000","order_id":"20926f14-30cf-4c85-9225-0285c2bddc93","remaining_size":"0.90000000","product_id":"BCH-USD","sequence":4839271263,"time":"2018-07-27T01:32:39.247000Z"}
{"type":"done","side":"buy","order_id":"ca9833a9-0cbf-4ec1-8851-850b45f1bce0","reason":"canceled","product_id":"BCH-USD","price":"792.37000000","remaining_size":"2.00000000","sequence":4839271264,"time":"2018-07-27T01:32:39.249000Z"}
{"type":"done","side":"sell","order_id":"fcab52f8-dd6c-4b38-8cf2-feef5a6cce3d","reason":"canceled","product_id":"BCH-USD","price":"794.63000000","remaining_size":"1.90000000","sequence":4839271265,"time":"2018-07-27T01:32:39.249000Z"}
{"type":"received","order_id":"0ce52e7f-85cb-495a-9eac-44ada696db90","order_type":"limit","size":"4.50000000","price":"795.28000000","side":"sell","client_oid":"e81a60d1-5362-484f-8b91-4196bb1b1920","product_id":"BCH-USD","sequence":4839271266,"time":"2018-07-27T01:32:39.251000Z"}
{"type":"open","side":"sell","price":"795.28000000","order_id":"0ce52e7f-85cb-495a-9eac-44ada696db90","remaining_size":"4.50000000","product_id":"BCH-USD","sequence":4839271267,"time":"2018-07-27T01:32:39.251000Z"}
{"type":"received","order_id":"81f35976-a01a-40b2-83b3-aed0d57bfca9","order_type":"limit","size":"14.98300000","price":"461.44000000","side":"buy","client_oid":"7f769cd8-a383-4f1c-bb71-5739d97d9267","product_id":"ETH-USD","sequence":4469354734,"time":"2018-07-27T01:32:39.252000Z"}
{"type":"open","side":"buy","price":"461.44000000","order_id":"81f35976-a01a-40b2-83b3-aed0d57bfca9","remaining_size":"14.98300000","product_id":"ETH-USD","sequence":4469354735,"time":"2018-07-27T01:32:39.252000Z"}
{"type":"done","side":"sell","order_id":"55f69e71-a9a9-4a2e-918e-9098a4d26e8f","reason":"canceled","product_id":"BCH-USD","price":"794.62000000","remaining_size":"4.50000000","sequence":4839271268,"time":"2018-07-27T01:32:39.257000Z"}
{"type":"received","order_id":"19d341c6-ffb3-4436-a0f0-51e44b064731","order_type":"limit","size":"0.90000000","price":"794.64000000","side":"sell","client_oid":"075b7898-6de9-4eae-b69b-d5d19c0dab5b","product_id":"BCH-USD","sequence":4839271269,"time":"2018-07-27T01:32:39.257000Z"}
{"type":"open","side":"sell","price":"794.64000000","order_id":"19d341c6-ffb3-4436-a0f0-51e44b064731","remaining_size":"0.90000000","product_id":"BCH-USD","sequence":4839271270,"time":"2018-07-27T01:32:39.257000Z"}
{"type":"received","order_id":"5cb0c1d5-f232-4d33-81db-7d6d1a6113e6","order_type":"limit","size":"4.50000000","price":"794.64000000","side":"sell","client_oid":"6d707a0f-8551-43a0-aa36-2fd3409e63f1","product_id":"BCH-USD","sequence":4839271271,"time":"2018-07-27T01:32:39.259000Z"}
