{"type":"received","order_id":"9e0f8a44-ae13-4a91-b172-9fa8d5853afd","order_type":"limit","size":"1.90000000","price":"795.17000000","side":"sell","client_oid":"cd102349-f2ab-4644-97b1-ba4af56864ac","product_id":"BCH-USD","sequence":4839271959,"time":"2018-07-27T01:32:40.186000Z"}
{"type":"open","side":"sell","price":"795.17000000","order_id":"9e0f8a44-ae13-4a91-b172-9fa8d5853afd","remaining_size":"1.90000000","product_id":"BCH-USD","sequence":4839271960,"time":"2018-07-27T01:32:40.186000Z"}
{"type":"received","order_id":"d3d725d0-ef4e-4a69-beb0-51fb3f90205c","order_type":"limit","size":"4.50000000","price":"795.16000000","side":"sell","client_oid":"526340b6-e00d-4aff-8d10-405f9a33e0d3","product_id":"BCH-USD","sequence":4839271961,"time":"2018-07-27T01:32:40.186000Z"}
{"type":"open","side":"sell","price":"795.16000000","order_id":"d3d725d0-ef4e-4a69-beb0-51fb3f90205c","remaining_size":"4.50000000","product_id":"BCH-USD","sequence":4839271962,"time":"2018-07-27T01:32:40.186000Z"}
{"type":"done","side":"buy","order_id":"ac93789d-fd29-43c8-bb5e-a432fb4c3574","reason":"canceled","product_id":"ETH-USD","price":"460.71000000","remaining_size":"14.24999000","sequence":4469354748,"time":"2018-07-27T01:32:40.188000Z"}
{"type":"done","side":"sell","order_id":"801981bd-1626-4995-9a88-caf7088cb45d","reason":"canceled","product_id":"BCH-USD","price":"795.28000000","remaining_size":"7.07900000","sequence":4839271963,"time":"2018-07-27T01:32:40.189000Z"}
{"type":"received","order_id":"9e230660-1482-4be5-8961-f3537f811db5","order_type":"limit","size":"1.81488800","price":"791.23000000","side":"buy","client_oid":"10560538-0e41-4654-95ea-9f95597a937c","product_id":"BCH-USD","sequence":4839271964,"time":"2018-07-27T01:32:40.190000Z"}
{"type":"open","side":"buy","price":"791.23000000","order_id":"9e230660-1482-4be5-8961-f3537f811db5","remaining_size":"1.81488800","product_id":"BCH-USD","sequence":4839271965,"time":"2018-07-27T01:32:40.190000Z"}
{"type":"done","side":"sell","order_id":"9e0f8a44-ae13-4a91-b172-9fa8d5853afd","reason":"canceled","product_id":"BCH-USD","price":"795.17000000","remaining_size":"1.90000000","sequence":4839271966,"time":"2018-07-27T01:32:40.190000Z"}
{"type":"done","side":"buy","order_id":"d7d793ab-3d73-4f44-8ac1-ad21f4c17bb3","reason":"canceled","product_id":"ETH-USD","price":"461.39000000","remaining_size":"1.93580600","sequence":4469354749,"time":"2018-07-27T01:32:40.193000Z"}
{"type":"received","order_id":"2e4bb13d-f7b0-4b34-9663-bf9ff55382dc","order_type":"limit","size":"4.50000000","price":"795.53000000","side":"sell","client_oid":"57029d8c-d63e-47e7-a54b-7461d7dfd42f","product_id":"BCH-USD","sequence":4839271967,"time":"2018-07-27T01:32:40.195000Z"}
{"type":"open","side":"sell","price":"795.53000000","order_id":"2e4bb13d-f7b0-4b34-9663-bf9ff55382dc","remaining_size":"4.50000000","product_id":"BCH-USD","sequence":4839271968,"time":"2018-07-27T01:32:40.195000Z"}
{"type":"done","side":"sell","order_id":"a7341887-a06f-446f-a8c6-b2aea54999db","reason":"canceled","product_id":"BCH-USD","price":"795.16000000","remaining_size":"1.90000000","sequence":4839271969,"time":"2018-07-27T01:32:40.195000Z"}
{"type":"done","side":"buy","order_id":"8dd71629-8c32-427d-8252-d866e0703a91","reason":"canceled","product_id":"ETH-USD","price":"461.25000000","remaining_size":"4.35140500","sequence":4469354750,"time":"2018-07-27T01:32:40.197000Z"}
{"type":"done","side":"sell","order_id":"d3d725d0-ef4e-4a69-beb0-51fb3f90205c","reason":"canceled","product_id":"BCH-USD","price":"795.16000000","remaining_size":"4.50000000","sequence":4839271970,"time":"2018-07-27T01:32:40.197000Z"}
{"type":"done","side":"sell","order_id":"d57f4f72-a762-4f3e-bd57-fbf3d34aa973","reason":"canceled","product_id":"BCH-USD","price":"795.17000000","remaining_size":"0.90000000","sequence":4839271971,"time":"2018-07-27T01:32:40.197000Z"}
{"type":"done","side":"buy","order_id":"55505d68-21e4-4557-8d10-add5495dedbe","reason":"canceled","product_id":"ETH-USD","price":"461.11000000","remaining_size":"12.21041400","sequence":4469354751,"time":"2018-07-27T01:32:40.200000Z"}
{"type":"done","side":"buy","order_id":"b61d0143-d8b9-41ca-956c-503b7c7916f1","reason":"canceled","product_id":"BCH-USD","price":"792.80000000","remaining_size":"2.00000000","sequence":4839271972,"time":"2018-07-27T01:32:40.199000Z"}
{"type":"done","side":"buy","order_id":"dcf67644-f96d-4a3d-8998-2b71cc39450a","reason":"canceled","product_id":"BCH-USD","price":"791.23000000","remaining_size":"0.18739300","sequence":4839271973,"time":"2018-07-27T01:32:40.200000Z"}
{"type":"received","order_id":"2fa25019-57a6-47b6-8357-5fb24bce1b50","order_type":"limit","size":"1.90000000","price":"795.17000000","side":"sell","client_oid":"8950289f-b585-425a-a66b-5e2d52f72e21","product_id":"BCH-USD","sequence":4839271974,"time":"2018-07-27T01:32:40.202000Z"}
{"type":"open","side":"sell","price":"795.17000000","order_id":"2fa25019-57a6-47b6-8357-5fb24bce1b50","remaining_size":"1.90000000","product_id":"BCH-USD","sequence":4839271975,"time":"2018-07-27T01:32:40.202000Z"}
{"type":"done","side":"buy","order_id":"9e230660-1482-4be5-8961-f3537f811db5","reason":"canceled","product_id":"BCH-USD","price":"791.23000000","remaining_size":"1.81488800","sequence":4839271976,"time":"2018-07-27T01:32:40.203000Z"}
{"type":"received","order_id":"52d89c54-2a79-4a32-8401-b995215ddc90","order_type":"limit","size":"0.18739300","price":"791.24000000","side":"buy","client_oid":"7766feba-b1ed-445a-ab5c-2f6c76b96ff3","product_id":"BCH-USD","sequence":4839271977,"time":"2018-07-27T01:32:40.206000Z"}
{"type":"open","side":"buy","price":"791.24000000","order_id":"52d89c54-2a79-4a32-8401-b995215ddc90","remaining_size":"0.18739300","product_id":"BCH-USD","sequence":4839271978,"time":"2018-07-27T01:32:40.206000Z"}
{"type":"received","order_id":"de05e658-5a2d-4bff-81eb-96238da1babc","order_type":"limit","size":"0.90000000","price":"795.16000000","side":"sell","client_oid":"5dde0c9d-e4b4-4a19-a54b-4e4b06e2fe30","product_id":"BCH-USD","sequence":4839271979,"time":"2018-07-27T01:32:40.208000Z"}
{"type":"open","side":"sell","price":"795.16000000","order_id":"de05e658-5a2d-4bff-81eb-96238da1babc","remaining_size":"0.90000000","product_id":"BCH-USD","sequence":4839271980,"time":"2018-07-27T01:32:40.208000Z"}
{"type":"done","side":"sell","order_id":"2fa25019-57a6-47b6-8357-5fb24bce1b50","reason":"canceled","product_id":"BCH-USD","price":"795.17000000","remaining_size":"1.90000000","sequence":4839271981,"time":"2018-07-27T01:32:40.208000Z"}
{"type":"received","order_id":"cbcc3243-7ae5-46d8-a5f0-0647d30889cc","order_type":"limit","size":"2.00000000","price":"794.00000000","side":"sell","client_oid":"1285e3ff-bf0d-47a3-9187-a2c7a1a86b06","product_id":"BCH-USD","sequence":4839271982,"time":"2018-07-27T01:32:40.208000Z"}
{"type":"open","side":"sell","price":"794.00000000","order_id":"cbcc3243-7ae5-46d8-a5f0-0647d30889cc","remaining_size":"2.00000000","product_id":"BCH-USD","sequence":4839271983,"time":"2018-07-27T01:32:40.208000Z"}
{"type":"done","side":"buy","order_id":"52d89c54-2a79-4a32-8401-b995215ddc90","reason":"canceled","product_id":"BCH-USD","price":"791.24000000","remaining_size":"0.18739300","sequence":4839271984,"time":"2018-07-27T01:32:40.211000Z"}
{"type":"done","side":"sell","order_id":"de05e658-5a2d-4bff-81eb-96238da1babc","reason":"canceled","product_id":"BCH-USD","price":"795.16000000","remaining_size":"0.90000000","sequence":4839271985,"time":"2018-07-27T01:32:40.211000Z"}
{"type":"received","order_id":"5626a2c9-24e4-44b2-afde-21e17e26575f","order_type":"limit","size":"4.50000000","price":"795.15000000","side":"sell","client_oid":"e2681745-2489-4403-9264-dbd1cb0653c6","product_id":"BCH-USD","sequence":4839271986,"time":"2018-07-27T01:32:40.212000Z"}
{"type":"open","side":"sell","price":"795.15000000","order_id":"5626a2c9-24e4-44b2-afde-21e17e26575f","remaining_size":"4.50000000","product_id":"BCH-USD","sequence":4839271987,"time":"2018-07-27T01:32:40.212000Z"}
{"type":"received","order_id":"d29f6868-b355-4f07-88c7-2748ce27a51e","order_type":"limit","size":"0.05057844","price":"494.28000000","side":"buy","client_oid":"66b1d579-f1ea-42b1-aaaf-46e6a58b9ed2","product_id":"ETH-USD","sequence":4469354752,"time":"2018-07-27T01:32:40.213000Z"}
{"type":"match","trade_id":37930050,"maker_order_id":"dc99fe95-2fed-4fe4-90a1-6f1dd8b6c5fd","taker_order_id":"d29f6868-b355-4f07-88c7-2748ce27a51e","side":"sell","size":"0.05057844","price":"462.51000000","product_id":"ETH-USD","sequence":4469354753,"time":"2018-07-27T01:32:40.213000Z"}
{"type":"done","side":"buy","order_id":"d29f6868-b355-4f07-88c7-2748ce27a51e","reason":"filled","product_id":"ETH-USD","price":"494.28000000","remaining_size":"0.00000000","sequence":4469354754,"time":"2018-07-27T01:32:40.213000Z"}
{"type":"done","side":"sell","order_id":"2e4bb13d-f7b0-4b34-9663-bf9ff55382dc","reason":"canceled","product_id":"BCH-USD","price":"795.53000000","remaining_size":"4.50000000","sequence":4839271988,"time":"2018-07-27T01:32:40.214000Z"}
{"type":"received","order_id":"529b72e4-0981-4d7d-9338-c5e4e44bdd8b","order_type":"limit","size":"1.90000000","price":"795.16000000","side":"sell","client_oid":"dea45157-89db-477b-bbdf-22ee84a8da40","product_id":"BCH-USD","sequence":4839271989,"time":"2018-07-27T01:32:40.215000Z"}
{"type":"open","side":"sell","price":"795.16000000","order_id":"529b72e4-0981-4d7d-9338-c5e4e44bdd8b","remaining_size":"1.90000000","product_id":"BCH-USD","sequence":4839271990,"time":"2018-07-27T01:32:40.215000Z"}
{"type":"done","side":"sell","order_id":"f4e163e6-3247-4be6-8def-a43b5a98b474","reason":"canceled","product_id":"ETH-USD","price":"464.31000000","remaining_size":"8.29703000","sequence":4469354755,"time":"2018-07-27T01:32:40.217000Z"}
{"type":"done","side":"sell","order_id":"5626a2c9-24e4-44b2-afde-21e17e26575f","reason":"canceled","product_id":"BCH-USD","price":"795.15000000","remaining_size":"4.50000000","sequence":4839271991,"time":"2018-07-27T01:32:40.218000Z"}
{"type":"received","order_id":"0e46836b-e1e8-41a6-acbc-5a577d2553f5","order_type":"limit","size":"1.90000000","price":"795.15000000","side":"sell","client_oid":"fdc5c2d9-54a5-4d16-84ca-b4ffec148c19","product_id":"BCH-USD","sequence":4839271992,"time":"2018-07-27T01:32:40.220000Z"}
{"type":"open","side":"sell","price":"795.15000000","order_id":"0e46836b-e1e8-41a6-acbc-5a577d2553f5","remaining_size":"1.90000000","product_id":"BCH-USD","sequence":4839271993,"time":"2018-07-27T01:32:40.220000Z"}
{"type":"received","order_id":"49fa6f0b-e572-43c0-95a6-7e31803baa1f","order_type":"limit","size":"1.81488800","price":"791.24000000","side":"buy","client_oid":"5b032872-5a7a-4851-8741-7ba3ac3e9617","product_id":"BCH-USD","sequence":4839271994,"time":"2018-07-27T01:32:40.222000Z"}
{"type":"open","side":"buy","price":"791.24000000","order_id":"49fa6f0b-e572-43c0-95a6-7e31803baa1f","remaining_size":"1.81488800","product_id":"BCH-USD","sequence":4839271995,"time":"2018-07-27T01:32:40.222000Z"}
{"type":"done","side":"sell","order_id":"0e46836b-e1e8-41a6-acbc-5a577d2553f5","reason":"canceled","product_id":"BCH-USD","price":"795.15000000","remaining_size":"1.90000000","sequence":4839271996,"time":"2018-07-27T01:32:40.224000Z"}
{"type":"done","side":"buy","order_id":"49fa6f0b-e572-43c0-95a6-7e31803baa1f","reason":"canceled","product_id":"BCH-USD","price":"791.24000000","remaining_size":"1.81488800","sequence":4839271997,"time":"2018-07-27T01:32:40.226000Z"}
{"type":"received","order_id":"b6d198fe-6042-49d7-b13a-7b6849785cdf","order_type":"limit","size":"0.18739300","price":"791.23000000","side":"buy","client_oid":"f74ce986-60b3-40fd-9b2e-99c386679ee0","product_id":"BCH-USD","sequence":4839271998,"time":"2018-07-27T01:32:40.228000Z"}
{"type":"open","side":"buy","price":"791.23000000","order_id":"b6d198fe-6042-49d7-b13a-7b6849785cdf","remaining_size":"0.18739300","product_id":"BCH-USD","sequence":4839271999,"time":"2018-07-27T01:32:40.228000Z"}
{"type":"received","order_id":"c3816de9-3763-4c09-a88a-55a75b073cea","order_type":"limit","size":"2.00000000","price":"792.80000000","side":"buy","client_oid":"4abd3a57-a956-4bfe-88c3-2a9ad9ea08a2","product_id":"BCH-USD","sequence":4839272000,"time":"2018-07-27T01:32:40.228000Z"}
{"type":"open","side":"buy","price":"792.80000000","order_id":"c3816de9-3763-4c09-a88a-55a75b073cea","remaining_size":"2.00000000","product_id":"BCH-USD","sequence":4839272001,"time":"2018-07-27T01:32:40.228000Z"}
{"type":"received","order_id":"aedee6f6-4b56-4064-90db-a9a494b58e28","order_type":"limit","size":"0.90000000","price":"795.15000000","side":"sell","client_oid":"d3b12236-f6fb-4686-b77a-9dc3751972f4","product_id":"BCH-USD","sequence":4839272002,"time":"2018-07-27T01:32:40.229000Z"}
{"type":"open","side":"sell","price":"795.15000000","order_id":"aedee6f6-4b56-4064-90db-a9a494b58e28","remaining_size":"0.90000000","product_id":"BCH-USD","sequence":4839272003,"time":"2018-07-27T01:32:40.229000Z"}
{"type":"received","order_id":"6f80c9be-8064-45c4-9611-9833e3b28257","order_type":"limit","size":"2.11712000","price":"461.39000000","side":"buy","client_oid":"da418960-9adb-476d-a844-f525e7ed83f8","product_id":"ETH-USD","sequence":4469354756,"time":"2018-07-27T01:32:40.232000Z"}
{"type":"done","side":"buy","order_id":"c3816de9-3763-4c09-a88a-55a75b073cea","reason":"canceled","product_id":"BCH-USD","price":"792.80000000","remaining_size":"2.00000000","sequence":4839272004,"time":"2018-07-27T01:32:40.232000Z"}
{"type":"open","side":"buy","price":"461.39000000","order_id":"6f80c9be-8064-45c4-9611-9833e3b28257","remaining_size":"2.11712000","product_id":"ETH-USD","sequence":4469354757,"time":"2018-07-27T01:32:40.232000Z"}
{"type":"done","side":"sell","order_id":"aedee6f6-4b56-4064-90db-a9a494b58e28","reason":"canceled","product_id":"BCH-USD","price":"795.15000000","remaining_size":"0.90000000","sequence":4839272005,"time":"2018-07-27T01:32:40.233000Z"}
{"type":"received","order_id":"9b32116e-b2c4-405d-a94c-95ad21a2eb09","order_type":"limit","size":"4.50000000","price":"795.60000000","side":"sell","client_oid":"029c0705-2ff5-4d94-a3df-c61c8be97364","product_id":"BCH-USD","sequence":4839272006,"time":"2018-07-27T01:32:40.238000Z"}
{"type":"open","side":"sell","price":"795.60000000","order_id":"9b32116e-b2c4-405d-a94c-95ad21a2eb09","remaining_size":"4.50000000","product_id":"BCH-USD","sequence":4839272007,"time":"2018-07-27T01:32:40.238000Z"}
{"type":"done","side":"sell","order_id":"529b72e4-0981-4d7d-9338-c5e4e44bdd8b","reason":"canceled","product_id":"BCH-USD","price":"795.16000000","remaining_size":"1.90000000","sequence":4839272008,"time":"2018-07-27T01:32:40.238000Z"}
{"type":"done","side":"buy","order_id":"7713e782-71c9-443b-af65-880e2deecb17","reason":"canceled","product_id":"LTC-USD","price":"83.25000000","remaining_size":"20.00000000","sequence":2423271750,"time":"2018-07-27T01:32:40.241000Z"}
{"type":"done","side":"sell","order_id":"9b32116e-b2c4-405d-a94c-95ad21a2eb09","reason":"canceled","product_id":"BCH-USD","price":"795.60000000","remaining_size":"4.50000000","sequence":4839272009,"time":"2018-07-27T01:32:40.241000Z"}
{"type":"received","order_id":"52a535b8-d6ce-401b-98f6-93185d8956f7","order_type":"limit","size":"1.81488800","price":"791.23000000","side":"buy","client_oid":"3c22513f-e804-4e63-8de1-89f98635e5c8","product_id":"BCH-USD","sequence":4839272010,"time":"2018-07-27T01:32:40.243000Z"}
{"type":"open","side":"buy","price":"791.23000000","order_id":"52a535b8-d6ce-401b-98f6-93185d8956f7","remaining_size":"1.81488800","product_id":"BCH-USD","sequence":4839272011,"time":"2018-07-27T01:32:40.243000Z"}
{"type":"done","side":"sell","order_id":"9415b7a3-7078-4d3a-8aa1-c5a960188271","reason":"canceled","product_id":"LTC-USD","price":"83.29000000","remaining_size":"18.00110900","sequence":2423271751,"time":"2018-07-27T01:32:40.246000Z"}
{"type":"received","order_id":"47c4b2a4-1a34-4849-b64e-10fdab267ef5","order_type":"limit","size":"4.50000000","price":"795.17000000","side":"sell","client_oid":"3d55212f-fd68-44cb-9964-bca16b14e932","product_id":"BCH-USD","sequence":4839272012,"time":"2018-07-27T01:32:40.244000Z"}
{"type":"open","side":"sell","price":"795.17000000","order_id":"47c4b2a4-1a34-4849-b64e-10fdab267ef5","remaining_size":"4.50000000","product_id":"BCH-USD","sequence":4839272013,"time":"2018-07-27T01:32:40.244000Z"}
{"type":"received","order_id":"bb9e40b0-8473-4a8d-b229-8eb7611a6546","order_type":"limit","size":"4.13454100","price":"461.25000000","side":"buy","client_oid":"c6493da7-6570-4c20-ad41-f702dfcd20a7","product_id":"ETH-USD","sequence":4469354758,"time":"2018-07-27T01:32:40.246000Z"}
{"type":"received","order_id":"dfbfca87-851e-4fed-8929-170644d2a3c7","order_type":"limit","size":"2.00000000","price":"792.54000000","side":"buy","client_oid":"7bc662fa-1319-4092-afc2-3204bdb1d8b1","product_id":"BCH-USD","sequence":4839272014,"time":"2018-07-27T01:32:40.246000Z"}
{"type":"open","side":"buy","price":"461.25000000","order_id":"bb9e40b0-8473-4a8d-b229-8eb7611a6546","remaining_size":"4.13454100","product_id":"ETH-USD","sequence":4469354759,"time":"2018-07-27T01:32:40.246000Z"}
{"type":"open","side":"buy","price":"792.54000000","order_id":"dfbfca87-851e-4fed-8929-170644d2a3c7","remaining_size":"2.00000000","product_id":"BCH-USD","sequence":4839272015,"time":"2018-07-27T01:32:40.246000Z"}
{"type":"done","side":"sell","order_id":"8127dde2-09d1-41b7-bc8f-b893717ff5ea","reason":"canceled","product_id":"LTC-USD","price":"83.30000000","remaining_size":"19.24453700","sequence":2423271752,"time":"2018-07-27T01:32:40.250000Z"}
{"type":"received","order_id":"3cd85018-8b7c-45e3-9a13-ba986c74bbda","order_type":"limit","size":"20.00000000","price":"83.23000000","side":"buy","client_oid":"f24143d8-8a7b-46c2-87a3-87bbc60af34d","product_id":"LTC-USD","sequence":2423271753,"time":"2018-07-27T01:32:40.251000Z"}
{"type":"received","order_id":"5ab3bfac-bb8a-4d2c-b85f-7b075582fd44","order_type":"limit","size":"0.90000000","price":"795.17000000","side":"sell","client_oid":"e2fbbf31-0ac8-45b7-9707-139f86cc5089","product_id":"BCH-USD","sequence":4839272016,"time":"2018-07-27T01:32:40.250000Z"}
{"type":"open","side":"buy","price":"83.23000000","order_id":"3cd85018-8b7c-45e3-9a13-ba986c74bbda","remaining_size":"20.00000000","product_id":"LTC-USD","sequence":2423271754,"time":"2018-07-27T01:32:40.251000Z"}
{"type":"open","side":"sell","price":"795.17000000","order_id":"5ab3bfac-bb8a-4d2c-b85f-7b075582fd44","remaining_size":"0.90000000","product_id":"BCH-USD","sequence":4839272017,"time":"2018-07-27T01:32:40.250000Z"}
{"type":"received","order_id":"ef9f7929-7dbd-4602-8f8f-1a0b5b5cdb43","order_type":"limit","size":"1.90000000","price":"795.17000000","side":"sell","client_oid":"a374ece2-3764-4326-be78-a02fab145b81","product_id":"BCH-USD","sequence":4839272018,"time":"2018-07-27T01:32:40.251000Z"}
{"type":"open","side":"sell","price":"795.17000000","order_id":"ef9f7929-7dbd-4602-8f8f-1a0b5b5cdb43","remaining_size":"1.90000000","product_id":"BCH-USD","sequence":4839272019,"time":"2018-07-27T01:32:40.251000Z"}
{"type":"done","side":"sell","order_id":"235239ba-2fd8-410f-aab2-8dcef236ff90","reason":"canceled","product_id":"LTC-USD","price":"83.32000000","remaining_size":"15.66918000","sequence":2423271755,"time":"2018-07-27T01:32:40.254000Z"}
{"type":"done","side":"buy","order_id":"52a535b8-d6ce-401b-98f6-93185d8956f7","reason":"canceled","product_id":"BCH-USD","price":"791.23000000","remaining_size":"1.81488800","sequence":4839272020,"time":"2018-07-27T01:32:40.254000Z"}
{"type":"done","side":"sell","order_id":"49319d4b-32e5-4e64-87b9-42a0243f228f","reason":"canceled","product_id":"LTC-USD","price":"83.34000000","remaining_size":"95.46385100","sequence":2423271756,"time":"2018-07-27T01:32:40.257000Z"}
{"type":"received","order_id":"e798b674-940c-4b47-ae76-aa4014dc9db2","order_type":"limit","size":"12.05302100","price":"461.11000000","side":"buy","client_oid":"e675e5b0-aa2c-4fb4-9fbd-21fb8c55d778","product_id":"ETH-USD","sequence":4469354760,"time":"2018-07-27T01:32:40.257000Z"}
{"type":"received","order_id":"bfbf0c50-08b7-4743-815a-c3d5ffd2fca8","order_type":"limit","size":"1.90000000","price":"795.17000000","side":"sell","client_oid":"2d6c0962-21a4-4267-88e4-e873b11a297c","product_id":"BCH-USD","sequence":4839272021,"time":"2018-07-27T01:32:40.256000Z"}
{"type":"open","side":"sell","price":"795.17000000","order_id":"bfbf0c50-08b7-4743-815a-c3d5ffd2fca8","remaining_size":"1.90000000","product_id":"BCH-USD","sequence":4839272022,"time":"2018-07-27T01:32:40.256000Z"}
{"type":"open","side":"buy","price":"461.11000000","order_id":"e798b674-940c-4b47-ae76-aa4014dc9db2","remaining_size":"12.05302100","product_id":"ETH-USD","sequence":4469354761,"time":"2018-07-27T01:32:40.257000Z"}
{"type":"done","side":"sell","order_id":"5ab3bfac-bb8a-4d2c-b85f-7b075582fd44","reason":"canceled","product_id":"BCH-USD","price":"795.17000000","remaining_size":"0.90000000","sequence":4839272023,"time":"2018-07-27T01:32:40.259000Z"}
{"type":"done","side":"sell","order_id":"6431448c-c656-465a-b80f-4fa6c37a9983","reason":"canceled","product_id":"LTC-USD","price":"83.37000000","remaining_size":"14.14913200","sequence":2423271757,"time":"2018-07-27T01:32:40.261000Z"}
{"type":"done","side":"sell","order_id":"d5b7e775-a690-4917-84f6-1a51dedb6cdf","reason":"canceled","product_id":"LTC-USD","price":"83.40000000","remaining_size":"11.48073900","sequence":2423271758,"time":"2018-07-27T01:32:40.265000Z"}
{"type":"done","side":"sell","order_id":"26055177-d5b2-416d-81dc-d3097128b2c9","reason":"canceled","product_id":"BCH-USD","price":"795.61000000","remaining_size":"1.60461000","sequence":4839272024,"time":"2018-07-27T01:32:40.266000Z"}
{"type":"done","side":"sell","order_id":"33f3384b-f484-4878-98ea-a82523c40963","reason":"canceled","product_id":"LTC-USD","price":"83.34000000","remaining_size":"7.44874862","sequence":2423271759,"time":"2018-07-27T01:32:40.268000Z"}
{"type":"received","order_id":"f4694ac8-4e03-45a0-b5cb-e948b3aa74cc","order_type":"limit","size":"0.19319100","price":"460.41000000","side":"buy","client_oid":"547a06ae-fccc-47b4-8931-b68287a43a6e","product_id":"ETH-USD","sequence":4469354762,"time":"2018-07-27T01:32:40.267000Z"}
{"type":"done","side":"sell","order_id":"f4bfa9d4-346e-4c9e-8a9a-aaf276ff7849","reason":"canceled","product_id":"LTC-USD","price":"83.43000000","remaining_size":"13.61311100","sequence":2423271760,"time":"2018-07-27T01:32:40.269000Z"}
{"type":"open","side":"buy","price":"460.41000000","order_id":"f4694ac8-4e03-45a0-b5cb-e948b3aa74cc","remaining_size":"0.19319100","product_id":"ETH-USD","sequence":4469354763,"time":"2018-07-27T01:32:40.267000Z"}
{"type":"done","side":"sell","order_id":"ef9f7929-7dbd-4602-8f8f-1a0b5b5cdb43","reason":"canceled","product_id":"BCH-USD","price":"795.17000000","remaining_size":"1.90000000","sequence":4839272025,"time":"2018-07-27T01:32:40.268000Z"}
{"type":"received","order_id":"073b4571-645e-4423-9af2-6e2a875deff9","order_type":"limit","size":"4.50000000","price":"795.67000000","side":"sell","client_oid":"13036651-6c18-4b6a-96d3-5836e8944384","product_id":"BCH-USD","sequence":4839272026,"time":"2018-07-27T01:32:40.268000Z"}
{"type":"open","side":"sell","price":"795.67000000","order_id":"073b4571-645e-4423-9af2-6e2a875deff9","remaining_size":"4.50000000","product_id":"BCH-USD","sequence":4839272027,"time":"2018-07-27T01:32:40.268000Z"}
{"type":"done","side":"sell","order_id":"47c4b2a4-1a34-4849-b64e-10fdab267ef5","reason":"canceled","product_id":"BCH-USD","price":"795.17000000","remaining_size":"4.50000000","sequence":4839272028,"time":"2018-07-27T01:32:40.270000Z"}
{"type":"done","side":"sell","order_id":"073b4571-645e-4423-9af2-6e2a875deff9","reason":"canceled","product_id":"BCH-USD","price":"795.67000000","remaining_size":"4.50000000","sequence":4839272029,"time":"2018-07-27T01:32:40.272000Z"}
{"type":"received","order_id":"8712758b-7c65-4061-aeab-0257819003af","order_type":"limit","size":"1.81488800","price":"791.24000000","side":"buy","client_oid":"7c90b6c4-5eda-4582-87b9-552dfb55fe16","product_id":"BCH-USD","sequence":4839272030,"time":"2018-07-27T01:32:40.274000Z"}
{"type":"open","side":"buy","price":"791.24000000","order_id":"8712758b-7c65-4061-aeab-0257819003af","remaining_size":"1.81488800","product_id":"BCH-USD","sequence":4839272031,"time":"2018-07-27T01:32:40.274000Z"}
{"type":"received","order_id":"7846e309-8f41-4717-8f94-920b4e1c5329","order_type":"limit","size":"4.50000000","price":"795.16000000","side":"sell","client_oid":"d2801887-03e2-42d4-b49b-f31519fe8b3e","product_id":"BCH-USD","sequence":4839272032,"time":"2018-07-27T01:32:40.275000Z"}
{"type":"open","side":"sell","price":"795.16000000","order_id":"7846e309-8f41-4717-8f94-920b4e1c5329","remaining_size":"4.50000000","product_id":"BCH-USD","sequence":4839272033,"time":"2018-07-27T01:32:40.275000Z"}
{"type":"done","side":"sell","order_id":"d2efacc9-001b-4f35-97f0-d8e4b6b26d77","reason":"canceled","product_id":"LTC-USD","price":"83.30000000","remaining_size":"7.44874862","sequence":2423271761,"time":"2018-07-27T01:32:40.278000Z"}
{"type":"received","order_id":"e4682230-2046-48a9-8ddf-924ec0a6f5e9","order_type":"limit","size":"1.90000000","price":"795.16000000","side":"sell","client_oid":"a652aa5a-3610-449b-8e2b-3b2d6a9e3c60","product_id":"BCH-USD","sequence":4839272034,"time":"2018-07-27T01:32:40.278000Z"}
{"type":"open","side":"sell","price":"795.16000000","order_id":"e4682230-2046-48a9-8ddf-924ec0a6f5e9","remaining_size":"1.90000000","product_id":"BCH-USD","sequence":4839272035,"time":"2018-07-27T01:32:40.278000Z"}
{"type":"done","side":"buy","order_id":"dfbfca87-851e-4fed-8929-170644d2a3c7","reason":"canceled","product_id":"BCH-USD","price":"792.54000000","remaining_size":"2.00000000","sequence":4839272036,"time":"2018-07-27T01:32:40.278000Z"}
{"type":"done","side":"buy","order_id":"8712758b-7c65-4061-aeab-0257819003af","reason":"canceled","product_id":"BCH-USD","price":"791.24000000","remaining_size":"1.81488800","sequence":4839272037,"time":"2018-07-27T01:32:40.278000Z"}
{"type":"done","side":"buy","order_id":"3cd85018-8b7c-45e3-9a13-ba986c74bbda","reason":"canceled","product_id":"LTC-USD","price":"83.23000000","remaining_size":"20.00000000","sequence":2423271762,"time":"2018-07-27T01:32:40.281000Z"}
{"type":"received","order_id":"cd9dd0c8-4e1c-46e9-9483-81c1998be3cf","order_type":"limit","size":"0.90000000","price":"795.16000000","side":"sell","client_oid":"07dfd871-c1be-4f33-b033-a8b3a2a11a3c","product_id":"BCH-USD","sequence":4839272038,"time":"2018-07-27T01:32:40.280000Z"}
{"type":"open","side":"sell","price":"795.16000000","order_id":"cd9dd0c8-4e1c-46e9-9483-81c1998be3cf","remaining_size":"0.90000000","product_id":"BCH-USD","sequence":4839272039,"time":"2018-07-27T01:32:40.280000Z"}
{"type":"done","side":"sell","order_id":"7846e309-8f41-4717-8f94-920b4e1c5329","reason":"canceled","product_id":"BCH-USD","price":"795.16000000","remaining_size":"4.50000000","sequence":4839272040,"time":"2018-07-27T01:32:40.282000Z"}
{"type":"received","order_id":"0726cb8e-0fc8-41fc-8875-293035c1b6f4","order_type":"limit","size":"7.44874862","price":"83.38000000","side":"sell","client_oid":"3725ef3e-17de-48c2-8000-079590fc4850","product_id":"LTC-USD","sequence":2423271763,"time":"2018-07-27T01:32:40.285000Z"}
{"type":"open","side":"sell","price":"83.38000000","order_id":"0726cb8e-0fc8-41fc-8875-293035c1b6f4","remaining_size":"7.44874862","product_id":"LTC-USD","sequence":2423271764,"time":"2018-07-27T01:32:40.285000Z"}
{"type":"done","side":"sell","order_id":"e4682230-2046-48a9-8ddf-924ec0a6f5e9","reason":"canceled","product_id":"BCH-USD","price":"795.16000000","remaining_size":"1.90000000","sequence":4839272041,"time":"2018-07-27T01:32:40.284000Z"}
{"type":"done","side":"sell","order_id":"bfbf0c50-08b7-4743-815a-c3d5ffd2fca8","reason":"canceled","product_id":"BCH-USD","price":"795.17000000","remaining_size":"1.90000000","sequence":4839272042,"time":"2018-07-27T01:32:40.286000Z"}
{"type":"received","order_id":"58f083fa-af83-4cb0-bb56-4bc21f9a6912","order_type":"limit","size":"4.50000000","price":"795.53000000","side":"sell","client_oid":"530ab579-2d9c-42d6-9eb7-f01837726873","product_id":"BCH-USD","sequence":4839272043,"time":"2018-07-27T01:32:40.287000Z"}
{"type":"open","side":"sell","price":"795.53000000","order_id":"58f083fa-af83-4cb0-bb56-4bc21f9a6912","remaining_size":"4.50000000","product_id":"BCH-USD","sequence":4839272044,"time":"2018-07-27T01:32:40.287000Z"}
{"type":"done","side":"buy","order_id":"b6d198fe-6042-49d7-b13a-7b6849785cdf","reason":"canceled","product_id":"BCH-USD","price":"791.23000000","remaining_size":"0.18739300","sequence":4839272045,"time":"2018-07-27T01:32:40.288000Z"}
{"type":"received","order_id":"bf077c41-9474-45fc-ba64-2959d56139cf","order_type":"limit","size":"1.81488800","price":"791.23000000","side":"buy","client_oid":"2f6916e6-3286-4229-8724-cd3c78467201","product_id":"BCH-USD","sequence":4839272046,"time":"2018-07-27T01:32:40.292000Z"}
{"type":"done","side":"sell","order_id":"19bd5c8d-d684-454c-b8ee-05edf6076bd3","reason":"canceled","product_id":"BTC-USD","price":"7939.20000000","remaining_size":"0.00100000","sequence":6418130223,"time":"2018-07-27T01:32:40.294000Z"}
{"type":"open","side":"buy","price":"791.23000000","order_id":"bf077c41-9474-45fc-ba64-2959d56139cf","remaining_size":"1.81488800","product_id":"BCH-USD","sequence":4839272047,"time":"2018-07-27T01:32:40.292000Z"}
{"type":"done","side":"sell","order_id":"7bbf41e2-e21a-47a3-b708-eeecab65b46c","reason":"canceled","product_id":"BTC-USD","price":"7907.18000000","remaining_size":"1.89141000","sequence":6418130224,"time":"2018-07-27T01:32:40.294000Z"}
{"type":"done","side":"sell","order_id":"cd9dd0c8-4e1c-46e9-9483-81c1998be3cf","reason":"canceled","product_id":"BCH-USD","price":"795.16000000","remaining_size":"0.90000000","sequence":4839272048,"time":"2018-07-27T01:32:40.295000Z"}
{"type":"received","order_id":"6708b4b9-a1d2-4a57-8b97-aa54528cd50a","order_type":"limit","size":"0.01000000","price":"462.23000000","side":"buy","client_oid":"817aef2d-204a-4858-aa58-d7b7856ac0f6","product_id":"ETH-USD","sequence":4469354764,"time":"2018-07-27T01:32:40.297000Z"}
{"type":"open","side":"buy","price":"462.23000000","order_id":"6708b4b9-a1d2-4a57-8b97-aa54528cd50a","remaining_size":"0.01000000","product_id":"ETH-USD","sequence":4469354765,"time":"2018-07-27T01:32:40.297000Z"}
{"type":"received","order_id":"abd9b069-978a-4c36-b67d-eae679dbf641","order_type":"limit","size":"2.00000000","price":"792.54000000","side":"buy","client_oid":"81c99df7-9ae1-4958-87ad-4b89b4a11e6b","product_id":"BCH-USD","sequence":4839272049,"time":"2018-07-27T01:32:40.297000Z"}
{"type":"open","side":"buy","price":"792.54000000","order_id":"abd9b069-978a-4c36-b67d-eae679dbf641","remaining_size":"2.00000000","product_id":"BCH-USD","sequence":4839272050,"time":"2018-07-27T01:32:40.297000Z"}
{"type":"received","order_id":"2ad65bbd-bb7a-4158-a34d-756bde5c8f15","order_type":"limit","size":"1.90000000","price":"795.16000000","side":"sell","client_oid":"275b150e-e92e-4511-a6e7-3b8b73331b3b","product_id":"BCH-USD","sequence":4839272051,"time":"2018-07-27T01:32:40.297000Z"}
{"type":"open","side":"sell","price":"795.16000000","order_id":"2ad65bbd-bb7a-4158-a34d-756bde5c8f15","remaining_size":"1.90000000","product_id":"BCH-USD","sequence":4839272052,"time":"2018-07-27T01:32:40.297000Z"}
{"type":"received","order_id":"e0f424fb-b0ed-4e40-8154-a97f23ce38ed","order_type":"limit","size":"4.50000000","price":"795.17000000","side":"sell","client_oid":"07b94901-6f17-42c6-9db9-3de895f26d24","product_id":"BCH-USD","sequence":4839272053,"time":"2018-07-27T01:32:40.298000Z"}
{"type":"open","side":"sell","price":"795.17000000","order_id":"e0f424fb-b0ed-4e40-8154-a97f23ce38ed","remaining_size":"4.50000000","product_id":"BCH-USD","sequence":4839272054,"time":"2018-07-27T01:32:40.298000Z"}
{"type":"done","side":"sell","order_id":"58f083fa-af83-4cb0-bb56-4bc21f9a6912","reason":"canceled","product_id":"BCH-USD","price":"795.53000000","remaining_size":"4.50000000","sequence":4839272055,"time":"2018-07-27T01:32:40.299000Z"}
{"type":"received","order_id":"c43e1c03-fad8-4638-bc56-6aef4fe3881a","order_type":"limit","size":"0.18739300","price":"791.25000000","side":"buy","client_oid":"c05b3242-1185-4a58-af8d-63ee4e00a3a6","product_id":"BCH-USD","sequence":4839272056,"time":"2018-07-27T01:32:40.300000Z"}
{"type":"open","side":"buy","price":"791.25000000","order_id":"c43e1c03-fad8-4638-bc56-6aef4fe3881a","remaining_size":"0.18739300","product_id":"BCH-USD","sequence":4839272057,"time":"2018-07-27T01:32:40.300000Z"}
{"type":"received","order_id":"7281f4e7-d7df-4fb2-861d-b39f5459eaa9","order_type":"limit","size":"1.89445000","price":"7907.59000000","side":"sell","client_oid":"0f5fdb05-b3ac-406d-8caa-4126164e27bd","product_id":"BTC-USD","sequence":6418130225,"time":"2018-07-27T01:32:40.304000Z"}
{"type":"received","order_id":"755647ef-4739-4a38-977b-058ca5a0ab7f","order_type":"limit","size":"20.00000000","price":"83.25000000","side":"buy","client_oid":"3521d5d1-e159-41e3-a5cf-c41dd87a5718","product_id":"LTC-USD","sequence":2423271765,"time":"2018-07-27T01:32:40.304000Z"}
{"type":"open","side":"sell","price":"7907.59000000","order_id":"7281f4e7-d7df-4fb2-861d-b39f5459eaa9","remaining_size":"1.89445000","product_id":"BTC-USD","sequence":6418130226,"time":"2018-07-27T01:32:40.304000Z"}
{"type":"open","side":"buy","price":"83.25000000","order_id":"755647ef-4739-4a38-977b-058ca5a0ab7f","remaining_size":"20.00000000","product_id":"LTC-USD","sequence":2423271766,"time":"2018-07-27T01:32:40.304000Z"}
{"type":"done","side":"buy","order_id":"abd9b069-978a-4c36-b67d-eae679dbf641","reason":"canceled","product_id":"BCH-USD","price":"792.54000000","remaining_size":"2.00000000","sequence":4839272058,"time":"2018-07-27T01:32:40.303000Z"}
{"type":"received","order_id":"6a4f0deb-1012-4426-a82e-42b8b78d0488","order_type":"limit","size":"0.90000000","price":"795.15000000","side":"sell","client_oid":"f268806c-076f-428c-84bc-0ded49ae7cb3","product_id":"BCH-USD","sequence":4839272059,"time":"2018-07-27T01:32:40.304000Z"}
{"type":"open","side":"sell","price":"795.15000000","order_id":"6a4f0deb-1012-4426-a82e-42b8b78d0488","remaining_size":"0.90000000","product_id":"BCH-USD","sequence":4839272060,"time":"2018-07-27T01:32:40.304000Z"}
{"type":"done","side":"buy","order_id":"bf077c41-9474-45fc-ba64-2959d56139cf","reason":"canceled","product_id":"BCH-USD","price":"791.23000000","remaining_size":"1.81488800","sequence":4839272061,"time":"2018-07-27T01:32:40.306000Z"}
{"type":"received","order_id":"41c947df-b132-4271-96c7-94b913bf28cd","order_type":"limit","size":"1.90000000","price":"795.17000000","side":"sell","client_oid":"d9b6f027-850d-4b00-928a-2c7001b6f437","product_id":"BCH-USD","sequence":4839272062,"time":"2018-07-27T01:32:40.307000Z"}
{"type":"open","side":"sell","price":"795.17000000","order_id":"41c947df-b132-4271-96c7-94b913bf28cd","remaining_size":"1.90000000","product_id":"BCH-USD","sequence":4839272063,"time":"2018-07-27T01:32:40.307000Z"}
{"type":"done","side":"sell","order_id":"6a4f0deb-1012-4426-a82e-42b8b78d0488","reason":"canceled","product_id":"BCH-USD","price":"795.15000000","remaining_size":"0.90000000","sequence":4839272064,"time":"2018-07-27T01:32:40.308000Z"}
{"type":"done","side":"buy","order_id":"c43e1c03-fad8-4638-bc56-6aef4fe3881a","reason":"canceled","product_id":"BCH-USD","price":"791.25000000","remaining_size":"0.18739300","sequence":4839272065,"time":"2018-07-27T01:32:40.309000Z"}
{"type":"received","order_id":"0f902fe5-79e3-4d38-b284-93ff3c0e873e","order_type":"limit","size":"7.44874862","price":"83.30000000","side":"sell","client_oid":"860247c6-2744-4c80-8000-00f31068d420","product_id":"LTC-USD","sequence":2423271767,"time":"2018-07-27T01:32:40.312000Z"}
{"type":"open","side":"sell","price":"83.30000000","order_id":"0f902fe5-79e3-4d38-b284-93ff3c0e873e","remaining_size":"7.44874862","product_id":"LTC-USD","sequence":2423271768,"time":"2018-07-27T01:32:40.312000Z"}
{"type":"done","side":"sell","order_id":"41c947df-b132-4271-96c7-94b913bf28cd","reason":"canceled","product_id":"BCH-USD","price":"795.17000000","remaining_size":"1.90000000","sequence":4839272066,"time":"2018-07-27T01:32:40.313000Z"}
{"type":"received","order_id":"680cdc02-8941-471a-9066-06cd0faf1855","order_type":"limit","size":"0.18739300","price":"791.23000000","side":"buy","client_oid":"721bf1af-7db3-4676-9dec-cd00b77a27de","product_id":"BCH-USD","sequence":4839272067,"time":"2018-07-27T01:32:40.314000Z"}
{"type":"open","side":"buy","price":"791.23000000","order_id":"680cdc02-8941-471a-9066-06cd0faf1855","remaining_size":"0.18739300","product_id":"BCH-USD","sequence":4839272068,"time":"2018-07-27T01:32:40.314000Z"}
{"type":"received","order_id":"994f0b05-7bfd-4b94-9442-0fb643872df7","order_type":"limit","size":"4.50000000","price":"795.68000000","side":"sell","client_oid":"6d62dcd8-ea95-426a-aa10-365d2168c263","product_id":"BCH-USD","sequence":4839272069,"time":"2018-07-27T01:32:40.315000Z"}
{"type":"open","side":"sell","price":"795.68000000","order_id":"994f0b05-7bfd-4b94-9442-0fb643872df7","remaining_size":"4.50000000","product_id":"BCH-USD","sequence":4839272070,"time":"2018-07-27T01:32:40.315000Z"}
{"type":"done","side":"sell","order_id":"a4f50309-4380-462a-b36d-aa5e41b7aa64","reason":"canceled","product_id":"BCH-USD","price":"795.19000000","remaining_size":"3.00000000","sequence":4839272071,"time":"2018-07-27T01:32:40.315000Z"}
{"type":"received","order_id":"3b616e25-1541-45cc-bd84-10e3b3e7e07a","order_type":"limit","size":"0.90000000","price":"795.17000000","side":"sell","client_oid":"dcfe3677-aee9-43e6-a635-cfdedc0362ee","product_id":"BCH-USD","sequence":4839272072,"time":"2018-07-27T01:32:40.317000Z"}
{"type":"open","side":"sell","price":"795.17000000","order_id":"3b616e25-1541-45cc-bd84-10e3b3e7e07a","remaining_size":"0.90000000","product_id":"BCH-USD","sequence":4839272073,"time":"2018-07-27T01:32:40.317000Z"}
{"type":"done","side":"buy","order_id":"680cdc02-8941-471a-9066-06cd0faf1855","reason":"canceled","product_id":"BCH-USD","price":"791.23000000","remaining_size":"0.18739300","sequence":4839272074,"time":"2018-07-27T01:32:40.318000Z"}
{"type":"done","side":"sell","order_id":"994f0b05-7bfd-4b94-9442-0fb643872df7","reason":"canceled","product_id":"BCH-USD","price":"795.68000000","remaining_size":"4.50000000","sequence":4839272075,"time":"2018-07-27T01:32:40.319000Z"}
{"type":"done","side":"sell","order_id":"3b616e25-1541-45cc-bd84-10e3b3e7e07a","reason":"canceled","product_id":"BCH-USD","price":"795.17000000","remaining_size":"0.90000000","sequence":4839272076,"time":"2018-07-27T01:32:40.321000Z"}
{"type":"received","order_id":"ee73983c-88ab-4c9a-adb1-b018777bd686","order_type":"limit","size":"1.90000000","price":"795.16000000","side":"sell","client_oid":"6144ab41-deed-4ff2-a460-85e07b12a1fb","product_id":"BCH-USD","sequence":4839272077,"time":"2018-07-27T01:32:40.323000Z"}
{"type":"open","side":"sell","price":"795.16000000","order_id":"ee73983c-88ab-4c9a-adb1-b018777bd686","remaining_size":"1.90000000","product_id":"BCH-USD","sequence":4839272078,"time":"2018-07-27T01:32:40.323000Z"}
{"type":"received","order_id":"d0091907-23e8-41b3-8502-e0c0d5e0d198","order_type":"limit","size":"1.81488800","price":"791.24000000","side":"buy","client_oid":"bff2c3e3-b277-404b-ae47-9ce48d0a9e8f","product_id":"BCH-USD","sequence":4839272079,"time":"2018-07-27T01:32:40.326000Z"}
{"type":"open","side":"buy","price":"791.24000000","order_id":"d0091907-23e8-41b3-8502-e0c0d5e0d198","remaining_size":"1.81488800","product_id":"BCH-USD","sequence":4839272080,"time":"2018-07-27T01:32:40.326000Z"}
{"type":"received","order_id":"7d30417b-8b90-458b-a426-14dde76e66d6","order_type":"limit","size":"3.00000000","price":"795.15000000","side":"sell","client_oid":"8bc77fd9-3b0a-4cc2-b911-2c935a6d0385","product_id":"BCH-USD","sequence":4839272081,"time":"2018-07-27T01:32:40.329000Z"}
{"type":"open","side":"sell","price":"795.15000000","order_id":"7d30417b-8b90-458b-a426-14dde76e66d6","remaining_size":"3.00000000","product_id":"BCH-USD","sequence":4839272082,"time":"2018-07-27T01:32:40.329000Z"}
{"type":"done","side":"buy","order_id":"d0091907-23e8-41b3-8502-e0c0d5e0d198","reason":"canceled","product_id":"BCH-USD","price":"791.24000000","remaining_size":"1.81488800","sequence":4839272083,"time":"2018-07-27T01:32:40.329000Z"}
{"type":"received","order_id":"bd2a346f-0657-43b4-8dfc-1669851f19a7","order_type":"limit","size":"4.50000000","price":"795.53000000","side":"sell","client_oid":"21483d69-8f58-4531-a491-a3da9d7e055f","product_id":"BCH-USD","sequence":4839272084,"time":"2018-07-27T01:32:40.333000Z"}
{"type":"open","side":"sell","price":"795.53000000","order_id":"bd2a346f-0657-43b4-8dfc-1669851f19a7","remaining_size":"4.50000000","product_id":"BCH-USD","sequence":4839272085,"time":"2018-07-27T01:32:40.333000Z"}
{"type":"done","side":"sell","order_id":"e0f424fb-b0ed-4e40-8154-a97f23ce38ed","reason":"canceled","product_id":"BCH-USD","price":"795.17000000","remaining_size":"4.50000000","sequence":4839272086,"time":"2018-07-27T01:32:40.334000Z"}
{"type":"received","order_id":"e50c4f49-4c1d-4cc3-97f5-694596fdedce","order_type":"limit","size":"0.18739300","price":"791.24000000","side":"buy","client_oid":"c2d0072b-6b3c-4986-8da6-51d9fdb324da","product_id":"BCH-USD","sequence":4839272087,"time":"2018-07-27T01:32:40.335000Z"}
{"type":"open","side":"buy","price":"791.24000000","order_id":"e50c4f49-4c1d-4cc3-97f5-694596fdedce","remaining_size":"0.18739300","product_id":"BCH-USD","sequence":4839272088,"time":"2018-07-27T01:32:40.335000Z"}
{"type":"done","side":"sell","order_id":"2ad65bbd-bb7a-4158-a34d-756bde5c8f15","reason":"canceled","product_id":"BCH-USD","price":"795.16000000","remaining_size":"1.90000000","sequence":4839272089,"time":"2018-07-27T01:32:40.335000Z"}
{"type":"done","side":"sell","order_id":"ee73983c-88ab-4c9a-adb1-b018777bd686","reason":"canceled","product_id":"BCH-USD","price":"795.16000000","remaining_size":"1.90000000","sequence":4839272090,"time":"2018-07-27T01:32:40.338000Z"}
{"type":"received","order_id":"e7ec15f5-11ac-4514-83a9-a911c4ed5829","order_type":"limit","size":"4.50000000","price":"795.16000000","side":"sell","client_oid":"52f210ec-564b-423f-88f3-8b42c9ec8bed","product_id":"BCH-USD","sequence":4839272091,"time":"2018-07-27T01:32:40.340000Z"}
{"type":"open","side":"sell","price":"795.16000000","order_id":"e7ec15f5-11ac-4514-83a9-a911c4ed5829","remaining_size":"4.50000000","product_id":"BCH-USD","sequence":4839272092,"time":"2018-07-27T01:32:40.340000Z"}
{"type":"done","side":"sell","order_id":"0726cb8e-0fc8-41fc-8875-293035c1b6f4","reason":"canceled","product_id":"LTC-USD","price":"83.38000000","remaining_size":"7.44874862","sequence":2423271769,"time":"2018-07-27T01:32:40.342000Z"}
{"type":"done","side":"buy","order_id":"e50c4f49-4c1d-4cc3-97f5-694596fdedce","reason":"canceled","product_id":"BCH-USD","price":"791.24000000","remaining_size":"0.18739300","sequence":4839272093,"time":"2018-07-27T01:32:40.341000Z"}
{"type":"received","order_id":"d16c9506-61a1-4025-910d-e3d431e4e4c3","order_type":"limit","size":"0.90000000","price":"795.16000000","side":"sell","client_oid":"ce7c4c2b-55f9-4087-b637-1c3e2b555d44","product_id":"BCH-USD","sequence":4839272094,"time":"2018-07-27T01:32:40.341000Z"}
{"type":"open","side":"sell","price":"795.16000000","order_id":"d16c9506-61a1-4025-910d-e3d431e4e4c3","remaining_size":"0.90000000","product_id":"BCH-USD","sequence":4839272095,"time":"2018-07-27T01:32:40.341000Z"}
{"type":"received","order_id":"72901e65-3fd1-48ef-b109-d73c295d3e30","order_type":"limit","size":"7.44874862","price":"83.34000000","side":"sell","client_oid":"76b2d809-0ab3-4291-8000-0750edde2060","product_id":"LTC-USD","sequence":2423271770,"time":"2018-07-27T01:32:40.354000Z"}
{"type":"received","order_id":"5403f162-4a65-4f84-8899-44176c62a5af","order_type":"limit","size":"1.81488800","price":"791.23000000","side":"buy","client_oid":"9677ec74-af93-42b2-8285-174c4905354f","product_id":"BCH-USD","sequence":4839272096,"time":"2018-07-27T01:32:40.353000Z"}
{"type":"open","side":"sell","price":"83.34000000","order_id":"72901e65-3fd1-48ef-b109-d73c295d3e30","remaining_size":"7.44874862","product_id":"LTC-USD","sequence":2423271771,"time":"2018-07-27T01:32:40.354000Z"}
{"type":"open","side":"buy","price":"791.23000000","order_id":"5403f162-4a65-4f84-8899-44176c62a5af","remaining_size":"1.81488800","product_id":"BCH-USD","sequence":4839272097,"time":"2018-07-27T01:32:40.353000Z"}
{"type":"received","order_id":"477df6dd-f732-47b2-b652-927dc5c0a02b","order_type":"limit","size":"1.90000000","price":"795.15000000","side":"sell","client_oid":"ebe64efb-54c9-4bc0-a83e-221e43065e9d","product_id":"BCH-USD","sequence":4839272098,"time":"2018-07-27T01:32:40.354000Z"}
{"type":"open","side":"sell","price":"795.15000000","order_id":"477df6dd-f732-47b2-b652-927dc5c0a02b","remaining_size":"1.90000000","product_id":"BCH-USD","sequence":4839272099,"time":"2018-07-27T01:32:40.354000Z"}
{"type":"received","order_id":"fd735fc8-e63a-45fe-ba5f-db0c7e9ccde3","order_type":"limit","size":"1.00000000","price":"7895.00000000","side":"buy","client_oid":"dc0864a6-9c44-4062-99d2-0032498dfcb9","product_id":"BTC-USD","sequence":6418130227,"time":"2018-07-27T01:32:40.362000Z"}
{"type":"open","side":"buy","price":"7895.00000000","order_id":"fd735fc8-e63a-45fe-ba5f-db0c7e9ccde3","remaining_size":"1.00000000","product_id":"BTC-USD","sequence":6418130228,"time":"2018-07-27T01:32:40.362000Z"}
{"type":"received","order_id":"42a12c5c-074b-4af9-be3e-a3920ffd91e9","order_type":"limit","size":"1.90000000","price":"795.15000000","side":"sell","client_oid":"b65932f6-ffd3-4fa3-bf53-3c8ca6ca319e","product_id":"BCH-USD","sequence":4839272100,"time":"2018-07-27T01:32:40.361000Z"}
{"type":"open","side":"sell","price":"795.15000000","order_id":"42a12c5c-074b-4af9-be3e-a3920ffd91e9","remaining_size":"1.90000000","product_id":"BCH-USD","sequence":4839272101,"time":"2018-07-27T01:32:40.361000Z"}
{"type":"received","order_id":"a2902528-14a5-4d10-825f-2c01342b7369","order_type":"limit","size":"2.00000000","price":"792.54000000","side":"buy","client_oid":"9d9edeb5-d7f5-47b0-b6c7-dbea2d65a3c6","product_id":"BCH-USD","sequence":4839272102,"time":"2018-07-27T01:32:40.363000Z"}
{"type":"open","side":"buy","price":"792.54000000","order_id":"a2902528-14a5-4d10-825f-2c01342b7369","remaining_size":"2.00000000","product_id":"BCH-USD","sequence":4839272103,"time":"2018-07-27T01:32:40.363000Z"}
{"type":"done","side":"sell","order_id":"0f902fe5-79e3-4d38-b284-93ff3c0e873e","reason":"canceled","product_id":"LTC-USD","price":"83.30000000","remaining_size":"7.44874862","sequence":2423271772,"time":"2018-07-27T01:32:40.366000Z"}
{"type":"received","order_id":"9395762b-70fd-40a7-980f-3fcec5663f4e","order_type":"limit","size":"0.18739300","price":"791.23000000","side":"buy","client_oid":"2b4f7218-2a36-41e8-b422-5f11b4d6562c","product_id":"BCH-USD","sequence":4839272104,"time":"2018-07-27T01:32:40.364000Z"}
{"type":"open","side":"buy","price":"791.23000000","order_id":"9395762b-70fd-40a7-980f-3fcec5663f4e","remaining_size":"0.18739300","product_id":"BCH-USD","sequence":4839272105,"time":"2018-07-27T01:32:40.364000Z"}
{"type":"done","side":"sell","order_id":"42a12c5c-074b-4af9-be3e-a3920ffd91e9","reason":"canceled","product_id":"BCH-USD","price":"795.15000000","remaining_size":"1.90000000","sequence":4839272106,"time":"2018-07-27T01:32:40.370000Z"}
{"type":"done","side":"buy","order_id":"9395762b-70fd-40a7-980f-3fcec5663f4e","reason":"canceled","product_id":"BCH-USD","price":"791.23000000","remaining_size":"0.18739300","sequence":4839272107,"time":"2018-07-27T01:32:40.371000Z"}
{"type":"done","side":"buy","order_id":"5403f162-4a65-4f84-8899-44176c62a5af","reason":"canceled","product_id":"BCH-USD","price":"791.23000000","remaining_size":"1.81488800","sequence":4839272108,"time":"2018-07-27T01:32:40.375000Z"}
{"type":"received","order_id":"efd9a242-af51-4d57-a891-05ac9e3d1781","order_type":"limit","size":"0.18739300","price":"791.24000000","side":"buy","client_oid":"b8618b87-de28-44af-817c-b65df033e85b","product_id":"BCH-USD","sequence":4839272109,"time":"2018-07-27T01:32:40.377000Z"}
{"type":"open","side":"buy","price":"791.24000000","order_id":"efd9a242-af51-4d57-a891-05ac9e3d1781","remaining_size":"0.18739300","product_id":"BCH-USD","sequence":4839272110,"time":"2018-07-27T01:32:40.377000Z"}
{"type":"done","side":"sell","order_id":"d16c9506-61a1-4025-910d-e3d431e4e4c3","reason":"canceled","product_id":"BCH-USD","price":"795.16000000","remaining_size":"0.90000000","sequence":4839272111,"time":"2018-07-27T01:32:40.380000Z"}
{"type":"received","order_id":"6990640e-2db4-4782-868d-0f9754cc426b","order_type":"limit","size":"1.60461000","price":"795.54000000","side":"sell","client_oid":"cb444b31-a44b-4549-a152-b252e1675d46","product_id":"BCH-USD","sequence":4839272112,"time":"2018-07-27T01:32:40.380000Z"}
{"type":"open","side":"sell","price":"795.54000000","order_id":"6990640e-2db4-4782-868d-0f9754cc426b","remaining_size":"1.60461000","product_id":"BCH-USD","sequence":4839272113,"time":"2018-07-27T01:32:40.380000Z"}
{"type":"done","side":"sell","order_id":"477df6dd-f732-47b2-b652-927dc5c0a02b","reason":"canceled","product_id":"BCH-USD","price":"795.15000000","remaining_size":"1.90000000","sequence":4839272114,"time":"2018-07-27T01:32:40.381000Z"}
{"type":"done","side":"sell","order_id":"e7ec15f5-11ac-4514-83a9-a911c4ed5829","reason":"canceled","product_id":"BCH-USD","price":"795.16000000","remaining_size":"4.50000000","sequence":4839272115,"time":"2018-07-27T01:32:40.381000Z"}
{"type":"received","order_id":"9d60a78d-11f8-4740-951b-f5c5442937d6","order_type":"limit","size":"1.90000000","price":"795.14000000","side":"sell","client_oid":"ded02822-2c1c-418c-816b-bc3f829108ac","product_id":"BCH-USD","sequence":4839272116,"time":"2018-07-27T01:32:40.384000Z"}
{"type":"open","side":"sell","price":"795.14000000","order_id":"9d60a78d-11f8-4740-951b-f5c5442937d6","remaining_size":"1.90000000","product_id":"BCH-USD","sequence":4839272117,"time":"2018-07-27T01:32:40.384000Z"}
{"type":"received","order_id":"dce24966-8f32-465b-b032-c1218436e7cc","order_type":"limit","size":"1.81488800","price":"791.24000000","side":"buy","client_oid":"a62426f1-12c8-495a-a7b8-3f1fce32dec3","product_id":"BCH-USD","sequence":4839272118,"time":"2018-07-27T01:32:40.385000Z"}
{"type":"open","side":"buy","price":"791.24000000","order_id":"dce24966-8f32-465b-b032-c1218436e7cc","remaining_size":"1.81488800","product_id":"BCH-USD","sequence":4839272119,"time":"2018-07-27T01:32:40.385000Z"}
{"type":"received","order_id":"f853b971-c532-4981-b25f-9b7f0ac3f242","order_type":"limit","size":"0.90000000","price":"795.15000000","side":"sell","client_oid":"5caed8d2-a263-4624-b98f-a9e2a763dfbd","product_id":"BCH-USD","sequence":4839272120,"time":"2018-07-27T01:32:40.387000Z"}
{"type":"open","side":"sell","price":"795.15000000","order_id":"f853b971-c532-4981-b25f-9b7f0ac3f242","remaining_size":"0.90000000","product_id":"BCH-USD","sequence":4839272121,"time":"2018-07-27T01:32:40.387000Z"}
{"type":"done","side":"sell","order_id":"9d60a78d-11f8-4740-951b-f5c5442937d6","reason":"canceled","product_id":"BCH-USD","price":"795.14000000","remaining_size":"1.90000000","sequence":4839272122,"time":"2018-07-27T01:32:40.388000Z"}
{"type":"received","order_id":"aa9f2c9d-140e-439a-a7c5-bd68ca862408","order_type":"limit","size":"4.50000000","price":"795.14000000","side":"sell","client_oid":"69b7d22a-284b-4107-8be7-cac10c07d9b0","product_id":"BCH-USD","sequence":4839272123,"time":"2018-07-27T01:32:40.388000Z"}
{"type":"open","side":"sell","price":"795.14000000","order_id":"aa9f2c9d-140e-439a-a7c5-bd68ca862408","remaining_size":"4.50000000","product_id":"BCH-USD","sequence":4839272124,"time":"2018-07-27T01:32:40.388000Z"}
{"type":"done","side":"buy","order_id":"efd9a242-af51-4d57-a891-05ac9e3d1781","reason":"canceled","product_id":"BCH-USD","price":"791.24000000","remaining_size":"0.18739300","sequence":4839272125,"time":"2018-07-27T01:32:40.389000Z"}
{"type":"received","order_id":"ad3142c8-86a3-497e-8695-81dbe344630f","order_type":"limit","size":"7.44874862","price":"83.38000000","side":"sell","client_oid":"9d0dc998-4027-4504-8000-0080c45fd8ec","product_id":"LTC-USD","sequence":2423271773,"time":"2018-07-27T01:32:40.392000Z"}
{"type":"done","side":"buy","order_id":"dce24966-8f32-465b-b032-c1218436e7cc","reason":"canceled","product_id":"BCH-USD","price":"791.24000000","remaining_size":"1.81488800","sequence":4839272126,"time":"2018-07-27T01:32:40.391000Z"}
{"type":"open","side":"sell","price":"83.38000000","order_id":"ad3142c8-86a3-497e-8695-81dbe344630f","remaining_size":"7.44874862","product_id":"LTC-USD","sequence":2423271774,"time":"2018-07-27T01:32:40.392000Z"}
{"type":"done","side":"sell","order_id":"f853b971-c532-4981-b25f-9b7f0ac3f242","reason":"canceled","product_id":"BCH-USD","price":"795.15000000","remaining_size":"0.90000000","sequence":4839272127,"time":"2018-07-27T01:32:40.395000Z"}
{"type":"received","order_id":"b961ff24-770f-4c0b-ae74-16edc76486f6","order_type":"limit","size":"1.90000000","price":"795.14000000","side":"sell","client_oid":"d0acbe87-511a-48c8-9f61-7821e939e089","product_id":"BCH-USD","sequence":4839272128,"time":"2018-07-27T01:32:40.396000Z"}
{"type":"open","side":"sell","price":"795.14000000","order_id":"b961ff24-770f-4c0b-ae74-16edc76486f6","remaining_size":"1.90000000","product_id":"BCH-USD","sequence":4839272129,"time":"2018-07-27T01:32:40.396000Z"}
{"type":"done","side":"sell","order_id":"aa9f2c9d-140e-439a-a7c5-bd68ca862408","reason":"canceled","product_id":"BCH-USD","price":"795.14000000","remaining_size":"4.50000000","sequence":4839272130,"time":"2018-07-27T01:32:40.396000Z"}
{"type":"done","side":"sell","order_id":"49faab74-3e10-4171-8f79-053953ef8ebf","reason":"canceled","product_id":"BTC-USD","price":"7907.17000000","remaining_size":"0.02500000","sequence":6418130229,"time":"2018-07-27T01:32:40.399000Z"}
{"type":"done","side":"sell","order_id":"b961ff24-770f-4c0b-ae74-16edc76486f6","reason":"canceled","product_id":"BCH-USD","price":"795.14000000","remaining_size":"1.90000000","sequence":4839272131,"time":"2018-07-27T01:32:40.400000Z"}
{"type":"received","order_id":"17e332ac-d862-4e37-972f-7b7d64e763ff","order_type":"limit","size":"0.18739300","price":"791.23000000","side":"buy","client_oid":"f5973774-b693-463f-8e71-da4fc520975d","product_id":"BCH-USD","sequence":4839272132,"time":"2018-07-27T01:32:40.400000Z"}
{"type":"open","side":"buy","price":"791.23000000","order_id":"17e332ac-d862-4e37-972f-7b7d64e763ff","remaining_size":"0.18739300","product_id":"BCH-USD","sequence":4839272133,"time":"2018-07-27T01:32:40.400000Z"}
{"type":"received","order_id":"119e0b98-0fc7-4ff6-84c2-9eac124507dc","order_type":"limit","size":"0.02500000","price":"7907.52000000","side":"sell","client_oid":"66ecb8d1-972b-4c18-8000-00add7204848","product_id":"BTC-USD","sequence":6418130230,"time":"2018-07-27T01:32:40.406000Z"}
{"type":"open","side":"sell","price":"7907.52000000","order_id":"119e0b98-0fc7-4ff6-84c2-9eac124507dc","remaining_size":"0.02500000","product_id":"BTC-USD","sequence":6418130231,"time":"2018-07-27T01:32:40.406000Z"}
{"type":"received","order_id":"5734fcc6-8739-479d-b3ea-23a231bd609a","order_type":"limit","size":"1.90000000","price":"795.15000000","side":"sell","client_oid":"4be20eb6-2069-4f0a-a763-497384ad7963","product_id":"BCH-USD","sequence":4839272134,"time":"2018-07-27T01:32:40.406000Z"}
{"type":"open","side":"sell","price":"795.15000000","order_id":"5734fcc6-8739-479d-b3ea-23a231bd609a","remaining_size":"1.90000000","product_id":"BCH-USD","sequence":4839272135,"time":"2018-07-27T01:32:40.406000Z"}
{"type":"done","side":"sell","order_id":"72901e65-3fd1-48ef-b109-d73c295d3e30","reason":"canceled","product_id":"LTC-USD","price":"83.34000000","remaining_size":"7.44874862","sequence":2423271775,"time":"2018-07-27T01:32:40.410000Z"}
{"type":"received","order_id":"c7953117-5b5a-4a3b-bd16-2d38b7141086","order_type":"limit","size":"1.81488800","price":"791.23000000","side":"buy","client_oid":"45dfe469-4412-492e-ae49-c5643bbdd540","product_id":"BCH-USD","sequence":4839272136,"time":"2018-07-27T01:32:40.409000Z"}
{"type":"open","side":"buy","price":"791.23000000","order_id":"c7953117-5b5a-4a3b-bd16-2d38b7141086","remaining_size":"1.81488800","product_id":"BCH-USD","sequence":4839272137,"time":"2018-07-27T01:32:40.409000Z"}
{"type":"done","side":"sell","order_id":"5734fcc6-8739-479d-b3ea-23a231bd609a","reason":"canceled","product_id":"BCH-USD","price":"795.15000000","remaining_size":"1.90000000","sequence":4839272138,"time":"2018-07-27T01:32:40.412000Z"}
{"type":"received","order_id":"f6c59c5d-c525-4825-913a-9e5f8ba41a05","order_type":"limit","size":"0.90000000","price":"795.17000000","side":"sell","client_oid":"9e95cc1c-3e11-4934-9141-a8a255d62838","product_id":"BCH-USD","sequence":4839272139,"time":"2018-07-27T01:32:40.414000Z"}
{"type":"open","side":"sell","price":"795.17000000","order_id":"f6c59c5d-c525-4825-913a-9e5f8ba41a05","remaining_size":"0.90000000","product_id":"BCH-USD","sequence":4839272140,"time":"2018-07-27T01:32:40.414000Z"}
{"type":"received","order_id":"4b38b904-ee3a-4296-822d-55015e42b38b","order_type":"limit","size":"1.90000000","price":"795.17000000","side":"sell","client_oid":"d3177a8b-f699-408c-95ab-9f244f7a53d0","product_id":"BCH-USD","sequence":4839272141,"time":"2018-07-27T01:32:40.417000Z"}
{"type":"open","side":"sell","price":"795.17000000","order_id":"4b38b904-ee3a-4296-822d-55015e42b38b","remaining_size":"1.90000000","product_id":"BCH-USD","sequence":4839272142,"time":"2018-07-27T01:32:40.417000Z"}
{"type":"received","order_id":"621c9008-4fd5-41a7-b866-c4cb222d04ff","order_type":"limit","size":"4.50000000","price":"795.15000000","side":"sell","client_oid":"ef1e89f6-171d-4ee7-b2b0-a36ea0e5c204","product_id":"BCH-USD","sequence":4839272143,"time":"2018-07-27T01:32:40.418000Z"}
{"type":"open","side":"sell","price":"795.15000000","order_id":"621c9008-4fd5-41a7-b866-c4cb222d04ff","remaining_size":"4.50000000","product_id":"BCH-USD","sequence":4839272144,"time":"2018-07-27T01:32:40.418000Z"}
{"type":"done","side":"buy","order_id":"17e332ac-d862-4e37-972f-7b7d64e763ff","reason":"canceled","product_id":"BCH-USD","price":"791.23000000","remaining_size":"0.18739300","sequence":4839272145,"time":"2018-07-27T01:32:40.420000Z"}
{"type":"received","order_id":"76d772e7-a217-462b-9dca-35757bcbbcc1","order_type":"limit","size":"14.24999000","price":"460.72000000","side":"buy","client_oid":"cf495324-9e18-446e-b0fd-cb3bc8f641d4","product_id":"ETH-USD","sequence":4469354766,"time":"2018-07-27T01:32:40.422000Z"}
{"type":"received","order_id":"8ce0c404-cffa-4fff-996f-55eb0ef668a4","order_type":"limit","size":"1.90000000","price":"795.17000000","side":"sell","client_oid":"a5ccbe04-c039-46d1-8fd1-71bb8354b5fd","product_id":"BCH-USD","sequence":4839272146,"time":"2018-07-27T01:32:40.421000Z"}
{"type":"open","side":"sell","price":"795.17000000","order_id":"8ce0c404-cffa-4fff-996f-55eb0ef668a4","remaining_size":"1.90000000","product_id":"BCH-USD","sequence":4839272147,"time":"2018-07-27T01:32:40.421000Z"}
{"type":"open","side":"buy","price":"460.72000000","order_id":"76d772e7-a217-462b-9dca-35757bcbbcc1","remaining_size":"14.24999000","product_id":"ETH-USD","sequence":4469354767,"time":"2018-07-27T01:32:40.422000Z"}
{"type":"done","side":"sell","order_id":"621c9008-4fd5-41a7-b866-c4cb222d04ff","reason":"canceled","product_id":"BCH-USD","price":"795.15000000","remaining_size":"4.50000000","sequence":4839272148,"time":"2018-07-27T01:32:40.422000Z"}
{"type":"received","order_id":"e759d6cd-2c75-4a20-b6fc-028dcaf29579","order_type":"limit","size":"8.29703000","price":"464.51000000","side":"sell","client_oid":"e1bc0912-f179-47b4-97cc-5b4336abadc7","product_id":"ETH-USD","sequence":4469354768,"time":"2018-07-27T01:32:40.425000Z"}
{"type":"done","side":"sell","order_id":"8ce0c404-cffa-4fff-996f-55eb0ef668a4","reason":"canceled","product_id":"BCH-USD","price":"795.17000000","remaining_size":"1.90000000","sequence":4839272149,"time":"2018-07-27T01:32:40.425000Z"}
{"type":"received","order_id":"3d756649-9961-49a7-9767-059584d407b0","order_type":"limit","size":"7.44874862","price":"83.30000000","side":"sell","client_oid":"eea26d6a-14af-43e3-8000-0036f3551068","product_id":"LTC-USD","sequence":2423271776,"time":"2018-07-27T01:32:40.427000Z"}
{"type":"open","side":"sell","price":"464.51000000","order_id":"e759d6cd-2c75-4a20-b6fc-028dcaf29579","remaining_size":"8.29703000","product_id":"ETH-USD","sequence":4469354769,"time":"2018-07-27T01:32:40.425000Z"}
{"type":"open","side":"sell","price":"83.30000000","order_id":"3d756649-9961-49a7-9767-059584d407b0","remaining_size":"7.44874862","product_id":"LTC-USD","sequence":2423271777,"time":"2018-07-27T01:32:40.427000Z"}
{"type":"received","order_id":"a2ddfc9e-e81c-480c-b937-6b04bb48e74c","order_type":"limit","size":"0.18739300","price":"791.24000000","side":"buy","client_oid":"aa7a8936-5cd8-4104-9c2f-1f93c6146542","product_id":"BCH-USD","sequence":4839272150,"time":"2018-07-27T01:32:40.430000Z"}
{"type":"open","side":"buy","price":"791.24000000","order_id":"a2ddfc9e-e81c-480c-b937-6b04bb48e74c","remaining_size":"0.18739300","product_id":"BCH-USD","sequence":4839272151,"time":"2018-07-27T01:32:40.430000Z"}
{"type":"done","side":"sell","order_id":"f6c59c5d-c525-4825-913a-9e5f8ba41a05","reason":"canceled","product_id":"BCH-USD","price":"795.17000000","remaining_size":"0.90000000","sequence":4839272152,"time":"2018-07-27T01:32:40.430000Z"}
{"type":"done","side":"sell","order_id":"4b38b904-ee3a-4296-822d-55015e42b38b","reason":"canceled","product_id":"BCH-USD","price":"795.17000000","remaining_size":"1.90000000","sequence":4839272153,"time":"2018-07-27T01:32:40.431000Z"}
{"type":"received","order_id":"ed98075e-0777-4e6c-9ecc-b9b3f39040ee","order_type":"limit","size":"4.50000000","price":"795.17000000","side":"sell","client_oid":"18953fcb-dda3-4c2f-ba92-7b64dd31d79a","product_id":"BCH-USD","sequence":4839272154,"time":"2018-07-27T01:32:40.434000Z"}
{"type":"open","side":"sell","price":"795.17000000","order_id":"ed98075e-0777-4e6c-9ecc-b9b3f39040ee","remaining_size":"4.50000000","product_id":"BCH-USD","sequence":4839272155,"time":"2018-07-27T01:32:40.434000Z"}
{"type":"received","order_id":"b508cd94-0e4b-46cd-bae9-59522dad8997","order_type":"limit","size":"1.90000000","price":"795.14000000","side":"sell","client_oid":"23cc8ba0-65ab-4014-b665-96fc5f1c0f11","product_id":"BCH-USD","sequence":4839272156,"time":"2018-07-27T01:32:40.439000Z"}
{"type":"open","side":"sell","price":"795.14000000","order_id":"b508cd94-0e4b-46cd-bae9-59522dad8997","remaining_size":"1.90000000","product_id":"BCH-USD","sequence":4839272157,"time":"2018-07-27T01:32:40.439000Z"}
{"type":"done","side":"sell","order_id":"ed98075e-0777-4e6c-9ecc-b9b3f39040ee","reason":"canceled","product_id":"BCH-USD","price":"795.17000000","remaining_size":"4.50000000","sequence":4839272158,"time":"2018-07-27T01:32:40.441000Z"}
{"type":"received","order_id":"421f6c16-b3bc-4696-b441-8c87d49b0a91","order_type":"limit","size":"0.90000000","price":"795.14000000","side":"sell","client_oid":"2f7827f2-2755-4b74-9b2d-4a6d2f806189","product_id":"BCH-USD","sequence":4839272159,"time":"2018-07-27T01:32:40.442000Z"}
{"type":"open","side":"sell","price":"795.14000000","order_id":"421f6c16-b3bc-4696-b441-8c87d49b0a91","remaining_size":"0.90000000","product_id":"BCH-USD","sequence":4839272160,"time":"2018-07-27T01:32:40.442000Z"}
{"type":"done","side":"sell","order_id":"b508cd94-0e4b-46cd-bae9-59522dad8997","reason":"canceled","product_id":"BCH-USD","price":"795.14000000","remaining_size":"1.90000000","sequence":4839272161,"time":"2018-07-27T01:32:40.443000Z"}
{"type":"received","order_id":"64a8ea02-9612-48fb-aa86-0132a8835a23","order_type":"limit","size":"1.90000000","price":"795.16000000","side":"sell","client_oid":"e41b04c0-be4f-4917-970c-e12694e752fc","product_id":"BCH-USD","sequence":4839272162,"time":"2018-07-27T01:32:40.444000Z"}
{"type":"open","side":"sell","price":"795.16000000","order_id":"64a8ea02-9612-48fb-aa86-0132a8835a23","remaining_size":"1.90000000","product_id":"BCH-USD","sequence":4839272163,"time":"2018-07-27T01:32:40.444000Z"}
{"type":"done","side":"sell","order_id":"421f6c16-b3bc-4696-b441-8c87d49b0a91","reason":"canceled","product_id":"BCH-USD","price":"795.14000000","remaining_size":"0.90000000","sequence":4839272164,"time":"2018-07-27T01:32:40.446000Z"}
{"type":"done","side":"buy","order_id":"a2902528-14a5-4d10-825f-2c01342b7369","reason":"canceled","product_id":"BCH-USD","price":"792.54000000","remaining_size":"2.00000000","sequence":4839272165,"time":"2018-07-27T01:32:40.447000Z"}
{"type":"done","side":"buy","order_id":"c7953117-5b5a-4a3b-bd16-2d38b7141086","reason":"canceled","product_id":"BCH-USD","price":"791.23000000","remaining_size":"1.81488800","sequence":4839272166,"time":"2018-07-27T01:32:40.448000Z"}
{"type":"done","side":"sell","order_id":"64a8ea02-9612-48fb-aa86-0132a8835a23","reason":"canceled","product_id":"BCH-USD","price":"795.16000000","remaining_size":"1.90000000","sequence":4839272167,"time":"2018-07-27T01:32:40.450000Z"}
{"type":"received","order_id":"833d974d-7eb6-42c0-9518-8a45ca4c8e1e","order_type":"limit","size":"4.50000000","price":"795.16000000","side":"sell","client_oid":"5bbccc80-4514-4547-bd27-760326a69929","product_id":"BCH-USD","sequence":4839272168,"time":"2018-07-27T01:32:40.452000Z"}
{"type":"open","side":"sell","price":"795.16000000","order_id":"833d974d-7eb6-42c0-9518-8a45ca4c8e1e","remaining_size":"4.50000000","product_id":"BCH-USD","sequence":4839272169,"time":"2018-07-27T01:32:40.452000Z"}
{"type":"received","order_id":"f7397431-fed5-44da-a014-1b7d01630627","order_type":"limit","size":"1.90000000","price":"795.16000000","side":"sell","client_oid":"bf8480f6-ba32-4c9d-9928-6e9fa0f51210","product_id":"BCH-USD","sequence":4839272170,"time":"2018-07-27T01:32:40.454000Z"}
{"type":"open","side":"sell","price":"795.16000000","order_id":"f7397431-fed5-44da-a014-1b7d01630627","remaining_size":"1.90000000","product_id":"BCH-USD","sequence":4839272171,"time":"2018-07-27T01:32:40.454000Z"}
{"type":"done","side":"buy","order_id":"a2ddfc9e-e81c-480c-b937-6b04bb48e74c","reason":"canceled","product_id":"BCH-USD","price":"791.24000000","remaining_size":"0.18739300","sequence":4839272172,"time":"2018-07-27T01:32:40.454000Z"}
{"type":"received","order_id":"b92e7617-c607-4eaa-9e27-9770c035d2e9","order_type":"limit","size":"0.90000000","price":"795.16000000","side":"sell","client_oid":"107a3a7d-1fe7-430b-a7e6-2c38d23c39df","product_id":"BCH-USD","sequence":4839272173,"time":"2018-07-27T01:32:40.457000Z"}
{"type":"open","side":"sell","price":"795.16000000","order_id":"b92e7617-c607-4eaa-9e27-9770c035d2e9","remaining_size":"0.90000000","product_id":"BCH-USD","sequence":4839272174,"time":"2018-07-27T01:32:40.457000Z"}
{"type":"done","side":"sell","order_id":"833d974d-7eb6-42c0-9518-8a45ca4c8e1e","reason":"canceled","product_id":"BCH-USD","price":"795.16000000","remaining_size":"4.50000000","sequence":4839272175,"time":"2018-07-27T01:32:40.457000Z"}
{"type":"done","side":"sell","order_id":"f7397431-fed5-44da-a014-1b7d01630627","reason":"canceled","product_id":"BCH-USD","price":"795.16000000","remaining_size":"1.90000000","sequence":4839272176,"time":"2018-07-27T01:32:40.458000Z"}
{"type":"received","order_id":"c7ad39ed-3ce7-4617-9652-8d9a77ad8206","order_type":"limit","size":"1.90000000","price":"795.14000000","side":"sell","client_oid":"a88cb057-000d-44f6-bf07-37f524ef927e","product_id":"BCH-USD","sequence":4839272177,"time":"2018-07-27T01:32:40.459000Z"}
{"type":"open","side":"sell","price":"795.14000000","order_id":"c7ad39ed-3ce7-4617-9652-8d9a77ad8206","remaining_size":"1.90000000","product_id":"BCH-USD","sequence":4839272178,"time":"2018-07-27T01:32:40.459000Z"}
{"type":"received","order_id":"f8d87f4e-4c4f-46f1-af47-905a62bb172d","order_type":"limit","size":"0.00500000","price":"7800.00000000","side":"buy","client_oid":"cb70b226-b1eb-446e-d3d5-a9ccb821985b","product_id":"BTC-USD","sequence":6418130232,"time":"2018-07-27T01:32:40.463000Z"}
{"type":"open","side":"buy","price":"7800.00000000","order_id":"f8d87f4e-4c4f-46f1-af47-905a62bb172d","remaining_size":"0.00500000","product_id":"BTC-USD","sequence":6418130233,"time":"2018-07-27T01:32:40.463000Z"}
{"type":"done","side":"sell","order_id":"c7ad39ed-3ce7-4617-9652-8d9a77ad8206","reason":"canceled","product_id":"BCH-USD","price":"795.14000000","remaining_size":"1.90000000","sequence":4839272179,"time":"2018-07-27T01:32:40.463000Z"}
{"type":"received","order_id":"8e8f82de-8656-42a5-a63b-f6ff51866310","order_type":"limit","size":"1.81488800","price":"791.24000000","side":"buy","client_oid":"06a4d4f3-aeec-4e5c-937f-183ad015362d","product_id":"BCH-USD","sequence":4839272180,"time":"2018-07-27T01:32:40.464000Z"}
{"type":"open","side":"buy","price":"791.24000000","order_id":"8e8f82de-8656-42a5-a63b-f6ff51866310","remaining_size":"1.81488800","product_id":"BCH-USD","sequence":4839272181,"time":"2018-07-27T01:32:40.464000Z"}
{"type":"received","order_id":"934df77c-3522-4136-8384-410c06750a56","order_type":"limit","size":"0.18739300","price":"791.23000000","side":"buy","client_oid":"40c79ee1-9640-4a37-befe-7f493ca6b220","product_id":"BCH-USD","sequence":4839272182,"time":"2018-07-27T01:32:40.466000Z"}
{"type":"open","side":"buy","price":"791.23000000","order_id":"934df77c-3522-4136-8384-410c06750a56","remaining_size":"0.18739300","product_id":"BCH-USD","sequence":4839272183,"time":"2018-07-27T01:32:40.466000Z"}
{"type":"done","side":"buy","order_id":"8e8f82de-8656-42a5-a63b-f6ff51866310","reason":"canceled","product_id":"BCH-USD","price":"791.24000000","remaining_size":"1.81488800","sequence":4839272184,"time":"2018-07-27T01:32:40.467000Z"}
{"type":"received","order_id":"a35dc3bc-fa3e-486e-a50c-d1056b7264c9","order_type":"limit","size":"1.90000000","price":"795.17000000","side":"sell","client_oid":"6ad1bfda-72ea-45c6-a176-2a88f6f7814b","product_id":"BCH-USD","sequence":4839272185,"time":"2018-07-27T01:32:40.471000Z"}
{"type":"open","side":"sell","price":"795.17000000","order_id":"a35dc3bc-fa3e-486e-a50c-d1056b7264c9","remaining_size":"1.90000000","product_id":"BCH-USD","sequence":4839272186,"time":"2018-07-27T01:32:40.471000Z"}
{"type":"received","order_id":"8da60a60-419f-419b-a57d-728f82fa2b23","order_type":"limit","size":"4.50000000","price":"795.17000000","side":"sell","client_oid":"c5466e24-b2a6-4614-8483-4da076d4307f","product_id":"BCH-USD","sequence":4839272187,"time":"2018-07-27T01:32:40.474000Z"}
{"type":"open","side":"sell","price":"795.17000000","order_id":"8da60a60-419f-419b-a57d-728f82fa2b23","remaining_size":"4.50000000","product_id":"BCH-USD","sequence":4839272188,"time":"2018-07-27T01:32:40.474000Z"}
{"type":"done","side":"sell","order_id":"a35dc3bc-fa3e-486e-a50c-d1056b7264c9","reason":"canceled","product_id":"BCH-USD","price":"795.17000000","remaining_size":"1.90000000","sequence":4839272189,"time":"2018-07-27T01:32:40.475000Z"}
{"type":"received","order_id":"2f55a392-255b-42d4-adb6-c74946373b54","order_type":"limit","size":"2.00000000","price":"792.53000000","side":"buy","client_oid":"33ff5431-70de-496e-a4ab-968ef9bd6945","product_id":"BCH-USD","sequence":4839272190,"time":"2018-07-27T01:32:40.479000Z"}
{"type":"open","side":"buy","price":"792.53000000","order_id":"2f55a392-255b-42d4-adb6-c74946373b54","remaining_size":"2.00000000","product_id":"BCH-USD","sequence":4839272191,"time":"2018-07-27T01:32:40.479000Z"}
{"type":"received","order_id":"f236204a-94b6-42b5-b4d2-3ad2cdb65778","order_type":"limit","size":"1.90000000","price":"795.17000000","side":"sell","client_oid":"fc8ee746-3ea7-434a-a4f2-a5f934987e84","product_id":"BCH-USD","sequence":4839272192,"time":"2018-07-27T01:32:40.484000Z"}
{"type":"open","side":"sell","price":"795.17000000","order_id":"f236204a-94b6-42b5-b4d2-3ad2cdb65778","remaining_size":"1.90000000","product_id":"BCH-USD","sequence":4839272193,"time":"2018-07-27T01:32:40.484000Z"}
{"type":"received","order_id":"b1ed74ff-dba6-4e5b-9552-9396af2de931","order_type":"limit","size":"1.81488800","price":"791.23000000","side":"buy","client_oid":"1aab99bb-dbb9-4f49-9d2d-b9f8ce7d5520","product_id":"BCH-USD","sequence":4839272194,"time":"2018-07-27T01:32:40.486000Z"}
{"type":"open","side":"buy","price":"791.23000000","order_id":"b1ed74ff-dba6-4e5b-9552-9396af2de931","remaining_size":"1.81488800","product_id":"BCH-USD","sequence":4839272195,"time":"2018-07-27T01:32:40.486000Z"}
{"type":"done","side":"sell","order_id":"f236204a-94b6-42b5-b4d2-3ad2cdb65778","reason":"canceled","product_id":"BCH-USD","price":"795.17000000","remaining_size":"1.90000000","sequence":4839272196,"time":"2018-07-27T01:32:40.489000Z"}
{"type":"received","order_id":"598b28f4-83f6-4869-b2cb-73d7205f8d1d","order_type":"limit","size":"1.90000000","price":"795.15000000","side":"sell","client_oid":"7d79e785-c1ed-410d-879f-1615c95bddcb","product_id":"BCH-USD","sequence":4839272197,"time":"2018-07-27T01:32:40.490000Z"}
{"type":"open","side":"sell","price":"795.15000000","order_id":"598b28f4-83f6-4869-b2cb-73d7205f8d1d","remaining_size":"1.90000000","product_id":"BCH-USD","sequence":4839272198,"time":"2018-07-27T01:32:40.490000Z"}
{"type":"done","side":"buy","order_id":"2f55a392-255b-42d4-adb6-c74946373b54","reason":"canceled","product_id":"BCH-USD","price":"792.53000000","remaining_size":"2.00000000","sequence":4839272199,"time":"2018-07-27T01:32:40.491000Z"}
{"type":"done","side":"sell","order_id":"598b28f4-83f6-4869-b2cb-73d7205f8d1d","reason":"canceled","product_id":"BCH-USD","price":"795.15000000","remaining_size":"1.90000000","sequence":4839272200,"time":"2018-07-27T01:32:40.494000Z"}
{"type":"done","side":"buy","order_id":"934df77c-3522-4136-8384-410c06750a56","reason":"canceled","product_id":"BCH-USD","price":"791.23000000","remaining_size":"0.18739300","sequence":4839272201,"time":"2018-07-27T01:32:40.495000Z"}
{"type":"done","side":"sell","order_id":"8da60a60-419f-419b-a57d-728f82fa2b23","reason":"canceled","product_id":"BCH-USD","price":"795.17000000","remaining_size":"4.50000000","sequence":4839272202,"time":"2018-07-27T01:32:40.497000Z"}
{"type":"received","order_id":"7efb93db-e3c5-4821-8151-e6efa73eff7e","order_type":"limit","size":"1.90000000","price":"795.16000000","side":"sell","client_oid":"a4b42e97-4ad0-46a6-ab07-076ed9073e02","product_id":"BCH-USD","sequence":4839272203,"time":"2018-07-27T01:32:40.498000Z"}
{"type":"open","side":"sell","price":"795.16000000","order_id":"7efb93db-e3c5-4821-8151-e6efa73eff7e","remaining_size":"1.90000000","product_id":"BCH-USD","sequence":4839272204,"time":"2018-07-27T01:32:40.498000Z"}
{"type":"received","order_id":"3cccfa6d-c735-4227-b490-9cc80e8a2bd8","order_type":"limit","size":"1.90000000","price":"795.16000000","side":"sell","client_oid":"423936a2-0db2-4a7c-84bc-e2384f3ff4a6","product_id":"BCH-USD","sequence":4839272205,"time":"2018-07-27T01:32:40.502000Z"}
{"type":"open","side":"sell","price":"795.16000000","order_id":"3cccfa6d-c735-4227-b490-9cc80e8a2bd8","remaining_size":"1.90000000","product_id":"BCH-USD","sequence":4839272206,"time":"2018-07-27T01:32:40.502000Z"}
{"type":"received","order_id":"37583dac-9247-4fa3-9e70-9d5b107b099c","order_type":"limit","size":"0.18739300","price":"791.24000000","side":"buy","client_oid":"6a11eef2-664a-4bbd-8ce7-086e1bb7e46a","product_id":"BCH-USD","sequence":4839272207,"time":"2018-07-27T01:32:40.505000Z"}
{"type":"open","side":"buy","price":"791.24000000","order_id":"37583dac-9247-4fa3-9e70-9d5b107b099c","remaining_size":"0.18739300","product_id":"BCH-USD","sequence":4839272208,"time":"2018-07-27T01:32:40.505000Z"}
{"type":"done","side":"sell","order_id":"7efb93db-e3c5-4821-8151-e6efa73eff7e","reason":"canceled","product_id":"BCH-USD","price":"795.16000000","remaining_size":"1.90000000","sequence":4839272209,"time":"2018-07-27T01:32:40.505000Z"}
{"type":"done","side":"buy","order_id":"b1ed74ff-dba6-4e5b-9552-9396af2de931","reason":"canceled","product_id":"BCH-USD","price":"791.23000000","remaining_size":"1.81488800","sequence":4839272210,"time":"2018-07-27T01:32:40.512000Z"}
{"type":"done","side":"sell","order_id":"b92e7617-c607-4eaa-9e27-9770c035d2e9","reason":"canceled","product_id":"BCH-USD","price":"795.16000000","remaining_size":"0.90000000","sequence":4839272211,"time":"2018-07-27T01:32:40.517000Z"}
{"type":"done","side":"sell","order_id":"3cccfa6d-c735-4227-b490-9cc80e8a2bd8","reason":"canceled","product_id":"BCH-USD","price":"795.16000000","remaining_size":"1.90000000","sequence":4839272212,"time":"2018-07-27T01:32:40.518000Z"}
{"type":"received","order_id":"5f9a961a-b792-4461-a793-f239daa97272","order_type":"limit","size":"1.81488800","price":"791.24000000","side":"buy","client_oid":"c872ec17-ddb4-418b-8174-c013cc30901f","product_id":"BCH-USD","sequence":4839272213,"time":"2018-07-27T01:32:40.519000Z"}
{"type":"open","side":"buy","price":"791.24000000","order_id":"5f9a961a-b792-4461-a793-f239daa97272","remaining_size":"1.81488800","product_id":"BCH-USD","sequence":4839272214,"time":"2018-07-27T01:32:40.519000Z"}
{"type":"received","order_id":"c763530f-1a29-41dd-bb0e-add8021db22a","order_type":"limit","size":"1.90000000","price":"795.15000000","side":"sell","client_oid":"b48f1127-0edf-420a-9238-9a34f92b45a5","product_id":"BCH-USD","sequence":4839272215,"time":"2018-07-27T01:32:40.520000Z"}
{"type":"open","side":"sell","price":"795.15000000","order_id":"c763530f-1a29-41dd-bb0e-add8021db22a","remaining_size":"1.90000000","product_id":"BCH-USD","sequence":4839272216,"time":"2018-07-27T01:32:40.520000Z"}
{"type":"done","side":"buy","order_id":"37583dac-9247-4fa3-9e70-9d5b107b099c","reason":"canceled","product_id":"BCH-USD","price":"791.24000000","remaining_size":"0.18739300","sequence":4839272217,"time":"2018-07-27T01:32:40.521000Z"}
{"type":"received","order_id":"030ad651-fce1-464b-8991-c8104dbae9b3","order_type":"limit","size":"4.50000000","price":"795.16000000","side":"sell","client_oid":"c7810ee6-a3e8-447d-8c34-fdfe61b788aa","product_id":"BCH-USD","sequence":4839272218,"time":"2018-07-27T01:32:40.522000Z"}
{"type":"open","side":"sell","price":"795.16000000","order_id":"030ad651-fce1-464b-8991-c8104dbae9b3","remaining_size":"4.50000000","product_id":"BCH-USD","sequence":4839272219,"time":"2018-07-27T01:32:40.522000Z"}
{"type":"done","side":"sell","order_id":"c763530f-1a29-41dd-bb0e-add8021db22a","reason":"canceled","product_id":"BCH-USD","price":"795.15000000","remaining_size":"1.90000000","sequence":4839272220,"time":"2018-07-27T01:32:40.526000Z"}
{"type":"done","side":"sell","order_id":"030ad651-fce1-464b-8991-c8104dbae9b3","reason":"canceled","product_id":"BCH-USD","price":"795.16000000","remaining_size":"4.50000000","sequence":4839272221,"time":"2018-07-27T01:32:40.528000Z"}
{"type":"received","order_id":"1f39b829-3a17-4b02-8369-882f8dc47733","order_type":"limit","size":"1.90000000","price":"795.15000000","side":"sell","client_oid":"d0d52d92-f8b7-4b9d-9cff-18ad5029578d","product_id":"BCH-USD","sequence":4839272222,"time":"2018-07-27T01:32:40.528000Z"}
{"type":"open","side":"sell","price":"795.15000000","order_id":"1f39b829-3a17-4b02-8369-882f8dc47733","remaining_size":"1.90000000","product_id":"BCH-USD","sequence":4839272223,"time":"2018-07-27T01:32:40.528000Z"}
{"type":"received","order_id":"031f66ed-c5f3-4be0-b5f6-b5d422ee0924","order_type":"limit","size":"0.18739300","price":"791.23000000","side":"buy","client_oid":"cf919459-9ef9-4df7-9698-af2e59c70017","product_id":"BCH-USD","sequence":4839272224,"time":"2018-07-27T01:32:40.528000Z"}
{"type":"open","side":"buy","price":"791.23000000","order_id":"031f66ed-c5f3-4be0-b5f6-b5d422ee0924","remaining_size":"0.18739300","product_id":"BCH-USD","sequence":4839272225,"time":"2018-07-27T01:32:40.528000Z"}
{"type":"received","order_id":"495ea7d6-01f4-464d-bc36-10813cbd4f68","order_type":"limit","size":"2.00000000","price":"792.37000000","side":"buy","client_oid":"be10fa05-2482-4dad-831f-263c8e004092","product_id":"BCH-USD","sequence":4839272226,"time":"2018-07-27T01:32:40.529000Z"}
{"type":"open","side":"buy","price":"792.37000000","order_id":"495ea7d6-01f4-464d-bc36-10813cbd4f68","remaining_size":"2.00000000","product_id":"BCH-USD","sequence":4839272227,"time":"2018-07-27T01:32:40.529000Z"}
{"type":"done","side":"buy","order_id":"495ea7d6-01f4-464d-bc36-10813cbd4f68","reason":"canceled","product_id":"BCH-USD","price":"792.37000000","remaining_size":"2.00000000","sequence":4839272228,"time":"2018-07-27T01:32:40.534000Z"}
{"type":"received","order_id":"3373a4ef-f250-4666-86d2-02433696a049","order_type":"limit","size":"0.90000000","price":"795.15000000","side":"sell","client_oid":"6c454287-6252-44b7-900f-80d9d79c8c3e","product_id":"BCH-USD","sequence":4839272229,"time":"2018-07-27T01:32:40.534000Z"}
{"type":"open","side":"sell","price":"795.15000000","order_id":"3373a4ef-f250-4666-86d2-02433696a049","remaining_size":"0.90000000","product_id":"BCH-USD","sequence":4839272230,"time":"2018-07-27T01:32:40.534000Z"}
{"type":"done","side":"buy","order_id":"031f66ed-c5f3-4be0-b5f6-b5d422ee0924","reason":"canceled","product_id":"BCH-USD","price":"791.23000000","remaining_size":"0.18739300","sequence":4839272231,"time":"2018-07-27T01:32:40.535000Z"}
{"type":"received","order_id":"180f3866-3003-485c-ac51-af4cf423ac0f","order_type":"limit","size":"4.50000000","price":"795.17000000","side":"sell","client_oid":"eff82e99-fc20-4239-96ca-e553f56935d3","product_id":"BCH-USD","sequence":4839272232,"time":"2018-07-27T01:32:40.540000Z"}
{"type":"open","side":"sell","price":"795.17000000","order_id":"180f3866-3003-485c-ac51-af4cf423ac0f","remaining_size":"4.50000000","product_id":"BCH-USD","sequence":4839272233,"time":"2018-07-27T01:32:40.540000Z"}
{"type":"received","order_id":"55879497-01a7-4798-be90-753a7d8a7e6e","order_type":"limit","size":"1.90000000","price":"795.17000000","side":"sell","client_oid":"a4ccda3f-9ccc-428c-a1e0-0e061f19cfa1","product_id":"BCH-USD","sequence":4839272234,"time":"2018-07-27T01:32:40.540000Z"}
{"type":"open","side":"sell","price":"795.17000000","order_id":"55879497-01a7-4798-be90-753a7d8a7e6e","remaining_size":"1.90000000","product_id":"BCH-USD","sequence":4839272235,"time":"2018-07-27T01:32:40.540000Z"}
{"type":"done","side":"sell","order_id":"3373a4ef-f250-4666-86d2-02433696a049","reason":"canceled","product_id":"BCH-USD","price":"795.15000000","remaining_size":"0.90000000","sequence":4839272236,"time":"2018-07-27T01:32:40.542000Z"}
{"type":"done","side":"sell","order_id":"1f39b829-3a17-4b02-8369-882f8dc47733","reason":"canceled","product_id":"BCH-USD","price":"795.15000000","remaining_size":"1.90000000","sequence":4839272237,"time":"2018-07-27T01:32:40.542000Z"}
{"type":"done","side":"buy","order_id":"5f9a961a-b792-4461-a793-f239daa97272","reason":"canceled","product_id":"BCH-USD","price":"791.24000000","remaining_size":"1.81488800","sequence":4839272238,"time":"2018-07-27T01:32:40.542000Z"}
{"type":"done","side":"sell","order_id":"180f3866-3003-485c-ac51-af4cf423ac0f","reason":"canceled","product_id":"BCH-USD","price":"795.17000000","remaining_size":"4.50000000","sequence":4839272239,"time":"2018-07-27T01:32:40.546000Z"}
{"type":"done","side":"sell","order_id":"55879497-01a7-4798-be90-753a7d8a7e6e","reason":"canceled","product_id":"BCH-USD","price":"795.17000000","remaining_size":"1.90000000","sequence":4839272240,"time":"2018-07-27T01:32:40.548000Z"}
{"type":"received","order_id":"cdab2202-7d1a-4385-a7d4-6e6a6fa2b3b5","order_type":"limit","size":"0.18739300","price":"791.25000000","side":"buy","client_oid":"19ee494b-c908-4996-b078-8893ddcfdbf2","product_id":"BCH-USD","sequence":4839272241,"time":"2018-07-27T01:32:40.554000Z"}
{"type":"open","side":"buy","price":"791.25000000","order_id":"cdab2202-7d1a-4385-a7d4-6e6a6fa2b3b5","remaining_size":"0.18739300","product_id":"BCH-USD","sequence":4839272242,"time":"2018-07-27T01:32:40.554000Z"}
{"type":"received","order_id":"767ba8de-e9e6-4bb7-b1fd-a559ed57a2ad","order_type":"limit","size":"2.00000000","price":"792.54000000","side":"buy","client_oid":"cfcc01f4-f5a6-447e-9f1f-c6c694c834ab","product_id":"BCH-USD","sequence":4839272243,"time":"2018-07-27T01:32:40.554000Z"}
{"type":"open","side":"buy","price":"792.54000000","order_id":"767ba8de-e9e6-4bb7-b1fd-a559ed57a2ad","remaining_size":"2.00000000","product_id":"BCH-USD","sequence":4839272244,"time":"2018-07-27T01:32:40.554000Z"}
{"type":"received","order_id":"482be570-7151-4df1-a8cb-6169165284f9","order_type":"limit","size":"1.81488800","price":"791.25000000","side":"buy","client_oid":"aaa24f4f-2a7e-45c0-9f3e-a3ec3ee92065","product_id":"BCH-USD","sequence":4839272245,"time":"2018-07-27T01:32:40.556000Z"}
{"type":"open","side":"buy","price":"791.25000000","order_id":"482be570-7151-4df1-a8cb-6169165284f9","remaining_size":"1.81488800","product_id":"BCH-USD","sequence":4839272246,"time":"2018-07-27T01:32:40.556000Z"}
{"type":"received","order_id":"c8d1d51c-3beb-4cc0-8c77-d2983c27d516","order_type":"limit","size":"1.90000000","price":"795.14000000","side":"sell","client_oid":"944b6f8c-efaa-460c-9589-41c87d1ef23a","product_id":"BCH-USD","sequence":4839272247,"time":"2018-07-27T01:32:40.560000Z"}
{"type":"open","side":"sell","price":"795.14000000","order_id":"c8d1d51c-3beb-4cc0-8c77-d2983c27d516","remaining_size":"1.90000000","product_id":"BCH-USD","sequence":4839272248,"time":"2018-07-27T01:32:40.560000Z"}
{"type":"done","side":"sell","order_id":"c8d1d51c-3beb-4cc0-8c77-d2983c27d516","reason":"canceled","product_id":"BCH-USD","price":"795.14000000","remaining_size":"1.90000000","sequence":4839272249,"time":"2018-07-27T01:32:40.564000Z"}
{"type":"received","order_id":"0196d238-e559-46f1-99d3-d3d93438a8a7","order_type":"limit","size":"0.90000000","price":"795.14000000","side":"sell","client_oid":"70e03da6-4602-4f2f-b6e3-4c6dbab5f909","product_id":"BCH-USD","sequence":4839272250,"time":"2018-07-27T01:32:40.565000Z"}
{"type":"open","side":"sell","price":"795.14000000","order_id":"0196d238-e559-46f1-99d3-d3d93438a8a7","remaining_size":"0.90000000","product_id":"BCH-USD","sequence":4839272251,"time":"2018-07-27T01:32:40.565000Z"}
{"type":"received","order_id":"02354838-d430-4de7-ab85-5677d7cb21a5","order_type":"limit","size":"4.50000000","price":"795.14000000","side":"sell","client_oid":"ba2b4be3-4840-4857-a964-335d24c98994","product_id":"BCH-USD","sequence":4839272252,"time":"2018-07-27T01:32:40.567000Z"}
{"type":"open","side":"sell","price":"795.14000000","order_id":"02354838-d430-4de7-ab85-5677d7cb21a5","remaining_size":"4.50000000","product_id":"BCH-USD","sequence":4839272253,"time":"2018-07-27T01:32:40.567000Z"}
{"type":"received","order_id":"464a11f8-dc07-4fc6-b688-ac8dc97565ff","order_type":"limit","size":"1.90000000","price":"795.14000000","side":"sell","client_oid":"162048d0-6552-4eea-a7f7-61979816d27c","product_id":"BCH-USD","sequence":4839272254,"time":"2018-07-27T01:32:40.570000Z"}
{"type":"open","side":"sell","price":"795.14000000","order_id":"464a11f8-dc07-4fc6-b688-ac8dc97565ff","remaining_size":"1.90000000","product_id":"BCH-USD","sequence":4839272255,"time":"2018-07-27T01:32:40.570000Z"}
{"type":"done","side":"sell","order_id":"02354838-d430-4de7-ab85-5677d7cb21a5","reason":"canceled","product_id":"BCH-USD","price":"795.14000000","remaining_size":"4.50000000","sequence":4839272256,"time":"2018-07-27T01:32:40.572000Z"}
{"type":"done","side":"sell","order_id":"464a11f8-dc07-4fc6-b688-ac8dc97565ff","reason":"canceled","product_id":"BCH-USD","price":"795.14000000","remaining_size":"1.90000000","sequence":4839272257,"time":"2018-07-27T01:32:40.574000Z"}
{"type":"done","side":"sell","order_id":"0196d238-e559-46f1-99d3-d3d93438a8a7","reason":"canceled","product_id":"BCH-USD","price":"795.14000000","remaining_size":"0.90000000","sequence":4839272258,"time":"2018-07-27T01:32:40.578000Z"}
{"type":"received","order_id":"41411302-0a9f-4d18-b5a8-a9ce7da0932b","order_type":"limit","size":"1.90000000","price":"795.17000000","side":"sell","client_oid":"b131d787-e5ee-4973-92e8-c72b318bbab8","product_id":"BCH-USD","sequence":4839272259,"time":"2018-07-27T01:32:40.580000Z"}
{"type":"open","side":"sell","price":"795.17000000","order_id":"41411302-0a9f-4d18-b5a8-a9ce7da0932b","remaining_size":"1.90000000","product_id":"BCH-USD","sequence":4839272260,"time":"2018-07-27T01:32:40.580000Z"}
{"type":"received","order_id":"a32e3089-d879-4a61-b702-a0315ac5bae1","order_type":"limit","size":"1.90000000","price":"795.17000000","side":"sell","client_oid":"8aaeb088-95db-4170-8f1f-d7bf352c94a0","product_id":"BCH-USD","sequence":4839272261,"time":"2018-07-27T01:32:40.582000Z"}
{"type":"open","side":"sell","price":"795.17000000","order_id":"a32e3089-d879-4a61-b702-a0315ac5bae1","remaining_size":"1.90000000","product_id":"BCH-USD","sequence":4839272262,"time":"2018-07-27T01:32:40.582000Z"}
{"type":"done","side":"buy","order_id":"482be570-7151-4df1-a8cb-6169165284f9","reason":"canceled","product_id":"BCH-USD","price":"791.25000000","remaining_size":"1.81488800","sequence":4839272263,"time":"2018-07-27T01:32:40.584000Z"}
{"type":"received","order_id":"1a0be198-7048-494f-afdb-01fd4fca723f","order_type":"limit","size":"0.90000000","price":"795.17000000","side":"sell","client_oid":"fa6ebb45-1717-4750-9520-0737845d2083","product_id":"BCH-USD","sequence":4839272264,"time":"2018-07-27T01:32:40.586000Z"}
{"type":"open","side":"sell","price":"795.17000000","order_id":"1a0be198-7048-494f-afdb-01fd4fca723f","remaining_size":"0.90000000","product_id":"BCH-USD","sequence":4839272265,"time":"2018-07-27T01:32:40.586000Z"}
{"type":"done","side":"sell","order_id":"a32e3089-d879-4a61-b702-a0315ac5bae1","reason":"canceled","product_id":"BCH-USD","price":"795.17000000","remaining_size":"1.90000000","sequence":4839272266,"time":"2018-07-27T01:32:40.587000Z"}
{"type":"done","side":"buy","order_id":"cdab2202-7d1a-4385-a7d4-6e6a6fa2b3b5","reason":"canceled","product_id":"BCH-USD","price":"791.25000000","remaining_size":"0.18739300","sequence":4839272267,"time":"2018-07-27T01:32:40.588000Z"}
{"type":"done","side":"sell","order_id":"1a0be198-7048-494f-afdb-01fd4fca723f","reason":"canceled","product_id":"BCH-USD","price":"795.17000000","remaining_size":"0.90000000","sequence":4839272268,"time":"2018-07-27T01:32:40.589000Z"}
{"type":"done","side":"sell","order_id":"41411302-0a9f-4d18-b5a8-a9ce7da0932b","reason":"canceled","product_id":"BCH-USD","price":"795.17000000","remaining_size":"1.90000000","sequence":4839272269,"time":"2018-07-27T01:32:40.591000Z"}
{"type":"received","order_id":"dd865626-3a09-4d11-aeba-d4a5d37a6c1e","order_type":"limit","size":"4.50000000","price":"795.17000000","side":"sell","client_oid":"ae57c4f4-c04b-4ce5-9bb3-cb0411ee5d79","product_id":"BCH-USD","sequence":4839272270,"time":"2018-07-27T01:32:40.592000Z"}
{"type":"open","side":"sell","price":"795.17000000","order_id":"dd865626-3a09-4d11-aeba-d4a5d37a6c1e","remaining_size":"4.50000000","product_id":"BCH-USD","sequence":4839272271,"time":"2018-07-27T01:32:40.592000Z"}
{"type":"received","order_id":"2ad04419-85c8-4c56-b87a-f0a2fe2be6f6","order_type":"limit","size":"1.81488800","price":"791.26000000","side":"buy","client_oid":"fe272226-1bc4-4c6d-a2eb-1afde5fe33e1","product_id":"BCH-USD","sequence":4839272272,"time":"2018-07-27T01:32:40.594000Z"}
{"type":"open","side":"buy","price":"791.26000000","order_id":"2ad04419-85c8-4c56-b87a-f0a2fe2be6f6","remaining_size":"1.81488800","product_id":"BCH-USD","sequence":4839272273,"time":"2018-07-27T01:32:40.594000Z"}
{"type":"done","side":"sell","order_id":"dd865626-3a09-4d11-aeba-d4a5d37a6c1e","reason":"canceled","product_id":"BCH-USD","price":"795.17000000","remaining_size":"4.50000000","sequence":4839272274,"time":"2018-07-27T01:32:40.597000Z"}
{"type":"done","side":"buy","order_id":"2ad04419-85c8-4c56-b87a-f0a2fe2be6f6","reason":"canceled","product_id":"BCH-USD","price":"791.26000000","remaining_size":"1.81488800","sequence":4839272275,"time":"2018-07-27T01:32:40.598000Z"}
{"type":"received","order_id":"81ed0664-54be-4eed-8811-5888cced0763","order_type":"limit","size":"1.90000000","price":"795.16000000","side":"sell","client_oid":"2832d069-74d6-4371-8036-b7bda4d910c2","product_id":"BCH-USD","sequence":4839272276,"time":"2018-07-27T01:32:40.599000Z"}
{"type":"open","side":"sell","price":"795.16000000","order_id":"81ed0664-54be-4eed-8811-5888cced0763","remaining_size":"1.90000000","product_id":"BCH-USD","sequence":4839272277,"time":"2018-07-27T01:32:40.599000Z"}
{"type":"received","order_id":"340a823c-2b77-4c16-b9a1-fb08a2d0955e","order_type":"limit","size":"1.90000000","price":"795.16000000","side":"sell","client_oid":"58f1c8ec-bebf-46ca-b089-df3d2687cd28","product_id":"BCH-USD","sequence":4839272278,"time":"2018-07-27T01:32:40.600000Z"}
{"type":"open","side":"sell","price":"795.16000000","order_id":"340a823c-2b77-4c16-b9a1-fb08a2d0955e","remaining_size":"1.90000000","product_id":"BCH-USD","sequence":4839272279,"time":"2018-07-27T01:32:40.600000Z"}
{"type":"received","order_id":"3aa6df56-9142-4028-aea8-0e887de12c5f","order_type":"limit","size":"0.18739300","price":"791.26000000","side":"buy","client_oid":"dc759e54-22a2-4af2-8fb6-7a1464e5778d","product_id":"BCH-USD","sequence":4839272280,"time":"2018-07-27T01:32:40.600000Z"}
{"type":"open","side":"buy","price":"791.26000000","order_id":"3aa6df56-9142-4028-aea8-0e887de12c5f","remaining_size":"0.18739300","product_id":"BCH-USD","sequence":4839272281,"time":"2018-07-27T01:32:40.600000Z"}
{"type":"done","side":"buy","order_id":"3aa6df56-9142-4028-aea8-0e887de12c5f","reason":"canceled","product_id":"BCH-USD","price":"791.26000000","remaining_size":"0.18739300","sequence":4839272282,"time":"2018-07-27T01:32:40.605000Z"}
{"type":"done","side":"sell","order_id":"340a823c-2b77-4c16-b9a1-fb08a2d0955e","reason":"canceled","product_id":"BCH-USD","price":"795.16000000","remaining_size":"1.90000000","sequence":4839272283,"time":"2018-07-27T01:32:40.607000Z"}
{"type":"received","order_id":"891333ce-5961-4ce9-9819-32e29a42e080","order_type":"limit","size":"0.90000000","price":"795.16000000","side":"sell","client_oid":"5b66f3a0-960a-432a-b91c-855a3eb50ea7","product_id":"BCH-USD","sequence":4839272284,"time":"2018-07-27T01:32:40.607000Z"}
{"type":"open","side":"sell","price":"795.16000000","order_id":"891333ce-5961-4ce9-9819-32e29a42e080","remaining_size":"0.90000000","product_id":"BCH-USD","sequence":4839272285,"time":"2018-07-27T01:32:40.607000Z"}
{"type":"received","order_id":"014ec46a-a930-41a6-af1f-62f4814ffc9e","order_type":"limit","size":"4.50000000","price":"795.16000000","side":"sell","client_oid":"bb75d176-b98e-4e62-a9bc-50e821492868","product_id":"BCH-USD","sequence":4839272286,"time":"2018-07-27T01:32:40.608000Z"}
{"type":"open","side":"sell","price":"795.16000000","order_id":"014ec46a-a930-41a6-af1f-62f4814ffc9e","remaining_size":"4.50000000","product_id":"BCH-USD","sequence":4839272287,"time":"2018-07-27T01:32:40.608000Z"}
{"type":"done","side":"sell","order_id":"81ed0664-54be-4eed-8811-5888cced0763","reason":"canceled","product_id":"BCH-USD","price":"795.16000000","remaining_size":"1.90000000","sequence":4839272288,"time":"2018-07-27T01:32:40.609000Z"}
{"type":"done","side":"sell","order_id":"891333ce-5961-4ce9-9819-32e29a42e080","reason":"canceled","product_id":"BCH-USD","price":"795.16000000","remaining_size":"0.90000000","sequence":4839272289,"time":"2018-07-27T01:32:40.612000Z"}
{"type":"done","side":"sell","order_id":"014ec46a-a930-41a6-af1f-62f4814ffc9e","reason":"canceled","product_id":"BCH-USD","price":"795.16000000","remaining_size":"4.50000000","sequence":4839272290,"time":"2018-07-27T01:32:40.613000Z"}
{"type":"received","order_id":"894c09d8-8fb1-4a40-9fd7-8a180716b038","order_type":"limit","size":"1.81488800","price":"791.23000000","side":"buy","client_oid":"d0edb30f-efd5-4fb9-a6a9-095c13bbdf04","product_id":"BCH-USD","sequence":4839272291,"time":"2018-07-27T01:32:40.616000Z"}
{"type":"open","side":"buy","price":"791.23000000","order_id":"894c09d8-8fb1-4a40-9fd7-8a180716b038","remaining_size":"1.81488800","product_id":"BCH-USD","sequence":4839272292,"time":"2018-07-27T01:32:40.616000Z"}
{"type":"done","side":"buy","order_id":"755647ef-4739-4a38-977b-058ca5a0ab7f","reason":"canceled","product_id":"LTC-USD","price":"83.25000000","remaining_size":"20.00000000","sequence":2423271778,"time":"2018-07-27T01:32:40.621000Z"}
{"type":"received","order_id":"2c2a3d02-89c3-4018-a1eb-58beeba52065","order_type":"limit","size":"0.18739300","price":"791.23000000","side":"buy","client_oid":"5ac09bb7-66e0-416e-975f-0bc3294a1d07","product_id":"BCH-USD","sequence":4839272293,"time":"2018-07-27T01:32:40.622000Z"}
{"type":"open","side":"buy","price":"791.23000000","order_id":"2c2a3d02-89c3-4018-a1eb-58beeba52065","remaining_size":"0.18739300","product_id":"BCH-USD","sequence":4839272294,"time":"2018-07-27T01:32:40.622000Z"}
{"type":"received","order_id":"96f11b07-3332-4f1a-93b8-133c3b33feac","order_type":"limit","size":"0.90000000","price":"795.15000000","side":"sell","client_oid":"2285c99d-9f96-4997-bf1b-9482b97eb694","product_id":"BCH-USD","sequence":4839272295,"time":"2018-07-27T01:32:40.622000Z"}
{"type":"open","side":"sell","price":"795.15000000","order_id":"96f11b07-3332-4f1a-93b8-133c3b33feac","remaining_size":"0.90000000","product_id":"BCH-USD","sequence":4839272296,"time":"2018-07-27T01:32:40.622000Z"}
{"type":"done","side":"buy","order_id":"894c09d8-8fb1-4a40-9fd7-8a180716b038","reason":"canceled","product_id":"BCH-USD","price":"791.23000000","remaining_size":"1.81488800","sequence":4839272297,"time":"2018-07-27T01:32:40.623000Z"}
{"type":"done","side":"buy","order_id":"f5774e80-47f0-4d2b-bc6d-4ee561a433e8","reason":"canceled","product_id":"LTC-USD","price":"83.05000000","remaining_size":"3.17467700","sequence":2423271779,"time":"2018-07-27T01:32:40.625000Z"}
{"type":"received","order_id":"7fcf3af7-0e5f-4401-bed5-76fa4e06402c","order_type":"limit","size":"4.50000000","price":"795.15000000","side":"sell","client_oid":"4173acd3-f9e4-4502-ac13-dc372341f0af","product_id":"BCH-USD","sequence":4839272298,"time":"2018-07-27T01:32:40.625000Z"}
{"type":"open","side":"sell","price":"795.15000000","order_id":"7fcf3af7-0e5f-4401-bed5-76fa4e06402c","remaining_size":"4.50000000","product_id":"BCH-USD","sequence":4839272299,"time":"2018-07-27T01:32:40.625000Z"}
{"type":"received","order_id":"a1acb00e-3714-4bc7-bdfb-dae7f1a54f96","order_type":"limit","size":"1.90000000","price":"795.15000000","side":"sell","client_oid":"4b8bb2ec-2319-4e96-b3d0-8b33277937c4","product_id":"BCH-USD","sequence":4839272300,"time":"2018-07-27T01:32:40.625000Z"}
{"type":"open","side":"sell","price":"795.15000000","order_id":"a1acb00e-3714-4bc7-bdfb-dae7f1a54f96","remaining_size":"1.90000000","product_id":"BCH-USD","sequence":4839272301,"time":"2018-07-27T01:32:40.625000Z"}
{"type":"done","side":"sell","order_id":"96f11b07-3332-4f1a-93b8-133c3b33feac","reason":"canceled","product_id":"BCH-USD","price":"795.15000000","remaining_size":"0.90000000","sequence":4839272302,"time":"2018-07-27T01:32:40.627000Z"}
{"type":"done","side":"buy","order_id":"2c2a3d02-89c3-4018-a1eb-58beeba52065","reason":"canceled","product_id":"BCH-USD","price":"791.23000000","remaining_size":"0.18739300","sequence":4839272303,"time":"2018-07-27T01:32:40.628000Z"}
{"type":"done","side":"buy","order_id":"1bb9d76e-0aeb-4fd6-8f74-8bf94c03a574","reason":"canceled","product_id":"LTC-USD","price":"83.03000000","remaining_size":"4.83845000","sequence":2423271780,"time":"2018-07-27T01:32:40.631000Z"}
{"type":"done","side":"sell","order_id":"a1acb00e-3714-4bc7-bdfb-dae7f1a54f96","reason":"canceled","product_id":"BCH-USD","price":"795.15000000","remaining_size":"1.90000000","sequence":4839272304,"time":"2018-07-27T01:32:40.631000Z"}
{"type":"received","order_id":"083c62cd-ed24-4627-9fd0-5320541cfc5c","order_type":"limit","size":"1.90000000","price":"795.15000000","side":"sell","client_oid":"d559719a-fce9-414b-a686-db0d8d63f438","product_id":"BCH-USD","sequence":4839272305,"time":"2018-07-27T01:32:40.632000Z"}
{"type":"open","side":"sell","price":"795.15000000","order_id":"083c62cd-ed24-4627-9fd0-5320541cfc5c","remaining_size":"1.90000000","product_id":"BCH-USD","sequence":4839272306,"time":"2018-07-27T01:32:40.632000Z"}
{"type":"done","side":"sell","order_id":"7fcf3af7-0e5f-4401-bed5-76fa4e06402c","reason":"canceled","product_id":"BCH-USD","price":"795.15000000","remaining_size":"4.50000000","sequence":4839272307,"time":"2018-07-27T01:32:40.633000Z"}
{"type":"done","side":"buy","order_id":"bca4ff18-6def-474a-aff9-197f2a72f13b","reason":"canceled","product_id":"LTC-USD","price":"83.01000000","remaining_size":"9.94519000","sequence":2423271781,"time":"2018-07-27T01:32:40.635000Z"}
{"type":"done","side":"sell","order_id":"083c62cd-ed24-4627-9fd0-5320541cfc5c","reason":"canceled","product_id":"BCH-USD","price":"795.15000000","remaining_size":"1.90000000","sequence":4839272308,"time":"2018-07-27T01:32:40.635000Z"}
{"type":"received","order_id":"6f78169b-3c22-452c-be4b-36df0fc59ab9","order_type":"limit","size":"0.10000000","price":"83.39000000","side":"sell","client_oid":"f3a157a6-913c-11e8-8d2c-16be7828d23e","product_id":"LTC-USD","sequence":2423271782,"time":"2018-07-27T01:32:40.638000Z"}
{"type":"done","side":"sell","order_id":"6f78169b-3c22-452c-be4b-36df0fc59ab9","reason":"canceled","product_id":"LTC-USD","price":"83.39000000","remaining_size":"0.10000000","sequence":2423271783,"time":"2018-07-27T01:32:40.638000Z"}
{"type":"received","order_id":"c4c9dabe-4500-42b9-bb04-702c80d893a7","order_type":"limit","size":"20.00000000","price":"83.23000000","side":"buy","client_oid":"0e296230-5c77-4ef4-b4b8-89b119c8138c","product_id":"LTC-USD","sequence":2423271784,"time":"2018-07-27T01:32:40.639000Z"}
{"type":"open","side":"buy","price":"83.23000000","order_id":"c4c9dabe-4500-42b9-bb04-702c80d893a7","remaining_size":"20.00000000","product_id":"LTC-USD","sequence":2423271785,"time":"2018-07-27T01:32:40.639000Z"}
{"type":"done","side":"buy","order_id":"b1beea06-5ba1-4f76-8994-87cbbd3be5ea","reason":"canceled","product_id":"LTC-USD","price":"82.95000000","remaining_size":"26.67592100","sequence":2423271786,"time":"2018-07-27T01:32:40.639000Z"}
{"type":"received","order_id":"6ba5b56c-bdde-47ad-a871-e99289c4fe0f","order_type":"limit","size":"1.81488800","price":"791.24000000","side":"buy","client_oid":"d7fc03cb-e47b-425c-a1fc-5ee33596553d","product_id":"BCH-USD","sequence":4839272309,"time":"2018-07-27T01:32:40.639000Z"}
{"type":"open","side":"buy","price":"791.24000000","order_id":"6ba5b56c-bdde-47ad-a871-e99289c4fe0f","remaining_size":"1.81488800","product_id":"BCH-USD","sequence":4839272310,"time":"2018-07-27T01:32:40.639000Z"}
{"type":"received","order_id":"b2f6faf2-81f6-4019-b52f-6da291b8f8ba","order_type":"limit","size":"0.18739300","price":"791.24000000","side":"buy","client_oid":"431c7718-e1ea-4a82-8edc-e6ea579dd83f","product_id":"BCH-USD","sequence":4839272311,"time":"2018-07-27T01:32:40.640000Z"}
{"type":"open","side":"buy","price":"791.24000000","order_id":"b2f6faf2-81f6-4019-b52f-6da291b8f8ba","remaining_size":"0.18739300","product_id":"BCH-USD","sequence":4839272312,"time":"2018-07-27T01:32:40.640000Z"}
{"type":"done","side":"buy","order_id":"8e391a6d-618d-402b-bb40-c60edf9f66da","reason":"canceled","product_id":"LTC-USD","price":"82.93000000","remaining_size":"123.67254800","sequence":2423271787,"time":"2018-07-27T01:32:40.643000Z"}
{"type":"received","order_id":"b4b88ced-9d5a-40ab-bafb-ce9c82bd1661","order_type":"limit","size":"0.90000000","price":"795.17000000","side":"sell","client_oid":"2c9a3184-5732-42f7-8414-70ef0f140f86","product_id":"BCH-USD","sequence":4839272313,"time":"2018-07-27T01:32:40.643000Z"}
{"type":"open","side":"sell","price":"795.17000000","order_id":"b4b88ced-9d5a-40ab-bafb-ce9c82bd1661","remaining_size":"0.90000000","product_id":"BCH-USD","sequence":4839272314,"time":"2018-07-27T01:32:40.643000Z"}
{"type":"received","order_id":"090afd67-b766-44f6-8f69-62aa47ead891","order_type":"limit","size":"4.50000000","price":"795.17000000","side":"sell","client_oid":"34aa75a0-38dc-4df8-91e4-013806950837","product_id":"BCH-USD","sequence":4839272315,"time":"2018-07-27T01:32:40.644000Z"}
{"type":"open","side":"sell","price":"795.17000000","order_id":"090afd67-b766-44f6-8f69-62aa47ead891","remaining_size":"4.50000000","product_id":"BCH-USD","sequence":4839272316,"time":"2018-07-27T01:32:40.644000Z"}
{"type":"done","side":"buy","order_id":"6ba5b56c-bdde-47ad-a871-e99289c4fe0f","reason":"canceled","product_id":"BCH-USD","price":"791.24000000","remaining_size":"1.81488800","sequence":4839272317,"time":"2018-07-27T01:32:40.645000Z"}
{"type":"done","side":"buy","order_id":"b2f6faf2-81f6-4019-b52f-6da291b8f8ba","reason":"canceled","product_id":"BCH-USD","price":"791.24000000","remaining_size":"0.18739300","sequence":4839272318,"time":"2018-07-27T01:32:40.646000Z"}
{"type":"done","side":"sell","order_id":"b4b88ced-9d5a-40ab-bafb-ce9c82bd1661","reason":"canceled","product_id":"BCH-USD","price":"795.17000000","remaining_size":"0.90000000","sequence":4839272319,"time":"2018-07-27T01:32:40.647000Z"}
{"type":"done","side":"buy","order_id":"cc0a9651-aec7-4bb9-997e-bc1454e30c04","reason":"canceled","product_id":"LTC-USD","price":"82.91000000","remaining_size":"101.76255900","sequence":2423271788,"time":"2018-07-27T01:32:40.649000Z"}
{"type":"received","order_id":"d24d77d6-0a17-43d2-b8f6-f63f8781997b","order_type":"limit","size":"1.90000000","price":"795.17000000","side":"sell","client_oid":"2aee3725-6766-41ef-964f-3a1929c5307c","product_id":"BCH-USD","sequence":4839272320,"time":"2018-07-27T01:32:40.651000Z"}
{"type":"open","side":"sell","price":"795.17000000","order_id":"d24d77d6-0a17-43d2-b8f6-f63f8781997b","remaining_size":"1.90000000","product_id":"BCH-USD","sequence":4839272321,"time":"2018-07-27T01:32:40.651000Z"}
{"type":"done","side":"sell","order_id":"3d756649-9961-49a7-9767-059584d407b0","reason":"canceled","product_id":"LTC-USD","price":"83.30000000","remaining_size":"7.44874862","sequence":2423271789,"time":"2018-07-27T01:32:40.661000Z"}
{"type":"received","order_id":"434f9f7c-680e-4141-833a-0f33c0f672c4","order_type":"limit","size":"1.81488800","price":"791.23000000","side":"buy","client_oid":"e9a23eef-af70-4677-b10f-379a249040b0","product_id":"BCH-USD","sequence":4839272322,"time":"2018-07-27T01:32:40.659000Z"}
{"type":"open","side":"buy","price":"791.23000000","order_id":"434f9f7c-680e-4141-833a-0f33c0f672c4","remaining_size":"1.81488800","product_id":"BCH-USD","sequence":4839272323,"time":"2018-07-27T01:32:40.659000Z"}
{"type":"received","order_id":"29d54b2f-884d-4fea-8300-6dad3e75036c","order_type":"limit","size":"0.18739300","price":"791.23000000","side":"buy","client_oid":"0af8c2b2-e538-4497-8cec-300031a5539e","product_id":"BCH-USD","sequence":4839272324,"time":"2018-07-27T01:32:40.661000Z"}
{"type":"open","side":"buy","price":"791.23000000","order_id":"29d54b2f-884d-4fea-8300-6dad3e75036c","remaining_size":"0.18739300","product_id":"BCH-USD","sequence":4839272325,"time":"2018-07-27T01:32:40.661000Z"}
{"type":"done","side":"sell","order_id":"090afd67-b766-44f6-8f69-62aa47ead891","reason":"canceled","product_id":"BCH-USD","price":"795.17000000","remaining_size":"4.50000000","sequence":4839272326,"time":"2018-07-27T01:32:40.661000Z"}
{"type":"done","side":"buy","order_id":"29d54b2f-884d-4fea-8300-6dad3e75036c","reason":"canceled","product_id":"BCH-USD","price":"791.23000000","remaining_size":"0.18739300","sequence":4839272327,"time":"2018-07-27T01:32:40.667000Z"}
{"type":"received","order_id":"a3f55aca-2005-4597-85c8-4addbb57c9a3","order_type":"limit","size":"4.50000000","price":"795.16000000","side":"sell","client_oid":"3ac7255e-8562-494d-9ed8-b99adb8e833e","product_id":"BCH-USD","sequence":4839272328,"time":"2018-07-27T01:32:40.669000Z"}
{"type":"open","side":"sell","price":"795.16000000","order_id":"a3f55aca-2005-4597-85c8-4addbb57c9a3","remaining_size":"4.50000000","product_id":"BCH-USD","sequence":4839272329,"time":"2018-07-27T01:32:40.669000Z"}
{"type":"done","side":"buy","order_id":"434f9f7c-680e-4141-833a-0f33c0f672c4","reason":"canceled","product_id":"BCH-USD","price":"791.23000000","remaining_size":"1.81488800","sequence":4839272330,"time":"2018-07-27T01:32:40.670000Z"}
{"type":"received","order_id":"b6534b80-f130-4d40-bbef-2d5bbb32290e","order_type":"limit","size":"0.90000000","price":"795.14000000","side":"sell","client_oid":"342d620f-be9a-4cb7-b426-6339a167bfad","product_id":"BCH-USD","sequence":4839272331,"time":"2018-07-27T01:32:40.671000Z"}
{"type":"open","side":"sell","price":"795.14000000","order_id":"b6534b80-f130-4d40-bbef-2d5bbb32290e","remaining_size":"0.90000000","product_id":"BCH-USD","sequence":4839272332,"time":"2018-07-27T01:32:40.671000Z"}
{"type":"done","side":"sell","order_id":"a3f55aca-2005-4597-85c8-4addbb57c9a3","reason":"canceled","product_id":"BCH-USD","price":"795.16000000","remaining_size":"4.50000000","sequence":4839272333,"time":"2018-07-27T01:32:40.674000Z"}
{"type":"received","order_id":"a7641881-71d1-488b-88d4-53710d2bcdde","order_type":"limit","size":"0.18739300","price":"791.24000000","side":"buy","client_oid":"20e4e83a-ef59-4305-9408-425136263055","product_id":"BCH-USD","sequence":4839272334,"time":"2018-07-27T01:32:40.676000Z"}
{"type":"received","order_id":"5429753d-ff1b-446f-bdd9-8d7d928f9973","order_type":"limit","size":"7.44874862","price":"83.34000000","side":"sell","client_oid":"b6d28baf-3fef-4581-8000-078d0940bc70","product_id":"LTC-USD","sequence":2423271790,"time":"2018-07-27T01:32:40.678000Z"}
{"type":"open","side":"buy","price":"791.24000000","order_id":"a7641881-71d1-488b-88d4-53710d2bcdde","remaining_size":"0.18739300","product_id":"BCH-USD","sequence":4839272335,"time":"2018-07-27T01:32:40.676000Z"}
{"type":"done","side":"sell","order_id":"b6534b80-f130-4d40-bbef-2d5bbb32290e","reason":"canceled","product_id":"BCH-USD","price":"795.14000000","remaining_size":"0.90000000","sequence":4839272336,"time":"2018-07-27T01:32:40.676000Z"}
{"type":"open","side":"sell","price":"83.34000000","order_id":"5429753d-ff1b-446f-bdd9-8d7d928f9973","remaining_size":"7.44874862","product_id":"LTC-USD","sequence":2423271791,"time":"2018-07-27T01:32:40.678000Z"}
{"type":"received","order_id":"3043d0d7-f2fd-4853-a9fc-01a5b45ecc2c","order_type":"limit","size":"1.81488800","price":"791.24000000","side":"buy","client_oid":"407feb82-2595-40b0-8366-482608168a72","product_id":"BCH-USD","sequence":4839272337,"time":"2018-07-27T01:32:40.679000Z"}
{"type":"received","order_id":"72b2c5af-d205-436e-8180-5b08dc1cfa3a","order_type":"limit","size":"9.50380000","price":"84.06000000","side":"sell","product_id":"LTC-USD","sequence":2423271792,"time":"2018-07-27T01:32:40.681000Z"}
{"type":"open","side":"buy","price":"791.24000000","order_id":"3043d0d7-f2fd-4853-a9fc-01a5b45ecc2c","remaining_size":"1.81488800","product_id":"BCH-USD","sequence":4839272338,"time":"2018-07-27T01:32:40.679000Z"}
{"type":"done","side":"sell","order_id":"d24d77d6-0a17-43d2-b8f6-f63f8781997b","reason":"canceled","product_id":"BCH-USD","price":"795.17000000","remaining_size":"1.90000000","sequence":4839272339,"time":"2018-07-27T01:32:40.680000Z"}
{"type":"open","side":"sell","price":"84.06000000","order_id":"72b2c5af-d205-436e-8180-5b08dc1cfa3a","remaining_size":"9.50380000","product_id":"LTC-USD","sequence":2423271793,"time":"2018-07-27T01:32:40.681000Z"}
{"type":"done","side":"buy","order_id":"3043d0d7-f2fd-4853-a9fc-01a5b45ecc2c","reason":"canceled","product_id":"BCH-USD","price":"791.24000000","remaining_size":"1.81488800","sequence":4839272340,"time":"2018-07-27T01:32:40.684000Z"}
{"type":"received","order_id":"0e75972b-3fef-42b0-a609-f51fa1e220d0","order_type":"limit","size":"4.50000000","price":"795.17000000","side":"sell","client_oid":"014ae65c-2e38-430a-8a0f-e5239d905f42","product_id":"BCH-USD","sequence":4839272341,"time":"2018-07-27T01:32:40.684000Z"}
{"type":"open","side":"sell","price":"795.17000000","order_id":"0e75972b-3fef-42b0-a609-f51fa1e220d0","remaining_size":"4.50000000","product_id":"BCH-USD","sequence":4839272342,"time":"2018-07-27T01:32:40.684000Z"}
{"type":"received","order_id":"e1c43b8a-64ae-4eed-bc9f-4005a8d4f4f5","order_type":"limit","size":"3.96192000","price":"83.05000000","side":"buy","client_oid":"4b575255-9cf6-4b58-8373-b14137fffcdc","product_id":"LTC-USD","sequence":2423271794,"time":"2018-07-27T01:32:40.686000Z"}
{"type":"done","side":"buy","order_id":"a7641881-71d1-488b-88d4-53710d2bcdde","reason":"canceled","product_id":"BCH-USD","price":"791.24000000","remaining_size":"0.18739300","sequence":4839272343,"time":"2018-07-27T01:32:40.685000Z"}
{"type":"open","side":"buy","price":"83.05000000","order_id":"e1c43b8a-64ae-4eed-bc9f-4005a8d4f4f5","remaining_size":"3.96192000","product_id":"LTC-USD","sequence":2423271795,"time":"2018-07-27T01:32:40.686000Z"}
{"type":"received","order_id":"190fda11-cf7a-4505-a1e4-89cc7b91e913","order_type":"limit","size":"0.90000000","price":"795.17000000","side":"sell","client_oid":"2500d785-ec83-4cb4-86ea-9e3336c1d989","product_id":"BCH-USD","sequence":4839272344,"time":"2018-07-27T01:32:40.688000Z"}
{"type":"open","side":"sell","price":"795.17000000","order_id":"190fda11-cf7a-4505-a1e4-89cc7b91e913","remaining_size":"0.90000000","product_id":"BCH-USD","sequence":4839272345,"time":"2018-07-27T01:32:40.688000Z"}
{"type":"received","order_id":"4c39fdc6-18ef-4a3b-8f7a-1f8adb0c3ebd","order_type":"limit","size":"1.90000000","price":"795.15000000","side":"sell","client_oid":"9e132db3-b5ce-433a-bcf9-b02b04f3c796","product_id":"BCH-USD","sequence":4839272346,"time":"2018-07-27T01:32:40.691000Z"}
{"type":"open","side":"sell","price":"795.15000000","order_id":"4c39fdc6-18ef-4a3b-8f7a-1f8adb0c3ebd","remaining_size":"1.90000000","product_id":"BCH-USD","sequence":4839272347,"time":"2018-07-27T01:32:40.691000Z"}
{"type":"received","order_id":"a2588f1c-e093-4535-ba6c-d356527c49ec","order_type":"limit","size":"1.81488800","price":"791.23000000","side":"buy","client_oid":"d7701054-d241-4f28-a2fe-84893baa6c33","product_id":"BCH-USD","sequence":4839272348,"time":"2018-07-27T01:32:40.691000Z"}
{"type":"open","side":"buy","price":"791.23000000","order_id":"a2588f1c-e093-4535-ba6c-d356527c49ec","remaining_size":"1.81488800","product_id":"BCH-USD","sequence":4839272349,"time":"2018-07-27T01:32:40.691000Z"}
{"type":"done","side":"sell","order_id":"0e75972b-3fef-42b0-a609-f51fa1e220d0","reason":"canceled","product_id":"BCH-USD","price":"795.17000000","remaining_size":"4.50000000","sequence":4839272350,"time":"2018-07-27T01:32:40.693000Z"}
{"type":"received","order_id":"64f448a8-5989-4e77-8a6a-2952942a9855","order_type":"limit","size":"0.18739300","price":"791.23000000","side":"buy","client_oid":"9b6237c7-3989-4651-afbe-79deac87dd68","product_id":"BCH-USD","sequence":4839272351,"time":"2018-07-27T01:32:40.695000Z"}
{"type":"open","side":"buy","price":"791.23000000","order_id":"64f448a8-5989-4e77-8a6a-2952942a9855","remaining_size":"0.18739300","product_id":"BCH-USD","sequence":4839272352,"time":"2018-07-27T01:32:40.695000Z"}
{"type":"done","side":"sell","order_id":"190fda11-cf7a-4505-a1e4-89cc7b91e913","reason":"canceled","product_id":"BCH-USD","price":"795.17000000","remaining_size":"0.90000000","sequence":4839272353,"time":"2018-07-27T01:32:40.696000Z"}
{"type":"done","side":"sell","order_id":"4c39fdc6-18ef-4a3b-8f7a-1f8adb0c3ebd","reason":"canceled","product_id":"BCH-USD","price":"795.15000000","remaining_size":"1.90000000","sequence":4839272354,"time":"2018-07-27T01:32:40.698000Z"}
{"type":"received","order_id":"59d41a24-2398-45c1-abf8-3c160c195ef9","order_type":"limit","size":"6.04639400","price":"83.03000000","side":"buy","client_oid":"0580bc7b-3dee-4208-97a5-2fcefca4b90d","product_id":"LTC-USD","sequence":2423271796,"time":"2018-07-27T01:32:40.701000Z"}
{"type":"done","side":"buy","order_id":"a2588f1c-e093-4535-ba6c-d356527c49ec","reason":"canceled","product_id":"BCH-USD","price":"791.23000000","remaining_size":"1.81488800","sequence":4839272355,"time":"2018-07-27T01:32:40.699000Z"}
{"type":"open","side":"buy","price":"83.03000000","order_id":"59d41a24-2398-45c1-abf8-3c160c195ef9","remaining_size":"6.04639400","product_id":"LTC-USD","sequence":2423271797,"time":"2018-07-27T01:32:40.701000Z"}
{"type":"received","order_id":"504fe11b-f4d7-45fd-9f72-1c3b29af199e","order_type":"limit","size":"4.50000000","price":"795.16000000","side":"sell","client_oid":"185e0c2d-dd4c-4fbd-b38d-1bed82ca73ea","product_id":"BCH-USD","sequence":4839272356,"time":"2018-07-27T01:32:40.705000Z"}
{"type":"open","side":"sell","price":"795.16000000","order_id":"504fe11b-f4d7-45fd-9f72-1c3b29af199e","remaining_size":"4.50000000","product_id":"BCH-USD","sequence":4839272357,"time":"2018-07-27T01:32:40.705000Z"}
{"type":"received","order_id":"77859b55-85b8-4700-b88a-a18671a2bcc3","order_type":"limit","size":"1.81488800","price":"791.24000000","side":"buy","client_oid":"ddf49726-d7b7-406f-8e25-79f2133188af","product_id":"BCH-USD","sequence":4839272358,"time":"2018-07-27T01:32:40.709000Z"}
{"type":"open","side":"buy","price":"791.24000000","order_id":"77859b55-85b8-4700-b88a-a18671a2bcc3","remaining_size":"1.81488800","product_id":"BCH-USD","sequence":4839272359,"time":"2018-07-27T01:32:40.709000Z"}
{"type":"done","side":"sell","order_id":"504fe11b-f4d7-45fd-9f72-1c3b29af199e","reason":"canceled","product_id":"BCH-USD","price":"795.16000000","remaining_size":"4.50000000","sequence":4839272360,"time":"2018-07-27T01:32:40.709000Z"}
{"type":"received","order_id":"878fdfdf-42ff-42d6-8a10-7cdb924ab33f","order_type":"limit","size":"1.90000000","price":"795.16000000","side":"sell","client_oid":"0a3180a9-4de6-46a8-a0bb-463a2375adbd","product_id":"BCH-USD","sequence":4839272361,"time":"2018-07-27T01:32:40.712000Z"}
{"type":"received","order_id":"1c4eb79f-89d9-476a-97a3-25d596a1bdc6","order_type":"limit","size":"12.25851900","price":"83.01000000","side":"buy","client_oid":"4aa4eac1-830c-4d22-8b2b-b01f3cb801ec","product_id":"LTC-USD","sequence":2423271798,"time":"2018-07-27T01:32:40.714000Z"}
{"type":"open","side":"sell","price":"795.16000000","order_id":"878fdfdf-42ff-42d6-8a10-7cdb924ab33f","remaining_size":"1.90000000","product_id":"BCH-USD","sequence":4839272362,"time":"2018-07-27T01:32:40.712000Z"}
{"type":"done","side":"buy","order_id":"77859b55-85b8-4700-b88a-a18671a2bcc3","reason":"canceled","product_id":"BCH-USD","price":"791.24000000","remaining_size":"1.81488800","sequence":4839272363,"time":"2018-07-27T01:32:40.713000Z"}
{"type":"open","side":"buy","price":"83.01000000","order_id":"1c4eb79f-89d9-476a-97a3-25d596a1bdc6","remaining_size":"12.25851900","product_id":"LTC-USD","sequence":2423271799,"time":"2018-07-27T01:32:40.714000Z"}
{"type":"done","side":"sell","order_id":"878fdfdf-42ff-42d6-8a10-7cdb924ab33f","reason":"canceled","product_id":"BCH-USD","price":"795.16000000","remaining_size":"1.90000000","sequence":4839272364,"time":"2018-07-27T01:32:40.715000Z"}
{"type":"received","order_id":"e15c26f0-f647-40b4-96fc-6cd573a1d6c6","order_type":"limit","size":"4.50000000","price":"795.17000000","side":"sell","client_oid":"1bc37192-a155-479c-8962-e9491212ff36","product_id":"BCH-USD","sequence":4839272365,"time":"2018-07-27T01:32:40.719000Z"}
{"type":"open","side":"sell","price":"795.17000000","order_id":"e15c26f0-f647-40b4-96fc-6cd573a1d6c6","remaining_size":"4.50000000","product_id":"BCH-USD","sequence":4839272366,"time":"2018-07-27T01:32:40.719000Z"}
{"type":"received","order_id":"25c08523-dd69-4cad-8a36-5a1f04b54231","order_type":"limit","size":"1.81488800","price":"791.23000000","side":"buy","client_oid":"ed9ded5e-91d3-4d91-9467-6585d9a9b32d","product_id":"BCH-USD","sequence":4839272367,"time":"2018-07-27T01:32:40.720000Z"}
{"type":"open","side":"buy","price":"791.23000000","order_id":"25c08523-dd69-4cad-8a36-5a1f04b54231","remaining_size":"1.81488800","product_id":"BCH-USD","sequence":4839272368,"time":"2018-07-27T01:32:40.720000Z"}
{"type":"received","order_id":"61d5691f-ca50-401d-80f1-edbed4913bfa","order_type":"limit","size":"1.90000000","price":"795.15000000","side":"sell","client_oid":"c4d57ccb-330f-437b-a951-4af75b421c77","product_id":"BCH-USD","sequence":4839272369,"time":"2018-07-27T01:32:40.722000Z"}
{"type":"open","side":"sell","price":"795.15000000","order_id":"61d5691f-ca50-401d-80f1-edbed4913bfa","remaining_size":"1.90000000","product_id":"BCH-USD","sequence":4839272370,"time":"2018-07-27T01:32:40.722000Z"}
{"type":"done","side":"buy","order_id":"64f448a8-5989-4e77-8a6a-2952942a9855","reason":"canceled","product_id":"BCH-USD","price":"791.23000000","remaining_size":"0.18739300","sequence":4839272371,"time":"2018-07-27T01:32:40.723000Z"}
{"type":"received","order_id":"88cadb1c-9b24-47fc-b887-f39ce099653b","order_type":"limit","size":"31.44458700","price":"82.95000000","side":"buy","client_oid":"439e5e56-39c8-42ab-bf47-23f56fd39af1","product_id":"LTC-USD","sequence":2423271800,"time":"2018-07-27T01:32:40.727000Z"}
{"type":"open","side":"buy","price":"82.95000000","order_id":"88cadb1c-9b24-47fc-b887-f39ce099653b","remaining_size":"31.44458700","product_id":"LTC-USD","sequence":2423271801,"time":"2018-07-27T01:32:40.727000Z"}
{"type":"done","side":"sell","order_id":"61d5691f-ca50-401d-80f1-edbed4913bfa","reason":"canceled","product_id":"BCH-USD","price":"795.15000000","remaining_size":"1.90000000","sequence":4839272372,"time":"2018-07-27T01:32:40.726000Z"}
{"type":"done","side":"sell","order_id":"e15c26f0-f647-40b4-96fc-6cd573a1d6c6","reason":"canceled","product_id":"BCH-USD","price":"795.17000000","remaining_size":"4.50000000","sequence":4839272373,"time":"2018-07-27T01:32:40.728000Z"}
{"type":"received","order_id":"068fe54f-7eff-4b8f-90a7-dc396a10d297","order_type":"limit","size":"0.18739300","price":"791.25000000","side":"buy","client_oid":"20e40698-42c8-42af-b530-63f08865cadc","product_id":"BCH-USD","sequence":4839272374,"time":"2018-07-27T01:32:40.732000Z"}
{"type":"open","side":"buy","price":"791.25000000","order_id":"068fe54f-7eff-4b8f-90a7-dc396a10d297","remaining_size":"0.18739300","product_id":"BCH-USD","sequence":4839272375,"time":"2018-07-27T01:32:40.732000Z"}
{"type":"done","side":"buy","order_id":"068fe54f-7eff-4b8f-90a7-dc396a10d297","reason":"canceled","product_id":"BCH-USD","price":"791.25000000","remaining_size":"0.18739300","sequence":4839272376,"time":"2018-07-27T01:32:40.735000Z"}
{"type":"received","order_id":"182b13b7-b897-4056-83b2-ed5411e48ff3","order_type":"limit","size":"1.90000000","price":"795.17000000","side":"sell","client_oid":"7d8694d8-cc46-48b8-9b38-d8dcb282bfcc","product_id":"BCH-USD","sequence":4839272377,"time":"2018-07-27T01:32:40.738000Z"}
{"type":"open","side":"sell","price":"795.17000000","order_id":"182b13b7-b897-4056-83b2-ed5411e48ff3","remaining_size":"1.90000000","product_id":"BCH-USD","sequence":4839272378,"time":"2018-07-27T01:32:40.738000Z"}
{"type":"received","order_id":"dc96cf5e-01ee-4cad-81a9-c86fdfaeb5b9","order_type":"limit","size":"1.90000000","price":"795.17000000","side":"sell","client_oid":"19f7886b-2901-4f80-84ab-32d95f8bd944","product_id":"BCH-USD","sequence":4839272379,"time":"2018-07-27T01:32:40.740000Z"}
{"type":"open","side":"sell","price":"795.17000000","order_id":"dc96cf5e-01ee-4cad-81a9-c86fdfaeb5b9","remaining_size":"1.90000000","product_id":"BCH-USD","sequence":4839272380,"time":"2018-07-27T01:32:40.740000Z"}
{"type":"received","order_id":"a6b64dd1-65c5-485b-92af-55fc7dea817c","order_type":"limit","size":"0.90000000","price":"795.16000000","side":"sell","client_oid":"8e5c405d-acbb-4b46-bf97-1b45771474dc","product_id":"BCH-USD","sequence":4839272381,"time":"2018-07-27T01:32:40.742000Z"}
{"type":"open","side":"sell","price":"795.16000000","order_id":"a6b64dd1-65c5-485b-92af-55fc7dea817c","remaining_size":"0.90000000","product_id":"BCH-USD","sequence":4839272382,"time":"2018-07-27T01:32:40.742000Z"}
{"type":"received","order_id":"875adb51-927a-4c95-9f23-9b35983b4136","order_type":"limit","size":"134.34493100","price":"82.93000000","side":"buy","client_oid":"dfa6552f-aef1-485f-9492-ddb0fc984820","product_id":"LTC-USD","sequence":2423271802,"time":"2018-07-27T01:32:40.749000Z"}
{"type":"open","side":"buy","price":"82.93000000","order_id":"875adb51-927a-4c95-9f23-9b35983b4136","remaining_size":"134.34493100","product_id":"LTC-USD","sequence":2423271803,"time":"2018-07-27T01:32:40.749000Z"}
{"type":"done","side":"sell","order_id":"5429753d-ff1b-446f-bdd9-8d7d928f9973","reason":"canceled","product_id":"LTC-USD","price":"83.34000000","remaining_size":"7.44874862","sequence":2423271804,"time":"2018-07-27T01:32:40.749000Z"}
{"type":"received","order_id":"79b8ebc4-c0b4-404d-9004-ca1e55e77bb3","order_type":"limit","size":"0.18739300","price":"791.24000000","side":"buy","client_oid":"372fde88-aaef-4853-987c-8e43b507f6cf","product_id":"BCH-USD","sequence":4839272383,"time":"2018-07-27T01:32:40.748000Z"}
{"type":"open","side":"buy","price":"791.24000000","order_id":"79b8ebc4-c0b4-404d-9004-ca1e55e77bb3","remaining_size":"0.18739300","product_id":"BCH-USD","sequence":4839272384,"time":"2018-07-27T01:32:40.748000Z"}
{"type":"done","side":"sell","order_id":"dc96cf5e-01ee-4cad-81a9-c86fdfaeb5b9","reason":"canceled","product_id":"BCH-USD","price":"795.17000000","remaining_size":"1.90000000","sequence":4839272385,"time":"2018-07-27T01:32:40.749000Z"}
{"type":"received","order_id":"b6df4fcb-ee51-444a-9f73-b866764e5b6f","order_type":"limit","size":"4.50000000","price":"795.16000000","side":"sell","client_oid":"b2a78bc7-a509-415c-9b28-84a14706b37f","product_id":"BCH-USD","sequence":4839272386,"time":"2018-07-27T01:32:40.753000Z"}
{"type":"open","side":"sell","price":"795.16000000","order_id":"b6df4fcb-ee51-444a-9f73-b866764e5b6f","remaining_size":"4.50000000","product_id":"BCH-USD","sequence":4839272387,"time":"2018-07-27T01:32:40.753000Z"}
{"type":"received","order_id":"810513cd-cc4e-4273-ba6c-dd0e018d28f2","order_type":"limit","size":"1.90000000","price":"795.16000000","side":"sell","client_oid":"abfa3d3c-77f7-4ca7-8762-92bed24a76cc","product_id":"BCH-USD","sequence":4839272388,"time":"2018-07-27T01:32:40.756000Z"}
{"type":"open","side":"sell","price":"795.16000000","order_id":"810513cd-cc4e-4273-ba6c-dd0e018d28f2","remaining_size":"1.90000000","product_id":"BCH-USD","sequence":4839272389,"time":"2018-07-27T01:32:40.756000Z"}
{"type":"done","side":"buy","order_id":"25c08523-dd69-4cad-8a36-5a1f04b54231","reason":"canceled","product_id":"BCH-USD","price":"791.23000000","remaining_size":"1.81488800","sequence":4839272390,"time":"2018-07-27T01:32:40.756000Z"}
{"type":"received","order_id":"8bf40e09-f889-44e2-ad53-f535a082ea2f","order_type":"limit","size":"82.00225100","price":"82.91000000","side":"buy","client_oid":"b3bf982a-a3ff-4f06-947e-b6e88e870b8d","product_id":"LTC-USD","sequence":2423271805,"time":"2018-07-27T01:32:40.761000Z"}
{"type":"open","side":"buy","price":"82.91000000","order_id":"8bf40e09-f889-44e2-ad53-f535a082ea2f","remaining_size":"82.00225100","product_id":"LTC-USD","sequence":2423271806,"time":"2018-07-27T01:32:40.761000Z"}
{"type":"received","order_id":"4f83e031-2c2e-4a08-aead-c82bdda387c6","order_type":"limit","size":"1.81488800","price":"791.24000000","side":"buy","client_oid":"ed8b2a2f-2abe-4fb2-80a7-cbbd021bf557","product_id":"BCH-USD","sequence":4839272391,"time":"2018-07-27T01:32:40.761000Z"}
{"type":"open","side":"buy","price":"791.24000000","order_id":"4f83e031-2c2e-4a08-aead-c82bdda387c6","remaining_size":"1.81488800","product_id":"BCH-USD","sequence":4839272392,"time":"2018-07-27T01:32:40.761000Z"}
{"type":"done","side":"sell","order_id":"b6df4fcb-ee51-444a-9f73-b866764e5b6f","reason":"canceled","product_id":"BCH-USD","price":"795.16000000","remaining_size":"4.50000000","sequence":4839272393,"time":"2018-07-27T01:32:40.764000Z"}
{"type":"done","side":"sell","order_id":"a6b64dd1-65c5-485b-92af-55fc7dea817c","reason":"canceled","product_id":"BCH-USD","price":"795.16000000","remaining_size":"0.90000000","sequence":4839272394,"time":"2018-07-27T01:32:40.765000Z"}
{"type":"done","side":"sell","order_id":"810513cd-cc4e-4273-ba6c-dd0e018d28f2","reason":"canceled","product_id":"BCH-USD","price":"795.16000000","remaining_size":"1.90000000","sequence":4839272395,"time":"2018-07-27T01:32:40.765000Z"}
{"type":"done","side":"sell","order_id":"182b13b7-b897-4056-83b2-ed5411e48ff3","reason":"canceled","product_id":"BCH-USD","price":"795.17000000","remaining_size":"1.90000000","sequence":4839272396,"time":"2018-07-27T01:32:40.767000Z"}
{"type":"done","side":"buy","order_id":"79b8ebc4-c0b4-404d-9004-ca1e55e77bb3","reason":"canceled","product_id":"BCH-USD","price":"791.24000000","remaining_size":"0.18739300","sequence":4839272397,"time":"2018-07-27T01:32:40.768000Z"}
{"type":"received","order_id":"ff879b97-b5a6-41c8-8dd5-8d41a339ef44","order_type":"limit","size":"7.44874862","price":"83.30000000","side":"sell","client_oid":"c23da4d4-c945-46c2-8000-0754b4fb48f0","product_id":"LTC-USD","sequence":2423271807,"time":"2018-07-27T01:32:40.775000Z"}
{"type":"open","side":"sell","price":"83.30000000","order_id":"ff879b97-b5a6-41c8-8dd5-8d41a339ef44","remaining_size":"7.44874862","product_id":"LTC-USD","sequence":2423271808,"time":"2018-07-27T01:32:40.775000Z"}
{"type":"received","order_id":"4f3501e6-fd05-444b-aa70-aa517e496688","order_type":"limit","size":"16.39875700","price":"83.29000000","side":"sell","client_oid":"2b007f7e-61a6-4acb-8bd3-24bbac396b27","product_id":"LTC-USD","sequence":2423271809,"time":"2018-07-27T01:32:40.775000Z"}
{"type":"open","side":"sell","price":"83.29000000","order_id":"4f3501e6-fd05-444b-aa70-aa517e496688","remaining_size":"16.39875700","product_id":"LTC-USD","sequence":2423271810,"time":"2018-07-27T01:32:40.775000Z"}
{"type":"received","order_id":"36f4a58d-4a6a-4a57-a037-4e370c8da500","order_type":"limit","size":"0.90000000","price":"795.15000000","side":"sell","client_oid":"6981fa79-75ed-460a-878c-2f3e0e2b85bd","product_id":"BCH-USD","sequence":4839272398,"time":"2018-07-27T01:32:40.774000Z"}
{"type":"done","side":"sell","order_id":"a166d3bc-77c6-481a-992f-1b0437de342a","reason":"canceled","product_id":"ETH-USD","price":"488.58000000","remaining_size":"0.01000000","sequence":4469354770,"time":"2018-07-27T01:32:40.775000Z"}
{"type":"open","side":"sell","price":"795.15000000","order_id":"36f4a58d-4a6a-4a57-a037-4e370c8da500","remaining_size":"0.90000000","product_id":"BCH-USD","sequence":4839272399,"time":"2018-07-27T01:32:40.774000Z"}
{"type":"done","side":"sell","order_id":"ff6bc3de-e9a4-416b-b70b-ec0a10f8818d","reason":"canceled","product_id":"ETH-USD","price":"462.59000000","remaining_size":"0.01000000","sequence":4469354771,"time":"2018-07-27T01:32:40.776000Z"}
{"type":"done","side":"buy","order_id":"4f83e031-2c2e-4a08-aead-c82bdda387c6","reason":"canceled","product_id":"BCH-USD","price":"791.24000000","remaining_size":"1.81488800","sequence":4839272400,"time":"2018-07-27T01:32:40.776000Z"}
{"type":"received","order_id":"6039846a-73df-4889-8289-67cb724de6ae","order_type":"limit","size":"4.50000000","price":"795.15000000","side":"sell","client_oid":"898b4591-a8d7-4059-8a10-361f022bb765","product_id":"BCH-USD","sequence":4839272401,"time":"2018-07-27T01:32:40.776000Z"}
{"type":"open","side":"sell","price":"795.15000000","order_id":"6039846a-73df-4889-8289-67cb724de6ae","remaining_size":"4.50000000","product_id":"BCH-USD","sequence":4839272402,"time":"2018-07-27T01:32:40.776000Z"}
{"type":"done","side":"buy","order_id":"38a94234-6062-4477-991e-b4a2bac8336a","reason":"canceled","product_id":"ETH-USD","price":"461.92000000","remaining_size":"0.12000000","sequence":4469354772,"time":"2018-07-27T01:32:40.779000Z"}
{"type":"done","side":"sell","order_id":"36f4a58d-4a6a-4a57-a037-4e370c8da500","reason":"canceled","product_id":"BCH-USD","price":"795.15000000","remaining_size":"0.90000000","sequence":4839272403,"time":"2018-07-27T01:32:40.781000Z"}
{"type":"done","side":"sell","order_id":"6039846a-73df-4889-8289-67cb724de6ae","reason":"canceled","product_id":"BCH-USD","price":"795.15000000","remaining_size":"4.50000000","sequence":4839272404,"time":"2018-07-27T01:32:40.782000Z"}
{"type":"received","order_id":"5643ea48-1140-4b09-9694-04888d4859b3","order_type":"limit","size":"1.90000000","price":"795.15000000","side":"sell","client_oid":"bccb55bc-486b-4e6f-a55c-fb568064ba7d","product_id":"BCH-USD","sequence":4839272405,"time":"2018-07-27T01:32:40.782000Z"}
{"type":"open","side":"sell","price":"795.15000000","order_id":"5643ea48-1140-4b09-9694-04888d4859b3","remaining_size":"1.90000000","product_id":"BCH-USD","sequence":4839272406,"time":"2018-07-27T01:32:40.782000Z"}
{"type":"done","side":"sell","order_id":"ad3142c8-86a3-497e-8695-81dbe344630f","reason":"canceled","product_id":"LTC-USD","price":"83.38000000","remaining_size":"7.44874862","sequence":2423271811,"time":"2018-07-27T01:32:40.787000Z"}
{"type":"received","order_id":"6c7d7acb-2eba-47ef-a820-7a7e1cf61c6e","order_type":"limit","size":"1.81488800","price":"791.25000000","side":"buy","client_oid":"2363e29a-b17b-4923-b898-ab97fdc71242","product_id":"BCH-USD","sequence":4839272407,"time":"2018-07-27T01:32:40.787000Z"}
{"type":"open","side":"buy","price":"791.25000000","order_id":"6c7d7acb-2eba-47ef-a820-7a7e1cf61c6e","remaining_size":"1.81488800","product_id":"BCH-USD","sequence":4839272408,"time":"2018-07-27T01:32:40.787000Z"}
{"type":"received","order_id":"58983e51-f00d-40d8-a3e4-fcd16f18ab8b","order_type":"limit","size":"1.90000000","price":"795.15000000","side":"sell","client_oid":"f67013ca-bcc3-4a45-8c03-2e9121e78818","product_id":"BCH-USD","sequence":4839272409,"time":"2018-07-27T01:32:40.788000Z"}
{"type":"open","side":"sell","price":"795.15000000","order_id":"58983e51-f00d-40d8-a3e4-fcd16f18ab8b","remaining_size":"1.90000000","product_id":"BCH-USD","sequence":4839272410,"time":"2018-07-27T01:32:40.788000Z"}
{"type":"received","order_id":"5e03a93b-cd14-4872-af29-e3cedd5bf9fa","order_type":"limit","size":"0.18739300","price":"791.25000000","side":"buy","client_oid":"69ea9287-4bee-4606-a399-50cc4be7174a","product_id":"BCH-USD","sequence":4839272411,"time":"2018-07-27T01:32:40.789000Z"}
{"type":"open","side":"buy","price":"791.25000000","order_id":"5e03a93b-cd14-4872-af29-e3cedd5bf9fa","remaining_size":"0.18739300","product_id":"BCH-USD","sequence":4839272412,"time":"2018-07-27T01:32:40.789000Z"}
{"type":"received","order_id":"6f390def-a9ae-4ea4-a4e6-4b6efc690d6f","order_type":"limit","size":"21.29141700","price":"83.30000000","side":"sell","client_oid":"37651f97-7de3-44ff-91fc-2e452b2769be","product_id":"LTC-USD","sequence":2423271812,"time":"2018-07-27T01:32:40.792000Z"}
{"type":"received","order_id":"62e5cce0-0a21-47d1-bf0f-457556388cbf","order_type":"limit","size":"0.90000000","price":"795.17000000","side":"sell","client_oid":"5ca3540f-ecb3-4e1a-b797-d41324d931bc","product_id":"BCH-USD","sequence":4839272413,"time":"2018-07-27T01:32:40.791000Z"}
{"type":"open","side":"sell","price":"795.17000000","order_id":"62e5cce0-0a21-47d1-bf0f-457556388cbf","remaining_size":"0.90000000","product_id":"BCH-USD","sequence":4839272414,"time":"2018-07-27T01:32:40.791000Z"}
{"type":"open","side":"sell","price":"83.30000000","order_id":"6f390def-a9ae-4ea4-a4e6-4b6efc690d6f","remaining_size":"21.29141700","product_id":"LTC-USD","sequence":2423271813,"time":"2018-07-27T01:32:40.792000Z"}
{"type":"received","order_id":"2e6232e4-3f94-48fc-8d08-82475384081e","order_type":"limit","size":"4.50000000","price":"795.17000000","side":"sell","client_oid":"9a3a9734-7d94-4fae-bb68-7bbe3dad77cb","product_id":"BCH-USD","sequence":4839272415,"time":"2018-07-27T01:32:40.793000Z"}
{"type":"open","side":"sell","price":"795.17000000","order_id":"2e6232e4-3f94-48fc-8d08-82475384081e","remaining_size":"4.50000000","product_id":"BCH-USD","sequence":4839272416,"time":"2018-07-27T01:32:40.793000Z"}
{"type":"done","side":"sell","order_id":"58983e51-f00d-40d8-a3e4-fcd16f18ab8b","reason":"canceled","product_id":"BCH-USD","price":"795.15000000","remaining_size":"1.90000000","sequence":4839272417,"time":"2018-07-27T01:32:40.793000Z"}
{"type":"received","order_id":"988d549a-d583-425c-bbc1-0f08192f1ea6","order_type":"limit","size":"7.44874862","price":"83.34000000","side":"sell","client_oid":"542a0cbc-92a2-43dc-8000-00720f4e2741","product_id":"LTC-USD","sequence":2423271814,"time":"2018-07-27T01:32:40.796000Z"}
{"type":"done","side":"buy","order_id":"5e03a93b-cd14-4872-af29-e3cedd5bf9fa","reason":"canceled","product_id":"BCH-USD","price":"791.25000000","remaining_size":"0.18739300","sequence":4839272418,"time":"2018-07-27T01:32:40.794000Z"}
{"type":"open","side":"sell","price":"83.34000000","order_id":"988d549a-d583-425c-bbc1-0f08192f1ea6","remaining_size":"7.44874862","product_id":"LTC-USD","sequence":2423271815,"time":"2018-07-27T01:32:40.796000Z"}
{"type":"done","side":"sell","order_id":"62e5cce0-0a21-47d1-bf0f-457556388cbf","reason":"canceled","product_id":"BCH-USD","price":"795.17000000","remaining_size":"0.90000000","sequence":4839272419,"time":"2018-07-27T01:32:40.795000Z"}
{"type":"done","side":"sell","order_id":"2e6232e4-3f94-48fc-8d08-82475384081e","reason":"canceled","product_id":"BCH-USD","price":"795.17000000","remaining_size":"4.50000000","sequence":4839272420,"time":"2018-07-27T01:32:40.799000Z"}
{"type":"received","order_id":"99e87678-8158-4227-b3bb-e98b3b1ecb1c","order_type":"limit","size":"0.49000000","price":"83.11000000","side":"buy","client_oid":"e8d80760-2d4a-4a49-b4fc-0d3dbbe663dd","product_id":"LTC-USD","sequence":2423271816,"time":"2018-07-27T01:32:40.802000Z"}
{"type":"open","side":"buy","price":"83.11000000","order_id":"99e87678-8158-4227-b3bb-e98b3b1ecb1c","remaining_size":"0.49000000","product_id":"LTC-USD","sequence":2423271817,"time":"2018-07-27T01:32:40.802000Z"}
{"type":"received","order_id":"d5e8ac78-cafb-4532-82a7-32e6a49e2b86","order_type":"limit","size":"0.18739300","price":"791.23000000","side":"buy","client_oid":"68d02ba4-1911-469b-9048-f5b32fd7dbb9","product_id":"BCH-USD","sequence":4839272421,"time":"2018-07-27T01:32:40.802000Z"}
{"type":"open","side":"buy","price":"791.23000000","order_id":"d5e8ac78-cafb-4532-82a7-32e6a49e2b86","remaining_size":"0.18739300","product_id":"BCH-USD","sequence":4839272422,"time":"2018-07-27T01:32:40.802000Z"}
{"type":"done","side":"buy","order_id":"807bfe44-2225-459b-b1cc-79598e99d275","reason":"canceled","product_id":"LTC-USD","price":"82.99000000","remaining_size":"20.00000000","sequence":2423271818,"time":"2018-07-27T01:32:40.806000Z"}
{"type":"done","side":"buy","order_id":"d5e8ac78-cafb-4532-82a7-32e6a49e2b86","reason":"canceled","product_id":"BCH-USD","price":"791.23000000","remaining_size":"0.18739300","sequence":4839272423,"time":"2018-07-27T01:32:40.805000Z"}
{"type":"done","side":"sell","order_id":"5643ea48-1140-4b09-9694-04888d4859b3","reason":"canceled","product_id":"BCH-USD","price":"795.15000000","remaining_size":"1.90000000","sequence":4839272424,"time":"2018-07-27T01:32:40.807000Z"}
{"type":"done","side":"sell","order_id":"ff879b97-b5a6-41c8-8dd5-8d41a339ef44","reason":"canceled","product_id":"LTC-USD","price":"83.30000000","remaining_size":"7.44874862","sequence":2423271819,"time":"2018-07-27T01:32:40.810000Z"}
{"type":"received","order_id":"b38bd004-0c20-402f-96cc-528f306b12b8","order_type":"limit","size":"4.50000000","price":"795.14000000","side":"sell","client_oid":"9ead943e-c555-4be8-bae3-c5d538f3d994","product_id":"BCH-USD","sequence":4839272425,"time":"2018-07-27T01:32:40.808000Z"}
{"type":"open","side":"sell","price":"795.14000000","order_id":"b38bd004-0c20-402f-96cc-528f306b12b8","remaining_size":"4.50000000","product_id":"BCH-USD","sequence":4839272426,"time":"2018-07-27T01:32:40.808000Z"}
{"type":"received","order_id":"e15ee496-5818-492f-a995-9556a55a2056","order_type":"limit","size":"1.90000000","price":"795.17000000","side":"sell","client_oid":"775f7a24-d4a0-44c7-a4f1-222f0ecca85c","product_id":"BCH-USD","sequence":4839272427,"time":"2018-07-27T01:32:40.808000Z"}
{"type":"open","side":"sell","price":"795.17000000","order_id":"e15ee496-5818-492f-a995-9556a55a2056","remaining_size":"1.90000000","product_id":"BCH-USD","sequence":4839272428,"time":"2018-07-27T01:32:40.808000Z"}
{"type":"done","side":"buy","order_id":"6c7d7acb-2eba-47ef-a820-7a7e1cf61c6e","reason":"canceled","product_id":"BCH-USD","price":"791.25000000","remaining_size":"1.81488800","sequence":4839272429,"time":"2018-07-27T01:32:40.812000Z"}
{"type":"received","order_id":"72634626-9aae-4dc7-ab29-4de68e0ee31f","order_type":"limit","size":"0.90000000","price":"795.14000000","side":"sell","client_oid":"a2842570-6526-41fb-8fe6-583e2680d539","product_id":"BCH-USD","sequence":4839272430,"time":"2018-07-27T01:32:40.812000Z"}
{"type":"open","side":"sell","price":"795.14000000","order_id":"72634626-9aae-4dc7-ab29-4de68e0ee31f","remaining_size":"0.90000000","product_id":"BCH-USD","sequence":4839272431,"time":"2018-07-27T01:32:40.812000Z"}
{"type":"done","side":"sell","order_id":"b38bd004-0c20-402f-96cc-528f306b12b8","reason":"canceled","product_id":"BCH-USD","price":"795.14000000","remaining_size":"4.50000000","sequence":4839272432,"time":"2018-07-27T01:32:40.813000Z"}
{"type":"received","order_id":"1e7de457-2c55-4036-8850-04b72420d489","order_type":"limit","size":"3.83226600","price":"83.32000000","side":"sell","client_oid":"41b7f523-82c8-49e2-80d7-40c26563a2cc","product_id":"LTC-USD","sequence":2423271820,"time":"2018-07-27T01:32:40.816000Z"}
{"type":"received","order_id":"92888366-2ecc-4456-9adf-58e9a7298e4c","order_type":"limit","size":"0.25000000","price":"462.77000000","side":"sell","client_oid":"9ad3b513-e8e8-4ff9-9be7-e088a8ced8f0","product_id":"ETH-USD","sequence":4469354773,"time":"2018-07-27T01:32:40.815000Z"}
{"type":"open","side":"sell","price":"83.32000000","order_id":"1e7de457-2c55-4036-8850-04b72420d489","remaining_size":"3.83226600","product_id":"LTC-USD","sequence":2423271821,"time":"2018-07-27T01:32:40.816000Z"}
{"type":"open","side":"sell","price":"462.77000000","order_id":"92888366-2ecc-4456-9adf-58e9a7298e4c","remaining_size":"0.25000000","product_id":"ETH-USD","sequence":4469354774,"time":"2018-07-27T01:32:40.815000Z"}
{"type":"received","order_id":"9b1944da-4851-465d-9af1-604660e7400b","order_type":"limit","size":"0.01000000","price":"484.72000000","side":"sell","client_oid":"46ff123d-685e-448e-8000-00dc7d8f4ab6","product_id":"ETH-USD","sequence":4469354775,"time":"2018-07-27T01:32:40.817000Z"}
{"type":"open","side":"sell","price":"484.72000000","order_id":"9b1944da-4851-465d-9af1-604660e7400b","remaining_size":"0.01000000","product_id":"ETH-USD","sequence":4469354776,"time":"2018-07-27T01:32:40.817000Z"}
{"type":"done","side":"sell","order_id":"72634626-9aae-4dc7-ab29-4de68e0ee31f","reason":"canceled","product_id":"BCH-USD","price":"795.14000000","remaining_size":"0.90000000","sequence":4839272433,"time":"2018-07-27T01:32:40.819000Z"}
{"type":"received","order_id":"de985ad0-d7f0-41da-87b0-b7af99e6bd8e","order_type":"limit","size":"7.44874862","price":"83.38000000","side":"sell","client_oid":"54d2f79b-5f48-43b4-8000-00a2ebc02029","product_id":"LTC-USD","sequence":2423271822,"time":"2018-07-27T01:32:40.825000Z"}
{"type":"open","side":"sell","price":"83.38000000","order_id":"de985ad0-d7f0-41da-87b0-b7af99e6bd8e","remaining_size":"7.44874862","product_id":"LTC-USD","sequence":2423271823,"time":"2018-07-27T01:32:40.825000Z"}
{"type":"received","order_id":"96c4954a-aa84-41e3-a87a-5f96d0bf00c1","order_type":"limit","size":"20.00000000","price":"82.98000000","side":"buy","client_oid":"fe2cb6b4-4ca2-4de6-8840-d47bd6485457","product_id":"LTC-USD","sequence":2423271824,"time":"2018-07-27T01:32:40.827000Z"}
{"type":"open","side":"buy","price":"82.98000000","order_id":"96c4954a-aa84-41e3-a87a-5f96d0bf00c1","remaining_size":"20.00000000","product_id":"LTC-USD","sequence":2423271825,"time":"2018-07-27T01:32:40.827000Z"}
{"type":"received","order_id":"cdc91f4c-c402-4096-9a39-099fa20628ff","order_type":"limit","size":"1.81488800","price":"791.26000000","side":"buy","client_oid":"3641b459-5a84-451f-9e06-0a69f7651ce9","product_id":"BCH-USD","sequence":4839272434,"time":"2018-07-27T01:32:40.827000Z"}
{"type":"open","side":"buy","price":"791.26000000","order_id":"cdc91f4c-c402-4096-9a39-099fa20628ff","remaining_size":"1.81488800","product_id":"BCH-USD","sequence":4839272435,"time":"2018-07-27T01:32:40.827000Z"}
{"type":"done","side":"sell","order_id":"e15ee496-5818-492f-a995-9556a55a2056","reason":"canceled","product_id":"BCH-USD","price":"795.17000000","remaining_size":"1.90000000","sequence":4839272436,"time":"2018-07-27T01:32:40.827000Z"}
{"type":"received","order_id":"b7c13edb-ac62-444f-bdcb-de4f5cc6bb98","order_type":"limit","size":"4.50000000","price":"795.17000000","side":"sell","client_oid":"75719826-6d51-4b28-b5d8-a918c246383f","product_id":"BCH-USD","sequence":4839272437,"time":"2018-07-27T01:32:40.828000Z"}
{"type":"open","side":"sell","price":"795.17000000","order_id":"b7c13edb-ac62-444f-bdcb-de4f5cc6bb98","remaining_size":"4.50000000","product_id":"BCH-USD","sequence":4839272438,"time":"2018-07-27T01:32:40.828000Z"}
{"type":"done","side":"sell","order_id":"b7c13edb-ac62-444f-bdcb-de4f5cc6bb98","reason":"canceled","product_id":"BCH-USD","price":"795.17000000","remaining_size":"4.50000000","sequence":4839272439,"time":"2018-07-27T01:32:40.832000Z"}
{"type":"received","order_id":"d18d609c-cca4-427c-9395-8935ba029949","order_type":"limit","size":"0.90000000","price":"795.17000000","side":"sell","client_oid":"5498fb77-e168-4ce7-a15f-3b5bc47793ca","product_id":"BCH-USD","sequence":4839272440,"time":"2018-07-27T01:32:40.833000Z"}
{"type":"open","side":"sell","price":"795.17000000","order_id":"d18d609c-cca4-427c-9395-8935ba029949","remaining_size":"0.90000000","product_id":"BCH-USD","sequence":4839272441,"time":"2018-07-27T01:32:40.833000Z"}
{"type":"done","side":"buy","order_id":"cdc91f4c-c402-4096-9a39-099fa20628ff","reason":"canceled","product_id":"BCH-USD","price":"791.26000000","remaining_size":"1.81488800","sequence":4839272442,"time":"2018-07-27T01:32:40.837000Z"}
{"type":"done","side":"sell","order_id":"988d549a-d583-425c-bbc1-0f08192f1ea6","reason":"canceled","product_id":"LTC-USD","price":"83.34000000","remaining_size":"7.44874862","sequence":2423271826,"time":"2018-07-27T01:32:40.840000Z"}
{"type":"received","order_id":"37043673-de1d-496d-b790-94c89042a611","order_type":"limit","size":"1.90000000","price":"795.14000000","side":"sell","client_oid":"22aca67c-8fb0-4c3d-b81e-803c0d7b4426","product_id":"BCH-USD","sequence":4839272443,"time":"2018-07-27T01:32:40.838000Z"}
{"type":"open","side":"sell","price":"795.14000000","order_id":"37043673-de1d-496d-b790-94c89042a611","remaining_size":"1.90000000","product_id":"BCH-USD","sequence":4839272444,"time":"2018-07-27T01:32:40.838000Z"}
{"type":"received","order_id":"c0631212-0966-4005-b89f-b1ae01c48ac4","order_type":"limit","size":"0.18739300","price":"791.26000000","side":"buy","client_oid":"e3f6a7ce-950c-4624-ac3d-422902a31457","product_id":"BCH-USD","sequence":4839272445,"time":"2018-07-27T01:32:40.839000Z"}
{"type":"open","side":"buy","price":"791.26000000","order_id":"c0631212-0966-4005-b89f-b1ae01c48ac4","remaining_size":"0.18739300","product_id":"BCH-USD","sequence":4839272446,"time":"2018-07-27T01:32:40.839000Z"}
{"type":"done","side":"buy","order_id":"96c4954a-aa84-41e3-a87a-5f96d0bf00c1","reason":"canceled","product_id":"LTC-USD","price":"82.98000000","remaining_size":"20.00000000","sequence":2423271827,"time":"2018-07-27T01:32:40.842000Z"}
{"type":"done","side":"sell","order_id":"37043673-de1d-496d-b790-94c89042a611","reason":"canceled","product_id":"BCH-USD","price":"795.14000000","remaining_size":"1.90000000","sequence":4839272447,"time":"2018-07-27T01:32:40.842000Z"}
{"type":"received","order_id":"bb635a5a-3792-4b5d-8ab6-58fd08257d3d","order_type":"limit","size":"124.24203800","price":"83.34000000","side":"sell","client_oid":"664248a0-fe7c-45aa-89fc-2e438a47e68f","product_id":"LTC-USD","sequence":2423271828,"time":"2018-07-27T01:32:40.844000Z"}
{"type":"done","side":"buy","order_id":"450ad95d-64d8-46ea-97fe-ad2e7c7b9c03","reason":"canceled","product_id":"BTC-USD","price":"6630.01000000","remaining_size":"0.00150000","sequence":6418130234,"time":"2018-07-27T01:32:40.845000Z"}
{"type":"open","side":"sell","price":"83.34000000","order_id":"bb635a5a-3792-4b5d-8ab6-58fd08257d3d","remaining_size":"124.24203800","product_id":"LTC-USD","sequence":2423271829,"time":"2018-07-27T01:32:40.844000Z"}
{"type":"done","side":"buy","order_id":"c0631212-0966-4005-b89f-b1ae01c48ac4","reason":"canceled","product_id":"BCH-USD","price":"791.26000000","remaining_size":"0.18739300","sequence":4839272448,"time":"2018-07-27T01:32:40.845000Z"}
{"type":"received","order_id":"65d753f9-8b4b-4f37-916d-61aac6d98d91","order_type":"limit","size":"20.00000000","price":"82.99000000","side":"buy","client_oid":"d11bf776-476e-4013-87ef-2bf40ae3a0c5","product_id":"LTC-USD","sequence":2423271830,"time":"2018-07-27T01:32:40.847000Z"}
{"type":"done","side":"sell","order_id":"d18d609c-cca4-427c-9395-8935ba029949","reason":"canceled","product_id":"BCH-USD","price":"795.17000000","remaining_size":"0.90000000","sequence":4839272449,"time":"2018-07-27T01:32:40.846000Z"}
{"type":"open","side":"buy","price":"82.99000000","order_id":"65d753f9-8b4b-4f37-916d-61aac6d98d91","remaining_size":"20.00000000","product_id":"LTC-USD","sequence":2423271831,"time":"2018-07-27T01:32:40.847000Z"}
{"type":"received","order_id":"183d9274-1606-44eb-8870-14d6f00b8766","order_type":"limit","size":"1.81488800","price":"791.27000000","side":"buy","client_oid":"b6c21e58-cc64-41a1-b58f-0a1d5b45cd80","product_id":"BCH-USD","sequence":4839272450,"time":"2018-07-27T01:32:40.858000Z"}
{"type":"open","side":"buy","price":"791.27000000","order_id":"183d9274-1606-44eb-8870-14d6f00b8766","remaining_size":"1.81488800","product_id":"BCH-USD","sequence":4839272451,"time":"2018-07-27T01:32:40.858000Z"}
{"type":"received","order_id":"c1d0350d-b7df-47c5-a784-a3ec87c3e7de","order_type":"limit","size":"0.00150000","price":"6599.01000000","side":"buy","client_oid":"2b4c8dec-a596-4516-8000-005d0bd87b9b","product_id":"BTC-USD","sequence":6418130235,"time":"2018-07-27T01:32:40.864000Z"}
{"type":"open","side":"buy","price":"6599.01000000","order_id":"c1d0350d-b7df-47c5-a784-a3ec87c3e7de","remaining_size":"0.00150000","product_id":"BTC-USD","sequence":6418130236,"time":"2018-07-27T01:32:40.864000Z"}
{"type":"done","side":"buy","order_id":"183d9274-1606-44eb-8870-14d6f00b8766","reason":"canceled","product_id":"BCH-USD","price":"791.27000000","remaining_size":"1.81488800","sequence":4839272452,"time":"2018-07-27T01:32:40.862000Z"}
{"type":"received","order_id":"6fdd168e-1191-489c-bb49-011600d0295a","order_type":"limit","size":"1.90000000","price":"795.17000000","side":"sell","client_oid":"99cbc64f-e4c5-4824-bb32-0b722deeb5ef","product_id":"BCH-USD","sequence":4839272453,"time":"2018-07-27T01:32:40.865000Z"}
{"type":"open","side":"sell","price":"795.17000000","order_id":"6fdd168e-1191-489c-bb49-011600d0295a","remaining_size":"1.90000000","product_id":"BCH-USD","sequence":4839272454,"time":"2018-07-27T01:32:40.865000Z"}
{"type":"received","order_id":"05e82977-bf1e-409c-a726-72ee47d296a4","order_type":"limit","size":"0.90000000","price":"795.16000000","side":"sell","client_oid":"6aa4388a-d6e6-44b4-b6aa-d04f253f3351","product_id":"BCH-USD","sequence":4839272455,"time":"2018-07-27T01:32:40.867000Z"}
{"type":"open","side":"sell","price":"795.16000000","order_id":"05e82977-bf1e-409c-a726-72ee47d296a4","remaining_size":"0.90000000","product_id":"BCH-USD","sequence":4839272456,"time":"2018-07-27T01:32:40.867000Z"}
{"type":"received","order_id":"b1ece1a3-e143-4c5a-81ea-5430a2d9ca00","order_type":"limit","size":"18.64678600","price":"83.37000000","side":"sell","client_oid":"98da40f3-276d-4145-8534-0e0685817924","product_id":"LTC-USD","sequence":2423271832,"time":"2018-07-27T01:32:40.869000Z"}
{"type":"received","order_id":"6a5dea82-0500-4f43-bf07-c716d715ef6d","order_type":"limit","size":"4.50000000","price":"795.16000000","side":"sell","client_oid":"1a8c0e52-18ae-4624-8338-a90aeabf5792","product_id":"BCH-USD","sequence":4839272457,"time":"2018-07-27T01:32:40.868000Z"}
{"type":"open","side":"sell","price":"83.37000000","order_id":"b1ece1a3-e143-4c5a-81ea-5430a2d9ca00","remaining_size":"18.64678600","product_id":"LTC-USD","sequence":2423271833,"time":"2018-07-27T01:32:40.869000Z"}
{"type":"open","side":"sell","price":"795.16000000","order_id":"6a5dea82-0500-4f43-bf07-c716d715ef6d","remaining_size":"4.50000000","product_id":"BCH-USD","sequence":4839272458,"time":"2018-07-27T01:32:40.868000Z"}
{"type":"received","order_id":"960973c5-104a-4311-985a-889128b8e568","order_type":"limit","size":"7.44874862","price":"83.30000000","side":"sell","client_oid":"c8118a31-7014-4763-8000-0086b1351e3b","product_id":"LTC-USD","sequence":2423271834,"time":"2018-07-27T01:32:40.872000Z"}
{"type":"done","side":"sell","order_id":"05e82977-bf1e-409c-a726-72ee47d296a4","reason":"canceled","product_id":"BCH-USD","price":"795.16000000","remaining_size":"0.90000000","sequence":4839272459,"time":"2018-07-27T01:32:40.871000Z"}
{"type":"open","side":"sell","price":"83.30000000","order_id":"960973c5-104a-4311-985a-889128b8e568","remaining_size":"7.44874862","product_id":"LTC-USD","sequence":2423271835,"time":"2018-07-27T01:32:40.872000Z"}
{"type":"received","order_id":"d44acbae-90b5-4851-92cf-7f2477887ed3","order_type":"limit","size":"1.90000000","price":"795.16000000","side":"sell","client_oid":"d288ce84-4389-44bb-820d-9b1f303ec1fb","product_id":"BCH-USD","sequence":4839272460,"time":"2018-07-27T01:32:40.874000Z"}
{"type":"open","side":"sell","price":"795.16000000","order_id":"d44acbae-90b5-4851-92cf-7f2477887ed3","remaining_size":"1.90000000","product_id":"BCH-USD","sequence":4839272461,"time":"2018-07-27T01:32:40.874000Z"}
{"type":"received","order_id":"3eef61f8-69ca-4d9b-83de-c6a4b89abc35","order_type":"limit","size":"0.18739300","price":"791.23000000","side":"buy","client_oid":"c09d22b8-5251-46da-a8c3-35095b7f4b0a","product_id":"BCH-USD","sequence":4839272462,"time":"2018-07-27T01:32:40.877000Z"}
{"type":"open","side":"buy","price":"791.23000000","order_id":"3eef61f8-69ca-4d9b-83de-c6a4b89abc35","remaining_size":"0.18739300","product_id":"BCH-USD","sequence":4839272463,"time":"2018-07-27T01:32:40.877000Z"}
{"type":"received","order_id":"8a6555df-9a36-488b-b701-6c8344a9513b","order_type":"limit","size":"1.81488800","price":"791.23000000","side":"buy","client_oid":"d2af9387-cfec-404e-a913-ac59c55f9c90","product_id":"BCH-USD","sequence":4839272464,"time":"2018-07-27T01:32:40.878000Z"}
{"type":"open","side":"buy","price":"791.23000000","order_id":"8a6555df-9a36-488b-b701-6c8344a9513b","remaining_size":"1.81488800","product_id":"BCH-USD","sequence":4839272465,"time":"2018-07-27T01:32:40.878000Z"}
{"type":"done","side":"sell","order_id":"de985ad0-d7f0-41da-87b0-b7af99e6bd8e","reason":"canceled","product_id":"LTC-USD","price":"83.38000000","remaining_size":"7.44874862","sequence":2423271836,"time":"2018-07-27T01:32:40.880000Z"}
{"type":"done","side":"sell","order_id":"5e96a1bf-355b-4dee-9e50-47801f764ae0","reason":"canceled","product_id":"ETH-USD","price":"462.60000000","remaining_size":"0.02000000","sequence":4469354777,"time":"2018-07-27T01:32:40.879000Z"}
{"type":"done","side":"sell","order_id":"6fdd168e-1191-489c-bb49-011600d0295a","reason":"canceled","product_id":"BCH-USD","price":"795.17000000","remaining_size":"1.90000000","sequence":4839272466,"time":"2018-07-27T01:32:40.881000Z"}
{"type":"received","order_id":"034d5e63-d534-4ed9-90bc-1e5a31d67936","order_type":"limit","size":"3.21039500","price":"83.40000000","side":"sell","client_oid":"47fa0821-82f7-42dd-9afb-df8ffc99d061","product_id":"LTC-USD","sequence":2423271837,"time":"2018-07-27T01:32:40.884000Z"}
{"type":"received","order_id":"6e856695-9bc3-4185-90cd-bcdc5a5da2e0","order_type":"limit","size":"0.90000000","price":"795.17000000","side":"sell","client_oid":"e3b0f4b1-a39a-4963-a373-d239e1fa9ed1","product_id":"BCH-USD","sequence":4839272467,"time":"2018-07-27T01:32:40.882000Z"}
{"type":"open","side":"sell","price":"795.17000000","order_id":"6e856695-9bc3-4185-90cd-bcdc5a5da2e0","remaining_size":"0.90000000","product_id":"BCH-USD","sequence":4839272468,"time":"2018-07-27T01:32:40.882000Z"}
{"type":"open","side":"sell","price":"83.40000000","order_id":"034d5e63-d534-4ed9-90bc-1e5a31d67936","remaining_size":"3.21039500","product_id":"LTC-USD","sequence":2423271838,"time":"2018-07-27T01:32:40.884000Z"}
{"type":"received","order_id":"304a696a-b86e-4c77-a664-75bb85124ad6","order_type":"limit","size":"1.90000000","price":"795.16000000","side":"sell","client_oid":"7b42938a-509c-4807-939f-2977eef6599f","product_id":"BCH-USD","sequence":4839272469,"time":"2018-07-27T01:32:40.886000Z"}
{"type":"open","side":"sell","price":"795.16000000","order_id":"304a696a-b86e-4c77-a664-75bb85124ad6","remaining_size":"1.90000000","product_id":"BCH-USD","sequence":4839272470,"time":"2018-07-27T01:32:40.886000Z"}
{"type":"done","side":"sell","order_id":"475fb182-805d-4881-a3b6-d5532afb856a","reason":"canceled","product_id":"ETH-USD","price":"462.59000000","remaining_size":"0.01000000","sequence":4469354778,"time":"2018-07-27T01:32:40.888000Z"}
{"type":"done","side":"buy","order_id":"65d753f9-8b4b-4f37-916d-61aac6d98d91","reason":"canceled","product_id":"LTC-USD","price":"82.99000000","remaining_size":"20.00000000","sequence":2423271839,"time":"2018-07-27T01:32:40.890000Z"}
{"type":"done","side":"sell","order_id":"6e856695-9bc3-4185-90cd-bcdc5a5da2e0","reason":"canceled","product_id":"BCH-USD","price":"795.17000000","remaining_size":"0.90000000","sequence":4839272471,"time":"2018-07-27T01:32:40.889000Z"}
{"type":"done","side":"sell","order_id":"6a5dea82-0500-4f43-bf07-c716d715ef6d","reason":"canceled","product_id":"BCH-USD","price":"795.16000000","remaining_size":"4.50000000","sequence":4839272472,"time":"2018-07-27T01:32:40.891000Z"}
{"type":"done","side":"sell","order_id":"304a696a-b86e-4c77-a664-75bb85124ad6","reason":"canceled","product_id":"BCH-USD","price":"795.16000000","remaining_size":"1.90000000","sequence":4839272473,"time":"2018-07-27T01:32:40.892000Z"}
{"type":"done","side":"sell","order_id":"d44acbae-90b5-4851-92cf-7f2477887ed3","reason":"canceled","product_id":"BCH-USD","price":"795.16000000","remaining_size":"1.90000000","sequence":4839272474,"time":"2018-07-27T01:32:40.893000Z"}
{"type":"done","side":"sell","order_id":"92888366-2ecc-4456-9adf-58e9a7298e4c","reason":"canceled","product_id":"ETH-USD","price":"462.77000000","remaining_size":"0.25000000","sequence":4469354779,"time":"2018-07-27T01:32:40.896000Z"}
{"type":"done","side":"buy","order_id":"8a6555df-9a36-488b-b701-6c8344a9513b","reason":"canceled","product_id":"BCH-USD","price":"791.23000000","remaining_size":"1.81488800","sequence":4839272475,"time":"2018-07-27T01:32:40.901000Z"}
{"type":"done","side":"buy","order_id":"3eef61f8-69ca-4d9b-83de-c6a4b89abc35","reason":"canceled","product_id":"BCH-USD","price":"791.23000000","remaining_size":"0.18739300","sequence":4839272476,"time":"2018-07-27T01:32:40.905000Z"}
{"type":"done","side":"sell","order_id":"960973c5-104a-4311-985a-889128b8e568","reason":"canceled","product_id":"LTC-USD","price":"83.30000000","remaining_size":"7.44874862","sequence":2423271840,"time":"2018-07-27T01:32:40.918000Z"}
{"type":"received","order_id":"e1ae8187-f15f-4f3e-819d-8dfb5c3eb9a0","order_type":"limit","size":"7.44874862","price":"83.34000000","side":"sell","client_oid":"b0e3c967-bd8a-443b-8000-00abfd658faa","product_id":"LTC-USD","sequence":2423271841,"time":"2018-07-27T01:32:40.960000Z"}
{"type":"open","side":"sell","price":"83.34000000","order_id":"e1ae8187-f15f-4f3e-819d-8dfb5c3eb9a0","remaining_size":"7.44874862","product_id":"LTC-USD","sequence":2423271842,"time":"2018-07-27T01:32:40.960000Z"}
{"type":"received","order_id":"ac309540-7d0a-43a5-8290-e1b01effb81a","order_type":"limit","size":"7.44874862","price":"83.38000000","side":"sell","client_oid":"0bf79aeb-de43-4c05-8000-00dacb6fbf10","product_id":"LTC-USD","sequence":2423271843,"time":"2018-07-27T01:32:40.966000Z"}
{"type":"open","side":"sell","price":"83.38000000","order_id":"ac309540-7d0a-43a5-8290-e1b01effb81a","remaining_size":"7.44874862","product_id":"LTC-USD","sequence":2423271844,"time":"2018-07-27T01:32:40.966000Z"}
{"type":"received","order_id":"6d0e4fea-c0e3-4ca9-a0ac-a8d88f5d8800","order_type":"limit","size":"20.00000000","price":"82.98000000","side":"buy","client_oid":"dc7e2803-a49b-4ad0-820f-cc936263e735","product_id":"LTC-USD","sequence":2423271845,"time":"2018-07-27T01:32:40.966000Z"}
{"type":"open","side":"buy","price":"82.98000000","order_id":"6d0e4fea-c0e3-4ca9-a0ac-a8d88f5d8800","remaining_size":"20.00000000","product_id":"LTC-USD","sequence":2423271846,"time":"2018-07-27T01:32:40.966000Z"}
{"type":"received","order_id":"cc74446c-f7ac-49c0-8556-eaf2c6729212","order_type":"limit","size":"0.12000000","price":"461.99000000","side":"buy","client_oid":"3715e488-5ea1-4751-aa60-462d72453bd0","product_id":"ETH-USD","sequence":4469354780,"time":"2018-07-27T01:32:40.966000Z"}
{"type":"open","side":"buy","price":"461.99000000","order_id":"cc74446c-f7ac-49c0-8556-eaf2c6729212","remaining_size":"0.12000000","product_id":"ETH-USD","sequence":4469354781,"time":"2018-07-27T01:32:40.966000Z"}
{"type":"received","order_id":"fb7f33f9-cbad-4eaf-a29e-2fad11afa2f8","order_type":"limit","size":"0.90000000","price":"795.15000000","side":"sell","client_oid":"b441bb56-d00e-4c23-9207-9f2c309aa6a9","product_id":"BCH-USD","sequence":4839272477,"time":"2018-07-27T01:32:40.966000Z"}
{"type":"open","side":"sell","price":"795.15000000","order_id":"fb7f33f9-cbad-4eaf-a29e-2fad11afa2f8","remaining_size":"0.90000000","product_id":"BCH-USD","sequence":4839272478,"time":"2018-07-27T01:32:40.966000Z"}
{"type":"received","order_id":"d376d8dd-c3bc-4abd-8f23-7b85a61ffad9","order_type":"limit","size":"1.90000000","price":"795.15000000","side":"sell","client_oid":"4fd17d9d-551d-483d-89bb-041b9df8a842","product_id":"BCH-USD","sequence":4839272479,"time":"2018-07-27T01:32:40.966000Z"}
{"type":"open","side":"sell","price":"795.15000000","order_id":"d376d8dd-c3bc-4abd-8f23-7b85a61ffad9","remaining_size":"1.90000000","product_id":"BCH-USD","sequence":4839272480,"time":"2018-07-27T01:32:40.966000Z"}
{"type":"received","order_id":"805040db-00a4-446a-95b2-e2e30dbb5145","order_type":"limit","size":"0.00100000","price":"8118.27000000","side":"sell","client_oid":"3eb94633-8a2c-4170-8000-05aa70cc56f0","product_id":"BTC-USD","sequence":6418130237,"time":"2018-07-27T01:32:40.970000Z"}
{"type":"received","order_id":"657b99b6-0f09-4919-9d8f-c5c7ffccdfc8","order_type":"limit","size":"1.90000000","price":"795.15000000","side":"sell","client_oid":"070425f7-5336-43d2-a453-273653b46348","product_id":"BCH-USD","sequence":4839272481,"time":"2018-07-27T01:32:40.968000Z"}
{"type":"open","side":"sell","price":"8118.27000000","order_id":"805040db-00a4-446a-95b2-e2e30dbb5145","remaining_size":"0.00100000","product_id":"BTC-USD","sequence":6418130238,"time":"2018-07-27T01:32:40.970000Z"}
{"type":"open","side":"sell","price":"795.15000000","order_id":"657b99b6-0f09-4919-9d8f-c5c7ffccdfc8","remaining_size":"1.90000000","product_id":"BCH-USD","sequence":4839272482,"time":"2018-07-27T01:32:40.968000Z"}
{"type":"done","side":"buy","order_id":"6d0e4fea-c0e3-4ca9-a0ac-a8d88f5d8800","reason":"canceled","product_id":"LTC-USD","price":"82.98000000","remaining_size":"20.00000000","sequence":2423271847,"time":"2018-07-27T01:32:40.971000Z"}
{"type":"done","side":"sell","order_id":"d376d8dd-c3bc-4abd-8f23-7b85a61ffad9","reason":"canceled","product_id":"BCH-USD","price":"795.15000000","remaining_size":"1.90000000","sequence":4839272483,"time":"2018-07-27T01:32:40.971000Z"}
{"type":"done","side":"buy","order_id":"5d6abc63-ee06-42e7-b38b-914a78517126","reason":"canceled","product_id":"BCH-USD","price":"790.16000000","remaining_size":"0.18361000","sequence":4839272484,"time":"2018-07-27T01:32:40.972000Z"}
{"type":"received","order_id":"52f62a9e-ba78-439f-80e9-4e1482e843d7","order_type":"limit","size":"1.81488800","price":"791.24000000","side":"buy","client_oid":"1e68959a-b9a4-4999-9b06-16d6c299aa52","product_id":"BCH-USD","sequence":4839272485,"time":"2018-07-27T01:32:40.973000Z"}
{"type":"open","side":"buy","price":"791.24000000","order_id":"52f62a9e-ba78-439f-80e9-4e1482e843d7","remaining_size":"1.81488800","product_id":"BCH-USD","sequence":4839272486,"time":"2018-07-27T01:32:40.973000Z"}
{"type":"done","side":"buy","order_id":"99e87678-8158-4227-b3bb-e98b3b1ecb1c","reason":"canceled","product_id":"LTC-USD","price":"83.11000000","remaining_size":"0.49000000","sequence":2423271848,"time":"2018-07-27T01:32:40.976000Z"}
{"type":"done","side":"sell","order_id":"657b99b6-0f09-4919-9d8f-c5c7ffccdfc8","reason":"canceled","product_id":"BCH-USD","price":"795.15000000","remaining_size":"1.90000000","sequence":4839272487,"time":"2018-07-27T01:32:40.975000Z"}
{"type":"done","side":"sell","order_id":"ad09d7b7-6696-4126-88a9-7ecf56240991","reason":"canceled","product_id":"BTC-USD","price":"8122.33000000","remaining_size":"0.00100000","sequence":6418130239,"time":"2018-07-27T01:32:40.978000Z"}
{"type":"done","side":"buy","order_id":"a39d3607-04b7-42f2-beb2-3c04ad094d00","reason":"canceled","product_id":"BCH-USD","price":"789.92000000","remaining_size":"0.17515900","sequence":4839272488,"time":"2018-07-27T01:32:40.975000Z"}
{"type":"done","side":"buy","order_id":"52f62a9e-ba78-439f-80e9-4e1482e843d7","reason":"canceled","product_id":"BCH-USD","price":"791.24000000","remaining_size":"1.81488800","sequence":4839272489,"time":"2018-07-27T01:32:40.977000Z"}
{"type":"received","order_id":"da1526f6-82e4-47fb-8c5a-574719df7626","order_type":"limit","size":"0.18739300","price":"791.24000000","side":"buy","client_oid":"ac16b61a-d0a7-4ff2-928d-ccb87753ea9f","product_id":"BCH-USD","sequence":4839272490,"time":"2018-07-27T01:32:40.978000Z"}
{"type":"open","side":"buy","price":"791.24000000","order_id":"da1526f6-82e4-47fb-8c5a-574719df7626","remaining_size":"0.18739300","product_id":"BCH-USD","sequence":4839272491,"time":"2018-07-27T01:32:40.978000Z"}
{"type":"received","order_id":"f18dc641-c69d-48b5-8d5d-792a675c9d67","order_type":"limit","size":"4.50000000","price":"795.15000000","side":"sell","client_oid":"cf2f69b8-26be-4ec8-a71f-7b926f94b1c7","product_id":"BCH-USD","sequence":4839272492,"time":"2018-07-27T01:32:40.978000Z"}
{"type":"open","side":"sell","price":"795.15000000","order_id":"f18dc641-c69d-48b5-8d5d-792a675c9d67","remaining_size":"4.50000000","product_id":"BCH-USD","sequence":4839272493,"time":"2018-07-27T01:32:40.978000Z"}
{"type":"done","side":"buy","order_id":"8e5ee1ad-fd02-4fcd-a828-65d57deea143","reason":"canceled","product_id":"BCH-USD","price":"789.20000000","remaining_size":"0.14525900","sequence":4839272494,"time":"2018-07-27T01:32:40.979000Z"}
{"type":"received","order_id":"3018991a-b1eb-4f0a-aa75-e32114f6170c","order_type":"limit","size":"1.90000000","price":"795.17000000","side":"sell","client_oid":"a8a2cf1f-9968-4246-b66b-44114ab5507e","product_id":"BCH-USD","sequence":4839272495,"time":"2018-07-27T01:32:40.983000Z"}
{"type":"open","side":"sell","price":"795.17000000","order_id":"3018991a-b1eb-4f0a-aa75-e32114f6170c","remaining_size":"1.90000000","product_id":"BCH-USD","sequence":4839272496,"time":"2018-07-27T01:32:40.983000Z"}
{"type":"done","side":"buy","order_id":"681c1b88-551d-4fe7-bc93-6b15120ba465","reason":"canceled","product_id":"BCH-USD","price":"788.72000000","remaining_size":"0.25147200","sequence":4839272497,"time":"2018-07-27T01:32:40.983000Z"}
{"type":"done","side":"sell","order_id":"fb7f33f9-cbad-4eaf-a29e-2fad11afa2f8","reason":"canceled","product_id":"BCH-USD","price":"795.15000000","remaining_size":"0.90000000","sequence":4839272498,"time":"2018-07-27T01:32:40.984000Z"}
{"type":"done","side":"sell","order_id":"425bdabe-0a81-45a7-828b-9a93810726f7","reason":"canceled","product_id":"BTC-USD","price":"8121.33000000","remaining_size":"0.00100000","sequence":6418130240,"time":"2018-07-27T01:32:40.986000Z"}
{"type":"received","order_id":"5ba82201-0b4a-4003-9cb8-ae4a96163d56","order_type":"limit","size":"20.00000000","price":"82.99000000","side":"buy","client_oid":"553e6dbe-fb57-4a82-b9ca-41b998a9060f","product_id":"LTC-USD","sequence":2423271849,"time":"2018-07-27T01:32:40.986000Z"}
{"type":"done","side":"buy","order_id":"da1526f6-82e4-47fb-8c5a-574719df7626","reason":"canceled","product_id":"BCH-USD","price":"791.24000000","remaining_size":"0.18739300","sequence":4839272499,"time":"2018-07-27T01:32:40.984000Z"}
{"type":"open","side":"buy","price":"82.99000000","order_id":"5ba82201-0b4a-4003-9cb8-ae4a96163d56","remaining_size":"20.00000000","product_id":"LTC-USD","sequence":2423271850,"time":"2018-07-27T01:32:40.986000Z"}
{"type":"received","order_id":"3636596b-b8eb-4d62-ab1e-6671a20b5c7c","order_type":"limit","size":"0.90000000","price":"795.17000000","side":"sell","client_oid":"4da49569-6d92-4ea3-ba96-dd4cda62b307","product_id":"BCH-USD","sequence":4839272500,"time":"2018-07-27T01:32:40.987000Z"}
{"type":"open","side":"sell","price":"795.17000000","order_id":"3636596b-b8eb-4d62-ab1e-6671a20b5c7c","remaining_size":"0.90000000","product_id":"BCH-USD","sequence":4839272501,"time":"2018-07-27T01:32:40.987000Z"}
{"type":"done","side":"sell","order_id":"f18dc641-c69d-48b5-8d5d-792a675c9d67","reason":"canceled","product_id":"BCH-USD","price":"795.15000000","remaining_size":"4.50000000","sequence":4839272502,"time":"2018-07-27T01:32:40.987000Z"}
{"type":"done","side":"sell","order_id":"3018991a-b1eb-4f0a-aa75-e32114f6170c","reason":"canceled","product_id":"BCH-USD","price":"795.17000000","remaining_size":"1.90000000","sequence":4839272503,"time":"2018-07-27T01:32:40.987000Z"}
{"type":"done","side":"sell","order_id":"324f090e-fb2b-44d5-9ceb-30cb7f323de7","reason":"canceled","product_id":"BTC-USD","price":"8120.33000000","remaining_size":"0.00100000","sequence":6418130241,"time":"2018-07-27T01:32:40.990000Z"}
{"type":"done","side":"buy","order_id":"b0ba4858-e1c7-428b-bd15-b2e22525e85a","reason":"canceled","product_id":"BCH-USD","price":"788.48000000","remaining_size":"0.33012600","sequence":4839272504,"time":"2018-07-27T01:32:40.990000Z"}
{"type":"done","side":"sell","order_id":"3636596b-b8eb-4d62-ab1e-6671a20b5c7c","reason":"canceled","product_id":"BCH-USD","price":"795.17000000","remaining_size":"0.90000000","sequence":4839272505,"time":"2018-07-27T01:32:40.991000Z"}
{"type":"done","side":"buy","order_id":"8b633619-9819-43bc-9b17-5534eb0b91cd","reason":"canceled","product_id":"ETH-USD","price":"461.95000000","remaining_size":"0.24000000","sequence":4469354782,"time":"2018-07-27T01:32:40.991000Z"}
{"type":"done","side":"sell","order_id":"238167ed-5aad-419a-879e-4de896f94b47","reason":"canceled","product_id":"BTC-USD","price":"8119.35000000","remaining_size":"0.00100000","sequence":6418130242,"time":"2018-07-27T01:32:40.994000Z"}
{"type":"done","side":"buy","order_id":"3ef84671-a20d-47b1-b45f-6ed6199401dd","reason":"canceled","product_id":"BCH-USD","price":"788.24000000","remaining_size":"3.86955600","sequence":4839272506,"time":"2018-07-27T01:32:40.992000Z"}
{"type":"received","order_id":"55a9ee2f-edd8-4886-9f78-08e7a42cd0b5","order_type":"limit","size":"0.00100000","price":"8120.25000000","side":"sell","client_oid":"311b8e41-ccab-4601-8000-0dae4fd408b0","product_id":"BTC-USD","sequence":6418130243,"time":"2018-07-27T01:32:40.997000Z"}
{"type":"open","side":"sell","price":"8120.25000000","order_id":"55a9ee2f-edd8-4886-9f78-08e7a42cd0b5","remaining_size":"0.00100000","product_id":"BTC-USD","sequence":6418130244,"time":"2018-07-27T01:32:40.997000Z"}
{"type":"received","order_id":"aa193796-e4ae-47da-b6be-4f3bad3408d1","order_type":"limit","size":"1.81488800","price":"791.23000000","side":"buy","client_oid":"a93a694b-3612-44e8-9209-43a5079613a1","product_id":"BCH-USD","sequence":4839272507,"time":"2018-07-27T01:32:40.995000Z"}
{"type":"open","side":"buy","price":"791.23000000","order_id":"aa193796-e4ae-47da-b6be-4f3bad3408d1","remaining_size":"1.81488800","product_id":"BCH-USD","sequence":4839272508,"time":"2018-07-27T01:32:40.995000Z"}
{"type":"done","side":"buy","order_id":"065bc85f-e5bc-458d-825e-b4cbbcc381fe","reason":"canceled","product_id":"BTC-USD","price":"7888.12000000","remaining_size":"0.90000000","sequence":6418130245,"time":"2018-07-27T01:32:40.998000Z"}
{"type":"done","side":"sell","order_id":"5f349a7e-0a8c-4b04-8f42-af644a652788","reason":"canceled","product_id":"BTC-USD","price":"7915.77000000","remaining_size":"0.90000000","sequence":6418130246,"time":"2018-07-27T01:32:40.999000Z"}
{"type":"received","order_id":"a7f5d327-17fa-4cab-a4df-5632be064390","order_type":"limit","size":"0.00100000","price":"8119.25000000","side":"sell","client_oid":"fc80132b-3253-4aed-8000-00477a84fece","product_id":"BTC-USD","sequence":6418130247,"time":"2018-07-27T01:32:40.999000Z"}
{"type":"open","side":"sell","price":"8119.25000000","order_id":"a7f5d327-17fa-4cab-a4df-5632be064390","remaining_size":"0.00100000","product_id":"BTC-USD","sequence":6418130248,"time":"2018-07-27T01:32:40.999000Z"}
{"type":"done","side":"buy","order_id":"28dbf442-b67a-45cf-b8d6-1c8e2d785a76","reason":"canceled","product_id":"LTC-USD","price":"83.08000000","remaining_size":"23.16886900","sequence":2423271851,"time":"2018-07-27T01:32:40.999000Z"}
{"type":"done","side":"buy","order_id":"1e55eb35-f00a-42a4-9941-d79ce195d004","reason":"canceled","product_id":"LTC-USD","price":"82.58000000","remaining_size":"36.32840882","sequence":2423271852,"time":"2018-07-27T01:32:41.000000Z"}
{"type":"done","side":"sell","order_id":"4d9d81b9-dd32-4b16-bab0-bb7e3e5c2e12","reason":"canceled","product_id":"LTC-USD","price":"83.45000000","remaining_size":"30.00000000","sequence":2423271853,"time":"2018-07-27T01:32:41.000000Z"}
{"type":"done","side":"sell","order_id":"6865195f-47a6-420f-8f16-ca97c2fb5125","reason":"canceled","product_id":"LTC-USD","price":"83.36000000","remaining_size":"20.00000000","sequence":2423271854,"time":"2018-07-27T01:32:41.001000Z"}
{"type":"received","order_id":"bdbef066-13c2-409a-b3af-f2a8df0fe64e","order_type":"limit","size":"0.27000000","price":"462.77000000","side":"sell","client_oid":"79ef52ef-2979-4783-8cef-297584126124","product_id":"ETH-USD","sequence":4469354783,"time":"2018-07-27T01:32:41.001000Z"}
{"type":"open","side":"sell","price":"462.77000000","order_id":"bdbef066-13c2-409a-b3af-f2a8df0fe64e","remaining_size":"0.27000000","product_id":"ETH-USD","sequence":4469354784,"time":"2018-07-27T01:32:41.001000Z"}
{"type":"done","side":"buy","order_id":"01a1fe27-b416-4c2f-96bf-b69ae875cf29","reason":"canceled","product_id":"LTC-USD","price":"83.11000000","remaining_size":"3.43478000","sequence":2423271855,"time":"2018-07-27T01:32:41.002000Z"}
{"type":"done","side":"sell","order_id":"16c123df-f2cf-492c-8e52-99763b2886ee","reason":"canceled","product_id":"BCH-USD","price":"798.26000000","remaining_size":"0.02000000","sequence":4839272509,"time":"2018-07-27T01:32:41.001000Z"}
{"type":"received","order_id":"dc845b9f-6b18-4a27-af2c-e66c96cf05a7","order_type":"limit","size":"1.90000000","price":"795.17000000","side":"sell","client_oid":"2c71fb59-f5ec-46c1-9651-0af8406ab5b1","product_id":"BCH-USD","sequence":4839272510,"time":"2018-07-27T01:32:41.001000Z"}
{"type":"open","side":"sell","price":"795.17000000","order_id":"dc845b9f-6b18-4a27-af2c-e66c96cf05a7","remaining_size":"1.90000000","product_id":"BCH-USD","sequence":4839272511,"time":"2018-07-27T01:32:41.001000Z"}
{"type":"received","order_id":"0679d972-9a6e-40e3-9886-1f7c13f9b998","order_type":"limit","size":"0.00100000","price":"8122.25000000","side":"sell","client_oid":"7a6b83b7-8334-405d-8000-0018f5d94201","product_id":"BTC-USD","sequence":6418130249,"time":"2018-07-27T01:32:41.004000Z"}
{"type":"open","side":"sell","price":"8122.25000000","order_id":"0679d972-9a6e-40e3-9886-1f7c13f9b998","remaining_size":"0.00100000","product_id":"BTC-USD","sequence":6418130250,"time":"2018-07-27T01:32:41.004000Z"}
{"type":"done","side":"sell","order_id":"ef85ee5f-a8c0-4351-8369-a0735b27c14c","reason":"canceled","product_id":"LTC-USD","price":"83.40000000","remaining_size":"20.00000000","sequence":2423271856,"time":"2018-07-27T01:32:41.003000Z"}
{"type":"done","side":"sell","order_id":"e1ae8187-f15f-4f3e-819d-8dfb5c3eb9a0","reason":"canceled","product_id":"LTC-USD","price":"83.34000000","remaining_size":"7.44874862","sequence":2423271857,"time":"2018-07-27T01:32:41.004000Z"}
{"type":"done","side":"buy","order_id":"2b7077b1-d1cd-43d4-8d10-25f391133e38","reason":"canceled","product_id":"ETH-USD","price":"461.88000000","remaining_size":"4.60839500","sequence":4469354785,"time":"2018-07-27T01:32:41.004000Z"}
{"type":"received","order_id":"2caffcf3-9349-427a-a46c-b7386a792305","order_type":"limit","size":"0.00100000","price":"8121.25000000","side":"sell","client_oid":"6c99b76c-0886-44a8-8000-0006d3d21628","product_id":"BTC-USD","sequence":6418130251,"time":"2018-07-27T01:32:41.006000Z"}
{"type":"open","side":"sell","price":"8121.25000000","order_id":"2caffcf3-9349-427a-a46c-b7386a792305","remaining_size":"0.00100000","product_id":"BTC-USD","sequence":6418130252,"time":"2018-07-27T01:32:41.006000Z"}
{"type":"done","side":"sell","order_id":"b5f201b6-d233-4542-93cc-542ee4b05dcd","reason":"canceled","product_id":"ETH-USD","price":"462.96000000","remaining_size":"6.00000000","sequence":4469354786,"time":"2018-07-27T01:32:41.005000Z"}
{"type":"done","side":"sell","order_id":"484867f8-1fbf-4297-981f-1a1cba2c605f","reason":"canceled","product_id":"ETH-USD","price":"463.46000000","remaining_size":"6.00000000","sequence":4469354787,"time":"2018-07-27T01:32:41.006000Z"}
{"type":"done","side":"buy","order_id":"d837bbc0-5d91-4564-ab2c-142d5834ec4f","reason":"canceled","product_id":"BCH-USD","price":"792.01000000","remaining_size":"0.90000000","sequence":4839272512,"time":"2018-07-27T01:32:41.005000Z"}
{"type":"received","order_id":"5f61cda9-79fd-476d-af91-10b4d175fd14","order_type":"limit","size":"0.00100000","price":"8112.25000000","side":"sell","client_oid":"36618a42-a94b-4cd3-8000-00157540dbc6","product_id":"BTC-USD","sequence":6418130253,"time":"2018-07-27T01:32:41.008000Z"}
{"type":"done","side":"sell","order_id":"bd2a346f-0657-43b4-8dfc-1669851f19a7","reason":"canceled","product_id":"BCH-USD","price":"795.53000000","remaining_size":"4.50000000","sequence":4839272513,"time":"2018-07-27T01:32:41.006000Z"}
{"type":"open","side":"sell","price":"8112.25000000","order_id":"5f61cda9-79fd-476d-af91-10b4d175fd14","remaining_size":"0.00100000","product_id":"BTC-USD","sequence":6418130254,"time":"2018-07-27T01:32:41.008000Z"}
{"type":"done","side":"sell","order_id":"dc845b9f-6b18-4a27-af2c-e66c96cf05a7","reason":"canceled","product_id":"BCH-USD","price":"795.17000000","remaining_size":"1.90000000","sequence":4839272514,"time":"2018-07-27T01:32:41.006000Z"}
{"type":"received","order_id":"3383ca61-0151-4095-85ea-824099e09a6a","order_type":"limit","size":"0.18739300","price":"791.23000000","side":"buy","client_oid":"ca90f825-4980-4440-b7cf-6d4c234eefc5","product_id":"BCH-USD","sequence":4839272515,"time":"2018-07-27T01:32:41.007000Z"}
{"type":"open","side":"buy","price":"791.23000000","order_id":"3383ca61-0151-4095-85ea-824099e09a6a","remaining_size":"0.18739300","product_id":"BCH-USD","sequence":4839272516,"time":"2018-07-27T01:32:41.007000Z"}
{"type":"received","order_id":"a53527ca-75b1-409c-8be8-6d9e58e234a8","order_type":"limit","size":"0.90000000","price":"795.14000000","side":"sell","client_oid":"80a568ce-e2cb-4232-bd56-d04de6286e4f","product_id":"BCH-USD","sequence":4839272517,"time":"2018-07-27T01:32:41.009000Z"}
{"type":"open","side":"sell","price":"795.14000000","order_id":"a53527ca-75b1-409c-8be8-6d9e58e234a8","remaining_size":"0.90000000","product_id":"BCH-USD","sequence":4839272518,"time":"2018-07-27T01:32:41.009000Z"}
{"type":"done","side":"sell","order_id":"405d8ff2-f337-48da-a8ed-559c5242a6f4","reason":"canceled","product_id":"BCH-USD","price":"794.65000000","remaining_size":"18.78697017","sequence":4839272519,"time":"2018-07-27T01:32:41.009000Z"}
{"type":"received","order_id":"6a5b90e2-bf94-42bf-9960-1f19993f7dd3","order_type":"limit","size":"1.90000000","price":"795.14000000","side":"sell","client_oid":"5b94287f-4b53-403c-b7c2-58ad2739b85c","product_id":"BCH-USD","sequence":4839272520,"time":"2018-07-27T01:32:41.010000Z"}
{"type":"done","side":"sell","order_id":"ce536471-4c0d-4713-947a-a87a628e0b01","reason":"canceled","product_id":"BTC-USD","price":"8117.27000000","remaining_size":"0.00100000","sequence":6418130255,"time":"2018-07-27T01:32:41.013000Z"}
{"type":"open","side":"sell","price":"795.14000000","order_id":"6a5b90e2-bf94-42bf-9960-1f19993f7dd3","remaining_size":"1.90000000","product_id":"BCH-USD","sequence":4839272521,"time":"2018-07-27T01:32:41.010000Z"}
{"type":"done","side":"sell","order_id":"aab32778-c2cc-445e-9f29-e47edf0bad7d","reason":"canceled","product_id":"BTC-USD","price":"8116.29000000","remaining_size":"0.00100000","sequence":6418130256,"time":"2018-07-27T01:32:41.015000Z"}
{"type":"received","order_id":"6a24c789-be71-4aa7-9d4e-23f7e724b030","order_type":"limit","size":"4.50000000","price":"795.14000000","side":"sell","client_oid":"abdea584-a654-4127-9e4f-dec2aa442e22","product_id":"BCH-USD","sequence":4839272522,"time":"2018-07-27T01:32:41.013000Z"}
{"type":"open","side":"sell","price":"795.14000000","order_id":"6a24c789-be71-4aa7-9d4e-23f7e724b030","remaining_size":"4.50000000","product_id":"BCH-USD","sequence":4839272523,"time":"2018-07-27T01:32:41.013000Z"}
{"type":"received","order_id":"bd2b34ce-bc17-422a-90c1-34bbb1104c5a","order_type":"limit","size":"7.44874862","price":"83.30000000","side":"sell","client_oid":"c7c8ec67-064c-4df9-8000-009f63cd1985","product_id":"LTC-USD","sequence":2423271858,"time":"2018-07-27T01:32:41.015000Z"}
{"type":"open","side":"sell","price":"83.30000000","order_id":"bd2b34ce-bc17-422a-90c1-34bbb1104c5a","remaining_size":"7.44874862","product_id":"LTC-USD","sequence":2423271859,"time":"2018-07-27T01:32:41.015000Z"}
{"type":"done","side":"buy","order_id":"aa193796-e4ae-47da-b6be-4f3bad3408d1","reason":"canceled","product_id":"BCH-USD","price":"791.23000000","remaining_size":"1.81488800","sequence":4839272524,"time":"2018-07-27T01:32:41.015000Z"}
{"type":"received","order_id":"770878a7-8249-438d-aba6-aafe3b5e9fb8","order_type":"limit","size":"0.00100000","price":"8113.25000000","side":"sell","client_oid":"ef442a24-fb7f-467e-8000-00b3edb813a4","product_id":"BTC-USD","sequence":6418130257,"time":"2018-07-27T01:32:41.018000Z"}
{"type":"open","side":"sell","price":"8113.25000000","order_id":"770878a7-8249-438d-aba6-aafe3b5e9fb8","remaining_size":"0.00100000","product_id":"BTC-USD","sequence":6418130258,"time":"2018-07-27T01:32:41.018000Z"}
{"type":"received","order_id":"3fd838e1-f6e3-4779-b232-fcf134ad8b25","order_type":"limit","size":"1.90000000","price":"795.14000000","side":"sell","client_oid":"f45dca75-6e9a-4c2a-95e3-7530f68d2df4","product_id":"BCH-USD","sequence":4839272525,"time":"2018-07-27T01:32:41.016000Z"}
{"type":"open","side":"sell","price":"795.14000000","order_id":"3fd838e1-f6e3-4779-b232-fcf134ad8b25","remaining_size":"1.90000000","product_id":"BCH-USD","sequence":4839272526,"time":"2018-07-27T01:32:41.016000Z"}
{"type":"done","side":"sell","order_id":"a53527ca-75b1-409c-8be8-6d9e58e234a8","reason":"canceled","product_id":"BCH-USD","price":"795.14000000","remaining_size":"0.90000000","sequence":4839272527,"time":"2018-07-27T01:32:41.018000Z"}
{"type":"done","side":"sell","order_id":"3fd838e1-f6e3-4779-b232-fcf134ad8b25","reason":"canceled","product_id":"BCH-USD","price":"795.14000000","remaining_size":"1.90000000","sequence":4839272528,"time":"2018-07-27T01:32:41.019000Z"}
{"type":"received","order_id":"b8cff66e-9b8c-47f2-b812-633854c4e708","order_type":"limit","size":"0.13840200","price":"788.72000000","side":"buy","client_oid":"936353ec-e47f-44c6-a1f2-1aebad89ff87","product_id":"BCH-USD","sequence":4839272529,"time":"2018-07-27T01:32:41.021000Z"}
{"type":"open","side":"buy","price":"788.72000000","order_id":"b8cff66e-9b8c-47f2-b812-633854c4e708","remaining_size":"0.13840200","product_id":"BCH-USD","sequence":4839272530,"time":"2018-07-27T01:32:41.021000Z"}
{"type":"done","side":"sell","order_id":"7281f4e7-d7df-4fb2-861d-b39f5459eaa9","reason":"canceled","product_id":"BTC-USD","price":"7907.59000000","remaining_size":"1.89445000","sequence":6418130259,"time":"2018-07-27T01:32:41.025000Z"}
{"type":"received","order_id":"be46f018-8f13-4999-a580-c066a0c7551d","order_type":"limit","size":"1.90000000","price":"795.17000000","side":"sell","client_oid":"3b8b3513-1f43-4628-8775-9cea2314258c","product_id":"BCH-USD","sequence":4839272531,"time":"2018-07-27T01:32:41.027000Z"}
{"type":"received","order_id":"13f3b8c4-3cb0-49de-8bd2-dd5836018072","order_type":"limit","size":"0.90000000","price":"7888.12000000","side":"buy","client_oid":"6a2405a6-b57b-448a-a64b-09daf898e2da","product_id":"BTC-USD","sequence":6418130260,"time":"2018-07-27T01:32:41.030000Z"}
{"type":"open","side":"sell","price":"795.17000000","order_id":"be46f018-8f13-4999-a580-c066a0c7551d","remaining_size":"1.90000000","product_id":"BCH-USD","sequence":4839272532,"time":"2018-07-27T01:32:41.027000Z"}
{"type":"open","side":"buy","price":"7888.12000000","order_id":"13f3b8c4-3cb0-49de-8bd2-dd5836018072","remaining_size":"0.90000000","product_id":"BTC-USD","sequence":6418130261,"time":"2018-07-27T01:32:41.030000Z"}
{"type":"received","order_id":"75f1c053-b184-493d-813e-7850bab6d9d2","order_type":"limit","size":"0.90000000","price":"7915.77000000","side":"sell","client_oid":"4997199a-53aa-4c3a-95cd-47870a71b73d","product_id":"BTC-USD","sequence":6418130262,"time":"2018-07-27T01:32:41.033000Z"}
{"type":"received","order_id":"812d7856-18df-4a62-829b-265ef178d4a2","order_type":"limit","size":"0.19532500","price":"788.48000000","side":"buy","client_oid":"c6dc6f79-5a14-4a0f-a20c-c516d2d99ce1","product_id":"BCH-USD","sequence":4839272533,"time":"2018-07-27T01:32:41.031000Z"}
{"type":"open","side":"sell","price":"7915.77000000","order_id":"75f1c053-b184-493d-813e-7850bab6d9d2","remaining_size":"0.90000000","product_id":"BTC-USD","sequence":6418130263,"time":"2018-07-27T01:32:41.033000Z"}
{"type":"open","side":"buy","price":"788.48000000","order_id":"812d7856-18df-4a62-829b-265ef178d4a2","remaining_size":"0.19532500","product_id":"BCH-USD","sequence":4839272534,"time":"2018-07-27T01:32:41.031000Z"}
{"type":"received","order_id":"0c552abf-aada-4063-a1e0-4a77d33f95b6","order_type":"limit","size":"0.90000000","price":"792.01000000","side":"buy","client_oid":"bb5110f8-1032-4b52-a377-69f5e4a49cb4","product_id":"BCH-USD","sequence":4839272535,"time":"2018-07-27T01:32:41.034000Z"}
{"type":"open","side":"buy","price":"792.01000000","order_id":"0c552abf-aada-4063-a1e0-4a77d33f95b6","remaining_size":"0.90000000","product_id":"BCH-USD","sequence":4839272536,"time":"2018-07-27T01:32:41.034000Z"}
{"type":"done","side":"sell","order_id":"6a24c789-be71-4aa7-9d4e-23f7e724b030","reason":"canceled","product_id":"BCH-USD","price":"795.14000000","remaining_size":"4.50000000","sequence":4839272537,"time":"2018-07-27T01:32:41.035000Z"}
{"type":"received","order_id":"409f3285-f4ce-44a8-beb3-1b9dc0fce128","order_type":"limit","size":"1.89169000","price":"7907.17000000","side":"sell","client_oid":"ac986e54-dc69-4ec7-98c7-e6cc0161e4dd","product_id":"BTC-USD","sequence":6418130264,"time":"2018-07-27T01:32:41.041000Z"}
{"type":"received","order_id":"f938b129-5535-4fd1-a4a4-a4c470193105","order_type":"limit","size":"20.00000000","price":"83.40000000","side":"sell","client_oid":"cd6fa8b8-e771-4492-b7c9-afba901c152f","product_id":"LTC-USD","sequence":2423271860,"time":"2018-07-27T01:32:41.041000Z"}
{"type":"open","side":"sell","price":"7907.17000000","order_id":"409f3285-f4ce-44a8-beb3-1b9dc0fce128","remaining_size":"1.89169000","product_id":"BTC-USD","sequence":6418130265,"time":"2018-07-27T01:32:41.041000Z"}
{"type":"open","side":"sell","price":"83.40000000","order_id":"f938b129-5535-4fd1-a4a4-a4c470193105","remaining_size":"20.00000000","product_id":"LTC-USD","sequence":2423271861,"time":"2018-07-27T01:32:41.041000Z"}
{"type":"done","side":"sell","order_id":"ac309540-7d0a-43a5-8290-e1b01effb81a","reason":"canceled","product_id":"LTC-USD","price":"83.38000000","remaining_size":"7.44874862","sequence":2423271862,"time":"2018-07-27T01:32:41.041000Z"}
{"type":"received","order_id":"116c411a-bbbb-493f-980e-e34cacb3d6b6","order_type":"limit","size":"0.90000000","price":"795.17000000","side":"sell","client_oid":"b78d5002-f8cd-44ae-a7f6-404c79e6f2aa","product_id":"BCH-USD","sequence":4839272538,"time":"2018-07-27T01:32:41.042000Z"}
{"type":"open","side":"sell","price":"795.17000000","order_id":"116c411a-bbbb-493f-980e-e34cacb3d6b6","remaining_size":"0.90000000","product_id":"BCH-USD","sequence":4839272539,"time":"2018-07-27T01:32:41.042000Z"}
{"type":"received","order_id":"f335ce68-0d5a-4332-a617-ba64b4f28dd3","order_type":"limit","size":"4.50000000","price":"795.53000000","side":"sell","client_oid":"8c862ceb-5be1-47ec-8036-fe9ece1b34c4","product_id":"BCH-USD","sequence":4839272540,"time":"2018-07-27T01:32:41.043000Z"}
{"type":"open","side":"sell","price":"795.53000000","order_id":"f335ce68-0d5a-4332-a617-ba64b4f28dd3","remaining_size":"4.50000000","product_id":"BCH-USD","sequence":4839272541,"time":"2018-07-27T01:32:41.043000Z"}
{"type":"received","order_id":"6e967259-a88c-4922-9b4f-a7d768bec7f3","order_type":"limit","size":"0.24000000","price":"462.00000000","side":"buy","client_oid":"9fdd470a-53c2-45a9-866a-621253c7adaa","product_id":"ETH-USD","sequence":4469354788,"time":"2018-07-27T01:32:41.047000Z"}
{"type":"done","side":"sell","order_id":"3e625436-1a6f-4476-a0bf-ea30d8626e35","reason":"canceled","product_id":"BCH-USD","price":"794.64000000","remaining_size":"0.90000000","sequence":4839272542,"time":"2018-07-27T01:32:41.047000Z"}
{"type":"done","side":"sell","order_id":"f335ce68-0d5a-4332-a617-ba64b4f28dd3","reason":"canceled","product_id":"BCH-USD","price":"795.53000000","remaining_size":"4.50000000","sequence":4839272543,"time":"2018-07-27T01:32:41.047000Z"}
{"type":"open","side":"buy","price":"462.00000000","order_id":"6e967259-a88c-4922-9b4f-a7d768bec7f3","remaining_size":"0.24000000","product_id":"ETH-USD","sequence":4469354789,"time":"2018-07-27T01:32:41.047000Z"}
{"type":"received","order_id":"9a19bf04-c6ec-4fee-8696-6aca4f4faa11","order_type":"limit","size":"9.84600000","price":"795.14000000","side":"sell","product_id":"BCH-USD","sequence":4839272544,"time":"2018-07-27T01:32:41.050000Z"}
{"type":"done","side":"sell","order_id":"9440ed81-2261-4a83-91e3-93f03e34c344","reason":"canceled","product_id":"ETH-USD","price":"463.59000000","remaining_size":"6.00000000","sequence":4469354790,"time":"2018-07-27T01:32:41.051000Z"}
{"type":"open","side":"sell","price":"795.14000000","order_id":"9a19bf04-c6ec-4fee-8696-6aca4f4faa11","remaining_size":"9.84600000","product_id":"BCH-USD","sequence":4839272545,"time":"2018-07-27T01:32:41.050000Z"}
{"type":"done","side":"sell","order_id":"be46f018-8f13-4999-a580-c066a0c7551d","reason":"canceled","product_id":"BCH-USD","price":"795.17000000","remaining_size":"1.90000000","sequence":4839272546,"time":"2018-07-27T01:32:41.051000Z"}
{"type":"done","side":"sell","order_id":"55c1e80c-fb4c-4f4a-a54d-d09e88f31bc8","reason":"canceled","product_id":"LTC-USD","price":"83.38000000","remaining_size":"30.00000000","sequence":2423271863,"time":"2018-07-27T01:32:41.053000Z"}
{"type":"done","side":"sell","order_id":"6a5b90e2-bf94-42bf-9960-1f19993f7dd3","reason":"canceled","product_id":"BCH-USD","price":"795.14000000","remaining_size":"1.90000000","sequence":4839272547,"time":"2018-07-27T01:32:41.052000Z"}
{"type":"received","order_id":"dd51c3e0-da58-4452-8af6-b5f2b1926c93","order_type":"limit","size":"4.50000000","price":"795.17000000","side":"sell","client_oid":"ac83ec29-7f63-49b1-833a-513d69192880","product_id":"BCH-USD","sequence":4839272548,"time":"2018-07-27T01:32:41.052000Z"}
{"type":"open","side":"sell","price":"795.17000000","order_id":"dd51c3e0-da58-4452-8af6-b5f2b1926c93","remaining_size":"4.50000000","product_id":"BCH-USD","sequence":4839272549,"time":"2018-07-27T01:32:41.052000Z"}
{"type":"received","order_id":"4591ab56-40de-4013-9512-b332cd97e32e","order_type":"limit","size":"2.82955100","price":"788.24000000","side":"buy","client_oid":"159f3d50-6c4d-4582-807a-40355b4c7973","product_id":"BCH-USD","sequence":4839272550,"time":"2018-07-27T01:32:41.054000Z"}
{"type":"open","side":"buy","price":"788.24000000","order_id":"4591ab56-40de-4013-9512-b332cd97e32e","remaining_size":"2.82955100","product_id":"BCH-USD","sequence":4839272551,"time":"2018-07-27T01:32:41.054000Z"}
{"type":"done","side":"buy","order_id":"767ba8de-e9e6-4bb7-b1fd-a559ed57a2ad","reason":"canceled","product_id":"BCH-USD","price":"792.54000000","remaining_size":"2.00000000","sequence":4839272552,"time":"2018-07-27T01:32:41.054000Z"}
{"type":"received","order_id":"b38cb653-5bf2-42de-be77-66d2f8def7e8","order_type":"limit","size":"7.44874862","price":"83.34000000","side":"sell","client_oid":"b46591a8-ab8e-4bbb-8000-003742540858","product_id":"LTC-USD","sequence":2423271864,"time":"2018-07-27T01:32:41.057000Z"}
{"type":"open","side":"sell","price":"83.34000000","order_id":"b38cb653-5bf2-42de-be77-66d2f8def7e8","remaining_size":"7.44874862","product_id":"LTC-USD","sequence":2423271865,"time":"2018-07-27T01:32:41.057000Z"}
{"type":"received","order_id":"6285d8a2-0f45-44eb-ac6c-44779bc778d3","order_type":"limit","size":"0.90000000","price":"795.13000000","side":"sell","client_oid":"6a07afb5-9578-4aa7-9792-ae1c06f69d2a","product_id":"BCH-USD","sequence":4839272553,"time":"2018-07-27T01:32:41.057000Z"}
{"type":"open","side":"sell","price":"795.13000000","order_id":"6285d8a2-0f45-44eb-ac6c-44779bc778d3","remaining_size":"0.90000000","product_id":"BCH-USD","sequence":4839272554,"time":"2018-07-27T01:32:41.057000Z"}
{"type":"received","order_id":"0dadaf72-e860-41bb-b5ed-abbe7cb71a95","order_type":"limit","size":"1.90000000","price":"795.13000000","side":"sell","client_oid":"47385ac7-f3d6-4ee1-8485-59159294c709","product_id":"BCH-USD","sequence":4839272555,"time":"2018-07-27T01:32:41.061000Z"}
{"type":"open","side":"sell","price":"795.13000000","order_id":"0dadaf72-e860-41bb-b5ed-abbe7cb71a95","remaining_size":"1.90000000","product_id":"BCH-USD","sequence":4839272556,"time":"2018-07-27T01:32:41.061000Z"}
{"type":"done","side":"sell","order_id":"dd51c3e0-da58-4452-8af6-b5f2b1926c93","reason":"canceled","product_id":"BCH-USD","price":"795.17000000","remaining_size":"4.50000000","sequence":4839272557,"time":"2018-07-27T01:32:41.061000Z"}
{"type":"received","order_id":"e961fb47-e560-4444-88d8-1f3d0b8d694f","order_type":"limit","size":"6.00000000","price":"463.46000000","side":"sell","client_oid":"36b476a1-b271-401f-b4a3-3438a2809da0","product_id":"ETH-USD","sequence":4469354791,"time":"2018-07-27T01:32:41.062000Z"}
{"type":"open","side":"sell","price":"463.46000000","order_id":"e961fb47-e560-4444-88d8-1f3d0b8d694f","remaining_size":"6.00000000","product_id":"ETH-USD","sequence":4469354792,"time":"2018-07-27T01:32:41.062000Z"}
{"type":"received","order_id":"33465787-f102-4b01-a16d-e1f5d84bc76a","order_type":"limit","size":"20.00000000","price":"83.36000000","side":"sell","client_oid":"4258b6ba-447e-4250-9a86-652d1fbc55f9","product_id":"LTC-USD","sequence":2423271866,"time":"2018-07-27T01:32:41.066000Z"}
{"type":"open","side":"sell","price":"83.36000000","order_id":"33465787-f102-4b01-a16d-e1f5d84bc76a","remaining_size":"20.00000000","product_id":"LTC-USD","sequence":2423271867,"time":"2018-07-27T01:32:41.066000Z"}
{"type":"done","side":"sell","order_id":"0dadaf72-e860-41bb-b5ed-abbe7cb71a95","reason":"canceled","product_id":"BCH-USD","price":"795.13000000","remaining_size":"1.90000000","sequence":4839272558,"time":"2018-07-27T01:32:41.065000Z"}
{"type":"received","order_id":"87f03390-3818-40ff-afeb-a5350a52eacf","order_type":"limit","size":"0.22367600","price":"788.00000000","side":"buy","client_oid":"47a284b9-e621-4a80-9220-3177897264ca","product_id":"BCH-USD","sequence":4839272559,"time":"2018-07-27T01:32:41.066000Z"}
{"type":"received","order_id":"48fd8d29-4c1a-4af5-9fea-d235403e89cd","order_type":"limit","size":"23.16886900","price":"83.08000000","side":"buy","client_oid":"b29d3103-dd11-4d2b-93a1-b88261bdff14","product_id":"LTC-USD","sequence":2423271868,"time":"2018-07-27T01:32:41.068000Z"}
{"type":"open","side":"buy","price":"788.00000000","order_id":"87f03390-3818-40ff-afeb-a5350a52eacf","remaining_size":"0.22367600","product_id":"BCH-USD","sequence":4839272560,"time":"2018-07-27T01:32:41.066000Z"}
{"type":"done","side":"buy","order_id":"b7012700-5b86-49e3-8fc0-1a73fb9e71e0","reason":"canceled","product_id":"BCH-USD","price":"789.70000000","remaining_size":"27.67223226","sequence":4839272561,"time":"2018-07-27T01:32:41.067000Z"}
{"type":"open","side":"buy","price":"83.08000000","order_id":"48fd8d29-4c1a-4af5-9fea-d235403e89cd","remaining_size":"23.16886900","product_id":"LTC-USD","sequence":2423271869,"time":"2018-07-27T01:32:41.068000Z"}
{"type":"received","order_id":"76f9f7ec-0f3a-4da7-b351-abfc0afd3aef","order_type":"limit","size":"30.00000000","price":"83.39000000","side":"sell","client_oid":"3db4c84d-f3d2-4b5e-aa16-05acabff3b92","product_id":"LTC-USD","sequence":2423271870,"time":"2018-07-27T01:32:41.069000Z"}
{"type":"open","side":"sell","price":"83.39000000","order_id":"76f9f7ec-0f3a-4da7-b351-abfc0afd3aef","remaining_size":"30.00000000","product_id":"LTC-USD","sequence":2423271871,"time":"2018-07-27T01:32:41.069000Z"}
{"type":"received","order_id":"ed06107d-deaf-4a72-af51-6c3c1d43aaa0","order_type":"limit","size":"2.00000000","price":"792.54000000","side":"buy","client_oid":"b5d35e0f-61d3-40d2-a281-e1e310b6dbd8","product_id":"BCH-USD","sequence":4839272562,"time":"2018-07-27T01:32:41.069000Z"}
{"type":"open","side":"buy","price":"792.54000000","order_id":"ed06107d-deaf-4a72-af51-6c3c1d43aaa0","remaining_size":"2.00000000","product_id":"BCH-USD","sequence":4839272563,"time":"2018-07-27T01:32:41.069000Z"}
{"type":"received","order_id":"22aee83d-c111-423e-bc88-717c2e5a1efd","order_type":"limit","size":"4.50000000","price":"795.14000000","side":"sell","client_oid":"bd55f186-6c29-4bcf-ba28-949038e066ee","product_id":"BCH-USD","sequence":4839272564,"time":"2018-07-27T01:32:41.070000Z"}
{"type":"open","side":"sell","price":"795.14000000","order_id":"22aee83d-c111-423e-bc88-717c2e5a1efd","remaining_size":"4.50000000","product_id":"BCH-USD","sequence":4839272565,"time":"2018-07-27T01:32:41.070000Z"}
{"type":"received","order_id":"c43581a6-17ac-43df-b6fd-a900248232e9","order_type":"limit","size":"1.90000000","price":"795.14000000","side":"sell","client_oid":"394a7547-2f67-4669-bc32-f4002ab7a904","product_id":"BCH-USD","sequence":4839272566,"time":"2018-07-27T01:32:41.071000Z"}
{"type":"open","side":"sell","price":"795.14000000","order_id":"c43581a6-17ac-43df-b6fd-a900248232e9","remaining_size":"1.90000000","product_id":"BCH-USD","sequence":4839272567,"time":"2018-07-27T01:32:41.071000Z"}
{"type":"done","side":"sell","order_id":"116c411a-bbbb-493f-980e-e34cacb3d6b6","reason":"canceled","product_id":"BCH-USD","price":"795.17000000","remaining_size":"0.90000000","sequence":4839272568,"time":"2018-07-27T01:32:41.073000Z"}
{"type":"received","order_id":"7dbc5035-41e7-4b24-93da-48bdd70f0421","order_type":"limit","size":"6.00000000","price":"463.58000000","side":"sell","client_oid":"5bc35e1a-dba6-4655-8403-af8165d2d959","product_id":"ETH-USD","sequence":4469354793,"time":"2018-07-27T01:32:41.074000Z"}
