{"type":"open","side":"sell","price":"463.58000000","order_id":"7dbc5035-41e7-4b24-93da-48bdd70f0421","remaining_size":"6.00000000","product_id":"ETH-USD","sequence":4469354794,"time":"2018-07-27T01:32:41.074000Z"}
{"type":"done","side":"sell","order_id":"f7e99097-80fc-4137-8063-1a329e927a56","reason":"canceled","product_id":"ETH-USD","price":"462.60000000","remaining_size":"0.01000000","sequence":4469354795,"time":"2018-07-27T01:32:41.075000Z"}
{"type":"received","order_id":"55f8a760-9a06-42d3-b385-401fec5a47e3","order_type":"limit","size":"0.02000000","price":"795.84000000","side":"sell","client_oid":"55abef0e-ee46-47ea-9ee1-c36e31e76f66","product_id":"BCH-USD","sequence":4839272569,"time":"2018-07-27T01:32:41.076000Z"}
{"type":"open","side":"sell","price":"795.84000000","order_id":"55f8a760-9a06-42d3-b385-401fec5a47e3","remaining_size":"0.02000000","product_id":"BCH-USD","sequence":4839272570,"time":"2018-07-27T01:32:41.076000Z"}
{"type":"received","order_id":"aa69a888-ff8b-47cb-967e-06c0b7fe923b","order_type":"limit","size":"1.57083900","price":"787.52000000","side":"buy","client_oid":"a468236a-641f-499e-a50a-0abe36b85907","product_id":"BCH-USD","sequence":4839272571,"time":"2018-07-27T01:32:41.078000Z"}
{"type":"open","side":"buy","price":"787.52000000","order_id":"aa69a888-ff8b-47cb-967e-06c0b7fe923b","remaining_size":"1.57083900","product_id":"BCH-USD","sequence":4839272572,"time":"2018-07-27T01:32:41.078000Z"}
{"type":"received","order_id":"95c85f22-08f6-43b4-9c22-aa1f9a6da66b","order_type":"limit","size":"3.43478000","price":"83.11000000","side":"buy","client_oid":"9b033aee-8e4a-4a4b-87f1-52eb4e94ce52","product_id":"LTC-USD","sequence":2423271872,"time":"2018-07-27T01:32:41.083000Z"}
{"type":"open","side":"buy","price":"83.11000000","order_id":"95c85f22-08f6-43b4-9c22-aa1f9a6da66b","remaining_size":"3.43478000","product_id":"LTC-USD","sequence":2423271873,"time":"2018-07-27T01:32:41.083000Z"}
{"type":"done","side":"sell","order_id":"c43581a6-17ac-43df-b6fd-a900248232e9","reason":"canceled","product_id":"BCH-USD","price":"795.14000000","remaining_size":"1.90000000","sequence":4839272573,"time":"2018-07-27T01:32:41.082000Z"}
{"type":"done","side":"sell","order_id":"bd2b34ce-bc17-422a-90c1-34bbb1104c5a","reason":"canceled","product_id":"LTC-USD","price":"83.30000000","remaining_size":"7.44874862","sequence":2423271874,"time":"2018-07-27T01:32:41.084000Z"}
{"type":"done","side":"sell","order_id":"22aee83d-c111-423e-bc88-717c2e5a1efd","reason":"canceled","product_id":"BCH-USD","price":"795.14000000","remaining_size":"4.50000000","sequence":4839272574,"time":"2018-07-27T01:32:41.083000Z"}
{"type":"done","side":"buy","order_id":"5ba82201-0b4a-4003-9cb8-ae4a96163d56","reason":"canceled","product_id":"LTC-USD","price":"82.99000000","remaining_size":"20.00000000","sequence":2423271875,"time":"2018-07-27T01:32:41.088000Z"}
{"type":"received","order_id":"38dae101-45d4-4af6-b0be-1ff916ad6fe1","order_type":"limit","size":"0.90000000","price":"795.13000000","side":"sell","client_oid":"e51ffe4e-7378-413c-bc91-d42887830e25","product_id":"BCH-USD","sequence":4839272575,"time":"2018-07-27T01:32:41.088000Z"}
{"type":"open","side":"sell","price":"795.13000000","order_id":"38dae101-45d4-4af6-b0be-1ff916ad6fe1","remaining_size":"0.90000000","product_id":"BCH-USD","sequence":4839272576,"time":"2018-07-27T01:32:41.088000Z"}
{"type":"received","order_id":"d5674aeb-12ed-4a22-851c-ee43f9fed52f","order_type":"limit","size":"1.90000000","price":"795.13000000","side":"sell","client_oid":"61ced861-9fbd-4c8c-982d-daced4aeb1d2","product_id":"BCH-USD","sequence":4839272577,"time":"2018-07-27T01:32:41.090000Z"}
{"type":"open","side":"sell","price":"795.13000000","order_id":"d5674aeb-12ed-4a22-851c-ee43f9fed52f","remaining_size":"1.90000000","product_id":"BCH-USD","sequence":4839272578,"time":"2018-07-27T01:32:41.090000Z"}
{"type":"received","order_id":"25ff9804-3e67-423b-8f96-06d7c7914d97","order_type":"limit","size":"6.00000000","price":"462.96000000","side":"sell","client_oid":"2f985081-d097-44ae-9b7e-f87dba3cc884","product_id":"ETH-USD","sequence":4469354796,"time":"2018-07-27T01:32:41.094000Z"}
{"type":"received","order_id":"66059654-9385-443a-8c3d-2552d604644c","order_type":"limit","size":"20.00000000","price":"82.98000000","side":"buy","client_oid":"ced424db-b68a-4c4c-878d-700500ae4225","product_id":"LTC-USD","sequence":2423271876,"time":"2018-07-27T01:32:41.095000Z"}
{"type":"open","side":"sell","price":"462.96000000","order_id":"25ff9804-3e67-423b-8f96-06d7c7914d97","remaining_size":"6.00000000","product_id":"ETH-USD","sequence":4469354797,"time":"2018-07-27T01:32:41.094000Z"}
{"type":"open","side":"buy","price":"82.98000000","order_id":"66059654-9385-443a-8c3d-2552d604644c","remaining_size":"20.00000000","product_id":"LTC-USD","sequence":2423271877,"time":"2018-07-27T01:32:41.095000Z"}
{"type":"received","order_id":"4e38921f-fd9b-4844-9d8a-53dcec781705","order_type":"limit","size":"7.44874862","price":"83.38000000","side":"sell","client_oid":"dc92c5fc-6d53-4ac4-8000-009fa1db490a","product_id":"LTC-USD","sequence":2423271878,"time":"2018-07-27T01:32:41.097000Z"}
{"type":"open","side":"sell","price":"83.38000000","order_id":"4e38921f-fd9b-4844-9d8a-53dcec781705","remaining_size":"7.44874862","product_id":"LTC-USD","sequence":2423271879,"time":"2018-07-27T01:32:41.097000Z"}
{"type":"received","order_id":"40d8a32b-fa0b-4f7f-ad69-2f07a51b01a9","order_type":"limit","size":"4.50000000","price":"795.13000000","side":"sell","client_oid":"8d3f01ad-e76d-4277-98e8-7a8e84beecbb","product_id":"BCH-USD","sequence":4839272579,"time":"2018-07-27T01:32:41.096000Z"}
{"type":"open","side":"sell","price":"795.13000000","order_id":"40d8a32b-fa0b-4f7f-ad69-2f07a51b01a9","remaining_size":"4.50000000","product_id":"BCH-USD","sequence":4839272580,"time":"2018-07-27T01:32:41.096000Z"}
{"type":"received","order_id":"e6c3c9b0-7383-4dbe-9287-912a71730f52","order_type":"limit","size":"4.60839500","price":"461.88000000","side":"buy","client_oid":"d16d81a5-480f-4a0d-8bb1-a97f544b5b1a","product_id":"ETH-USD","sequence":4469354798,"time":"2018-07-27T01:32:41.100000Z"}
{"type":"open","side":"buy","price":"461.88000000","order_id":"e6c3c9b0-7383-4dbe-9287-912a71730f52","remaining_size":"4.60839500","product_id":"ETH-USD","sequence":4469354799,"time":"2018-07-27T01:32:41.100000Z"}
{"type":"received","order_id":"b01f6c80-55a2-4f1f-82f4-ef9f0012f20f","order_type":"limit","size":"30.00000000","price":"83.45000000","side":"sell","client_oid":"3a285912-51c0-4b07-9317-2106a58e52ff","product_id":"LTC-USD","sequence":2423271880,"time":"2018-07-27T01:32:41.103000Z"}
{"type":"open","side":"sell","price":"83.45000000","order_id":"b01f6c80-55a2-4f1f-82f4-ef9f0012f20f","remaining_size":"30.00000000","product_id":"LTC-USD","sequence":2423271881,"time":"2018-07-27T01:32:41.103000Z"}
{"type":"received","order_id":"1344bd89-5add-4dc6-9027-fd2e516a23cd","order_type":"limit","size":"0.02000000","price":"462.77000000","side":"sell","client_oid":"caae6146-2da7-4caf-93d0-f4e643c4a930","product_id":"ETH-USD","sequence":4469354800,"time":"2018-07-27T01:32:41.104000Z"}
{"type":"open","side":"sell","price":"462.77000000","order_id":"1344bd89-5add-4dc6-9027-fd2e516a23cd","remaining_size":"0.02000000","product_id":"ETH-USD","sequence":4469354801,"time":"2018-07-27T01:32:41.104000Z"}
{"type":"received","order_id":"001d66cd-adc8-43fb-a6fc-877d73d7059f","order_type":"limit","size":"1.81488800","price":"791.24000000","side":"buy","client_oid":"72054e1c-1281-4136-98a2-6b5aac7986c8","product_id":"BCH-USD","sequence":4839272581,"time":"2018-07-27T01:32:41.107000Z"}
{"type":"open","side":"buy","price":"791.24000000","order_id":"001d66cd-adc8-43fb-a6fc-877d73d7059f","remaining_size":"1.81488800","product_id":"BCH-USD","sequence":4839272582,"time":"2018-07-27T01:32:41.107000Z"}
{"type":"received","order_id":"05df48db-05a8-4469-9435-9161e8906e25","order_type":"limit","size":"4.50000000","price":"795.67000000","side":"sell","client_oid":"1000c3ec-d108-4107-a77c-c3d04c1fa9d4","product_id":"BCH-USD","sequence":4839272583,"time":"2018-07-27T01:32:41.110000Z"}
{"type":"open","side":"sell","price":"795.67000000","order_id":"05df48db-05a8-4469-9435-9161e8906e25","remaining_size":"4.50000000","product_id":"BCH-USD","sequence":4839272584,"time":"2018-07-27T01:32:41.110000Z"}
{"type":"done","side":"buy","order_id":"001d66cd-adc8-43fb-a6fc-877d73d7059f","reason":"canceled","product_id":"BCH-USD","price":"791.24000000","remaining_size":"1.81488800","sequence":4839272585,"time":"2018-07-27T01:32:41.112000Z"}
{"type":"done","side":"sell","order_id":"05df48db-05a8-4469-9435-9161e8906e25","reason":"canceled","product_id":"BCH-USD","price":"795.67000000","remaining_size":"4.50000000","sequence":4839272586,"time":"2018-07-27T01:32:41.114000Z"}
{"type":"received","order_id":"ebd31150-d680-4b70-a6d6-0b9ef264af7e","order_type":"limit","size":"1.90000000","price":"795.13000000","side":"sell","client_oid":"aa0e991a-d80c-445f-adb9-703b4ea6d27c","product_id":"BCH-USD","sequence":4839272587,"time":"2018-07-27T01:32:41.118000Z"}
{"type":"open","side":"sell","price":"795.13000000","order_id":"ebd31150-d680-4b70-a6d6-0b9ef264af7e","remaining_size":"1.90000000","product_id":"BCH-USD","sequence":4839272588,"time":"2018-07-27T01:32:41.118000Z"}
{"type":"done","side":"sell","order_id":"d5674aeb-12ed-4a22-851c-ee43f9fed52f","reason":"canceled","product_id":"BCH-USD","price":"795.13000000","remaining_size":"1.90000000","sequence":4839272589,"time":"2018-07-27T01:32:41.120000Z"}
{"type":"done","side":"sell","order_id":"6285d8a2-0f45-44eb-ac6c-44779bc778d3","reason":"canceled","product_id":"BCH-USD","price":"795.13000000","remaining_size":"0.90000000","sequence":4839272590,"time":"2018-07-27T01:32:41.121000Z"}
{"type":"done","side":"sell","order_id":"b38cb653-5bf2-42de-be77-66d2f8def7e8","reason":"canceled","product_id":"LTC-USD","price":"83.34000000","remaining_size":"7.44874862","sequence":2423271882,"time":"2018-07-27T01:32:41.124000Z"}
{"type":"received","order_id":"ea7f1d42-a10d-4863-95df-9ab2c0758d54","order_type":"limit","size":"1.81488800","price":"791.23000000","side":"buy","client_oid":"8c451f79-805d-4e3b-aa62-3bb6a9ae4db4","product_id":"BCH-USD","sequence":4839272591,"time":"2018-07-27T01:32:41.124000Z"}
{"type":"open","side":"buy","price":"791.23000000","order_id":"ea7f1d42-a10d-4863-95df-9ab2c0758d54","remaining_size":"1.81488800","product_id":"BCH-USD","sequence":4839272592,"time":"2018-07-27T01:32:41.124000Z"}
{"type":"received","order_id":"ad64555f-6cbd-4966-913c-c6218d49e752","order_type":"limit","size":"1.90000000","price":"795.12000000","side":"sell","client_oid":"7f72a68a-1db8-42d9-82fa-02d99a972213","product_id":"BCH-USD","sequence":4839272593,"time":"2018-07-27T01:32:41.127000Z"}
{"type":"open","side":"sell","price":"795.12000000","order_id":"ad64555f-6cbd-4966-913c-c6218d49e752","remaining_size":"1.90000000","product_id":"BCH-USD","sequence":4839272594,"time":"2018-07-27T01:32:41.127000Z"}
{"type":"done","side":"sell","order_id":"40d8a32b-fa0b-4f7f-ad69-2f07a51b01a9","reason":"canceled","product_id":"BCH-USD","price":"795.13000000","remaining_size":"4.50000000","sequence":4839272595,"time":"2018-07-27T01:32:41.129000Z"}
{"type":"received","order_id":"020233e5-0fa1-4af0-84df-d1fb580842ee","order_type":"limit","size":"4.50000000","price":"795.53000000","side":"sell","client_oid":"bd397976-97e4-47be-b897-0f67965d5ff5","product_id":"BCH-USD","sequence":4839272596,"time":"2018-07-27T01:32:41.131000Z"}
{"type":"open","side":"sell","price":"795.53000000","order_id":"020233e5-0fa1-4af0-84df-d1fb580842ee","remaining_size":"4.50000000","product_id":"BCH-USD","sequence":4839272597,"time":"2018-07-27T01:32:41.131000Z"}
{"type":"done","side":"sell","order_id":"38dae101-45d4-4af6-b0be-1ff916ad6fe1","reason":"canceled","product_id":"BCH-USD","price":"795.13000000","remaining_size":"0.90000000","sequence":4839272598,"time":"2018-07-27T01:32:41.134000Z"}
{"type":"received","order_id":"0da86e10-9fff-4ef3-a615-0e4564dc7cc8","order_type":"limit","size":"0.90000000","price":"795.12000000","side":"sell","client_oid":"ca3e56b3-03e1-4bc5-bdb6-27c5ac27e4a7","product_id":"BCH-USD","sequence":4839272599,"time":"2018-07-27T01:32:41.135000Z"}
{"type":"done","side":"buy","order_id":"66059654-9385-443a-8c3d-2552d604644c","reason":"canceled","product_id":"LTC-USD","price":"82.98000000","remaining_size":"20.00000000","sequence":2423271883,"time":"2018-07-27T01:32:41.137000Z"}
{"type":"open","side":"sell","price":"795.12000000","order_id":"0da86e10-9fff-4ef3-a615-0e4564dc7cc8","remaining_size":"0.90000000","product_id":"BCH-USD","sequence":4839272600,"time":"2018-07-27T01:32:41.135000Z"}
{"type":"done","side":"buy","order_id":"3383ca61-0151-4095-85ea-824099e09a6a","reason":"canceled","product_id":"BCH-USD","price":"791.23000000","remaining_size":"0.18739300","sequence":4839272601,"time":"2018-07-27T01:32:41.138000Z"}
{"type":"done","side":"sell","order_id":"119e0b98-0fc7-4ff6-84c2-9eac124507dc","reason":"canceled","product_id":"BTC-USD","price":"7907.52000000","remaining_size":"0.02500000","sequence":6418130266,"time":"2018-07-27T01:32:41.144000Z"}
{"type":"received","order_id":"1bb334da-55fc-4405-8370-3cb49eab3881","order_type":"limit","size":"0.90000000","price":"795.12000000","side":"sell","client_oid":"266a00db-d8cc-41a7-a2bb-56d6a3e88485","product_id":"BCH-USD","sequence":4839272602,"time":"2018-07-27T01:32:41.142000Z"}
{"type":"open","side":"sell","price":"795.12000000","order_id":"1bb334da-55fc-4405-8370-3cb49eab3881","remaining_size":"0.90000000","product_id":"BCH-USD","sequence":4839272603,"time":"2018-07-27T01:32:41.142000Z"}
{"type":"received","order_id":"41470b16-61e6-4dfd-a92c-8e3d8f4ec1dc","order_type":"limit","size":"20.00000000","price":"82.99000000","side":"buy","client_oid":"5ac752c5-a05b-4df3-814a-b554ef60dc3c","product_id":"LTC-USD","sequence":2423271884,"time":"2018-07-27T01:32:41.146000Z"}
{"type":"open","side":"buy","price":"82.99000000","order_id":"41470b16-61e6-4dfd-a92c-8e3d8f4ec1dc","remaining_size":"20.00000000","product_id":"LTC-USD","sequence":2423271885,"time":"2018-07-27T01:32:41.146000Z"}
{"type":"received","order_id":"f199b5d1-497e-4369-b832-010f54452371","order_type":"limit","size":"7.44874862","price":"83.30000000","side":"sell","client_oid":"69e4cf5d-f471-4481-8000-0a2bbba15630","product_id":"LTC-USD","sequence":2423271886,"time":"2018-07-27T01:32:41.147000Z"}
{"type":"open","side":"sell","price":"83.30000000","order_id":"f199b5d1-497e-4369-b832-010f54452371","remaining_size":"7.44874862","product_id":"LTC-USD","sequence":2423271887,"time":"2018-07-27T01:32:41.147000Z"}
{"type":"received","order_id":"d973934d-cb17-4c92-a848-42e2c77cbb35","order_type":"limit","size":"4.50000000","price":"795.12000000","side":"sell","client_oid":"9871c70f-05a1-45cc-b2a6-d31d20248139","product_id":"BCH-USD","sequence":4839272604,"time":"2018-07-27T01:32:41.148000Z"}
{"type":"received","order_id":"7e05813e-3f0e-4225-90d2-14edc18e9c7b","order_type":"limit","size":"0.02500000","price":"7907.16000000","side":"sell","client_oid":"1b0da633-0d6c-48db-8000-00a13fe45791","product_id":"BTC-USD","sequence":6418130267,"time":"2018-07-27T01:32:41.151000Z"}
{"type":"open","side":"sell","price":"795.12000000","order_id":"d973934d-cb17-4c92-a848-42e2c77cbb35","remaining_size":"4.50000000","product_id":"BCH-USD","sequence":4839272605,"time":"2018-07-27T01:32:41.148000Z"}
{"type":"open","side":"sell","price":"7907.16000000","order_id":"7e05813e-3f0e-4225-90d2-14edc18e9c7b","remaining_size":"0.02500000","product_id":"BTC-USD","sequence":6418130268,"time":"2018-07-27T01:32:41.151000Z"}
{"type":"done","side":"sell","order_id":"d973934d-cb17-4c92-a848-42e2c77cbb35","reason":"canceled","product_id":"BCH-USD","price":"795.12000000","remaining_size":"4.50000000","sequence":4839272606,"time":"2018-07-27T01:32:41.153000Z"}
{"type":"done","side":"sell","order_id":"ad64555f-6cbd-4966-913c-c6218d49e752","reason":"canceled","product_id":"BCH-USD","price":"795.12000000","remaining_size":"1.90000000","sequence":4839272607,"time":"2018-07-27T01:32:41.153000Z"}
{"type":"done","side":"sell","order_id":"4e38921f-fd9b-4844-9d8a-53dcec781705","reason":"canceled","product_id":"LTC-USD","price":"83.38000000","remaining_size":"7.44874862","sequence":2423271888,"time":"2018-07-27T01:32:41.156000Z"}
{"type":"done","side":"sell","order_id":"0da86e10-9fff-4ef3-a615-0e4564dc7cc8","reason":"canceled","product_id":"BCH-USD","price":"795.12000000","remaining_size":"0.90000000","sequence":4839272608,"time":"2018-07-27T01:32:41.156000Z"}
{"type":"received","order_id":"2bac0dae-90b5-44e6-b2d6-fa89f44ddfe7","order_type":"limit","size":"0.18739300","price":"791.24000000","side":"buy","client_oid":"51714c3c-e21f-43b0-a1dc-391458e073e9","product_id":"BCH-USD","sequence":4839272609,"time":"2018-07-27T01:32:41.157000Z"}
{"type":"open","side":"buy","price":"791.24000000","order_id":"2bac0dae-90b5-44e6-b2d6-fa89f44ddfe7","remaining_size":"0.18739300","product_id":"BCH-USD","sequence":4839272610,"time":"2018-07-27T01:32:41.157000Z"}
{"type":"received","order_id":"5384fb87-2907-44b9-9719-ac285d1a26d3","order_type":"limit","size":"7.00000000","price":"794.00000000","side":"sell","client_oid":"8bb48617-7e75-492e-b089-c9c6eb9893f6","product_id":"BCH-USD","sequence":4839272611,"time":"2018-07-27T01:32:41.159000Z"}
{"type":"open","side":"sell","price":"794.00000000","order_id":"5384fb87-2907-44b9-9719-ac285d1a26d3","remaining_size":"7.00000000","product_id":"BCH-USD","sequence":4839272612,"time":"2018-07-27T01:32:41.159000Z"}
{"type":"received","order_id":"f39d86a3-349c-4f68-a748-7b158ae9450c","order_type":"limit","size":"0.90000000","price":"795.11000000","side":"sell","client_oid":"3ffb78d2-8e16-4acf-8d12-ba847d2d2c21","product_id":"BCH-USD","sequence":4839272613,"time":"2018-07-27T01:32:41.162000Z"}
{"type":"open","side":"sell","price":"795.11000000","order_id":"f39d86a3-349c-4f68-a748-7b158ae9450c","remaining_size":"0.90000000","product_id":"BCH-USD","sequence":4839272614,"time":"2018-07-27T01:32:41.162000Z"}
{"type":"received","order_id":"36b08fd7-3ff9-49a8-a5a4-32b836f46552","order_type":"limit","size":"4.50000000","price":"795.11000000","side":"sell","client_oid":"c11b3c83-02da-47cf-866d-54f1636a5603","product_id":"BCH-USD","sequence":4839272615,"time":"2018-07-27T01:32:41.164000Z"}
{"type":"open","side":"sell","price":"795.11000000","order_id":"36b08fd7-3ff9-49a8-a5a4-32b836f46552","remaining_size":"4.50000000","product_id":"BCH-USD","sequence":4839272616,"time":"2018-07-27T01:32:41.164000Z"}
{"type":"received","order_id":"0bf14930-4333-4954-83f3-7393aa4ed637","order_type":"limit","size":"1.90000000","price":"795.11000000","side":"sell","client_oid":"dab2b9c6-3528-4294-ae8a-9e99e4ebc256","product_id":"BCH-USD","sequence":4839272617,"time":"2018-07-27T01:32:41.167000Z"}
{"type":"open","side":"sell","price":"795.11000000","order_id":"0bf14930-4333-4954-83f3-7393aa4ed637","remaining_size":"1.90000000","product_id":"BCH-USD","sequence":4839272618,"time":"2018-07-27T01:32:41.167000Z"}
{"type":"received","order_id":"bb9b4f33-58d0-4334-b215-da88e632fe17","order_type":"limit","size":"7.44874862","price":"83.34000000","side":"sell","client_oid":"c0f952a7-d5b2-47c3-8000-00bbc6def2cd","product_id":"LTC-USD","sequence":2423271889,"time":"2018-07-27T01:32:41.170000Z"}
{"type":"open","side":"sell","price":"83.34000000","order_id":"bb9b4f33-58d0-4334-b215-da88e632fe17","remaining_size":"7.44874862","product_id":"LTC-USD","sequence":2423271890,"time":"2018-07-27T01:32:41.170000Z"}
{"type":"done","side":"buy","order_id":"ea7f1d42-a10d-4863-95df-9ab2c0758d54","reason":"canceled","product_id":"BCH-USD","price":"791.23000000","remaining_size":"1.81488800","sequence":4839272619,"time":"2018-07-27T01:32:41.175000Z"}
{"type":"done","side":"sell","order_id":"c3c44a45-f34c-4bbf-9278-1c3dc32974e7","reason":"canceled","product_id":"BCH-USD","price":"795.18000000","remaining_size":"7.07900000","sequence":4839272620,"time":"2018-07-27T01:32:41.176000Z"}
{"type":"done","side":"buy","order_id":"41470b16-61e6-4dfd-a92c-8e3d8f4ec1dc","reason":"canceled","product_id":"LTC-USD","price":"82.99000000","remaining_size":"20.00000000","sequence":2423271891,"time":"2018-07-27T01:32:41.178000Z"}
{"type":"done","side":"sell","order_id":"1bb334da-55fc-4405-8370-3cb49eab3881","reason":"canceled","product_id":"BCH-USD","price":"795.12000000","remaining_size":"0.90000000","sequence":4839272621,"time":"2018-07-27T01:32:41.179000Z"}
{"type":"received","order_id":"654420f9-0ad9-4c6d-b9eb-1a93fa5f452e","order_type":"limit","size":"20.00000000","price":"82.98000000","side":"buy","client_oid":"0cbba1e1-6b34-4b3e-b9cb-02e77c7438ad","product_id":"LTC-USD","sequence":2423271892,"time":"2018-07-27T01:32:41.184000Z"}
{"type":"received","order_id":"b9605579-1273-4ce7-ad75-349c77e2358a","order_type":"limit","size":"1.81488800","price":"791.24000000","side":"buy","client_oid":"306a6ebf-7c56-4d70-b634-ebde1b9ae3f9","product_id":"BCH-USD","sequence":4839272622,"time":"2018-07-27T01:32:41.183000Z"}
{"type":"open","side":"buy","price":"791.24000000","order_id":"b9605579-1273-4ce7-ad75-349c77e2358a","remaining_size":"1.81488800","product_id":"BCH-USD","sequence":4839272623,"time":"2018-07-27T01:32:41.183000Z"}
{"type":"open","side":"buy","price":"82.98000000","order_id":"654420f9-0ad9-4c6d-b9eb-1a93fa5f452e","remaining_size":"20.00000000","product_id":"LTC-USD","sequence":2423271893,"time":"2018-07-27T01:32:41.184000Z"}
{"type":"done","side":"buy","order_id":"2bac0dae-90b5-44e6-b2d6-fa89f44ddfe7","reason":"canceled","product_id":"BCH-USD","price":"791.24000000","remaining_size":"0.18739300","sequence":4839272624,"time":"2018-07-27T01:32:41.184000Z"}
{"type":"received","order_id":"d7bcd26e-fd7e-4415-9ba4-76748c7b06a5","order_type":"limit","size":"18.78697017","price":"795.09000000","side":"sell","client_oid":"9cfbb45e-9124-11e8-8caa-000e1eec81f0","product_id":"BCH-USD","sequence":4839272625,"time":"2018-07-27T01:32:41.184000Z"}
{"type":"open","side":"sell","price":"795.09000000","order_id":"d7bcd26e-fd7e-4415-9ba4-76748c7b06a5","remaining_size":"18.78697017","product_id":"BCH-USD","sequence":4839272626,"time":"2018-07-27T01:32:41.184000Z"}
{"type":"done","side":"sell","order_id":"f199b5d1-497e-4369-b832-010f54452371","reason":"canceled","product_id":"LTC-USD","price":"83.30000000","remaining_size":"7.44874862","sequence":2423271894,"time":"2018-07-27T01:32:41.187000Z"}
{"type":"received","order_id":"d8ec8e0f-b6ec-40b0-b030-84f9c872c081","order_type":"limit","size":"0.90000000","price":"795.11000000","side":"sell","client_oid":"339fff2e-9c0d-44cf-aae9-672e8aff6bcf","product_id":"BCH-USD","sequence":4839272627,"time":"2018-07-27T01:32:41.190000Z"}
{"type":"open","side":"sell","price":"795.11000000","order_id":"d8ec8e0f-b6ec-40b0-b030-84f9c872c081","remaining_size":"0.90000000","product_id":"BCH-USD","sequence":4839272628,"time":"2018-07-27T01:32:41.190000Z"}
{"type":"received","order_id":"b51a9084-6115-4e12-b35f-dde15b004aea","order_type":"limit","size":"0.18739300","price":"791.23000000","side":"buy","client_oid":"0b04133e-1e35-4961-a3b5-97f5cbe0a85c","product_id":"BCH-USD","sequence":4839272629,"time":"2018-07-27T01:32:41.192000Z"}
{"type":"open","side":"buy","price":"791.23000000","order_id":"b51a9084-6115-4e12-b35f-dde15b004aea","remaining_size":"0.18739300","product_id":"BCH-USD","sequence":4839272630,"time":"2018-07-27T01:32:41.192000Z"}
{"type":"done","side":"sell","order_id":"f39d86a3-349c-4f68-a748-7b158ae9450c","reason":"canceled","product_id":"BCH-USD","price":"795.11000000","remaining_size":"0.90000000","sequence":4839272631,"time":"2018-07-27T01:32:41.195000Z"}
{"type":"done","side":"buy","order_id":"654420f9-0ad9-4c6d-b9eb-1a93fa5f452e","reason":"canceled","product_id":"LTC-USD","price":"82.98000000","remaining_size":"20.00000000","sequence":2423271895,"time":"2018-07-27T01:32:41.197000Z"}
{"type":"done","side":"sell","order_id":"36b08fd7-3ff9-49a8-a5a4-32b836f46552","reason":"canceled","product_id":"BCH-USD","price":"795.11000000","remaining_size":"4.50000000","sequence":4839272632,"time":"2018-07-27T01:32:41.199000Z"}
{"type":"received","order_id":"835a8eed-71ae-497e-a6f0-55b764873596","order_type":"limit","size":"7.44874862","price":"83.38000000","side":"sell","client_oid":"5cbe90a7-0813-4d33-8000-00ea483c0ef0","product_id":"LTC-USD","sequence":2423271896,"time":"2018-07-27T01:32:41.201000Z"}
{"type":"open","side":"sell","price":"83.38000000","order_id":"835a8eed-71ae-497e-a6f0-55b764873596","remaining_size":"7.44874862","product_id":"LTC-USD","sequence":2423271897,"time":"2018-07-27T01:32:41.201000Z"}
{"type":"done","side":"buy","order_id":"b51a9084-6115-4e12-b35f-dde15b004aea","reason":"canceled","product_id":"BCH-USD","price":"791.23000000","remaining_size":"0.18739300","sequence":4839272633,"time":"2018-07-27T01:32:41.200000Z"}
{"type":"done","side":"sell","order_id":"0bf14930-4333-4954-83f3-7393aa4ed637","reason":"canceled","product_id":"BCH-USD","price":"795.11000000","remaining_size":"1.90000000","sequence":4839272634,"time":"2018-07-27T01:32:41.202000Z"}
{"type":"done","side":"sell","order_id":"aa0b172a-53d0-4019-b69a-a94f169344d8","reason":"canceled","product_id":"BTC-USD","price":"7914.19000000","remaining_size":"0.90000000","sequence":6418130269,"time":"2018-07-27T01:32:41.205000Z"}
{"type":"received","order_id":"db2b88db-858e-4d5b-b05b-4b7993296d93","order_type":"limit","size":"0.90000000","price":"795.10000000","side":"sell","client_oid":"ee79e922-6f5e-43ef-bb7f-663ad32a150b","product_id":"BCH-USD","sequence":4839272635,"time":"2018-07-27T01:32:41.203000Z"}
{"type":"done","side":"sell","order_id":"98dca3c6-ce8a-41d9-8c50-94fb9da13ce5","reason":"canceled","product_id":"BTC-USD","price":"7911.82000000","remaining_size":"0.90000000","sequence":6418130270,"time":"2018-07-27T01:32:41.206000Z"}
{"type":"open","side":"sell","price":"795.10000000","order_id":"db2b88db-858e-4d5b-b05b-4b7993296d93","remaining_size":"0.90000000","product_id":"BCH-USD","sequence":4839272636,"time":"2018-07-27T01:32:41.203000Z"}
{"type":"done","side":"sell","order_id":"6ff3a801-88fd-4f7f-b05e-561a263813c6","reason":"canceled","product_id":"LTC-USD","price":"83.52000000","remaining_size":"20.00000000","sequence":2423271898,"time":"2018-07-27T01:32:41.206000Z"}
{"type":"done","side":"buy","order_id":"e6f9074a-360a-4fdb-a4cf-f0056ecedda1","reason":"canceled","product_id":"LTC-USD","price":"83.06000000","remaining_size":"20.00000000","sequence":2423271899,"time":"2018-07-27T01:32:41.207000Z"}
{"type":"done","side":"sell","order_id":"0b05b572-139a-4569-9669-65e04e7be0a7","reason":"canceled","product_id":"LTC-USD","price":"83.45000000","remaining_size":"20.00000000","sequence":2423271900,"time":"2018-07-27T01:32:41.208000Z"}
{"type":"received","order_id":"e3158b99-003f-4396-8a0d-f8b56a5cc026","order_type":"limit","size":"20.00000000","price":"82.99000000","side":"buy","client_oid":"fd215ee6-d787-48d8-ae8e-ae07a7d664e9","product_id":"LTC-USD","sequence":2423271901,"time":"2018-07-27T01:32:41.208000Z"}
{"type":"open","side":"buy","price":"82.99000000","order_id":"e3158b99-003f-4396-8a0d-f8b56a5cc026","remaining_size":"20.00000000","product_id":"LTC-USD","sequence":2423271902,"time":"2018-07-27T01:32:41.208000Z"}
{"type":"done","side":"sell","order_id":"72be7d53-5a34-44fa-abdb-972d77bf252a","reason":"canceled","product_id":"ETH-USD","price":"463.42000000","remaining_size":"9.00000000","sequence":4469354802,"time":"2018-07-27T01:32:41.208000Z"}
{"type":"done","side":"sell","order_id":"db2b88db-858e-4d5b-b05b-4b7993296d93","reason":"canceled","product_id":"BCH-USD","price":"795.10000000","remaining_size":"0.90000000","sequence":4839272637,"time":"2018-07-27T01:32:41.207000Z"}
{"type":"done","side":"sell","order_id":"3dd20a32-d31a-4498-8b2a-2f2397e1950a","reason":"canceled","product_id":"ETH-USD","price":"463.46000000","remaining_size":"9.00000000","sequence":4469354803,"time":"2018-07-27T01:32:41.209000Z"}
{"type":"done","side":"buy","order_id":"8cd5c6e9-f6a4-47b5-8a3e-d7b016cb691a","reason":"canceled","product_id":"BCH-USD","price":"792.01000000","remaining_size":"1.90000000","sequence":4839272638,"time":"2018-07-27T01:32:41.208000Z"}
{"type":"done","side":"buy","order_id":"4a8b8cab-8d23-4919-a25b-4aedc6d7593b","reason":"canceled","product_id":"BCH-USD","price":"792.54000000","remaining_size":"0.90000000","sequence":4839272639,"time":"2018-07-27T01:32:41.209000Z"}
{"type":"done","side":"buy","order_id":"6f80c9be-8064-45c4-9611-9833e3b28257","reason":"canceled","product_id":"ETH-USD","price":"461.39000000","remaining_size":"2.11712000","sequence":4469354804,"time":"2018-07-27T01:32:41.214000Z"}
{"type":"received","order_id":"7d0e5803-d83d-430d-b425-20c3c583cb13","order_type":"limit","size":"0.18739300","price":"791.25000000","side":"buy","client_oid":"ce9ff207-fefa-4a4c-b5dd-5c773ad89806","product_id":"BCH-USD","sequence":4839272640,"time":"2018-07-27T01:32:41.216000Z"}
{"type":"open","side":"buy","price":"791.25000000","order_id":"7d0e5803-d83d-430d-b425-20c3c583cb13","remaining_size":"0.18739300","product_id":"BCH-USD","sequence":4839272641,"time":"2018-07-27T01:32:41.216000Z"}
{"type":"done","side":"sell","order_id":"6990640e-2db4-4782-868d-0f9754cc426b","reason":"canceled","product_id":"BCH-USD","price":"795.54000000","remaining_size":"1.60461000","sequence":4839272642,"time":"2018-07-27T01:32:41.217000Z"}
{"type":"done","side":"buy","order_id":"bb9e40b0-8473-4a8d-b229-8eb7611a6546","reason":"canceled","product_id":"ETH-USD","price":"461.25000000","remaining_size":"4.13454100","sequence":4469354805,"time":"2018-07-27T01:32:41.218000Z"}
{"type":"done","side":"sell","order_id":"bb9b4f33-58d0-4334-b215-da88e632fe17","reason":"canceled","product_id":"LTC-USD","price":"83.34000000","remaining_size":"7.44874862","sequence":2423271903,"time":"2018-07-27T01:32:41.220000Z"}
{"type":"received","order_id":"ffb2dd70-8841-41cd-9f11-9868b15e1ca1","order_type":"limit","size":"1.90000000","price":"795.10000000","side":"sell","client_oid":"04f11800-44a3-44da-af37-fbf143e3cf64","product_id":"BCH-USD","sequence":4839272643,"time":"2018-07-27T01:32:41.219000Z"}
{"type":"open","side":"sell","price":"795.10000000","order_id":"ffb2dd70-8841-41cd-9f11-9868b15e1ca1","remaining_size":"1.90000000","product_id":"BCH-USD","sequence":4839272644,"time":"2018-07-27T01:32:41.219000Z"}
{"type":"done","side":"sell","order_id":"d8ec8e0f-b6ec-40b0-b030-84f9c872c081","reason":"canceled","product_id":"BCH-USD","price":"795.11000000","remaining_size":"0.90000000","sequence":4839272645,"time":"2018-07-27T01:32:41.220000Z"}
{"type":"done","side":"buy","order_id":"e798b674-940c-4b47-ae76-aa4014dc9db2","reason":"canceled","product_id":"ETH-USD","price":"461.11000000","remaining_size":"12.05302100","sequence":4469354806,"time":"2018-07-27T01:32:41.221000Z"}
{"type":"done","side":"buy","order_id":"f4694ac8-4e03-45a0-b5cb-e948b3aa74cc","reason":"canceled","product_id":"ETH-USD","price":"460.41000000","remaining_size":"0.19319100","sequence":4469354807,"time":"2018-07-27T01:32:41.225000Z"}
{"type":"done","side":"buy","order_id":"b9605579-1273-4ce7-ad75-349c77e2358a","reason":"canceled","product_id":"BCH-USD","price":"791.24000000","remaining_size":"1.81488800","sequence":4839272646,"time":"2018-07-27T01:32:41.224000Z"}
{"type":"received","order_id":"d6f63449-22bd-4643-894f-9ab8ca1a717c","order_type":"limit","size":"0.90000000","price":"795.10000000","side":"sell","client_oid":"67d49c3e-616f-4b0c-8db0-fdcbf1bf1d65","product_id":"BCH-USD","sequence":4839272647,"time":"2018-07-27T01:32:41.227000Z"}
{"type":"received","order_id":"76f4861c-ea02-44a0-8557-58dda28df0a4","order_type":"limit","size":"20.00000000","price":"83.06000000","side":"buy","client_oid":"219bf7a0-865d-484d-a783-717e2177bb58","product_id":"LTC-USD","sequence":2423271904,"time":"2018-07-27T01:32:41.229000Z"}
{"type":"open","side":"sell","price":"795.10000000","order_id":"d6f63449-22bd-4643-894f-9ab8ca1a717c","remaining_size":"0.90000000","product_id":"BCH-USD","sequence":4839272648,"time":"2018-07-27T01:32:41.227000Z"}
{"type":"open","side":"buy","price":"83.06000000","order_id":"76f4861c-ea02-44a0-8557-58dda28df0a4","remaining_size":"20.00000000","product_id":"LTC-USD","sequence":2423271905,"time":"2018-07-27T01:32:41.229000Z"}
{"type":"received","order_id":"421a441f-11ee-4257-a5fd-2d301dcb7a66","order_type":"limit","size":"1.81488800","price":"791.23000000","side":"buy","client_oid":"577f8ad0-94c4-4858-b91a-9debcc29f029","product_id":"BCH-USD","sequence":4839272649,"time":"2018-07-27T01:32:41.231000Z"}
{"type":"open","side":"buy","price":"791.23000000","order_id":"421a441f-11ee-4257-a5fd-2d301dcb7a66","remaining_size":"1.81488800","product_id":"BCH-USD","sequence":4839272650,"time":"2018-07-27T01:32:41.231000Z"}
{"type":"done","side":"sell","order_id":"d6f63449-22bd-4643-894f-9ab8ca1a717c","reason":"canceled","product_id":"BCH-USD","price":"795.10000000","remaining_size":"0.90000000","sequence":4839272651,"time":"2018-07-27T01:32:41.233000Z"}
{"type":"received","order_id":"a69e1396-4f48-483b-8a41-5f2bd28e274f","order_type":"limit","size":"7.44874862","price":"83.30000000","side":"sell","client_oid":"29f1578d-2585-4477-8000-00ae988a1976","product_id":"LTC-USD","sequence":2423271906,"time":"2018-07-27T01:32:41.237000Z"}
{"type":"done","side":"buy","order_id":"421a441f-11ee-4257-a5fd-2d301dcb7a66","reason":"canceled","product_id":"BCH-USD","price":"791.23000000","remaining_size":"1.81488800","sequence":4839272652,"time":"2018-07-27T01:32:41.235000Z"}
{"type":"open","side":"sell","price":"83.30000000","order_id":"a69e1396-4f48-483b-8a41-5f2bd28e274f","remaining_size":"7.44874862","product_id":"LTC-USD","sequence":2423271907,"time":"2018-07-27T01:32:41.237000Z"}
{"type":"done","side":"buy","order_id":"7d0e5803-d83d-430d-b425-20c3c583cb13","reason":"canceled","product_id":"BCH-USD","price":"791.25000000","remaining_size":"0.18739300","sequence":4839272653,"time":"2018-07-27T01:32:41.239000Z"}
{"type":"received","order_id":"d01ea403-95df-45bf-a742-27b5211fbaad","order_type":"limit","size":"4.50000000","price":"795.10000000","side":"sell","client_oid":"1503587c-452e-410a-a4d8-8c5450a80adf","product_id":"BCH-USD","sequence":4839272654,"time":"2018-07-27T01:32:41.243000Z"}
{"type":"open","side":"sell","price":"795.10000000","order_id":"d01ea403-95df-45bf-a742-27b5211fbaad","remaining_size":"4.50000000","product_id":"BCH-USD","sequence":4839272655,"time":"2018-07-27T01:32:41.243000Z"}
{"type":"done","side":"sell","order_id":"ffb2dd70-8841-41cd-9f11-9868b15e1ca1","reason":"canceled","product_id":"BCH-USD","price":"795.10000000","remaining_size":"1.90000000","sequence":4839272656,"time":"2018-07-27T01:32:41.243000Z"}
{"type":"received","order_id":"1cebba68-2867-4ebc-91b2-1e6d071439f2","order_type":"limit","size":"20.00000000","price":"83.45000000","side":"sell","client_oid":"2614fc8c-ad86-4201-b780-9fc70db43af6","product_id":"LTC-USD","sequence":2423271908,"time":"2018-07-27T01:32:41.246000Z"}
{"type":"open","side":"sell","price":"83.45000000","order_id":"1cebba68-2867-4ebc-91b2-1e6d071439f2","remaining_size":"20.00000000","product_id":"LTC-USD","sequence":2423271909,"time":"2018-07-27T01:32:41.246000Z"}
{"type":"received","order_id":"7ba965ea-a37e-42a3-830e-24ceb85895c0","order_type":"limit","size":"1.81488800","price":"791.25000000","side":"buy","client_oid":"51e5b3b3-3c86-4b2b-a08f-308544a7ffcb","product_id":"BCH-USD","sequence":4839272657,"time":"2018-07-27T01:32:41.246000Z"}
{"type":"open","side":"buy","price":"791.25000000","order_id":"7ba965ea-a37e-42a3-830e-24ceb85895c0","remaining_size":"1.81488800","product_id":"BCH-USD","sequence":4839272658,"time":"2018-07-27T01:32:41.246000Z"}
{"type":"done","side":"buy","order_id":"e3158b99-003f-4396-8a0d-f8b56a5cc026","reason":"canceled","product_id":"LTC-USD","price":"82.99000000","remaining_size":"20.00000000","sequence":2423271910,"time":"2018-07-27T01:32:41.249000Z"}
{"type":"done","side":"sell","order_id":"d01ea403-95df-45bf-a742-27b5211fbaad","reason":"canceled","product_id":"BCH-USD","price":"795.10000000","remaining_size":"4.50000000","sequence":4839272659,"time":"2018-07-27T01:32:41.248000Z"}
{"type":"received","order_id":"c319b2f9-d94c-453c-8266-f237f270e4b2","order_type":"limit","size":"20.00000000","price":"83.52000000","side":"sell","client_oid":"387f826a-db22-4257-a54e-910b59269f59","product_id":"LTC-USD","sequence":2423271911,"time":"2018-07-27T01:32:41.255000Z"}
{"type":"open","side":"sell","price":"83.52000000","order_id":"c319b2f9-d94c-453c-8266-f237f270e4b2","remaining_size":"20.00000000","product_id":"LTC-USD","sequence":2423271912,"time":"2018-07-27T01:32:41.255000Z"}
{"type":"received","order_id":"e2d494c1-170c-4933-91a2-1b0652f3fa18","order_type":"limit","size":"0.90000000","price":"795.08000000","side":"sell","client_oid":"0aed7a56-6fc7-4e1b-9cc0-fe501e57d775","product_id":"BCH-USD","sequence":4839272660,"time":"2018-07-27T01:32:41.254000Z"}
{"type":"open","side":"sell","price":"795.08000000","order_id":"e2d494c1-170c-4933-91a2-1b0652f3fa18","remaining_size":"0.90000000","product_id":"BCH-USD","sequence":4839272661,"time":"2018-07-27T01:32:41.254000Z"}
{"type":"received","order_id":"636d67b6-5ce2-4b38-af8b-6e782e6dd39f","order_type":"limit","size":"3.86683100","price":"461.39000000","side":"buy","client_oid":"7fdd89dc-03da-405c-a263-f54a6b76f659","product_id":"ETH-USD","sequence":4469354808,"time":"2018-07-27T01:32:41.257000Z"}
{"type":"open","side":"buy","price":"461.39000000","order_id":"636d67b6-5ce2-4b38-af8b-6e782e6dd39f","remaining_size":"3.86683100","product_id":"ETH-USD","sequence":4469354809,"time":"2018-07-27T01:32:41.257000Z"}
{"type":"received","order_id":"6295274f-850a-4231-b31b-de2d556af807","order_type":"limit","size":"20.00000000","price":"82.98000000","side":"buy","client_oid":"a167755f-0e69-41cf-ba8f-3460ddb8b63d","product_id":"LTC-USD","sequence":2423271913,"time":"2018-07-27T01:32:41.265000Z"}
{"type":"open","side":"buy","price":"82.98000000","order_id":"6295274f-850a-4231-b31b-de2d556af807","remaining_size":"20.00000000","product_id":"LTC-USD","sequence":2423271914,"time":"2018-07-27T01:32:41.265000Z"}
{"type":"received","order_id":"05892a9e-b52d-4499-836a-93acaf49fb08","order_type":"limit","size":"7.57706500","price":"461.25000000","side":"buy","client_oid":"5f9289d1-ba8d-47f2-8eb0-f7c0768f7372","product_id":"ETH-USD","sequence":4469354810,"time":"2018-07-27T01:32:41.269000Z"}
{"type":"received","order_id":"41cbc4f6-71c0-485d-85e2-1874e381e6e5","order_type":"limit","size":"0.90000000","price":"7911.82000000","side":"sell","client_oid":"0fe50af8-4da1-4ad6-9bdf-499b811103b1","product_id":"BTC-USD","sequence":6418130271,"time":"2018-07-27T01:32:41.271000Z"}
{"type":"open","side":"buy","price":"461.25000000","order_id":"05892a9e-b52d-4499-836a-93acaf49fb08","remaining_size":"7.57706500","product_id":"ETH-USD","sequence":4469354811,"time":"2018-07-27T01:32:41.269000Z"}
{"type":"open","side":"sell","price":"7911.82000000","order_id":"41cbc4f6-71c0-485d-85e2-1874e381e6e5","remaining_size":"0.90000000","product_id":"BTC-USD","sequence":6418130272,"time":"2018-07-27T01:32:41.271000Z"}
{"type":"done","side":"sell","order_id":"835a8eed-71ae-497e-a6f0-55b764873596","reason":"canceled","product_id":"LTC-USD","price":"83.38000000","remaining_size":"7.44874862","sequence":2423271915,"time":"2018-07-27T01:32:41.271000Z"}
{"type":"done","side":"buy","order_id":"7ba965ea-a37e-42a3-830e-24ceb85895c0","reason":"canceled","product_id":"BCH-USD","price":"791.25000000","remaining_size":"1.81488800","sequence":4839272662,"time":"2018-07-27T01:32:41.270000Z"}
{"type":"done","side":"sell","order_id":"020233e5-0fa1-4af0-84df-d1fb580842ee","reason":"canceled","product_id":"BCH-USD","price":"795.53000000","remaining_size":"4.50000000","sequence":4839272663,"time":"2018-07-27T01:32:41.271000Z"}
{"type":"done","side":"sell","order_id":"e759d6cd-2c75-4a20-b6fc-028dcaf29579","reason":"canceled","product_id":"ETH-USD","price":"464.51000000","remaining_size":"8.29703000","sequence":4469354812,"time":"2018-07-27T01:32:41.273000Z"}
{"type":"received","order_id":"23dd3352-adc7-4220-8ac0-57fc3ba1c380","order_type":"limit","size":"9.00000000","price":"463.42000000","side":"sell","client_oid":"abdaf05a-285b-44e7-8c34-a8f42835a6b5","product_id":"ETH-USD","sequence":4469354813,"time":"2018-07-27T01:32:41.278000Z"}
{"type":"open","side":"sell","price":"463.42000000","order_id":"23dd3352-adc7-4220-8ac0-57fc3ba1c380","remaining_size":"9.00000000","product_id":"ETH-USD","sequence":4469354814,"time":"2018-07-27T01:32:41.278000Z"}
{"type":"received","order_id":"632bdb40-624e-4088-b4a0-5ff145e8120d","order_type":"limit","size":"4.50000000","price":"795.67000000","side":"sell","client_oid":"32fcae9a-14b9-4c11-9544-e4cc38411608","product_id":"BCH-USD","sequence":4839272664,"time":"2018-07-27T01:32:41.280000Z"}
{"type":"received","order_id":"0d1a7c33-e061-4477-8bd9-d2e758c1d7d0","order_type":"limit","size":"7.05157600","price":"461.11000000","side":"buy","client_oid":"fb4ecacd-6677-4933-a90f-e6ff1012e7a1","product_id":"ETH-USD","sequence":4469354815,"time":"2018-07-27T01:32:41.281000Z"}
{"type":"open","side":"sell","price":"795.67000000","order_id":"632bdb40-624e-4088-b4a0-5ff145e8120d","remaining_size":"4.50000000","product_id":"BCH-USD","sequence":4839272665,"time":"2018-07-27T01:32:41.280000Z"}
{"type":"open","side":"buy","price":"461.11000000","order_id":"0d1a7c33-e061-4477-8bd9-d2e758c1d7d0","remaining_size":"7.05157600","product_id":"ETH-USD","sequence":4469354816,"time":"2018-07-27T01:32:41.281000Z"}
{"type":"received","order_id":"51f427e9-e44e-4651-b2e0-5320f43de361","order_type":"limit","size":"7.44874862","price":"83.34000000","side":"sell","client_oid":"2598152f-1f65-4c52-8000-0c3d110a1e00","product_id":"LTC-USD","sequence":2423271916,"time":"2018-07-27T01:32:41.283000Z"}
{"type":"open","side":"sell","price":"83.34000000","order_id":"51f427e9-e44e-4651-b2e0-5320f43de361","remaining_size":"7.44874862","product_id":"LTC-USD","sequence":2423271917,"time":"2018-07-27T01:32:41.283000Z"}
{"type":"received","order_id":"80879134-00dc-478d-8de5-09cab9d5557f","order_type":"limit","size":"0.90000000","price":"7914.19000000","side":"sell","client_oid":"b2c2a945-2101-4cf6-b251-84f88dd7165b","product_id":"BTC-USD","sequence":6418130273,"time":"2018-07-27T01:32:41.286000Z"}
{"type":"open","side":"sell","price":"7914.19000000","order_id":"80879134-00dc-478d-8de5-09cab9d5557f","remaining_size":"0.90000000","product_id":"BTC-USD","sequence":6418130274,"time":"2018-07-27T01:32:41.286000Z"}
{"type":"received","order_id":"313da727-3e10-4274-b6c5-6ae602b0044c","order_type":"limit","size":"9.00000000","price":"463.46000000","side":"sell","client_oid":"9de6e8e9-b1b6-4c31-b75b-5899e95a3d15","product_id":"ETH-USD","sequence":4469354817,"time":"2018-07-27T01:32:41.291000Z"}
{"type":"open","side":"sell","price":"463.46000000","order_id":"313da727-3e10-4274-b6c5-6ae602b0044c","remaining_size":"9.00000000","product_id":"ETH-USD","sequence":4469354818,"time":"2018-07-27T01:32:41.291000Z"}
{"type":"received","order_id":"0670f467-31a2-4491-ae5d-a6cd0d42f896","order_type":"limit","size":"36.33720930","price":"82.56000000","side":"buy","product_id":"LTC-USD","sequence":2423271918,"time":"2018-07-27T01:32:41.296000Z"}
{"type":"open","side":"buy","price":"82.56000000","order_id":"0670f467-31a2-4491-ae5d-a6cd0d42f896","remaining_size":"36.33720930","product_id":"LTC-USD","sequence":2423271919,"time":"2018-07-27T01:32:41.296000Z"}
{"type":"received","order_id":"62ebcba1-450d-4580-8925-61270a756549","order_type":"limit","size":"0.90000000","price":"795.08000000","side":"sell","client_oid":"f6225e70-d76a-4781-804b-ab6adcff3369","product_id":"BCH-USD","sequence":4839272666,"time":"2018-07-27T01:32:41.296000Z"}
{"type":"open","side":"sell","price":"795.08000000","order_id":"62ebcba1-450d-4580-8925-61270a756549","remaining_size":"0.90000000","product_id":"BCH-USD","sequence":4839272667,"time":"2018-07-27T01:32:41.296000Z"}
{"type":"received","order_id":"81f9447e-7332-4ce2-bc06-625a04fdb928","order_type":"limit","size":"4.50000000","price":"795.08000000","side":"sell","client_oid":"c0e8bcd9-eebc-4f34-af9a-3dc4ed33c8b7","product_id":"BCH-USD","sequence":4839272668,"time":"2018-07-27T01:32:41.304000Z"}
{"type":"open","side":"sell","price":"795.08000000","order_id":"81f9447e-7332-4ce2-bc06-625a04fdb928","remaining_size":"4.50000000","product_id":"BCH-USD","sequence":4839272669,"time":"2018-07-27T01:32:41.304000Z"}
{"type":"done","side":"sell","order_id":"a69e1396-4f48-483b-8a41-5f2bd28e274f","reason":"canceled","product_id":"LTC-USD","price":"83.30000000","remaining_size":"7.44874862","sequence":2423271920,"time":"2018-07-27T01:32:41.310000Z"}
{"type":"done","side":"sell","order_id":"5384fb87-2907-44b9-9719-ac285d1a26d3","reason":"canceled","product_id":"BCH-USD","price":"794.00000000","remaining_size":"7.00000000","sequence":4839272670,"time":"2018-07-27T01:32:41.313000Z"}
{"type":"received","order_id":"33cb5d48-f316-46d0-847e-4a086a8d7972","order_type":"limit","size":"4.50000000","price":"795.53000000","side":"sell","client_oid":"e19c50a4-82ac-40eb-bcaa-4d7524b1abe4","product_id":"BCH-USD","sequence":4839272671,"time":"2018-07-27T01:32:41.318000Z"}
{"type":"open","side":"sell","price":"795.53000000","order_id":"33cb5d48-f316-46d0-847e-4a086a8d7972","remaining_size":"4.50000000","product_id":"BCH-USD","sequence":4839272672,"time":"2018-07-27T01:32:41.318000Z"}
{"type":"done","side":"sell","order_id":"62ebcba1-450d-4580-8925-61270a756549","reason":"canceled","product_id":"BCH-USD","price":"795.08000000","remaining_size":"0.90000000","sequence":4839272673,"time":"2018-07-27T01:32:41.320000Z"}
{"type":"done","side":"sell","order_id":"81f9447e-7332-4ce2-bc06-625a04fdb928","reason":"canceled","product_id":"BCH-USD","price":"795.08000000","remaining_size":"4.50000000","sequence":4839272674,"time":"2018-07-27T01:32:41.320000Z"}
{"type":"done","side":"sell","order_id":"33cb5d48-f316-46d0-847e-4a086a8d7972","reason":"canceled","product_id":"BCH-USD","price":"795.53000000","remaining_size":"4.50000000","sequence":4839272675,"time":"2018-07-27T01:32:41.322000Z"}
{"type":"received","order_id":"a7a20fca-6d13-4d15-a37e-8a0e1e368069","order_type":"limit","size":"1.90000000","price":"792.01000000","side":"buy","client_oid":"bc2e3c59-5dbe-4776-b0a8-cbb135e6b9ed","product_id":"BCH-USD","sequence":4839272676,"time":"2018-07-27T01:32:41.322000Z"}
{"type":"open","side":"buy","price":"792.01000000","order_id":"a7a20fca-6d13-4d15-a37e-8a0e1e368069","remaining_size":"1.90000000","product_id":"BCH-USD","sequence":4839272677,"time":"2018-07-27T01:32:41.322000Z"}
{"type":"received","order_id":"7fd958ab-e68e-4aec-8df9-4ef21545d2c9","order_type":"limit","size":"7.44874862","price":"83.38000000","side":"sell","client_oid":"443bb14b-2142-48fc-8000-0071eea00195","product_id":"LTC-USD","sequence":2423271921,"time":"2018-07-27T01:32:41.327000Z"}
{"type":"open","side":"sell","price":"83.38000000","order_id":"7fd958ab-e68e-4aec-8df9-4ef21545d2c9","remaining_size":"7.44874862","product_id":"LTC-USD","sequence":2423271922,"time":"2018-07-27T01:32:41.327000Z"}
{"type":"received","order_id":"f0cb7c31-c500-4f4f-9df5-938a47f23f4c","order_type":"limit","size":"1.90000000","price":"795.08000000","side":"sell","client_oid":"fd756813-fbfe-4203-a615-f7f4444067ed","product_id":"BCH-USD","sequence":4839272678,"time":"2018-07-27T01:32:41.329000Z"}
{"type":"open","side":"sell","price":"795.08000000","order_id":"f0cb7c31-c500-4f4f-9df5-938a47f23f4c","remaining_size":"1.90000000","product_id":"BCH-USD","sequence":4839272679,"time":"2018-07-27T01:32:41.329000Z"}
{"type":"received","order_id":"dfc709a4-e6e0-4ec3-9e38-c28f149ac880","order_type":"limit","size":"4.50000000","price":"795.67000000","side":"sell","client_oid":"e94f9006-6379-48bc-92db-a4f7735c15af","product_id":"BCH-USD","sequence":4839272680,"time":"2018-07-27T01:32:41.332000Z"}
{"type":"open","side":"sell","price":"795.67000000","order_id":"dfc709a4-e6e0-4ec3-9e38-c28f149ac880","remaining_size":"4.50000000","product_id":"BCH-USD","sequence":4839272681,"time":"2018-07-27T01:32:41.332000Z"}
{"type":"done","side":"buy","order_id":"97506b8f-5287-4063-9519-ea56814aad7c","reason":"canceled","product_id":"BCH-USD","price":"789.71000000","remaining_size":"11.32000000","sequence":4839272682,"time":"2018-07-27T01:32:41.332000Z"}
{"type":"done","side":"sell","order_id":"dfc709a4-e6e0-4ec3-9e38-c28f149ac880","reason":"canceled","product_id":"BCH-USD","price":"795.67000000","remaining_size":"4.50000000","sequence":4839272683,"time":"2018-07-27T01:32:41.336000Z"}
{"type":"received","order_id":"b2421161-f7ef-4e3c-90df-98475fead6d7","order_type":"limit","size":"0.18739300","price":"791.24000000","side":"buy","client_oid":"1fd793be-9f48-4598-bb4e-b64e98c07cf1","product_id":"BCH-USD","sequence":4839272684,"time":"2018-07-27T01:32:41.338000Z"}
{"type":"open","side":"buy","price":"791.24000000","order_id":"b2421161-f7ef-4e3c-90df-98475fead6d7","remaining_size":"0.18739300","product_id":"BCH-USD","sequence":4839272685,"time":"2018-07-27T01:32:41.338000Z"}
{"type":"received","order_id":"64649299-907c-43bb-9ecd-e4145a67d532","order_type":"limit","size":"12.39000000","price":"789.01000000","side":"buy","client_oid":"7566876c-c8dd-4718-88b9-237679aa1b4f","product_id":"BCH-USD","sequence":4839272686,"time":"2018-07-27T01:32:41.339000Z"}
{"type":"open","side":"buy","price":"789.01000000","order_id":"64649299-907c-43bb-9ecd-e4145a67d532","remaining_size":"12.39000000","product_id":"BCH-USD","sequence":4839272687,"time":"2018-07-27T01:32:41.339000Z"}
{"type":"done","side":"buy","order_id":"b2421161-f7ef-4e3c-90df-98475fead6d7","reason":"canceled","product_id":"BCH-USD","price":"791.24000000","remaining_size":"0.18739300","sequence":4839272688,"time":"2018-07-27T01:32:41.343000Z"}
{"type":"received","order_id":"0d7c39ce-d99c-491a-a4f9-bc123d7fc000","order_type":"limit","size":"0.90000000","price":"792.54000000","side":"buy","client_oid":"a2250c22-0d57-4188-97e4-63331d3969be","product_id":"BCH-USD","sequence":4839272689,"time":"2018-07-27T01:32:41.345000Z"}
{"type":"open","side":"buy","price":"792.54000000","order_id":"0d7c39ce-d99c-491a-a4f9-bc123d7fc000","remaining_size":"0.90000000","product_id":"BCH-USD","sequence":4839272690,"time":"2018-07-27T01:32:41.345000Z"}
{"type":"received","order_id":"eb0a5df0-ae2d-44e5-9d7f-7d02d8dc6318","order_type":"limit","size":"4.50000000","price":"795.68000000","side":"sell","client_oid":"26fe4553-aec0-4d4a-acd6-45ae928d9b3f","product_id":"BCH-USD","sequence":4839272691,"time":"2018-07-27T01:32:41.346000Z"}
{"type":"open","side":"sell","price":"795.68000000","order_id":"eb0a5df0-ae2d-44e5-9d7f-7d02d8dc6318","remaining_size":"4.50000000","product_id":"BCH-USD","sequence":4839272692,"time":"2018-07-27T01:32:41.346000Z"}
{"type":"received","order_id":"098c8abd-f88e-4529-9879-1d693534255c","order_type":"limit","size":"0.90000000","price":"795.07000000","side":"sell","client_oid":"1c44cc9a-8602-40a0-b691-54a94ec02b83","product_id":"BCH-USD","sequence":4839272693,"time":"2018-07-27T01:32:41.347000Z"}
{"type":"done","side":"sell","order_id":"51f427e9-e44e-4651-b2e0-5320f43de361","reason":"canceled","product_id":"LTC-USD","price":"83.34000000","remaining_size":"7.44874862","sequence":2423271923,"time":"2018-07-27T01:32:41.349000Z"}
{"type":"open","side":"sell","price":"795.07000000","order_id":"098c8abd-f88e-4529-9879-1d693534255c","remaining_size":"0.90000000","product_id":"BCH-USD","sequence":4839272694,"time":"2018-07-27T01:32:41.347000Z"}
{"type":"done","side":"sell","order_id":"eb0a5df0-ae2d-44e5-9d7f-7d02d8dc6318","reason":"canceled","product_id":"BCH-USD","price":"795.68000000","remaining_size":"4.50000000","sequence":4839272695,"time":"2018-07-27T01:32:41.349000Z"}
{"type":"done","side":"sell","order_id":"e2d494c1-170c-4933-91a2-1b0652f3fa18","reason":"canceled","product_id":"BCH-USD","price":"795.08000000","remaining_size":"0.90000000","sequence":4839272696,"time":"2018-07-27T01:32:41.351000Z"}
{"type":"done","side":"sell","order_id":"098c8abd-f88e-4529-9879-1d693534255c","reason":"canceled","product_id":"BCH-USD","price":"795.07000000","remaining_size":"0.90000000","sequence":4839272697,"time":"2018-07-27T01:32:41.352000Z"}
{"type":"done","side":"sell","order_id":"f0cb7c31-c500-4f4f-9df5-938a47f23f4c","reason":"canceled","product_id":"BCH-USD","price":"795.08000000","remaining_size":"1.90000000","sequence":4839272698,"time":"2018-07-27T01:32:41.355000Z"}
{"type":"received","order_id":"688ba5dc-44b2-4d21-9914-2451d7771188","order_type":"limit","size":"4.50000000","price":"795.67000000","side":"sell","client_oid":"97a767f3-8bca-4bee-8934-6ad14a76b2b4","product_id":"BCH-USD","sequence":4839272699,"time":"2018-07-27T01:32:41.356000Z"}
{"type":"open","side":"sell","price":"795.67000000","order_id":"688ba5dc-44b2-4d21-9914-2451d7771188","remaining_size":"4.50000000","product_id":"BCH-USD","sequence":4839272700,"time":"2018-07-27T01:32:41.356000Z"}
{"type":"received","order_id":"5f96ae3d-eddf-406a-9a15-62d0eab664dc","order_type":"limit","size":"4.50000000","price":"795.07000000","side":"sell","client_oid":"44f4f719-fc40-4c38-bc78-24322b1483c0","product_id":"BCH-USD","sequence":4839272701,"time":"2018-07-27T01:32:41.360000Z"}
{"type":"open","side":"sell","price":"795.07000000","order_id":"5f96ae3d-eddf-406a-9a15-62d0eab664dc","remaining_size":"4.50000000","product_id":"BCH-USD","sequence":4839272702,"time":"2018-07-27T01:32:41.360000Z"}
{"type":"received","order_id":"0c8d891f-7fd8-4424-bf15-600cfd957e4c","order_type":"limit","size":"0.18739300","price":"791.23000000","side":"buy","client_oid":"04aaacbe-e2cc-498a-b5aa-1f6b8918909b","product_id":"BCH-USD","sequence":4839272703,"time":"2018-07-27T01:32:41.360000Z"}
{"type":"open","side":"buy","price":"791.23000000","order_id":"0c8d891f-7fd8-4424-bf15-600cfd957e4c","remaining_size":"0.18739300","product_id":"BCH-USD","sequence":4839272704,"time":"2018-07-27T01:32:41.360000Z"}
{"type":"done","side":"sell","order_id":"688ba5dc-44b2-4d21-9914-2451d7771188","reason":"canceled","product_id":"BCH-USD","price":"795.67000000","remaining_size":"4.50000000","sequence":4839272705,"time":"2018-07-27T01:32:41.360000Z"}
{"type":"received","order_id":"b8810036-0040-4c5a-8254-229aa0128c37","order_type":"limit","size":"0.90000000","price":"795.08000000","side":"sell","client_oid":"18089596-177a-4349-a534-c11b5700adea","product_id":"BCH-USD","sequence":4839272706,"time":"2018-07-27T01:32:41.363000Z"}
{"type":"open","side":"sell","price":"795.08000000","order_id":"b8810036-0040-4c5a-8254-229aa0128c37","remaining_size":"0.90000000","product_id":"BCH-USD","sequence":4839272707,"time":"2018-07-27T01:32:41.363000Z"}
{"type":"received","order_id":"68a9845c-579e-4e38-b1f2-9955c50034e3","order_type":"limit","size":"7.44874862","price":"83.30000000","side":"sell","client_oid":"2c1d1120-170c-440f-8000-00f5a4f3addc","product_id":"LTC-USD","sequence":2423271924,"time":"2018-07-27T01:32:41.365000Z"}
{"type":"open","side":"sell","price":"83.30000000","order_id":"68a9845c-579e-4e38-b1f2-9955c50034e3","remaining_size":"7.44874862","product_id":"LTC-USD","sequence":2423271925,"time":"2018-07-27T01:32:41.365000Z"}
{"type":"done","side":"sell","order_id":"632bdb40-624e-4088-b4a0-5ff145e8120d","reason":"canceled","product_id":"BCH-USD","price":"795.67000000","remaining_size":"4.50000000","sequence":4839272708,"time":"2018-07-27T01:32:41.368000Z"}
{"type":"done","side":"sell","order_id":"7fd958ab-e68e-4aec-8df9-4ef21545d2c9","reason":"canceled","product_id":"LTC-USD","price":"83.38000000","remaining_size":"7.44874862","sequence":2423271926,"time":"2018-07-27T01:32:41.376000Z"}
{"type":"received","order_id":"a64e83b1-e121-40b6-b6ce-b36af444fe47","order_type":"limit","size":"1.81488800","price":"791.23000000","side":"buy","client_oid":"6dd9cb20-6bfb-4500-adbb-40467fdcf682","product_id":"BCH-USD","sequence":4839272709,"time":"2018-07-27T01:32:41.374000Z"}
{"type":"open","side":"buy","price":"791.23000000","order_id":"a64e83b1-e121-40b6-b6ce-b36af444fe47","remaining_size":"1.81488800","product_id":"BCH-USD","sequence":4839272710,"time":"2018-07-27T01:32:41.374000Z"}
{"type":"received","order_id":"65f93b4f-271d-4a8f-b401-7477ddd32ab4","order_type":"limit","size":"1.90000000","price":"795.07000000","side":"sell","client_oid":"fe2a4b26-a48a-49d7-b635-34f55f1e66f4","product_id":"BCH-USD","sequence":4839272711,"time":"2018-07-27T01:32:41.379000Z"}
{"type":"open","side":"sell","price":"795.07000000","order_id":"65f93b4f-271d-4a8f-b401-7477ddd32ab4","remaining_size":"1.90000000","product_id":"BCH-USD","sequence":4839272712,"time":"2018-07-27T01:32:41.379000Z"}
{"type":"received","order_id":"102be429-40d9-459e-b5f3-823ec2b33c62","order_type":"limit","size":"0.90000000","price":"795.07000000","side":"sell","client_oid":"715436f9-fab7-4b7e-9314-bd77022925c3","product_id":"BCH-USD","sequence":4839272713,"time":"2018-07-27T01:32:41.383000Z"}
{"type":"open","side":"sell","price":"795.07000000","order_id":"102be429-40d9-459e-b5f3-823ec2b33c62","remaining_size":"0.90000000","product_id":"BCH-USD","sequence":4839272714,"time":"2018-07-27T01:32:41.383000Z"}
{"type":"done","side":"sell","order_id":"65f93b4f-271d-4a8f-b401-7477ddd32ab4","reason":"canceled","product_id":"BCH-USD","price":"795.07000000","remaining_size":"1.90000000","sequence":4839272715,"time":"2018-07-27T01:32:41.383000Z"}
{"type":"received","order_id":"59f01d98-e8ae-4acb-a895-6bb6bbe4efd4","order_type":"limit","size":"4.50000000","price":"795.53000000","side":"sell","client_oid":"5bd7b142-2add-4e24-9db7-0ed4f833f90e","product_id":"BCH-USD","sequence":4839272716,"time":"2018-07-27T01:32:41.384000Z"}
{"type":"open","side":"sell","price":"795.53000000","order_id":"59f01d98-e8ae-4acb-a895-6bb6bbe4efd4","remaining_size":"4.50000000","product_id":"BCH-USD","sequence":4839272717,"time":"2018-07-27T01:32:41.384000Z"}
{"type":"done","side":"sell","order_id":"102be429-40d9-459e-b5f3-823ec2b33c62","reason":"canceled","product_id":"BCH-USD","price":"795.07000000","remaining_size":"0.90000000","sequence":4839272718,"time":"2018-07-27T01:32:41.387000Z"}
{"type":"done","side":"buy","order_id":"0c8d891f-7fd8-4424-bf15-600cfd957e4c","reason":"canceled","product_id":"BCH-USD","price":"791.23000000","remaining_size":"0.18739300","sequence":4839272719,"time":"2018-07-27T01:32:41.388000Z"}
{"type":"done","side":"sell","order_id":"5f96ae3d-eddf-406a-9a15-62d0eab664dc","reason":"canceled","product_id":"BCH-USD","price":"795.07000000","remaining_size":"4.50000000","sequence":4839272720,"time":"2018-07-27T01:32:41.388000Z"}
{"type":"received","order_id":"d91a9188-b9f6-40ea-a424-f5f61ea39720","order_type":"limit","size":"1.90000000","price":"795.06000000","side":"sell","client_oid":"378ddcc0-d7f7-4310-b60b-bd6fd37bd733","product_id":"BCH-USD","sequence":4839272721,"time":"2018-07-27T01:32:41.390000Z"}
{"type":"open","side":"sell","price":"795.06000000","order_id":"d91a9188-b9f6-40ea-a424-f5f61ea39720","remaining_size":"1.90000000","product_id":"BCH-USD","sequence":4839272722,"time":"2018-07-27T01:32:41.390000Z"}
{"type":"received","order_id":"02e8730f-c301-44af-89ae-86b14ba79665","order_type":"limit","size":"7.44874862","price":"83.34000000","side":"sell","client_oid":"40df163e-53e8-4b67-8000-005dcc97d52b","product_id":"LTC-USD","sequence":2423271927,"time":"2018-07-27T01:32:41.393000Z"}
{"type":"open","side":"sell","price":"83.34000000","order_id":"02e8730f-c301-44af-89ae-86b14ba79665","remaining_size":"7.44874862","product_id":"LTC-USD","sequence":2423271928,"time":"2018-07-27T01:32:41.393000Z"}
{"type":"received","order_id":"e1ebf547-b39e-41eb-ac77-3004b15ce3da","order_type":"limit","size":"0.90000000","price":"795.08000000","side":"sell","client_oid":"38fecf40-6237-44ce-84f3-a5435e049221","product_id":"BCH-USD","sequence":4839272723,"time":"2018-07-27T01:32:41.394000Z"}
{"type":"open","side":"sell","price":"795.08000000","order_id":"e1ebf547-b39e-41eb-ac77-3004b15ce3da","remaining_size":"0.90000000","product_id":"BCH-USD","sequence":4839272724,"time":"2018-07-27T01:32:41.394000Z"}
{"type":"received","order_id":"6ec79b76-27f2-4652-8924-0269ef094b46","order_type":"limit","size":"4.50000000","price":"795.06000000","side":"sell","client_oid":"5fffa8af-8170-4e32-85ec-97905cd7d6f6","product_id":"BCH-USD","sequence":4839272725,"time":"2018-07-27T01:32:41.395000Z"}
{"type":"open","side":"sell","price":"795.06000000","order_id":"6ec79b76-27f2-4652-8924-0269ef094b46","remaining_size":"4.50000000","product_id":"BCH-USD","sequence":4839272726,"time":"2018-07-27T01:32:41.395000Z"}
{"type":"done","side":"buy","order_id":"a64e83b1-e121-40b6-b6ce-b36af444fe47","reason":"canceled","product_id":"BCH-USD","price":"791.23000000","remaining_size":"1.81488800","sequence":4839272727,"time":"2018-07-27T01:32:41.396000Z"}
{"type":"done","side":"sell","order_id":"e1ebf547-b39e-41eb-ac77-3004b15ce3da","reason":"canceled","product_id":"BCH-USD","price":"795.08000000","remaining_size":"0.90000000","sequence":4839272728,"time":"2018-07-27T01:32:41.398000Z"}
{"type":"done","side":"sell","order_id":"b8810036-0040-4c5a-8254-229aa0128c37","reason":"canceled","product_id":"BCH-USD","price":"795.08000000","remaining_size":"0.90000000","sequence":4839272729,"time":"2018-07-27T01:32:41.399000Z"}
{"type":"received","order_id":"26eabdf5-516b-4e33-9b67-903f54a61b38","order_type":"limit","size":"1.81488800","price":"791.24000000","side":"buy","client_oid":"dd57bbea-7111-4f2e-b04c-4ba548a519bc","product_id":"BCH-USD","sequence":4839272730,"time":"2018-07-27T01:32:41.401000Z"}
{"type":"open","side":"buy","price":"791.24000000","order_id":"26eabdf5-516b-4e33-9b67-903f54a61b38","remaining_size":"1.81488800","product_id":"BCH-USD","sequence":4839272731,"time":"2018-07-27T01:32:41.401000Z"}
{"type":"done","side":"sell","order_id":"68a9845c-579e-4e38-b1f2-9955c50034e3","reason":"canceled","product_id":"LTC-USD","price":"83.30000000","remaining_size":"7.44874862","sequence":2423271929,"time":"2018-07-27T01:32:41.406000Z"}
{"type":"received","order_id":"207b151e-6f54-40e5-adc4-90d996b9dc3b","order_type":"limit","size":"0.18739300","price":"791.24000000","side":"buy","client_oid":"9f9ddb6c-a97d-4c4b-b619-43fd345d934c","product_id":"BCH-USD","sequence":4839272732,"time":"2018-07-27T01:32:41.406000Z"}
{"type":"open","side":"buy","price":"791.24000000","order_id":"207b151e-6f54-40e5-adc4-90d996b9dc3b","remaining_size":"0.18739300","product_id":"BCH-USD","sequence":4839272733,"time":"2018-07-27T01:32:41.406000Z"}
{"type":"received","order_id":"a04355ad-d964-4519-aca8-838a416e64b0","order_type":"limit","size":"0.90000000","price":"795.06000000","side":"sell","client_oid":"957b14c5-0f0c-4df2-9791-ef9f189ae0dc","product_id":"BCH-USD","sequence":4839272734,"time":"2018-07-27T01:32:41.411000Z"}
{"type":"open","side":"sell","price":"795.06000000","order_id":"a04355ad-d964-4519-aca8-838a416e64b0","remaining_size":"0.90000000","product_id":"BCH-USD","sequence":4839272735,"time":"2018-07-27T01:32:41.411000Z"}
{"type":"done","side":"buy","order_id":"26eabdf5-516b-4e33-9b67-903f54a61b38","reason":"canceled","product_id":"BCH-USD","price":"791.24000000","remaining_size":"1.81488800","sequence":4839272736,"time":"2018-07-27T01:32:41.412000Z"}
{"type":"done","side":"buy","order_id":"6295274f-850a-4231-b31b-de2d556af807","reason":"canceled","product_id":"LTC-USD","price":"82.98000000","remaining_size":"20.00000000","sequence":2423271930,"time":"2018-07-27T01:32:41.415000Z"}
{"type":"done","side":"sell","order_id":"a04355ad-d964-4519-aca8-838a416e64b0","reason":"canceled","product_id":"BCH-USD","price":"795.06000000","remaining_size":"0.90000000","sequence":4839272737,"time":"2018-07-27T01:32:41.414000Z"}
{"type":"done","side":"sell","order_id":"d91a9188-b9f6-40ea-a424-f5f61ea39720","reason":"canceled","product_id":"BCH-USD","price":"795.06000000","remaining_size":"1.90000000","sequence":4839272738,"time":"2018-07-27T01:32:41.416000Z"}
{"type":"done","side":"sell","order_id":"6ec79b76-27f2-4652-8924-0269ef094b46","reason":"canceled","product_id":"BCH-USD","price":"795.06000000","remaining_size":"4.50000000","sequence":4839272739,"time":"2018-07-27T01:32:41.417000Z"}
{"type":"received","order_id":"4e29d72f-d623-432c-ac74-d9bbe8573830","order_type":"limit","size":"27.67223226","price":"790.14000000","side":"buy","client_oid":"9cfc8ef6-9124-11e8-8caa-000e1eec81f0","product_id":"BCH-USD","sequence":4839272740,"time":"2018-07-27T01:32:41.418000Z"}
{"type":"open","side":"buy","price":"790.14000000","order_id":"4e29d72f-d623-432c-ac74-d9bbe8573830","remaining_size":"27.67223226","product_id":"BCH-USD","sequence":4839272741,"time":"2018-07-27T01:32:41.418000Z"}
{"type":"received","order_id":"438dbbf1-5fa4-4328-b627-17af73c08888","order_type":"limit","size":"0.90000000","price":"795.06000000","side":"sell","client_oid":"376abd66-0cb2-446a-9c99-fd1649d2d7e5","product_id":"BCH-USD","sequence":4839272742,"time":"2018-07-27T01:32:41.420000Z"}
{"type":"open","side":"sell","price":"795.06000000","order_id":"438dbbf1-5fa4-4328-b627-17af73c08888","remaining_size":"0.90000000","product_id":"BCH-USD","sequence":4839272743,"time":"2018-07-27T01:32:41.420000Z"}
{"type":"received","order_id":"ba5b61d0-32f9-4605-b838-df6cf9b408d9","order_type":"limit","size":"1.81488800","price":"791.25000000","side":"buy","client_oid":"0d8cdf3d-72ec-4a31-8a44-422b2a738763","product_id":"BCH-USD","sequence":4839272744,"time":"2018-07-27T01:32:41.421000Z"}
{"type":"open","side":"buy","price":"791.25000000","order_id":"ba5b61d0-32f9-4605-b838-df6cf9b408d9","remaining_size":"1.81488800","product_id":"BCH-USD","sequence":4839272745,"time":"2018-07-27T01:32:41.421000Z"}
{"type":"received","order_id":"fe7a0121-03f8-4daa-9169-d1344467faa0","order_type":"limit","size":"7.44874862","price":"83.38000000","side":"sell","client_oid":"0c223f9c-353d-4f41-8000-0f09742645a0","product_id":"LTC-USD","sequence":2423271931,"time":"2018-07-27T01:32:41.426000Z"}
{"type":"done","side":"sell","order_id":"438dbbf1-5fa4-4328-b627-17af73c08888","reason":"canceled","product_id":"BCH-USD","price":"795.06000000","remaining_size":"0.90000000","sequence":4839272746,"time":"2018-07-27T01:32:41.424000Z"}
{"type":"open","side":"sell","price":"83.38000000","order_id":"fe7a0121-03f8-4daa-9169-d1344467faa0","remaining_size":"7.44874862","product_id":"LTC-USD","sequence":2423271932,"time":"2018-07-27T01:32:41.426000Z"}
{"type":"done","side":"buy","order_id":"ba5b61d0-32f9-4605-b838-df6cf9b408d9","reason":"canceled","product_id":"BCH-USD","price":"791.25000000","remaining_size":"1.81488800","sequence":4839272747,"time":"2018-07-27T01:32:41.425000Z"}
{"type":"received","order_id":"fb18bdf9-3877-474e-9699-46d1c1d4bc48","order_type":"limit","size":"20.00000000","price":"82.99000000","side":"buy","client_oid":"7fa61e9a-3986-4809-a0fb-35edc0ec6b6f","product_id":"LTC-USD","sequence":2423271933,"time":"2018-07-27T01:32:41.428000Z"}
{"type":"open","side":"buy","price":"82.99000000","order_id":"fb18bdf9-3877-474e-9699-46d1c1d4bc48","remaining_size":"20.00000000","product_id":"LTC-USD","sequence":2423271934,"time":"2018-07-27T01:32:41.428000Z"}
{"type":"done","side":"sell","order_id":"59f01d98-e8ae-4acb-a895-6bb6bbe4efd4","reason":"canceled","product_id":"BCH-USD","price":"795.53000000","remaining_size":"4.50000000","sequence":4839272748,"time":"2018-07-27T01:32:41.428000Z"}
{"type":"received","order_id":"527af053-bc58-473d-82ce-d4eac0e6b620","order_type":"limit","size":"0.90000000","price":"795.05000000","side":"sell","client_oid":"11fa2885-9716-43a1-8a6d-2e1890de11db","product_id":"BCH-USD","sequence":4839272749,"time":"2018-07-27T01:32:41.429000Z"}
{"type":"open","side":"sell","price":"795.05000000","order_id":"527af053-bc58-473d-82ce-d4eac0e6b620","remaining_size":"0.90000000","product_id":"BCH-USD","sequence":4839272750,"time":"2018-07-27T01:32:41.429000Z"}
{"type":"done","side":"buy","order_id":"207b151e-6f54-40e5-adc4-90d996b9dc3b","reason":"canceled","product_id":"BCH-USD","price":"791.24000000","remaining_size":"0.18739300","sequence":4839272751,"time":"2018-07-27T01:32:41.431000Z"}
{"type":"done","side":"sell","order_id":"527af053-bc58-473d-82ce-d4eac0e6b620","reason":"canceled","product_id":"BCH-USD","price":"795.05000000","remaining_size":"0.90000000","sequence":4839272752,"time":"2018-07-27T01:32:41.433000Z"}
{"type":"received","order_id":"61b1f301-fcca-4879-9730-f42b21a1e420","order_type":"limit","size":"1.90000000","price":"795.05000000","side":"sell","client_oid":"ed3b6bb7-da5b-4712-9f63-a50df79ba020","product_id":"BCH-USD","sequence":4839272753,"time":"2018-07-27T01:32:41.434000Z"}
{"type":"open","side":"sell","price":"795.05000000","order_id":"61b1f301-fcca-4879-9730-f42b21a1e420","remaining_size":"1.90000000","product_id":"BCH-USD","sequence":4839272754,"time":"2018-07-27T01:32:41.434000Z"}
{"type":"received","order_id":"d92351e5-d5e9-4380-bcc2-06221043b6e8","order_type":"limit","size":"1.81488800","price":"791.23000000","side":"buy","client_oid":"e62c8dc1-a78d-495c-a774-99f7ff63effb","product_id":"BCH-USD","sequence":4839272755,"time":"2018-07-27T01:32:41.437000Z"}
{"type":"open","side":"buy","price":"791.23000000","order_id":"d92351e5-d5e9-4380-bcc2-06221043b6e8","remaining_size":"1.81488800","product_id":"BCH-USD","sequence":4839272756,"time":"2018-07-27T01:32:41.437000Z"}
{"type":"done","side":"sell","order_id":"61b1f301-fcca-4879-9730-f42b21a1e420","reason":"canceled","product_id":"BCH-USD","price":"795.05000000","remaining_size":"1.90000000","sequence":4839272757,"time":"2018-07-27T01:32:41.439000Z"}
{"type":"done","side":"buy","order_id":"fb18bdf9-3877-474e-9699-46d1c1d4bc48","reason":"canceled","product_id":"LTC-USD","price":"82.99000000","remaining_size":"20.00000000","sequence":2423271935,"time":"2018-07-27T01:32:41.441000Z"}
{"type":"received","order_id":"bf77655c-11dd-4ff2-9278-994d616e23b3","order_type":"limit","size":"0.18739300","price":"791.23000000","side":"buy","client_oid":"9abc1db2-a0f4-4dc7-a1c7-89fdfbbd3974","product_id":"BCH-USD","sequence":4839272758,"time":"2018-07-27T01:32:41.442000Z"}
{"type":"open","side":"buy","price":"791.23000000","order_id":"bf77655c-11dd-4ff2-9278-994d616e23b3","remaining_size":"0.18739300","product_id":"BCH-USD","sequence":4839272759,"time":"2018-07-27T01:32:41.442000Z"}
{"type":"received","order_id":"8052e7c9-b108-46dd-93e5-2f61fd7eadb0","order_type":"limit","size":"1.60461000","price":"795.53000000","side":"sell","client_oid":"f7ec64d1-d13d-4746-b846-08b7d2440812","product_id":"BCH-USD","sequence":4839272760,"time":"2018-07-27T01:32:41.444000Z"}
{"type":"open","side":"sell","price":"795.53000000","order_id":"8052e7c9-b108-46dd-93e5-2f61fd7eadb0","remaining_size":"1.60461000","product_id":"BCH-USD","sequence":4839272761,"time":"2018-07-27T01:32:41.444000Z"}
{"type":"done","side":"sell","order_id":"02e8730f-c301-44af-89ae-86b14ba79665","reason":"canceled","product_id":"LTC-USD","price":"83.34000000","remaining_size":"7.44874862","sequence":2423271936,"time":"2018-07-27T01:32:41.447000Z"}
{"type":"received","order_id":"f90002a5-9291-4af3-b893-951b90d54639","order_type":"limit","size":"4.50000000","price":"795.67000000","side":"sell","client_oid":"ca2b09d4-a0f1-47dd-947b-f8ab3523af0a","product_id":"BCH-USD","sequence":4839272762,"time":"2018-07-27T01:32:41.446000Z"}
{"type":"received","order_id":"25c8b931-ede4-4f82-8426-9aebff6f9a01","order_type":"limit","size":"20.00000000","price":"82.98000000","side":"buy","client_oid":"59fb3317-3223-49ee-9253-387d4b062267","product_id":"LTC-USD","sequence":2423271937,"time":"2018-07-27T01:32:41.448000Z"}
{"type":"open","side":"sell","price":"795.67000000","order_id":"f90002a5-9291-4af3-b893-951b90d54639","remaining_size":"4.50000000","product_id":"BCH-USD","sequence":4839272763,"time":"2018-07-27T01:32:41.446000Z"}
{"type":"done","side":"sell","order_id":"f90002a5-9291-4af3-b893-951b90d54639","reason":"canceled","product_id":"BCH-USD","price":"795.67000000","remaining_size":"4.50000000","sequence":4839272764,"time":"2018-07-27T01:32:41.450000Z"}
{"type":"open","side":"buy","price":"82.98000000","order_id":"25c8b931-ede4-4f82-8426-9aebff6f9a01","remaining_size":"20.00000000","product_id":"LTC-USD","sequence":2423271938,"time":"2018-07-27T01:32:41.448000Z"}
{"type":"received","order_id":"2d0f7d96-3752-42f6-8e2d-fcb2cd359c2b","order_type":"limit","size":"4.50000000","price":"795.68000000","side":"sell","client_oid":"4b2220e0-c194-46db-8d63-e1f10da18e43","product_id":"BCH-USD","sequence":4839272765,"time":"2018-07-27T01:32:41.457000Z"}
{"type":"open","side":"sell","price":"795.68000000","order_id":"2d0f7d96-3752-42f6-8e2d-fcb2cd359c2b","remaining_size":"4.50000000","product_id":"BCH-USD","sequence":4839272766,"time":"2018-07-27T01:32:41.457000Z"}
{"type":"received","order_id":"08aec990-83cf-47e9-8d44-5e75d6d610be","order_type":"limit","size":"0.90000000","price":"795.08000000","side":"sell","client_oid":"263ff64b-9a14-4ffb-ad4b-41d376d776b6","product_id":"BCH-USD","sequence":4839272767,"time":"2018-07-27T01:32:41.459000Z"}
{"type":"open","side":"sell","price":"795.08000000","order_id":"08aec990-83cf-47e9-8d44-5e75d6d610be","remaining_size":"0.90000000","product_id":"BCH-USD","sequence":4839272768,"time":"2018-07-27T01:32:41.459000Z"}
{"type":"received","order_id":"ca9e17d4-85f3-4547-8be4-64ed2d687f62","order_type":"limit","size":"0.90000000","price":"795.05000000","side":"sell","client_oid":"ea8dd4e4-2366-4e74-ac12-10a2bf55a87f","product_id":"BCH-USD","sequence":4839272769,"time":"2018-07-27T01:32:41.461000Z"}
{"type":"open","side":"sell","price":"795.05000000","order_id":"ca9e17d4-85f3-4547-8be4-64ed2d687f62","remaining_size":"0.90000000","product_id":"BCH-USD","sequence":4839272770,"time":"2018-07-27T01:32:41.461000Z"}
{"type":"received","order_id":"a019db7f-b17e-496c-8cd3-a41382c14e23","order_type":"limit","size":"7.44874862","price":"83.30000000","side":"sell","client_oid":"2d21d7d7-75b3-47b8-8000-004ff362366f","product_id":"LTC-USD","sequence":2423271939,"time":"2018-07-27T01:32:41.465000Z"}
{"type":"open","side":"sell","price":"83.30000000","order_id":"a019db7f-b17e-496c-8cd3-a41382c14e23","remaining_size":"7.44874862","product_id":"LTC-USD","sequence":2423271940,"time":"2018-07-27T01:32:41.465000Z"}
{"type":"done","side":"sell","order_id":"ca9e17d4-85f3-4547-8be4-64ed2d687f62","reason":"canceled","product_id":"BCH-USD","price":"795.05000000","remaining_size":"0.90000000","sequence":4839272771,"time":"2018-07-27T01:32:41.466000Z"}
{"type":"done","side":"buy","order_id":"25c8b931-ede4-4f82-8426-9aebff6f9a01","reason":"canceled","product_id":"LTC-USD","price":"82.98000000","remaining_size":"20.00000000","sequence":2423271941,"time":"2018-07-27T01:32:41.470000Z"}
{"type":"received","order_id":"05346336-90ef-49a5-9544-5971aad89ced","order_type":"limit","size":"4.50000000","price":"795.05000000","side":"sell","client_oid":"59298da4-a4cd-4f98-be9e-e2cf3d1fda81","product_id":"BCH-USD","sequence":4839272772,"time":"2018-07-27T01:32:41.470000Z"}
{"type":"open","side":"sell","price":"795.05000000","order_id":"05346336-90ef-49a5-9544-5971aad89ced","remaining_size":"4.50000000","product_id":"BCH-USD","sequence":4839272773,"time":"2018-07-27T01:32:41.470000Z"}
{"type":"received","order_id":"81efd4d7-9d7c-4db6-aa28-cbcba4d19d26","order_type":"limit","size":"1.90000000","price":"795.08000000","side":"sell","client_oid":"350e8e82-8336-4725-bf02-060a57f97f0c","product_id":"BCH-USD","sequence":4839272774,"time":"2018-07-27T01:32:41.472000Z"}
{"type":"open","side":"sell","price":"795.08000000","order_id":"81efd4d7-9d7c-4db6-aa28-cbcba4d19d26","remaining_size":"1.90000000","product_id":"BCH-USD","sequence":4839272775,"time":"2018-07-27T01:32:41.472000Z"}
{"type":"done","side":"sell","order_id":"05346336-90ef-49a5-9544-5971aad89ced","reason":"canceled","product_id":"BCH-USD","price":"795.05000000","remaining_size":"4.50000000","sequence":4839272776,"time":"2018-07-27T01:32:41.474000Z"}
{"type":"done","side":"buy","order_id":"bf77655c-11dd-4ff2-9278-994d616e23b3","reason":"canceled","product_id":"BCH-USD","price":"791.23000000","remaining_size":"0.18739300","sequence":4839272777,"time":"2018-07-27T01:32:41.476000Z"}
{"type":"received","order_id":"0688f2b5-21c1-46eb-805d-7f6434d724e4","order_type":"limit","size":"20.00000000","price":"82.99000000","side":"buy","client_oid":"5dd1907f-8520-474a-8967-09b68656b570","product_id":"LTC-USD","sequence":2423271942,"time":"2018-07-27T01:32:41.479000Z"}
{"type":"open","side":"buy","price":"82.99000000","order_id":"0688f2b5-21c1-46eb-805d-7f6434d724e4","remaining_size":"20.00000000","product_id":"LTC-USD","sequence":2423271943,"time":"2018-07-27T01:32:41.479000Z"}
{"type":"received","order_id":"10139dac-4234-4c9f-bf64-2d1f1b3f6ebd","order_type":"limit","size":"0.90000000","price":"795.08000000","side":"sell","client_oid":"7f6dfd1a-5fef-4e3f-812a-b13317a3df1e","product_id":"BCH-USD","sequence":4839272778,"time":"2018-07-27T01:32:41.478000Z"}
{"type":"open","side":"sell","price":"795.08000000","order_id":"10139dac-4234-4c9f-bf64-2d1f1b3f6ebd","remaining_size":"0.90000000","product_id":"BCH-USD","sequence":4839272779,"time":"2018-07-27T01:32:41.478000Z"}
{"type":"done","side":"sell","order_id":"fe7a0121-03f8-4daa-9169-d1344467faa0","reason":"canceled","product_id":"LTC-USD","price":"83.38000000","remaining_size":"7.44874862","sequence":2423271944,"time":"2018-07-27T01:32:41.485000Z"}
{"type":"received","order_id":"1442dd41-0058-4bf8-a3bf-9301f67fd161","order_type":"limit","size":"0.18739300","price":"791.24000000","side":"buy","client_oid":"0a0ecad0-870f-4cab-872c-2b701c255b71","product_id":"BCH-USD","sequence":4839272780,"time":"2018-07-27T01:32:41.488000Z"}
{"type":"open","side":"buy","price":"791.24000000","order_id":"1442dd41-0058-4bf8-a3bf-9301f67fd161","remaining_size":"0.18739300","product_id":"BCH-USD","sequence":4839272781,"time":"2018-07-27T01:32:41.488000Z"}
{"type":"done","side":"sell","order_id":"81efd4d7-9d7c-4db6-aa28-cbcba4d19d26","reason":"canceled","product_id":"BCH-USD","price":"795.08000000","remaining_size":"1.90000000","sequence":4839272782,"time":"2018-07-27T01:32:41.492000Z"}
{"type":"done","side":"buy","order_id":"d92351e5-d5e9-4380-bcc2-06221043b6e8","reason":"canceled","product_id":"BCH-USD","price":"791.23000000","remaining_size":"1.81488800","sequence":4839272783,"time":"2018-07-27T01:32:41.493000Z"}
{"type":"received","order_id":"9cab5375-ccf0-40f7-84f7-440b37b49d87","order_type":"limit","size":"4.50000000","price":"795.08000000","side":"sell","client_oid":"24e06dbd-a0cb-4e4e-9958-ae293f1e8f83","product_id":"BCH-USD","sequence":4839272784,"time":"2018-07-27T01:32:41.496000Z"}
{"type":"open","side":"sell","price":"795.08000000","order_id":"9cab5375-ccf0-40f7-84f7-440b37b49d87","remaining_size":"4.50000000","product_id":"BCH-USD","sequence":4839272785,"time":"2018-07-27T01:32:41.496000Z"}
{"type":"done","side":"sell","order_id":"2d0f7d96-3752-42f6-8e2d-fcb2cd359c2b","reason":"canceled","product_id":"BCH-USD","price":"795.68000000","remaining_size":"4.50000000","sequence":4839272786,"time":"2018-07-27T01:32:41.498000Z"}
{"type":"done","side":"buy","order_id":"0688f2b5-21c1-46eb-805d-7f6434d724e4","reason":"canceled","product_id":"LTC-USD","price":"82.99000000","remaining_size":"20.00000000","sequence":2423271945,"time":"2018-07-27T01:32:41.502000Z"}
{"type":"received","order_id":"38338406-b320-45d5-bad4-3ae64e0a54cd","order_type":"limit","size":"1.81488800","price":"791.24000000","side":"buy","client_oid":"c9fc9004-de3f-46f2-b17e-f8f457f881a6","product_id":"BCH-USD","sequence":4839272787,"time":"2018-07-27T01:32:41.500000Z"}
{"type":"open","side":"buy","price":"791.24000000","order_id":"38338406-b320-45d5-bad4-3ae64e0a54cd","remaining_size":"1.81488800","product_id":"BCH-USD","sequence":4839272788,"time":"2018-07-27T01:32:41.500000Z"}
{"type":"received","order_id":"e32a4c19-eb15-4559-9149-4648b92da134","order_type":"limit","size":"8.29703000","price":"464.52000000","side":"sell","client_oid":"18bb7cf1-d730-4eb5-87ac-4bbb7d8ad8ef","product_id":"ETH-USD","sequence":4469354819,"time":"2018-07-27T01:32:41.502000Z"}
{"type":"received","order_id":"2627cefc-4c09-4faa-8bf9-b0ec8ed6a2bd","order_type":"limit","size":"7.44874862","price":"83.34000000","side":"sell","client_oid":"eb532e03-ff5f-4aa5-8000-0099010f571c","product_id":"LTC-USD","sequence":2423271946,"time":"2018-07-27T01:32:41.504000Z"}
{"type":"open","side":"sell","price":"464.52000000","order_id":"e32a4c19-eb15-4559-9149-4648b92da134","remaining_size":"8.29703000","product_id":"ETH-USD","sequence":4469354820,"time":"2018-07-27T01:32:41.502000Z"}
{"type":"open","side":"sell","price":"83.34000000","order_id":"2627cefc-4c09-4faa-8bf9-b0ec8ed6a2bd","remaining_size":"7.44874862","product_id":"LTC-USD","sequence":2423271947,"time":"2018-07-27T01:32:41.504000Z"}
{"type":"done","side":"buy","order_id":"1442dd41-0058-4bf8-a3bf-9301f67fd161","reason":"canceled","product_id":"BCH-USD","price":"791.24000000","remaining_size":"0.18739300","sequence":4839272789,"time":"2018-07-27T01:32:41.503000Z"}
{"type":"received","order_id":"91fd114d-31d7-493b-8e73-ec8af6d19e8e","order_type":"limit","size":"20.00000000","price":"82.98000000","side":"buy","client_oid":"28d432b7-2a30-4ac0-9784-7b8964f145e3","product_id":"LTC-USD","sequence":2423271948,"time":"2018-07-27T01:32:41.512000Z"}
{"type":"open","side":"buy","price":"82.98000000","order_id":"91fd114d-31d7-493b-8e73-ec8af6d19e8e","remaining_size":"20.00000000","product_id":"LTC-USD","sequence":2423271949,"time":"2018-07-27T01:32:41.512000Z"}
{"type":"received","order_id":"2a4a1b4f-df04-40f9-9e35-2e057a8c2b91","order_type":"limit","size":"4.50000000","price":"795.67000000","side":"sell","client_oid":"c643b263-ecd5-48ab-b4b9-2fde4a75ce2c","product_id":"BCH-USD","sequence":4839272790,"time":"2018-07-27T01:32:41.512000Z"}
{"type":"done","side":"sell","order_id":"a019db7f-b17e-496c-8cd3-a41382c14e23","reason":"canceled","product_id":"LTC-USD","price":"83.30000000","remaining_size":"7.44874862","sequence":2423271950,"time":"2018-07-27T01:32:41.515000Z"}
{"type":"open","side":"sell","price":"795.67000000","order_id":"2a4a1b4f-df04-40f9-9e35-2e057a8c2b91","remaining_size":"4.50000000","product_id":"BCH-USD","sequence":4839272791,"time":"2018-07-27T01:32:41.512000Z"}
{"type":"received","order_id":"2d1a39c4-537e-4d52-a6cb-5e522d15fca5","order_type":"limit","size":"1.90000000","price":"795.07000000","side":"sell","client_oid":"dc084700-365a-48c7-a5d6-1995cc8d4085","product_id":"BCH-USD","sequence":4839272792,"time":"2018-07-27T01:32:41.516000Z"}
{"type":"open","side":"sell","price":"795.07000000","order_id":"2d1a39c4-537e-4d52-a6cb-5e522d15fca5","remaining_size":"1.90000000","product_id":"BCH-USD","sequence":4839272793,"time":"2018-07-27T01:32:41.516000Z"}
{"type":"received","order_id":"f22f4d40-4641-47cc-bbbd-841988b841dc","order_type":"limit","size":"7.44874862","price":"83.38000000","side":"sell","client_oid":"fb92390d-fb4e-4382-8000-0e01a6f19c90","product_id":"LTC-USD","sequence":2423271951,"time":"2018-07-27T01:32:41.522000Z"}
{"type":"open","side":"sell","price":"83.38000000","order_id":"f22f4d40-4641-47cc-bbbd-841988b841dc","remaining_size":"7.44874862","product_id":"LTC-USD","sequence":2423271952,"time":"2018-07-27T01:32:41.522000Z"}
{"type":"done","side":"sell","order_id":"10139dac-4234-4c9f-bf64-2d1f1b3f6ebd","reason":"canceled","product_id":"BCH-USD","price":"795.08000000","remaining_size":"0.90000000","sequence":4839272794,"time":"2018-07-27T01:32:41.521000Z"}
{"type":"received","order_id":"a84afa30-7cb7-4887-9971-e0510d1881e6","order_type":"limit","size":"0.18739300","price":"791.23000000","side":"buy","client_oid":"96a06957-26be-4655-8a63-a2e2edef8871","product_id":"BCH-USD","sequence":4839272795,"time":"2018-07-27T01:32:41.524000Z"}
{"type":"open","side":"buy","price":"791.23000000","order_id":"a84afa30-7cb7-4887-9971-e0510d1881e6","remaining_size":"0.18739300","product_id":"BCH-USD","sequence":4839272796,"time":"2018-07-27T01:32:41.524000Z"}
{"type":"done","side":"sell","order_id":"9cab5375-ccf0-40f7-84f7-440b37b49d87","reason":"canceled","product_id":"BCH-USD","price":"795.08000000","remaining_size":"4.50000000","sequence":4839272797,"time":"2018-07-27T01:32:41.524000Z"}
{"type":"done","side":"buy","order_id":"a84afa30-7cb7-4887-9971-e0510d1881e6","reason":"canceled","product_id":"BCH-USD","price":"791.23000000","remaining_size":"0.18739300","sequence":4839272798,"time":"2018-07-27T01:32:41.527000Z"}
{"type":"done","side":"buy","order_id":"91fd114d-31d7-493b-8e73-ec8af6d19e8e","reason":"canceled","product_id":"LTC-USD","price":"82.98000000","remaining_size":"20.00000000","sequence":2423271953,"time":"2018-07-27T01:32:41.532000Z"}
{"type":"received","order_id":"8f2f2e3b-7028-4113-abc2-70f92c7aa721","order_type":"limit","size":"0.90000000","price":"795.07000000","side":"sell","client_oid":"3b9918c8-ab9b-4873-8dad-75e351dbb286","product_id":"BCH-USD","sequence":4839272799,"time":"2018-07-27T01:32:41.530000Z"}
{"type":"open","side":"sell","price":"795.07000000","order_id":"8f2f2e3b-7028-4113-abc2-70f92c7aa721","remaining_size":"0.90000000","product_id":"BCH-USD","sequence":4839272800,"time":"2018-07-27T01:32:41.530000Z"}
{"type":"received","order_id":"f40b316e-ce89-43d0-829e-ce662362e213","order_type":"limit","size":"4.50000000","price":"795.07000000","side":"sell","client_oid":"d1d6061f-08da-4f17-839b-21d8f7019138","product_id":"BCH-USD","sequence":4839272801,"time":"2018-07-27T01:32:41.531000Z"}
{"type":"open","side":"sell","price":"795.07000000","order_id":"f40b316e-ce89-43d0-829e-ce662362e213","remaining_size":"4.50000000","product_id":"BCH-USD","sequence":4839272802,"time":"2018-07-27T01:32:41.531000Z"}
{"type":"done","side":"buy","order_id":"38338406-b320-45d5-bad4-3ae64e0a54cd","reason":"canceled","product_id":"BCH-USD","price":"791.24000000","remaining_size":"1.81488800","sequence":4839272803,"time":"2018-07-27T01:32:41.533000Z"}
{"type":"done","side":"sell","order_id":"08aec990-83cf-47e9-8d44-5e75d6d610be","reason":"canceled","product_id":"BCH-USD","price":"795.08000000","remaining_size":"0.90000000","sequence":4839272804,"time":"2018-07-27T01:32:41.533000Z"}
{"type":"done","side":"sell","order_id":"2a4a1b4f-df04-40f9-9e35-2e057a8c2b91","reason":"canceled","product_id":"BCH-USD","price":"795.67000000","remaining_size":"4.50000000","sequence":4839272805,"time":"2018-07-27T01:32:41.535000Z"}
{"type":"received","order_id":"c8a96ea0-8d76-4584-bded-db6fc030fc55","order_type":"limit","size":"20.00000000","price":"82.99000000","side":"buy","client_oid":"779faf08-2e9d-449b-939a-2a0222247a95","product_id":"LTC-USD","sequence":2423271954,"time":"2018-07-27T01:32:41.541000Z"}
{"type":"open","side":"buy","price":"82.99000000","order_id":"c8a96ea0-8d76-4584-bded-db6fc030fc55","remaining_size":"20.00000000","product_id":"LTC-USD","sequence":2423271955,"time":"2018-07-27T01:32:41.541000Z"}
{"type":"received","order_id":"abf8a708-6335-43ac-8949-d5e59404fb3b","order_type":"limit","size":"0.90000000","price":"795.07000000","side":"sell","client_oid":"2654e9e8-b019-4b89-8026-4346383c8c72","product_id":"BCH-USD","sequence":4839272806,"time":"2018-07-27T01:32:41.542000Z"}
{"type":"open","side":"sell","price":"795.07000000","order_id":"abf8a708-6335-43ac-8949-d5e59404fb3b","remaining_size":"0.90000000","product_id":"BCH-USD","sequence":4839272807,"time":"2018-07-27T01:32:41.542000Z"}
{"type":"done","side":"sell","order_id":"2d1a39c4-537e-4d52-a6cb-5e522d15fca5","reason":"canceled","product_id":"BCH-USD","price":"795.07000000","remaining_size":"1.90000000","sequence":4839272808,"time":"2018-07-27T01:32:41.543000Z"}
{"type":"done","side":"sell","order_id":"8f2f2e3b-7028-4113-abc2-70f92c7aa721","reason":"canceled","product_id":"BCH-USD","price":"795.07000000","remaining_size":"0.90000000","sequence":4839272809,"time":"2018-07-27T01:32:41.546000Z"}
{"type":"received","order_id":"50978c9f-70b7-4838-a29e-eb42105ed69e","order_type":"limit","size":"4.50000000","price":"795.53000000","side":"sell","client_oid":"22dbfac5-5d61-4f82-889e-3890e26cb1a1","product_id":"BCH-USD","sequence":4839272810,"time":"2018-07-27T01:32:41.547000Z"}
{"type":"open","side":"sell","price":"795.53000000","order_id":"50978c9f-70b7-4838-a29e-eb42105ed69e","remaining_size":"4.50000000","product_id":"BCH-USD","sequence":4839272811,"time":"2018-07-27T01:32:41.547000Z"}
{"type":"received","order_id":"84da7f6e-225f-434f-8c47-14784259e836","order_type":"limit","size":"0.18739300","price":"791.25000000","side":"buy","client_oid":"dcfa297a-7ad2-4578-81d4-d4c15fb4d311","product_id":"BCH-USD","sequence":4839272812,"time":"2018-07-27T01:32:41.553000Z"}
{"type":"open","side":"buy","price":"791.25000000","order_id":"84da7f6e-225f-434f-8c47-14784259e836","remaining_size":"0.18739300","product_id":"BCH-USD","sequence":4839272813,"time":"2018-07-27T01:32:41.553000Z"}
{"type":"done","side":"sell","order_id":"abf8a708-6335-43ac-8949-d5e59404fb3b","reason":"canceled","product_id":"BCH-USD","price":"795.07000000","remaining_size":"0.90000000","sequence":4839272814,"time":"2018-07-27T01:32:41.554000Z"}
{"type":"done","side":"sell","order_id":"50978c9f-70b7-4838-a29e-eb42105ed69e","reason":"canceled","product_id":"BCH-USD","price":"795.53000000","remaining_size":"4.50000000","sequence":4839272815,"time":"2018-07-27T01:32:41.556000Z"}
{"type":"done","side":"buy","order_id":"84da7f6e-225f-434f-8c47-14784259e836","reason":"canceled","product_id":"BCH-USD","price":"791.25000000","remaining_size":"0.18739300","sequence":4839272816,"time":"2018-07-27T01:32:41.557000Z"}
{"type":"received","order_id":"c369299f-5a50-42a6-914d-cd868d110205","order_type":"limit","size":"1.81488800","price":"791.25000000","side":"buy","client_oid":"5f9a9bd8-827f-4c41-9c1a-b02958cdf9ac","product_id":"BCH-USD","sequence":4839272817,"time":"2018-07-27T01:32:41.558000Z"}
{"type":"open","side":"buy","price":"791.25000000","order_id":"c369299f-5a50-42a6-914d-cd868d110205","remaining_size":"1.81488800","product_id":"BCH-USD","sequence":4839272818,"time":"2018-07-27T01:32:41.558000Z"}
{"type":"received","order_id":"52d91e70-298d-4e7f-9e9e-5eb827757179","order_type":"limit","size":"1.90000000","price":"795.06000000","side":"sell","client_oid":"1c778cec-8537-4948-b0bc-8db3cf09300f","product_id":"BCH-USD","sequence":4839272819,"time":"2018-07-27T01:32:41.558000Z"}
{"type":"open","side":"sell","price":"795.06000000","order_id":"52d91e70-298d-4e7f-9e9e-5eb827757179","remaining_size":"1.90000000","product_id":"BCH-USD","sequence":4839272820,"time":"2018-07-27T01:32:41.558000Z"}
{"type":"done","side":"sell","order_id":"2627cefc-4c09-4faa-8bf9-b0ec8ed6a2bd","reason":"canceled","product_id":"LTC-USD","price":"83.34000000","remaining_size":"7.44874862","sequence":2423271956,"time":"2018-07-27T01:32:41.561000Z"}
{"type":"done","side":"sell","order_id":"f40b316e-ce89-43d0-829e-ce662362e213","reason":"canceled","product_id":"BCH-USD","price":"795.07000000","remaining_size":"4.50000000","sequence":4839272821,"time":"2018-07-27T01:32:41.560000Z"}
{"type":"received","order_id":"2106d467-a35f-4cbc-b55b-794130bc8185","order_type":"limit","size":"0.90000000","price":"795.06000000","side":"sell","client_oid":"31752ea9-5e5b-4776-9d2f-3cecb1ec66a8","product_id":"BCH-USD","sequence":4839272822,"time":"2018-07-27T01:32:41.562000Z"}
{"type":"open","side":"sell","price":"795.06000000","order_id":"2106d467-a35f-4cbc-b55b-794130bc8185","remaining_size":"0.90000000","product_id":"BCH-USD","sequence":4839272823,"time":"2018-07-27T01:32:41.562000Z"}
{"type":"received","order_id":"6b2ff2f6-32fb-4a8c-890b-234755ff81c6","order_type":"limit","size":"4.50000000","price":"795.66000000","side":"sell","client_oid":"ac07501c-257b-4b2c-b9b7-75ea81220ec0","product_id":"BCH-USD","sequence":4839272824,"time":"2018-07-27T01:32:41.563000Z"}
{"type":"open","side":"sell","price":"795.66000000","order_id":"6b2ff2f6-32fb-4a8c-890b-234755ff81c6","remaining_size":"4.50000000","product_id":"BCH-USD","sequence":4839272825,"time":"2018-07-27T01:32:41.563000Z"}
{"type":"done","side":"buy","order_id":"c369299f-5a50-42a6-914d-cd868d110205","reason":"canceled","product_id":"BCH-USD","price":"791.25000000","remaining_size":"1.81488800","sequence":4839272826,"time":"2018-07-27T01:32:41.566000Z"}
{"type":"received","order_id":"11ab51f4-eebc-4c14-a1de-7984f41bd53f","order_type":"limit","size":"0.90000000","price":"795.08000000","side":"sell","client_oid":"8f54ffce-b163-432f-a2ed-088d08a7dafc","product_id":"BCH-USD","sequence":4839272827,"time":"2018-07-27T01:32:41.566000Z"}
{"type":"open","side":"sell","price":"795.08000000","order_id":"11ab51f4-eebc-4c14-a1de-7984f41bd53f","remaining_size":"0.90000000","product_id":"BCH-USD","sequence":4839272828,"time":"2018-07-27T01:32:41.566000Z"}
{"type":"done","side":"sell","order_id":"6b2ff2f6-32fb-4a8c-890b-234755ff81c6","reason":"canceled","product_id":"BCH-USD","price":"795.66000000","remaining_size":"4.50000000","sequence":4839272829,"time":"2018-07-27T01:32:41.566000Z"}
{"type":"done","side":"sell","order_id":"2106d467-a35f-4cbc-b55b-794130bc8185","reason":"canceled","product_id":"BCH-USD","price":"795.06000000","remaining_size":"0.90000000","sequence":4839272830,"time":"2018-07-27T01:32:41.569000Z"}
{"type":"received","order_id":"77bf5d9f-11c1-439c-961b-c78c1c2715cf","order_type":"limit","size":"7.44874862","price":"83.30000000","side":"sell","client_oid":"4ac65e14-98bf-47e4-8000-007a287415e4","product_id":"LTC-USD","sequence":2423271957,"time":"2018-07-27T01:32:41.571000Z"}
{"type":"open","side":"sell","price":"83.30000000","order_id":"77bf5d9f-11c1-439c-961b-c78c1c2715cf","remaining_size":"7.44874862","product_id":"LTC-USD","sequence":2423271958,"time":"2018-07-27T01:32:41.571000Z"}
{"type":"received","order_id":"03c8a7a9-a228-43a0-99e5-e16cf2373912","order_type":"limit","size":"4.50000000","price":"795.06000000","side":"sell","client_oid":"40e4d7e1-ca69-4ebc-aace-86221e588949","product_id":"BCH-USD","sequence":4839272831,"time":"2018-07-27T01:32:41.571000Z"}
{"type":"open","side":"sell","price":"795.06000000","order_id":"03c8a7a9-a228-43a0-99e5-e16cf2373912","remaining_size":"4.50000000","product_id":"BCH-USD","sequence":4839272832,"time":"2018-07-27T01:32:41.571000Z"}
{"type":"done","side":"sell","order_id":"409f3285-f4ce-44a8-beb3-1b9dc0fce128","reason":"canceled","product_id":"BTC-USD","price":"7907.17000000","remaining_size":"1.89169000","sequence":6418130275,"time":"2018-07-27T01:32:41.573000Z"}
{"type":"received","order_id":"65aad3fe-f77c-4e8b-adaa-d6a1f6fb44e9","order_type":"limit","size":"1.81488800","price":"791.23000000","side":"buy","client_oid":"48697220-6b4a-41b6-9701-bdb96d44e6cc","product_id":"BCH-USD","sequence":4839272833,"time":"2018-07-27T01:32:41.574000Z"}
{"type":"open","side":"buy","price":"791.23000000","order_id":"65aad3fe-f77c-4e8b-adaa-d6a1f6fb44e9","remaining_size":"1.81488800","product_id":"BCH-USD","sequence":4839272834,"time":"2018-07-27T01:32:41.574000Z"}
{"type":"done","side":"sell","order_id":"03c8a7a9-a228-43a0-99e5-e16cf2373912","reason":"canceled","product_id":"BCH-USD","price":"795.06000000","remaining_size":"4.50000000","sequence":4839272835,"time":"2018-07-27T01:32:41.575000Z"}
{"type":"done","side":"sell","order_id":"f22f4d40-4641-47cc-bbbd-841988b841dc","reason":"canceled","product_id":"LTC-USD","price":"83.38000000","remaining_size":"7.44874862","sequence":2423271959,"time":"2018-07-27T01:32:41.580000Z"}
{"type":"done","side":"buy","order_id":"65aad3fe-f77c-4e8b-adaa-d6a1f6fb44e9","reason":"canceled","product_id":"BCH-USD","price":"791.23000000","remaining_size":"1.81488800","sequence":4839272836,"time":"2018-07-27T01:32:41.578000Z"}
{"type":"received","order_id":"9a096d18-c673-48d2-88e9-e033a7a54d3b","order_type":"limit","size":"0.18739300","price":"791.23000000","side":"buy","client_oid":"7b68040c-4c97-47d1-bca0-b06f77747b36","product_id":"BCH-USD","sequence":4839272837,"time":"2018-07-27T01:32:41.579000Z"}
{"type":"open","side":"buy","price":"791.23000000","order_id":"9a096d18-c673-48d2-88e9-e033a7a54d3b","remaining_size":"0.18739300","product_id":"BCH-USD","sequence":4839272838,"time":"2018-07-27T01:32:41.579000Z"}
{"type":"done","side":"buy","order_id":"c8a96ea0-8d76-4584-bded-db6fc030fc55","reason":"canceled","product_id":"LTC-USD","price":"82.99000000","remaining_size":"20.00000000","sequence":2423271960,"time":"2018-07-27T01:32:41.582000Z"}
{"type":"received","order_id":"5d9e08b0-b1cd-46f6-bd18-9727d5442b9e","order_type":"limit","size":"7.78700000","price":"462.51000000","side":"buy","product_id":"ETH-USD","sequence":4469354821,"time":"2018-07-27T01:32:41.581000Z"}
{"type":"match","trade_id":37930051,"maker_order_id":"dc99fe95-2fed-4fe4-90a1-6f1dd8b6c5fd","taker_order_id":"5d9e08b0-b1cd-46f6-bd18-9727d5442b9e","side":"sell","size":"7.78700000","price":"462.51000000","product_id":"ETH-USD","sequence":4469354822,"time":"2018-07-27T01:32:41.581000Z"}
{"type":"done","side":"buy","order_id":"5d9e08b0-b1cd-46f6-bd18-9727d5442b9e","reason":"filled","product_id":"ETH-USD","price":"462.51000000","remaining_size":"0.00000000","sequence":4469354823,"time":"2018-07-27T01:32:41.581000Z"}
{"type":"received","order_id":"02b442b7-1951-40cd-9b52-5907e1f1a4e8","order_type":"limit","size":"1.89039000","price":"7906.43000000","side":"sell","client_oid":"506657df-52d6-4191-a1d5-4408e08b7999","product_id":"BTC-USD","sequence":6418130276,"time":"2018-07-27T01:32:41.584000Z"}
{"type":"open","side":"sell","price":"7906.43000000","order_id":"02b442b7-1951-40cd-9b52-5907e1f1a4e8","remaining_size":"1.89039000","product_id":"BTC-USD","sequence":6418130277,"time":"2018-07-27T01:32:41.584000Z"}
{"type":"done","side":"buy","order_id":"ed06107d-deaf-4a72-af51-6c3c1d43aaa0","reason":"canceled","product_id":"BCH-USD","price":"792.54000000","remaining_size":"2.00000000","sequence":4839272839,"time":"2018-07-27T01:32:41.585000Z"}
{"type":"received","order_id":"ae9a2df9-8503-4dd1-b1db-8e79c74cd004","order_type":"limit","size":"0.90000000","price":"795.08000000","side":"sell","client_oid":"67fac2e6-79e2-4018-a214-8dfe9ccadb6f","product_id":"BCH-USD","sequence":4839272840,"time":"2018-07-27T01:32:41.588000Z"}
{"type":"open","side":"sell","price":"795.08000000","order_id":"ae9a2df9-8503-4dd1-b1db-8e79c74cd004","remaining_size":"0.90000000","product_id":"BCH-USD","sequence":4839272841,"time":"2018-07-27T01:32:41.588000Z"}
{"type":"done","side":"sell","order_id":"06e70fc9-9d42-48c4-a6fd-9b22d60f8132","reason":"canceled","product_id":"ETH-USD","price":"463.65000000","remaining_size":"8.90526000","sequence":4469354824,"time":"2018-07-27T01:32:41.593000Z"}
{"type":"received","order_id":"1a659338-3238-4dcf-89d2-e53c7665d3e9","order_type":"limit","size":"1.81488800","price":"791.26000000","side":"buy","client_oid":"0e825735-3ff0-4c7c-82e6-ba4aabd9ab07","product_id":"BCH-USD","sequence":4839272842,"time":"2018-07-27T01:32:41.592000Z"}
{"type":"received","order_id":"a9bc6190-722d-4df9-a30a-9fd21f704bad","order_type":"limit","size":"7.44874862","price":"83.34000000","side":"sell","client_oid":"eb5ac497-1aec-4706-8000-00b8aeb03a8a","product_id":"LTC-USD","sequence":2423271961,"time":"2018-07-27T01:32:41.594000Z"}
{"type":"open","side":"buy","price":"791.26000000","order_id":"1a659338-3238-4dcf-89d2-e53c7665d3e9","remaining_size":"1.81488800","product_id":"BCH-USD","sequence":4839272843,"time":"2018-07-27T01:32:41.592000Z"}
{"type":"open","side":"sell","price":"83.34000000","order_id":"a9bc6190-722d-4df9-a30a-9fd21f704bad","remaining_size":"7.44874862","product_id":"LTC-USD","sequence":2423271962,"time":"2018-07-27T01:32:41.594000Z"}
{"type":"done","side":"sell","order_id":"52d91e70-298d-4e7f-9e9e-5eb827757179","reason":"canceled","product_id":"BCH-USD","price":"795.06000000","remaining_size":"1.90000000","sequence":4839272844,"time":"2018-07-27T01:32:41.593000Z"}
{"type":"received","order_id":"16565473-9a9e-4b5f-b02d-a0faee938d6d","order_type":"limit","size":"4.50000000","price":"795.53000000","side":"sell","client_oid":"9864173b-f44b-415c-93c0-a2cc7d600cd6","product_id":"BCH-USD","sequence":4839272845,"time":"2018-07-27T01:32:41.594000Z"}
{"type":"open","side":"sell","price":"795.53000000","order_id":"16565473-9a9e-4b5f-b02d-a0faee938d6d","remaining_size":"4.50000000","product_id":"BCH-USD","sequence":4839272846,"time":"2018-07-27T01:32:41.594000Z"}
{"type":"received","order_id":"e4fbbb41-679e-4662-9d4b-0cfed8d23f31","order_type":"limit","size":"4.50000000","price":"795.08000000","side":"sell","client_oid":"3e78b7c4-e4a6-4fe0-bf07-8a3871f56c6e","product_id":"BCH-USD","sequence":4839272847,"time":"2018-07-27T01:32:41.597000Z"}
{"type":"open","side":"sell","price":"795.08000000","order_id":"e4fbbb41-679e-4662-9d4b-0cfed8d23f31","remaining_size":"4.50000000","product_id":"BCH-USD","sequence":4839272848,"time":"2018-07-27T01:32:41.597000Z"}
{"type":"done","side":"buy","order_id":"1a659338-3238-4dcf-89d2-e53c7665d3e9","reason":"canceled","product_id":"BCH-USD","price":"791.26000000","remaining_size":"1.81488800","sequence":4839272849,"time":"2018-07-27T01:32:41.597000Z"}
{"type":"done","side":"sell","order_id":"16565473-9a9e-4b5f-b02d-a0faee938d6d","reason":"canceled","product_id":"BCH-USD","price":"795.53000000","remaining_size":"4.50000000","sequence":4839272850,"time":"2018-07-27T01:32:41.599000Z"}
{"type":"received","order_id":"b43177a5-10a5-47b4-bb42-87cfcd8365c7","order_type":"limit","size":"2.00000000","price":"792.80000000","side":"buy","client_oid":"db77546d-702b-4055-9f40-fd9512b3ed8a","product_id":"BCH-USD","sequence":4839272851,"time":"2018-07-27T01:32:41.600000Z"}
{"type":"open","side":"buy","price":"792.80000000","order_id":"b43177a5-10a5-47b4-bb42-87cfcd8365c7","remaining_size":"2.00000000","product_id":"BCH-USD","sequence":4839272852,"time":"2018-07-27T01:32:41.600000Z"}
{"type":"done","side":"sell","order_id":"77bf5d9f-11c1-439c-961b-c78c1c2715cf","reason":"canceled","product_id":"LTC-USD","price":"83.30000000","remaining_size":"7.44874862","sequence":2423271963,"time":"2018-07-27T01:32:41.603000Z"}
{"type":"received","order_id":"47449a63-e9d3-4ca7-9b08-c24ff6a5fb1c","order_type":"limit","size":"1.90000000","price":"795.08000000","side":"sell","client_oid":"44bd09e9-2bb3-4a66-b8b9-8495bbd88ce4","product_id":"BCH-USD","sequence":4839272853,"time":"2018-07-27T01:32:41.601000Z"}
{"type":"open","side":"sell","price":"795.08000000","order_id":"47449a63-e9d3-4ca7-9b08-c24ff6a5fb1c","remaining_size":"1.90000000","product_id":"BCH-USD","sequence":4839272854,"time":"2018-07-27T01:32:41.601000Z"}
{"type":"received","order_id":"c223f713-a739-42ca-99c3-41a9d79844f6","order_type":"limit","size":"1.81488800","price":"791.24000000","side":"buy","client_oid":"d6265ce4-61f0-48eb-9fee-20688aee0d3f","product_id":"BCH-USD","sequence":4839272855,"time":"2018-07-27T01:32:41.603000Z"}
{"type":"open","side":"buy","price":"791.24000000","order_id":"c223f713-a739-42ca-99c3-41a9d79844f6","remaining_size":"1.81488800","product_id":"BCH-USD","sequence":4839272856,"time":"2018-07-27T01:32:41.603000Z"}
{"type":"done","side":"buy","order_id":"b43177a5-10a5-47b4-bb42-87cfcd8365c7","reason":"canceled","product_id":"BCH-USD","price":"792.80000000","remaining_size":"2.00000000","sequence":4839272857,"time":"2018-07-27T01:32:41.604000Z"}
{"type":"done","side":"sell","order_id":"11ab51f4-eebc-4c14-a1de-7984f41bd53f","reason":"canceled","product_id":"BCH-USD","price":"795.08000000","remaining_size":"0.90000000","sequence":4839272858,"time":"2018-07-27T01:32:41.604000Z"}
{"type":"done","side":"buy","order_id":"9a096d18-c673-48d2-88e9-e033a7a54d3b","reason":"canceled","product_id":"BCH-USD","price":"791.23000000","remaining_size":"0.18739300","sequence":4839272859,"time":"2018-07-27T01:32:41.606000Z"}
{"type":"received","order_id":"0b050559-c2b8-4f78-9dfd-6c0125126572","order_type":"limit","size":"4.50000000","price":"795.67000000","side":"sell","client_oid":"d08e4e5b-5c82-45d3-a31c-6c65fc57b763","product_id":"BCH-USD","sequence":4839272860,"time":"2018-07-27T01:32:41.606000Z"}
{"type":"open","side":"sell","price":"795.67000000","order_id":"0b050559-c2b8-4f78-9dfd-6c0125126572","remaining_size":"4.50000000","product_id":"BCH-USD","sequence":4839272861,"time":"2018-07-27T01:32:41.606000Z"}
{"type":"done","side":"buy","order_id":"c223f713-a739-42ca-99c3-41a9d79844f6","reason":"canceled","product_id":"BCH-USD","price":"791.24000000","remaining_size":"1.81488800","sequence":4839272862,"time":"2018-07-27T01:32:41.607000Z"}
{"type":"done","side":"sell","order_id":"e4fbbb41-679e-4662-9d4b-0cfed8d23f31","reason":"canceled","product_id":"BCH-USD","price":"795.08000000","remaining_size":"4.50000000","sequence":4839272863,"time":"2018-07-27T01:32:41.608000Z"}
{"type":"received","order_id":"1c1ab0e4-9f87-455b-80bf-2358c96264db","order_type":"limit","size":"0.18739300","price":"791.27000000","side":"buy","client_oid":"dba2d5c6-9295-4287-86d4-83b8d79743eb","product_id":"BCH-USD","sequence":4839272864,"time":"2018-07-27T01:32:41.611000Z"}
{"type":"open","side":"buy","price":"791.27000000","order_id":"1c1ab0e4-9f87-455b-80bf-2358c96264db","remaining_size":"0.18739300","product_id":"BCH-USD","sequence":4839272865,"time":"2018-07-27T01:32:41.611000Z"}
{"type":"done","side":"buy","order_id":"1c1ab0e4-9f87-455b-80bf-2358c96264db","reason":"canceled","product_id":"BCH-USD","price":"791.27000000","remaining_size":"0.18739300","sequence":4839272866,"time":"2018-07-27T01:32:41.616000Z"}
{"type":"received","order_id":"787b5e41-3dea-43b3-8604-ab7afeeab1a9","order_type":"limit","size":"1.81488800","price":"791.23000000","side":"buy","client_oid":"76b29359-9f82-4f95-870d-150c3e2f35d0","product_id":"BCH-USD","sequence":4839272867,"time":"2018-07-27T01:32:41.616000Z"}
{"type":"open","side":"buy","price":"791.23000000","order_id":"787b5e41-3dea-43b3-8604-ab7afeeab1a9","remaining_size":"1.81488800","product_id":"BCH-USD","sequence":4839272868,"time":"2018-07-27T01:32:41.616000Z"}
{"type":"received","order_id":"084f79c3-ad8d-4a5a-90ab-e29f10e36922","order_type":"limit","size":"7.44874862","price":"83.38000000","side":"sell","client_oid":"6227ce9c-54e5-49ec-8000-0060c8ea74db","product_id":"LTC-USD","sequence":2423271964,"time":"2018-07-27T01:32:41.620000Z"}
{"type":"received","order_id":"b1b6b8ea-216d-4eb3-82d7-af2470fe5bba","order_type":"limit","size":"2.00000000","price":"792.54000000","side":"buy","client_oid":"47c54f40-f8dc-4eb8-b3d1-e0112ed84d6b","product_id":"BCH-USD","sequence":4839272869,"time":"2018-07-27T01:32:41.618000Z"}
{"type":"open","side":"sell","price":"83.38000000","order_id":"084f79c3-ad8d-4a5a-90ab-e29f10e36922","remaining_size":"7.44874862","product_id":"LTC-USD","sequence":2423271965,"time":"2018-07-27T01:32:41.620000Z"}
{"type":"open","side":"buy","price":"792.54000000","order_id":"b1b6b8ea-216d-4eb3-82d7-af2470fe5bba","remaining_size":"2.00000000","product_id":"BCH-USD","sequence":4839272870,"time":"2018-07-27T01:32:41.618000Z"}
{"type":"done","side":"sell","order_id":"ae9a2df9-8503-4dd1-b1db-8e79c74cd004","reason":"canceled","product_id":"BCH-USD","price":"795.08000000","remaining_size":"0.90000000","sequence":4839272871,"time":"2018-07-27T01:32:41.619000Z"}
{"type":"done","side":"buy","order_id":"787b5e41-3dea-43b3-8604-ab7afeeab1a9","reason":"canceled","product_id":"BCH-USD","price":"791.23000000","remaining_size":"1.81488800","sequence":4839272872,"time":"2018-07-27T01:32:41.621000Z"}
{"type":"received","order_id":"92ca48c2-21ae-4117-a806-feabf2febee7","order_type":"limit","size":"4.50000000","price":"795.07000000","side":"sell","client_oid":"519aa648-01d4-43c3-b5ce-d4607388e464","product_id":"BCH-USD","sequence":4839272873,"time":"2018-07-27T01:32:41.622000Z"}
{"type":"open","side":"sell","price":"795.07000000","order_id":"92ca48c2-21ae-4117-a806-feabf2febee7","remaining_size":"4.50000000","product_id":"BCH-USD","sequence":4839272874,"time":"2018-07-27T01:32:41.622000Z"}
{"type":"received","order_id":"99811758-913b-43c4-9aad-82d888aeceea","order_type":"limit","size":"0.90000000","price":"795.07000000","side":"sell","client_oid":"8b748115-fe23-4b80-89a7-ab4baf66f092","product_id":"BCH-USD","sequence":4839272875,"time":"2018-07-27T01:32:41.623000Z"}
{"type":"open","side":"sell","price":"795.07000000","order_id":"99811758-913b-43c4-9aad-82d888aeceea","remaining_size":"0.90000000","product_id":"BCH-USD","sequence":4839272876,"time":"2018-07-27T01:32:41.623000Z"}
{"type":"received","order_id":"af961e42-9566-43c6-b5d1-ee35e5bd2c2b","order_type":"limit","size":"20.00000000","price":"82.98000000","side":"buy","client_oid":"e58506a7-bfaa-42de-8fd4-ed18c488f0a1","product_id":"LTC-USD","sequence":2423271966,"time":"2018-07-27T01:32:41.626000Z"}
{"type":"done","side":"buy","order_id":"b1b6b8ea-216d-4eb3-82d7-af2470fe5bba","reason":"canceled","product_id":"BCH-USD","price":"792.54000000","remaining_size":"2.00000000","sequence":4839272877,"time":"2018-07-27T01:32:41.624000Z"}
{"type":"open","side":"buy","price":"82.98000000","order_id":"af961e42-9566-43c6-b5d1-ee35e5bd2c2b","remaining_size":"20.00000000","product_id":"LTC-USD","sequence":2423271967,"time":"2018-07-27T01:32:41.626000Z"}
{"type":"done","side":"buy","order_id":"e1c43b8a-64ae-4eed-bc9f-4005a8d4f4f5","reason":"canceled","product_id":"LTC-USD","price":"83.05000000","remaining_size":"3.96192000","sequence":2423271968,"time":"2018-07-27T01:32:41.626000Z"}
{"type":"done","side":"sell","order_id":"99811758-913b-43c4-9aad-82d888aeceea","reason":"canceled","product_id":"BCH-USD","price":"795.07000000","remaining_size":"0.90000000","sequence":4839272878,"time":"2018-07-27T01:32:41.626000Z"}
{"type":"done","side":"buy","order_id":"59d41a24-2398-45c1-abf8-3c160c195ef9","reason":"canceled","product_id":"LTC-USD","price":"83.03000000","remaining_size":"6.04639400","sequence":2423271969,"time":"2018-07-27T01:32:41.631000Z"}
{"type":"received","order_id":"0e55f7e1-9205-408e-8875-8367a243e0b9","order_type":"limit","size":"0.18739300","price":"791.23000000","side":"buy","client_oid":"6e4965a5-33e5-4628-ae64-6cec67011445","product_id":"BCH-USD","sequence":4839272879,"time":"2018-07-27T01:32:41.629000Z"}
{"type":"open","side":"buy","price":"791.23000000","order_id":"0e55f7e1-9205-408e-8875-8367a243e0b9","remaining_size":"0.18739300","product_id":"BCH-USD","sequence":4839272880,"time":"2018-07-27T01:32:41.629000Z"}
{"type":"done","side":"buy","order_id":"af961e42-9566-43c6-b5d1-ee35e5bd2c2b","reason":"canceled","product_id":"LTC-USD","price":"82.98000000","remaining_size":"20.00000000","sequence":2423271970,"time":"2018-07-27T01:32:41.633000Z"}
{"type":"received","order_id":"2dc3833b-bfba-4106-9b5c-bd812b6db910","order_type":"limit","size":"1.81488800","price":"791.25000000","side":"buy","client_oid":"8cabbd26-18a4-404c-9abc-4dab5e5219cc","product_id":"BCH-USD","sequence":4839272881,"time":"2018-07-27T01:32:41.631000Z"}
{"type":"open","side":"buy","price":"791.25000000","order_id":"2dc3833b-bfba-4106-9b5c-bd812b6db910","remaining_size":"1.81488800","product_id":"BCH-USD","sequence":4839272882,"time":"2018-07-27T01:32:41.631000Z"}
{"type":"received","order_id":"c9110773-0078-4167-89ee-26b43d17d07d","order_type":"limit","size":"0.90000000","price":"795.07000000","side":"sell","client_oid":"53752e52-ccf6-484f-aa0f-3e79a6401376","product_id":"BCH-USD","sequence":4839272883,"time":"2018-07-27T01:32:41.632000Z"}
{"type":"open","side":"sell","price":"795.07000000","order_id":"c9110773-0078-4167-89ee-26b43d17d07d","remaining_size":"0.90000000","product_id":"BCH-USD","sequence":4839272884,"time":"2018-07-27T01:32:41.632000Z"}
{"type":"done","side":"buy","order_id":"1c4eb79f-89d9-476a-97a3-25d596a1bdc6","reason":"canceled","product_id":"LTC-USD","price":"83.01000000","remaining_size":"12.25851900","sequence":2423271971,"time":"2018-07-27T01:32:41.635000Z"}
{"type":"done","side":"sell","order_id":"031230ef-30d0-4089-9665-1d9ac2b7e9d0","reason":"canceled","product_id":"BTC-USD","price":"7914.53000000","remaining_size":"1.40200000","sequence":6418130278,"time":"2018-07-27T01:32:41.636000Z"}
{"type":"done","side":"sell","order_id":"a9bc6190-722d-4df9-a30a-9fd21f704bad","reason":"canceled","product_id":"LTC-USD","price":"83.34000000","remaining_size":"7.44874862","sequence":2423271972,"time":"2018-07-27T01:32:41.637000Z"}
{"type":"done","side":"buy","order_id":"2dc3833b-bfba-4106-9b5c-bd812b6db910","reason":"canceled","product_id":"BCH-USD","price":"791.25000000","remaining_size":"1.81488800","sequence":4839272885,"time":"2018-07-27T01:32:41.637000Z"}
{"type":"done","side":"buy","order_id":"ec8bf59e-f207-4707-a064-68cd2168dd77","reason":"canceled","product_id":"BTC-USD","price":"7890.02000000","remaining_size":"1.36500000","sequence":6418130279,"time":"2018-07-27T01:32:41.640000Z"}
{"type":"received","order_id":"b34bc1c3-a80c-40bf-aaf6-c5945b22acb9","order_type":"limit","size":"0.90000000","price":"795.08000000","side":"sell","client_oid":"e1648194-ccbf-4f91-b924-ef4fce296e00","product_id":"BCH-USD","sequence":4839272886,"time":"2018-07-27T01:32:41.638000Z"}
{"type":"open","side":"sell","price":"795.08000000","order_id":"b34bc1c3-a80c-40bf-aaf6-c5945b22acb9","remaining_size":"0.90000000","product_id":"BCH-USD","sequence":4839272887,"time":"2018-07-27T01:32:41.638000Z"}
{"type":"done","side":"sell","order_id":"47449a63-e9d3-4ca7-9b08-c24ff6a5fb1c","reason":"canceled","product_id":"BCH-USD","price":"795.08000000","remaining_size":"1.90000000","sequence":4839272888,"time":"2018-07-27T01:32:41.640000Z"}
{"type":"done","side":"sell","order_id":"0b050559-c2b8-4f78-9dfd-6c0125126572","reason":"canceled","product_id":"BCH-USD","price":"795.67000000","remaining_size":"4.50000000","sequence":4839272889,"time":"2018-07-27T01:32:41.640000Z"}
{"type":"done","side":"sell","order_id":"b34bc1c3-a80c-40bf-aaf6-c5945b22acb9","reason":"canceled","product_id":"BCH-USD","price":"795.08000000","remaining_size":"0.90000000","sequence":4839272890,"time":"2018-07-27T01:32:41.643000Z"}
{"type":"received","order_id":"db9c5067-bbe7-4ca8-9a55-dc9845a456ac","order_type":"limit","size":"2.00000000","price":"792.54000000","side":"buy","client_oid":"ce1eef61-e520-41d8-bfa1-1565bf2a2e28","product_id":"BCH-USD","sequence":4839272891,"time":"2018-07-27T01:32:41.645000Z"}
{"type":"open","side":"buy","price":"792.54000000","order_id":"db9c5067-bbe7-4ca8-9a55-dc9845a456ac","remaining_size":"2.00000000","product_id":"BCH-USD","sequence":4839272892,"time":"2018-07-27T01:32:41.645000Z"}
{"type":"received","order_id":"35d8b07d-aa56-400d-873d-2cefed105d92","order_type":"limit","size":"1.81488800","price":"791.24000000","side":"buy","client_oid":"9f5d6306-41bd-4dc7-a12b-ca787d830de3","product_id":"BCH-USD","sequence":4839272893,"time":"2018-07-27T01:32:41.645000Z"}
{"type":"open","side":"buy","price":"791.24000000","order_id":"35d8b07d-aa56-400d-873d-2cefed105d92","remaining_size":"1.81488800","product_id":"BCH-USD","sequence":4839272894,"time":"2018-07-27T01:32:41.645000Z"}
{"type":"received","order_id":"0bf9b43c-697e-44b0-90a4-535781016001","order_type":"limit","size":"1.37700000","price":"7903.13000000","side":"sell","client_oid":"8cdc72b3-a245-39e3-fc6d-0e5727412d74","product_id":"BTC-USD","sequence":6418130280,"time":"2018-07-27T01:32:41.648000Z"}
{"type":"open","side":"sell","price":"7903.13000000","order_id":"0bf9b43c-697e-44b0-90a4-535781016001","remaining_size":"1.37700000","product_id":"BTC-USD","sequence":6418130281,"time":"2018-07-27T01:32:41.648000Z"}
{"type":"received","order_id":"74337576-c7b4-441b-98ab-bdd73b8c49f5","order_type":"limit","size":"1.42700000","price":"7878.62000000","side":"buy","client_oid":"a774882e-96de-35f0-e827-d658beea3194","product_id":"BTC-USD","sequence":6418130282,"time":"2018-07-27T01:32:41.650000Z"}
{"type":"open","side":"buy","price":"7878.62000000","order_id":"74337576-c7b4-441b-98ab-bdd73b8c49f5","remaining_size":"1.42700000","product_id":"BTC-USD","sequence":6418130283,"time":"2018-07-27T01:32:41.650000Z"}
{"type":"received","order_id":"00166c30-6fda-4622-a45c-fc0499831ae1","order_type":"limit","size":"20.00000000","price":"82.99000000","side":"buy","client_oid":"a42429a2-9e7a-496c-9938-160f6eb825b0","product_id":"LTC-USD","sequence":2423271973,"time":"2018-07-27T01:32:41.651000Z"}
{"type":"open","side":"buy","price":"82.99000000","order_id":"00166c30-6fda-4622-a45c-fc0499831ae1","remaining_size":"20.00000000","product_id":"LTC-USD","sequence":2423271974,"time":"2018-07-27T01:32:41.651000Z"}
{"type":"received","order_id":"34299092-908d-48ad-be99-d8229a614c67","order_type":"limit","size":"7.44874862","price":"83.30000000","side":"sell","client_oid":"1071e942-c2b2-4e8c-8000-004f5389d4bc","product_id":"LTC-USD","sequence":2423271975,"time":"2018-07-27T01:32:41.652000Z"}
{"type":"open","side":"sell","price":"83.30000000","order_id":"34299092-908d-48ad-be99-d8229a614c67","remaining_size":"7.44874862","product_id":"LTC-USD","sequence":2423271976,"time":"2018-07-27T01:32:41.652000Z"}
{"type":"done","side":"sell","order_id":"92ca48c2-21ae-4117-a806-feabf2febee7","reason":"canceled","product_id":"BCH-USD","price":"795.07000000","remaining_size":"4.50000000","sequence":4839272895,"time":"2018-07-27T01:32:41.651000Z"}
{"type":"done","side":"buy","order_id":"db9c5067-bbe7-4ca8-9a55-dc9845a456ac","reason":"canceled","product_id":"BCH-USD","price":"792.54000000","remaining_size":"2.00000000","sequence":4839272896,"time":"2018-07-27T01:32:41.651000Z"}
{"type":"received","order_id":"daafab7f-2918-454d-870d-ea1b0c86f737","order_type":"limit","size":"0.90000000","price":"795.06000000","side":"sell","client_oid":"d5d54a01-0c8f-4af6-82bb-4c51df645d4e","product_id":"BCH-USD","sequence":4839272897,"time":"2018-07-27T01:32:41.652000Z"}
{"type":"open","side":"sell","price":"795.06000000","order_id":"daafab7f-2918-454d-870d-ea1b0c86f737","remaining_size":"0.90000000","product_id":"BCH-USD","sequence":4839272898,"time":"2018-07-27T01:32:41.652000Z"}
{"type":"received","order_id":"b5f79828-c232-4de5-84fc-00609883a233","order_type":"limit","size":"0.90000000","price":"795.06000000","side":"sell","client_oid":"5bf5b408-d5eb-4051-9674-d92534d9bd8a","product_id":"BCH-USD","sequence":4839272899,"time":"2018-07-27T01:32:41.652000Z"}
{"type":"open","side":"sell","price":"795.06000000","order_id":"b5f79828-c232-4de5-84fc-00609883a233","remaining_size":"0.90000000","product_id":"BCH-USD","sequence":4839272900,"time":"2018-07-27T01:32:41.652000Z"}
{"type":"done","side":"buy","order_id":"88cadb1c-9b24-47fc-b887-f39ce099653b","reason":"canceled","product_id":"LTC-USD","price":"82.95000000","remaining_size":"31.44458700","sequence":2423271977,"time":"2018-07-27T01:32:41.656000Z"}
{"type":"done","side":"sell","order_id":"c9110773-0078-4167-89ee-26b43d17d07d","reason":"canceled","product_id":"BCH-USD","price":"795.07000000","remaining_size":"0.90000000","sequence":4839272901,"time":"2018-07-27T01:32:41.655000Z"}
{"type":"done","side":"buy","order_id":"875adb51-927a-4c95-9f23-9b35983b4136","reason":"canceled","product_id":"LTC-USD","price":"82.93000000","remaining_size":"134.34493100","sequence":2423271978,"time":"2018-07-27T01:32:41.662000Z"}
{"type":"received","order_id":"3d4ae586-c458-42dc-9b48-c6406020b765","order_type":"limit","size":"1.90000000","price":"795.06000000","side":"sell","client_oid":"3bc30774-20f3-44c4-9834-49efb1644c0f","product_id":"BCH-USD","sequence":4839272902,"time":"2018-07-27T01:32:41.661000Z"}
{"type":"open","side":"sell","price":"795.06000000","order_id":"3d4ae586-c458-42dc-9b48-c6406020b765","remaining_size":"1.90000000","product_id":"BCH-USD","sequence":4839272903,"time":"2018-07-27T01:32:41.661000Z"}
{"type":"received","order_id":"94010c6f-b86c-4865-bbbb-8f1d6a22edb7","order_type":"limit","size":"0.10000000","price":"83.39000000","side":"sell","client_oid":"f43af906-913c-11e8-8d2c-16be7828d23e","product_id":"LTC-USD","sequence":2423271979,"time":"2018-07-27T01:32:41.664000Z"}
{"type":"done","side":"sell","order_id":"94010c6f-b86c-4865-bbbb-8f1d6a22edb7","reason":"canceled","product_id":"LTC-USD","price":"83.39000000","remaining_size":"0.10000000","sequence":2423271980,"time":"2018-07-27T01:32:41.664000Z"}
{"type":"received","order_id":"3706c6d2-3d32-4e96-8352-9adc543799b1","order_type":"limit","size":"4.50000000","price":"795.66000000","side":"sell","client_oid":"5779a61d-dc1d-4921-ad09-e8b588a16757","product_id":"BCH-USD","sequence":4839272904,"time":"2018-07-27T01:32:41.665000Z"}
{"type":"open","side":"sell","price":"795.66000000","order_id":"3706c6d2-3d32-4e96-8352-9adc543799b1","remaining_size":"4.50000000","product_id":"BCH-USD","sequence":4839272905,"time":"2018-07-27T01:32:41.665000Z"}
{"type":"done","side":"buy","order_id":"8bf40e09-f889-44e2-ad53-f535a082ea2f","reason":"canceled","product_id":"LTC-USD","price":"82.91000000","remaining_size":"82.00225100","sequence":2423271981,"time":"2018-07-27T01:32:41.667000Z"}
{"type":"done","side":"sell","order_id":"3706c6d2-3d32-4e96-8352-9adc543799b1","reason":"canceled","product_id":"BCH-USD","price":"795.66000000","remaining_size":"4.50000000","sequence":4839272906,"time":"2018-07-27T01:32:41.668000Z"}
{"type":"done","side":"sell","order_id":"4f3501e6-fd05-444b-aa70-aa517e496688","reason":"canceled","product_id":"LTC-USD","price":"83.29000000","remaining_size":"16.39875700","sequence":2423271982,"time":"2018-07-27T01:32:41.672000Z"}
{"type":"done","side":"sell","order_id":"084f79c3-ad8d-4a5a-90ab-e29f10e36922","reason":"canceled","product_id":"LTC-USD","price":"83.38000000","remaining_size":"7.44874862","sequence":2423271983,"time":"2018-07-27T01:32:41.675000Z"}
{"type":"done","side":"sell","order_id":"6f390def-a9ae-4ea4-a4e6-4b6efc690d6f","reason":"canceled","product_id":"LTC-USD","price":"83.30000000","remaining_size":"21.29141700","sequence":2423271984,"time":"2018-07-27T01:32:41.675000Z"}
{"type":"done","side":"buy","order_id":"00166c30-6fda-4622-a45c-fc0499831ae1","reason":"canceled","product_id":"LTC-USD","price":"82.99000000","remaining_size":"20.00000000","sequence":2423271985,"time":"2018-07-27T01:32:41.675000Z"}
{"type":"received","order_id":"409a61e1-d080-4523-a03e-2415129b076c","order_type":"limit","size":"9.01200000","price":"795.06000000","side":"sell","product_id":"BCH-USD","sequence":4839272907,"time":"2018-07-27T01:32:41.676000Z"}
{"type":"open","side":"sell","price":"795.06000000","order_id":"409a61e1-d080-4523-a03e-2415129b076c","remaining_size":"9.01200000","product_id":"BCH-USD","sequence":4839272908,"time":"2018-07-27T01:32:41.676000Z"}
{"type":"received","order_id":"944adadf-eac5-4d89-be96-fac5ddc29796","order_type":"limit","size":"4.50000000","price":"795.53000000","side":"sell","client_oid":"20a84691-6718-49d7-b752-534967a9cf4f","product_id":"BCH-USD","sequence":4839272909,"time":"2018-07-27T01:32:41.676000Z"}
{"type":"open","side":"sell","price":"795.53000000","order_id":"944adadf-eac5-4d89-be96-fac5ddc29796","remaining_size":"4.50000000","product_id":"BCH-USD","sequence":4839272910,"time":"2018-07-27T01:32:41.676000Z"}
{"type":"done","side":"sell","order_id":"1e7de457-2c55-4036-8850-04b72420d489","reason":"canceled","product_id":"LTC-USD","price":"83.32000000","remaining_size":"3.83226600","sequence":2423271986,"time":"2018-07-27T01:32:41.682000Z"}
{"type":"received","order_id":"5f5e6afe-39b9-4e32-ac46-67f4fe343126","order_type":"limit","size":"20.00000000","price":"82.98000000","side":"buy","client_oid":"073315e3-739c-4e13-957e-a5a0ddcc12d4","product_id":"LTC-USD","sequence":2423271987,"time":"2018-07-27T01:32:41.684000Z"}
{"type":"open","side":"buy","price":"82.98000000","order_id":"5f5e6afe-39b9-4e32-ac46-67f4fe343126","remaining_size":"20.00000000","product_id":"LTC-USD","sequence":2423271988,"time":"2018-07-27T01:32:41.684000Z"}
{"type":"done","side":"sell","order_id":"7e05813e-3f0e-4225-90d2-14edc18e9c7b","reason":"canceled","product_id":"BTC-USD","price":"7907.16000000","remaining_size":"0.02500000","sequence":6418130284,"time":"2018-07-27T01:32:41.687000Z"}
{"type":"done","side":"buy","order_id":"35d8b07d-aa56-400d-873d-2cefed105d92","reason":"canceled","product_id":"BCH-USD","price":"791.24000000","remaining_size":"1.81488800","sequence":4839272911,"time":"2018-07-27T01:32:41.685000Z"}
{"type":"done","side":"sell","order_id":"bb635a5a-3792-4b5d-8ab6-58fd08257d3d","reason":"canceled","product_id":"LTC-USD","price":"83.34000000","remaining_size":"124.24203800","sequence":2423271989,"time":"2018-07-27T01:32:41.687000Z"}
{"type":"done","side":"buy","order_id":"5f5e6afe-39b9-4e32-ac46-67f4fe343126","reason":"canceled","product_id":"LTC-USD","price":"82.98000000","remaining_size":"20.00000000","sequence":2423271990,"time":"2018-07-27T01:32:41.689000Z"}
{"type":"received","order_id":"04f26861-2a5e-4350-a790-9fcff92a52cf","order_type":"limit","size":"7.44874862","price":"83.34000000","side":"sell","client_oid":"2f8f7d09-2591-4021-8000-0a444f67f240","product_id":"LTC-USD","sequence":2423271991,"time":"2018-07-27T01:32:41.690000Z"}
{"type":"open","side":"sell","price":"83.34000000","order_id":"04f26861-2a5e-4350-a790-9fcff92a52cf","remaining_size":"7.44874862","product_id":"LTC-USD","sequence":2423271992,"time":"2018-07-27T01:32:41.690000Z"}
{"type":"done","side":"sell","order_id":"b1ece1a3-e143-4c5a-81ea-5430a2d9ca00","reason":"canceled","product_id":"LTC-USD","price":"83.37000000","remaining_size":"18.64678600","sequence":2423271993,"time":"2018-07-27T01:32:41.691000Z"}
{"type":"done","side":"sell","order_id":"944adadf-eac5-4d89-be96-fac5ddc29796","reason":"canceled","product_id":"BCH-USD","price":"795.53000000","remaining_size":"4.50000000","sequence":4839272912,"time":"2018-07-27T01:32:41.690000Z"}
{"type":"received","order_id":"7b3a4134-4fd4-47b4-90a3-864767adbc99","order_type":"limit","size":"0.90000000","price":"795.05000000","side":"sell","client_oid":"572b9733-7798-4b46-b510-06396ab8e494","product_id":"BCH-USD","sequence":4839272913,"time":"2018-07-27T01:32:41.691000Z"}
{"type":"open","side":"sell","price":"795.05000000","order_id":"7b3a4134-4fd4-47b4-90a3-864767adbc99","remaining_size":"0.90000000","product_id":"BCH-USD","sequence":4839272914,"time":"2018-07-27T01:32:41.691000Z"}
{"type":"received","order_id":"9dd2fa7a-f2dc-490c-b7ea-c978f79a93e7","order_type":"limit","size":"0.02500000","price":"7907.52000000","side":"sell","client_oid":"2f35ee9a-e0b6-4059-8000-00cc4bbbf307","product_id":"BTC-USD","sequence":6418130285,"time":"2018-07-27T01:32:41.695000Z"}
{"type":"done","side":"sell","order_id":"034d5e63-d534-4ed9-90bc-1e5a31d67936","reason":"canceled","product_id":"LTC-USD","price":"83.40000000","remaining_size":"3.21039500","sequence":2423271994,"time":"2018-07-27T01:32:41.695000Z"}
{"type":"open","side":"sell","price":"7907.52000000","order_id":"9dd2fa7a-f2dc-490c-b7ea-c978f79a93e7","remaining_size":"0.02500000","product_id":"BTC-USD","sequence":6418130286,"time":"2018-07-27T01:32:41.695000Z"}
{"type":"received","order_id":"dab78657-c4f3-4569-b9b8-5230e83d3fe6","order_type":"limit","size":"1.81488800","price":"791.25000000","side":"buy","client_oid":"de305764-5e06-4d5d-8adc-3f52ac94778d","product_id":"BCH-USD","sequence":4839272915,"time":"2018-07-27T01:32:41.694000Z"}
{"type":"open","side":"buy","price":"791.25000000","order_id":"dab78657-c4f3-4569-b9b8-5230e83d3fe6","remaining_size":"1.81488800","product_id":"BCH-USD","sequence":4839272916,"time":"2018-07-27T01:32:41.694000Z"}
{"type":"done","side":"sell","order_id":"daafab7f-2918-454d-870d-ea1b0c86f737","reason":"canceled","product_id":"BCH-USD","price":"795.06000000","remaining_size":"0.90000000","sequence":4839272917,"time":"2018-07-27T01:32:41.697000Z"}
{"type":"received","order_id":"f093505c-5263-4cdd-9d11-0cb1d95d2ad7","order_type":"limit","size":"0.90000000","price":"795.08000000","side":"sell","client_oid":"1cf5e396-8b9a-4b8d-998d-99b4431254a7","product_id":"BCH-USD","sequence":4839272918,"time":"2018-07-27T01:32:41.699000Z"}
{"type":"open","side":"sell","price":"795.08000000","order_id":"f093505c-5263-4cdd-9d11-0cb1d95d2ad7","remaining_size":"0.90000000","product_id":"BCH-USD","sequence":4839272919,"time":"2018-07-27T01:32:41.699000Z"}
{"type":"done","side":"sell","order_id":"3d4ae586-c458-42dc-9b48-c6406020b765","reason":"canceled","product_id":"BCH-USD","price":"795.06000000","remaining_size":"1.90000000","sequence":4839272920,"time":"2018-07-27T01:32:41.701000Z"}
{"type":"done","side":"sell","order_id":"f093505c-5263-4cdd-9d11-0cb1d95d2ad7","reason":"canceled","product_id":"BCH-USD","price":"795.08000000","remaining_size":"0.90000000","sequence":4839272921,"time":"2018-07-27T01:32:41.704000Z"}
{"type":"received","order_id":"f74b249a-ab12-413f-9359-23898c7183f6","order_type":"limit","size":"0.01000000","price":"462.77000000","side":"sell","client_oid":"63f8310e-8d0e-4670-bdb5-55f2841d0276","product_id":"ETH-USD","sequence":4469354825,"time":"2018-07-27T01:32:41.705000Z"}
{"type":"open","side":"sell","price":"462.77000000","order_id":"f74b249a-ab12-413f-9359-23898c7183f6","remaining_size":"0.01000000","product_id":"ETH-USD","sequence":4469354826,"time":"2018-07-27T01:32:41.705000Z"}
{"type":"received","order_id":"932481e1-2395-4d12-b119-70a804283682","order_type":"limit","size":"4.50000000","price":"795.67000000","side":"sell","client_oid":"76b3e51d-5496-4660-896f-663f9724ee04","product_id":"BCH-USD","sequence":4839272922,"time":"2018-07-27T01:32:41.707000Z"}
{"type":"open","side":"sell","price":"795.67000000","order_id":"932481e1-2395-4d12-b119-70a804283682","remaining_size":"4.50000000","product_id":"BCH-USD","sequence":4839272923,"time":"2018-07-27T01:32:41.707000Z"}
{"type":"received","order_id":"678244fd-9315-4ddf-bc71-3b3e2a99b7f4","order_type":"limit","size":"0.49000000","price":"83.11000000","side":"buy","client_oid":"413db8ae-1527-4721-89a6-4c4bfb17c553","product_id":"LTC-USD","sequence":2423271995,"time":"2018-07-27T01:32:41.710000Z"}
{"type":"received","order_id":"a0323cf4-baa0-4e6f-90d8-7c60d6c840fc","order_type":"limit","size":"1.90000000","price":"795.05000000","side":"sell","client_oid":"b35cf322-1e58-47f4-bc89-dbbb4c3fbea6","product_id":"BCH-USD","sequence":4839272924,"time":"2018-07-27T01:32:41.709000Z"}
{"type":"open","side":"buy","price":"83.11000000","order_id":"678244fd-9315-4ddf-bc71-3b3e2a99b7f4","remaining_size":"0.49000000","product_id":"LTC-USD","sequence":2423271996,"time":"2018-07-27T01:32:41.710000Z"}
{"type":"open","side":"sell","price":"795.05000000","order_id":"a0323cf4-baa0-4e6f-90d8-7c60d6c840fc","remaining_size":"1.90000000","product_id":"BCH-USD","sequence":4839272925,"time":"2018-07-27T01:32:41.709000Z"}
{"type":"done","side":"sell","order_id":"932481e1-2395-4d12-b119-70a804283682","reason":"canceled","product_id":"BCH-USD","price":"795.67000000","remaining_size":"4.50000000","sequence":4839272926,"time":"2018-07-27T01:32:41.711000Z"}
{"type":"received","order_id":"d5e4f860-4f63-4d48-ae26-88889db5d100","order_type":"limit","size":"0.90000000","price":"795.05000000","side":"sell","client_oid":"1bd7a663-32fd-4ad8-986a-e34a4b139eca","product_id":"BCH-USD","sequence":4839272927,"time":"2018-07-27T01:32:41.713000Z"}
{"type":"open","side":"sell","price":"795.05000000","order_id":"d5e4f860-4f63-4d48-ae26-88889db5d100","remaining_size":"0.90000000","product_id":"BCH-USD","sequence":4839272928,"time":"2018-07-27T01:32:41.713000Z"}
{"type":"done","side":"buy","order_id":"dab78657-c4f3-4569-b9b8-5230e83d3fe6","reason":"canceled","product_id":"BCH-USD","price":"791.25000000","remaining_size":"1.81488800","sequence":4839272929,"time":"2018-07-27T01:32:41.716000Z"}
{"type":"done","side":"sell","order_id":"7b3a4134-4fd4-47b4-90a3-864767adbc99","reason":"canceled","product_id":"BCH-USD","price":"795.05000000","remaining_size":"0.90000000","sequence":4839272930,"time":"2018-07-27T01:32:41.720000Z"}
{"type":"done","side":"sell","order_id":"34299092-908d-48ad-be99-d8229a614c67","reason":"canceled","product_id":"LTC-USD","price":"83.30000000","remaining_size":"7.44874862","sequence":2423271997,"time":"2018-07-27T01:32:41.722000Z"}
{"type":"received","order_id":"8bf84c9e-e95e-4145-8ba1-84cad71ae5e8","order_type":"limit","size":"4.50000000","price":"795.53000000","side":"sell","client_oid":"092867b4-a6bf-46f8-8a38-abfb500dfa3b","product_id":"BCH-USD","sequence":4839272931,"time":"2018-07-27T01:32:41.722000Z"}
{"type":"open","side":"sell","price":"795.53000000","order_id":"8bf84c9e-e95e-4145-8ba1-84cad71ae5e8","remaining_size":"4.50000000","product_id":"BCH-USD","sequence":4839272932,"time":"2018-07-27T01:32:41.722000Z"}
{"type":"received","order_id":"8eb06ad4-0567-4383-b920-0db727b7241a","order_type":"limit","size":"1.81488800","price":"791.23000000","side":"buy","client_oid":"bdde8d38-2e5d-4d59-94b5-37906eb3d69b","product_id":"BCH-USD","sequence":4839272933,"time":"2018-07-27T01:32:41.729000Z"}
{"type":"open","side":"buy","price":"791.23000000","order_id":"8eb06ad4-0567-4383-b920-0db727b7241a","remaining_size":"1.81488800","product_id":"BCH-USD","sequence":4839272934,"time":"2018-07-27T01:32:41.729000Z"}
{"type":"received","order_id":"88e31317-dd52-487c-8ed2-a1d6ba9a0ea1","order_type":"limit","size":"4.00725100","price":"83.03000000","side":"buy","client_oid":"ebf9fb50-0310-4a10-9819-e020da929b73","product_id":"LTC-USD","sequence":2423271998,"time":"2018-07-27T01:32:41.734000Z"}
{"type":"open","side":"buy","price":"83.03000000","order_id":"88e31317-dd52-487c-8ed2-a1d6ba9a0ea1","remaining_size":"4.00725100","product_id":"LTC-USD","sequence":2423271999,"time":"2018-07-27T01:32:41.734000Z"}
{"type":"done","side":"buy","order_id":"8eb06ad4-0567-4383-b920-0db727b7241a","reason":"canceled","product_id":"BCH-USD","price":"791.23000000","remaining_size":"1.81488800","sequence":4839272935,"time":"2018-07-27T01:32:41.735000Z"}
{"type":"done","side":"buy","order_id":"0e55f7e1-9205-408e-8875-8367a243e0b9","reason":"canceled","product_id":"BCH-USD","price":"791.23000000","remaining_size":"0.18739300","sequence":4839272936,"time":"2018-07-27T01:32:41.735000Z"}
{"type":"received","order_id":"bb549990-2ef4-4ee7-b260-56b2e7e4a4da","order_type":"limit","size":"1.81488800","price":"791.26000000","side":"buy","client_oid":"e2525c6b-9821-4faa-a974-fcdd67551b7d","product_id":"BCH-USD","sequence":4839272937,"time":"2018-07-27T01:32:41.740000Z"}
{"type":"open","side":"buy","price":"791.26000000","order_id":"bb549990-2ef4-4ee7-b260-56b2e7e4a4da","remaining_size":"1.81488800","product_id":"BCH-USD","sequence":4839272938,"time":"2018-07-27T01:32:41.740000Z"}
{"type":"done","side":"buy","order_id":"bb549990-2ef4-4ee7-b260-56b2e7e4a4da","reason":"canceled","product_id":"BCH-USD","price":"791.26000000","remaining_size":"1.81488800","sequence":4839272939,"time":"2018-07-27T01:32:41.743000Z"}
{"type":"received","order_id":"ec113ba8-d273-4a06-a280-8b64da9edf34","order_type":"limit","size":"7.39504000","price":"83.01000000","side":"buy","client_oid":"7e839d29-4e88-4c01-91b1-e853606750d9","product_id":"LTC-USD","sequence":2423272000,"time":"2018-07-27T01:32:41.746000Z"}
{"type":"done","side":"sell","order_id":"a0323cf4-baa0-4e6f-90d8-7c60d6c840fc","reason":"canceled","product_id":"BCH-USD","price":"795.05000000","remaining_size":"1.90000000","sequence":4839272940,"time":"2018-07-27T01:32:41.745000Z"}
{"type":"open","side":"buy","price":"83.01000000","order_id":"ec113ba8-d273-4a06-a280-8b64da9edf34","remaining_size":"7.39504000","product_id":"LTC-USD","sequence":2423272001,"time":"2018-07-27T01:32:41.746000Z"}
{"type":"done","side":"sell","order_id":"b5f79828-c232-4de5-84fc-00609883a233","reason":"canceled","product_id":"BCH-USD","price":"795.06000000","remaining_size":"0.90000000","sequence":4839272941,"time":"2018-07-27T01:32:41.745000Z"}
{"type":"done","side":"buy","order_id":"ea101b96-039a-4393-a752-d0d2689318e2","reason":"canceled","product_id":"ETH-USD","price":"437.60000000","remaining_size":"0.13000000","sequence":4469354827,"time":"2018-07-27T01:32:41.747000Z"}
{"type":"received","order_id":"a40de4d3-1e99-4053-98a4-7e39f84b7fb3","order_type":"limit","size":"1.81488800","price":"791.23000000","side":"buy","client_oid":"756c3556-28c0-485b-b79c-7db7b918bbfc","product_id":"BCH-USD","sequence":4839272942,"time":"2018-07-27T01:32:41.750000Z"}
{"type":"open","side":"buy","price":"791.23000000","order_id":"a40de4d3-1e99-4053-98a4-7e39f84b7fb3","remaining_size":"1.81488800","product_id":"BCH-USD","sequence":4839272943,"time":"2018-07-27T01:32:41.750000Z"}
{"type":"received","order_id":"b5f69a0c-4233-4eb6-93ba-cf4ecd7812f7","order_type":"limit","size":"4.50000000","price":"795.06000000","side":"sell","client_oid":"0d5b68cb-9ca1-46ce-ab09-6df2f5ae2700","product_id":"BCH-USD","sequence":4839272944,"time":"2018-07-27T01:32:41.753000Z"}
{"type":"open","side":"sell","price":"795.06000000","order_id":"b5f69a0c-4233-4eb6-93ba-cf4ecd7812f7","remaining_size":"4.50000000","product_id":"BCH-USD","sequence":4839272945,"time":"2018-07-27T01:32:41.753000Z"}
{"type":"received","order_id":"16e304fb-8eac-4cc2-8715-4ecb6f3b1096","order_type":"limit","size":"2.00000000","price":"792.80000000","side":"buy","client_oid":"b02e45b0-db58-449e-add6-5584f9e32bd6","product_id":"BCH-USD","sequence":4839272946,"time":"2018-07-27T01:32:41.755000Z"}
{"type":"open","side":"buy","price":"792.80000000","order_id":"16e304fb-8eac-4cc2-8715-4ecb6f3b1096","remaining_size":"2.00000000","product_id":"BCH-USD","sequence":4839272947,"time":"2018-07-27T01:32:41.755000Z"}
{"type":"received","order_id":"57c68b14-b789-4588-bf5e-fa4420d2b89a","order_type":"limit","size":"25.06599100","price":"82.95000000","side":"buy","client_oid":"0398e597-7785-4865-b7ae-c366293faef0","product_id":"LTC-USD","sequence":2423272002,"time":"2018-07-27T01:32:41.758000Z"}
{"type":"open","side":"buy","price":"82.95000000","order_id":"57c68b14-b789-4588-bf5e-fa4420d2b89a","remaining_size":"25.06599100","product_id":"LTC-USD","sequence":2423272003,"time":"2018-07-27T01:32:41.758000Z"}
{"type":"received","order_id":"c25edd63-05e0-42cc-9204-033048c5c359","order_type":"limit","size":"0.18739300","price":"791.25000000","side":"buy","client_oid":"b9ed7273-310b-4d5d-87d5-2fdf0e962b3e","product_id":"BCH-USD","sequence":4839272948,"time":"2018-07-27T01:32:41.759000Z"}
{"type":"open","side":"buy","price":"791.25000000","order_id":"c25edd63-05e0-42cc-9204-033048c5c359","remaining_size":"0.18739300","product_id":"BCH-USD","sequence":4839272949,"time":"2018-07-27T01:32:41.759000Z"}
{"type":"received","order_id":"3d43d592-ba22-4cd3-85fb-ca3f3347c498","order_type":"limit","size":"20.00000000","price":"82.99000000","side":"buy","client_oid":"73917b41-ce1b-47d9-a416-544d95785966","product_id":"LTC-USD","sequence":2423272004,"time":"2018-07-27T01:32:41.762000Z"}
{"type":"open","side":"buy","price":"82.99000000","order_id":"3d43d592-ba22-4cd3-85fb-ca3f3347c498","remaining_size":"20.00000000","product_id":"LTC-USD","sequence":2423272005,"time":"2018-07-27T01:32:41.762000Z"}
{"type":"received","order_id":"5564b010-777b-44c9-bde2-a2d0d875e5c2","order_type":"limit","size":"0.90000000","price":"795.04000000","side":"sell","client_oid":"30789ffc-bc41-4909-b30b-ca8b75881566","product_id":"BCH-USD","sequence":4839272950,"time":"2018-07-27T01:32:41.762000Z"}
{"type":"open","side":"sell","price":"795.04000000","order_id":"5564b010-777b-44c9-bde2-a2d0d875e5c2","remaining_size":"0.90000000","product_id":"BCH-USD","sequence":4839272951,"time":"2018-07-27T01:32:41.762000Z"}
{"type":"done","side":"buy","order_id":"a40de4d3-1e99-4053-98a4-7e39f84b7fb3","reason":"canceled","product_id":"BCH-USD","price":"791.23000000","remaining_size":"1.81488800","sequence":4839272952,"time":"2018-07-27T01:32:41.764000Z"}
{"type":"done","side":"sell","order_id":"b5f69a0c-4233-4eb6-93ba-cf4ecd7812f7","reason":"canceled","product_id":"BCH-USD","price":"795.06000000","remaining_size":"4.50000000","sequence":4839272953,"time":"2018-07-27T01:32:41.765000Z"}
{"type":"received","order_id":"263ab7d1-7378-47ab-b8f6-91a385e845af","order_type":"limit","size":"4.50000000","price":"795.04000000","side":"sell","client_oid":"aa24fc6d-04af-4020-9bc2-76b9e1f3a7cb","product_id":"BCH-USD","sequence":4839272954,"time":"2018-07-27T01:32:41.767000Z"}
{"type":"received","order_id":"0c87e408-8bd6-4a32-b64a-d4696d224147","order_type":"limit","size":"97.23664300","price":"82.93000000","side":"buy","client_oid":"aff02149-5592-4a6c-9771-b7ccab534296","product_id":"LTC-USD","sequence":2423272006,"time":"2018-07-27T01:32:41.769000Z"}
{"type":"open","side":"sell","price":"795.04000000","order_id":"263ab7d1-7378-47ab-b8f6-91a385e845af","remaining_size":"4.50000000","product_id":"BCH-USD","sequence":4839272955,"time":"2018-07-27T01:32:41.767000Z"}
{"type":"open","side":"buy","price":"82.93000000","order_id":"0c87e408-8bd6-4a32-b64a-d4696d224147","remaining_size":"97.23664300","product_id":"LTC-USD","sequence":2423272007,"time":"2018-07-27T01:32:41.769000Z"}
{"type":"done","side":"sell","order_id":"5564b010-777b-44c9-bde2-a2d0d875e5c2","reason":"canceled","product_id":"BCH-USD","price":"795.04000000","remaining_size":"0.90000000","sequence":4839272956,"time":"2018-07-27T01:32:41.768000Z"}
{"type":"received","order_id":"db36ba70-9c83-4f3b-9581-f8ec92f35cc0","order_type":"limit","size":"1.90000000","price":"795.04000000","side":"sell","client_oid":"938fcc9c-34f9-425d-be2d-741cbad89799","product_id":"BCH-USD","sequence":4839272957,"time":"2018-07-27T01:32:41.770000Z"}
{"type":"open","side":"sell","price":"795.04000000","order_id":"db36ba70-9c83-4f3b-9581-f8ec92f35cc0","remaining_size":"1.90000000","product_id":"BCH-USD","sequence":4839272958,"time":"2018-07-27T01:32:41.770000Z"}
{"type":"done","side":"sell","order_id":"263ab7d1-7378-47ab-b8f6-91a385e845af","reason":"canceled","product_id":"BCH-USD","price":"795.04000000","remaining_size":"4.50000000","sequence":4839272959,"time":"2018-07-27T01:32:41.771000Z"}
{"type":"received","order_id":"5003ff81-84b2-4204-ab78-0c618b24d2ff","order_type":"limit","size":"0.90000000","price":"795.05000000","side":"sell","client_oid":"4c53ef7c-ef8a-4471-b917-a72812ed3a36","product_id":"BCH-USD","sequence":4839272960,"time":"2018-07-27T01:32:41.774000Z"}
{"type":"open","side":"sell","price":"795.05000000","order_id":"5003ff81-84b2-4204-ab78-0c618b24d2ff","remaining_size":"0.90000000","product_id":"BCH-USD","sequence":4839272961,"time":"2018-07-27T01:32:41.774000Z"}
{"type":"received","order_id":"854f7af2-2774-4aa3-874c-376a0fa8ad4e","order_type":"limit","size":"136.38121400","price":"82.91000000","side":"buy","client_oid":"0c470121-469e-49ee-9b45-2f3fe5954f61","product_id":"LTC-USD","sequence":2423272008,"time":"2018-07-27T01:32:41.781000Z"}
{"type":"open","side":"buy","price":"82.91000000","order_id":"854f7af2-2774-4aa3-874c-376a0fa8ad4e","remaining_size":"136.38121400","product_id":"LTC-USD","sequence":2423272009,"time":"2018-07-27T01:32:41.781000Z"}
{"type":"received","order_id":"3e2fa121-86f3-40f8-97df-b3ce69ed85a3","order_type":"limit","size":"4.50000000","price":"795.05000000","side":"sell","client_oid":"732be6db-bb02-418d-bc7e-254a762238bf","product_id":"BCH-USD","sequence":4839272962,"time":"2018-07-27T01:32:41.782000Z"}
{"type":"done","side":"sell","order_id":"9dd2fa7a-f2dc-490c-b7ea-c978f79a93e7","reason":"canceled","product_id":"BTC-USD","price":"7907.52000000","remaining_size":"0.02500000","sequence":6418130287,"time":"2018-07-27T01:32:41.785000Z"}
{"type":"open","side":"sell","price":"795.05000000","order_id":"3e2fa121-86f3-40f8-97df-b3ce69ed85a3","remaining_size":"4.50000000","product_id":"BCH-USD","sequence":4839272963,"time":"2018-07-27T01:32:41.782000Z"}
{"type":"done","side":"buy","order_id":"16e304fb-8eac-4cc2-8715-4ecb6f3b1096","reason":"canceled","product_id":"BCH-USD","price":"792.80000000","remaining_size":"2.00000000","sequence":4839272964,"time":"2018-07-27T01:32:41.786000Z"}
{"type":"done","side":"sell","order_id":"db36ba70-9c83-4f3b-9581-f8ec92f35cc0","reason":"canceled","product_id":"BCH-USD","price":"795.04000000","remaining_size":"1.90000000","sequence":4839272965,"time":"2018-07-27T01:32:41.788000Z"}
{"type":"done","side":"sell","order_id":"9a19bf04-c6ec-4fee-8696-6aca4f4faa11","reason":"canceled","product_id":"BCH-USD","price":"795.14000000","remaining_size":"9.84600000","sequence":4839272966,"time":"2018-07-27T01:32:41.789000Z"}
{"type":"done","side":"buy","order_id":"c25edd63-05e0-42cc-9204-033048c5c359","reason":"canceled","product_id":"BCH-USD","price":"791.25000000","remaining_size":"0.18739300","sequence":4839272967,"time":"2018-07-27T01:32:41.789000Z"}
{"type":"done","side":"sell","order_id":"5003ff81-84b2-4204-ab78-0c618b24d2ff","reason":"canceled","product_id":"BCH-USD","price":"795.05000000","remaining_size":"0.90000000","sequence":4839272968,"time":"2018-07-27T01:32:41.790000Z"}
{"type":"received","order_id":"28686d77-1cd2-4f2f-8f27-9de421caacd5","order_type":"limit","size":"0.02500000","price":"7906.42000000","side":"sell","client_oid":"1ef5eb77-d3ba-4f38-8000-000f96bfa137","product_id":"BTC-USD","sequence":6418130288,"time":"2018-07-27T01:32:41.793000Z"}
{"type":"open","side":"sell","price":"7906.42000000","order_id":"28686d77-1cd2-4f2f-8f27-9de421caacd5","remaining_size":"0.02500000","product_id":"BTC-USD","sequence":6418130289,"time":"2018-07-27T01:32:41.793000Z"}
{"type":"done","side":"sell","order_id":"04f26861-2a5e-4350-a790-9fcff92a52cf","reason":"canceled","product_id":"LTC-USD","price":"83.34000000","remaining_size":"7.44874862","sequence":2423272010,"time":"2018-07-27T01:32:41.794000Z"}
{"type":"received","order_id":"4a2ee598-fe6c-4f4e-8279-6343a5352085","order_type":"limit","size":"20.72693600","price":"83.29000000","side":"sell","client_oid":"2658ad7d-e921-4c45-8eb6-cfe334b6f5e7","product_id":"LTC-USD","sequence":2423272011,"time":"2018-07-27T01:32:41.794000Z"}
{"type":"open","side":"sell","price":"83.29000000","order_id":"4a2ee598-fe6c-4f4e-8279-6343a5352085","remaining_size":"20.72693600","product_id":"LTC-USD","sequence":2423272012,"time":"2018-07-27T01:32:41.794000Z"}
{"type":"received","order_id":"ee63ea76-3e3d-4a5a-9326-d53fb7a539a2","order_type":"limit","size":"0.18739300","price":"791.23000000","side":"buy","client_oid":"f0e116e2-0906-4d6d-83fa-68ff9b98fbb7","product_id":"BCH-USD","sequence":4839272969,"time":"2018-07-27T01:32:41.795000Z"}
{"type":"open","side":"buy","price":"791.23000000","order_id":"ee63ea76-3e3d-4a5a-9326-d53fb7a539a2","remaining_size":"0.18739300","product_id":"BCH-USD","sequence":4839272970,"time":"2018-07-27T01:32:41.795000Z"}
{"type":"received","order_id":"cb2c1e79-51d2-4564-8f12-6fab10509068","order_type":"limit","size":"7.44874862","price":"83.38000000","side":"sell","client_oid":"3bcc8005-4e43-44cf-8000-00d62dd33630","product_id":"LTC-USD","sequence":2423272013,"time":"2018-07-27T01:32:41.801000Z"}
{"type":"open","side":"sell","price":"83.38000000","order_id":"cb2c1e79-51d2-4564-8f12-6fab10509068","remaining_size":"7.44874862","product_id":"LTC-USD","sequence":2423272014,"time":"2018-07-27T01:32:41.801000Z"}
{"type":"received","order_id":"42920f48-187c-4e3f-a8da-2daca5734728","order_type":"limit","size":"2.00000000","price":"792.54000000","side":"buy","client_oid":"58a80aa8-28ad-4725-bc96-d8f18f391d1c","product_id":"BCH-USD","sequence":4839272971,"time":"2018-07-27T01:32:41.800000Z"}
{"type":"open","side":"buy","price":"792.54000000","order_id":"42920f48-187c-4e3f-a8da-2daca5734728","remaining_size":"2.00000000","product_id":"BCH-USD","sequence":4839272972,"time":"2018-07-27T01:32:41.800000Z"}
{"type":"received","order_id":"9a526669-f44c-45fe-b99e-c4d903bc22e3","order_type":"limit","size":"1.81488800","price":"791.24000000","side":"buy","client_oid":"7ad35136-7f44-416b-ba00-9108142e73cb","product_id":"BCH-USD","sequence":4839272973,"time":"2018-07-27T01:32:41.804000Z"}
{"type":"open","side":"buy","price":"791.24000000","order_id":"9a526669-f44c-45fe-b99e-c4d903bc22e3","remaining_size":"1.81488800","product_id":"BCH-USD","sequence":4839272974,"time":"2018-07-27T01:32:41.804000Z"}
{"type":"received","order_id":"75f3c13c-91f6-4abb-8eb1-618018d5ac9e","order_type":"limit","size":"0.90000000","price":"795.04000000","side":"sell","client_oid":"b8fb1492-c66e-4cba-a77b-3e32ad741bcd","product_id":"BCH-USD","sequence":4839272975,"time":"2018-07-27T01:32:41.806000Z"}
{"type":"open","side":"sell","price":"795.04000000","order_id":"75f3c13c-91f6-4abb-8eb1-618018d5ac9e","remaining_size":"0.90000000","product_id":"BCH-USD","sequence":4839272976,"time":"2018-07-27T01:32:41.806000Z"}
{"type":"done","side":"buy","order_id":"9a526669-f44c-45fe-b99e-c4d903bc22e3","reason":"canceled","product_id":"BCH-USD","price":"791.24000000","remaining_size":"1.81488800","sequence":4839272977,"time":"2018-07-27T01:32:41.808000Z"}
{"type":"received","order_id":"02220c2a-7b9a-4cc3-8a92-bc47e6b9050f","order_type":"limit","size":"7.44874862","price":"83.30000000","side":"sell","client_oid":"2ecc1093-2787-4ae1-8000-0bf688715180","product_id":"LTC-USD","sequence":2423272015,"time":"2018-07-27T01:32:41.811000Z"}
{"type":"open","side":"sell","price":"83.30000000","order_id":"02220c2a-7b9a-4cc3-8a92-bc47e6b9050f","remaining_size":"7.44874862","product_id":"LTC-USD","sequence":2423272016,"time":"2018-07-27T01:32:41.811000Z"}
{"type":"done","side":"buy","order_id":"42920f48-187c-4e3f-a8da-2daca5734728","reason":"canceled","product_id":"BCH-USD","price":"792.54000000","remaining_size":"2.00000000","sequence":4839272978,"time":"2018-07-27T01:32:41.811000Z"}
{"type":"done","side":"buy","order_id":"3d43d592-ba22-4cd3-85fb-ca3f3347c498","reason":"canceled","product_id":"LTC-USD","price":"82.99000000","remaining_size":"20.00000000","sequence":2423272017,"time":"2018-07-27T01:32:41.812000Z"}
{"type":"done","side":"sell","order_id":"3e2fa121-86f3-40f8-97df-b3ce69ed85a3","reason":"canceled","product_id":"BCH-USD","price":"795.05000000","remaining_size":"4.50000000","sequence":4839272979,"time":"2018-07-27T01:32:41.813000Z"}
{"type":"done","side":"buy","order_id":"ee63ea76-3e3d-4a5a-9326-d53fb7a539a2","reason":"canceled","product_id":"BCH-USD","price":"791.23000000","remaining_size":"0.18739300","sequence":4839272980,"time":"2018-07-27T01:32:41.814000Z"}
{"type":"received","order_id":"b395bba0-c6a3-4e98-9624-64c747e5c909","order_type":"limit","size":"1.90000000","price":"795.05000000","side":"sell","client_oid":"1780e56e-b1cb-4547-aec4-699aeb4a9df4","product_id":"BCH-USD","sequence":4839272981,"time":"2018-07-27T01:32:41.815000Z"}
{"type":"open","side":"sell","price":"795.05000000","order_id":"b395bba0-c6a3-4e98-9624-64c747e5c909","remaining_size":"1.90000000","product_id":"BCH-USD","sequence":4839272982,"time":"2018-07-27T01:32:41.815000Z"}
{"type":"received","order_id":"6f43f93e-44a3-46e6-95ef-a1b149b1dbec","order_type":"limit","size":"20.00000000","price":"82.98000000","side":"buy","client_oid":"a36bd484-2940-40b9-895b-f5de101a3448","product_id":"LTC-USD","sequence":2423272018,"time":"2018-07-27T01:32:41.820000Z"}
{"type":"open","side":"buy","price":"82.98000000","order_id":"6f43f93e-44a3-46e6-95ef-a1b149b1dbec","remaining_size":"20.00000000","product_id":"LTC-USD","sequence":2423272019,"time":"2018-07-27T01:32:41.820000Z"}
{"type":"received","order_id":"f119d481-22c4-4d63-ac53-e5dd2e9dd79f","order_type":"limit","size":"20.66630200","price":"83.30000000","side":"sell","client_oid":"ff3a3ce7-94e6-4bb2-97f9-8a25fde5af0e","product_id":"LTC-USD","sequence":2423272020,"time":"2018-07-27T01:32:41.820000Z"}
{"type":"open","side":"sell","price":"83.30000000","order_id":"f119d481-22c4-4d63-ac53-e5dd2e9dd79f","remaining_size":"20.66630200","product_id":"LTC-USD","sequence":2423272021,"time":"2018-07-27T01:32:41.820000Z"}
{"type":"received","order_id":"54885de6-9151-4cc3-b145-651e15058b51","order_type":"limit","size":"1.81488800","price":"791.23000000","side":"buy","client_oid":"0817aa9f-94ff-4d8b-b4ba-ea64d3012bbb","product_id":"BCH-USD","sequence":4839272983,"time":"2018-07-27T01:32:41.819000Z"}
{"type":"open","side":"buy","price":"791.23000000","order_id":"54885de6-9151-4cc3-b145-651e15058b51","remaining_size":"1.81488800","product_id":"BCH-USD","sequence":4839272984,"time":"2018-07-27T01:32:41.819000Z"}
{"type":"received","order_id":"44d612fc-c6c8-4af4-90f1-3921b5cd7cd8","order_type":"limit","size":"0.18739300","price":"791.25000000","side":"buy","client_oid":"b5bef888-a567-4491-8e7c-d4997639a3a2","product_id":"BCH-USD","sequence":4839272985,"time":"2018-07-27T01:32:41.822000Z"}
{"type":"open","side":"buy","price":"791.25000000","order_id":"44d612fc-c6c8-4af4-90f1-3921b5cd7cd8","remaining_size":"0.18739300","product_id":"BCH-USD","sequence":4839272986,"time":"2018-07-27T01:32:41.822000Z"}
{"type":"done","side":"sell","order_id":"cb2c1e79-51d2-4564-8f12-6fab10509068","reason":"canceled","product_id":"LTC-USD","price":"83.38000000","remaining_size":"7.44874862","sequence":2423272022,"time":"2018-07-27T01:32:41.824000Z"}
{"type":"done","side":"buy","order_id":"44d612fc-c6c8-4af4-90f1-3921b5cd7cd8","reason":"canceled","product_id":"BCH-USD","price":"791.25000000","remaining_size":"0.18739300","sequence":4839272987,"time":"2018-07-27T01:32:41.824000Z"}
{"type":"received","order_id":"33a897c9-3788-468d-8e22-18532afaeb2f","order_type":"limit","size":"2.00000000","price":"792.80000000","side":"buy","client_oid":"393907f7-8131-4165-887a-66dd84c2cc68","product_id":"BCH-USD","sequence":4839272988,"time":"2018-07-27T01:32:41.825000Z"}
{"type":"open","side":"buy","price":"792.80000000","order_id":"33a897c9-3788-468d-8e22-18532afaeb2f","remaining_size":"2.00000000","product_id":"BCH-USD","sequence":4839272989,"time":"2018-07-27T01:32:41.825000Z"}
{"type":"received","order_id":"80854aae-8f2f-4c58-bb1f-0d37d4ab0885","order_type":"limit","size":"4.50000000","price":"795.04000000","side":"sell","client_oid":"072cce9e-dc3f-4238-84f1-752ca9acc297","product_id":"BCH-USD","sequence":4839272990,"time":"2018-07-27T01:32:41.828000Z"}
{"type":"open","side":"sell","price":"795.04000000","order_id":"80854aae-8f2f-4c58-bb1f-0d37d4ab0885","remaining_size":"4.50000000","product_id":"BCH-USD","sequence":4839272991,"time":"2018-07-27T01:32:41.828000Z"}
{"type":"received","order_id":"c9479b01-c825-4114-bf6f-5f3e17a972ae","order_type":"limit","size":"22.20393100","price":"83.32000000","side":"sell","client_oid":"d3b39959-5b91-4b8e-91ff-f99ca5bc2704","product_id":"LTC-USD","sequence":2423272023,"time":"2018-07-27T01:32:41.833000Z"}
{"type":"open","side":"sell","price":"83.32000000","order_id":"c9479b01-c825-4114-bf6f-5f3e17a972ae","remaining_size":"22.20393100","product_id":"LTC-USD","sequence":2423272024,"time":"2018-07-27T01:32:41.833000Z"}
{"type":"received","order_id":"cfb6a601-ea70-4fdb-85c2-96b5453adea1","order_type":"limit","size":"7.44874862","price":"83.34000000","side":"sell","client_oid":"765edf9b-f07c-47c8-8000-00274ada5674","product_id":"LTC-USD","sequence":2423272025,"time":"2018-07-27T01:32:41.835000Z"}
{"type":"open","side":"sell","price":"83.34000000","order_id":"cfb6a601-ea70-4fdb-85c2-96b5453adea1","remaining_size":"7.44874862","product_id":"LTC-USD","sequence":2423272026,"time":"2018-07-27T01:32:41.835000Z"}
{"type":"received","order_id":"ab0d7e3e-a2f2-4108-88b9-0ad3b4a97a9e","order_type":"limit","size":"8.90526000","price":"463.64000000","side":"sell","client_oid":"1b586819-74a6-4344-ae80-6999743cc2ea","product_id":"ETH-USD","sequence":4469354828,"time":"2018-07-27T01:32:41.836000Z"}
{"type":"open","side":"sell","price":"463.64000000","order_id":"ab0d7e3e-a2f2-4108-88b9-0ad3b4a97a9e","remaining_size":"8.90526000","product_id":"ETH-USD","sequence":4469354829,"time":"2018-07-27T01:32:41.836000Z"}
{"type":"done","side":"sell","order_id":"75f3c13c-91f6-4abb-8eb1-618018d5ac9e","reason":"canceled","product_id":"BCH-USD","price":"795.04000000","remaining_size":"0.90000000","sequence":4839272992,"time":"2018-07-27T01:32:41.838000Z"}
{"type":"done","side":"sell","order_id":"80854aae-8f2f-4c58-bb1f-0d37d4ab0885","reason":"canceled","product_id":"BCH-USD","price":"795.04000000","remaining_size":"4.50000000","sequence":4839272993,"time":"2018-07-27T01:32:41.838000Z"}
{"type":"done","side":"sell","order_id":"b395bba0-c6a3-4e98-9624-64c747e5c909","reason":"canceled","product_id":"BCH-USD","price":"795.05000000","remaining_size":"1.90000000","sequence":4839272994,"time":"2018-07-27T01:32:41.841000Z"}
{"type":"received","order_id":"ab88ccd7-fa7f-45e1-afd5-dd1eac320cde","order_type":"limit","size":"0.18739300","price":"791.23000000","side":"buy","client_oid":"559c22de-022d-465e-a2a4-f097427ecd7e","product_id":"BCH-USD","sequence":4839272995,"time":"2018-07-27T01:32:41.843000Z"}
{"type":"open","side":"buy","price":"791.23000000","order_id":"ab88ccd7-fa7f-45e1-afd5-dd1eac320cde","remaining_size":"0.18739300","product_id":"BCH-USD","sequence":4839272996,"time":"2018-07-27T01:32:41.843000Z"}
{"type":"received","order_id":"97651a00-713d-463e-8d19-d88b3079a38e","order_type":"limit","size":"110.59878700","price":"83.34000000","side":"sell","client_oid":"52a1f5a6-ad4f-4d89-8266-a4745ffbaeb3","product_id":"LTC-USD","sequence":2423272027,"time":"2018-07-27T01:32:41.847000Z"}
{"type":"open","side":"sell","price":"83.34000000","order_id":"97651a00-713d-463e-8d19-d88b3079a38e","remaining_size":"110.59878700","product_id":"LTC-USD","sequence":2423272028,"time":"2018-07-27T01:32:41.847000Z"}
{"type":"received","order_id":"ef02693d-6d0a-4877-8be5-c7012fff9ac3","order_type":"limit","size":"4.50000000","price":"795.03000000","side":"sell","client_oid":"c10e5230-3508-4aee-a76b-00de973b3d1a","product_id":"BCH-USD","sequence":4839272997,"time":"2018-07-27T01:32:41.847000Z"}
{"type":"open","side":"sell","price":"795.03000000","order_id":"ef02693d-6d0a-4877-8be5-c7012fff9ac3","remaining_size":"4.50000000","product_id":"BCH-USD","sequence":4839272998,"time":"2018-07-27T01:32:41.847000Z"}
{"type":"received","order_id":"46466ce4-8577-438d-af03-1d069cb594fd","order_type":"limit","size":"0.90000000","price":"795.03000000","side":"sell","client_oid":"6d55d3a9-da09-4a8a-bade-aee521044e6c","product_id":"BCH-USD","sequence":4839272999,"time":"2018-07-27T01:32:41.850000Z"}
{"type":"done","side":"sell","order_id":"02220c2a-7b9a-4cc3-8a92-bc47e6b9050f","reason":"canceled","product_id":"LTC-USD","price":"83.30000000","remaining_size":"7.44874862","sequence":2423272029,"time":"2018-07-27T01:32:41.852000Z"}
{"type":"open","side":"sell","price":"795.03000000","order_id":"46466ce4-8577-438d-af03-1d069cb594fd","remaining_size":"0.90000000","product_id":"BCH-USD","sequence":4839273000,"time":"2018-07-27T01:32:41.850000Z"}
{"type":"received","order_id":"0eb1ec32-b94d-49f8-a926-b723b2d3580e","order_type":"limit","size":"1.90000000","price":"795.03000000","side":"sell","client_oid":"a45f7563-0a55-4b89-8a02-2acbde9731bb","product_id":"BCH-USD","sequence":4839273001,"time":"2018-07-27T01:32:41.854000Z"}
{"type":"open","side":"sell","price":"795.03000000","order_id":"0eb1ec32-b94d-49f8-a926-b723b2d3580e","remaining_size":"1.90000000","product_id":"BCH-USD","sequence":4839273002,"time":"2018-07-27T01:32:41.854000Z"}
{"type":"received","order_id":"e73909c6-13eb-49b7-bcb3-c94804d62098","order_type":"limit","size":"13.42570300","price":"83.37000000","side":"sell","client_oid":"28d9b9d5-13c6-45b8-9384-953e577a11ce","product_id":"LTC-USD","sequence":2423272030,"time":"2018-07-27T01:32:41.858000Z"}
{"type":"open","side":"sell","price":"83.37000000","order_id":"e73909c6-13eb-49b7-bcb3-c94804d62098","remaining_size":"13.42570300","product_id":"LTC-USD","sequence":2423272031,"time":"2018-07-27T01:32:41.858000Z"}
{"type":"done","side":"buy","order_id":"6f43f93e-44a3-46e6-95ef-a1b149b1dbec","reason":"canceled","product_id":"LTC-USD","price":"82.98000000","remaining_size":"20.00000000","sequence":2423272032,"time":"2018-07-27T01:32:41.861000Z"}
{"type":"done","side":"sell","order_id":"d5e4f860-4f63-4d48-ae26-88889db5d100","reason":"canceled","product_id":"BCH-USD","price":"795.05000000","remaining_size":"0.90000000","sequence":4839273003,"time":"2018-07-27T01:32:41.861000Z"}
{"type":"done","side":"sell","order_id":"0eb1ec32-b94d-49f8-a926-b723b2d3580e","reason":"canceled","product_id":"BCH-USD","price":"795.03000000","remaining_size":"1.90000000","sequence":4839273004,"time":"2018-07-27T01:32:41.862000Z"}
{"type":"done","side":"buy","order_id":"ab88ccd7-fa7f-45e1-afd5-dd1eac320cde","reason":"canceled","product_id":"BCH-USD","price":"791.23000000","remaining_size":"0.18739300","sequence":4839273005,"time":"2018-07-27T01:32:41.863000Z"}
{"type":"received","order_id":"52200748-c304-4c2b-abdb-110ef0d1603d","order_type":"limit","size":"7.44874862","price":"83.38000000","side":"sell","client_oid":"05dcc986-120c-489d-8000-00449fb9cb2d","product_id":"LTC-USD","sequence":2423272033,"time":"2018-07-27T01:32:41.867000Z"}
{"type":"done","side":"sell","order_id":"46466ce4-8577-438d-af03-1d069cb594fd","reason":"canceled","product_id":"BCH-USD","price":"795.03000000","remaining_size":"0.90000000","sequence":4839273006,"time":"2018-07-27T01:32:41.866000Z"}
{"type":"open","side":"sell","price":"83.38000000","order_id":"52200748-c304-4c2b-abdb-110ef0d1603d","remaining_size":"7.44874862","product_id":"LTC-USD","sequence":2423272034,"time":"2018-07-27T01:32:41.867000Z"}
{"type":"done","side":"sell","order_id":"ef02693d-6d0a-4877-8be5-c7012fff9ac3","reason":"canceled","product_id":"BCH-USD","price":"795.03000000","remaining_size":"4.50000000","sequence":4839273007,"time":"2018-07-27T01:32:41.868000Z"}
{"type":"received","order_id":"cad6bafa-244c-4f07-b350-3e4294332303","order_type":"limit","size":"20.00000000","price":"82.99000000","side":"buy","client_oid":"e126b40d-9894-432e-aedb-b0b0aa484b72","product_id":"LTC-USD","sequence":2423272035,"time":"2018-07-27T01:32:41.871000Z"}
{"type":"received","order_id":"e74bdbb9-b548-4763-be99-6d05f3726ce4","order_type":"limit","size":"0.90000000","price":"795.04000000","side":"sell","client_oid":"7a87d65b-3c25-48c7-9151-bb0bce53af74","product_id":"BCH-USD","sequence":4839273008,"time":"2018-07-27T01:32:41.870000Z"}
{"type":"open","side":"sell","price":"795.04000000","order_id":"e74bdbb9-b548-4763-be99-6d05f3726ce4","remaining_size":"0.90000000","product_id":"BCH-USD","sequence":4839273009,"time":"2018-07-27T01:32:41.870000Z"}
{"type":"open","side":"buy","price":"82.99000000","order_id":"cad6bafa-244c-4f07-b350-3e4294332303","remaining_size":"20.00000000","product_id":"LTC-USD","sequence":2423272036,"time":"2018-07-27T01:32:41.871000Z"}
{"type":"done","side":"buy","order_id":"54885de6-9151-4cc3-b145-651e15058b51","reason":"canceled","product_id":"BCH-USD","price":"791.23000000","remaining_size":"1.81488800","sequence":4839273010,"time":"2018-07-27T01:32:41.872000Z"}
{"type":"received","order_id":"2081affd-11fb-4bf5-bb94-351ea44f8e35","order_type":"limit","size":"1.90000000","price":"795.02000000","side":"sell","client_oid":"ac45c649-bb5f-4137-8328-7bcf70ed7ae7","product_id":"BCH-USD","sequence":4839273011,"time":"2018-07-27T01:32:41.873000Z"}
{"type":"open","side":"sell","price":"795.02000000","order_id":"2081affd-11fb-4bf5-bb94-351ea44f8e35","remaining_size":"1.90000000","product_id":"BCH-USD","sequence":4839273012,"time":"2018-07-27T01:32:41.873000Z"}
{"type":"done","side":"sell","order_id":"ebd31150-d680-4b70-a6d6-0b9ef264af7e","reason":"canceled","product_id":"BCH-USD","price":"795.13000000","remaining_size":"1.90000000","sequence":4839273013,"time":"2018-07-27T01:32:41.873000Z"}
{"type":"done","side":"sell","order_id":"e74bdbb9-b548-4763-be99-6d05f3726ce4","reason":"canceled","product_id":"BCH-USD","price":"795.04000000","remaining_size":"0.90000000","sequence":4839273014,"time":"2018-07-27T01:32:41.874000Z"}
{"type":"received","order_id":"20ed90bf-bb6a-4fcb-a052-dd5290a0f879","order_type":"limit","size":"0.13000000","price":"437.60000000","side":"buy","product_id":"ETH-USD","sequence":4469354830,"time":"2018-07-27T01:32:41.879000Z"}
{"type":"open","side":"buy","price":"437.60000000","order_id":"20ed90bf-bb6a-4fcb-a052-dd5290a0f879","remaining_size":"0.13000000","product_id":"ETH-USD","sequence":4469354831,"time":"2018-07-27T01:32:41.879000Z"}
{"type":"done","side":"buy","order_id":"678244fd-9315-4ddf-bc71-3b3e2a99b7f4","reason":"canceled","product_id":"LTC-USD","price":"83.11000000","remaining_size":"0.49000000","sequence":2423272037,"time":"2018-07-27T01:32:41.882000Z"}
{"type":"received","order_id":"c97d6107-be77-40c4-9fdc-7ce222a73781","order_type":"limit","size":"0.90000000","price":"795.02000000","side":"sell","client_oid":"5ba0cc51-825c-4148-94cb-a7a83e96e8e3","product_id":"BCH-USD","sequence":4839273015,"time":"2018-07-27T01:32:41.882000Z"}
{"type":"open","side":"sell","price":"795.02000000","order_id":"c97d6107-be77-40c4-9fdc-7ce222a73781","remaining_size":"0.90000000","product_id":"BCH-USD","sequence":4839273016,"time":"2018-07-27T01:32:41.882000Z"}
{"type":"received","order_id":"2bff4fe3-0fb4-41fc-a40a-592ab94c4bd3","order_type":"limit","size":"0.18739300","price":"791.24000000","side":"buy","client_oid":"493d09c9-098c-4712-af1c-c0a86862dddf","product_id":"BCH-USD","sequence":4839273017,"time":"2018-07-27T01:32:41.882000Z"}
{"type":"open","side":"buy","price":"791.24000000","order_id":"2bff4fe3-0fb4-41fc-a40a-592ab94c4bd3","remaining_size":"0.18739300","product_id":"BCH-USD","sequence":4839273018,"time":"2018-07-27T01:32:41.882000Z"}
{"type":"done","side":"sell","order_id":"cfb6a601-ea70-4fdb-85c2-96b5453adea1","reason":"canceled","product_id":"LTC-USD","price":"83.34000000","remaining_size":"7.44874862","sequence":2423272038,"time":"2018-07-27T01:32:41.888000Z"}
{"type":"received","order_id":"e390b9e8-a3dd-4495-8e13-25051cdefca3","order_type":"limit","size":"1.90000000","price":"795.29000000","side":"sell","client_oid":"34075e1f-6e12-4e4d-b1e9-2e73d9dbe997","product_id":"BCH-USD","sequence":4839273019,"time":"2018-07-27T01:32:41.888000Z"}
{"type":"open","side":"sell","price":"795.29000000","order_id":"e390b9e8-a3dd-4495-8e13-25051cdefca3","remaining_size":"1.90000000","product_id":"BCH-USD","sequence":4839273020,"time":"2018-07-27T01:32:41.888000Z"}
{"type":"received","order_id":"29ca63f7-8ecb-47ff-87ac-d8349ce83088","order_type":"limit","size":"0.90000000","price":"795.02000000","side":"sell","client_oid":"0d0b03d3-50f0-455a-9ea7-724cd9191db4","product_id":"BCH-USD","sequence":4839273021,"time":"2018-07-27T01:32:41.891000Z"}
{"type":"open","side":"sell","price":"795.02000000","order_id":"29ca63f7-8ecb-47ff-87ac-d8349ce83088","remaining_size":"0.90000000","product_id":"BCH-USD","sequence":4839273022,"time":"2018-07-27T01:32:41.891000Z"}
{"type":"received","order_id":"4a6f3f92-70aa-42a5-bd6f-01fec4fbad5d","order_type":"limit","size":"1.81488800","price":"791.24000000","side":"buy","client_oid":"0ab36f11-7a47-4eec-9faf-24950733c665","product_id":"BCH-USD","sequence":4839273023,"time":"2018-07-27T01:32:41.891000Z"}
{"type":"open","side":"buy","price":"791.24000000","order_id":"4a6f3f92-70aa-42a5-bd6f-01fec4fbad5d","remaining_size":"1.81488800","product_id":"BCH-USD","sequence":4839273024,"time":"2018-07-27T01:32:41.891000Z"}
{"type":"done","side":"sell","order_id":"c97d6107-be77-40c4-9fdc-7ce222a73781","reason":"canceled","product_id":"BCH-USD","price":"795.02000000","remaining_size":"0.90000000","sequence":4839273025,"time":"2018-07-27T01:32:41.892000Z"}
{"type":"received","order_id":"b93b93d5-89f6-4e48-b7cb-f6287693a1c5","order_type":"limit","size":"4.50000000","price":"795.02000000","side":"sell","client_oid":"7c9d7202-3f1c-436c-aa6c-9109545367e1","product_id":"BCH-USD","sequence":4839273026,"time":"2018-07-27T01:32:41.895000Z"}
{"type":"open","side":"sell","price":"795.02000000","order_id":"b93b93d5-89f6-4e48-b7cb-f6287693a1c5","remaining_size":"4.50000000","product_id":"BCH-USD","sequence":4839273027,"time":"2018-07-27T01:32:41.895000Z"}
{"type":"done","side":"buy","order_id":"4a6f3f92-70aa-42a5-bd6f-01fec4fbad5d","reason":"canceled","product_id":"BCH-USD","price":"791.24000000","remaining_size":"1.81488800","sequence":4839273028,"time":"2018-07-27T01:32:41.898000Z"}
{"type":"received","order_id":"0f7bc2c2-af58-47f8-8fe7-8d3a0325de60","order_type":"limit","size":"7.44874862","price":"83.30000000","side":"sell","client_oid":"529d6ecd-f35c-46e7-8000-00cd7dbfd815","product_id":"LTC-USD","sequence":2423272039,"time":"2018-07-27T01:32:41.903000Z"}
{"type":"open","side":"sell","price":"83.30000000","order_id":"0f7bc2c2-af58-47f8-8fe7-8d3a0325de60","remaining_size":"7.44874862","product_id":"LTC-USD","sequence":2423272040,"time":"2018-07-27T01:32:41.903000Z"}
{"type":"received","order_id":"7d52dcd3-99b0-4610-b5a9-4e18b4609591","order_type":"limit","size":"0.90000000","price":"795.05000000","side":"sell","client_oid":"59e9d6c7-8c84-435d-9a6e-9d0edf312fb5","product_id":"BCH-USD","sequence":4839273029,"time":"2018-07-27T01:32:41.905000Z"}
{"type":"open","side":"sell","price":"795.05000000","order_id":"7d52dcd3-99b0-4610-b5a9-4e18b4609591","remaining_size":"0.90000000","product_id":"BCH-USD","sequence":4839273030,"time":"2018-07-27T01:32:41.905000Z"}
{"type":"done","side":"sell","order_id":"b93b93d5-89f6-4e48-b7cb-f6287693a1c5","reason":"canceled","product_id":"BCH-USD","price":"795.02000000","remaining_size":"4.50000000","sequence":4839273031,"time":"2018-07-27T01:32:41.907000Z"}
{"type":"done","side":"buy","order_id":"2bff4fe3-0fb4-41fc-a40a-592ab94c4bd3","reason":"canceled","product_id":"BCH-USD","price":"791.24000000","remaining_size":"0.18739300","sequence":4839273032,"time":"2018-07-27T01:32:41.909000Z"}
{"type":"done","side":"sell","order_id":"7d52dcd3-99b0-4610-b5a9-4e18b4609591","reason":"canceled","product_id":"BCH-USD","price":"795.05000000","remaining_size":"0.90000000","sequence":4839273033,"time":"2018-07-27T01:32:41.909000Z"}
{"type":"done","side":"sell","order_id":"2081affd-11fb-4bf5-bb94-351ea44f8e35","reason":"canceled","product_id":"BCH-USD","price":"795.02000000","remaining_size":"1.90000000","sequence":4839273034,"time":"2018-07-27T01:32:41.910000Z"}
{"type":"done","side":"sell","order_id":"29ca63f7-8ecb-47ff-87ac-d8349ce83088","reason":"canceled","product_id":"BCH-USD","price":"795.02000000","remaining_size":"0.90000000","sequence":4839273035,"time":"2018-07-27T01:32:41.912000Z"}
{"type":"received","order_id":"28070981-1536-4eac-9539-d48754655af6","order_type":"limit","size":"1.90000000","price":"795.01000000","side":"sell","client_oid":"60be1385-7d09-45ff-b94e-ae31cb36f6cd","product_id":"BCH-USD","sequence":4839273036,"time":"2018-07-27T01:32:41.914000Z"}
{"type":"open","side":"sell","price":"795.01000000","order_id":"28070981-1536-4eac-9539-d48754655af6","remaining_size":"1.90000000","product_id":"BCH-USD","sequence":4839273037,"time":"2018-07-27T01:32:41.914000Z"}
{"type":"received","order_id":"3902e3b9-6668-4b96-b0a6-31dda3db7ee3","order_type":"limit","size":"1.81488800","price":"791.23000000","side":"buy","client_oid":"b9d4489e-afde-4e61-8591-08e323f62649","product_id":"BCH-USD","sequence":4839273038,"time":"2018-07-27T01:32:41.914000Z"}
{"type":"open","side":"buy","price":"791.23000000","order_id":"3902e3b9-6668-4b96-b0a6-31dda3db7ee3","remaining_size":"1.81488800","product_id":"BCH-USD","sequence":4839273039,"time":"2018-07-27T01:32:41.914000Z"}
{"type":"done","side":"buy","order_id":"3902e3b9-6668-4b96-b0a6-31dda3db7ee3","reason":"canceled","product_id":"BCH-USD","price":"791.23000000","remaining_size":"1.81488800","sequence":4839273040,"time":"2018-07-27T01:32:41.917000Z"}
{"type":"received","order_id":"aaa4bcdb-44e2-46e8-94bd-6a6fcd140448","order_type":"limit","size":"4.50000000","price":"795.01000000","side":"sell","client_oid":"0fa1c8dc-e686-4b8d-91c3-1104eac90450","product_id":"BCH-USD","sequence":4839273041,"time":"2018-07-27T01:32:41.918000Z"}
{"type":"open","side":"sell","price":"795.01000000","order_id":"aaa4bcdb-44e2-46e8-94bd-6a6fcd140448","remaining_size":"4.50000000","product_id":"BCH-USD","sequence":4839273042,"time":"2018-07-27T01:32:41.918000Z"}
{"type":"done","side":"sell","order_id":"28070981-1536-4eac-9539-d48754655af6","reason":"canceled","product_id":"BCH-USD","price":"795.01000000","remaining_size":"1.90000000","sequence":4839273043,"time":"2018-07-27T01:32:41.921000Z"}
{"type":"done","side":"buy","order_id":"cad6bafa-244c-4f07-b350-3e4294332303","reason":"canceled","product_id":"LTC-USD","price":"82.99000000","remaining_size":"20.00000000","sequence":2423272041,"time":"2018-07-27T01:32:41.923000Z"}
{"type":"received","order_id":"88f49914-fad4-4c05-b26e-81aca476bc3d","order_type":"limit","size":"0.90000000","price":"795.01000000","side":"sell","client_oid":"49e99043-b3e1-49ba-a4e2-a7ec71cf9487","product_id":"BCH-USD","sequence":4839273044,"time":"2018-07-27T01:32:41.923000Z"}
{"type":"done","side":"sell","order_id":"52200748-c304-4c2b-abdb-110ef0d1603d","reason":"canceled","product_id":"LTC-USD","price":"83.38000000","remaining_size":"7.44874862","sequence":2423272042,"time":"2018-07-27T01:32:41.925000Z"}
{"type":"open","side":"sell","price":"795.01000000","order_id":"88f49914-fad4-4c05-b26e-81aca476bc3d","remaining_size":"0.90000000","product_id":"BCH-USD","sequence":4839273045,"time":"2018-07-27T01:32:41.923000Z"}
{"type":"done","side":"sell","order_id":"aaa4bcdb-44e2-46e8-94bd-6a6fcd140448","reason":"canceled","product_id":"BCH-USD","price":"795.01000000","remaining_size":"4.50000000","sequence":4839273046,"time":"2018-07-27T01:32:41.923000Z"}
{"type":"done","side":"sell","order_id":"88f49914-fad4-4c05-b26e-81aca476bc3d","reason":"canceled","product_id":"BCH-USD","price":"795.01000000","remaining_size":"0.90000000","sequence":4839273047,"time":"2018-07-27T01:32:41.927000Z"}
{"type":"received","order_id":"397dcc50-4a5a-4a1d-8d00-6d2af4cbec99","order_type":"limit","size":"1.81488800","price":"791.25000000","side":"buy","client_oid":"33a9d9b3-e883-4d68-bd0b-d7036fd44084","product_id":"BCH-USD","sequence":4839273048,"time":"2018-07-27T01:32:41.929000Z"}
{"type":"open","side":"buy","price":"791.25000000","order_id":"397dcc50-4a5a-4a1d-8d00-6d2af4cbec99","remaining_size":"1.81488800","product_id":"BCH-USD","sequence":4839273049,"time":"2018-07-27T01:32:41.929000Z"}
{"type":"received","order_id":"d809cf7a-9166-44f9-8c87-8bc5d165b6de","order_type":"limit","size":"0.18739300","price":"791.23000000","side":"buy","client_oid":"8643c85f-49cc-4998-b0e2-1430e0e2db91","product_id":"BCH-USD","sequence":4839273050,"time":"2018-07-27T01:32:41.930000Z"}
{"type":"open","side":"buy","price":"791.23000000","order_id":"d809cf7a-9166-44f9-8c87-8bc5d165b6de","remaining_size":"0.18739300","product_id":"BCH-USD","sequence":4839273051,"time":"2018-07-27T01:32:41.930000Z"}
{"type":"received","order_id":"8afadde5-fab4-4e9e-988e-c332625682ac","order_type":"limit","size":"0.90000000","price":"795.01000000","side":"sell","client_oid":"eaab6716-f8e5-458c-accb-18532f26c3f6","product_id":"BCH-USD","sequence":4839273052,"time":"2018-07-27T01:32:41.932000Z"}
{"type":"open","side":"sell","price":"795.01000000","order_id":"8afadde5-fab4-4e9e-988e-c332625682ac","remaining_size":"0.90000000","product_id":"BCH-USD","sequence":4839273053,"time":"2018-07-27T01:32:41.932000Z"}
{"type":"done","side":"buy","order_id":"397dcc50-4a5a-4a1d-8d00-6d2af4cbec99","reason":"canceled","product_id":"BCH-USD","price":"791.25000000","remaining_size":"1.81488800","sequence":4839273054,"time":"2018-07-27T01:32:41.932000Z"}
{"type":"received","order_id":"c88848bf-41da-4f50-935f-eac70d0c9996","order_type":"limit","size":"20.00000000","price":"82.98000000","side":"buy","client_oid":"6c7312e9-9b3c-4c4e-83ad-171122d09d4e","product_id":"LTC-USD","sequence":2423272043,"time":"2018-07-27T01:32:41.935000Z"}
{"type":"open","side":"buy","price":"82.98000000","order_id":"c88848bf-41da-4f50-935f-eac70d0c9996","remaining_size":"20.00000000","product_id":"LTC-USD","sequence":2423272044,"time":"2018-07-27T01:32:41.935000Z"}
{"type":"received","order_id":"f6d7dd70-a0da-4d18-b058-527062daa7dc","order_type":"limit","size":"0.90000000","price":"795.05000000","side":"sell","client_oid":"ae7c5fca-f282-4b0e-b0ad-ff84193c678d","product_id":"BCH-USD","sequence":4839273055,"time":"2018-07-27T01:32:41.938000Z"}
{"type":"received","order_id":"b1b08c27-4af0-40a2-943a-e65660d35a8d","order_type":"limit","size":"7.44874862","price":"83.34000000","side":"sell","client_oid":"a989af83-1bf6-4beb-8000-004c5bf93552","product_id":"LTC-USD","sequence":2423272045,"time":"2018-07-27T01:32:41.940000Z"}
{"type":"open","side":"sell","price":"795.05000000","order_id":"f6d7dd70-a0da-4d18-b058-527062daa7dc","remaining_size":"0.90000000","product_id":"BCH-USD","sequence":4839273056,"time":"2018-07-27T01:32:41.938000Z"}
{"type":"open","side":"sell","price":"83.34000000","order_id":"b1b08c27-4af0-40a2-943a-e65660d35a8d","remaining_size":"7.44874862","product_id":"LTC-USD","sequence":2423272046,"time":"2018-07-27T01:32:41.940000Z"}
{"type":"done","side":"buy","order_id":"fd735fc8-e63a-45fe-ba5f-db0c7e9ccde3","reason":"canceled","product_id":"BTC-USD","price":"7895.00000000","remaining_size":"1.00000000","sequence":6418130290,"time":"2018-07-27T01:32:41.943000Z"}
{"type":"received","order_id":"316e3971-bf5e-4a15-8d37-30ed21e48320","order_type":"limit","size":"1.81488800","price":"791.24000000","side":"buy","client_oid":"bd4ca176-7d21-4cdc-84ec-c87d5071520d","product_id":"BCH-USD","sequence":4839273057,"time":"2018-07-27T01:32:41.943000Z"}
{"type":"open","side":"buy","price":"791.24000000","order_id":"316e3971-bf5e-4a15-8d37-30ed21e48320","remaining_size":"1.81488800","product_id":"BCH-USD","sequence":4839273058,"time":"2018-07-27T01:32:41.943000Z"}
{"type":"received","order_id":"38f0a3f4-550f-4513-b75a-d2c05182cf8f","order_type":"limit","size":"4.50000000","price":"795.05000000","side":"sell","client_oid":"3313de7b-31a4-432b-8e39-781456d67d10","product_id":"BCH-USD","sequence":4839273059,"time":"2018-07-27T01:32:41.947000Z"}
{"type":"open","side":"sell","price":"795.05000000","order_id":"38f0a3f4-550f-4513-b75a-d2c05182cf8f","remaining_size":"4.50000000","product_id":"BCH-USD","sequence":4839273060,"time":"2018-07-27T01:32:41.947000Z"}
{"type":"done","side":"buy","order_id":"316e3971-bf5e-4a15-8d37-30ed21e48320","reason":"canceled","product_id":"BCH-USD","price":"791.24000000","remaining_size":"1.81488800","sequence":4839273061,"time":"2018-07-27T01:32:41.947000Z"}
{"type":"done","side":"sell","order_id":"bdbef066-13c2-409a-b3af-f2a8df0fe64e","reason":"canceled","product_id":"ETH-USD","price":"462.77000000","remaining_size":"0.27000000","sequence":4469354832,"time":"2018-07-27T01:32:41.951000Z"}
{"type":"done","side":"sell","order_id":"f74b249a-ab12-413f-9359-23898c7183f6","reason":"canceled","product_id":"ETH-USD","price":"462.77000000","remaining_size":"0.01000000","sequence":4469354833,"time":"2018-07-27T01:32:41.953000Z"}
{"type":"done","side":"sell","order_id":"8afadde5-fab4-4e9e-988e-c332625682ac","reason":"canceled","product_id":"BCH-USD","price":"795.01000000","remaining_size":"0.90000000","sequence":4839273062,"time":"2018-07-27T01:32:41.952000Z"}
{"type":"received","order_id":"e9016242-9bfc-4d8e-aa39-a9048728526f","order_type":"limit","size":"1.81488800","price":"791.23000000","side":"buy","client_oid":"c735b98e-973d-4209-bacb-e5807857df65","product_id":"BCH-USD","sequence":4839273063,"time":"2018-07-27T01:32:41.955000Z"}
{"type":"open","side":"buy","price":"791.23000000","order_id":"e9016242-9bfc-4d8e-aa39-a9048728526f","remaining_size":"1.81488800","product_id":"BCH-USD","sequence":4839273064,"time":"2018-07-27T01:32:41.955000Z"}
{"type":"done","side":"buy","order_id":"d809cf7a-9166-44f9-8c87-8bc5d165b6de","reason":"canceled","product_id":"BCH-USD","price":"791.23000000","remaining_size":"0.18739300","sequence":4839273065,"time":"2018-07-27T01:32:41.955000Z"}
{"type":"received","order_id":"f2775f4f-6ff1-4409-b83a-c95c8a63d384","order_type":"limit","size":"1.90000000","price":"795.05000000","side":"sell","client_oid":"0f84e374-3391-4683-af51-dcc62a0de531","product_id":"BCH-USD","sequence":4839273066,"time":"2018-07-27T01:32:41.958000Z"}
{"type":"open","side":"sell","price":"795.05000000","order_id":"f2775f4f-6ff1-4409-b83a-c95c8a63d384","remaining_size":"1.90000000","product_id":"BCH-USD","sequence":4839273067,"time":"2018-07-27T01:32:41.958000Z"}
{"type":"done","side":"buy","order_id":"e9016242-9bfc-4d8e-aa39-a9048728526f","reason":"canceled","product_id":"BCH-USD","price":"791.23000000","remaining_size":"1.81488800","sequence":4839273068,"time":"2018-07-27T01:32:41.960000Z"}
{"type":"done","side":"sell","order_id":"0f7bc2c2-af58-47f8-8fe7-8d3a0325de60","reason":"canceled","product_id":"LTC-USD","price":"83.30000000","remaining_size":"7.44874862","sequence":2423272047,"time":"2018-07-27T01:32:41.963000Z"}
{"type":"done","side":"sell","order_id":"f2775f4f-6ff1-4409-b83a-c95c8a63d384","reason":"canceled","product_id":"BCH-USD","price":"795.05000000","remaining_size":"1.90000000","sequence":4839273069,"time":"2018-07-27T01:32:41.963000Z"}
{"type":"done","side":"sell","order_id":"f6d7dd70-a0da-4d18-b058-527062daa7dc","reason":"canceled","product_id":"BCH-USD","price":"795.05000000","remaining_size":"0.90000000","sequence":4839273070,"time":"2018-07-27T01:32:41.963000Z"}
{"type":"received","order_id":"4e1c8cb8-20ae-47c4-8d02-a358c6132c83","order_type":"limit","size":"1.81488800","price":"791.25000000","side":"buy","client_oid":"49061aad-b1ff-40bd-9dcb-37efe2098d48","product_id":"BCH-USD","sequence":4839273071,"time":"2018-07-27T01:32:41.965000Z"}
{"type":"open","side":"buy","price":"791.25000000","order_id":"4e1c8cb8-20ae-47c4-8d02-a358c6132c83","remaining_size":"1.81488800","product_id":"BCH-USD","sequence":4839273072,"time":"2018-07-27T01:32:41.965000Z"}
{"type":"done","side":"sell","order_id":"38f0a3f4-550f-4513-b75a-d2c05182cf8f","reason":"canceled","product_id":"BCH-USD","price":"795.05000000","remaining_size":"4.50000000","sequence":4839273073,"time":"2018-07-27T01:32:41.967000Z"}
{"type":"received","order_id":"5777e196-9cf0-41f1-aceb-e0b9390c55c1","order_type":"limit","size":"0.90000000","price":"795.05000000","side":"sell","client_oid":"722a6458-347f-439d-96a8-06a041a70249","product_id":"BCH-USD","sequence":4839273074,"time":"2018-07-27T01:32:41.968000Z"}
{"type":"open","side":"sell","price":"795.05000000","order_id":"5777e196-9cf0-41f1-aceb-e0b9390c55c1","remaining_size":"0.90000000","product_id":"BCH-USD","sequence":4839273075,"time":"2018-07-27T01:32:41.968000Z"}
{"type":"done","side":"sell","order_id":"5777e196-9cf0-41f1-aceb-e0b9390c55c1","reason":"canceled","product_id":"BCH-USD","price":"795.05000000","remaining_size":"0.90000000","sequence":4839273076,"time":"2018-07-27T01:32:41.971000Z"}
{"type":"done","side":"buy","order_id":"b8cff66e-9b8c-47f2-b812-633854c4e708","reason":"canceled","product_id":"BCH-USD","price":"788.72000000","remaining_size":"0.13840200","sequence":4839273077,"time":"2018-07-27T01:32:41.972000Z"}
{"type":"received","order_id":"817e549d-54d0-4233-adf6-7469780a405c","order_type":"limit","size":"0.18739300","price":"791.25000000","side":"buy","client_oid":"f606bd2e-6cd4-43b1-a735-7a7835278dad","product_id":"BCH-USD","sequence":4839273078,"time":"2018-07-27T01:32:41.974000Z"}
{"type":"open","side":"buy","price":"791.25000000","order_id":"817e549d-54d0-4233-adf6-7469780a405c","remaining_size":"0.18739300","product_id":"BCH-USD","sequence":4839273079,"time":"2018-07-27T01:32:41.974000Z"}
{"type":"received","order_id":"a5ce706a-d090-428d-b5fb-de6d94904110","order_type":"limit","size":"7.44874862","price":"83.38000000","side":"sell","client_oid":"b03e8fe4-8a9c-4a55-8000-00794d5f5522","product_id":"LTC-USD","sequence":2423272048,"time":"2018-07-27T01:32:41.980000Z"}
{"type":"open","side":"sell","price":"83.38000000","order_id":"a5ce706a-d090-428d-b5fb-de6d94904110","remaining_size":"7.44874862","product_id":"LTC-USD","sequence":2423272049,"time":"2018-07-27T01:32:41.980000Z"}
{"type":"done","side":"sell","order_id":"b1b08c27-4af0-40a2-943a-e65660d35a8d","reason":"canceled","product_id":"LTC-USD","price":"83.34000000","remaining_size":"7.44874862","sequence":2423272050,"time":"2018-07-27T01:32:41.985000Z"}
{"type":"done","side":"buy","order_id":"812d7856-18df-4a62-829b-265ef178d4a2","reason":"canceled","product_id":"BCH-USD","price":"788.48000000","remaining_size":"0.19532500","sequence":4839273080,"time":"2018-07-27T01:32:41.984000Z"}
{"type":"done","side":"buy","order_id":"c88848bf-41da-4f50-935f-eac70d0c9996","reason":"canceled","product_id":"LTC-USD","price":"82.98000000","remaining_size":"20.00000000","sequence":2423272051,"time":"2018-07-27T01:32:41.988000Z"}
{"type":"done","side":"buy","order_id":"4591ab56-40de-4013-9512-b332cd97e32e","reason":"canceled","product_id":"BCH-USD","price":"788.24000000","remaining_size":"2.82955100","sequence":4839273081,"time":"2018-07-27T01:32:41.988000Z"}
{"type":"received","order_id":"8248f7e7-cf2f-42ee-95df-24b3bc8bf851","order_type":"limit","size":"1.90000000","price":"795.04000000","side":"sell","client_oid":"6dbd483e-9d2b-4f45-bcfe-8963f786115f","product_id":"BCH-USD","sequence":4839273082,"time":"2018-07-27T01:32:41.990000Z"}
{"type":"open","side":"sell","price":"795.04000000","order_id":"8248f7e7-cf2f-42ee-95df-24b3bc8bf851","remaining_size":"1.90000000","product_id":"BCH-USD","sequence":4839273083,"time":"2018-07-27T01:32:41.990000Z"}
{"type":"received","order_id":"43657789-c88e-4026-882c-64457d2ce6e1","order_type":"limit","size":"0.90000000","price":"795.04000000","side":"sell","client_oid":"1a9c81e9-57ee-4d98-b97c-85ad0f3369cb","product_id":"BCH-USD","sequence":4839273084,"time":"2018-07-27T01:32:41.991000Z"}
{"type":"open","side":"sell","price":"795.04000000","order_id":"43657789-c88e-4026-882c-64457d2ce6e1","remaining_size":"0.90000000","product_id":"BCH-USD","sequence":4839273085,"time":"2018-07-27T01:32:41.991000Z"}
{"type":"received","order_id":"3aba9943-5ab7-483a-8c72-2b2a07e29c5f","order_type":"limit","size":"0.90000000","price":"795.04000000","side":"sell","client_oid":"3346b7e0-d09f-4462-a8cd-705b0369db96","product_id":"BCH-USD","sequence":4839273086,"time":"2018-07-27T01:32:41.992000Z"}
{"type":"open","side":"sell","price":"795.04000000","order_id":"3aba9943-5ab7-483a-8c72-2b2a07e29c5f","remaining_size":"0.90000000","product_id":"BCH-USD","sequence":4839273087,"time":"2018-07-27T01:32:41.992000Z"}
{"type":"done","side":"buy","order_id":"87f03390-3818-40ff-afeb-a5350a52eacf","reason":"canceled","product_id":"BCH-USD","price":"788.00000000","remaining_size":"0.22367600","sequence":4839273088,"time":"2018-07-27T01:32:41.993000Z"}
{"type":"done","side":"sell","order_id":"8248f7e7-cf2f-42ee-95df-24b3bc8bf851","reason":"canceled","product_id":"BCH-USD","price":"795.04000000","remaining_size":"1.90000000","sequence":4839273089,"time":"2018-07-27T01:32:41.995000Z"}
{"type":"done","side":"buy","order_id":"aa69a888-ff8b-47cb-967e-06c0b7fe923b","reason":"canceled","product_id":"BCH-USD","price":"787.52000000","remaining_size":"1.57083900","sequence":4839273090,"time":"2018-07-27T01:32:41.996000Z"}
{"type":"received","order_id":"671e8ee0-21d7-4635-88fe-20648853f608","order_type":"limit","size":"4.50000000","price":"795.04000000","side":"sell","client_oid":"7a3e89fe-77f8-4f55-9d9d-3ead009f0958","product_id":"BCH-USD","sequence":4839273091,"time":"2018-07-27T01:32:41.996000Z"}
{"type":"open","side":"sell","price":"795.04000000","order_id":"671e8ee0-21d7-4635-88fe-20648853f608","remaining_size":"4.50000000","product_id":"BCH-USD","sequence":4839273092,"time":"2018-07-27T01:32:41.996000Z"}
{"type":"done","side":"sell","order_id":"43657789-c88e-4026-882c-64457d2ce6e1","reason":"canceled","product_id":"BCH-USD","price":"795.04000000","remaining_size":"0.90000000","sequence":4839273093,"time":"2018-07-27T01:32:41.997000Z"}
{"type":"received","order_id":"1722b4b7-928e-4777-b69e-854dcb9e8230","order_type":"limit","size":"7.44874862","price":"83.30000000","side":"sell","client_oid":"dd9c1b00-5a57-42f2-8000-05325f34e9b0","product_id":"LTC-USD","sequence":2423272052,"time":"2018-07-27T01:32:42.000000Z"}
{"type":"open","side":"sell","price":"83.30000000","order_id":"1722b4b7-928e-4777-b69e-854dcb9e8230","remaining_size":"7.44874862","product_id":"LTC-USD","sequence":2423272053,"time":"2018-07-27T01:32:42.000000Z"}
{"type":"done","side":"sell","order_id":"3aba9943-5ab7-483a-8c72-2b2a07e29c5f","reason":"canceled","product_id":"BCH-USD","price":"795.04000000","remaining_size":"0.90000000","sequence":4839273094,"time":"2018-07-27T01:32:42.000000Z"}
{"type":"received","order_id":"a6b3d955-9b2a-4ddb-8437-255255bee067","order_type":"limit","size":"20.00000000","price":"82.99000000","side":"buy","client_oid":"15009f25-e53a-4d0b-9415-3e0731055e5e","product_id":"LTC-USD","sequence":2423272054,"time":"2018-07-27T01:32:42.002000Z"}
{"type":"open","side":"buy","price":"82.99000000","order_id":"a6b3d955-9b2a-4ddb-8437-255255bee067","remaining_size":"20.00000000","product_id":"LTC-USD","sequence":2423272055,"time":"2018-07-27T01:32:42.002000Z"}
{"type":"received","order_id":"f0a7991f-e623-4c85-82a2-51aa85f53f8b","order_type":"limit","size":"0.90000000","price":"795.05000000","side":"sell","client_oid":"27cf70eb-3806-4d18-a040-428d1b0a1798","product_id":"BCH-USD","sequence":4839273095,"time":"2018-07-27T01:32:42.003000Z"}
{"type":"open","side":"sell","price":"795.05000000","order_id":"f0a7991f-e623-4c85-82a2-51aa85f53f8b","remaining_size":"0.90000000","product_id":"BCH-USD","sequence":4839273096,"time":"2018-07-27T01:32:42.003000Z"}
{"type":"done","side":"buy","order_id":"817e549d-54d0-4233-adf6-7469780a405c","reason":"canceled","product_id":"BCH-USD","price":"791.25000000","remaining_size":"0.18739300","sequence":4839273097,"time":"2018-07-27T01:32:42.003000Z"}
{"type":"done","side":"buy","order_id":"4e1c8cb8-20ae-47c4-8d02-a358c6132c83","reason":"canceled","product_id":"BCH-USD","price":"791.25000000","remaining_size":"1.81488800","sequence":4839273098,"time":"2018-07-27T01:32:42.005000Z"}
{"type":"done","side":"sell","order_id":"f0a7991f-e623-4c85-82a2-51aa85f53f8b","reason":"canceled","product_id":"BCH-USD","price":"795.05000000","remaining_size":"0.90000000","sequence":4839273099,"time":"2018-07-27T01:32:42.007000Z"}
{"type":"received","order_id":"ba74ebe1-ea81-4204-8813-8fbf7d720f41","order_type":"limit","size":"1.90000000","price":"795.05000000","side":"sell","client_oid":"724f1f78-a5c6-4131-8fd6-e0ad0ba35e4e","product_id":"BCH-USD","sequence":4839273100,"time":"2018-07-27T01:32:42.007000Z"}
{"type":"open","side":"sell","price":"795.05000000","order_id":"ba74ebe1-ea81-4204-8813-8fbf7d720f41","remaining_size":"1.90000000","product_id":"BCH-USD","sequence":4839273101,"time":"2018-07-27T01:32:42.007000Z"}
{"type":"done","side":"sell","order_id":"9b1944da-4851-465d-9af1-604660e7400b","reason":"canceled","product_id":"ETH-USD","price":"484.72000000","remaining_size":"0.01000000","sequence":4469354834,"time":"2018-07-27T01:32:42.011000Z"}
{"type":"done","side":"sell","order_id":"ba74ebe1-ea81-4204-8813-8fbf7d720f41","reason":"canceled","product_id":"BCH-USD","price":"795.05000000","remaining_size":"1.90000000","sequence":4839273102,"time":"2018-07-27T01:32:42.010000Z"}
{"type":"done","side":"sell","order_id":"a5ce706a-d090-428d-b5fb-de6d94904110","reason":"canceled","product_id":"LTC-USD","price":"83.38000000","remaining_size":"7.44874862","sequence":2423272056,"time":"2018-07-27T01:32:42.013000Z"}
{"type":"done","side":"sell","order_id":"1344bd89-5add-4dc6-9027-fd2e516a23cd","reason":"canceled","product_id":"ETH-USD","price":"462.77000000","remaining_size":"0.02000000","sequence":4469354835,"time":"2018-07-27T01:32:42.013000Z"}
{"type":"done","side":"sell","order_id":"671e8ee0-21d7-4635-88fe-20648853f608","reason":"canceled","product_id":"BCH-USD","price":"795.04000000","remaining_size":"4.50000000","sequence":4839273103,"time":"2018-07-27T01:32:42.014000Z"}
{"type":"done","side":"buy","order_id":"a6b3d955-9b2a-4ddb-8437-255255bee067","reason":"canceled","product_id":"LTC-USD","price":"82.99000000","remaining_size":"20.00000000","sequence":2423272057,"time":"2018-07-27T01:32:42.023000Z"}
{"type":"done","side":"buy","order_id":"c1d0350d-b7df-47c5-a784-a3ec87c3e7de","reason":"canceled","product_id":"BTC-USD","price":"6599.01000000","remaining_size":"0.00150000","sequence":6418130291,"time":"2018-07-27T01:32:42.034000Z"}
{"type":"done","side":"sell","order_id":"1722b4b7-928e-4777-b69e-854dcb9e8230","reason":"canceled","product_id":"LTC-USD","price":"83.30000000","remaining_size":"7.44874862","sequence":2423272058,"time":"2018-07-27T01:32:42.039000Z"}
{"type":"received","order_id":"9a9cfcf8-0789-4a97-afa4-94cf49c175c5","order_type":"limit","size":"1.81488800","price":"791.26000000","side":"buy","client_oid":"2e9cefbe-8575-444b-b1a5-93fa4586f59f","product_id":"BCH-USD","sequence":4839273104,"time":"2018-07-27T01:32:42.102000Z"}
{"type":"received","order_id":"ad7453a1-2465-4c0b-bf3e-cdfef8a72691","order_type":"limit","size":"7.44874862","price":"83.34000000","side":"sell","client_oid":"f9b863bd-a3a7-4046-8000-00378f6b9e70","product_id":"LTC-USD","sequence":2423272059,"time":"2018-07-27T01:32:42.104000Z"}
{"type":"open","side":"buy","price":"791.26000000","order_id":"9a9cfcf8-0789-4a97-afa4-94cf49c175c5","remaining_size":"1.81488800","product_id":"BCH-USD","sequence":4839273105,"time":"2018-07-27T01:32:42.102000Z"}
{"type":"received","order_id":"b0e0a32e-e49e-4dfd-bdef-7eece5a322ac","order_type":"limit","size":"0.16458200","price":"790.16000000","side":"buy","client_oid":"7d9929c8-e664-42a2-b0d5-c0a242bf1a74","product_id":"BCH-USD","sequence":4839273106,"time":"2018-07-27T01:32:42.103000Z"}
{"type":"open","side":"sell","price":"83.34000000","order_id":"ad7453a1-2465-4c0b-bf3e-cdfef8a72691","remaining_size":"7.44874862","product_id":"LTC-USD","sequence":2423272060,"time":"2018-07-27T01:32:42.104000Z"}
{"type":"open","side":"buy","price":"790.16000000","order_id":"b0e0a32e-e49e-4dfd-bdef-7eece5a322ac","remaining_size":"0.16458200","product_id":"BCH-USD","sequence":4839273107,"time":"2018-07-27T01:32:42.103000Z"}
{"type":"received","order_id":"28dcec1b-ed51-41d0-bcac-5936b13305d4","order_type":"limit","size":"0.90000000","price":"795.05000000","side":"sell","client_oid":"6f29f614-4fa4-415b-9f6c-99a716660a9e","product_id":"BCH-USD","sequence":4839273108,"time":"2018-07-27T01:32:42.110000Z"}
{"type":"received","order_id":"1827522a-62c2-4b67-804f-23553a0f3853","order_type":"limit","size":"20.00000000","price":"82.98000000","side":"buy","client_oid":"b5646e6b-b726-442b-bdd4-cd14ce29823e","product_id":"LTC-USD","sequence":2423272061,"time":"2018-07-27T01:32:42.113000Z"}
{"type":"received","order_id":"4d976f35-6327-45f2-9233-a9fa1b378dea","order_type":"limit","size":"0.00150000","price":"6727.01000000","side":"buy","client_oid":"74208b99-3f99-4853-8000-004256619351","product_id":"BTC-USD","sequence":6418130292,"time":"2018-07-27T01:32:42.113000Z"}
{"type":"open","side":"sell","price":"795.05000000","order_id":"28dcec1b-ed51-41d0-bcac-5936b13305d4","remaining_size":"0.90000000","product_id":"BCH-USD","sequence":4839273109,"time":"2018-07-27T01:32:42.110000Z"}
{"type":"open","side":"buy","price":"6727.01000000","order_id":"4d976f35-6327-45f2-9233-a9fa1b378dea","remaining_size":"0.00150000","product_id":"BTC-USD","sequence":6418130293,"time":"2018-07-27T01:32:42.113000Z"}
{"type":"open","side":"buy","price":"82.98000000","order_id":"1827522a-62c2-4b67-804f-23553a0f3853","remaining_size":"20.00000000","product_id":"LTC-USD","sequence":2423272062,"time":"2018-07-27T01:32:42.113000Z"}
{"type":"received","order_id":"8a1b346c-882a-467e-878e-0256f1e0c4b1","order_type":"limit","size":"0.01000000","price":"486.55000000","side":"sell","client_oid":"3988562d-724d-4638-8000-0075169fad0e","product_id":"ETH-USD","sequence":4469354836,"time":"2018-07-27T01:32:42.116000Z"}
{"type":"open","side":"sell","price":"486.55000000","order_id":"8a1b346c-882a-467e-878e-0256f1e0c4b1","remaining_size":"0.01000000","product_id":"ETH-USD","sequence":4469354837,"time":"2018-07-27T01:32:42.116000Z"}
{"type":"done","side":"buy","order_id":"9a9cfcf8-0789-4a97-afa4-94cf49c175c5","reason":"canceled","product_id":"BCH-USD","price":"791.26000000","remaining_size":"1.81488800","sequence":4839273110,"time":"2018-07-27T01:32:42.115000Z"}
{"type":"received","order_id":"5378bf41-c856-4646-b48f-3876d95ba77f","order_type":"limit","size":"1.81488800","price":"791.23000000","side":"buy","client_oid":"e8d5d320-508d-4f96-90a9-86e026e74e99","product_id":"BCH-USD","sequence":4839273111,"time":"2018-07-27T01:32:42.117000Z"}
{"type":"open","side":"buy","price":"791.23000000","order_id":"5378bf41-c856-4646-b48f-3876d95ba77f","remaining_size":"1.81488800","product_id":"BCH-USD","sequence":4839273112,"time":"2018-07-27T01:32:42.117000Z"}
{"type":"done","side":"buy","order_id":"1827522a-62c2-4b67-804f-23553a0f3853","reason":"canceled","product_id":"LTC-USD","price":"82.98000000","remaining_size":"20.00000000","sequence":2423272063,"time":"2018-07-27T01:32:42.119000Z"}
{"type":"received","order_id":"10f75bd0-26b7-4c2a-be43-0aff938aa2e2","order_type":"limit","size":"4.50000000","price":"795.03000000","side":"sell","client_oid":"b817fdba-600a-42dd-a6d7-4daccccaf1fe","product_id":"BCH-USD","sequence":4839273113,"time":"2018-07-27T01:32:42.118000Z"}
{"type":"open","side":"sell","price":"795.03000000","order_id":"10f75bd0-26b7-4c2a-be43-0aff938aa2e2","remaining_size":"4.50000000","product_id":"BCH-USD","sequence":4839273114,"time":"2018-07-27T01:32:42.118000Z"}
{"type":"received","order_id":"87d2aa12-4bca-4764-ac75-54dc51ab152b","order_type":"limit","size":"0.90000000","price":"795.03000000","side":"sell","client_oid":"2eb7df51-3784-4955-98b3-4239ceafd728","product_id":"BCH-USD","sequence":4839273115,"time":"2018-07-27T01:32:42.119000Z"}
{"type":"open","side":"sell","price":"795.03000000","order_id":"87d2aa12-4bca-4764-ac75-54dc51ab152b","remaining_size":"0.90000000","product_id":"BCH-USD","sequence":4839273116,"time":"2018-07-27T01:32:42.119000Z"}
{"type":"received","order_id":"7ecc8448-364d-465a-b6eb-2d44819732fb","order_type":"limit","size":"0.15109400","price":"789.20000000","side":"buy","client_oid":"a332c006-6db0-4f66-899c-b0f172d4ba92","product_id":"BCH-USD","sequence":4839273117,"time":"2018-07-27T01:32:42.119000Z"}
{"type":"open","side":"buy","price":"789.20000000","order_id":"7ecc8448-364d-465a-b6eb-2d44819732fb","remaining_size":"0.15109400","product_id":"BCH-USD","sequence":4839273118,"time":"2018-07-27T01:32:42.119000Z"}
{"type":"done","side":"buy","order_id":"5378bf41-c856-4646-b48f-3876d95ba77f","reason":"canceled","product_id":"BCH-USD","price":"791.23000000","remaining_size":"1.81488800","sequence":4839273119,"time":"2018-07-27T01:32:42.120000Z"}
{"type":"done","side":"sell","order_id":"10f75bd0-26b7-4c2a-be43-0aff938aa2e2","reason":"canceled","product_id":"BCH-USD","price":"795.03000000","remaining_size":"4.50000000","sequence":4839273120,"time":"2018-07-27T01:32:42.122000Z"}
{"type":"received","order_id":"8f8aa6d4-7b90-4ea4-97c5-871adba78411","order_type":"limit","size":"20.00000000","price":"82.99000000","side":"buy","client_oid":"1ce0d9d8-6a64-4e35-b819-aa4373e71c5a","product_id":"LTC-USD","sequence":2423272064,"time":"2018-07-27T01:32:42.126000Z"}
{"type":"open","side":"buy","price":"82.99000000","order_id":"8f8aa6d4-7b90-4ea4-97c5-871adba78411","remaining_size":"20.00000000","product_id":"LTC-USD","sequence":2423272065,"time":"2018-07-27T01:32:42.126000Z"}
{"type":"done","side":"sell","order_id":"87d2aa12-4bca-4764-ac75-54dc51ab152b","reason":"canceled","product_id":"BCH-USD","price":"795.03000000","remaining_size":"0.90000000","sequence":4839273121,"time":"2018-07-27T01:32:42.125000Z"}
{"type":"received","order_id":"e890c66e-1f9e-4a94-9a21-db461e5dc1e5","order_type":"limit","size":"7.44874862","price":"83.30000000","side":"sell","client_oid":"ca9e4641-8618-4ff8-8000-006f7ef509e4","product_id":"LTC-USD","sequence":2423272066,"time":"2018-07-27T01:32:42.131000Z"}
{"type":"received","order_id":"9d955487-af62-4568-9e0c-8aa052f081b5","order_type":"limit","size":"1.00000000","price":"7885.00000000","side":"buy","client_oid":"959c57e2-b178-4276-8c33-ab856096dbc5","product_id":"BTC-USD","sequence":6418130294,"time":"2018-07-27T01:32:42.131000Z"}
