{"type":"open","side":"sell","price":"794.64000000","order_id":"5cb0c1d5-f232-4d33-81db-7d6d1a6113e6","remaining_size":"4.50000000","product_id":"BCH-USD","sequence":4839271272,"time":"2018-07-27T01:32:39.259000Z"}
{"type":"received","order_id":"fa6626d3-cef5-404c-a10a-3338cc4c2368","order_type":"limit","size":"1.90000000","price":"795.28000000","side":"sell","client_oid":"83c72be0-9387-4850-8d15-5fcb45dcd595","product_id":"BCH-USD","sequence":4839271273,"time":"2018-07-27T01:32:39.260000Z"}
{"type":"open","side":"sell","price":"795.28000000","order_id":"fa6626d3-cef5-404c-a10a-3338cc4c2368","remaining_size":"1.90000000","product_id":"BCH-USD","sequence":4839271274,"time":"2018-07-27T01:32:39.260000Z"}
{"type":"done","side":"sell","order_id":"19d341c6-ffb3-4436-a0f0-51e44b064731","reason":"canceled","product_id":"BCH-USD","price":"794.64000000","remaining_size":"0.90000000","sequence":4839271275,"time":"2018-07-27T01:32:39.261000Z"}
{"type":"done","side":"sell","order_id":"5cb0c1d5-f232-4d33-81db-7d6d1a6113e6","reason":"canceled","product_id":"BCH-USD","price":"794.64000000","remaining_size":"4.50000000","sequence":4839271276,"time":"2018-07-27T01:32:39.263000Z"}
{"type":"done","side":"buy","order_id":"5f7d7ce7-5ddf-4147-a548-521c1e6e4d1f","reason":"canceled","product_id":"BCH-USD","price":"791.95000000","remaining_size":"4.88000000","sequence":4839271277,"time":"2018-07-27T01:32:39.267000Z"}
{"type":"received","order_id":"c8558372-7a99-4741-b52b-b269f244e5a9","order_type":"limit","size":"0.90000000","price":"794.62000000","side":"sell","client_oid":"4670d727-fe07-4d05-834b-4a14e84c9a2f","product_id":"BCH-USD","sequence":4839271278,"time":"2018-07-27T01:32:39.269000Z"}
{"type":"received","order_id":"7713e782-71c9-443b-af65-880e2deecb17","order_type":"limit","size":"20.00000000","price":"83.25000000","side":"buy","client_oid":"8c2cd7c9-167a-411f-9cb1-58b8ab5320f8","product_id":"LTC-USD","sequence":2423271654,"time":"2018-07-27T01:32:39.271000Z"}
{"type":"open","side":"sell","price":"794.62000000","order_id":"c8558372-7a99-4741-b52b-b269f244e5a9","remaining_size":"0.90000000","product_id":"BCH-USD","sequence":4839271279,"time":"2018-07-27T01:32:39.269000Z"}
{"type":"open","side":"buy","price":"83.25000000","order_id":"7713e782-71c9-443b-af65-880e2deecb17","remaining_size":"20.00000000","product_id":"LTC-USD","sequence":2423271655,"time":"2018-07-27T01:32:39.271000Z"}
{"type":"received","order_id":"02206345-fcb1-4126-8298-5e242fccd73e","order_type":"limit","size":"1.90000000","price":"794.62000000","side":"sell","client_oid":"cefe4f8b-e131-449b-8972-a876e9af6f72","product_id":"BCH-USD","sequence":4839271280,"time":"2018-07-27T01:32:39.270000Z"}
{"type":"open","side":"sell","price":"794.62000000","order_id":"02206345-fcb1-4126-8298-5e242fccd73e","remaining_size":"1.90000000","product_id":"BCH-USD","sequence":4839271281,"time":"2018-07-27T01:32:39.270000Z"}
{"type":"received","order_id":"17ee9d64-7f1d-411f-9a08-a4d3bfa1445f","order_type":"limit","size":"4.50000000","price":"794.61000000","side":"sell","client_oid":"131b81e8-62c9-4212-96a9-83870fa24339","product_id":"BCH-USD","sequence":4839271282,"time":"2018-07-27T01:32:39.271000Z"}
{"type":"open","side":"sell","price":"794.61000000","order_id":"17ee9d64-7f1d-411f-9a08-a4d3bfa1445f","remaining_size":"4.50000000","product_id":"BCH-USD","sequence":4839271283,"time":"2018-07-27T01:32:39.271000Z"}
{"type":"done","side":"sell","order_id":"17ee9d64-7f1d-411f-9a08-a4d3bfa1445f","reason":"canceled","product_id":"BCH-USD","price":"794.61000000","remaining_size":"4.50000000","sequence":4839271284,"time":"2018-07-27T01:32:39.274000Z"}
{"type":"done","side":"sell","order_id":"20926f14-30cf-4c85-9225-0285c2bddc93","reason":"canceled","product_id":"BCH-USD","price":"794.62000000","remaining_size":"0.90000000","sequence":4839271285,"time":"2018-07-27T01:32:39.276000Z"}
{"type":"received","order_id":"5c48799f-d5f8-402b-be88-a1b71de4baed","order_type":"limit","size":"0.20000000","price":"7893.00000000","side":"buy","client_oid":"e4df352e-624b-4bee-aef7-7dbdfa0f5f65","product_id":"BTC-USD","sequence":6418130198,"time":"2018-07-27T01:32:39.281000Z"}
{"type":"open","side":"buy","price":"7893.00000000","order_id":"5c48799f-d5f8-402b-be88-a1b71de4baed","remaining_size":"0.20000000","product_id":"BTC-USD","sequence":6418130199,"time":"2018-07-27T01:32:39.281000Z"}
{"type":"done","side":"buy","order_id":"52ea5c8f-ea69-40c4-92e6-2fb15d551b93","reason":"canceled","product_id":"BCH-USD","price":"791.23000000","remaining_size":"0.18739300","sequence":4839271286,"time":"2018-07-27T01:32:39.282000Z"}
{"type":"done","side":"sell","order_id":"02206345-fcb1-4126-8298-5e242fccd73e","reason":"canceled","product_id":"BCH-USD","price":"794.62000000","remaining_size":"1.90000000","sequence":4839271287,"time":"2018-07-27T01:32:39.286000Z"}
{"type":"done","side":"sell","order_id":"c8558372-7a99-4741-b52b-b269f244e5a9","reason":"canceled","product_id":"BCH-USD","price":"794.62000000","remaining_size":"0.90000000","sequence":4839271288,"time":"2018-07-27T01:32:39.288000Z"}
{"type":"done","side":"sell","order_id":"0ce52e7f-85cb-495a-9eac-44ada696db90","reason":"canceled","product_id":"BCH-USD","price":"795.28000000","remaining_size":"4.50000000","sequence":4839271289,"time":"2018-07-27T01:32:39.288000Z"}
{"type":"received","order_id":"c93d8126-e51d-4436-957f-357ec5dba147","order_type":"limit","size":"2.00000000","price":"792.53000000","side":"buy","client_oid":"b1dabae6-b178-46d3-9368-daec368023ee","product_id":"BCH-USD","sequence":4839271290,"time":"2018-07-27T01:32:39.289000Z"}
{"type":"open","side":"buy","price":"792.53000000","order_id":"c93d8126-e51d-4436-957f-357ec5dba147","remaining_size":"2.00000000","product_id":"BCH-USD","sequence":4839271291,"time":"2018-07-27T01:32:39.289000Z"}
{"type":"done","side":"sell","order_id":"fa6626d3-cef5-404c-a10a-3338cc4c2368","reason":"canceled","product_id":"BCH-USD","price":"795.28000000","remaining_size":"1.90000000","sequence":4839271292,"time":"2018-07-27T01:32:39.290000Z"}
{"type":"received","order_id":"53d25702-cc0c-4988-89c2-aeeaa7e5c654","order_type":"limit","size":"5.59400000","price":"793.11000000","side":"buy","client_oid":"b2a88285-fd48-3b89-ccdc-5778fb174f1a","product_id":"BCH-USD","sequence":4839271293,"time":"2018-07-27T01:32:39.290000Z"}
{"type":"open","side":"buy","price":"793.11000000","order_id":"53d25702-cc0c-4988-89c2-aeeaa7e5c654","remaining_size":"5.59400000","product_id":"BCH-USD","sequence":4839271294,"time":"2018-07-27T01:32:39.290000Z"}
{"type":"received","order_id":"7763996e-96f4-40bf-b64e-03c2a44c8084","order_type":"limit","size":"0.90000000","price":"794.64000000","side":"sell","client_oid":"4e74138d-52ec-4fa1-bbc2-df080dd11c84","product_id":"BCH-USD","sequence":4839271295,"time":"2018-07-27T01:32:39.292000Z"}
{"type":"open","side":"sell","price":"794.64000000","order_id":"7763996e-96f4-40bf-b64e-03c2a44c8084","remaining_size":"0.90000000","product_id":"BCH-USD","sequence":4839271296,"time":"2018-07-27T01:32:39.292000Z"}
{"type":"received","order_id":"3384a403-d49b-4e0a-ad7d-150bb1c47e67","order_type":"limit","size":"1.90000000","price":"795.29000000","side":"sell","client_oid":"c6498596-e974-4673-8b40-6e14b56f3b7c","product_id":"BCH-USD","sequence":4839271297,"time":"2018-07-27T01:32:39.295000Z"}
{"type":"open","side":"sell","price":"795.29000000","order_id":"3384a403-d49b-4e0a-ad7d-150bb1c47e67","remaining_size":"1.90000000","product_id":"BCH-USD","sequence":4839271298,"time":"2018-07-27T01:32:39.295000Z"}
{"type":"received","order_id":"ed822e21-a3b2-4f08-a8aa-decd70fbdb8a","order_type":"limit","size":"4.50000000","price":"795.29000000","side":"sell","client_oid":"77048863-7491-4177-a061-d2cd128d9806","product_id":"BCH-USD","sequence":4839271299,"time":"2018-07-27T01:32:39.298000Z"}
{"type":"open","side":"sell","price":"795.29000000","order_id":"ed822e21-a3b2-4f08-a8aa-decd70fbdb8a","remaining_size":"4.50000000","product_id":"BCH-USD","sequence":4839271300,"time":"2018-07-27T01:32:39.298000Z"}
{"type":"received","order_id":"5ea1d5db-d310-4bba-b375-e9e494909c07","order_type":"limit","size":"8.24720000","price":"799.83000000","side":"sell","product_id":"BCH-USD","sequence":4839271301,"time":"2018-07-27T01:32:39.298000Z"}
{"type":"open","side":"sell","price":"799.83000000","order_id":"5ea1d5db-d310-4bba-b375-e9e494909c07","remaining_size":"8.24720000","product_id":"BCH-USD","sequence":4839271302,"time":"2018-07-27T01:32:39.298000Z"}
{"type":"received","order_id":"d56a6bec-272c-4d7b-956f-cf644f4c8191","order_type":"limit","size":"4.50000000","price":"794.64000000","side":"sell","client_oid":"82948b7d-d5d2-4ab7-9562-96e01c520edb","product_id":"BCH-USD","sequence":4839271303,"time":"2018-07-27T01:32:39.298000Z"}
{"type":"open","side":"sell","price":"794.64000000","order_id":"d56a6bec-272c-4d7b-956f-cf644f4c8191","remaining_size":"4.50000000","product_id":"BCH-USD","sequence":4839271304,"time":"2018-07-27T01:32:39.298000Z"}
{"type":"done","side":"buy","order_id":"8a9ff45e-aede-4b44-8d00-35b147f59b1f","reason":"canceled","product_id":"LTC-USD","price":"82.98000000","remaining_size":"20.00000000","sequence":2423271656,"time":"2018-07-27T01:32:39.301000Z"}
{"type":"received","order_id":"7da2d336-eada-4d9c-88e5-bf943ad0b060","order_type":"limit","size":"0.90000000","price":"794.64000000","side":"sell","client_oid":"b60966e0-6e63-4baa-ab0e-e99900a52d94","product_id":"BCH-USD","sequence":4839271305,"time":"2018-07-27T01:32:39.301000Z"}
{"type":"open","side":"sell","price":"794.64000000","order_id":"7da2d336-eada-4d9c-88e5-bf943ad0b060","remaining_size":"0.90000000","product_id":"BCH-USD","sequence":4839271306,"time":"2018-07-27T01:32:39.301000Z"}
{"type":"received","order_id":"64d79b78-9827-4a67-8ff4-f82f24834dbf","order_type":"limit","size":"1.90000000","price":"794.60000000","side":"sell","client_oid":"578cd333-5ccd-425d-bb89-d65dcae857de","product_id":"BCH-USD","sequence":4839271307,"time":"2018-07-27T01:32:39.303000Z"}
{"type":"open","side":"sell","price":"794.60000000","order_id":"64d79b78-9827-4a67-8ff4-f82f24834dbf","remaining_size":"1.90000000","product_id":"BCH-USD","sequence":4839271308,"time":"2018-07-27T01:32:39.303000Z"}
{"type":"done","side":"buy","order_id":"4d6a5564-781e-4248-bd97-724222adc1d4","reason":"canceled","product_id":"BCH-USD","price":"791.84000000","remaining_size":"0.90000000","sequence":4839271309,"time":"2018-07-27T01:32:39.303000Z"}
{"type":"done","side":"sell","order_id":"3384a403-d49b-4e0a-ad7d-150bb1c47e67","reason":"canceled","product_id":"BCH-USD","price":"795.29000000","remaining_size":"1.90000000","sequence":4839271310,"time":"2018-07-27T01:32:39.305000Z"}
{"type":"done","side":"sell","order_id":"ed822e21-a3b2-4f08-a8aa-decd70fbdb8a","reason":"canceled","product_id":"BCH-USD","price":"795.29000000","remaining_size":"4.50000000","sequence":4839271311,"time":"2018-07-27T01:32:39.305000Z"}
{"type":"done","side":"buy","order_id":"7148deb9-42b6-4753-af54-6da30d01e10c","reason":"canceled","product_id":"BCH-USD","price":"791.03000000","remaining_size":"1.81488800","sequence":4839271312,"time":"2018-07-27T01:32:39.306000Z"}
{"type":"done","side":"sell","order_id":"7da2d336-eada-4d9c-88e5-bf943ad0b060","reason":"canceled","product_id":"BCH-USD","price":"794.64000000","remaining_size":"0.90000000","sequence":4839271313,"time":"2018-07-27T01:32:39.308000Z"}
{"type":"done","side":"sell","order_id":"13d64a62-97ea-474f-8289-a3b308d986c6","reason":"canceled","product_id":"LTC-USD","price":"83.30000000","remaining_size":"7.44874862","sequence":2423271657,"time":"2018-07-27T01:32:39.311000Z"}
{"type":"done","side":"buy","order_id":"47c58673-23b3-4646-83c2-a5bffbbecdb8","reason":"canceled","product_id":"BCH-USD","price":"792.01000000","remaining_size":"0.90000000","sequence":4839271314,"time":"2018-07-27T01:32:39.312000Z"}
{"type":"received","order_id":"807bfe44-2225-459b-b1cc-79598e99d275","order_type":"limit","size":"20.00000000","price":"82.99000000","side":"buy","client_oid":"37b15994-1bb9-4a68-b8d4-a52b593c921f","product_id":"LTC-USD","sequence":2423271658,"time":"2018-07-27T01:32:39.314000Z"}
{"type":"done","side":"sell","order_id":"5fe33a4c-961f-4495-8606-bf621e634982","reason":"canceled","product_id":"BCH-USD","price":"795.68000000","remaining_size":"1.60461000","sequence":4839271315,"time":"2018-07-27T01:32:39.312000Z"}
{"type":"open","side":"buy","price":"82.99000000","order_id":"807bfe44-2225-459b-b1cc-79598e99d275","remaining_size":"20.00000000","product_id":"LTC-USD","sequence":2423271659,"time":"2018-07-27T01:32:39.314000Z"}
{"type":"received","order_id":"2e7f7905-a038-42cc-a807-591439aa4641","order_type":"limit","size":"1.90000000","price":"795.27000000","side":"sell","client_oid":"fe4814c1-29c2-47e3-b3c5-3ce6a1296c82","product_id":"BCH-USD","sequence":4839271316,"time":"2018-07-27T01:32:39.315000Z"}
{"type":"open","side":"sell","price":"795.27000000","order_id":"2e7f7905-a038-42cc-a807-591439aa4641","remaining_size":"1.90000000","product_id":"BCH-USD","sequence":4839271317,"time":"2018-07-27T01:32:39.315000Z"}
{"type":"done","side":"sell","order_id":"826c2cdf-d2ae-4fce-8251-c45561406901","reason":"canceled","product_id":"BCH-USD","price":"795.36000000","remaining_size":"3.00000000","sequence":4839271318,"time":"2018-07-27T01:32:39.315000Z"}
{"type":"received","order_id":"f68857a0-131f-4aee-aee6-1174c949b3f7","order_type":"limit","size":"4.50000000","price":"795.27000000","side":"sell","client_oid":"f2342cfb-5445-4616-b22b-5ef7c6e47e5d","product_id":"BCH-USD","sequence":4839271319,"time":"2018-07-27T01:32:39.316000Z"}
{"type":"open","side":"sell","price":"795.27000000","order_id":"f68857a0-131f-4aee-aee6-1174c949b3f7","remaining_size":"4.50000000","product_id":"BCH-USD","sequence":4839271320,"time":"2018-07-27T01:32:39.316000Z"}
{"type":"done","side":"sell","order_id":"d56a6bec-272c-4d7b-956f-cf644f4c8191","reason":"canceled","product_id":"BCH-USD","price":"794.64000000","remaining_size":"4.50000000","sequence":4839271321,"time":"2018-07-27T01:32:39.316000Z"}
{"type":"received","order_id":"ac64f42a-8d9b-4a32-91e8-c771d2dc2b57","order_type":"limit","size":"1.81488800","price":"790.89000000","side":"buy","client_oid":"18ddd715-7409-4c0a-b86f-02386af950c4","product_id":"BCH-USD","sequence":4839271322,"time":"2018-07-27T01:32:39.319000Z"}
{"type":"open","side":"buy","price":"790.89000000","order_id":"ac64f42a-8d9b-4a32-91e8-c771d2dc2b57","remaining_size":"1.81488800","product_id":"BCH-USD","sequence":4839271323,"time":"2018-07-27T01:32:39.319000Z"}
{"type":"received","order_id":"49804746-f027-4e6d-87bc-f243b1481dc0","order_type":"limit","size":"0.18739300","price":"791.58000000","side":"buy","client_oid":"74762e0f-246f-4f78-872d-46782c070dfc","product_id":"BCH-USD","sequence":4839271324,"time":"2018-07-27T01:32:39.319000Z"}
{"type":"open","side":"buy","price":"791.58000000","order_id":"49804746-f027-4e6d-87bc-f243b1481dc0","remaining_size":"0.18739300","product_id":"BCH-USD","sequence":4839271325,"time":"2018-07-27T01:32:39.319000Z"}
{"type":"received","order_id":"4a8b8cab-8d23-4919-a25b-4aedc6d7593b","order_type":"limit","size":"0.90000000","price":"792.54000000","side":"buy","client_oid":"351d348d-effe-41b8-95e5-506375547956","product_id":"BCH-USD","sequence":4839271326,"time":"2018-07-27T01:32:39.320000Z"}
{"type":"open","side":"buy","price":"792.54000000","order_id":"4a8b8cab-8d23-4919-a25b-4aedc6d7593b","remaining_size":"0.90000000","product_id":"BCH-USD","sequence":4839271327,"time":"2018-07-27T01:32:39.320000Z"}
{"type":"done","side":"sell","order_id":"7763996e-96f4-40bf-b64e-03c2a44c8084","reason":"canceled","product_id":"BCH-USD","price":"794.64000000","remaining_size":"0.90000000","sequence":4839271328,"time":"2018-07-27T01:32:39.321000Z"}
{"type":"received","order_id":"5afde432-cb66-4783-b289-e088678c6baa","order_type":"limit","size":"1.90000000","price":"795.29000000","side":"sell","client_oid":"1ffbee74-059a-4989-ba80-831eea1bf34d","product_id":"BCH-USD","sequence":4839271329,"time":"2018-07-27T01:32:39.323000Z"}
{"type":"open","side":"sell","price":"795.29000000","order_id":"5afde432-cb66-4783-b289-e088678c6baa","remaining_size":"1.90000000","product_id":"BCH-USD","sequence":4839271330,"time":"2018-07-27T01:32:39.323000Z"}
{"type":"done","side":"sell","order_id":"64d79b78-9827-4a67-8ff4-f82f24834dbf","reason":"canceled","product_id":"BCH-USD","price":"794.60000000","remaining_size":"1.90000000","sequence":4839271331,"time":"2018-07-27T01:32:39.324000Z"}
{"type":"received","order_id":"6caae1ae-30da-460d-851a-bf05cafcd5fb","order_type":"limit","size":"0.90000000","price":"791.58000000","side":"buy","client_oid":"7cc0912c-2251-458c-b3e4-f35fa0dd7699","product_id":"BCH-USD","sequence":4839271332,"time":"2018-07-27T01:32:39.326000Z"}
{"type":"open","side":"buy","price":"791.58000000","order_id":"6caae1ae-30da-460d-851a-bf05cafcd5fb","remaining_size":"0.90000000","product_id":"BCH-USD","sequence":4839271333,"time":"2018-07-27T01:32:39.326000Z"}
{"type":"done","side":"buy","order_id":"49804746-f027-4e6d-87bc-f243b1481dc0","reason":"canceled","product_id":"BCH-USD","price":"791.58000000","remaining_size":"0.18739300","sequence":4839271334,"time":"2018-07-27T01:32:39.327000Z"}
{"type":"received","order_id":"625a5c52-bcaf-4b2c-bc4b-d549a8501d78","order_type":"limit","size":"7.44874862","price":"83.34000000","side":"sell","client_oid":"15066f47-57df-4b6d-8000-002fa43be745","product_id":"LTC-USD","sequence":2423271660,"time":"2018-07-27T01:32:39.330000Z"}
{"type":"received","order_id":"758099f9-d910-4ee1-ae4f-e1f47e056d0d","order_type":"limit","size":"4.50000000","price":"795.29000000","side":"sell","client_oid":"7fb40093-b78a-497b-ae19-675d74c6de85","product_id":"BCH-USD","sequence":4839271335,"time":"2018-07-27T01:32:39.329000Z"}
{"type":"open","side":"sell","price":"795.29000000","order_id":"758099f9-d910-4ee1-ae4f-e1f47e056d0d","remaining_size":"4.50000000","product_id":"BCH-USD","sequence":4839271336,"time":"2018-07-27T01:32:39.329000Z"}
{"type":"received","order_id":"a4f50309-4380-462a-b36d-aa5e41b7aa64","order_type":"limit","size":"3.00000000","price":"795.19000000","side":"sell","client_oid":"68eebb49-a162-4ea4-88eb-5f860717e9fb","product_id":"BCH-USD","sequence":4839271337,"time":"2018-07-27T01:32:39.329000Z"}
{"type":"open","side":"sell","price":"83.34000000","order_id":"625a5c52-bcaf-4b2c-bc4b-d549a8501d78","remaining_size":"7.44874862","product_id":"LTC-USD","sequence":2423271661,"time":"2018-07-27T01:32:39.330000Z"}
{"type":"open","side":"sell","price":"795.19000000","order_id":"a4f50309-4380-462a-b36d-aa5e41b7aa64","remaining_size":"3.00000000","product_id":"BCH-USD","sequence":4839271338,"time":"2018-07-27T01:32:39.329000Z"}
{"type":"done","side":"buy","order_id":"c93d8126-e51d-4436-957f-357ec5dba147","reason":"canceled","product_id":"BCH-USD","price":"792.53000000","remaining_size":"2.00000000","sequence":4839271339,"time":"2018-07-27T01:32:39.330000Z"}
{"type":"received","order_id":"9c82a144-9bc0-4184-8874-cfa8363cffef","order_type":"limit","size":"0.90000000","price":"794.63000000","side":"sell","client_oid":"b8e7270b-aae9-4076-9823-7b9700f2da33","product_id":"BCH-USD","sequence":4839271340,"time":"2018-07-27T01:32:39.336000Z"}
{"type":"open","side":"sell","price":"794.63000000","order_id":"9c82a144-9bc0-4184-8874-cfa8363cffef","remaining_size":"0.90000000","product_id":"BCH-USD","sequence":4839271341,"time":"2018-07-27T01:32:39.336000Z"}
{"type":"received","order_id":"ce0d04bb-36d5-4d9f-96b5-0752e2eb7f33","order_type":"limit","size":"0.18739300","price":"791.23000000","side":"buy","client_oid":"6a89346c-2a82-40b9-8e4f-3e578196eba9","product_id":"BCH-USD","sequence":4839271342,"time":"2018-07-27T01:32:39.337000Z"}
{"type":"open","side":"buy","price":"791.23000000","order_id":"ce0d04bb-36d5-4d9f-96b5-0752e2eb7f33","remaining_size":"0.18739300","product_id":"BCH-USD","sequence":4839271343,"time":"2018-07-27T01:32:39.337000Z"}
{"type":"done","side":"sell","order_id":"2e7f7905-a038-42cc-a807-591439aa4641","reason":"canceled","product_id":"BCH-USD","price":"795.27000000","remaining_size":"1.90000000","sequence":4839271344,"time":"2018-07-27T01:32:39.339000Z"}
{"type":"received","order_id":"c034e611-790d-49d1-9f33-7228ca44bd00","order_type":"limit","size":"0.90000000","price":"794.61000000","side":"sell","client_oid":"7f4b48aa-3838-4c47-a29e-62a5424a732f","product_id":"BCH-USD","sequence":4839271345,"time":"2018-07-27T01:32:39.340000Z"}
{"type":"open","side":"sell","price":"794.61000000","order_id":"c034e611-790d-49d1-9f33-7228ca44bd00","remaining_size":"0.90000000","product_id":"BCH-USD","sequence":4839271346,"time":"2018-07-27T01:32:39.340000Z"}
{"type":"received","order_id":"ce747b9c-e68c-4a58-9703-201156c7a854","order_type":"limit","size":"2.00000000","price":"792.80000000","side":"buy","client_oid":"e3288fac-50b9-4cf8-9861-d25d4fb2f473","product_id":"BCH-USD","sequence":4839271347,"time":"2018-07-27T01:32:39.341000Z"}
{"type":"open","side":"buy","price":"792.80000000","order_id":"ce747b9c-e68c-4a58-9703-201156c7a854","remaining_size":"2.00000000","product_id":"BCH-USD","sequence":4839271348,"time":"2018-07-27T01:32:39.341000Z"}
{"type":"done","side":"buy","order_id":"ce0d04bb-36d5-4d9f-96b5-0752e2eb7f33","reason":"canceled","product_id":"BCH-USD","price":"791.23000000","remaining_size":"0.18739300","sequence":4839271349,"time":"2018-07-27T01:32:39.342000Z"}
{"type":"done","side":"sell","order_id":"c034e611-790d-49d1-9f33-7228ca44bd00","reason":"canceled","product_id":"BCH-USD","price":"794.61000000","remaining_size":"0.90000000","sequence":4839271350,"time":"2018-07-27T01:32:39.343000Z"}
{"type":"done","side":"buy","order_id":"ac64f42a-8d9b-4a32-91e8-c771d2dc2b57","reason":"canceled","product_id":"BCH-USD","price":"790.89000000","remaining_size":"1.81488800","sequence":4839271351,"time":"2018-07-27T01:32:39.344000Z"}
{"type":"received","order_id":"9cf03538-cbf6-4dec-b8f0-1b4079ec3219","order_type":"limit","size":"1.90000000","price":"795.29000000","side":"sell","client_oid":"8e1c4c06-0b64-4636-b948-9137bd076457","product_id":"BCH-USD","sequence":4839271352,"time":"2018-07-27T01:32:39.345000Z"}
{"type":"open","side":"sell","price":"795.29000000","order_id":"9cf03538-cbf6-4dec-b8f0-1b4079ec3219","remaining_size":"1.90000000","product_id":"BCH-USD","sequence":4839271353,"time":"2018-07-27T01:32:39.345000Z"}
{"type":"done","side":"buy","order_id":"6caae1ae-30da-460d-851a-bf05cafcd5fb","reason":"canceled","product_id":"BCH-USD","price":"791.58000000","remaining_size":"0.90000000","sequence":4839271354,"time":"2018-07-27T01:32:39.347000Z"}
{"type":"received","order_id":"32aa4e66-aded-47aa-8c85-360a6701cf6b","order_type":"limit","size":"0.18739300","price":"791.58000000","side":"buy","client_oid":"f9c5eb02-8f23-4c4c-a5d2-7dcbb72bdd79","product_id":"BCH-USD","sequence":4839271355,"time":"2018-07-27T01:32:39.350000Z"}
{"type":"open","side":"buy","price":"791.58000000","order_id":"32aa4e66-aded-47aa-8c85-360a6701cf6b","remaining_size":"0.18739300","product_id":"BCH-USD","sequence":4839271356,"time":"2018-07-27T01:32:39.350000Z"}
{"type":"received","order_id":"d6c82fe2-0e47-4ef8-bbfe-c514463f132a","order_type":"limit","size":"0.90000000","price":"794.64000000","side":"sell","client_oid":"22585a95-e0d6-4722-8a03-9b4594136da1","product_id":"BCH-USD","sequence":4839271357,"time":"2018-07-27T01:32:39.352000Z"}
{"type":"open","side":"sell","price":"794.64000000","order_id":"d6c82fe2-0e47-4ef8-bbfe-c514463f132a","remaining_size":"0.90000000","product_id":"BCH-USD","sequence":4839271358,"time":"2018-07-27T01:32:39.352000Z"}
{"type":"done","side":"sell","order_id":"f68857a0-131f-4aee-aee6-1174c949b3f7","reason":"canceled","product_id":"BCH-USD","price":"795.27000000","remaining_size":"4.50000000","sequence":4839271359,"time":"2018-07-27T01:32:39.352000Z"}
{"type":"received","order_id":"6b95f232-2546-438c-aa75-86bc117ddb43","order_type":"limit","size":"1.81488800","price":"791.21000000","side":"buy","client_oid":"c0ba03d4-e03b-469f-a7db-f31ef3e6ce1d","product_id":"BCH-USD","sequence":4839271360,"time":"2018-07-27T01:32:39.355000Z"}
{"type":"open","side":"buy","price":"791.21000000","order_id":"6b95f232-2546-438c-aa75-86bc117ddb43","remaining_size":"1.81488800","product_id":"BCH-USD","sequence":4839271361,"time":"2018-07-27T01:32:39.355000Z"}
{"type":"done","side":"buy","order_id":"32aa4e66-aded-47aa-8c85-360a6701cf6b","reason":"canceled","product_id":"BCH-USD","price":"791.58000000","remaining_size":"0.18739300","sequence":4839271362,"time":"2018-07-27T01:32:39.356000Z"}
{"type":"received","order_id":"d837bbc0-5d91-4564-ab2c-142d5834ec4f","order_type":"limit","size":"0.90000000","price":"792.01000000","side":"buy","client_oid":"b0d3e103-3c16-4f57-9212-4669ab64ec9d","product_id":"BCH-USD","sequence":4839271363,"time":"2018-07-27T01:32:39.361000Z"}
{"type":"open","side":"buy","price":"792.01000000","order_id":"d837bbc0-5d91-4564-ab2c-142d5834ec4f","remaining_size":"0.90000000","product_id":"BCH-USD","sequence":4839271364,"time":"2018-07-27T01:32:39.361000Z"}
{"type":"done","side":"buy","order_id":"6b95f232-2546-438c-aa75-86bc117ddb43","reason":"canceled","product_id":"BCH-USD","price":"791.21000000","remaining_size":"1.81488800","sequence":4839271365,"time":"2018-07-27T01:32:39.361000Z"}
{"type":"received","order_id":"e7721b35-257f-4a35-a81d-09d61f9fd6bd","order_type":"limit","size":"4.50000000","price":"795.67000000","side":"sell","client_oid":"109fad3a-92c5-4d40-9b2d-45494b693d53","product_id":"BCH-USD","sequence":4839271366,"time":"2018-07-27T01:32:39.363000Z"}
{"type":"open","side":"sell","price":"795.67000000","order_id":"e7721b35-257f-4a35-a81d-09d61f9fd6bd","remaining_size":"4.50000000","product_id":"BCH-USD","sequence":4839271367,"time":"2018-07-27T01:32:39.363000Z"}
{"type":"received","order_id":"9e4d023b-eed0-4c43-a761-0fc4422fb956","order_type":"limit","size":"0.18739300","price":"791.23000000","side":"buy","client_oid":"e8af8fae-15fc-40e3-9bc5-df9ed9438f59","product_id":"BCH-USD","sequence":4839271368,"time":"2018-07-27T01:32:39.363000Z"}
{"type":"open","side":"buy","price":"791.23000000","order_id":"9e4d023b-eed0-4c43-a761-0fc4422fb956","remaining_size":"0.18739300","product_id":"BCH-USD","sequence":4839271369,"time":"2018-07-27T01:32:39.363000Z"}
{"type":"done","side":"sell","order_id":"5afde432-cb66-4783-b289-e088678c6baa","reason":"canceled","product_id":"BCH-USD","price":"795.29000000","remaining_size":"1.90000000","sequence":4839271370,"time":"2018-07-27T01:32:39.366000Z"}
{"type":"done","side":"sell","order_id":"9c82a144-9bc0-4184-8874-cfa8363cffef","reason":"canceled","product_id":"BCH-USD","price":"794.63000000","remaining_size":"0.90000000","sequence":4839271371,"time":"2018-07-27T01:32:39.367000Z"}
{"type":"done","side":"sell","order_id":"cc953afc-dcaf-44a0-95e5-9d5b457275b0","reason":"canceled","product_id":"LTC-USD","price":"83.38000000","remaining_size":"7.44874862","sequence":2423271662,"time":"2018-07-27T01:32:39.371000Z"}
{"type":"received","order_id":"c172ee41-7a1a-46fb-8c4f-645931d53d32","order_type":"limit","size":"1.90000000","price":"795.28000000","side":"sell","client_oid":"67261f71-d8e6-4a04-80ca-4661654a795f","product_id":"BCH-USD","sequence":4839271372,"time":"2018-07-27T01:32:39.371000Z"}
{"type":"open","side":"sell","price":"795.28000000","order_id":"c172ee41-7a1a-46fb-8c4f-645931d53d32","remaining_size":"1.90000000","product_id":"BCH-USD","sequence":4839271373,"time":"2018-07-27T01:32:39.371000Z"}
{"type":"done","side":"sell","order_id":"758099f9-d910-4ee1-ae4f-e1f47e056d0d","reason":"canceled","product_id":"BCH-USD","price":"795.29000000","remaining_size":"4.50000000","sequence":4839271374,"time":"2018-07-27T01:32:39.372000Z"}
{"type":"received","order_id":"3e625436-1a6f-4476-a0bf-ea30d8626e35","order_type":"limit","size":"0.90000000","price":"794.64000000","side":"sell","client_oid":"cf4fbc89-be11-4e4c-873e-7f13894a99c1","product_id":"BCH-USD","sequence":4839271375,"time":"2018-07-27T01:32:39.375000Z"}
{"type":"open","side":"sell","price":"794.64000000","order_id":"3e625436-1a6f-4476-a0bf-ea30d8626e35","remaining_size":"0.90000000","product_id":"BCH-USD","sequence":4839271376,"time":"2018-07-27T01:32:39.375000Z"}
{"type":"received","order_id":"57c56fab-c11f-4f8a-a557-9e2dee22f57a","order_type":"limit","size":"1.81488800","price":"791.23000000","side":"buy","client_oid":"54f827bb-8f67-408d-a389-8c064ece1358","product_id":"BCH-USD","sequence":4839271377,"time":"2018-07-27T01:32:39.377000Z"}
{"type":"open","side":"buy","price":"791.23000000","order_id":"57c56fab-c11f-4f8a-a557-9e2dee22f57a","remaining_size":"1.81488800","product_id":"BCH-USD","sequence":4839271378,"time":"2018-07-27T01:32:39.377000Z"}
{"type":"received","order_id":"674db05e-9956-4309-bad2-db692a29259f","order_type":"limit","size":"4.50000000","price":"795.28000000","side":"sell","client_oid":"5bf8ff1e-c4b8-456b-98ba-848b2ce30046","product_id":"BCH-USD","sequence":4839271379,"time":"2018-07-27T01:32:39.384000Z"}
{"type":"open","side":"sell","price":"795.28000000","order_id":"674db05e-9956-4309-bad2-db692a29259f","remaining_size":"4.50000000","product_id":"BCH-USD","sequence":4839271380,"time":"2018-07-27T01:32:39.384000Z"}
{"type":"received","order_id":"288a6e3d-1694-4cb9-a11c-a9d6a6e11173","order_type":"limit","size":"7.44874862","price":"83.30000000","side":"sell","client_oid":"125f13e9-1458-454e-8000-0049bba42ffa","product_id":"LTC-USD","sequence":2423271663,"time":"2018-07-27T01:32:39.388000Z"}
{"type":"open","side":"sell","price":"83.30000000","order_id":"288a6e3d-1694-4cb9-a11c-a9d6a6e11173","remaining_size":"7.44874862","product_id":"LTC-USD","sequence":2423271664,"time":"2018-07-27T01:32:39.388000Z"}
{"type":"done","side":"sell","order_id":"d6c82fe2-0e47-4ef8-bbfe-c514463f132a","reason":"canceled","product_id":"BCH-USD","price":"794.64000000","remaining_size":"0.90000000","sequence":4839271381,"time":"2018-07-27T01:32:39.390000Z"}
{"type":"done","side":"sell","order_id":"9cf03538-cbf6-4dec-b8f0-1b4079ec3219","reason":"canceled","product_id":"BCH-USD","price":"795.29000000","remaining_size":"1.90000000","sequence":4839271382,"time":"2018-07-27T01:32:39.391000Z"}
{"type":"done","side":"buy","order_id":"57c56fab-c11f-4f8a-a557-9e2dee22f57a","reason":"canceled","product_id":"BCH-USD","price":"791.23000000","remaining_size":"1.81488800","sequence":4839271383,"time":"2018-07-27T01:32:39.394000Z"}
{"type":"received","order_id":"81998b81-1cae-432b-ac69-9d29eb20f8dd","order_type":"limit","size":"1.90000000","price":"795.26000000","side":"sell","client_oid":"24358ddf-f209-4d15-8fbc-b80064e8e6be","product_id":"BCH-USD","sequence":4839271384,"time":"2018-07-27T01:32:39.395000Z"}
{"type":"open","side":"sell","price":"795.26000000","order_id":"81998b81-1cae-432b-ac69-9d29eb20f8dd","remaining_size":"1.90000000","product_id":"BCH-USD","sequence":4839271385,"time":"2018-07-27T01:32:39.395000Z"}
{"type":"done","side":"buy","order_id":"9e4d023b-eed0-4c43-a761-0fc4422fb956","reason":"canceled","product_id":"BCH-USD","price":"791.23000000","remaining_size":"0.18739300","sequence":4839271386,"time":"2018-07-27T01:32:39.396000Z"}
{"type":"done","side":"sell","order_id":"e7721b35-257f-4a35-a81d-09d61f9fd6bd","reason":"canceled","product_id":"BCH-USD","price":"795.67000000","remaining_size":"4.50000000","sequence":4839271387,"time":"2018-07-27T01:32:39.396000Z"}
{"type":"received","order_id":"7566b3ea-67a4-41bd-b421-ad9e8e311ead","order_type":"limit","size":"0.90000000","price":"795.26000000","side":"sell","client_oid":"d8ff3413-e3ee-43bf-b238-4ac3b2d3f0d7","product_id":"BCH-USD","sequence":4839271388,"time":"2018-07-27T01:32:39.399000Z"}
{"type":"open","side":"sell","price":"795.26000000","order_id":"7566b3ea-67a4-41bd-b421-ad9e8e311ead","remaining_size":"0.90000000","product_id":"BCH-USD","sequence":4839271389,"time":"2018-07-27T01:32:39.399000Z"}
{"type":"received","order_id":"db280f85-df3c-4087-9608-02cf02f271a6","order_type":"limit","size":"1.81488800","price":"791.21000000","side":"buy","client_oid":"00e90465-e614-48aa-8544-e05a7bd2fc56","product_id":"BCH-USD","sequence":4839271390,"time":"2018-07-27T01:32:39.402000Z"}
{"type":"open","side":"buy","price":"791.21000000","order_id":"db280f85-df3c-4087-9608-02cf02f271a6","remaining_size":"1.81488800","product_id":"BCH-USD","sequence":4839271391,"time":"2018-07-27T01:32:39.402000Z"}
{"type":"received","order_id":"aeb0bd0a-e8c0-4404-b617-cbf622ff3f8f","order_type":"limit","size":"0.18739300","price":"791.24000000","side":"buy","client_oid":"6a8b1c72-4752-469c-849a-3382f45677cc","product_id":"BCH-USD","sequence":4839271392,"time":"2018-07-27T01:32:39.404000Z"}
{"type":"open","side":"buy","price":"791.24000000","order_id":"aeb0bd0a-e8c0-4404-b617-cbf622ff3f8f","remaining_size":"0.18739300","product_id":"BCH-USD","sequence":4839271393,"time":"2018-07-27T01:32:39.404000Z"}
{"type":"done","side":"sell","order_id":"625a5c52-bcaf-4b2c-bc4b-d549a8501d78","reason":"canceled","product_id":"LTC-USD","price":"83.34000000","remaining_size":"7.44874862","sequence":2423271665,"time":"2018-07-27T01:32:39.408000Z"}
{"type":"done","side":"sell","order_id":"c172ee41-7a1a-46fb-8c4f-645931d53d32","reason":"canceled","product_id":"BCH-USD","price":"795.28000000","remaining_size":"1.90000000","sequence":4839271394,"time":"2018-07-27T01:32:39.408000Z"}
{"type":"done","side":"buy","order_id":"db280f85-df3c-4087-9608-02cf02f271a6","reason":"canceled","product_id":"BCH-USD","price":"791.21000000","remaining_size":"1.81488800","sequence":4839271395,"time":"2018-07-27T01:32:39.409000Z"}
{"type":"done","side":"buy","order_id":"aeb0bd0a-e8c0-4404-b617-cbf622ff3f8f","reason":"canceled","product_id":"BCH-USD","price":"791.24000000","remaining_size":"0.18739300","sequence":4839271396,"time":"2018-07-27T01:32:39.410000Z"}
{"type":"received","order_id":"ede19e0c-2ec5-4d65-91c2-5a63b0b759b4","order_type":"limit","size":"4.50000000","price":"795.68000000","side":"sell","client_oid":"f32f8c2e-3644-4348-9e2f-e9db5594f329","product_id":"BCH-USD","sequence":4839271397,"time":"2018-07-27T01:32:39.412000Z"}
{"type":"open","side":"sell","price":"795.68000000","order_id":"ede19e0c-2ec5-4d65-91c2-5a63b0b759b4","remaining_size":"4.50000000","product_id":"BCH-USD","sequence":4839271398,"time":"2018-07-27T01:32:39.412000Z"}
{"type":"done","side":"sell","order_id":"674db05e-9956-4309-bad2-db692a29259f","reason":"canceled","product_id":"BCH-USD","price":"795.28000000","remaining_size":"4.50000000","sequence":4839271399,"time":"2018-07-27T01:32:39.412000Z"}
{"type":"done","side":"buy","order_id":"0a65a038-8736-468c-afd3-fe431580a9dd","reason":"canceled","product_id":"BCH-USD","price":"784.55000000","remaining_size":"0.01901000","sequence":4839271400,"time":"2018-07-27T01:32:39.415000Z"}
{"type":"received","order_id":"32f2e318-6bb3-4af2-9b3a-cac8f7a8b545","order_type":"limit","size":"1.90000000","price":"795.27000000","side":"sell","client_oid":"61bf842e-9c41-47fb-a638-cd83bf99f01e","product_id":"BCH-USD","sequence":4839271401,"time":"2018-07-27T01:32:39.416000Z"}
{"type":"open","side":"sell","price":"795.27000000","order_id":"32f2e318-6bb3-4af2-9b3a-cac8f7a8b545","remaining_size":"1.90000000","product_id":"BCH-USD","sequence":4839271402,"time":"2018-07-27T01:32:39.416000Z"}
{"type":"done","side":"sell","order_id":"32f2e318-6bb3-4af2-9b3a-cac8f7a8b545","reason":"canceled","product_id":"BCH-USD","price":"795.27000000","remaining_size":"1.90000000","sequence":4839271403,"time":"2018-07-27T01:32:39.420000Z"}
{"type":"received","order_id":"ac93789d-fd29-43c8-bb5e-a432fb4c3574","order_type":"limit","size":"14.24999000","price":"460.71000000","side":"buy","client_oid":"e8941ac6-dbb0-4b1f-a516-bcfbd92301fd","product_id":"ETH-USD","sequence":4469354736,"time":"2018-07-27T01:32:39.421000Z"}
{"type":"open","side":"buy","price":"460.71000000","order_id":"ac93789d-fd29-43c8-bb5e-a432fb4c3574","remaining_size":"14.24999000","product_id":"ETH-USD","sequence":4469354737,"time":"2018-07-27T01:32:39.421000Z"}
{"type":"received","order_id":"341c72cd-0b9e-4596-a0c6-ec8b6dea572e","order_type":"limit","size":"1.81488800","price":"791.23000000","side":"buy","client_oid":"b7ade48c-5354-4b39-9f8d-38979e2f5ce3","product_id":"BCH-USD","sequence":4839271404,"time":"2018-07-27T01:32:39.422000Z"}
{"type":"open","side":"buy","price":"791.23000000","order_id":"341c72cd-0b9e-4596-a0c6-ec8b6dea572e","remaining_size":"1.81488800","product_id":"BCH-USD","sequence":4839271405,"time":"2018-07-27T01:32:39.422000Z"}
{"type":"received","order_id":"793ba010-27e1-41e3-b7ad-562a105c16e7","order_type":"limit","size":"7.44874862","price":"83.38000000","side":"sell","client_oid":"490c61b5-5c4c-4102-8000-01f855ef7390","product_id":"LTC-USD","sequence":2423271666,"time":"2018-07-27T01:32:39.427000Z"}
{"type":"open","side":"sell","price":"83.38000000","order_id":"793ba010-27e1-41e3-b7ad-562a105c16e7","remaining_size":"7.44874862","product_id":"LTC-USD","sequence":2423271667,"time":"2018-07-27T01:32:39.427000Z"}
{"type":"received","order_id":"a06c821d-9c03-4ab1-ad54-412246c418cd","order_type":"limit","size":"4.50000000","price":"795.27000000","side":"sell","client_oid":"daf0ad9e-157a-4db2-a18c-bf96bef2da42","product_id":"BCH-USD","sequence":4839271406,"time":"2018-07-27T01:32:39.428000Z"}
{"type":"open","side":"sell","price":"795.27000000","order_id":"a06c821d-9c03-4ab1-ad54-412246c418cd","remaining_size":"4.50000000","product_id":"BCH-USD","sequence":4839271407,"time":"2018-07-27T01:32:39.428000Z"}
{"type":"received","order_id":"8f073660-dc66-48c6-9f00-516ea6abf2dc","order_type":"limit","size":"0.18739300","price":"791.23000000","side":"buy","client_oid":"bd83553b-36e8-4fa7-a96c-da5ac6c4a2d8","product_id":"BCH-USD","sequence":4839271408,"time":"2018-07-27T01:32:39.430000Z"}
{"type":"open","side":"buy","price":"791.23000000","order_id":"8f073660-dc66-48c6-9f00-516ea6abf2dc","remaining_size":"0.18739300","product_id":"BCH-USD","sequence":4839271409,"time":"2018-07-27T01:32:39.430000Z"}
{"type":"done","side":"sell","order_id":"81998b81-1cae-432b-ac69-9d29eb20f8dd","reason":"canceled","product_id":"BCH-USD","price":"795.26000000","remaining_size":"1.90000000","sequence":4839271410,"time":"2018-07-27T01:32:39.432000Z"}
{"type":"done","side":"sell","order_id":"7566b3ea-67a4-41bd-b421-ad9e8e311ead","reason":"canceled","product_id":"BCH-USD","price":"795.26000000","remaining_size":"0.90000000","sequence":4839271411,"time":"2018-07-27T01:32:39.434000Z"}
{"type":"received","order_id":"e806db61-79d7-4785-8a71-55dd7166d852","order_type":"limit","size":"1.90000000","price":"795.25000000","side":"sell","client_oid":"13f5e601-36e8-493b-b8c6-ce04583b3c6d","product_id":"BCH-USD","sequence":4839271412,"time":"2018-07-27T01:32:39.435000Z"}
{"type":"open","side":"sell","price":"795.25000000","order_id":"e806db61-79d7-4785-8a71-55dd7166d852","remaining_size":"1.90000000","product_id":"BCH-USD","sequence":4839271413,"time":"2018-07-27T01:32:39.435000Z"}
{"type":"received","order_id":"bbd14313-9e98-40ef-89b8-d9a91d574c85","order_type":"limit","size":"0.01913000","price":"780.03000000","side":"buy","client_oid":"e77d81db-cba2-4dec-9de4-8048ec4566e0","product_id":"BCH-USD","sequence":4839271414,"time":"2018-07-27T01:32:39.436000Z"}
{"type":"open","side":"buy","price":"780.03000000","order_id":"bbd14313-9e98-40ef-89b8-d9a91d574c85","remaining_size":"0.01913000","product_id":"BCH-USD","sequence":4839271415,"time":"2018-07-27T01:32:39.436000Z"}
{"type":"done","side":"sell","order_id":"ede19e0c-2ec5-4d65-91c2-5a63b0b759b4","reason":"canceled","product_id":"BCH-USD","price":"795.68000000","remaining_size":"4.50000000","sequence":4839271416,"time":"2018-07-27T01:32:39.440000Z"}
{"type":"done","side":"sell","order_id":"288a6e3d-1694-4cb9-a11c-a9d6a6e11173","reason":"canceled","product_id":"LTC-USD","price":"83.30000000","remaining_size":"7.44874862","sequence":2423271668,"time":"2018-07-27T01:32:39.443000Z"}
{"type":"done","side":"sell","order_id":"e806db61-79d7-4785-8a71-55dd7166d852","reason":"canceled","product_id":"BCH-USD","price":"795.25000000","remaining_size":"1.90000000","sequence":4839271417,"time":"2018-07-27T01:32:39.443000Z"}
{"type":"done","side":"buy","order_id":"8f073660-dc66-48c6-9f00-516ea6abf2dc","reason":"canceled","product_id":"BCH-USD","price":"791.23000000","remaining_size":"0.18739300","sequence":4839271418,"time":"2018-07-27T01:32:39.446000Z"}
{"type":"received","order_id":"cad4bf64-facd-4048-b731-12e09a4a0dac","order_type":"limit","size":"1.90000000","price":"795.28000000","side":"sell","client_oid":"b3c5a506-d51c-4ba5-8d1b-731366739483","product_id":"BCH-USD","sequence":4839271419,"time":"2018-07-27T01:32:39.447000Z"}
{"type":"open","side":"sell","price":"795.28000000","order_id":"cad4bf64-facd-4048-b731-12e09a4a0dac","remaining_size":"1.90000000","product_id":"BCH-USD","sequence":4839271420,"time":"2018-07-27T01:32:39.447000Z"}
{"type":"done","side":"sell","order_id":"70d09ab2-a084-4ca3-819b-993cfcf58a44","reason":"canceled","product_id":"BCH-USD","price":"794.00000000","remaining_size":"2.00000000","sequence":4839271421,"time":"2018-07-27T01:32:39.448000Z"}
{"type":"received","order_id":"2148bde2-6fab-4b30-9e3e-ef2dae3c2cd8","order_type":"limit","size":"4.50000000","price":"795.67000000","side":"sell","client_oid":"8618b080-03cb-44e2-b99c-2304e2a80926","product_id":"BCH-USD","sequence":4839271422,"time":"2018-07-27T01:32:39.450000Z"}
{"type":"open","side":"sell","price":"795.67000000","order_id":"2148bde2-6fab-4b30-9e3e-ef2dae3c2cd8","remaining_size":"4.50000000","product_id":"BCH-USD","sequence":4839271423,"time":"2018-07-27T01:32:39.450000Z"}
{"type":"received","order_id":"a96d9f61-f79e-400d-8728-545b3617a401","order_type":"limit","size":"1.90000000","price":"795.26000000","side":"sell","client_oid":"d18b24e4-1747-4a43-9226-1e1154e259de","product_id":"BCH-USD","sequence":4839271424,"time":"2018-07-27T01:32:39.451000Z"}
{"type":"open","side":"sell","price":"795.26000000","order_id":"a96d9f61-f79e-400d-8728-545b3617a401","remaining_size":"1.90000000","product_id":"BCH-USD","sequence":4839271425,"time":"2018-07-27T01:32:39.451000Z"}
{"type":"done","side":"sell","order_id":"cad4bf64-facd-4048-b731-12e09a4a0dac","reason":"canceled","product_id":"BCH-USD","price":"795.28000000","remaining_size":"1.90000000","sequence":4839271426,"time":"2018-07-27T01:32:39.451000Z"}
{"type":"done","side":"sell","order_id":"a06c821d-9c03-4ab1-ad54-412246c418cd","reason":"canceled","product_id":"BCH-USD","price":"795.27000000","remaining_size":"4.50000000","sequence":4839271427,"time":"2018-07-27T01:32:39.453000Z"}
{"type":"received","order_id":"712b816f-5c14-4c24-a31a-2ed319c19d16","order_type":"limit","size":"0.90000000","price":"795.28000000","side":"sell","client_oid":"c8d6195e-267f-4cc3-9808-1a0eac269442","product_id":"BCH-USD","sequence":4839271428,"time":"2018-07-27T01:32:39.456000Z"}
{"type":"open","side":"sell","price":"795.28000000","order_id":"712b816f-5c14-4c24-a31a-2ed319c19d16","remaining_size":"0.90000000","product_id":"BCH-USD","sequence":4839271429,"time":"2018-07-27T01:32:39.456000Z"}
{"type":"received","order_id":"598395e3-f11e-4323-bc02-3f644944621f","order_type":"limit","size":"0.18739300","price":"791.24000000","side":"buy","client_oid":"66badb90-632f-4a9d-bacf-96a4df0cc714","product_id":"BCH-USD","sequence":4839271430,"time":"2018-07-27T01:32:39.457000Z"}
{"type":"open","side":"buy","price":"791.24000000","order_id":"598395e3-f11e-4323-bc02-3f644944621f","remaining_size":"0.18739300","product_id":"BCH-USD","sequence":4839271431,"time":"2018-07-27T01:32:39.457000Z"}
{"type":"done","side":"sell","order_id":"712b816f-5c14-4c24-a31a-2ed319c19d16","reason":"canceled","product_id":"BCH-USD","price":"795.28000000","remaining_size":"0.90000000","sequence":4839271432,"time":"2018-07-27T01:32:39.459000Z"}
{"type":"received","order_id":"f497aa98-dc3e-4902-9ad2-42204b7443da","order_type":"limit","size":"4.50000000","price":"795.26000000","side":"sell","client_oid":"24d53f6a-fac9-4d39-8dab-e510ee2d85da","product_id":"BCH-USD","sequence":4839271433,"time":"2018-07-27T01:32:39.460000Z"}
{"type":"open","side":"sell","price":"795.26000000","order_id":"f497aa98-dc3e-4902-9ad2-42204b7443da","remaining_size":"4.50000000","product_id":"BCH-USD","sequence":4839271434,"time":"2018-07-27T01:32:39.460000Z"}
{"type":"done","side":"sell","order_id":"2148bde2-6fab-4b30-9e3e-ef2dae3c2cd8","reason":"canceled","product_id":"BCH-USD","price":"795.67000000","remaining_size":"4.50000000","sequence":4839271435,"time":"2018-07-27T01:32:39.460000Z"}
{"type":"received","order_id":"67790db0-f7f4-4314-940f-5935a1458caa","order_type":"limit","size":"7.44874862","price":"83.34000000","side":"sell","client_oid":"0240d8b1-0f2c-4c46-8000-0027aeb1bf37","product_id":"LTC-USD","sequence":2423271669,"time":"2018-07-27T01:32:39.462000Z"}
{"type":"open","side":"sell","price":"83.34000000","order_id":"67790db0-f7f4-4314-940f-5935a1458caa","remaining_size":"7.44874862","product_id":"LTC-USD","sequence":2423271670,"time":"2018-07-27T01:32:39.462000Z"}
{"type":"done","side":"sell","order_id":"a96d9f61-f79e-400d-8728-545b3617a401","reason":"canceled","product_id":"BCH-USD","price":"795.26000000","remaining_size":"1.90000000","sequence":4839271436,"time":"2018-07-27T01:32:39.463000Z"}
{"type":"done","side":"sell","order_id":"f497aa98-dc3e-4902-9ad2-42204b7443da","reason":"canceled","product_id":"BCH-USD","price":"795.26000000","remaining_size":"4.50000000","sequence":4839271437,"time":"2018-07-27T01:32:39.463000Z"}
{"type":"received","order_id":"745340dc-7178-4d1d-8331-22e21d0d84e5","order_type":"limit","size":"2.00000000","price":"794.00000000","side":"sell","client_oid":"424d1550-7a47-47c7-a8d4-223fc5e5f68b","product_id":"BCH-USD","sequence":4839271438,"time":"2018-07-27T01:32:39.465000Z"}
{"type":"open","side":"sell","price":"794.00000000","order_id":"745340dc-7178-4d1d-8331-22e21d0d84e5","remaining_size":"2.00000000","product_id":"BCH-USD","sequence":4839271439,"time":"2018-07-27T01:32:39.465000Z"}
{"type":"received","order_id":"72b50716-b8fd-49f6-bff3-2020507e4f23","order_type":"limit","size":"4.50000000","price":"795.68000000","side":"sell","client_oid":"1790b8d0-efe1-4f1f-b5e8-958cd0580fc3","product_id":"BCH-USD","sequence":4839271440,"time":"2018-07-27T01:32:39.469000Z"}
{"type":"open","side":"sell","price":"795.68000000","order_id":"72b50716-b8fd-49f6-bff3-2020507e4f23","remaining_size":"4.50000000","product_id":"BCH-USD","sequence":4839271441,"time":"2018-07-27T01:32:39.469000Z"}
{"type":"done","side":"sell","order_id":"745340dc-7178-4d1d-8331-22e21d0d84e5","reason":"canceled","product_id":"BCH-USD","price":"794.00000000","remaining_size":"2.00000000","sequence":4839271442,"time":"2018-07-27T01:32:39.469000Z"}
{"type":"received","order_id":"ff738b4b-ff24-46fb-b566-db44d3667182","order_type":"limit","size":"1.90000000","price":"795.29000000","side":"sell","client_oid":"69a98b69-e674-4eb0-a1c7-bbba88674d4a","product_id":"BCH-USD","sequence":4839271443,"time":"2018-07-27T01:32:39.470000Z"}
{"type":"open","side":"sell","price":"795.29000000","order_id":"ff738b4b-ff24-46fb-b566-db44d3667182","remaining_size":"1.90000000","product_id":"BCH-USD","sequence":4839271444,"time":"2018-07-27T01:32:39.470000Z"}
{"type":"done","side":"sell","order_id":"793ba010-27e1-41e3-b7ad-562a105c16e7","reason":"canceled","product_id":"LTC-USD","price":"83.38000000","remaining_size":"7.44874862","sequence":2423271671,"time":"2018-07-27T01:32:39.473000Z"}
{"type":"received","order_id":"5e15ba4d-c8d5-4889-b087-24bb93bbc43b","order_type":"limit","size":"4.50000000","price":"795.29000000","side":"sell","client_oid":"e8765924-a359-4e06-99ba-8359c71c528e","product_id":"BCH-USD","sequence":4839271445,"time":"2018-07-27T01:32:39.472000Z"}
{"type":"open","side":"sell","price":"795.29000000","order_id":"5e15ba4d-c8d5-4889-b087-24bb93bbc43b","remaining_size":"4.50000000","product_id":"BCH-USD","sequence":4839271446,"time":"2018-07-27T01:32:39.472000Z"}
{"type":"received","order_id":"537dd8cb-3060-4a6f-88e4-308e306a1f1e","order_type":"limit","size":"1.90000000","price":"795.27000000","side":"sell","client_oid":"1eb67c67-a008-42fc-a0d2-af24932a66ad","product_id":"BCH-USD","sequence":4839271447,"time":"2018-07-27T01:32:39.473000Z"}
{"type":"open","side":"sell","price":"795.27000000","order_id":"537dd8cb-3060-4a6f-88e4-308e306a1f1e","remaining_size":"1.90000000","product_id":"BCH-USD","sequence":4839271448,"time":"2018-07-27T01:32:39.473000Z"}
{"type":"received","order_id":"99f90b1b-5346-4b10-a001-2190581ded41","order_type":"limit","size":"0.90000000","price":"795.27000000","side":"sell","client_oid":"a1bf5eb2-5530-4ce9-8dc2-d44f05e25f96","product_id":"BCH-USD","sequence":4839271449,"time":"2018-07-27T01:32:39.474000Z"}
{"type":"open","side":"sell","price":"795.27000000","order_id":"99f90b1b-5346-4b10-a001-2190581ded41","remaining_size":"0.90000000","product_id":"BCH-USD","sequence":4839271450,"time":"2018-07-27T01:32:39.474000Z"}
{"type":"done","side":"sell","order_id":"72b50716-b8fd-49f6-bff3-2020507e4f23","reason":"canceled","product_id":"BCH-USD","price":"795.68000000","remaining_size":"4.50000000","sequence":4839271451,"time":"2018-07-27T01:32:39.475000Z"}
{"type":"done","side":"sell","order_id":"537dd8cb-3060-4a6f-88e4-308e306a1f1e","reason":"canceled","product_id":"BCH-USD","price":"795.27000000","remaining_size":"1.90000000","sequence":4839271452,"time":"2018-07-27T01:32:39.478000Z"}
{"type":"received","order_id":"22cb87ef-023f-48c7-8827-ee6313a80127","order_type":"limit","size":"7.44874862","price":"83.30000000","side":"sell","client_oid":"0235df3d-e957-4ded-8000-005579a112f8","product_id":"LTC-USD","sequence":2423271672,"time":"2018-07-27T01:32:39.481000Z"}
{"type":"open","side":"sell","price":"83.30000000","order_id":"22cb87ef-023f-48c7-8827-ee6313a80127","remaining_size":"7.44874862","product_id":"LTC-USD","sequence":2423271673,"time":"2018-07-27T01:32:39.481000Z"}
{"type":"received","order_id":"d5d56ca3-5f09-49f2-abf1-5af1b3a782a5","order_type":"limit","size":"2.00000000","price":"794.37000000","side":"sell","client_oid":"888ccf98-932b-4c08-aafa-3b044f348a27","product_id":"BCH-USD","sequence":4839271453,"time":"2018-07-27T01:32:39.481000Z"}
{"type":"open","side":"sell","price":"794.37000000","order_id":"d5d56ca3-5f09-49f2-abf1-5af1b3a782a5","remaining_size":"2.00000000","product_id":"BCH-USD","sequence":4839271454,"time":"2018-07-27T01:32:39.481000Z"}
{"type":"done","side":"sell","order_id":"99f90b1b-5346-4b10-a001-2190581ded41","reason":"canceled","product_id":"BCH-USD","price":"795.27000000","remaining_size":"0.90000000","sequence":4839271455,"time":"2018-07-27T01:32:39.482000Z"}
{"type":"received","order_id":"95c0568a-41d6-4821-a99a-94a41afc97b8","order_type":"limit","size":"4.50000000","price":"795.67000000","side":"sell","client_oid":"76d8d07d-e9e5-4198-bb12-622f565bcca3","product_id":"BCH-USD","sequence":4839271456,"time":"2018-07-27T01:32:39.482000Z"}
{"type":"open","side":"sell","price":"795.67000000","order_id":"95c0568a-41d6-4821-a99a-94a41afc97b8","remaining_size":"4.50000000","product_id":"BCH-USD","sequence":4839271457,"time":"2018-07-27T01:32:39.482000Z"}
{"type":"done","side":"sell","order_id":"5e15ba4d-c8d5-4889-b087-24bb93bbc43b","reason":"canceled","product_id":"BCH-USD","price":"795.29000000","remaining_size":"4.50000000","sequence":4839271458,"time":"2018-07-27T01:32:39.483000Z"}
{"type":"done","side":"sell","order_id":"ff738b4b-ff24-46fb-b566-db44d3667182","reason":"canceled","product_id":"BCH-USD","price":"795.29000000","remaining_size":"1.90000000","sequence":4839271459,"time":"2018-07-27T01:32:39.486000Z"}
{"type":"done","side":"sell","order_id":"d5d56ca3-5f09-49f2-abf1-5af1b3a782a5","reason":"canceled","product_id":"BCH-USD","price":"794.37000000","remaining_size":"2.00000000","sequence":4839271460,"time":"2018-07-27T01:32:39.488000Z"}
{"type":"received","order_id":"599d2b95-29d4-412d-92a1-69e850154395","order_type":"limit","size":"1.90000000","price":"795.25000000","side":"sell","client_oid":"4336d2e5-badc-46a3-bcfa-61e717d7bb5a","product_id":"BCH-USD","sequence":4839271461,"time":"2018-07-27T01:32:39.489000Z"}
{"type":"open","side":"sell","price":"795.25000000","order_id":"599d2b95-29d4-412d-92a1-69e850154395","remaining_size":"1.90000000","product_id":"BCH-USD","sequence":4839271462,"time":"2018-07-27T01:32:39.489000Z"}
{"type":"received","order_id":"b6d2c45d-2b03-4bf9-be36-3ceba1fa4d7a","order_type":"limit","size":"0.10000000","price":"83.14000000","side":"buy","client_oid":"f2f294b4-913c-11e8-8d2c-16be7828d23e","product_id":"LTC-USD","sequence":2423271674,"time":"2018-07-27T01:32:39.492000Z"}
{"type":"done","side":"buy","order_id":"b6d2c45d-2b03-4bf9-be36-3ceba1fa4d7a","reason":"canceled","product_id":"LTC-USD","price":"83.14000000","remaining_size":"0.10000000","sequence":2423271675,"time":"2018-07-27T01:32:39.492000Z"}
{"type":"received","order_id":"cf940241-9c3d-4b17-8298-536043db7aff","order_type":"limit","size":"4.50000000","price":"795.26000000","side":"sell","client_oid":"5f8d94d1-0c84-4a02-b733-32ec46dbafde","product_id":"BCH-USD","sequence":4839271463,"time":"2018-07-27T01:32:39.493000Z"}
{"type":"open","side":"sell","price":"795.26000000","order_id":"cf940241-9c3d-4b17-8298-536043db7aff","remaining_size":"4.50000000","product_id":"BCH-USD","sequence":4839271464,"time":"2018-07-27T01:32:39.493000Z"}
{"type":"received","order_id":"08b421fa-16dd-4452-ba62-fe026bf9c430","order_type":"limit","size":"0.90000000","price":"795.25000000","side":"sell","client_oid":"b71896b5-e02c-4a2d-b90f-3e1fd4f90364","product_id":"BCH-USD","sequence":4839271465,"time":"2018-07-27T01:32:39.495000Z"}
{"type":"open","side":"sell","price":"795.25000000","order_id":"08b421fa-16dd-4452-ba62-fe026bf9c430","remaining_size":"0.90000000","product_id":"BCH-USD","sequence":4839271466,"time":"2018-07-27T01:32:39.495000Z"}
{"type":"received","order_id":"0f5b849d-7a5a-44b7-ba29-b059bd919912","order_type":"limit","size":"1.90000000","price":"795.26000000","side":"sell","client_oid":"6cf26c43-9d66-4166-8480-e7c4a0e12b6c","product_id":"BCH-USD","sequence":4839271467,"time":"2018-07-27T01:32:39.495000Z"}
{"type":"open","side":"sell","price":"795.26000000","order_id":"0f5b849d-7a5a-44b7-ba29-b059bd919912","remaining_size":"1.90000000","product_id":"BCH-USD","sequence":4839271468,"time":"2018-07-27T01:32:39.495000Z"}
{"type":"done","side":"sell","order_id":"67790db0-f7f4-4314-940f-5935a1458caa","reason":"canceled","product_id":"LTC-USD","price":"83.34000000","remaining_size":"7.44874862","sequence":2423271676,"time":"2018-07-27T01:32:39.499000Z"}
{"type":"done","side":"sell","order_id":"cf940241-9c3d-4b17-8298-536043db7aff","reason":"canceled","product_id":"BCH-USD","price":"795.26000000","remaining_size":"4.50000000","sequence":4839271469,"time":"2018-07-27T01:32:39.498000Z"}
{"type":"done","side":"sell","order_id":"0f5b849d-7a5a-44b7-ba29-b059bd919912","reason":"canceled","product_id":"BCH-USD","price":"795.26000000","remaining_size":"1.90000000","sequence":4839271470,"time":"2018-07-27T01:32:39.500000Z"}
{"type":"received","order_id":"c4ad76a4-75a8-4f47-b88b-0c9af6a9501d","order_type":"limit","size":"2.00000000","price":"794.37000000","side":"sell","client_oid":"00ddb6b4-c588-4cff-8bbd-41a1240bfc28","product_id":"BCH-USD","sequence":4839271471,"time":"2018-07-27T01:32:39.501000Z"}
{"type":"open","side":"sell","price":"794.37000000","order_id":"c4ad76a4-75a8-4f47-b88b-0c9af6a9501d","remaining_size":"2.00000000","product_id":"BCH-USD","sequence":4839271472,"time":"2018-07-27T01:32:39.501000Z"}
{"type":"received","order_id":"f0e14544-e317-477a-85b9-07e9140089ff","order_type":"limit","size":"4.50000000","price":"795.29000000","side":"sell","client_oid":"7009f768-68dc-441a-8e07-b3c6fa3f412c","product_id":"BCH-USD","sequence":4839271473,"time":"2018-07-27T01:32:39.506000Z"}
{"type":"open","side":"sell","price":"795.29000000","order_id":"f0e14544-e317-477a-85b9-07e9140089ff","remaining_size":"4.50000000","product_id":"BCH-USD","sequence":4839271474,"time":"2018-07-27T01:32:39.506000Z"}
{"type":"received","order_id":"9daf49e3-7b38-4422-9111-842b4445a7e8","order_type":"limit","size":"1.90000000","price":"795.29000000","side":"sell","client_oid":"285ee7a8-e507-45ad-bfe7-cdafb25b14dc","product_id":"BCH-USD","sequence":4839271475,"time":"2018-07-27T01:32:39.509000Z"}
{"type":"open","side":"sell","price":"795.29000000","order_id":"9daf49e3-7b38-4422-9111-842b4445a7e8","remaining_size":"1.90000000","product_id":"BCH-USD","sequence":4839271476,"time":"2018-07-27T01:32:39.509000Z"}
{"type":"done","side":"sell","order_id":"f0e14544-e317-477a-85b9-07e9140089ff","reason":"canceled","product_id":"BCH-USD","price":"795.29000000","remaining_size":"4.50000000","sequence":4839271477,"time":"2018-07-27T01:32:39.510000Z"}
{"type":"done","side":"buy","order_id":"341c72cd-0b9e-4596-a0c6-ec8b6dea572e","reason":"canceled","product_id":"BCH-USD","price":"791.23000000","remaining_size":"1.81488800","sequence":4839271478,"time":"2018-07-27T01:32:39.511000Z"}
{"type":"received","order_id":"b2b5ece8-7967-43b0-838f-541463ced1ee","order_type":"limit","size":"7.44874862","price":"83.38000000","side":"sell","client_oid":"7eb10238-b9cd-436f-8000-0026f622cc9c","product_id":"LTC-USD","sequence":2423271677,"time":"2018-07-27T01:32:39.513000Z"}
{"type":"done","side":"sell","order_id":"c4ad76a4-75a8-4f47-b88b-0c9af6a9501d","reason":"canceled","product_id":"BCH-USD","price":"794.37000000","remaining_size":"2.00000000","sequence":4839271479,"time":"2018-07-27T01:32:39.512000Z"}
{"type":"open","side":"sell","price":"83.38000000","order_id":"b2b5ece8-7967-43b0-838f-541463ced1ee","remaining_size":"7.44874862","product_id":"LTC-USD","sequence":2423271678,"time":"2018-07-27T01:32:39.513000Z"}
{"type":"done","side":"sell","order_id":"9daf49e3-7b38-4422-9111-842b4445a7e8","reason":"canceled","product_id":"BCH-USD","price":"795.29000000","remaining_size":"1.90000000","sequence":4839271480,"time":"2018-07-27T01:32:39.513000Z"}
{"type":"done","side":"sell","order_id":"08b421fa-16dd-4452-ba62-fe026bf9c430","reason":"canceled","product_id":"BCH-USD","price":"795.25000000","remaining_size":"0.90000000","sequence":4839271481,"time":"2018-07-27T01:32:39.516000Z"}
{"type":"done","side":"sell","order_id":"599d2b95-29d4-412d-92a1-69e850154395","reason":"canceled","product_id":"BCH-USD","price":"795.25000000","remaining_size":"1.90000000","sequence":4839271482,"time":"2018-07-27T01:32:39.516000Z"}
{"type":"received","order_id":"52f5a421-2633-441e-b4bf-ff8d9afaafd3","order_type":"limit","size":"1.81488800","price":"791.24000000","side":"buy","client_oid":"41e52be3-56a4-405c-86e2-0619d209a7ea","product_id":"BCH-USD","sequence":4839271483,"time":"2018-07-27T01:32:39.518000Z"}
{"type":"open","side":"buy","price":"791.24000000","order_id":"52f5a421-2633-441e-b4bf-ff8d9afaafd3","remaining_size":"1.81488800","product_id":"BCH-USD","sequence":4839271484,"time":"2018-07-27T01:32:39.518000Z"}
{"type":"done","side":"buy","order_id":"598395e3-f11e-4323-bc02-3f644944621f","reason":"canceled","product_id":"BCH-USD","price":"791.24000000","remaining_size":"0.18739300","sequence":4839271485,"time":"2018-07-27T01:32:39.518000Z"}
{"type":"received","order_id":"a5cf00c3-47f8-4c86-8bde-2def084d41d1","order_type":"limit","size":"4.50000000","price":"795.24000000","side":"sell","client_oid":"0f306282-27c6-47e8-89d7-fc62abc95525","product_id":"BCH-USD","sequence":4839271486,"time":"2018-07-27T01:32:39.519000Z"}
{"type":"open","side":"sell","price":"795.24000000","order_id":"a5cf00c3-47f8-4c86-8bde-2def084d41d1","remaining_size":"4.50000000","product_id":"BCH-USD","sequence":4839271487,"time":"2018-07-27T01:32:39.519000Z"}
{"type":"done","side":"sell","order_id":"95c0568a-41d6-4821-a99a-94a41afc97b8","reason":"canceled","product_id":"BCH-USD","price":"795.67000000","remaining_size":"4.50000000","sequence":4839271488,"time":"2018-07-27T01:32:39.521000Z"}
{"type":"done","side":"sell","order_id":"22cb87ef-023f-48c7-8827-ee6313a80127","reason":"canceled","product_id":"LTC-USD","price":"83.30000000","remaining_size":"7.44874862","sequence":2423271679,"time":"2018-07-27T01:32:39.523000Z"}
{"type":"received","order_id":"cfde6c05-0fb4-4c60-b240-d05defb5c341","order_type":"limit","size":"2.00000000","price":"794.00000000","side":"sell","client_oid":"44aca9af-1878-484e-96ad-51e77d13da03","product_id":"BCH-USD","sequence":4839271489,"time":"2018-07-27T01:32:39.523000Z"}
{"type":"open","side":"sell","price":"794.00000000","order_id":"cfde6c05-0fb4-4c60-b240-d05defb5c341","remaining_size":"2.00000000","product_id":"BCH-USD","sequence":4839271490,"time":"2018-07-27T01:32:39.523000Z"}
{"type":"received","order_id":"6b5b32d4-6f14-4b21-b324-2c755d20284a","order_type":"limit","size":"0.90000000","price":"795.26000000","side":"sell","client_oid":"10698cc8-077d-4f61-91bc-a14bb3e2d16e","product_id":"BCH-USD","sequence":4839271491,"time":"2018-07-27T01:32:39.523000Z"}
{"type":"done","side":"sell","order_id":"bfadc978-6858-4698-b30f-35a957665348","reason":"canceled","product_id":"ETH-USD","price":"486.55000000","remaining_size":"0.01000000","sequence":4469354738,"time":"2018-07-27T01:32:39.524000Z"}
{"type":"open","side":"sell","price":"795.26000000","order_id":"6b5b32d4-6f14-4b21-b324-2c755d20284a","remaining_size":"0.90000000","product_id":"BCH-USD","sequence":4839271492,"time":"2018-07-27T01:32:39.523000Z"}
{"type":"received","order_id":"6c8d315d-ea62-43a5-9478-26779a2da288","order_type":"limit","size":"1.90000000","price":"795.24000000","side":"sell","client_oid":"61a994b9-b348-440b-84d8-5393099850da","product_id":"BCH-USD","sequence":4839271493,"time":"2018-07-27T01:32:39.525000Z"}
{"type":"open","side":"sell","price":"795.24000000","order_id":"6c8d315d-ea62-43a5-9478-26779a2da288","remaining_size":"1.90000000","product_id":"BCH-USD","sequence":4839271494,"time":"2018-07-27T01:32:39.525000Z"}
{"type":"done","side":"sell","order_id":"cfde6c05-0fb4-4c60-b240-d05defb5c341","reason":"canceled","product_id":"BCH-USD","price":"794.00000000","remaining_size":"2.00000000","sequence":4839271495,"time":"2018-07-27T01:32:39.527000Z"}
{"type":"done","side":"sell","order_id":"6c8d315d-ea62-43a5-9478-26779a2da288","reason":"canceled","product_id":"BCH-USD","price":"795.24000000","remaining_size":"1.90000000","sequence":4839271496,"time":"2018-07-27T01:32:39.529000Z"}
{"type":"done","side":"sell","order_id":"a5cf00c3-47f8-4c86-8bde-2def084d41d1","reason":"canceled","product_id":"BCH-USD","price":"795.24000000","remaining_size":"4.50000000","sequence":4839271497,"time":"2018-07-27T01:32:39.531000Z"}
{"type":"done","side":"sell","order_id":"6b5b32d4-6f14-4b21-b324-2c755d20284a","reason":"canceled","product_id":"BCH-USD","price":"795.26000000","remaining_size":"0.90000000","sequence":4839271498,"time":"2018-07-27T01:32:39.532000Z"}
{"type":"received","order_id":"0a1c47d4-e525-4d27-9f79-96deb865cd0f","order_type":"limit","size":"0.18739300","price":"791.23000000","side":"buy","client_oid":"f04abb2c-9db3-460d-8a69-e00ffc6be496","product_id":"BCH-USD","sequence":4839271499,"time":"2018-07-27T01:32:39.533000Z"}
{"type":"open","side":"buy","price":"791.23000000","order_id":"0a1c47d4-e525-4d27-9f79-96deb865cd0f","remaining_size":"0.18739300","product_id":"BCH-USD","sequence":4839271500,"time":"2018-07-27T01:32:39.533000Z"}
{"type":"received","order_id":"1f81c775-ce85-4941-8b76-528975f2e9b9","order_type":"limit","size":"7.44874862","price":"83.34000000","side":"sell","client_oid":"98f46349-394e-4224-8000-0076a423d161","product_id":"LTC-USD","sequence":2423271680,"time":"2018-07-27T01:32:39.538000Z"}
{"type":"open","side":"sell","price":"83.34000000","order_id":"1f81c775-ce85-4941-8b76-528975f2e9b9","remaining_size":"7.44874862","product_id":"LTC-USD","sequence":2423271681,"time":"2018-07-27T01:32:39.538000Z"}
{"type":"received","order_id":"1bf4ab80-b3a0-4197-bf87-7dab1b7cdaab","order_type":"limit","size":"1.90000000","price":"795.26000000","side":"sell","client_oid":"595765f5-b716-4605-8390-693872abb52f","product_id":"BCH-USD","sequence":4839271501,"time":"2018-07-27T01:32:39.537000Z"}
{"type":"open","side":"sell","price":"795.26000000","order_id":"1bf4ab80-b3a0-4197-bf87-7dab1b7cdaab","remaining_size":"1.90000000","product_id":"BCH-USD","sequence":4839271502,"time":"2018-07-27T01:32:39.537000Z"}
{"type":"done","side":"buy","order_id":"ce747b9c-e68c-4a58-9703-201156c7a854","reason":"canceled","product_id":"BCH-USD","price":"792.80000000","remaining_size":"2.00000000","sequence":4839271503,"time":"2018-07-27T01:32:39.539000Z"}
{"type":"done","side":"buy","order_id":"125b4090-c46f-4dfd-ac1e-fb74f385e033","reason":"canceled","product_id":"LTC-USD","price":"83.05000000","remaining_size":"3.04869500","sequence":2423271682,"time":"2018-07-27T01:32:39.542000Z"}
{"type":"received","order_id":"d56d4972-40d0-4f70-b546-91f24bf1a12e","order_type":"limit","size":"4.50000000","price":"795.68000000","side":"sell","client_oid":"30cc340c-efc2-401a-a217-04adc0531897","product_id":"BCH-USD","sequence":4839271504,"time":"2018-07-27T01:32:39.542000Z"}
{"type":"open","side":"sell","price":"795.68000000","order_id":"d56d4972-40d0-4f70-b546-91f24bf1a12e","remaining_size":"4.50000000","product_id":"BCH-USD","sequence":4839271505,"time":"2018-07-27T01:32:39.542000Z"}
{"type":"received","order_id":"adb555a5-e671-47db-8984-5d47a74730f4","order_type":"limit","size":"4.50000000","price":"795.23000000","side":"sell","client_oid":"c389a0e7-f0bc-4a9e-b8ef-ca8bb90fb82e","product_id":"BCH-USD","sequence":4839271506,"time":"2018-07-27T01:32:39.545000Z"}
{"type":"done","side":"buy","order_id":"0e6a23a8-8db0-4bcc-adde-8be64d30d8b3","reason":"canceled","product_id":"BTC-USD","price":"6663.24000000","remaining_size":"0.00150000","sequence":6418130200,"time":"2018-07-27T01:32:39.547000Z"}
{"type":"done","side":"sell","order_id":"b2b5ece8-7967-43b0-838f-541463ced1ee","reason":"canceled","product_id":"LTC-USD","price":"83.38000000","remaining_size":"7.44874862","sequence":2423271683,"time":"2018-07-27T01:32:39.547000Z"}
{"type":"open","side":"sell","price":"795.23000000","order_id":"adb555a5-e671-47db-8984-5d47a74730f4","remaining_size":"4.50000000","product_id":"BCH-USD","sequence":4839271507,"time":"2018-07-27T01:32:39.545000Z"}
{"type":"done","side":"buy","order_id":"70b0e358-4e53-458e-af97-8fd678db5a65","reason":"canceled","product_id":"LTC-USD","price":"83.03000000","remaining_size":"4.56965600","sequence":2423271684,"time":"2018-07-27T01:32:39.548000Z"}
{"type":"received","order_id":"58b24287-088f-408d-8e93-1a7459c74af0","order_type":"limit","size":"2.00000000","price":"794.00000000","side":"sell","client_oid":"3e6cdc4f-87f9-4bc6-99b9-d6dd37bcd957","product_id":"BCH-USD","sequence":4839271508,"time":"2018-07-27T01:32:39.546000Z"}
{"type":"open","side":"sell","price":"794.00000000","order_id":"58b24287-088f-408d-8e93-1a7459c74af0","remaining_size":"2.00000000","product_id":"BCH-USD","sequence":4839271509,"time":"2018-07-27T01:32:39.546000Z"}
{"type":"done","side":"sell","order_id":"d56d4972-40d0-4f70-b546-91f24bf1a12e","reason":"canceled","product_id":"BCH-USD","price":"795.68000000","remaining_size":"4.50000000","sequence":4839271510,"time":"2018-07-27T01:32:39.548000Z"}
{"type":"received","order_id":"697e2a3e-3a97-41ff-aea9-0b02c3fb63f5","order_type":"limit","size":"0.90000000","price":"795.27000000","side":"sell","client_oid":"3687a0bc-eef3-4ee8-9215-77a74de45490","product_id":"BCH-USD","sequence":4839271511,"time":"2018-07-27T01:32:39.548000Z"}
{"type":"open","side":"sell","price":"795.27000000","order_id":"697e2a3e-3a97-41ff-aea9-0b02c3fb63f5","remaining_size":"0.90000000","product_id":"BCH-USD","sequence":4839271512,"time":"2018-07-27T01:32:39.548000Z"}
{"type":"done","side":"sell","order_id":"adb555a5-e671-47db-8984-5d47a74730f4","reason":"canceled","product_id":"BCH-USD","price":"795.23000000","remaining_size":"4.50000000","sequence":4839271513,"time":"2018-07-27T01:32:39.550000Z"}
{"type":"received","order_id":"450ad95d-64d8-46ea-97fe-ad2e7c7b9c03","order_type":"limit","size":"0.00150000","price":"6630.01000000","side":"buy","client_oid":"d2fae012-c463-419d-8000-00a5291c5fff","product_id":"BTC-USD","sequence":6418130201,"time":"2018-07-27T01:32:39.554000Z"}
{"type":"open","side":"buy","price":"6630.01000000","order_id":"450ad95d-64d8-46ea-97fe-ad2e7c7b9c03","remaining_size":"0.00150000","product_id":"BTC-USD","sequence":6418130202,"time":"2018-07-27T01:32:39.554000Z"}
{"type":"received","order_id":"8b001228-680d-41e6-a6a7-5be1f3d3ef3c","order_type":"limit","size":"1.90000000","price":"795.23000000","side":"sell","client_oid":"bb7b32c3-4fc7-4b81-bd8a-105d3a5bdcd0","product_id":"BCH-USD","sequence":4839271514,"time":"2018-07-27T01:32:39.552000Z"}
{"type":"open","side":"sell","price":"795.23000000","order_id":"8b001228-680d-41e6-a6a7-5be1f3d3ef3c","remaining_size":"1.90000000","product_id":"BCH-USD","sequence":4839271515,"time":"2018-07-27T01:32:39.552000Z"}
{"type":"received","order_id":"26055177-d5b2-416d-81dc-d3097128b2c9","order_type":"limit","size":"1.60461000","price":"795.61000000","side":"sell","client_oid":"618784a3-bd1e-46cc-b832-7661c8760211","product_id":"BCH-USD","sequence":4839271516,"time":"2018-07-27T01:32:39.553000Z"}
{"type":"open","side":"sell","price":"795.61000000","order_id":"26055177-d5b2-416d-81dc-d3097128b2c9","remaining_size":"1.60461000","product_id":"BCH-USD","sequence":4839271517,"time":"2018-07-27T01:32:39.553000Z"}
{"type":"done","side":"sell","order_id":"697e2a3e-3a97-41ff-aea9-0b02c3fb63f5","reason":"canceled","product_id":"BCH-USD","price":"795.27000000","remaining_size":"0.90000000","sequence":4839271518,"time":"2018-07-27T01:32:39.553000Z"}
{"type":"done","side":"buy","order_id":"9bd98e4b-444e-4768-8d2d-c23347678907","reason":"canceled","product_id":"LTC-USD","price":"83.01000000","remaining_size":"9.38632400","sequence":2423271685,"time":"2018-07-27T01:32:39.557000Z"}
{"type":"received","order_id":"139dbbe6-2881-4278-8386-49d9c5c33ebe","order_type":"limit","size":"4.50000000","price":"795.67000000","side":"sell","client_oid":"c9714039-5a77-4314-bf68-d4717f628ea9","product_id":"BCH-USD","sequence":4839271519,"time":"2018-07-27T01:32:39.557000Z"}
{"type":"open","side":"sell","price":"795.67000000","order_id":"139dbbe6-2881-4278-8386-49d9c5c33ebe","remaining_size":"4.50000000","product_id":"BCH-USD","sequence":4839271520,"time":"2018-07-27T01:32:39.557000Z"}
{"type":"received","order_id":"a0ff1a49-076e-4541-aa07-8d11507e4352","order_type":"limit","size":"4.50000000","price":"795.29000000","side":"sell","client_oid":"7e872f54-5c98-4f78-babe-35040f0c4c19","product_id":"BCH-USD","sequence":4839271521,"time":"2018-07-27T01:32:39.557000Z"}
{"type":"open","side":"sell","price":"795.29000000","order_id":"a0ff1a49-076e-4541-aa07-8d11507e4352","remaining_size":"4.50000000","product_id":"BCH-USD","sequence":4839271522,"time":"2018-07-27T01:32:39.557000Z"}
{"type":"received","order_id":"46e384e2-8fe2-4d9f-a658-82ce6e127c2d","order_type":"limit","size":"7.44874862","price":"83.30000000","side":"sell","client_oid":"f19db51f-b9bb-4fce-8000-00f9f390621d","product_id":"LTC-USD","sequence":2423271686,"time":"2018-07-27T01:32:39.562000Z"}
{"type":"received","order_id":"e921924b-79fb-4e44-9e77-789effcf8dc5","order_type":"limit","size":"0.90000000","price":"795.28000000","side":"sell","client_oid":"d1b8d93e-2c7b-4bcc-aa1d-fe6f2a870ae8","product_id":"BCH-USD","sequence":4839271523,"time":"2018-07-27T01:32:39.561000Z"}
{"type":"open","side":"sell","price":"83.30000000","order_id":"46e384e2-8fe2-4d9f-a658-82ce6e127c2d","remaining_size":"7.44874862","product_id":"LTC-USD","sequence":2423271687,"time":"2018-07-27T01:32:39.562000Z"}
{"type":"open","side":"sell","price":"795.28000000","order_id":"e921924b-79fb-4e44-9e77-789effcf8dc5","remaining_size":"0.90000000","product_id":"BCH-USD","sequence":4839271524,"time":"2018-07-27T01:32:39.561000Z"}
{"type":"done","side":"buy","order_id":"b01c4e2d-d6d3-4383-b6c9-60725de8cb9a","reason":"canceled","product_id":"LTC-USD","price":"82.95000000","remaining_size":"27.41547700","sequence":2423271688,"time":"2018-07-27T01:32:39.564000Z"}
{"type":"done","side":"sell","order_id":"a0ff1a49-076e-4541-aa07-8d11507e4352","reason":"canceled","product_id":"BCH-USD","price":"795.29000000","remaining_size":"4.50000000","sequence":4839271525,"time":"2018-07-27T01:32:39.563000Z"}
{"type":"received","order_id":"1379c92f-2e29-4276-9fb2-f8019594373e","order_type":"limit","size":"1.90000000","price":"795.22000000","side":"sell","client_oid":"8f3b9042-8b42-4fd8-ad08-6c54fd48f9d5","product_id":"BCH-USD","sequence":4839271526,"time":"2018-07-27T01:32:39.564000Z"}
{"type":"open","side":"sell","price":"795.22000000","order_id":"1379c92f-2e29-4276-9fb2-f8019594373e","remaining_size":"1.90000000","product_id":"BCH-USD","sequence":4839271527,"time":"2018-07-27T01:32:39.564000Z"}
{"type":"done","side":"sell","order_id":"1bf4ab80-b3a0-4197-bf87-7dab1b7cdaab","reason":"canceled","product_id":"BCH-USD","price":"795.26000000","remaining_size":"1.90000000","sequence":4839271528,"time":"2018-07-27T01:32:39.564000Z"}
{"type":"done","side":"sell","order_id":"e921924b-79fb-4e44-9e77-789effcf8dc5","reason":"canceled","product_id":"BCH-USD","price":"795.28000000","remaining_size":"0.90000000","sequence":4839271529,"time":"2018-07-27T01:32:39.565000Z"}
{"type":"received","order_id":"a166d3bc-77c6-481a-992f-1b0437de342a","order_type":"limit","size":"0.01000000","price":"488.58000000","side":"sell","client_oid":"b742f190-2879-459d-8000-005276982069","product_id":"ETH-USD","sequence":4469354739,"time":"2018-07-27T01:32:39.568000Z"}
{"type":"done","side":"sell","order_id":"8b001228-680d-41e6-a6a7-5be1f3d3ef3c","reason":"canceled","product_id":"BCH-USD","price":"795.23000000","remaining_size":"1.90000000","sequence":4839271530,"time":"2018-07-27T01:32:39.566000Z"}
{"type":"open","side":"sell","price":"488.58000000","order_id":"a166d3bc-77c6-481a-992f-1b0437de342a","remaining_size":"0.01000000","product_id":"ETH-USD","sequence":4469354740,"time":"2018-07-27T01:32:39.568000Z"}
{"type":"done","side":"buy","order_id":"c7d1a752-12c9-4896-89e8-49c2717d211d","reason":"canceled","product_id":"LTC-USD","price":"82.93000000","remaining_size":"120.20633300","sequence":2423271689,"time":"2018-07-27T01:32:39.570000Z"}
{"type":"done","side":"sell","order_id":"1f81c775-ce85-4941-8b76-528975f2e9b9","reason":"canceled","product_id":"LTC-USD","price":"83.34000000","remaining_size":"7.44874862","sequence":2423271690,"time":"2018-07-27T01:32:39.571000Z"}
{"type":"received","order_id":"681bc912-6d0a-4fb5-873c-1a6a4062e5a2","order_type":"limit","size":"2.00000000","price":"793.11000000","side":"buy","client_oid":"bb56b3bc-3fc0-49fe-b080-5c0dbe4016ca","product_id":"BCH-USD","sequence":4839271531,"time":"2018-07-27T01:32:39.569000Z"}
{"type":"open","side":"buy","price":"793.11000000","order_id":"681bc912-6d0a-4fb5-873c-1a6a4062e5a2","remaining_size":"2.00000000","product_id":"BCH-USD","sequence":4839271532,"time":"2018-07-27T01:32:39.569000Z"}
{"type":"done","side":"sell","order_id":"1379c92f-2e29-4276-9fb2-f8019594373e","reason":"canceled","product_id":"BCH-USD","price":"795.22000000","remaining_size":"1.90000000","sequence":4839271533,"time":"2018-07-27T01:32:39.569000Z"}
{"type":"done","side":"buy","order_id":"0a1c47d4-e525-4d27-9f79-96deb865cd0f","reason":"canceled","product_id":"BCH-USD","price":"791.23000000","remaining_size":"0.18739300","sequence":4839271534,"time":"2018-07-27T01:32:39.571000Z"}
{"type":"received","order_id":"4a8c940b-b1a0-4d01-9c65-bfe564c3a584","order_type":"limit","size":"1.90000000","price":"795.29000000","side":"sell","client_oid":"3bc84be7-cc40-4994-9e46-9bdafaa6fb6a","product_id":"BCH-USD","sequence":4839271535,"time":"2018-07-27T01:32:39.572000Z"}
{"type":"open","side":"sell","price":"795.29000000","order_id":"4a8c940b-b1a0-4d01-9c65-bfe564c3a584","remaining_size":"1.90000000","product_id":"BCH-USD","sequence":4839271536,"time":"2018-07-27T01:32:39.572000Z"}
{"type":"done","side":"buy","order_id":"a0d0a0cb-793e-4e8e-a48b-d3b6fb112cbd","reason":"canceled","product_id":"LTC-USD","price":"82.91000000","remaining_size":"105.44461500","sequence":2423271691,"time":"2018-07-27T01:32:39.576000Z"}
{"type":"received","order_id":"74854140-55a0-4dcb-9523-6806e3719a39","order_type":"limit","size":"4.50000000","price":"795.26000000","side":"sell","client_oid":"6d0c55a0-c899-426e-9174-862f7c61eca1","product_id":"BCH-USD","sequence":4839271537,"time":"2018-07-27T01:32:39.575000Z"}
{"type":"open","side":"sell","price":"795.26000000","order_id":"74854140-55a0-4dcb-9523-6806e3719a39","remaining_size":"4.50000000","product_id":"BCH-USD","sequence":4839271538,"time":"2018-07-27T01:32:39.575000Z"}
{"type":"done","side":"sell","order_id":"4a8c940b-b1a0-4d01-9c65-bfe564c3a584","reason":"canceled","product_id":"BCH-USD","price":"795.29000000","remaining_size":"1.90000000","sequence":4839271539,"time":"2018-07-27T01:32:39.575000Z"}
{"type":"received","order_id":"da3c6ffe-7899-458c-8eaa-67bb379fed8d","order_type":"limit","size":"0.90000000","price":"795.29000000","side":"sell","client_oid":"01516233-fe75-4703-bdfd-283e51387a00","product_id":"BCH-USD","sequence":4839271540,"time":"2018-07-27T01:32:39.578000Z"}
{"type":"open","side":"sell","price":"795.29000000","order_id":"da3c6ffe-7899-458c-8eaa-67bb379fed8d","remaining_size":"0.90000000","product_id":"BCH-USD","sequence":4839271541,"time":"2018-07-27T01:32:39.578000Z"}
{"type":"done","side":"sell","order_id":"08c0a027-0437-46d0-a4ec-c69992029ac6","reason":"canceled","product_id":"LTC-USD","price":"83.29000000","remaining_size":"21.22678200","sequence":2423271692,"time":"2018-07-27T01:32:39.580000Z"}
{"type":"received","order_id":"01694cb2-a060-4b5b-85b8-37f3bcba6915","order_type":"limit","size":"1.90000000","price":"795.26000000","side":"sell","client_oid":"dda7fef4-2086-4b0c-9c53-49345495e6ec","product_id":"BCH-USD","sequence":4839271542,"time":"2018-07-27T01:32:39.580000Z"}
{"type":"open","side":"sell","price":"795.26000000","order_id":"01694cb2-a060-4b5b-85b8-37f3bcba6915","remaining_size":"1.90000000","product_id":"BCH-USD","sequence":4839271543,"time":"2018-07-27T01:32:39.580000Z"}
{"type":"done","side":"sell","order_id":"74854140-55a0-4dcb-9523-6806e3719a39","reason":"canceled","product_id":"BCH-USD","price":"795.26000000","remaining_size":"4.50000000","sequence":4839271544,"time":"2018-07-27T01:32:39.582000Z"}
{"type":"done","side":"sell","order_id":"5f269e15-efe5-47d9-964b-9c246e0b3859","reason":"canceled","product_id":"LTC-USD","price":"83.30000000","remaining_size":"21.27450500","sequence":2423271693,"time":"2018-07-27T01:32:39.584000Z"}
{"type":"received","order_id":"3a653de1-e1d3-4e6a-a368-5489b5c2f606","order_type":"limit","size":"7.44874862","price":"83.38000000","side":"sell","client_oid":"1b20d9f2-1f17-4e50-8000-04fcdfc713f0","product_id":"LTC-USD","sequence":2423271694,"time":"2018-07-27T01:32:39.585000Z"}
{"type":"open","side":"sell","price":"83.38000000","order_id":"3a653de1-e1d3-4e6a-a368-5489b5c2f606","remaining_size":"7.44874862","product_id":"LTC-USD","sequence":2423271695,"time":"2018-07-27T01:32:39.585000Z"}
{"type":"received","order_id":"6ddda7d4-5614-411b-8ca9-9968371561a1","order_type":"limit","size":"0.18739300","price":"791.25000000","side":"buy","client_oid":"d64fa24a-e478-4023-8282-18c69d153165","product_id":"BCH-USD","sequence":4839271545,"time":"2018-07-27T01:32:39.584000Z"}
{"type":"open","side":"buy","price":"791.25000000","order_id":"6ddda7d4-5614-411b-8ca9-9968371561a1","remaining_size":"0.18739300","product_id":"BCH-USD","sequence":4839271546,"time":"2018-07-27T01:32:39.584000Z"}
{"type":"received","order_id":"3891399d-22d8-4e24-a9fc-bd2279d67999","order_type":"limit","size":"1.90000000","price":"795.24000000","side":"sell","client_oid":"f7dbd832-454f-4b4b-8992-acca7e2d1dd6","product_id":"BCH-USD","sequence":4839271547,"time":"2018-07-27T01:32:39.585000Z"}
{"type":"open","side":"sell","price":"795.24000000","order_id":"3891399d-22d8-4e24-a9fc-bd2279d67999","remaining_size":"1.90000000","product_id":"BCH-USD","sequence":4839271548,"time":"2018-07-27T01:32:39.585000Z"}
{"type":"done","side":"buy","order_id":"681bc912-6d0a-4fb5-873c-1a6a4062e5a2","reason":"canceled","product_id":"BCH-USD","price":"793.11000000","remaining_size":"2.00000000","sequence":4839271549,"time":"2018-07-27T01:32:39.586000Z"}
{"type":"done","side":"sell","order_id":"f76418dd-6d70-48e0-bcbf-eb2e61a9e9ca","reason":"canceled","product_id":"LTC-USD","price":"83.32000000","remaining_size":"18.05683200","sequence":2423271696,"time":"2018-07-27T01:32:39.588000Z"}
{"type":"done","side":"sell","order_id":"8609db74-a377-4fb1-bfb8-67ec4d54d52d","reason":"canceled","product_id":"LTC-USD","price":"83.34000000","remaining_size":"104.37178200","sequence":2423271697,"time":"2018-07-27T01:32:39.592000Z"}
{"type":"received","order_id":"06121aac-a710-4afc-93ae-63fdbff3ab66","order_type":"limit","size":"4.50000000","price":"795.25000000","side":"sell","client_oid":"2f39352a-dca0-45e7-b001-38c5e0cb5811","product_id":"BCH-USD","sequence":4839271550,"time":"2018-07-27T01:32:39.593000Z"}
{"type":"open","side":"sell","price":"795.25000000","order_id":"06121aac-a710-4afc-93ae-63fdbff3ab66","remaining_size":"4.50000000","product_id":"BCH-USD","sequence":4839271551,"time":"2018-07-27T01:32:39.593000Z"}
{"type":"done","side":"sell","order_id":"abb2556b-c9fe-4d4c-b3f7-e3895e7f8ec4","reason":"canceled","product_id":"LTC-USD","price":"83.37000000","remaining_size":"14.23750300","sequence":2423271698,"time":"2018-07-27T01:32:39.596000Z"}
{"type":"done","side":"sell","order_id":"32458cd3-3db4-4d49-bb02-b96e90e11f2a","reason":"canceled","product_id":"LTC-USD","price":"83.40000000","remaining_size":"8.45425500","sequence":2423271699,"time":"2018-07-27T01:32:39.600000Z"}
{"type":"done","side":"sell","order_id":"06121aac-a710-4afc-93ae-63fdbff3ab66","reason":"canceled","product_id":"BCH-USD","price":"795.25000000","remaining_size":"4.50000000","sequence":4839271552,"time":"2018-07-27T01:32:39.599000Z"}
{"type":"done","side":"sell","order_id":"139dbbe6-2881-4278-8386-49d9c5c33ebe","reason":"canceled","product_id":"BCH-USD","price":"795.67000000","remaining_size":"4.50000000","sequence":4839271553,"time":"2018-07-27T01:32:39.602000Z"}
{"type":"received","order_id":"8cb19b76-49fb-4427-b083-63b7eeaae025","order_type":"limit","size":"2.00000000","price":"792.80000000","side":"buy","client_oid":"36a975fd-ef02-45fe-8c0c-8cb4a4e3b898","product_id":"BCH-USD","sequence":4839271554,"time":"2018-07-27T01:32:39.603000Z"}
{"type":"open","side":"buy","price":"792.80000000","order_id":"8cb19b76-49fb-4427-b083-63b7eeaae025","remaining_size":"2.00000000","product_id":"BCH-USD","sequence":4839271555,"time":"2018-07-27T01:32:39.603000Z"}
{"type":"done","side":"sell","order_id":"da3c6ffe-7899-458c-8eaa-67bb379fed8d","reason":"canceled","product_id":"BCH-USD","price":"795.29000000","remaining_size":"0.90000000","sequence":4839271556,"time":"2018-07-27T01:32:39.608000Z"}
{"type":"received","order_id":"eeb97561-9839-4bbb-9b1f-8231dfb82fd7","order_type":"limit","size":"4.50000000","price":"795.53000000","side":"sell","client_oid":"00505331-2e10-4583-8137-38099d7e5ddf","product_id":"BCH-USD","sequence":4839271557,"time":"2018-07-27T01:32:39.611000Z"}
{"type":"open","side":"sell","price":"795.53000000","order_id":"eeb97561-9839-4bbb-9b1f-8231dfb82fd7","remaining_size":"4.50000000","product_id":"BCH-USD","sequence":4839271558,"time":"2018-07-27T01:32:39.611000Z"}
{"type":"done","side":"buy","order_id":"52f5a421-2633-441e-b4bf-ff8d9afaafd3","reason":"canceled","product_id":"BCH-USD","price":"791.24000000","remaining_size":"1.81488800","sequence":4839271559,"time":"2018-07-27T01:32:39.612000Z"}
{"type":"done","side":"sell","order_id":"eeb97561-9839-4bbb-9b1f-8231dfb82fd7","reason":"canceled","product_id":"BCH-USD","price":"795.53000000","remaining_size":"4.50000000","sequence":4839271560,"time":"2018-07-27T01:32:39.615000Z"}
{"type":"received","order_id":"a136c418-668d-4268-a2a7-a039b207890c","order_type":"limit","size":"0.90000000","price":"795.24000000","side":"sell","client_oid":"6475c677-6b3f-4bc2-b95f-8973e722d4cb","product_id":"BCH-USD","sequence":4839271561,"time":"2018-07-27T01:32:39.619000Z"}
{"type":"open","side":"sell","price":"795.24000000","order_id":"a136c418-668d-4268-a2a7-a039b207890c","remaining_size":"0.90000000","product_id":"BCH-USD","sequence":4839271562,"time":"2018-07-27T01:32:39.619000Z"}
{"type":"done","side":"buy","order_id":"6ddda7d4-5614-411b-8ca9-9968371561a1","reason":"canceled","product_id":"BCH-USD","price":"791.25000000","remaining_size":"0.18739300","sequence":4839271563,"time":"2018-07-27T01:32:39.620000Z"}
{"type":"done","side":"sell","order_id":"01694cb2-a060-4b5b-85b8-37f3bcba6915","reason":"canceled","product_id":"BCH-USD","price":"795.26000000","remaining_size":"1.90000000","sequence":4839271564,"time":"2018-07-27T01:32:39.621000Z"}
{"type":"done","side":"sell","order_id":"46e384e2-8fe2-4d9f-a658-82ce6e127c2d","reason":"canceled","product_id":"LTC-USD","price":"83.30000000","remaining_size":"7.44874862","sequence":2423271700,"time":"2018-07-27T01:32:39.626000Z"}
{"type":"done","side":"sell","order_id":"3891399d-22d8-4e24-a9fc-bd2279d67999","reason":"canceled","product_id":"BCH-USD","price":"795.24000000","remaining_size":"1.90000000","sequence":4839271565,"time":"2018-07-27T01:32:39.625000Z"}
{"type":"received","order_id":"5a40072c-2d6f-4709-b5e2-b42568b28b9a","order_type":"limit","size":"1.90000000","price":"795.25000000","side":"sell","client_oid":"afbed95a-863d-406f-b8b1-e79a737098ca","product_id":"BCH-USD","sequence":4839271566,"time":"2018-07-27T01:32:39.626000Z"}
{"type":"open","side":"sell","price":"795.25000000","order_id":"5a40072c-2d6f-4709-b5e2-b42568b28b9a","remaining_size":"1.90000000","product_id":"BCH-USD","sequence":4839271567,"time":"2018-07-27T01:32:39.626000Z"}
{"type":"received","order_id":"62e7a288-c538-4380-99ce-8f0390c57685","order_type":"limit","size":"1.81488800","price":"791.23000000","side":"buy","client_oid":"4e0043c1-03df-4628-b27f-b8259c12c468","product_id":"BCH-USD","sequence":4839271568,"time":"2018-07-27T01:32:39.627000Z"}
{"type":"open","side":"buy","price":"791.23000000","order_id":"62e7a288-c538-4380-99ce-8f0390c57685","remaining_size":"1.81488800","product_id":"BCH-USD","sequence":4839271569,"time":"2018-07-27T01:32:39.627000Z"}
{"type":"received","order_id":"8b936a9c-9bfa-47ce-afcf-0a0eacac5cea","order_type":"limit","size":"4.50000000","price":"795.28000000","side":"sell","client_oid":"7816255e-ed8a-4e1a-899c-f37bd18a4031","product_id":"BCH-USD","sequence":4839271570,"time":"2018-07-27T01:32:39.628000Z"}
{"type":"open","side":"sell","price":"795.28000000","order_id":"8b936a9c-9bfa-47ce-afcf-0a0eacac5cea","remaining_size":"4.50000000","product_id":"BCH-USD","sequence":4839271571,"time":"2018-07-27T01:32:39.628000Z"}
{"type":"received","order_id":"3b996f3a-388c-4091-a4ad-e3b4b76c53bc","order_type":"limit","size":"0.18739300","price":"791.23000000","side":"buy","client_oid":"aff2bd8c-f2c3-427e-a65e-078b50342bc6","product_id":"BCH-USD","sequence":4839271572,"time":"2018-07-27T01:32:39.630000Z"}
{"type":"open","side":"buy","price":"791.23000000","order_id":"3b996f3a-388c-4091-a4ad-e3b4b76c53bc","remaining_size":"0.18739300","product_id":"BCH-USD","sequence":4839271573,"time":"2018-07-27T01:32:39.630000Z"}
{"type":"done","side":"buy","order_id":"62e7a288-c538-4380-99ce-8f0390c57685","reason":"canceled","product_id":"BCH-USD","price":"791.23000000","remaining_size":"1.81488800","sequence":4839271574,"time":"2018-07-27T01:32:39.631000Z"}
{"type":"done","side":"sell","order_id":"5a40072c-2d6f-4709-b5e2-b42568b28b9a","reason":"canceled","product_id":"BCH-USD","price":"795.25000000","remaining_size":"1.90000000","sequence":4839271575,"time":"2018-07-27T01:32:39.632000Z"}
{"type":"done","side":"sell","order_id":"8b936a9c-9bfa-47ce-afcf-0a0eacac5cea","reason":"canceled","product_id":"BCH-USD","price":"795.28000000","remaining_size":"4.50000000","sequence":4839271576,"time":"2018-07-27T01:32:39.633000Z"}
{"type":"received","order_id":"f5774e80-47f0-4d2b-bc6d-4ee561a433e8","order_type":"limit","size":"3.17467700","price":"83.05000000","side":"buy","client_oid":"459d5aa2-40de-4524-817f-e204fd6dc130","product_id":"LTC-USD","sequence":2423271701,"time":"2018-07-27T01:32:39.638000Z"}
{"type":"open","side":"buy","price":"83.05000000","order_id":"f5774e80-47f0-4d2b-bc6d-4ee561a433e8","remaining_size":"3.17467700","product_id":"LTC-USD","sequence":2423271702,"time":"2018-07-27T01:32:39.638000Z"}
{"type":"received","order_id":"1a458d39-0974-4a5c-8e42-6704e7f9f525","order_type":"limit","size":"4.50000000","price":"795.67000000","side":"sell","client_oid":"c8534942-54cc-46b6-ad6a-71194c99fa3f","product_id":"BCH-USD","sequence":4839271577,"time":"2018-07-27T01:32:39.638000Z"}
{"type":"open","side":"sell","price":"795.67000000","order_id":"1a458d39-0974-4a5c-8e42-6704e7f9f525","remaining_size":"4.50000000","product_id":"BCH-USD","sequence":4839271578,"time":"2018-07-27T01:32:39.638000Z"}
{"type":"received","order_id":"facb8022-5d1e-4939-a10c-5be578217cb7","order_type":"limit","size":"1.90000000","price":"795.23000000","side":"sell","client_oid":"2c86b72e-2500-40be-9a76-ea78058c1a7e","product_id":"BCH-USD","sequence":4839271579,"time":"2018-07-27T01:32:39.640000Z"}
{"type":"open","side":"sell","price":"795.23000000","order_id":"facb8022-5d1e-4939-a10c-5be578217cb7","remaining_size":"1.90000000","product_id":"BCH-USD","sequence":4839271580,"time":"2018-07-27T01:32:39.640000Z"}
{"type":"received","order_id":"08096e55-d7f7-47d1-b0fe-c8ea361bd70b","order_type":"limit","size":"7.44874862","price":"83.34000000","side":"sell","client_oid":"6c2ea63d-7dca-4811-8000-04171b0517a0","product_id":"LTC-USD","sequence":2423271703,"time":"2018-07-27T01:32:39.643000Z"}
{"type":"open","side":"sell","price":"83.34000000","order_id":"08096e55-d7f7-47d1-b0fe-c8ea361bd70b","remaining_size":"7.44874862","product_id":"LTC-USD","sequence":2423271704,"time":"2018-07-27T01:32:39.643000Z"}
{"type":"done","side":"sell","order_id":"1a458d39-0974-4a5c-8e42-6704e7f9f525","reason":"canceled","product_id":"BCH-USD","price":"795.67000000","remaining_size":"4.50000000","sequence":4839271581,"time":"2018-07-27T01:32:39.642000Z"}
{"type":"received","order_id":"3bb9231e-37b0-48ca-9232-bc336d27c6a3","order_type":"limit","size":"1.90000000","price":"795.23000000","side":"sell","client_oid":"a91b94d7-d46d-4e59-b0b6-50da3b03b74e","product_id":"BCH-USD","sequence":4839271582,"time":"2018-07-27T01:32:39.642000Z"}
{"type":"open","side":"sell","price":"795.23000000","order_id":"3bb9231e-37b0-48ca-9232-bc336d27c6a3","remaining_size":"1.90000000","product_id":"BCH-USD","sequence":4839271583,"time":"2018-07-27T01:32:39.642000Z"}
{"type":"received","order_id":"f42c9505-66e7-400c-9917-5d0469e857fd","order_type":"limit","size":"4.50000000","price":"795.23000000","side":"sell","client_oid":"4884c1b9-1fa0-4ec2-9ba2-3a6a0008c5b8","product_id":"BCH-USD","sequence":4839271584,"time":"2018-07-27T01:32:39.644000Z"}
{"type":"open","side":"sell","price":"795.23000000","order_id":"f42c9505-66e7-400c-9917-5d0469e857fd","remaining_size":"4.50000000","product_id":"BCH-USD","sequence":4839271585,"time":"2018-07-27T01:32:39.644000Z"}
{"type":"done","side":"sell","order_id":"58b24287-088f-408d-8e93-1a7459c74af0","reason":"canceled","product_id":"BCH-USD","price":"794.00000000","remaining_size":"2.00000000","sequence":4839271586,"time":"2018-07-27T01:32:39.645000Z"}
{"type":"done","side":"sell","order_id":"3bb9231e-37b0-48ca-9232-bc336d27c6a3","reason":"canceled","product_id":"BCH-USD","price":"795.23000000","remaining_size":"1.90000000","sequence":4839271587,"time":"2018-07-27T01:32:39.646000Z"}
{"type":"received","order_id":"1bb9d76e-0aeb-4fd6-8f74-8bf94c03a574","order_type":"limit","size":"4.83845000","price":"83.03000000","side":"buy","client_oid":"af5a23b7-4650-4d7e-ada5-5bb08d81221c","product_id":"LTC-USD","sequence":2423271705,"time":"2018-07-27T01:32:39.649000Z"}
{"type":"done","side":"sell","order_id":"facb8022-5d1e-4939-a10c-5be578217cb7","reason":"canceled","product_id":"BCH-USD","price":"795.23000000","remaining_size":"1.90000000","sequence":4839271588,"time":"2018-07-27T01:32:39.648000Z"}
{"type":"done","side":"sell","order_id":"a136c418-668d-4268-a2a7-a039b207890c","reason":"canceled","product_id":"BCH-USD","price":"795.24000000","remaining_size":"0.90000000","sequence":4839271589,"time":"2018-07-27T01:32:39.648000Z"}
{"type":"open","side":"buy","price":"83.03000000","order_id":"1bb9d76e-0aeb-4fd6-8f74-8bf94c03a574","remaining_size":"4.83845000","product_id":"LTC-USD","sequence":2423271706,"time":"2018-07-27T01:32:39.649000Z"}
{"type":"received","order_id":"b618f5ce-0f79-4d8a-aba1-832833653cd9","order_type":"limit","size":"1.81488800","price":"791.25000000","side":"buy","client_oid":"a91e94e3-8417-4d03-91d6-46d690338ca6","product_id":"BCH-USD","sequence":4839271590,"time":"2018-07-27T01:32:39.648000Z"}
{"type":"open","side":"buy","price":"791.25000000","order_id":"b618f5ce-0f79-4d8a-aba1-832833653cd9","remaining_size":"1.81488800","product_id":"BCH-USD","sequence":4839271591,"time":"2018-07-27T01:32:39.648000Z"}
{"type":"done","side":"sell","order_id":"f42c9505-66e7-400c-9917-5d0469e857fd","reason":"canceled","product_id":"BCH-USD","price":"795.23000000","remaining_size":"4.50000000","sequence":4839271592,"time":"2018-07-27T01:32:39.649000Z"}
{"type":"received","order_id":"79737cc3-03d0-4020-aab9-184fa4561795","order_type":"limit","size":"1.90000000","price":"795.27000000","side":"sell","client_oid":"5652f8ce-3270-461c-9b79-03cde6365c3f","product_id":"BCH-USD","sequence":4839271593,"time":"2018-07-27T01:32:39.654000Z"}
{"type":"open","side":"sell","price":"795.27000000","order_id":"79737cc3-03d0-4020-aab9-184fa4561795","remaining_size":"1.90000000","product_id":"BCH-USD","sequence":4839271594,"time":"2018-07-27T01:32:39.654000Z"}
{"type":"received","order_id":"912c537f-ae0c-4b6e-81f5-ef719fb90d73","order_type":"limit","size":"4.50000000","price":"795.66000000","side":"sell","client_oid":"5d58d19e-3353-4446-994e-374833835c70","product_id":"BCH-USD","sequence":4839271595,"time":"2018-07-27T01:32:39.656000Z"}
{"type":"open","side":"sell","price":"795.66000000","order_id":"912c537f-ae0c-4b6e-81f5-ef719fb90d73","remaining_size":"4.50000000","product_id":"BCH-USD","sequence":4839271596,"time":"2018-07-27T01:32:39.656000Z"}
{"type":"done","side":"sell","order_id":"79737cc3-03d0-4020-aab9-184fa4561795","reason":"canceled","product_id":"BCH-USD","price":"795.27000000","remaining_size":"1.90000000","sequence":4839271597,"time":"2018-07-27T01:32:39.658000Z"}
{"type":"received","order_id":"58662891-04e4-4db9-b5c8-3594bc9314ad","order_type":"limit","size":"4.50000000","price":"795.29000000","side":"sell","client_oid":"0e632595-c2a1-4384-9aae-ae5ab9c61759","product_id":"BCH-USD","sequence":4839271598,"time":"2018-07-27T01:32:39.662000Z"}
{"type":"open","side":"sell","price":"795.29000000","order_id":"58662891-04e4-4db9-b5c8-3594bc9314ad","remaining_size":"4.50000000","product_id":"BCH-USD","sequence":4839271599,"time":"2018-07-27T01:32:39.662000Z"}
{"type":"received","order_id":"bca4ff18-6def-474a-aff9-197f2a72f13b","order_type":"limit","size":"9.94519000","price":"83.01000000","side":"buy","client_oid":"fbcccaf1-a7a4-40b7-a556-39bfe1897218","product_id":"LTC-USD","sequence":2423271707,"time":"2018-07-27T01:32:39.664000Z"}
{"type":"done","side":"buy","order_id":"2fd2f91a-553e-4c4d-8904-03f9b26a9107","reason":"canceled","product_id":"BTC-USD","price":"7895.00000000","remaining_size":"1.00000000","sequence":6418130203,"time":"2018-07-27T01:32:39.665000Z"}
{"type":"open","side":"buy","price":"83.01000000","order_id":"bca4ff18-6def-474a-aff9-197f2a72f13b","remaining_size":"9.94519000","product_id":"LTC-USD","sequence":2423271708,"time":"2018-07-27T01:32:39.664000Z"}
{"type":"received","order_id":"037ae706-fbe2-42b1-b9f0-6b9a788320b5","order_type":"limit","size":"2.00000000","price":"794.37000000","side":"sell","client_oid":"b2fb9929-1b50-4791-a397-9eefe901ea85","product_id":"BCH-USD","sequence":4839271600,"time":"2018-07-27T01:32:39.666000Z"}
{"type":"open","side":"sell","price":"794.37000000","order_id":"037ae706-fbe2-42b1-b9f0-6b9a788320b5","remaining_size":"2.00000000","product_id":"BCH-USD","sequence":4839271601,"time":"2018-07-27T01:32:39.666000Z"}
{"type":"done","side":"buy","order_id":"3b996f3a-388c-4091-a4ad-e3b4b76c53bc","reason":"canceled","product_id":"BCH-USD","price":"791.23000000","remaining_size":"0.18739300","sequence":4839271602,"time":"2018-07-27T01:32:39.667000Z"}
{"type":"received","order_id":"603c0a02-56b0-46d9-820f-e4ffc6d9f005","order_type":"limit","size":"1.90000000","price":"795.22000000","side":"sell","client_oid":"01025908-0f76-475c-9d12-2cca972e2706","product_id":"BCH-USD","sequence":4839271603,"time":"2018-07-27T01:32:39.670000Z"}
{"type":"open","side":"sell","price":"795.22000000","order_id":"603c0a02-56b0-46d9-820f-e4ffc6d9f005","remaining_size":"1.90000000","product_id":"BCH-USD","sequence":4839271604,"time":"2018-07-27T01:32:39.670000Z"}
{"type":"received","order_id":"7a381e64-2828-45b1-95b9-9961eaff9b2c","order_type":"limit","size":"1.90000000","price":"795.22000000","side":"sell","client_oid":"d0e4f065-8ffa-4354-8803-2a2685ab0078","product_id":"BCH-USD","sequence":4839271605,"time":"2018-07-27T01:32:39.672000Z"}
{"type":"open","side":"sell","price":"795.22000000","order_id":"7a381e64-2828-45b1-95b9-9961eaff9b2c","remaining_size":"1.90000000","product_id":"BCH-USD","sequence":4839271606,"time":"2018-07-27T01:32:39.672000Z"}
{"type":"received","order_id":"b1beea06-5ba1-4f76-8994-87cbbd3be5ea","order_type":"limit","size":"26.67592100","price":"82.95000000","side":"buy","client_oid":"9cb9c401-5908-4ef3-a5c8-58b82fce06d2","product_id":"LTC-USD","sequence":2423271709,"time":"2018-07-27T01:32:39.677000Z"}
{"type":"done","side":"sell","order_id":"58662891-04e4-4db9-b5c8-3594bc9314ad","reason":"canceled","product_id":"BCH-USD","price":"795.29000000","remaining_size":"4.50000000","sequence":4839271607,"time":"2018-07-27T01:32:39.675000Z"}
{"type":"open","side":"buy","price":"82.95000000","order_id":"b1beea06-5ba1-4f76-8994-87cbbd3be5ea","remaining_size":"26.67592100","product_id":"LTC-USD","sequence":2423271710,"time":"2018-07-27T01:32:39.677000Z"}
{"type":"done","side":"sell","order_id":"08096e55-d7f7-47d1-b0fe-c8ea361bd70b","reason":"canceled","product_id":"LTC-USD","price":"83.34000000","remaining_size":"7.44874862","sequence":2423271711,"time":"2018-07-27T01:32:39.677000Z"}
{"type":"received","order_id":"f65cdc9c-70b6-4674-85c8-46dc556a9ba6","order_type":"limit","size":"0.90000000","price":"795.29000000","side":"sell","client_oid":"ea4a2662-4770-464c-a2c7-20984d2d5a55","product_id":"BCH-USD","sequence":4839271608,"time":"2018-07-27T01:32:39.677000Z"}
{"type":"open","side":"sell","price":"795.29000000","order_id":"f65cdc9c-70b6-4674-85c8-46dc556a9ba6","remaining_size":"0.90000000","product_id":"BCH-USD","sequence":4839271609,"time":"2018-07-27T01:32:39.677000Z"}
{"type":"received","order_id":"afa5959b-1126-4ffd-b583-11a5d9fe2432","order_type":"limit","size":"0.18739300","price":"791.26000000","side":"buy","client_oid":"17303060-6489-47be-8a86-a49a5a462353","product_id":"BCH-USD","sequence":4839271610,"time":"2018-07-27T01:32:39.679000Z"}
{"type":"open","side":"buy","price":"791.26000000","order_id":"afa5959b-1126-4ffd-b583-11a5d9fe2432","remaining_size":"0.18739300","product_id":"BCH-USD","sequence":4839271611,"time":"2018-07-27T01:32:39.679000Z"}
{"type":"done","side":"sell","order_id":"7a381e64-2828-45b1-95b9-9961eaff9b2c","reason":"canceled","product_id":"BCH-USD","price":"795.22000000","remaining_size":"1.90000000","sequence":4839271612,"time":"2018-07-27T01:32:39.680000Z"}
{"type":"done","side":"sell","order_id":"f65cdc9c-70b6-4674-85c8-46dc556a9ba6","reason":"canceled","product_id":"BCH-USD","price":"795.29000000","remaining_size":"0.90000000","sequence":4839271613,"time":"2018-07-27T01:32:39.681000Z"}
{"type":"received","order_id":"2afeef60-be5d-4eb1-bb0c-30c1fd22e3ed","order_type":"limit","size":"1.90000000","price":"795.28000000","side":"sell","client_oid":"0db2e70f-0909-49ce-b01d-3b7b9fbcde88","product_id":"BCH-USD","sequence":4839271614,"time":"2018-07-27T01:32:39.686000Z"}
{"type":"open","side":"sell","price":"795.28000000","order_id":"2afeef60-be5d-4eb1-bb0c-30c1fd22e3ed","remaining_size":"1.90000000","product_id":"BCH-USD","sequence":4839271615,"time":"2018-07-27T01:32:39.686000Z"}
{"type":"received","order_id":"8e391a6d-618d-402b-bb40-c60edf9f66da","order_type":"limit","size":"123.67254800","price":"82.93000000","side":"buy","client_oid":"9611fd36-02d7-4f47-bbe3-78fe4404aee5","product_id":"LTC-USD","sequence":2423271712,"time":"2018-07-27T01:32:39.688000Z"}
{"type":"open","side":"buy","price":"82.93000000","order_id":"8e391a6d-618d-402b-bb40-c60edf9f66da","remaining_size":"123.67254800","product_id":"LTC-USD","sequence":2423271713,"time":"2018-07-27T01:32:39.688000Z"}
{"type":"received","order_id":"f560b212-c8cf-41a3-8941-893e34af7dff","order_type":"limit","size":"0.90000000","price":"795.28000000","side":"sell","client_oid":"60e95838-ba56-445c-9370-0058079c443a","product_id":"BCH-USD","sequence":4839271616,"time":"2018-07-27T01:32:39.688000Z"}
{"type":"open","side":"sell","price":"795.28000000","order_id":"f560b212-c8cf-41a3-8941-893e34af7dff","remaining_size":"0.90000000","product_id":"BCH-USD","sequence":4839271617,"time":"2018-07-27T01:32:39.688000Z"}
{"type":"done","side":"sell","order_id":"2afeef60-be5d-4eb1-bb0c-30c1fd22e3ed","reason":"canceled","product_id":"BCH-USD","price":"795.28000000","remaining_size":"1.90000000","sequence":4839271618,"time":"2018-07-27T01:32:39.690000Z"}
{"type":"done","side":"sell","order_id":"603c0a02-56b0-46d9-820f-e4ffc6d9f005","reason":"canceled","product_id":"BCH-USD","price":"795.22000000","remaining_size":"1.90000000","sequence":4839271619,"time":"2018-07-27T01:32:39.690000Z"}
{"type":"received","order_id":"4dbd6e17-cc12-47b7-b399-6e61810ba9f9","order_type":"limit","size":"4.50000000","price":"795.28000000","side":"sell","client_oid":"a7e27859-7d3b-4f21-9a6c-2814da6fdfa9","product_id":"BCH-USD","sequence":4839271620,"time":"2018-07-27T01:32:39.691000Z"}
{"type":"open","side":"sell","price":"795.28000000","order_id":"4dbd6e17-cc12-47b7-b399-6e61810ba9f9","remaining_size":"4.50000000","product_id":"BCH-USD","sequence":4839271621,"time":"2018-07-27T01:32:39.691000Z"}
{"type":"done","side":"sell","order_id":"f560b212-c8cf-41a3-8941-893e34af7dff","reason":"canceled","product_id":"BCH-USD","price":"795.28000000","remaining_size":"0.90000000","sequence":4839271622,"time":"2018-07-27T01:32:39.692000Z"}
{"type":"received","order_id":"71119ce2-31f5-4d29-b7cb-27e32fe4536a","order_type":"limit","size":"7.44874862","price":"83.30000000","side":"sell","client_oid":"ef6dc816-6a67-451e-8000-0046dc47d16b","product_id":"LTC-USD","sequence":2423271714,"time":"2018-07-27T01:32:39.696000Z"}
{"type":"open","side":"sell","price":"83.30000000","order_id":"71119ce2-31f5-4d29-b7cb-27e32fe4536a","remaining_size":"7.44874862","product_id":"LTC-USD","sequence":2423271715,"time":"2018-07-27T01:32:39.696000Z"}
{"type":"done","side":"sell","order_id":"4dbd6e17-cc12-47b7-b399-6e61810ba9f9","reason":"canceled","product_id":"BCH-USD","price":"795.28000000","remaining_size":"4.50000000","sequence":4839271623,"time":"2018-07-27T01:32:39.695000Z"}
{"type":"done","side":"buy","order_id":"b618f5ce-0f79-4d8a-aba1-832833653cd9","reason":"canceled","product_id":"BCH-USD","price":"791.25000000","remaining_size":"1.81488800","sequence":4839271624,"time":"2018-07-27T01:32:39.697000Z"}
{"type":"received","order_id":"e632fdac-5a2e-4694-8585-23c3c79fa608","order_type":"limit","size":"1.90000000","price":"795.25000000","side":"sell","client_oid":"4d054a42-5824-4685-a6b7-9daa93fc4438","product_id":"BCH-USD","sequence":4839271625,"time":"2018-07-27T01:32:39.699000Z"}
{"type":"open","side":"sell","price":"795.25000000","order_id":"e632fdac-5a2e-4694-8585-23c3c79fa608","remaining_size":"1.90000000","product_id":"BCH-USD","sequence":4839271626,"time":"2018-07-27T01:32:39.699000Z"}
{"type":"done","side":"buy","order_id":"8cb19b76-49fb-4427-b083-63b7eeaae025","reason":"canceled","product_id":"BCH-USD","price":"792.80000000","remaining_size":"2.00000000","sequence":4839271627,"time":"2018-07-27T01:32:39.699000Z"}
{"type":"done","side":"sell","order_id":"912c537f-ae0c-4b6e-81f5-ef719fb90d73","reason":"canceled","product_id":"BCH-USD","price":"795.66000000","remaining_size":"4.50000000","sequence":4839271628,"time":"2018-07-27T01:32:39.699000Z"}
{"type":"received","order_id":"cc0a9651-aec7-4bb9-997e-bc1454e30c04","order_type":"limit","size":"101.76255900","price":"82.91000000","side":"buy","client_oid":"f6bb8b5a-a1d4-4129-8f6c-355866605e94","product_id":"LTC-USD","sequence":2423271716,"time":"2018-07-27T01:32:39.702000Z"}
{"type":"open","side":"buy","price":"82.91000000","order_id":"cc0a9651-aec7-4bb9-997e-bc1454e30c04","remaining_size":"101.76255900","product_id":"LTC-USD","sequence":2423271717,"time":"2018-07-27T01:32:39.702000Z"}
{"type":"received","order_id":"801981bd-1626-4995-9a88-caf7088cb45d","order_type":"limit","size":"7.07900000","price":"795.28000000","side":"sell","product_id":"BCH-USD","sequence":4839271629,"time":"2018-07-27T01:32:39.702000Z"}
{"type":"open","side":"sell","price":"795.28000000","order_id":"801981bd-1626-4995-9a88-caf7088cb45d","remaining_size":"7.07900000","product_id":"BCH-USD","sequence":4839271630,"time":"2018-07-27T01:32:39.702000Z"}
{"type":"received","order_id":"d8c7f60e-34dd-433d-b7f1-fa25b1975bb5","order_type":"limit","size":"1.90000000","price":"795.21000000","side":"sell","client_oid":"998ebc41-7283-4f74-b2fa-a93d90294127","product_id":"BCH-USD","sequence":4839271631,"time":"2018-07-27T01:32:39.703000Z"}
{"type":"open","side":"sell","price":"795.21000000","order_id":"d8c7f60e-34dd-433d-b7f1-fa25b1975bb5","remaining_size":"1.90000000","product_id":"BCH-USD","sequence":4839271632,"time":"2018-07-27T01:32:39.703000Z"}
{"type":"received","order_id":"1f18a793-dfe5-4566-be9d-254859b711f5","order_type":"limit","size":"0.90000000","price":"795.25000000","side":"sell","client_oid":"ea300db0-99aa-440b-a05c-d8c144c65191","product_id":"BCH-USD","sequence":4839271633,"time":"2018-07-27T01:32:39.706000Z"}
{"type":"open","side":"sell","price":"795.25000000","order_id":"1f18a793-dfe5-4566-be9d-254859b711f5","remaining_size":"0.90000000","product_id":"BCH-USD","sequence":4839271634,"time":"2018-07-27T01:32:39.706000Z"}
{"type":"done","side":"sell","order_id":"1f18a793-dfe5-4566-be9d-254859b711f5","reason":"canceled","product_id":"BCH-USD","price":"795.25000000","remaining_size":"0.90000000","sequence":4839271635,"time":"2018-07-27T01:32:39.708000Z"}
{"type":"done","side":"sell","order_id":"d8c7f60e-34dd-433d-b7f1-fa25b1975bb5","reason":"canceled","product_id":"BCH-USD","price":"795.21000000","remaining_size":"1.90000000","sequence":4839271636,"time":"2018-07-27T01:32:39.709000Z"}
{"type":"received","order_id":"4c08c1f6-0454-4078-bfe2-92cba7095b13","order_type":"limit","size":"4.50000000","price":"795.29000000","side":"sell","client_oid":"0d857289-0504-4bf9-b49d-5cf7fb77fa92","product_id":"BCH-USD","sequence":4839271637,"time":"2018-07-27T01:32:39.710000Z"}
{"type":"open","side":"sell","price":"795.29000000","order_id":"4c08c1f6-0454-4078-bfe2-92cba7095b13","remaining_size":"4.50000000","product_id":"BCH-USD","sequence":4839271638,"time":"2018-07-27T01:32:39.710000Z"}
{"type":"received","order_id":"9415b7a3-7078-4d3a-8aa1-c5a960188271","order_type":"limit","size":"18.00110900","price":"83.29000000","side":"sell","client_oid":"c671fac6-fe71-49cb-8855-f65fb713b2f7","product_id":"LTC-USD","sequence":2423271718,"time":"2018-07-27T01:32:39.714000Z"}
{"type":"done","side":"buy","order_id":"afa5959b-1126-4ffd-b583-11a5d9fe2432","reason":"canceled","product_id":"BCH-USD","price":"791.26000000","remaining_size":"0.18739300","sequence":4839271639,"time":"2018-07-27T01:32:39.712000Z"}
{"type":"open","side":"sell","price":"83.29000000","order_id":"9415b7a3-7078-4d3a-8aa1-c5a960188271","remaining_size":"18.00110900","product_id":"LTC-USD","sequence":2423271719,"time":"2018-07-27T01:32:39.714000Z"}
{"type":"done","side":"sell","order_id":"4c08c1f6-0454-4078-bfe2-92cba7095b13","reason":"canceled","product_id":"BCH-USD","price":"795.29000000","remaining_size":"4.50000000","sequence":4839271640,"time":"2018-07-27T01:32:39.713000Z"}
{"type":"received","order_id":"40264e03-1831-4aeb-8feb-56eb3678ca47","order_type":"limit","size":"1.81488800","price":"791.23000000","side":"buy","client_oid":"6d430ead-ac7f-4551-899b-fddb20b5e4c3","product_id":"BCH-USD","sequence":4839271641,"time":"2018-07-27T01:32:39.716000Z"}
{"type":"open","side":"buy","price":"791.23000000","order_id":"40264e03-1831-4aeb-8feb-56eb3678ca47","remaining_size":"1.81488800","product_id":"BCH-USD","sequence":4839271642,"time":"2018-07-27T01:32:39.716000Z"}
{"type":"received","order_id":"3f622067-a6ff-4aa1-a51d-ac34deffb950","order_type":"limit","size":"2.00000000","price":"792.80000000","side":"buy","client_oid":"3ab1089a-7c2a-41ac-aa48-3b52f10f2400","product_id":"BCH-USD","sequence":4839271643,"time":"2018-07-27T01:32:39.718000Z"}
{"type":"open","side":"buy","price":"792.80000000","order_id":"3f622067-a6ff-4aa1-a51d-ac34deffb950","remaining_size":"2.00000000","product_id":"BCH-USD","sequence":4839271644,"time":"2018-07-27T01:32:39.718000Z"}
{"type":"received","order_id":"bd0d71c4-dd9d-4164-a17d-9cedaedbcf4f","order_type":"limit","size":"0.12416624","price":"8051.71000000","side":"buy","client_oid":"09011358-8901-44d9-be9e-f0f85374733e","product_id":"BTC-USD","sequence":6418130204,"time":"2018-07-27T01:32:39.723000Z"}
{"type":"match","trade_id":47446109,"maker_order_id":"2797376b-a7bf-4cf0-82d7-0f8e918e7d8b","taker_order_id":"bd0d71c4-dd9d-4164-a17d-9cedaedbcf4f","side":"sell","size":"0.12416624","price":"7896.01000000","product_id":"BTC-USD","sequence":6418130205,"time":"2018-07-27T01:32:39.723000Z"}
{"type":"done","side":"buy","order_id":"bd0d71c4-dd9d-4164-a17d-9cedaedbcf4f","reason":"filled","product_id":"BTC-USD","price":"8051.71000000","remaining_size":"0.00000000","sequence":6418130206,"time":"2018-07-27T01:32:39.723000Z"}
{"type":"received","order_id":"b0dcd707-bb76-453e-8985-aa30ffa57fd9","order_type":"limit","size":"4.50000000","price":"795.67000000","side":"sell","client_oid":"002f4954-7cd5-4b69-a8b2-1655c570026c","product_id":"BCH-USD","sequence":4839271645,"time":"2018-07-27T01:32:39.723000Z"}
{"type":"open","side":"sell","price":"795.67000000","order_id":"b0dcd707-bb76-453e-8985-aa30ffa57fd9","remaining_size":"4.50000000","product_id":"BCH-USD","sequence":4839271646,"time":"2018-07-27T01:32:39.723000Z"}
{"type":"done","side":"buy","order_id":"40264e03-1831-4aeb-8feb-56eb3678ca47","reason":"canceled","product_id":"BCH-USD","price":"791.23000000","remaining_size":"1.81488800","sequence":4839271647,"time":"2018-07-27T01:32:39.724000Z"}
{"type":"received","order_id":"f3d1fb81-b48a-4b7d-8e4b-39a1ae9a4a8e","order_type":"limit","size":"1.90000000","price":"795.29000000","side":"sell","client_oid":"c682c5d8-6e65-4b42-8411-458962db2399","product_id":"BCH-USD","sequence":4839271648,"time":"2018-07-27T01:32:39.725000Z"}
{"type":"open","side":"sell","price":"795.29000000","order_id":"f3d1fb81-b48a-4b7d-8e4b-39a1ae9a4a8e","remaining_size":"1.90000000","product_id":"BCH-USD","sequence":4839271649,"time":"2018-07-27T01:32:39.725000Z"}
{"type":"done","side":"sell","order_id":"b0dcd707-bb76-453e-8985-aa30ffa57fd9","reason":"canceled","product_id":"BCH-USD","price":"795.67000000","remaining_size":"4.50000000","sequence":4839271650,"time":"2018-07-27T01:32:39.727000Z"}
{"type":"received","order_id":"8127dde2-09d1-41b7-bc8f-b893717ff5ea","order_type":"limit","size":"19.24453700","price":"83.30000000","side":"sell","client_oid":"107cbc91-068d-44c4-8847-6b299cd87fc8","product_id":"LTC-USD","sequence":2423271720,"time":"2018-07-27T01:32:39.730000Z"}
{"type":"done","side":"sell","order_id":"f79e0ea2-2c46-40c9-af46-4ed61989b415","reason":"canceled","product_id":"BTC-USD","price":"7906.55000000","remaining_size":"1.89033000","sequence":6418130207,"time":"2018-07-27T01:32:39.732000Z"}
{"type":"open","side":"sell","price":"83.30000000","order_id":"8127dde2-09d1-41b7-bc8f-b893717ff5ea","remaining_size":"19.24453700","product_id":"LTC-USD","sequence":2423271721,"time":"2018-07-27T01:32:39.730000Z"}
{"type":"received","order_id":"40d4009a-210a-468a-82fa-c62c21b1f6ec","order_type":"limit","size":"0.18739300","price":"791.23000000","side":"buy","client_oid":"a3d4bf0d-e350-400f-b439-43c63ce85931","product_id":"BCH-USD","sequence":4839271651,"time":"2018-07-27T01:32:39.731000Z"}
{"type":"open","side":"buy","price":"791.23000000","order_id":"40d4009a-210a-468a-82fa-c62c21b1f6ec","remaining_size":"0.18739300","product_id":"BCH-USD","sequence":4839271652,"time":"2018-07-27T01:32:39.731000Z"}
{"type":"done","side":"sell","order_id":"f3d1fb81-b48a-4b7d-8e4b-39a1ae9a4a8e","reason":"canceled","product_id":"BCH-USD","price":"795.29000000","remaining_size":"1.90000000","sequence":4839271653,"time":"2018-07-27T01:32:39.732000Z"}
{"type":"received","order_id":"4ad220a0-772e-451a-b592-5ab69a87a4c6","order_type":"limit","size":"1.90000000","price":"795.27000000","side":"sell","client_oid":"ee950a95-26a5-4a20-8673-cb8c486fa86a","product_id":"BCH-USD","sequence":4839271654,"time":"2018-07-27T01:32:39.733000Z"}
{"type":"open","side":"sell","price":"795.27000000","order_id":"4ad220a0-772e-451a-b592-5ab69a87a4c6","remaining_size":"1.90000000","product_id":"BCH-USD","sequence":4839271655,"time":"2018-07-27T01:32:39.733000Z"}
{"type":"received","order_id":"bd3f8472-593e-462c-8e41-b24317ee2b0b","order_type":"limit","size":"4.50000000","price":"795.24000000","side":"sell","client_oid":"b0255951-180f-40ca-9729-7696c839d645","product_id":"BCH-USD","sequence":4839271656,"time":"2018-07-27T01:32:39.735000Z"}
{"type":"open","side":"sell","price":"795.24000000","order_id":"bd3f8472-593e-462c-8e41-b24317ee2b0b","remaining_size":"4.50000000","product_id":"BCH-USD","sequence":4839271657,"time":"2018-07-27T01:32:39.735000Z"}
{"type":"received","order_id":"7bbf41e2-e21a-47a3-b708-eeecab65b46c","order_type":"limit","size":"1.89141000","price":"7907.18000000","side":"sell","client_oid":"cf74124b-10dc-4f60-98a2-84a3fa3d678d","product_id":"BTC-USD","sequence":6418130208,"time":"2018-07-27T01:32:39.739000Z"}
{"type":"open","side":"sell","price":"7907.18000000","order_id":"7bbf41e2-e21a-47a3-b708-eeecab65b46c","remaining_size":"1.89141000","product_id":"BTC-USD","sequence":6418130209,"time":"2018-07-27T01:32:39.739000Z"}
{"type":"received","order_id":"161c07ae-2513-4204-bc41-276e264e6b45","order_type":"limit","size":"0.90000000","price":"795.27000000","side":"sell","client_oid":"6f1df6fd-6d2b-4884-bf0e-4feb0246e93f","product_id":"BCH-USD","sequence":4839271658,"time":"2018-07-27T01:32:39.737000Z"}
{"type":"open","side":"sell","price":"795.27000000","order_id":"161c07ae-2513-4204-bc41-276e264e6b45","remaining_size":"0.90000000","product_id":"BCH-USD","sequence":4839271659,"time":"2018-07-27T01:32:39.737000Z"}
{"type":"done","side":"sell","order_id":"4ad220a0-772e-451a-b592-5ab69a87a4c6","reason":"canceled","product_id":"BCH-USD","price":"795.27000000","remaining_size":"1.90000000","sequence":4839271660,"time":"2018-07-27T01:32:39.737000Z"}
{"type":"received","order_id":"7f2ba1cf-088b-4010-805d-b0cb18a71de0","order_type":"limit","size":"0.62690000","price":"7899.99000000","side":"sell","client_oid":"407a67c8-c6b9-f6fa-62dd-36a088686abc","product_id":"BTC-USD","sequence":6418130210,"time":"2018-07-27T01:32:39.741000Z"}
{"type":"open","side":"sell","price":"7899.99000000","order_id":"7f2ba1cf-088b-4010-805d-b0cb18a71de0","remaining_size":"0.62690000","product_id":"BTC-USD","sequence":6418130211,"time":"2018-07-27T01:32:39.741000Z"}
{"type":"done","side":"sell","order_id":"bd3f8472-593e-462c-8e41-b24317ee2b0b","reason":"canceled","product_id":"BCH-USD","price":"795.24000000","remaining_size":"4.50000000","sequence":4839271661,"time":"2018-07-27T01:32:39.739000Z"}
{"type":"done","side":"sell","order_id":"161c07ae-2513-4204-bc41-276e264e6b45","reason":"canceled","product_id":"BCH-USD","price":"795.27000000","remaining_size":"0.90000000","sequence":4839271662,"time":"2018-07-27T01:32:39.741000Z"}
{"type":"received","order_id":"2d4ed440-01d3-4af8-a7f8-6c177a4ac8a3","order_type":"limit","size":"1.90000000","price":"795.27000000","side":"sell","client_oid":"52783123-4b01-48bb-b434-9e76d430d5c3","product_id":"BCH-USD","sequence":4839271663,"time":"2018-07-27T01:32:39.744000Z"}
{"type":"received","order_id":"235239ba-2fd8-410f-aab2-8dcef236ff90","order_type":"limit","size":"15.66918000","price":"83.32000000","side":"sell","client_oid":"e7da3273-b221-4e3a-a83f-7945ccead376","product_id":"LTC-USD","sequence":2423271722,"time":"2018-07-27T01:32:39.747000Z"}
{"type":"open","side":"sell","price":"795.27000000","order_id":"2d4ed440-01d3-4af8-a7f8-6c177a4ac8a3","remaining_size":"1.90000000","product_id":"BCH-USD","sequence":4839271664,"time":"2018-07-27T01:32:39.744000Z"}
{"type":"open","side":"sell","price":"83.32000000","order_id":"235239ba-2fd8-410f-aab2-8dcef236ff90","remaining_size":"15.66918000","product_id":"LTC-USD","sequence":2423271723,"time":"2018-07-27T01:32:39.747000Z"}
{"type":"done","side":"sell","order_id":"2d4ed440-01d3-4af8-a7f8-6c177a4ac8a3","reason":"canceled","product_id":"BCH-USD","price":"795.27000000","remaining_size":"1.90000000","sequence":4839271665,"time":"2018-07-27T01:32:39.748000Z"}
{"type":"done","side":"sell","order_id":"037ae706-fbe2-42b1-b9f0-6b9a788320b5","reason":"canceled","product_id":"BCH-USD","price":"794.37000000","remaining_size":"2.00000000","sequence":4839271666,"time":"2018-07-27T01:32:39.750000Z"}
{"type":"received","order_id":"3750eb5c-01f1-47b3-939e-4f6dd268753e","order_type":"limit","size":"0.90000000","price":"795.28000000","side":"sell","client_oid":"a4d898bc-f634-4188-b279-983920845ef0","product_id":"BCH-USD","sequence":4839271667,"time":"2018-07-27T01:32:39.751000Z"}
{"type":"open","side":"sell","price":"795.28000000","order_id":"3750eb5c-01f1-47b3-939e-4f6dd268753e","remaining_size":"0.90000000","product_id":"BCH-USD","sequence":4839271668,"time":"2018-07-27T01:32:39.751000Z"}
{"type":"done","side":"sell","order_id":"23b9ed2d-5ca0-4394-89d9-88d345e582cf","reason":"canceled","product_id":"BCH-USD","price":"801.21000000","remaining_size":"160.47500000","sequence":4839271669,"time":"2018-07-27T01:32:39.752000Z"}
{"type":"received","order_id":"cd4afab6-8722-48c7-bfda-6007e438f238","order_type":"limit","size":"1.90000000","price":"795.26000000","side":"sell","client_oid":"65617d33-9d7f-4160-aea2-94041724a502","product_id":"BCH-USD","sequence":4839271670,"time":"2018-07-27T01:32:39.763000Z"}
{"type":"open","side":"sell","price":"795.26000000","order_id":"cd4afab6-8722-48c7-bfda-6007e438f238","remaining_size":"1.90000000","product_id":"BCH-USD","sequence":4839271671,"time":"2018-07-27T01:32:39.763000Z"}
{"type":"done","side":"sell","order_id":"cd4afab6-8722-48c7-bfda-6007e438f238","reason":"canceled","product_id":"BCH-USD","price":"795.26000000","remaining_size":"1.90000000","sequence":4839271672,"time":"2018-07-27T01:32:39.765000Z"}
{"type":"received","order_id":"ef1b1865-5f19-4a84-9187-c281b353c088","order_type":"limit","size":"0.00100000","price":"7863.67000000","side":"buy","client_oid":"6535682c-5ce4-458d-b496-ffe48a2d9b05","product_id":"BTC-USD","sequence":6418130212,"time":"2018-07-27T01:32:39.771000Z"}
{"type":"open","side":"buy","price":"7863.67000000","order_id":"ef1b1865-5f19-4a84-9187-c281b353c088","remaining_size":"0.00100000","product_id":"BTC-USD","sequence":6418130213,"time":"2018-07-27T01:32:39.771000Z"}
{"type":"done","side":"sell","order_id":"3750eb5c-01f1-47b3-939e-4f6dd268753e","reason":"canceled","product_id":"BCH-USD","price":"795.28000000","remaining_size":"0.90000000","sequence":4839271673,"time":"2018-07-27T01:32:39.773000Z"}
{"type":"done","side":"sell","order_id":"e632fdac-5a2e-4694-8585-23c3c79fa608","reason":"canceled","product_id":"BCH-USD","price":"795.25000000","remaining_size":"1.90000000","sequence":4839271674,"time":"2018-07-27T01:32:39.779000Z"}
{"type":"received","order_id":"6461f03c-1c2c-4ddc-9ebd-c9273fbdd803","order_type":"limit","size":"1.90000000","price":"795.27000000","side":"sell","client_oid":"a738694c-1dad-4236-9034-f3c72214595d","product_id":"BCH-USD","sequence":4839271675,"time":"2018-07-27T01:32:39.780000Z"}
{"type":"done","side":"sell","order_id":"3a653de1-e1d3-4e6a-a368-5489b5c2f606","reason":"canceled","product_id":"LTC-USD","price":"83.38000000","remaining_size":"7.44874862","sequence":2423271724,"time":"2018-07-27T01:32:39.782000Z"}
{"type":"open","side":"sell","price":"795.27000000","order_id":"6461f03c-1c2c-4ddc-9ebd-c9273fbdd803","remaining_size":"1.90000000","product_id":"BCH-USD","sequence":4839271676,"time":"2018-07-27T01:32:39.780000Z"}
{"type":"done","side":"sell","order_id":"b939d517-741e-4ea9-a015-b1b125bc9873","reason":"canceled","product_id":"ETH-USD","price":"492.64000000","remaining_size":"0.01000000","sequence":4469354741,"time":"2018-07-27T01:32:39.781000Z"}
{"type":"received","order_id":"1e2e2816-01d3-48f8-b88d-ee181d745269","order_type":"limit","size":"0.90000000","price":"795.21000000","side":"sell","client_oid":"c6ca91b9-ca5c-41e5-9cb7-fb67d8de61be","product_id":"BCH-USD","sequence":4839271677,"time":"2018-07-27T01:32:39.783000Z"}
{"type":"open","side":"sell","price":"795.21000000","order_id":"1e2e2816-01d3-48f8-b88d-ee181d745269","remaining_size":"0.90000000","product_id":"BCH-USD","sequence":4839271678,"time":"2018-07-27T01:32:39.783000Z"}
{"type":"done","side":"buy","order_id":"5c48799f-d5f8-402b-be88-a1b71de4baed","reason":"canceled","product_id":"BTC-USD","price":"7893.00000000","remaining_size":"0.20000000","sequence":6418130214,"time":"2018-07-27T01:32:39.788000Z"}
{"type":"done","side":"sell","order_id":"1e2e2816-01d3-48f8-b88d-ee181d745269","reason":"canceled","product_id":"BCH-USD","price":"795.21000000","remaining_size":"0.90000000","sequence":4839271679,"time":"2018-07-27T01:32:39.787000Z"}
{"type":"received","order_id":"9cdb1bc7-1c76-4acf-9880-f403e930ba5c","order_type":"limit","size":"0.01000000","price":"483.62000000","side":"sell","client_oid":"fcc8bcfa-0baa-46a4-8000-00a04db21aab","product_id":"ETH-USD","sequence":4469354742,"time":"2018-07-27T01:32:39.788000Z"}
{"type":"open","side":"sell","price":"483.62000000","order_id":"9cdb1bc7-1c76-4acf-9880-f403e930ba5c","remaining_size":"0.01000000","product_id":"ETH-USD","sequence":4469354743,"time":"2018-07-27T01:32:39.788000Z"}
{"type":"received","order_id":"e07f8b9e-148c-49a7-aa7b-29d4e199ba25","order_type":"limit","size":"0.01000000","price":"484.60000000","side":"sell","client_oid":"a84f7c58-bd2e-458b-8000-007d0630aefa","product_id":"ETH-USD","sequence":4469354744,"time":"2018-07-27T01:32:39.790000Z"}
{"type":"open","side":"sell","price":"484.60000000","order_id":"e07f8b9e-148c-49a7-aa7b-29d4e199ba25","remaining_size":"0.01000000","product_id":"ETH-USD","sequence":4469354745,"time":"2018-07-27T01:32:39.790000Z"}
{"type":"received","order_id":"26df35a7-09ae-4a72-99f5-d490987c7f99","order_type":"limit","size":"7.44874862","price":"83.34000000","side":"sell","client_oid":"48575951-2189-448a-8000-00fde1abf942","product_id":"LTC-USD","sequence":2423271725,"time":"2018-07-27T01:32:39.792000Z"}
{"type":"open","side":"sell","price":"83.34000000","order_id":"26df35a7-09ae-4a72-99f5-d490987c7f99","remaining_size":"7.44874862","product_id":"LTC-USD","sequence":2423271726,"time":"2018-07-27T01:32:39.792000Z"}
{"type":"done","side":"sell","order_id":"6461f03c-1c2c-4ddc-9ebd-c9273fbdd803","reason":"canceled","product_id":"BCH-USD","price":"795.27000000","remaining_size":"1.90000000","sequence":4839271680,"time":"2018-07-27T01:32:39.792000Z"}
{"type":"received","order_id":"91ab2749-bd88-497c-af63-b4848cf2e49e","order_type":"limit","size":"0.01000000","price":"485.60000000","side":"sell","client_oid":"0ef8d2c0-dfff-4a5b-8000-007d5134bc79","product_id":"ETH-USD","sequence":4469354746,"time":"2018-07-27T01:32:39.793000Z"}
{"type":"received","order_id":"7ad05ceb-b415-4e4e-9766-5bad8658e73e","order_type":"limit","size":"4.50000000","price":"795.65000000","side":"sell","client_oid":"06c1388e-cf81-4076-bb9d-105a4e510c0c","product_id":"BCH-USD","sequence":4839271681,"time":"2018-07-27T01:32:39.793000Z"}
{"type":"open","side":"sell","price":"485.60000000","order_id":"91ab2749-bd88-497c-af63-b4848cf2e49e","remaining_size":"0.01000000","product_id":"ETH-USD","sequence":4469354747,"time":"2018-07-27T01:32:39.793000Z"}
{"type":"open","side":"sell","price":"795.65000000","order_id":"7ad05ceb-b415-4e4e-9766-5bad8658e73e","remaining_size":"4.50000000","product_id":"BCH-USD","sequence":4839271682,"time":"2018-07-27T01:32:39.793000Z"}
{"type":"received","order_id":"48b2eb1e-bad8-4c58-8a31-97664e33a4f3","order_type":"limit","size":"1.81488800","price":"791.26000000","side":"buy","client_oid":"4be81fc4-21a1-46c9-9e74-46584dafcc71","product_id":"BCH-USD","sequence":4839271683,"time":"2018-07-27T01:32:39.796000Z"}
{"type":"open","side":"buy","price":"791.26000000","order_id":"48b2eb1e-bad8-4c58-8a31-97664e33a4f3","remaining_size":"1.81488800","product_id":"BCH-USD","sequence":4839271684,"time":"2018-07-27T01:32:39.796000Z"}
{"type":"received","order_id":"c471ccdb-0a8f-4d19-be04-d6c8c5c137d2","order_type":"limit","size":"0.90000000","price":"795.27000000","side":"sell","client_oid":"01cfcf32-f7d3-4422-a3e2-24551c174a97","product_id":"BCH-USD","sequence":4839271685,"time":"2018-07-27T01:32:39.802000Z"}
{"type":"open","side":"sell","price":"795.27000000","order_id":"c471ccdb-0a8f-4d19-be04-d6c8c5c137d2","remaining_size":"0.90000000","product_id":"BCH-USD","sequence":4839271686,"time":"2018-07-27T01:32:39.802000Z"}
{"type":"received","order_id":"c4715374-893f-49ba-8b3a-d0c5b9469118","order_type":"limit","size":"0.18739300","price":"791.27000000","side":"buy","client_oid":"a86a8f07-a14d-4791-b0c7-58eafb047594","product_id":"BCH-USD","sequence":4839271687,"time":"2018-07-27T01:32:39.810000Z"}
{"type":"open","side":"buy","price":"791.27000000","order_id":"c4715374-893f-49ba-8b3a-d0c5b9469118","remaining_size":"0.18739300","product_id":"BCH-USD","sequence":4839271688,"time":"2018-07-27T01:32:39.810000Z"}
{"type":"done","side":"sell","order_id":"c471ccdb-0a8f-4d19-be04-d6c8c5c137d2","reason":"canceled","product_id":"BCH-USD","price":"795.27000000","remaining_size":"0.90000000","sequence":4839271689,"time":"2018-07-27T01:32:39.814000Z"}
{"type":"received","order_id":"e931a97a-1012-4c49-8497-1b76d5c0acfc","order_type":"limit","size":"0.90000000","price":"795.23000000","side":"sell","client_oid":"56725460-185d-45b5-b237-b3a3c001c195","product_id":"BCH-USD","sequence":4839271690,"time":"2018-07-27T01:32:39.820000Z"}
{"type":"open","side":"sell","price":"795.23000000","order_id":"e931a97a-1012-4c49-8497-1b76d5c0acfc","remaining_size":"0.90000000","product_id":"BCH-USD","sequence":4839271691,"time":"2018-07-27T01:32:39.820000Z"}
{"type":"done","side":"sell","order_id":"71119ce2-31f5-4d29-b7cb-27e32fe4536a","reason":"canceled","product_id":"LTC-USD","price":"83.30000000","remaining_size":"7.44874862","sequence":2423271727,"time":"2018-07-27T01:32:39.825000Z"}
{"type":"received","order_id":"4f30fea2-33f2-4bb1-9b2d-faf652f6ae56","order_type":"limit","size":"1.90000000","price":"795.28000000","side":"sell","client_oid":"dc2091af-b95d-4d0b-81e2-52e8ea175b89","product_id":"BCH-USD","sequence":4839271692,"time":"2018-07-27T01:32:39.825000Z"}
{"type":"open","side":"sell","price":"795.28000000","order_id":"4f30fea2-33f2-4bb1-9b2d-faf652f6ae56","remaining_size":"1.90000000","product_id":"BCH-USD","sequence":4839271693,"time":"2018-07-27T01:32:39.825000Z"}
{"type":"done","side":"sell","order_id":"e931a97a-1012-4c49-8497-1b76d5c0acfc","reason":"canceled","product_id":"BCH-USD","price":"795.23000000","remaining_size":"0.90000000","sequence":4839271694,"time":"2018-07-27T01:32:39.826000Z"}
{"type":"done","side":"buy","order_id":"48b2eb1e-bad8-4c58-8a31-97664e33a4f3","reason":"canceled","product_id":"BCH-USD","price":"791.26000000","remaining_size":"1.81488800","sequence":4839271695,"time":"2018-07-27T01:32:39.827000Z"}
{"type":"done","side":"sell","order_id":"dec516a1-b181-4a2b-ba6e-940e89e2e4b9","reason":"canceled","product_id":"BTC-USD","price":"7906.54000000","remaining_size":"0.02500000","sequence":6418130215,"time":"2018-07-27T01:32:39.830000Z"}
{"type":"done","side":"sell","order_id":"7ad05ceb-b415-4e4e-9766-5bad8658e73e","reason":"canceled","product_id":"BCH-USD","price":"795.65000000","remaining_size":"4.50000000","sequence":4839271696,"time":"2018-07-27T01:32:39.829000Z"}
{"type":"received","order_id":"abaab7c4-886c-4d40-a74f-9c3242e7eb3b","order_type":"limit","size":"7.44874862","price":"83.38000000","side":"sell","client_oid":"d948dc3a-4016-4373-8000-00778f0722d8","product_id":"LTC-USD","sequence":2423271728,"time":"2018-07-27T01:32:39.834000Z"}
{"type":"open","side":"sell","price":"83.38000000","order_id":"abaab7c4-886c-4d40-a74f-9c3242e7eb3b","remaining_size":"7.44874862","product_id":"LTC-USD","sequence":2423271729,"time":"2018-07-27T01:32:39.834000Z"}
{"type":"received","order_id":"7ad97b63-f1f4-478e-b2ca-f81fd8541d27","order_type":"limit","size":"0.90000000","price":"795.27000000","side":"sell","client_oid":"58aab594-d1e7-434d-9c29-1622a70a28f0","product_id":"BCH-USD","sequence":4839271697,"time":"2018-07-27T01:32:39.835000Z"}
{"type":"open","side":"sell","price":"795.27000000","order_id":"7ad97b63-f1f4-478e-b2ca-f81fd8541d27","remaining_size":"0.90000000","product_id":"BCH-USD","sequence":4839271698,"time":"2018-07-27T01:32:39.835000Z"}
{"type":"received","order_id":"6d289ed8-fede-432d-a381-8960d319ac2d","order_type":"limit","size":"0.02500000","price":"7906.79000000","side":"sell","client_oid":"1c4e811b-804d-4e2f-8000-00e197a246f7","product_id":"BTC-USD","sequence":6418130216,"time":"2018-07-27T01:32:39.838000Z"}
{"type":"open","side":"sell","price":"7906.79000000","order_id":"6d289ed8-fede-432d-a381-8960d319ac2d","remaining_size":"0.02500000","product_id":"BTC-USD","sequence":6418130217,"time":"2018-07-27T01:32:39.838000Z"}
{"type":"done","side":"buy","order_id":"40d4009a-210a-468a-82fa-c62c21b1f6ec","reason":"canceled","product_id":"BCH-USD","price":"791.23000000","remaining_size":"0.18739300","sequence":4839271699,"time":"2018-07-27T01:32:39.837000Z"}
{"type":"done","side":"buy","order_id":"c4715374-893f-49ba-8b3a-d0c5b9469118","reason":"canceled","product_id":"BCH-USD","price":"791.27000000","remaining_size":"0.18739300","sequence":4839271700,"time":"2018-07-27T01:32:39.838000Z"}
{"type":"received","order_id":"c2c605bf-270a-495f-9b47-77613eb4aa34","order_type":"limit","size":"1.81488800","price":"791.23000000","side":"buy","client_oid":"d7e0794a-6b8d-4c35-86d7-5f22fc3027a5","product_id":"BCH-USD","sequence":4839271701,"time":"2018-07-27T01:32:39.839000Z"}
{"type":"open","side":"buy","price":"791.23000000","order_id":"c2c605bf-270a-495f-9b47-77613eb4aa34","remaining_size":"1.81488800","product_id":"BCH-USD","sequence":4839271702,"time":"2018-07-27T01:32:39.839000Z"}
{"type":"done","side":"sell","order_id":"4f30fea2-33f2-4bb1-9b2d-faf652f6ae56","reason":"canceled","product_id":"BCH-USD","price":"795.28000000","remaining_size":"1.90000000","sequence":4839271703,"time":"2018-07-27T01:32:39.842000Z"}
{"type":"received","order_id":"8402da54-a51e-4243-882d-763f485656a9","order_type":"limit","size":"4.50000000","price":"795.27000000","side":"sell","client_oid":"18a48316-9812-486f-af38-7a1f1877d0c8","product_id":"BCH-USD","sequence":4839271704,"time":"2018-07-27T01:32:39.843000Z"}
{"type":"open","side":"sell","price":"795.27000000","order_id":"8402da54-a51e-4243-882d-763f485656a9","remaining_size":"4.50000000","product_id":"BCH-USD","sequence":4839271705,"time":"2018-07-27T01:32:39.843000Z"}
{"type":"received","order_id":"49319d4b-32e5-4e64-87b9-42a0243f228f","order_type":"limit","size":"95.46385100","price":"83.34000000","side":"sell","client_oid":"f1d6ea72-48f7-4741-bea2-03122ab8e823","product_id":"LTC-USD","sequence":2423271730,"time":"2018-07-27T01:32:39.847000Z"}
{"type":"open","side":"sell","price":"83.34000000","order_id":"49319d4b-32e5-4e64-87b9-42a0243f228f","remaining_size":"95.46385100","product_id":"LTC-USD","sequence":2423271731,"time":"2018-07-27T01:32:39.847000Z"}
{"type":"received","order_id":"b210b1c2-6717-489d-9ee8-c5243cc30b26","order_type":"limit","size":"1.90000000","price":"795.26000000","side":"sell","client_oid":"ad7f0daa-6858-4f08-9d53-497ec77ce2ba","product_id":"BCH-USD","sequence":4839271706,"time":"2018-07-27T01:32:39.848000Z"}
{"type":"open","side":"sell","price":"795.26000000","order_id":"b210b1c2-6717-489d-9ee8-c5243cc30b26","remaining_size":"1.90000000","product_id":"BCH-USD","sequence":4839271707,"time":"2018-07-27T01:32:39.848000Z"}
{"type":"received","order_id":"8a74e830-4482-4d0a-a578-2d81cc17b824","order_type":"limit","size":"0.18739300","price":"791.24000000","side":"buy","client_oid":"11131510-7f77-44b7-87e1-949ede2a52d8","product_id":"BCH-USD","sequence":4839271708,"time":"2018-07-27T01:32:39.850000Z"}
{"type":"open","side":"buy","price":"791.24000000","order_id":"8a74e830-4482-4d0a-a578-2d81cc17b824","remaining_size":"0.18739300","product_id":"BCH-USD","sequence":4839271709,"time":"2018-07-27T01:32:39.850000Z"}
{"type":"done","side":"sell","order_id":"8402da54-a51e-4243-882d-763f485656a9","reason":"canceled","product_id":"BCH-USD","price":"795.27000000","remaining_size":"4.50000000","sequence":4839271710,"time":"2018-07-27T01:32:39.854000Z"}
{"type":"received","order_id":"e5dc6f3c-552c-4637-b7a1-733437193a0f","order_type":"limit","size":"4.50000000","price":"795.67000000","side":"sell","client_oid":"d80e9e07-7d7a-4b46-b504-51399041cd50","product_id":"BCH-USD","sequence":4839271711,"time":"2018-07-27T01:32:39.858000Z"}
{"type":"open","side":"sell","price":"795.67000000","order_id":"e5dc6f3c-552c-4637-b7a1-733437193a0f","remaining_size":"4.50000000","product_id":"BCH-USD","sequence":4839271712,"time":"2018-07-27T01:32:39.858000Z"}
{"type":"received","order_id":"ffaa468d-8595-49b2-88ba-2835281f1761","order_type":"limit","size":"1.90000000","price":"795.27000000","side":"sell","client_oid":"c33768ec-b87d-4e8b-bb36-a7c2d698773c","product_id":"BCH-USD","sequence":4839271713,"time":"2018-07-27T01:32:39.858000Z"}
{"type":"open","side":"sell","price":"795.27000000","order_id":"ffaa468d-8595-49b2-88ba-2835281f1761","remaining_size":"1.90000000","product_id":"BCH-USD","sequence":4839271714,"time":"2018-07-27T01:32:39.858000Z"}
{"type":"received","order_id":"6431448c-c656-465a-b80f-4fa6c37a9983","order_type":"limit","size":"14.14913200","price":"83.37000000","side":"sell","client_oid":"611f36fa-935c-472e-823d-4ea3cc3d0403","product_id":"LTC-USD","sequence":2423271732,"time":"2018-07-27T01:32:39.861000Z"}
{"type":"open","side":"sell","price":"83.37000000","order_id":"6431448c-c656-465a-b80f-4fa6c37a9983","remaining_size":"14.14913200","product_id":"LTC-USD","sequence":2423271733,"time":"2018-07-27T01:32:39.861000Z"}
{"type":"received","order_id":"bfc859c5-9c3d-4d99-8dcb-d2209baf4a73","order_type":"limit","size":"4.50000000","price":"795.26000000","side":"sell","client_oid":"a595b6d8-c31c-403d-8241-a5ec75966650","product_id":"BCH-USD","sequence":4839271715,"time":"2018-07-27T01:32:39.868000Z"}
{"type":"open","side":"sell","price":"795.26000000","order_id":"bfc859c5-9c3d-4d99-8dcb-d2209baf4a73","remaining_size":"4.50000000","product_id":"BCH-USD","sequence":4839271716,"time":"2018-07-27T01:32:39.868000Z"}
{"type":"done","side":"buy","order_id":"c2c605bf-270a-495f-9b47-77613eb4aa34","reason":"canceled","product_id":"BCH-USD","price":"791.23000000","remaining_size":"1.81488800","sequence":4839271717,"time":"2018-07-27T01:32:39.870000Z"}
{"type":"received","order_id":"a1623692-af05-495f-bb79-a8bdad62370b","order_type":"limit","size":"160.47500000","price":"798.80000000","side":"sell","product_id":"BCH-USD","sequence":4839271718,"time":"2018-07-27T01:32:39.872000Z"}
{"type":"open","side":"sell","price":"798.80000000","order_id":"a1623692-af05-495f-bb79-a8bdad62370b","remaining_size":"160.47500000","product_id":"BCH-USD","sequence":4839271719,"time":"2018-07-27T01:32:39.872000Z"}
{"type":"received","order_id":"d5b7e775-a690-4917-84f6-1a51dedb6cdf","order_type":"limit","size":"11.48073900","price":"83.40000000","side":"sell","client_oid":"6ccf12c8-1d2b-411b-9985-720f76aa3570","product_id":"LTC-USD","sequence":2423271734,"time":"2018-07-27T01:32:39.876000Z"}
{"type":"open","side":"sell","price":"83.40000000","order_id":"d5b7e775-a690-4917-84f6-1a51dedb6cdf","remaining_size":"11.48073900","product_id":"LTC-USD","sequence":2423271735,"time":"2018-07-27T01:32:39.876000Z"}
{"type":"received","order_id":"1707331d-b4a5-4c10-a9eb-aaa0e66b33bd","order_type":"limit","size":"1.81488800","price":"791.27000000","side":"buy","client_oid":"48323d89-c376-4680-94dc-82ae01ca7a14","product_id":"BCH-USD","sequence":4839271720,"time":"2018-07-27T01:32:39.878000Z"}
{"type":"open","side":"buy","price":"791.27000000","order_id":"1707331d-b4a5-4c10-a9eb-aaa0e66b33bd","remaining_size":"1.81488800","product_id":"BCH-USD","sequence":4839271721,"time":"2018-07-27T01:32:39.878000Z"}
{"type":"done","side":"buy","order_id":"8a74e830-4482-4d0a-a578-2d81cc17b824","reason":"canceled","product_id":"BCH-USD","price":"791.24000000","remaining_size":"0.18739300","sequence":4839271722,"time":"2018-07-27T01:32:39.883000Z"}
{"type":"done","side":"sell","order_id":"b210b1c2-6717-489d-9ee8-c5243cc30b26","reason":"canceled","product_id":"BCH-USD","price":"795.26000000","remaining_size":"1.90000000","sequence":4839271723,"time":"2018-07-27T01:32:39.884000Z"}
{"type":"done","side":"sell","order_id":"e5dc6f3c-552c-4637-b7a1-733437193a0f","reason":"canceled","product_id":"BCH-USD","price":"795.67000000","remaining_size":"4.50000000","sequence":4839271724,"time":"2018-07-27T01:32:39.886000Z"}
{"type":"received","order_id":"f4bfa9d4-346e-4c9e-8a9a-aaf276ff7849","order_type":"limit","size":"13.61311100","price":"83.43000000","side":"sell","client_oid":"dbe34da4-7559-48c3-abd6-b1c90eac65fe","product_id":"LTC-USD","sequence":2423271736,"time":"2018-07-27T01:32:39.890000Z"}
{"type":"open","side":"sell","price":"83.43000000","order_id":"f4bfa9d4-346e-4c9e-8a9a-aaf276ff7849","remaining_size":"13.61311100","product_id":"LTC-USD","sequence":2423271737,"time":"2018-07-27T01:32:39.890000Z"}
{"type":"received","order_id":"5f101767-6cb1-4d83-8104-e775086ad7a9","order_type":"limit","size":"0.18739300","price":"791.23000000","side":"buy","client_oid":"186e8bca-8068-4745-aee8-565a50e0642e","product_id":"BCH-USD","sequence":4839271725,"time":"2018-07-27T01:32:39.891000Z"}
{"type":"open","side":"buy","price":"791.23000000","order_id":"5f101767-6cb1-4d83-8104-e775086ad7a9","remaining_size":"0.18739300","product_id":"BCH-USD","sequence":4839271726,"time":"2018-07-27T01:32:39.891000Z"}
{"type":"received","order_id":"8c82e179-56d7-478c-bd2e-62f389f1f400","order_type":"limit","size":"4.50000000","price":"795.64000000","side":"sell","client_oid":"e80f0f8a-324f-4c01-94a8-6f3ca97a8f9c","product_id":"BCH-USD","sequence":4839271727,"time":"2018-07-27T01:32:39.893000Z"}
{"type":"open","side":"sell","price":"795.64000000","order_id":"8c82e179-56d7-478c-bd2e-62f389f1f400","remaining_size":"4.50000000","product_id":"BCH-USD","sequence":4839271728,"time":"2018-07-27T01:32:39.893000Z"}
{"type":"received","order_id":"bdacf69e-da97-474d-9d38-49a19ab23ca8","order_type":"limit","size":"1.90000000","price":"795.25000000","side":"sell","client_oid":"e7ef5c5a-6099-4ce8-8b09-0df68ed98e02","product_id":"BCH-USD","sequence":4839271729,"time":"2018-07-27T01:32:39.893000Z"}
{"type":"open","side":"sell","price":"795.25000000","order_id":"bdacf69e-da97-474d-9d38-49a19ab23ca8","remaining_size":"1.90000000","product_id":"BCH-USD","sequence":4839271730,"time":"2018-07-27T01:32:39.893000Z"}
{"type":"done","side":"buy","order_id":"5f101767-6cb1-4d83-8104-e775086ad7a9","reason":"canceled","product_id":"BCH-USD","price":"791.23000000","remaining_size":"0.18739300","sequence":4839271731,"time":"2018-07-27T01:32:39.895000Z"}
{"type":"done","side":"buy","order_id":"1707331d-b4a5-4c10-a9eb-aaa0e66b33bd","reason":"canceled","product_id":"BCH-USD","price":"791.27000000","remaining_size":"1.81488800","sequence":4839271732,"time":"2018-07-27T01:32:39.900000Z"}
{"type":"done","side":"sell","order_id":"8c82e179-56d7-478c-bd2e-62f389f1f400","reason":"canceled","product_id":"BCH-USD","price":"795.64000000","remaining_size":"4.50000000","sequence":4839271733,"time":"2018-07-27T01:32:39.900000Z"}
{"type":"done","side":"buy","order_id":"3f622067-a6ff-4aa1-a51d-ac34deffb950","reason":"canceled","product_id":"BCH-USD","price":"792.80000000","remaining_size":"2.00000000","sequence":4839271734,"time":"2018-07-27T01:32:39.900000Z"}
{"type":"done","side":"sell","order_id":"bfc859c5-9c3d-4d99-8dcb-d2209baf4a73","reason":"canceled","product_id":"BCH-USD","price":"795.26000000","remaining_size":"4.50000000","sequence":4839271735,"time":"2018-07-27T01:32:39.903000Z"}
{"type":"done","side":"sell","order_id":"7ad97b63-f1f4-478e-b2ca-f81fd8541d27","reason":"canceled","product_id":"BCH-USD","price":"795.27000000","remaining_size":"0.90000000","sequence":4839271736,"time":"2018-07-27T01:32:39.905000Z"}
{"type":"done","side":"sell","order_id":"ffaa468d-8595-49b2-88ba-2835281f1761","reason":"canceled","product_id":"BCH-USD","price":"795.27000000","remaining_size":"1.90000000","sequence":4839271737,"time":"2018-07-27T01:32:39.907000Z"}
{"type":"received","order_id":"500a1647-e5ac-4de3-81ba-e196cc094104","order_type":"limit","size":"0.18739300","price":"791.28000000","side":"buy","client_oid":"6aed2552-7455-4176-9cc7-52e747d6cbbc","product_id":"BCH-USD","sequence":4839271738,"time":"2018-07-27T01:32:39.909000Z"}
{"type":"open","side":"buy","price":"791.28000000","order_id":"500a1647-e5ac-4de3-81ba-e196cc094104","remaining_size":"0.18739300","product_id":"BCH-USD","sequence":4839271739,"time":"2018-07-27T01:32:39.909000Z"}
{"type":"done","side":"sell","order_id":"abaab7c4-886c-4d40-a74f-9c3242e7eb3b","reason":"canceled","product_id":"LTC-USD","price":"83.38000000","remaining_size":"7.44874862","sequence":2423271738,"time":"2018-07-27T01:32:39.911000Z"}
{"type":"received","order_id":"cbf81338-de2d-4385-807e-3df550340537","order_type":"limit","size":"1.81488800","price":"791.24000000","side":"buy","client_oid":"11ec6ca0-6237-4faf-8fb7-a1f57404fe01","product_id":"BCH-USD","sequence":4839271740,"time":"2018-07-27T01:32:39.910000Z"}
{"type":"open","side":"buy","price":"791.24000000","order_id":"cbf81338-de2d-4385-807e-3df550340537","remaining_size":"1.81488800","product_id":"BCH-USD","sequence":4839271741,"time":"2018-07-27T01:32:39.910000Z"}
{"type":"received","order_id":"459efb40-f66e-4e98-90be-8489a5e15f26","order_type":"limit","size":"2.00000000","price":"794.37000000","side":"sell","client_oid":"552a0a8b-6768-4d00-9881-43f9cbd7e518","product_id":"BCH-USD","sequence":4839271742,"time":"2018-07-27T01:32:39.912000Z"}
{"type":"open","side":"sell","price":"794.37000000","order_id":"459efb40-f66e-4e98-90be-8489a5e15f26","remaining_size":"2.00000000","product_id":"BCH-USD","sequence":4839271743,"time":"2018-07-27T01:32:39.912000Z"}
{"type":"received","order_id":"34d05b78-12b6-4730-aac4-e739ebfde816","order_type":"limit","size":"4.50000000","price":"795.25000000","side":"sell","client_oid":"d94072b1-8293-42fb-a8cd-6acaa4eb083e","product_id":"BCH-USD","sequence":4839271744,"time":"2018-07-27T01:32:39.912000Z"}
{"type":"open","side":"sell","price":"795.25000000","order_id":"34d05b78-12b6-4730-aac4-e739ebfde816","remaining_size":"4.50000000","product_id":"BCH-USD","sequence":4839271745,"time":"2018-07-27T01:32:39.912000Z"}
{"type":"done","side":"buy","order_id":"cbf81338-de2d-4385-807e-3df550340537","reason":"canceled","product_id":"BCH-USD","price":"791.24000000","remaining_size":"1.81488800","sequence":4839271746,"time":"2018-07-27T01:32:39.916000Z"}
{"type":"received","order_id":"c985d880-d1fa-4d13-93c7-a49aef7f64f4","order_type":"limit","size":"4.50000000","price":"795.67000000","side":"sell","client_oid":"272f5f07-a9bc-43ba-8900-fe8a02aa41bf","product_id":"BCH-USD","sequence":4839271747,"time":"2018-07-27T01:32:39.917000Z"}
{"type":"open","side":"sell","price":"795.67000000","order_id":"c985d880-d1fa-4d13-93c7-a49aef7f64f4","remaining_size":"4.50000000","product_id":"BCH-USD","sequence":4839271748,"time":"2018-07-27T01:32:39.917000Z"}
{"type":"done","side":"buy","order_id":"500a1647-e5ac-4de3-81ba-e196cc094104","reason":"canceled","product_id":"BCH-USD","price":"791.28000000","remaining_size":"0.18739300","sequence":4839271749,"time":"2018-07-27T01:32:39.920000Z"}
{"type":"done","side":"sell","order_id":"c985d880-d1fa-4d13-93c7-a49aef7f64f4","reason":"canceled","product_id":"BCH-USD","price":"795.67000000","remaining_size":"4.50000000","sequence":4839271750,"time":"2018-07-27T01:32:39.920000Z"}
{"type":"done","side":"sell","order_id":"bdacf69e-da97-474d-9d38-49a19ab23ca8","reason":"canceled","product_id":"BCH-USD","price":"795.25000000","remaining_size":"1.90000000","sequence":4839271751,"time":"2018-07-27T01:32:39.921000Z"}
{"type":"received","order_id":"dcaa2e4e-dc4a-4174-af4d-e034a9a295a3","order_type":"limit","size":"1.90000000","price":"795.26000000","side":"sell","client_oid":"20aeef27-69d2-44b9-96da-6fef85398cd4","product_id":"BCH-USD","sequence":4839271752,"time":"2018-07-27T01:32:39.921000Z"}
{"type":"open","side":"sell","price":"795.26000000","order_id":"dcaa2e4e-dc4a-4174-af4d-e034a9a295a3","remaining_size":"1.90000000","product_id":"BCH-USD","sequence":4839271753,"time":"2018-07-27T01:32:39.921000Z"}
{"type":"done","side":"sell","order_id":"34d05b78-12b6-4730-aac4-e739ebfde816","reason":"canceled","product_id":"BCH-USD","price":"795.25000000","remaining_size":"4.50000000","sequence":4839271754,"time":"2018-07-27T01:32:39.924000Z"}
{"type":"done","side":"sell","order_id":"6d289ed8-fede-432d-a381-8960d319ac2d","reason":"canceled","product_id":"BTC-USD","price":"7906.79000000","remaining_size":"0.02500000","sequence":6418130218,"time":"2018-07-27T01:32:39.929000Z"}
{"type":"received","order_id":"8700674f-d199-4c08-8c32-9b726b3b01da","order_type":"limit","size":"1.90000000","price":"795.27000000","side":"sell","client_oid":"0eab4125-3e19-4449-9e2f-23614c6f3266","product_id":"BCH-USD","sequence":4839271755,"time":"2018-07-27T01:32:39.927000Z"}
{"type":"open","side":"sell","price":"795.27000000","order_id":"8700674f-d199-4c08-8c32-9b726b3b01da","remaining_size":"1.90000000","product_id":"BCH-USD","sequence":4839271756,"time":"2018-07-27T01:32:39.927000Z"}
{"type":"received","order_id":"6da2858e-4a7c-4b1c-8018-0c1a4fb639a2","order_type":"limit","size":"7.44874862","price":"83.30000000","side":"sell","client_oid":"bf590cbb-850a-4453-8000-00f1735c474c","product_id":"LTC-USD","sequence":2423271739,"time":"2018-07-27T01:32:39.929000Z"}
{"type":"done","side":"sell","order_id":"dcaa2e4e-dc4a-4174-af4d-e034a9a295a3","reason":"canceled","product_id":"BCH-USD","price":"795.26000000","remaining_size":"1.90000000","sequence":4839271757,"time":"2018-07-27T01:32:39.927000Z"}
{"type":"open","side":"sell","price":"83.30000000","order_id":"6da2858e-4a7c-4b1c-8018-0c1a4fb639a2","remaining_size":"7.44874862","product_id":"LTC-USD","sequence":2423271740,"time":"2018-07-27T01:32:39.929000Z"}
{"type":"done","side":"sell","order_id":"8700674f-d199-4c08-8c32-9b726b3b01da","reason":"canceled","product_id":"BCH-USD","price":"795.27000000","remaining_size":"1.90000000","sequence":4839271758,"time":"2018-07-27T01:32:39.931000Z"}
{"type":"received","order_id":"1d996a91-28a4-4e2b-b8dd-7061a37ea7ee","order_type":"limit","size":"0.90000000","price":"795.26000000","side":"sell","client_oid":"bba77e6f-e470-4a3e-9294-d5b22df0ac1a","product_id":"BCH-USD","sequence":4839271759,"time":"2018-07-27T01:32:39.931000Z"}
{"type":"open","side":"sell","price":"795.26000000","order_id":"1d996a91-28a4-4e2b-b8dd-7061a37ea7ee","remaining_size":"0.90000000","product_id":"BCH-USD","sequence":4839271760,"time":"2018-07-27T01:32:39.931000Z"}
{"type":"received","order_id":"b7f34037-8bd5-40d0-9af7-1177e33fba42","order_type":"limit","size":"0.18739300","price":"791.25000000","side":"buy","client_oid":"c24f47c2-ebd4-4604-93cf-9dfa93d42344","product_id":"BCH-USD","sequence":4839271761,"time":"2018-07-27T01:32:39.932000Z"}
{"type":"received","order_id":"49faab74-3e10-4171-8f79-053953ef8ebf","order_type":"limit","size":"0.02500000","price":"7907.17000000","side":"sell","client_oid":"4efd147d-7684-4d4d-8000-003f2c766757","product_id":"BTC-USD","sequence":6418130219,"time":"2018-07-27T01:32:39.935000Z"}
{"type":"open","side":"buy","price":"791.25000000","order_id":"b7f34037-8bd5-40d0-9af7-1177e33fba42","remaining_size":"0.18739300","product_id":"BCH-USD","sequence":4839271762,"time":"2018-07-27T01:32:39.932000Z"}
{"type":"open","side":"sell","price":"7907.17000000","order_id":"49faab74-3e10-4171-8f79-053953ef8ebf","remaining_size":"0.02500000","product_id":"BTC-USD","sequence":6418130220,"time":"2018-07-27T01:32:39.935000Z"}
{"type":"received","order_id":"c205664a-160c-4d7c-a9c3-011de63990f0","order_type":"limit","size":"1.81488800","price":"791.28000000","side":"buy","client_oid":"57983bdd-e2cd-49bb-8893-82a0364f76f9","product_id":"BCH-USD","sequence":4839271763,"time":"2018-07-27T01:32:39.935000Z"}
{"type":"open","side":"buy","price":"791.28000000","order_id":"c205664a-160c-4d7c-a9c3-011de63990f0","remaining_size":"1.81488800","product_id":"BCH-USD","sequence":4839271764,"time":"2018-07-27T01:32:39.935000Z"}
{"type":"done","side":"sell","order_id":"1d996a91-28a4-4e2b-b8dd-7061a37ea7ee","reason":"canceled","product_id":"BCH-USD","price":"795.26000000","remaining_size":"0.90000000","sequence":4839271765,"time":"2018-07-27T01:32:39.935000Z"}
{"type":"done","side":"buy","order_id":"b7f34037-8bd5-40d0-9af7-1177e33fba42","reason":"canceled","product_id":"BCH-USD","price":"791.25000000","remaining_size":"0.18739300","sequence":4839271766,"time":"2018-07-27T01:32:39.936000Z"}
{"type":"received","order_id":"5f0af5cb-32b2-4e90-95ae-4c015cf62922","order_type":"limit","size":"4.50000000","price":"795.53000000","side":"sell","client_oid":"34577f29-39e0-4813-96a4-24895147c0ac","product_id":"BCH-USD","sequence":4839271767,"time":"2018-07-27T01:32:39.938000Z"}
{"type":"open","side":"sell","price":"795.53000000","order_id":"5f0af5cb-32b2-4e90-95ae-4c015cf62922","remaining_size":"4.50000000","product_id":"BCH-USD","sequence":4839271768,"time":"2018-07-27T01:32:39.938000Z"}
{"type":"done","side":"buy","order_id":"c205664a-160c-4d7c-a9c3-011de63990f0","reason":"canceled","product_id":"BCH-USD","price":"791.28000000","remaining_size":"1.81488800","sequence":4839271769,"time":"2018-07-27T01:32:39.939000Z"}
{"type":"received","order_id":"2046c220-dc30-47d2-8ede-d4f9ce1225e4","order_type":"limit","size":"4.50000000","price":"795.27000000","side":"sell","client_oid":"cf19b95f-7ef5-4f21-9757-2c2888a7b1d6","product_id":"BCH-USD","sequence":4839271770,"time":"2018-07-27T01:32:39.941000Z"}
{"type":"open","side":"sell","price":"795.27000000","order_id":"2046c220-dc30-47d2-8ede-d4f9ce1225e4","remaining_size":"4.50000000","product_id":"BCH-USD","sequence":4839271771,"time":"2018-07-27T01:32:39.941000Z"}
{"type":"done","side":"sell","order_id":"5f0af5cb-32b2-4e90-95ae-4c015cf62922","reason":"canceled","product_id":"BCH-USD","price":"795.53000000","remaining_size":"4.50000000","sequence":4839271772,"time":"2018-07-27T01:32:39.942000Z"}
{"type":"done","side":"buy","order_id":"eab17fc5-86e8-48a1-a2df-43a4decc2e9d","reason":"canceled","product_id":"BCH-USD","price":"790.16000000","remaining_size":"0.26091200","sequence":4839271773,"time":"2018-07-27T01:32:39.944000Z"}
{"type":"done","side":"sell","order_id":"459efb40-f66e-4e98-90be-8489a5e15f26","reason":"canceled","product_id":"BCH-USD","price":"794.37000000","remaining_size":"2.00000000","sequence":4839271774,"time":"2018-07-27T01:32:39.944000Z"}
{"type":"done","side":"buy","order_id":"94e111bb-e407-46cf-b23b-edef2acf85c7","reason":"canceled","product_id":"BCH-USD","price":"789.92000000","remaining_size":"0.24356000","sequence":4839271775,"time":"2018-07-27T01:32:39.946000Z"}
{"type":"done","side":"buy","order_id":"4e41bbf7-6afd-45f3-b1a0-3f5e45d4bf3c","reason":"canceled","product_id":"BCH-USD","price":"789.68000000","remaining_size":"0.13292500","sequence":4839271776,"time":"2018-07-27T01:32:39.948000Z"}
{"type":"done","side":"sell","order_id":"2046c220-dc30-47d2-8ede-d4f9ce1225e4","reason":"canceled","product_id":"BCH-USD","price":"795.27000000","remaining_size":"4.50000000","sequence":4839271777,"time":"2018-07-27T01:32:39.951000Z"}
{"type":"done","side":"sell","order_id":"6da2858e-4a7c-4b1c-8018-0c1a4fb639a2","reason":"canceled","product_id":"LTC-USD","price":"83.30000000","remaining_size":"7.44874862","sequence":2423271741,"time":"2018-07-27T01:32:39.953000Z"}
{"type":"done","side":"buy","order_id":"9787d530-8ef6-4cf2-9a03-72b702ef3613","reason":"canceled","product_id":"BCH-USD","price":"789.20000000","remaining_size":"0.20120600","sequence":4839271778,"time":"2018-07-27T01:32:39.952000Z"}
{"type":"received","order_id":"f383765b-729c-41cb-8e96-19d751ddd5ba","order_type":"limit","size":"1.81488800","price":"791.23000000","side":"buy","client_oid":"7c75f169-69c6-44b5-bf5b-484f9e1b5d73","product_id":"BCH-USD","sequence":4839271779,"time":"2018-07-27T01:32:39.953000Z"}
{"type":"open","side":"buy","price":"791.23000000","order_id":"f383765b-729c-41cb-8e96-19d751ddd5ba","remaining_size":"1.81488800","product_id":"BCH-USD","sequence":4839271780,"time":"2018-07-27T01:32:39.953000Z"}
{"type":"done","side":"buy","order_id":"f458748f-22ee-4c51-a014-49f1bd8c8d9f","reason":"canceled","product_id":"BCH-USD","price":"788.96000000","remaining_size":"0.16068500","sequence":4839271781,"time":"2018-07-27T01:32:39.955000Z"}
{"type":"received","order_id":"8b035c78-ee39-4e6e-9490-13b0ea1efacf","order_type":"limit","size":"1.90000000","price":"795.24000000","side":"sell","client_oid":"3761d682-aee8-4d59-a84f-df571ed68a6d","product_id":"BCH-USD","sequence":4839271782,"time":"2018-07-27T01:32:39.956000Z"}
{"type":"open","side":"sell","price":"795.24000000","order_id":"8b035c78-ee39-4e6e-9490-13b0ea1efacf","remaining_size":"1.90000000","product_id":"BCH-USD","sequence":4839271783,"time":"2018-07-27T01:32:39.956000Z"}
{"type":"done","side":"buy","order_id":"ffde1876-8bcc-407a-a748-d307b58c2c62","reason":"canceled","product_id":"BCH-USD","price":"788.72000000","remaining_size":"0.34862100","sequence":4839271784,"time":"2018-07-27T01:32:39.957000Z"}
{"type":"done","side":"sell","order_id":"8b035c78-ee39-4e6e-9490-13b0ea1efacf","reason":"canceled","product_id":"BCH-USD","price":"795.24000000","remaining_size":"1.90000000","sequence":4839271785,"time":"2018-07-27T01:32:39.959000Z"}
{"type":"done","side":"buy","order_id":"1d937f6a-766f-40b4-b0b5-be2695fefd69","reason":"canceled","product_id":"BCH-USD","price":"788.48000000","remaining_size":"0.40003100","sequence":4839271786,"time":"2018-07-27T01:32:39.959000Z"}
{"type":"received","order_id":"f2d1da25-eb0b-422a-a19a-dcca0c01b44d","order_type":"limit","size":"1.90000000","price":"795.25000000","side":"sell","client_oid":"993f5419-3489-4061-90f1-8820ec255d05","product_id":"BCH-USD","sequence":4839271787,"time":"2018-07-27T01:32:39.961000Z"}
{"type":"open","side":"sell","price":"795.25000000","order_id":"f2d1da25-eb0b-422a-a19a-dcca0c01b44d","remaining_size":"1.90000000","product_id":"BCH-USD","sequence":4839271788,"time":"2018-07-27T01:32:39.961000Z"}
{"type":"done","side":"buy","order_id":"9bee12bf-3a65-46f6-913c-c93748677cf3","reason":"canceled","product_id":"BCH-USD","price":"788.24000000","remaining_size":"3.20636900","sequence":4839271789,"time":"2018-07-27T01:32:39.962000Z"}
{"type":"done","side":"sell","order_id":"f2d1da25-eb0b-422a-a19a-dcca0c01b44d","reason":"canceled","product_id":"BCH-USD","price":"795.25000000","remaining_size":"1.90000000","sequence":4839271790,"time":"2018-07-27T01:32:39.964000Z"}
{"type":"done","side":"sell","order_id":"26df35a7-09ae-4a72-99f5-d490987c7f99","reason":"canceled","product_id":"LTC-USD","price":"83.34000000","remaining_size":"7.44874862","sequence":2423271742,"time":"2018-07-27T01:32:39.966000Z"}
{"type":"received","order_id":"398d2ec1-06ed-4343-b072-8769e77e2dd2","order_type":"limit","size":"4.50000000","price":"795.67000000","side":"sell","client_oid":"7dbd33cb-cacf-4472-ad60-978ffde04956","product_id":"BCH-USD","sequence":4839271791,"time":"2018-07-27T01:32:39.964000Z"}
{"type":"open","side":"sell","price":"795.67000000","order_id":"398d2ec1-06ed-4343-b072-8769e77e2dd2","remaining_size":"4.50000000","product_id":"BCH-USD","sequence":4839271792,"time":"2018-07-27T01:32:39.964000Z"}
{"type":"received","order_id":"3cfda733-3bd0-468f-a84a-d7ba7df571bd","order_type":"limit","size":"4.50000000","price":"795.26000000","side":"sell","client_oid":"853c7a1c-36e2-48b8-9cb5-2b24f70e02a6","product_id":"BCH-USD","sequence":4839271793,"time":"2018-07-27T01:32:39.965000Z"}
{"type":"open","side":"sell","price":"795.26000000","order_id":"3cfda733-3bd0-468f-a84a-d7ba7df571bd","remaining_size":"4.50000000","product_id":"BCH-USD","sequence":4839271794,"time":"2018-07-27T01:32:39.965000Z"}
{"type":"received","order_id":"46a3d303-fbf7-4400-9a66-93f792659b5d","order_type":"limit","size":"0.90000000","price":"795.25000000","side":"sell","client_oid":"21ce2144-77a5-438b-bb5b-7da9bf3a9bb8","product_id":"BCH-USD","sequence":4839271795,"time":"2018-07-27T01:32:39.967000Z"}
{"type":"open","side":"sell","price":"795.25000000","order_id":"46a3d303-fbf7-4400-9a66-93f792659b5d","remaining_size":"0.90000000","product_id":"BCH-USD","sequence":4839271796,"time":"2018-07-27T01:32:39.967000Z"}
{"type":"received","order_id":"25de55d9-5e02-49db-a19f-5499c96c5b67","order_type":"limit","size":"0.18739300","price":"791.23000000","side":"buy","client_oid":"8a051ddd-b708-4bd5-bc5f-8364983fb63f","product_id":"BCH-USD","sequence":4839271797,"time":"2018-07-27T01:32:39.970000Z"}
{"type":"received","order_id":"cf2e0b8e-c61b-41b5-8a72-fb460d9c2f75","order_type":"limit","size":"0.20000000","price":"7893.00000000","side":"buy","client_oid":"b690bed9-4906-42a8-8a5d-886e89c8264b","product_id":"BTC-USD","sequence":6418130221,"time":"2018-07-27T01:32:39.973000Z"}
{"type":"open","side":"buy","price":"791.23000000","order_id":"25de55d9-5e02-49db-a19f-5499c96c5b67","remaining_size":"0.18739300","product_id":"BCH-USD","sequence":4839271798,"time":"2018-07-27T01:32:39.970000Z"}
{"type":"open","side":"buy","price":"7893.00000000","order_id":"cf2e0b8e-c61b-41b5-8a72-fb460d9c2f75","remaining_size":"0.20000000","product_id":"BTC-USD","sequence":6418130222,"time":"2018-07-27T01:32:39.973000Z"}
{"type":"done","side":"buy","order_id":"f383765b-729c-41cb-8e96-19d751ddd5ba","reason":"canceled","product_id":"BCH-USD","price":"791.23000000","remaining_size":"1.81488800","sequence":4839271799,"time":"2018-07-27T01:32:39.971000Z"}
{"type":"received","order_id":"add30fd7-bb17-4113-961d-80dfbebb33fb","order_type":"limit","size":"7.44874862","price":"83.38000000","side":"sell","client_oid":"6a1d841b-2a6f-41f6-8000-000087963ebd","product_id":"LTC-USD","sequence":2423271743,"time":"2018-07-27T01:32:39.973000Z"}
{"type":"done","side":"sell","order_id":"46a3d303-fbf7-4400-9a66-93f792659b5d","reason":"canceled","product_id":"BCH-USD","price":"795.25000000","remaining_size":"0.90000000","sequence":4839271800,"time":"2018-07-27T01:32:39.971000Z"}
{"type":"open","side":"sell","price":"83.38000000","order_id":"add30fd7-bb17-4113-961d-80dfbebb33fb","remaining_size":"7.44874862","product_id":"LTC-USD","sequence":2423271744,"time":"2018-07-27T01:32:39.973000Z"}
{"type":"done","side":"buy","order_id":"25de55d9-5e02-49db-a19f-5499c96c5b67","reason":"canceled","product_id":"BCH-USD","price":"791.23000000","remaining_size":"0.18739300","sequence":4839271801,"time":"2018-07-27T01:32:39.976000Z"}
{"type":"received","order_id":"6687e317-4133-4b48-aa42-7891bc05f3b8","order_type":"limit","size":"1.90000000","price":"795.27000000","side":"sell","client_oid":"74358003-fb78-4c13-9825-6442c64caaf6","product_id":"BCH-USD","sequence":4839271802,"time":"2018-07-27T01:32:39.977000Z"}
{"type":"open","side":"sell","price":"795.27000000","order_id":"6687e317-4133-4b48-aa42-7891bc05f3b8","remaining_size":"1.90000000","product_id":"BCH-USD","sequence":4839271803,"time":"2018-07-27T01:32:39.977000Z"}
{"type":"received","order_id":"19774039-d0a9-428f-a7f8-e5bdecd4677c","order_type":"limit","size":"1.90000000","price":"795.27000000","side":"sell","client_oid":"621fa85c-70cf-491f-8e5f-f959520b8ba6","product_id":"BCH-USD","sequence":4839271804,"time":"2018-07-27T01:32:39.978000Z"}
{"type":"open","side":"sell","price":"795.27000000","order_id":"19774039-d0a9-428f-a7f8-e5bdecd4677c","remaining_size":"1.90000000","product_id":"BCH-USD","sequence":4839271805,"time":"2018-07-27T01:32:39.978000Z"}
{"type":"done","side":"sell","order_id":"6687e317-4133-4b48-aa42-7891bc05f3b8","reason":"canceled","product_id":"BCH-USD","price":"795.27000000","remaining_size":"1.90000000","sequence":4839271806,"time":"2018-07-27T01:32:39.981000Z"}
{"type":"received","order_id":"7800316e-f0d8-42dd-bab6-2802a6b0c7b8","order_type":"limit","size":"0.18739300","price":"791.24000000","side":"buy","client_oid":"998df6f8-425a-45ed-b15a-0e1619fcfbba","product_id":"BCH-USD","sequence":4839271807,"time":"2018-07-27T01:32:39.984000Z"}
{"type":"open","side":"buy","price":"791.24000000","order_id":"7800316e-f0d8-42dd-bab6-2802a6b0c7b8","remaining_size":"0.18739300","product_id":"BCH-USD","sequence":4839271808,"time":"2018-07-27T01:32:39.984000Z"}
{"type":"received","order_id":"f56c2b36-6da9-42d6-a6d5-eb3519c70959","order_type":"limit","size":"1.81488800","price":"791.29000000","side":"buy","client_oid":"ea1c933f-6ae8-4699-b45c-f131fa61d0f3","product_id":"BCH-USD","sequence":4839271809,"time":"2018-07-27T01:32:39.986000Z"}
{"type":"open","side":"buy","price":"791.29000000","order_id":"f56c2b36-6da9-42d6-a6d5-eb3519c70959","remaining_size":"1.81488800","product_id":"BCH-USD","sequence":4839271810,"time":"2018-07-27T01:32:39.986000Z"}
{"type":"done","side":"buy","order_id":"f56c2b36-6da9-42d6-a6d5-eb3519c70959","reason":"canceled","product_id":"BCH-USD","price":"791.29000000","remaining_size":"1.81488800","sequence":4839271811,"time":"2018-07-27T01:32:39.990000Z"}
{"type":"received","order_id":"3ef17c02-75c0-43fa-9866-8e9e5b6a22e2","order_type":"limit","size":"0.90000000","price":"795.27000000","side":"sell","client_oid":"f5838c98-cef7-41ad-830f-21e686a7bcb5","product_id":"BCH-USD","sequence":4839271812,"time":"2018-07-27T01:32:39.991000Z"}
{"type":"open","side":"sell","price":"795.27000000","order_id":"3ef17c02-75c0-43fa-9866-8e9e5b6a22e2","remaining_size":"0.90000000","product_id":"BCH-USD","sequence":4839271813,"time":"2018-07-27T01:32:39.991000Z"}
{"type":"received","order_id":"d2efacc9-001b-4f35-97f0-d8e4b6b26d77","order_type":"limit","size":"7.44874862","price":"83.30000000","side":"sell","client_oid":"1e4b0900-3c28-4bdd-8000-0090edcfaaa8","product_id":"LTC-USD","sequence":2423271745,"time":"2018-07-27T01:32:39.995000Z"}
{"type":"done","side":"sell","order_id":"3cfda733-3bd0-468f-a84a-d7ba7df571bd","reason":"canceled","product_id":"BCH-USD","price":"795.26000000","remaining_size":"4.50000000","sequence":4839271814,"time":"2018-07-27T01:32:39.993000Z"}
{"type":"open","side":"sell","price":"83.30000000","order_id":"d2efacc9-001b-4f35-97f0-d8e4b6b26d77","remaining_size":"7.44874862","product_id":"LTC-USD","sequence":2423271746,"time":"2018-07-27T01:32:39.995000Z"}
{"type":"done","side":"buy","order_id":"7800316e-f0d8-42dd-bab6-2802a6b0c7b8","reason":"canceled","product_id":"BCH-USD","price":"791.24000000","remaining_size":"0.18739300","sequence":4839271815,"time":"2018-07-27T01:32:39.994000Z"}
{"type":"done","side":"sell","order_id":"19774039-d0a9-428f-a7f8-e5bdecd4677c","reason":"canceled","product_id":"BCH-USD","price":"795.27000000","remaining_size":"1.90000000","sequence":4839271816,"time":"2018-07-27T01:32:39.996000Z"}
{"type":"received","order_id":"22437628-07d2-4586-b0ac-e6c827fefe2c","order_type":"limit","size":"1.90000000","price":"795.25000000","side":"sell","client_oid":"d73e1e6e-327f-47fb-af0e-eb8f74834699","product_id":"BCH-USD","sequence":4839271817,"time":"2018-07-27T01:32:39.996000Z"}
{"type":"open","side":"sell","price":"795.25000000","order_id":"22437628-07d2-4586-b0ac-e6c827fefe2c","remaining_size":"1.90000000","product_id":"BCH-USD","sequence":4839271818,"time":"2018-07-27T01:32:39.996000Z"}
{"type":"received","order_id":"5d6abc63-ee06-42e7-b38b-914a78517126","order_type":"limit","size":"0.18361000","price":"790.16000000","side":"buy","client_oid":"1b6237da-4816-492e-a669-78f41ddd9673","product_id":"BCH-USD","sequence":4839271819,"time":"2018-07-27T01:32:39.998000Z"}
{"type":"open","side":"buy","price":"790.16000000","order_id":"5d6abc63-ee06-42e7-b38b-914a78517126","remaining_size":"0.18361000","product_id":"BCH-USD","sequence":4839271820,"time":"2018-07-27T01:32:39.998000Z"}
{"type":"done","side":"sell","order_id":"398d2ec1-06ed-4343-b072-8769e77e2dd2","reason":"canceled","product_id":"BCH-USD","price":"795.67000000","remaining_size":"4.50000000","sequence":4839271821,"time":"2018-07-27T01:32:39.999000Z"}
{"type":"received","order_id":"35c7ff43-8d67-4fdb-9174-b3c5aec43e40","order_type":"limit","size":"1.81488800","price":"791.24000000","side":"buy","client_oid":"41ffbbf7-7a35-461b-a35a-71d12e52eb59","product_id":"BCH-USD","sequence":4839271822,"time":"2018-07-27T01:32:40.001000Z"}
{"type":"open","side":"buy","price":"791.24000000","order_id":"35c7ff43-8d67-4fdb-9174-b3c5aec43e40","remaining_size":"1.81488800","product_id":"BCH-USD","sequence":4839271823,"time":"2018-07-27T01:32:40.001000Z"}
{"type":"received","order_id":"7eea5ef8-a64e-430c-9c7a-5e2d21065668","order_type":"limit","size":"4.50000000","price":"795.25000000","side":"sell","client_oid":"29b342f7-a0af-4753-a323-2f8c9de2b4f7","product_id":"BCH-USD","sequence":4839271824,"time":"2018-07-27T01:32:40.002000Z"}
{"type":"open","side":"sell","price":"795.25000000","order_id":"7eea5ef8-a64e-430c-9c7a-5e2d21065668","remaining_size":"4.50000000","product_id":"BCH-USD","sequence":4839271825,"time":"2018-07-27T01:32:40.002000Z"}
{"type":"done","side":"buy","order_id":"35c7ff43-8d67-4fdb-9174-b3c5aec43e40","reason":"canceled","product_id":"BCH-USD","price":"791.24000000","remaining_size":"1.81488800","sequence":4839271826,"time":"2018-07-27T01:32:40.005000Z"}
{"type":"done","side":"sell","order_id":"22437628-07d2-4586-b0ac-e6c827fefe2c","reason":"canceled","product_id":"BCH-USD","price":"795.25000000","remaining_size":"1.90000000","sequence":4839271827,"time":"2018-07-27T01:32:40.007000Z"}
{"type":"done","side":"sell","order_id":"7eea5ef8-a64e-430c-9c7a-5e2d21065668","reason":"canceled","product_id":"BCH-USD","price":"795.25000000","remaining_size":"4.50000000","sequence":4839271828,"time":"2018-07-27T01:32:40.007000Z"}
{"type":"done","side":"sell","order_id":"3ef17c02-75c0-43fa-9866-8e9e5b6a22e2","reason":"canceled","product_id":"BCH-USD","price":"795.27000000","remaining_size":"0.90000000","sequence":4839271829,"time":"2018-07-27T01:32:40.009000Z"}
{"type":"received","order_id":"e47739e2-8d1c-4d02-9737-170183e3b055","order_type":"limit","size":"4.50000000","price":"795.53000000","side":"sell","client_oid":"f80fe316-b643-4031-bc3c-b5d3cf69f3e1","product_id":"BCH-USD","sequence":4839271830,"time":"2018-07-27T01:32:40.009000Z"}
{"type":"open","side":"sell","price":"795.53000000","order_id":"e47739e2-8d1c-4d02-9737-170183e3b055","remaining_size":"4.50000000","product_id":"BCH-USD","sequence":4839271831,"time":"2018-07-27T01:32:40.009000Z"}
{"type":"received","order_id":"b61d0143-d8b9-41ca-956c-503b7c7916f1","order_type":"limit","size":"2.00000000","price":"792.80000000","side":"buy","client_oid":"053c29f5-1ec5-46dd-a7e7-2d54214ad0ae","product_id":"BCH-USD","sequence":4839271832,"time":"2018-07-27T01:32:40.011000Z"}
{"type":"open","side":"buy","price":"792.80000000","order_id":"b61d0143-d8b9-41ca-956c-503b7c7916f1","remaining_size":"2.00000000","product_id":"BCH-USD","sequence":4839271833,"time":"2018-07-27T01:32:40.011000Z"}
{"type":"received","order_id":"0e66ca08-ff0a-4239-a069-e4311758f37e","order_type":"limit","size":"0.18739300","price":"791.23000000","side":"buy","client_oid":"dcd758d5-a7a4-4210-8369-4d54b52ef8d0","product_id":"BCH-USD","sequence":4839271834,"time":"2018-07-27T01:32:40.013000Z"}
{"type":"open","side":"buy","price":"791.23000000","order_id":"0e66ca08-ff0a-4239-a069-e4311758f37e","remaining_size":"0.18739300","product_id":"BCH-USD","sequence":4839271835,"time":"2018-07-27T01:32:40.013000Z"}
{"type":"received","order_id":"9ef79946-9a0f-4d0a-b81f-9c146f8b2674","order_type":"limit","size":"1.90000000","price":"795.27000000","side":"sell","client_oid":"b6544613-2dcc-4391-88de-7a864b903a1c","product_id":"BCH-USD","sequence":4839271836,"time":"2018-07-27T01:32:40.015000Z"}
{"type":"open","side":"sell","price":"795.27000000","order_id":"9ef79946-9a0f-4d0a-b81f-9c146f8b2674","remaining_size":"1.90000000","product_id":"BCH-USD","sequence":4839271837,"time":"2018-07-27T01:32:40.015000Z"}
{"type":"received","order_id":"a39d3607-04b7-42f2-beb2-3c04ad094d00","order_type":"limit","size":"0.17515900","price":"789.92000000","side":"buy","client_oid":"63b691bb-51a6-482e-a5b1-b37d82223eba","product_id":"BCH-USD","sequence":4839271838,"time":"2018-07-27T01:32:40.016000Z"}
{"type":"open","side":"buy","price":"789.92000000","order_id":"a39d3607-04b7-42f2-beb2-3c04ad094d00","remaining_size":"0.17515900","product_id":"BCH-USD","sequence":4839271839,"time":"2018-07-27T01:32:40.016000Z"}
{"type":"done","side":"sell","order_id":"add30fd7-bb17-4113-961d-80dfbebb33fb","reason":"canceled","product_id":"LTC-USD","price":"83.38000000","remaining_size":"7.44874862","sequence":2423271747,"time":"2018-07-27T01:32:40.018000Z"}
{"type":"received","order_id":"d1644032-6e74-41c1-a8b9-d28ee50135ea","order_type":"limit","size":"4.50000000","price":"795.27000000","side":"sell","client_oid":"7b020b98-ef9c-4fc2-809e-9d34aa1c507c","product_id":"BCH-USD","sequence":4839271840,"time":"2018-07-27T01:32:40.018000Z"}
{"type":"open","side":"sell","price":"795.27000000","order_id":"d1644032-6e74-41c1-a8b9-d28ee50135ea","remaining_size":"4.50000000","product_id":"BCH-USD","sequence":4839271841,"time":"2018-07-27T01:32:40.018000Z"}
{"type":"done","side":"sell","order_id":"9ef79946-9a0f-4d0a-b81f-9c146f8b2674","reason":"canceled","product_id":"BCH-USD","price":"795.27000000","remaining_size":"1.90000000","sequence":4839271842,"time":"2018-07-27T01:32:40.020000Z"}
{"type":"received","order_id":"8e5ee1ad-fd02-4fcd-a828-65d57deea143","order_type":"limit","size":"0.14525900","price":"789.20000000","side":"buy","client_oid":"1ebc0270-95d6-483b-98ad-983569d692a8","product_id":"BCH-USD","sequence":4839271843,"time":"2018-07-27T01:32:40.024000Z"}
{"type":"open","side":"buy","price":"789.20000000","order_id":"8e5ee1ad-fd02-4fcd-a828-65d57deea143","remaining_size":"0.14525900","product_id":"BCH-USD","sequence":4839271844,"time":"2018-07-27T01:32:40.024000Z"}
{"type":"done","side":"sell","order_id":"d1644032-6e74-41c1-a8b9-d28ee50135ea","reason":"canceled","product_id":"BCH-USD","price":"795.27000000","remaining_size":"4.50000000","sequence":4839271845,"time":"2018-07-27T01:32:40.025000Z"}
{"type":"received","order_id":"bf5775dd-3ac8-4497-9a60-9f994d53734b","order_type":"limit","size":"1.90000000","price":"795.25000000","side":"sell","client_oid":"4ed99d18-3ae4-452f-8f3e-7e87abeea075","product_id":"BCH-USD","sequence":4839271846,"time":"2018-07-27T01:32:40.025000Z"}
{"type":"open","side":"sell","price":"795.25000000","order_id":"bf5775dd-3ac8-4497-9a60-9f994d53734b","remaining_size":"1.90000000","product_id":"BCH-USD","sequence":4839271847,"time":"2018-07-27T01:32:40.025000Z"}
{"type":"received","order_id":"4081ac8f-87c2-4c0b-a207-c5048476d0a0","order_type":"limit","size":"0.90000000","price":"795.25000000","side":"sell","client_oid":"f58540fb-f578-43a4-9ee0-66b0f5122b41","product_id":"BCH-USD","sequence":4839271848,"time":"2018-07-27T01:32:40.026000Z"}
{"type":"open","side":"sell","price":"795.25000000","order_id":"4081ac8f-87c2-4c0b-a207-c5048476d0a0","remaining_size":"0.90000000","product_id":"BCH-USD","sequence":4839271849,"time":"2018-07-27T01:32:40.026000Z"}
{"type":"received","order_id":"30426dc2-f1de-4f7a-be2c-bca55da63247","order_type":"limit","size":"1.81488800","price":"791.23000000","side":"buy","client_oid":"05859828-8387-43b8-960f-adf1e95266cc","product_id":"BCH-USD","sequence":4839271850,"time":"2018-07-27T01:32:40.027000Z"}
{"type":"open","side":"buy","price":"791.23000000","order_id":"30426dc2-f1de-4f7a-be2c-bca55da63247","remaining_size":"1.81488800","product_id":"BCH-USD","sequence":4839271851,"time":"2018-07-27T01:32:40.027000Z"}
{"type":"received","order_id":"89f39fb1-922b-41fe-9d8b-8381dab072f6","order_type":"limit","size":"1.90000000","price":"795.24000000","side":"sell","client_oid":"798b8319-a654-462a-a2ca-5009dd418702","product_id":"BCH-USD","sequence":4839271852,"time":"2018-07-27T01:32:40.031000Z"}
{"type":"open","side":"sell","price":"795.24000000","order_id":"89f39fb1-922b-41fe-9d8b-8381dab072f6","remaining_size":"1.90000000","product_id":"BCH-USD","sequence":4839271853,"time":"2018-07-27T01:32:40.031000Z"}
{"type":"received","order_id":"33f3384b-f484-4878-98ea-a82523c40963","order_type":"limit","size":"7.44874862","price":"83.34000000","side":"sell","client_oid":"dcb2e0b0-1fd4-45a7-8000-001a36d8b7b0","product_id":"LTC-USD","sequence":2423271748,"time":"2018-07-27T01:32:40.034000Z"}
{"type":"open","side":"sell","price":"83.34000000","order_id":"33f3384b-f484-4878-98ea-a82523c40963","remaining_size":"7.44874862","product_id":"LTC-USD","sequence":2423271749,"time":"2018-07-27T01:32:40.034000Z"}
{"type":"received","order_id":"681c1b88-551d-4fe7-bc93-6b15120ba465","order_type":"limit","size":"0.25147200","price":"788.72000000","side":"buy","client_oid":"eeaab42a-3a8a-44fe-aa25-d5f22f07d749","product_id":"BCH-USD","sequence":4839271854,"time":"2018-07-27T01:32:40.035000Z"}
{"type":"open","side":"buy","price":"788.72000000","order_id":"681c1b88-551d-4fe7-bc93-6b15120ba465","remaining_size":"0.25147200","product_id":"BCH-USD","sequence":4839271855,"time":"2018-07-27T01:32:40.035000Z"}
{"type":"received","order_id":"6b56865d-9384-4e5b-b266-8de2667d74f3","order_type":"limit","size":"4.50000000","price":"795.26000000","side":"sell","client_oid":"bd7e1e2f-8cd9-45c4-ab7e-da22e91a1e83","product_id":"BCH-USD","sequence":4839271856,"time":"2018-07-27T01:32:40.035000Z"}
{"type":"open","side":"sell","price":"795.26000000","order_id":"6b56865d-9384-4e5b-b266-8de2667d74f3","remaining_size":"4.50000000","product_id":"BCH-USD","sequence":4839271857,"time":"2018-07-27T01:32:40.035000Z"}
{"type":"done","side":"sell","order_id":"4081ac8f-87c2-4c0b-a207-c5048476d0a0","reason":"canceled","product_id":"BCH-USD","price":"795.25000000","remaining_size":"0.90000000","sequence":4839271858,"time":"2018-07-27T01:32:40.036000Z"}
{"type":"done","side":"sell","order_id":"6b56865d-9384-4e5b-b266-8de2667d74f3","reason":"canceled","product_id":"BCH-USD","price":"795.26000000","remaining_size":"4.50000000","sequence":4839271859,"time":"2018-07-27T01:32:40.038000Z"}
{"type":"done","side":"sell","order_id":"e47739e2-8d1c-4d02-9737-170183e3b055","reason":"canceled","product_id":"BCH-USD","price":"795.53000000","remaining_size":"4.50000000","sequence":4839271860,"time":"2018-07-27T01:32:40.040000Z"}
{"type":"done","side":"buy","order_id":"0e66ca08-ff0a-4239-a069-e4311758f37e","reason":"canceled","product_id":"BCH-USD","price":"791.23000000","remaining_size":"0.18739300","sequence":4839271861,"time":"2018-07-27T01:32:40.042000Z"}
{"type":"done","side":"sell","order_id":"bf5775dd-3ac8-4497-9a60-9f994d53734b","reason":"canceled","product_id":"BCH-USD","price":"795.25000000","remaining_size":"1.90000000","sequence":4839271862,"time":"2018-07-27T01:32:40.044000Z"}
{"type":"received","order_id":"4ac408c0-894d-49fa-9b80-1991c72dc616","order_type":"limit","size":"0.90000000","price":"795.27000000","side":"sell","client_oid":"606af773-4ad7-4c98-aafe-d4801959b11c","product_id":"BCH-USD","sequence":4839271863,"time":"2018-07-27T01:32:40.045000Z"}
{"type":"open","side":"sell","price":"795.27000000","order_id":"4ac408c0-894d-49fa-9b80-1991c72dc616","remaining_size":"0.90000000","product_id":"BCH-USD","sequence":4839271864,"time":"2018-07-27T01:32:40.045000Z"}
{"type":"received","order_id":"dccd4001-1950-4eed-a9db-b0a88b02c030","order_type":"limit","size":"4.50000000","price":"795.24000000","side":"sell","client_oid":"629aa90f-3811-4e3a-baf4-80dcb7ae7f6d","product_id":"BCH-USD","sequence":4839271865,"time":"2018-07-27T01:32:40.045000Z"}
{"type":"open","side":"sell","price":"795.24000000","order_id":"dccd4001-1950-4eed-a9db-b0a88b02c030","remaining_size":"4.50000000","product_id":"BCH-USD","sequence":4839271866,"time":"2018-07-27T01:32:40.045000Z"}
{"type":"received","order_id":"8fa08d0f-62e2-469d-a061-ec0e98b87343","order_type":"limit","size":"4.50000000","price":"795.60000000","side":"sell","client_oid":"a904210e-b621-4f32-93ec-6892b7496a98","product_id":"BCH-USD","sequence":4839271867,"time":"2018-07-27T01:32:40.047000Z"}
{"type":"open","side":"sell","price":"795.60000000","order_id":"8fa08d0f-62e2-469d-a061-ec0e98b87343","remaining_size":"4.50000000","product_id":"BCH-USD","sequence":4839271868,"time":"2018-07-27T01:32:40.047000Z"}
{"type":"received","order_id":"b0ba4858-e1c7-428b-bd15-b2e22525e85a","order_type":"limit","size":"0.33012600","price":"788.48000000","side":"buy","client_oid":"36bc8974-ddd4-46fc-a97a-2a64c6ff48cb","product_id":"BCH-USD","sequence":4839271869,"time":"2018-07-27T01:32:40.047000Z"}
{"type":"open","side":"buy","price":"788.48000000","order_id":"b0ba4858-e1c7-428b-bd15-b2e22525e85a","remaining_size":"0.33012600","product_id":"BCH-USD","sequence":4839271870,"time":"2018-07-27T01:32:40.047000Z"}
{"type":"received","order_id":"e4579a80-a44c-4891-9f66-6c192b8faca4","order_type":"limit","size":"0.18739300","price":"791.24000000","side":"buy","client_oid":"d6313591-cb5c-46ca-9d43-be9784d63df6","product_id":"BCH-USD","sequence":4839271871,"time":"2018-07-27T01:32:40.049000Z"}
{"type":"open","side":"buy","price":"791.24000000","order_id":"e4579a80-a44c-4891-9f66-6c192b8faca4","remaining_size":"0.18739300","product_id":"BCH-USD","sequence":4839271872,"time":"2018-07-27T01:32:40.049000Z"}
{"type":"done","side":"sell","order_id":"89f39fb1-922b-41fe-9d8b-8381dab072f6","reason":"canceled","product_id":"BCH-USD","price":"795.24000000","remaining_size":"1.90000000","sequence":4839271873,"time":"2018-07-27T01:32:40.055000Z"}
{"type":"received","order_id":"cea16425-eafb-45ab-975a-9d4d0c732a24","order_type":"limit","size":"1.90000000","price":"795.27000000","side":"sell","client_oid":"a77d5620-aa61-49e0-9ba8-2e84429a86f3","product_id":"BCH-USD","sequence":4839271874,"time":"2018-07-27T01:32:40.058000Z"}
{"type":"open","side":"sell","price":"795.27000000","order_id":"cea16425-eafb-45ab-975a-9d4d0c732a24","remaining_size":"1.90000000","product_id":"BCH-USD","sequence":4839271875,"time":"2018-07-27T01:32:40.058000Z"}
{"type":"received","order_id":"79faebc6-d4d6-4b80-9c08-68e5471935a2","order_type":"limit","size":"0.01000000","price":"788.29000000","side":"buy","client_oid":"e4cb18dd-2267-4d20-b03d-63ee5dc378c5","product_id":"BCH-USD","sequence":4839271876,"time":"2018-07-27T01:32:40.058000Z"}
{"type":"open","side":"buy","price":"788.29000000","order_id":"79faebc6-d4d6-4b80-9c08-68e5471935a2","remaining_size":"0.01000000","product_id":"BCH-USD","sequence":4839271877,"time":"2018-07-27T01:32:40.058000Z"}
{"type":"done","side":"sell","order_id":"dccd4001-1950-4eed-a9db-b0a88b02c030","reason":"canceled","product_id":"BCH-USD","price":"795.24000000","remaining_size":"4.50000000","sequence":4839271878,"time":"2018-07-27T01:32:40.058000Z"}
{"type":"received","order_id":"3ef84671-a20d-47b1-b45f-6ed6199401dd","order_type":"limit","size":"3.86955600","price":"788.24000000","side":"buy","client_oid":"a52e3df8-3378-4c20-b9ad-f3f45a85604c","product_id":"BCH-USD","sequence":4839271879,"time":"2018-07-27T01:32:40.060000Z"}
{"type":"open","side":"buy","price":"788.24000000","order_id":"3ef84671-a20d-47b1-b45f-6ed6199401dd","remaining_size":"3.86955600","product_id":"BCH-USD","sequence":4839271880,"time":"2018-07-27T01:32:40.060000Z"}
{"type":"done","side":"sell","order_id":"4ac408c0-894d-49fa-9b80-1991c72dc616","reason":"canceled","product_id":"BCH-USD","price":"795.27000000","remaining_size":"0.90000000","sequence":4839271881,"time":"2018-07-27T01:32:40.062000Z"}
{"type":"done","side":"sell","order_id":"cea16425-eafb-45ab-975a-9d4d0c732a24","reason":"canceled","product_id":"BCH-USD","price":"795.27000000","remaining_size":"1.90000000","sequence":4839271882,"time":"2018-07-27T01:32:40.062000Z"}
{"type":"done","side":"sell","order_id":"8fa08d0f-62e2-469d-a061-ec0e98b87343","reason":"canceled","product_id":"BCH-USD","price":"795.60000000","remaining_size":"4.50000000","sequence":4839271883,"time":"2018-07-27T01:32:40.062000Z"}
{"type":"received","order_id":"618fccb4-6c5d-4cb3-981d-bd9940bd4c8d","order_type":"limit","size":"1.90000000","price":"795.27000000","side":"sell","client_oid":"1c9dfaef-706e-4658-9e6b-090a73b1f051","product_id":"BCH-USD","sequence":4839271884,"time":"2018-07-27T01:32:40.062000Z"}
{"type":"open","side":"sell","price":"795.27000000","order_id":"618fccb4-6c5d-4cb3-981d-bd9940bd4c8d","remaining_size":"1.90000000","product_id":"BCH-USD","sequence":4839271885,"time":"2018-07-27T01:32:40.062000Z"}
{"type":"done","side":"buy","order_id":"30426dc2-f1de-4f7a-be2c-bca55da63247","reason":"canceled","product_id":"BCH-USD","price":"791.23000000","remaining_size":"1.81488800","sequence":4839271886,"time":"2018-07-27T01:32:40.065000Z"}
{"type":"received","order_id":"cde5ccbc-5cf9-4b35-83fa-a3da2d4ea49c","order_type":"limit","size":"4.50000000","price":"795.27000000","side":"sell","client_oid":"37c63b3e-4b84-478e-adc4-078a867b62c9","product_id":"BCH-USD","sequence":4839271887,"time":"2018-07-27T01:32:40.066000Z"}
{"type":"open","side":"sell","price":"795.27000000","order_id":"cde5ccbc-5cf9-4b35-83fa-a3da2d4ea49c","remaining_size":"4.50000000","product_id":"BCH-USD","sequence":4839271888,"time":"2018-07-27T01:32:40.066000Z"}
{"type":"done","side":"sell","order_id":"618fccb4-6c5d-4cb3-981d-bd9940bd4c8d","reason":"canceled","product_id":"BCH-USD","price":"795.27000000","remaining_size":"1.90000000","sequence":4839271889,"time":"2018-07-27T01:32:40.068000Z"}
{"type":"done","side":"sell","order_id":"cde5ccbc-5cf9-4b35-83fa-a3da2d4ea49c","reason":"canceled","product_id":"BCH-USD","price":"795.27000000","remaining_size":"4.50000000","sequence":4839271890,"time":"2018-07-27T01:32:40.070000Z"}
{"type":"received","order_id":"181c427b-284f-4371-a12c-31bee6c09a33","order_type":"limit","size":"1.81488800","price":"791.24000000","side":"buy","client_oid":"f21da6f9-deda-4b10-ac16-6bd62e915138","product_id":"BCH-USD","sequence":4839271891,"time":"2018-07-27T01:32:40.073000Z"}
{"type":"open","side":"buy","price":"791.24000000","order_id":"181c427b-284f-4371-a12c-31bee6c09a33","remaining_size":"1.81488800","product_id":"BCH-USD","sequence":4839271892,"time":"2018-07-27T01:32:40.073000Z"}
{"type":"received","order_id":"78aaad2b-ee51-4b38-a3a0-7f07bed38ecf","order_type":"limit","size":"0.90000000","price":"795.24000000","side":"sell","client_oid":"7b236c15-2bc5-49f4-a85a-776fb69df18e","product_id":"BCH-USD","sequence":4839271893,"time":"2018-07-27T01:32:40.073000Z"}
{"type":"open","side":"sell","price":"795.24000000","order_id":"78aaad2b-ee51-4b38-a3a0-7f07bed38ecf","remaining_size":"0.90000000","product_id":"BCH-USD","sequence":4839271894,"time":"2018-07-27T01:32:40.073000Z"}
{"type":"received","order_id":"eae85e96-7242-40fe-8403-9cf313e2bccb","order_type":"limit","size":"1.90000000","price":"795.26000000","side":"sell","client_oid":"8d743d3c-7d4f-46b0-8995-e8ba9561d869","product_id":"BCH-USD","sequence":4839271895,"time":"2018-07-27T01:32:40.075000Z"}
{"type":"open","side":"sell","price":"795.26000000","order_id":"eae85e96-7242-40fe-8403-9cf313e2bccb","remaining_size":"1.90000000","product_id":"BCH-USD","sequence":4839271896,"time":"2018-07-27T01:32:40.075000Z"}
{"type":"received","order_id":"aed278bb-c70b-4174-b4f7-af2f63b05141","order_type":"limit","size":"1.90000000","price":"795.24000000","side":"sell","client_oid":"ec973ba3-bfa9-4b60-b6b0-2ac36a923743","product_id":"BCH-USD","sequence":4839271897,"time":"2018-07-27T01:32:40.076000Z"}
{"type":"open","side":"sell","price":"795.24000000","order_id":"aed278bb-c70b-4174-b4f7-af2f63b05141","remaining_size":"1.90000000","product_id":"BCH-USD","sequence":4839271898,"time":"2018-07-27T01:32:40.076000Z"}
{"type":"received","order_id":"4967482d-8263-4d96-8294-09c5265bb4f4","order_type":"limit","size":"4.50000000","price":"795.26000000","side":"sell","client_oid":"f54f80dc-b98c-4180-bded-38d963f19082","product_id":"BCH-USD","sequence":4839271899,"time":"2018-07-27T01:32:40.078000Z"}
{"type":"open","side":"sell","price":"795.26000000","order_id":"4967482d-8263-4d96-8294-09c5265bb4f4","remaining_size":"4.50000000","product_id":"BCH-USD","sequence":4839271900,"time":"2018-07-27T01:32:40.078000Z"}
{"type":"received","order_id":"4c043e9f-f652-49cd-bc15-e1e25f17dfe6","order_type":"limit","size":"4.50000000","price":"795.53000000","side":"sell","client_oid":"a2751ffe-44d6-4ebf-8571-8448954044bd","product_id":"BCH-USD","sequence":4839271901,"time":"2018-07-27T01:32:40.079000Z"}
{"type":"open","side":"sell","price":"795.53000000","order_id":"4c043e9f-f652-49cd-bc15-e1e25f17dfe6","remaining_size":"4.50000000","product_id":"BCH-USD","sequence":4839271902,"time":"2018-07-27T01:32:40.079000Z"}
{"type":"done","side":"sell","order_id":"eae85e96-7242-40fe-8403-9cf313e2bccb","reason":"canceled","product_id":"BCH-USD","price":"795.26000000","remaining_size":"1.90000000","sequence":4839271903,"time":"2018-07-27T01:32:40.079000Z"}
{"type":"done","side":"sell","order_id":"4967482d-8263-4d96-8294-09c5265bb4f4","reason":"canceled","product_id":"BCH-USD","price":"795.26000000","remaining_size":"4.50000000","sequence":4839271904,"time":"2018-07-27T01:32:40.081000Z"}
{"type":"done","side":"buy","order_id":"e4579a80-a44c-4891-9f66-6c192b8faca4","reason":"canceled","product_id":"BCH-USD","price":"791.24000000","remaining_size":"0.18739300","sequence":4839271905,"time":"2018-07-27T01:32:40.084000Z"}
{"type":"received","order_id":"2ad047c3-aad9-4ebe-a3f3-d801d52becde","order_type":"limit","size":"1.90000000","price":"795.27000000","side":"sell","client_oid":"5f259d27-6098-4d68-87fa-62d99d806397","product_id":"BCH-USD","sequence":4839271906,"time":"2018-07-27T01:32:40.086000Z"}
{"type":"open","side":"sell","price":"795.27000000","order_id":"2ad047c3-aad9-4ebe-a3f3-d801d52becde","remaining_size":"1.90000000","product_id":"BCH-USD","sequence":4839271907,"time":"2018-07-27T01:32:40.086000Z"}
{"type":"done","side":"sell","order_id":"aed278bb-c70b-4174-b4f7-af2f63b05141","reason":"canceled","product_id":"BCH-USD","price":"795.24000000","remaining_size":"1.90000000","sequence":4839271908,"time":"2018-07-27T01:32:40.087000Z"}
{"type":"done","side":"sell","order_id":"78aaad2b-ee51-4b38-a3a0-7f07bed38ecf","reason":"canceled","product_id":"BCH-USD","price":"795.24000000","remaining_size":"0.90000000","sequence":4839271909,"time":"2018-07-27T01:32:40.087000Z"}
{"type":"received","order_id":"c3c44a45-f34c-4bbf-9278-1c3dc32974e7","order_type":"limit","size":"7.07900000","price":"795.18000000","side":"sell","product_id":"BCH-USD","sequence":4839271910,"time":"2018-07-27T01:32:40.089000Z"}
{"type":"open","side":"sell","price":"795.18000000","order_id":"c3c44a45-f34c-4bbf-9278-1c3dc32974e7","remaining_size":"7.07900000","product_id":"BCH-USD","sequence":4839271911,"time":"2018-07-27T01:32:40.089000Z"}
{"type":"received","order_id":"3fd85a91-fd98-4cb0-9a3c-d9ba12df7773","order_type":"limit","size":"4.50000000","price":"795.27000000","side":"sell","client_oid":"4febf5d5-a739-44b6-b103-c34772d1b90a","product_id":"BCH-USD","sequence":4839271912,"time":"2018-07-27T01:32:40.092000Z"}
{"type":"open","side":"sell","price":"795.27000000","order_id":"3fd85a91-fd98-4cb0-9a3c-d9ba12df7773","remaining_size":"4.50000000","product_id":"BCH-USD","sequence":4839271913,"time":"2018-07-27T01:32:40.092000Z"}
{"type":"done","side":"sell","order_id":"2ad047c3-aad9-4ebe-a3f3-d801d52becde","reason":"canceled","product_id":"BCH-USD","price":"795.27000000","remaining_size":"1.90000000","sequence":4839271914,"time":"2018-07-27T01:32:40.092000Z"}
{"type":"received","order_id":"483abd43-6faa-4db7-8716-146c52c5e49a","order_type":"limit","size":"0.90000000","price":"795.23000000","side":"sell","client_oid":"656b40e9-2683-4c81-a5dc-b07ee897d850","product_id":"BCH-USD","sequence":4839271915,"time":"2018-07-27T01:32:40.094000Z"}
{"type":"open","side":"sell","price":"795.23000000","order_id":"483abd43-6faa-4db7-8716-146c52c5e49a","remaining_size":"0.90000000","product_id":"BCH-USD","sequence":4839271916,"time":"2018-07-27T01:32:40.094000Z"}
{"type":"received","order_id":"43a34e25-6c1e-4b68-917a-7378ffedee0e","order_type":"limit","size":"1.90000000","price":"795.23000000","side":"sell","client_oid":"57fcb43e-bd71-405e-b4fc-377b9bfe975a","product_id":"BCH-USD","sequence":4839271917,"time":"2018-07-27T01:32:40.097000Z"}
{"type":"open","side":"sell","price":"795.23000000","order_id":"43a34e25-6c1e-4b68-917a-7378ffedee0e","remaining_size":"1.90000000","product_id":"BCH-USD","sequence":4839271918,"time":"2018-07-27T01:32:40.097000Z"}
{"type":"received","order_id":"31e4a2ba-3ec4-433e-accf-375095bde0b7","order_type":"limit","size":"0.18739300","price":"791.23000000","side":"buy","client_oid":"783b61eb-1d2c-4afe-ac47-2b91ff15cb6a","product_id":"BCH-USD","sequence":4839271919,"time":"2018-07-27T01:32:40.100000Z"}
{"type":"open","side":"buy","price":"791.23000000","order_id":"31e4a2ba-3ec4-433e-accf-375095bde0b7","remaining_size":"0.18739300","product_id":"BCH-USD","sequence":4839271920,"time":"2018-07-27T01:32:40.100000Z"}
{"type":"done","side":"sell","order_id":"483abd43-6faa-4db7-8716-146c52c5e49a","reason":"canceled","product_id":"BCH-USD","price":"795.23000000","remaining_size":"0.90000000","sequence":4839271921,"time":"2018-07-27T01:32:40.101000Z"}
{"type":"done","side":"sell","order_id":"43a34e25-6c1e-4b68-917a-7378ffedee0e","reason":"canceled","product_id":"BCH-USD","price":"795.23000000","remaining_size":"1.90000000","sequence":4839271922,"time":"2018-07-27T01:32:40.102000Z"}
{"type":"done","side":"buy","order_id":"31e4a2ba-3ec4-433e-accf-375095bde0b7","reason":"canceled","product_id":"BCH-USD","price":"791.23000000","remaining_size":"0.18739300","sequence":4839271923,"time":"2018-07-27T01:32:40.104000Z"}
{"type":"received","order_id":"0e30e55d-5d04-4e7a-8f75-f1103b1b622d","order_type":"limit","size":"1.90000000","price":"795.23000000","side":"sell","client_oid":"f31b2a18-f50a-4c81-aa58-31b74bbd0928","product_id":"BCH-USD","sequence":4839271924,"time":"2018-07-27T01:32:40.108000Z"}
{"type":"open","side":"sell","price":"795.23000000","order_id":"0e30e55d-5d04-4e7a-8f75-f1103b1b622d","remaining_size":"1.90000000","product_id":"BCH-USD","sequence":4839271925,"time":"2018-07-27T01:32:40.108000Z"}
{"type":"done","side":"buy","order_id":"181c427b-284f-4371-a12c-31bee6c09a33","reason":"canceled","product_id":"BCH-USD","price":"791.24000000","remaining_size":"1.81488800","sequence":4839271926,"time":"2018-07-27T01:32:40.108000Z"}
{"type":"done","side":"sell","order_id":"0e30e55d-5d04-4e7a-8f75-f1103b1b622d","reason":"canceled","product_id":"BCH-USD","price":"795.23000000","remaining_size":"1.90000000","sequence":4839271927,"time":"2018-07-27T01:32:40.112000Z"}
{"type":"done","side":"sell","order_id":"4c043e9f-f652-49cd-bc15-e1e25f17dfe6","reason":"canceled","product_id":"BCH-USD","price":"795.53000000","remaining_size":"4.50000000","sequence":4839271928,"time":"2018-07-27T01:32:40.113000Z"}
{"type":"done","side":"sell","order_id":"3fd85a91-fd98-4cb0-9a3c-d9ba12df7773","reason":"canceled","product_id":"BCH-USD","price":"795.27000000","remaining_size":"4.50000000","sequence":4839271929,"time":"2018-07-27T01:32:40.128000Z"}
{"type":"received","order_id":"a0b1775c-00b2-4481-840e-15d23ae48acb","order_type":"limit","size":"0.90000000","price":"795.27000000","side":"sell","client_oid":"588f6616-1ffb-4ca9-a0f0-65c03380b18b","product_id":"BCH-USD","sequence":4839271930,"time":"2018-07-27T01:32:40.151000Z"}
{"type":"open","side":"sell","price":"795.27000000","order_id":"a0b1775c-00b2-4481-840e-15d23ae48acb","remaining_size":"0.90000000","product_id":"BCH-USD","sequence":4839271931,"time":"2018-07-27T01:32:40.151000Z"}
{"type":"done","side":"sell","order_id":"a0b1775c-00b2-4481-840e-15d23ae48acb","reason":"canceled","product_id":"BCH-USD","price":"795.27000000","remaining_size":"0.90000000","sequence":4839271932,"time":"2018-07-27T01:32:40.155000Z"}
{"type":"received","order_id":"a28db63b-8fdb-45b5-baef-c661d0452284","order_type":"limit","size":"0.18739300","price":"791.25000000","side":"buy","client_oid":"054dc7e9-1c37-4862-8894-763c0aac3afb","product_id":"BCH-USD","sequence":4839271933,"time":"2018-07-27T01:32:40.156000Z"}
{"type":"open","side":"buy","price":"791.25000000","order_id":"a28db63b-8fdb-45b5-baef-c661d0452284","remaining_size":"0.18739300","product_id":"BCH-USD","sequence":4839271934,"time":"2018-07-27T01:32:40.156000Z"}
{"type":"received","order_id":"74ed58a7-9bb2-4b4f-82a7-3ef6a7a7b34f","order_type":"limit","size":"1.90000000","price":"795.27000000","side":"sell","client_oid":"6f54c2ed-256e-4009-bdd2-66129d6b921b","product_id":"BCH-USD","sequence":4839271935,"time":"2018-07-27T01:32:40.156000Z"}
{"type":"open","side":"sell","price":"795.27000000","order_id":"74ed58a7-9bb2-4b4f-82a7-3ef6a7a7b34f","remaining_size":"1.90000000","product_id":"BCH-USD","sequence":4839271936,"time":"2018-07-27T01:32:40.156000Z"}
{"type":"received","order_id":"286994eb-e6ef-4e13-a7e6-d6454892e984","order_type":"limit","size":"1.81488800","price":"791.25000000","side":"buy","client_oid":"b4967dc5-0ec9-4446-8893-8b4c250cb7c0","product_id":"BCH-USD","sequence":4839271937,"time":"2018-07-27T01:32:40.160000Z"}
{"type":"open","side":"buy","price":"791.25000000","order_id":"286994eb-e6ef-4e13-a7e6-d6454892e984","remaining_size":"1.81488800","product_id":"BCH-USD","sequence":4839271938,"time":"2018-07-27T01:32:40.160000Z"}
{"type":"done","side":"buy","order_id":"a28db63b-8fdb-45b5-baef-c661d0452284","reason":"canceled","product_id":"BCH-USD","price":"791.25000000","remaining_size":"0.18739300","sequence":4839271939,"time":"2018-07-27T01:32:40.160000Z"}
{"type":"done","side":"sell","order_id":"74ed58a7-9bb2-4b4f-82a7-3ef6a7a7b34f","reason":"canceled","product_id":"BCH-USD","price":"795.27000000","remaining_size":"1.90000000","sequence":4839271940,"time":"2018-07-27T01:32:40.161000Z"}
{"type":"received","order_id":"6638e0bd-5c71-402f-9d5f-768f92843059","order_type":"limit","size":"4.50000000","price":"795.60000000","side":"sell","client_oid":"dd0adf2a-9361-47f2-817d-104cd0e197ba","product_id":"BCH-USD","sequence":4839271941,"time":"2018-07-27T01:32:40.163000Z"}
{"type":"open","side":"sell","price":"795.60000000","order_id":"6638e0bd-5c71-402f-9d5f-768f92843059","remaining_size":"4.50000000","product_id":"BCH-USD","sequence":4839271942,"time":"2018-07-27T01:32:40.163000Z"}
{"type":"received","order_id":"d640447e-17be-4a67-b82d-1e9e7032cb8b","order_type":"limit","size":"1.90000000","price":"795.17000000","side":"sell","client_oid":"3a249d86-9efc-4b4a-b9e1-3ab049acd933","product_id":"BCH-USD","sequence":4839271943,"time":"2018-07-27T01:32:40.163000Z"}
{"type":"open","side":"sell","price":"795.17000000","order_id":"d640447e-17be-4a67-b82d-1e9e7032cb8b","remaining_size":"1.90000000","product_id":"BCH-USD","sequence":4839271944,"time":"2018-07-27T01:32:40.163000Z"}
{"type":"done","side":"buy","order_id":"286994eb-e6ef-4e13-a7e6-d6454892e984","reason":"canceled","product_id":"BCH-USD","price":"791.25000000","remaining_size":"1.81488800","sequence":4839271945,"time":"2018-07-27T01:32:40.164000Z"}
{"type":"received","order_id":"497cd0d6-4d9b-4c8b-b6eb-a7d6f994fbeb","order_type":"limit","size":"4.50000000","price":"795.17000000","side":"sell","client_oid":"f68f62c7-cfe5-4589-aeb1-d4cb24e229e1","product_id":"BCH-USD","sequence":4839271946,"time":"2018-07-27T01:32:40.167000Z"}
{"type":"open","side":"sell","price":"795.17000000","order_id":"497cd0d6-4d9b-4c8b-b6eb-a7d6f994fbeb","remaining_size":"4.50000000","product_id":"BCH-USD","sequence":4839271947,"time":"2018-07-27T01:32:40.167000Z"}
{"type":"done","side":"sell","order_id":"6638e0bd-5c71-402f-9d5f-768f92843059","reason":"canceled","product_id":"BCH-USD","price":"795.60000000","remaining_size":"4.50000000","sequence":4839271948,"time":"2018-07-27T01:32:40.167000Z"}
{"type":"received","order_id":"d57f4f72-a762-4f3e-bd57-fbf3d34aa973","order_type":"limit","size":"0.90000000","price":"795.17000000","side":"sell","client_oid":"cc015904-cf1f-4121-a1ae-38bf2bd4b98b","product_id":"BCH-USD","sequence":4839271949,"time":"2018-07-27T01:32:40.169000Z"}
{"type":"open","side":"sell","price":"795.17000000","order_id":"d57f4f72-a762-4f3e-bd57-fbf3d34aa973","remaining_size":"0.90000000","product_id":"BCH-USD","sequence":4839271950,"time":"2018-07-27T01:32:40.169000Z"}
{"type":"received","order_id":"18ad6dd6-e75a-44c3-b989-c288e3cf8254","order_type":"limit","size":"54.00000000","price":"794.00000000","side":"sell","client_oid":"9400695e-e9e2-46c9-93e3-be782faa4c1d","product_id":"BCH-USD","sequence":4839271951,"time":"2018-07-27T01:32:40.169000Z"}
{"type":"open","side":"sell","price":"794.00000000","order_id":"18ad6dd6-e75a-44c3-b989-c288e3cf8254","remaining_size":"54.00000000","product_id":"BCH-USD","sequence":4839271952,"time":"2018-07-27T01:32:40.169000Z"}
{"type":"done","side":"sell","order_id":"d640447e-17be-4a67-b82d-1e9e7032cb8b","reason":"canceled","product_id":"BCH-USD","price":"795.17000000","remaining_size":"1.90000000","sequence":4839271953,"time":"2018-07-27T01:32:40.177000Z"}
{"type":"received","order_id":"dcf67644-f96d-4a3d-8998-2b71cc39450a","order_type":"limit","size":"0.18739300","price":"791.23000000","side":"buy","client_oid":"9e5d7418-37f8-4ebe-addb-e3507cdd6c6d","product_id":"BCH-USD","sequence":4839271954,"time":"2018-07-27T01:32:40.179000Z"}
{"type":"open","side":"buy","price":"791.23000000","order_id":"dcf67644-f96d-4a3d-8998-2b71cc39450a","remaining_size":"0.18739300","product_id":"BCH-USD","sequence":4839271955,"time":"2018-07-27T01:32:40.179000Z"}
{"type":"done","side":"sell","order_id":"497cd0d6-4d9b-4c8b-b6eb-a7d6f994fbeb","reason":"canceled","product_id":"BCH-USD","price":"795.17000000","remaining_size":"4.50000000","sequence":4839271956,"time":"2018-07-27T01:32:40.179000Z"}
{"type":"received","order_id":"a7341887-a06f-446f-a8c6-b2aea54999db","order_type":"limit","size":"1.90000000","price":"795.16000000","side":"sell","client_oid":"abefc6e2-d271-4746-a93a-9a6603bb5984","product_id":"BCH-USD","sequence":4839271957,"time":"2018-07-27T01:32:40.182000Z"}
{"type":"open","side":"sell","price":"795.16000000","order_id":"a7341887-a06f-446f-a8c6-b2aea54999db","remaining_size":"1.90000000","product_id":"BCH-USD","sequence":4839271958,"time":"2018-07-27T01:32:40.182000Z"}
