{"type":"open","side":"buy","price":"7885.00000000","order_id":"9d955487-af62-4568-9e0c-8aa052f081b5","remaining_size":"1.00000000","product_id":"BTC-USD","sequence":6418130295,"time":"2018-07-27T01:32:42.131000Z"}
{"type":"open","side":"sell","price":"83.30000000","order_id":"e890c66e-1f9e-4a94-9a21-db461e5dc1e5","remaining_size":"7.44874862","product_id":"LTC-USD","sequence":2423272067,"time":"2018-07-27T01:32:42.131000Z"}
{"type":"received","order_id":"69944415-3f35-4dde-8b47-30f19035b981","order_type":"limit","size":"0.12908300","price":"788.72000000","side":"buy","client_oid":"10033771-b035-4060-b619-003c49609fb7","product_id":"BCH-USD","sequence":4839273122,"time":"2018-07-27T01:32:42.131000Z"}
{"type":"open","side":"buy","price":"788.72000000","order_id":"69944415-3f35-4dde-8b47-30f19035b981","remaining_size":"0.12908300","product_id":"BCH-USD","sequence":4839273123,"time":"2018-07-27T01:32:42.131000Z"}
{"type":"received","order_id":"c500fe53-87fe-4d8d-ad17-cd14ef5d2907","order_type":"limit","size":"1.90000000","price":"795.03000000","side":"sell","client_oid":"402230e8-dcd4-41b0-bbf7-1580f886ead8","product_id":"BCH-USD","sequence":4839273124,"time":"2018-07-27T01:32:42.132000Z"}
{"type":"open","side":"sell","price":"795.03000000","order_id":"c500fe53-87fe-4d8d-ad17-cd14ef5d2907","remaining_size":"1.90000000","product_id":"BCH-USD","sequence":4839273125,"time":"2018-07-27T01:32:42.132000Z"}
{"type":"received","order_id":"f21590f5-58be-4688-a512-dee19c4deacb","order_type":"limit","size":"0.90000000","price":"795.05000000","side":"sell","client_oid":"540a7bf4-415a-4a87-bc7d-e75e37125e0b","product_id":"BCH-USD","sequence":4839273126,"time":"2018-07-27T01:32:42.135000Z"}
{"type":"done","side":"sell","order_id":"ad7453a1-2465-4c0b-bf3e-cdfef8a72691","reason":"canceled","product_id":"LTC-USD","price":"83.34000000","remaining_size":"7.44874862","sequence":2423272068,"time":"2018-07-27T01:32:42.137000Z"}
{"type":"open","side":"sell","price":"795.05000000","order_id":"f21590f5-58be-4688-a512-dee19c4deacb","remaining_size":"0.90000000","product_id":"BCH-USD","sequence":4839273127,"time":"2018-07-27T01:32:42.135000Z"}
{"type":"done","side":"sell","order_id":"c500fe53-87fe-4d8d-ad17-cd14ef5d2907","reason":"canceled","product_id":"BCH-USD","price":"795.03000000","remaining_size":"1.90000000","sequence":4839273128,"time":"2018-07-27T01:32:42.137000Z"}
{"type":"done","side":"sell","order_id":"f21590f5-58be-4688-a512-dee19c4deacb","reason":"canceled","product_id":"BCH-USD","price":"795.05000000","remaining_size":"0.90000000","sequence":4839273129,"time":"2018-07-27T01:32:42.139000Z"}
{"type":"received","order_id":"ab0bf13c-bcf1-4f8d-b9fe-0e17d29d7224","order_type":"limit","size":"1.81488800","price":"791.27000000","side":"buy","client_oid":"2d6ac56c-5abb-4b57-b421-ab25f63f59af","product_id":"BCH-USD","sequence":4839273130,"time":"2018-07-27T01:32:42.140000Z"}
{"type":"open","side":"buy","price":"791.27000000","order_id":"ab0bf13c-bcf1-4f8d-b9fe-0e17d29d7224","remaining_size":"1.81488800","product_id":"BCH-USD","sequence":4839273131,"time":"2018-07-27T01:32:42.140000Z"}
{"type":"done","side":"sell","order_id":"28dcec1b-ed51-41d0-bcac-5936b13305d4","reason":"canceled","product_id":"BCH-USD","price":"795.05000000","remaining_size":"0.90000000","sequence":4839273132,"time":"2018-07-27T01:32:42.141000Z"}
{"type":"done","side":"buy","order_id":"8f8aa6d4-7b90-4ea4-97c5-871adba78411","reason":"canceled","product_id":"LTC-USD","price":"82.99000000","remaining_size":"20.00000000","sequence":2423272069,"time":"2018-07-27T01:32:42.144000Z"}
{"type":"received","order_id":"6e0a0b15-5971-4fa8-8d44-a10d9df90aad","order_type":"limit","size":"4.50000000","price":"795.05000000","side":"sell","client_oid":"95234ad3-7174-4f22-ba7b-771c75aecb2f","product_id":"BCH-USD","sequence":4839273133,"time":"2018-07-27T01:32:42.144000Z"}
{"type":"open","side":"sell","price":"795.05000000","order_id":"6e0a0b15-5971-4fa8-8d44-a10d9df90aad","remaining_size":"4.50000000","product_id":"BCH-USD","sequence":4839273134,"time":"2018-07-27T01:32:42.144000Z"}
{"type":"received","order_id":"3c6d9dca-c5fd-44a0-a875-f50f20286136","order_type":"limit","size":"0.18739300","price":"791.26000000","side":"buy","client_oid":"68e2c811-5d70-4b23-9cae-31f07abb6873","product_id":"BCH-USD","sequence":4839273135,"time":"2018-07-27T01:32:42.144000Z"}
{"type":"open","side":"buy","price":"791.26000000","order_id":"3c6d9dca-c5fd-44a0-a875-f50f20286136","remaining_size":"0.18739300","product_id":"BCH-USD","sequence":4839273136,"time":"2018-07-27T01:32:42.144000Z"}
{"type":"received","order_id":"1aea05f5-753f-4841-8436-cfd6428080f1","order_type":"limit","size":"0.90000000","price":"795.02000000","side":"sell","client_oid":"a7daca4e-f879-47ce-93b9-2ce1b7240980","product_id":"BCH-USD","sequence":4839273137,"time":"2018-07-27T01:32:42.144000Z"}
{"type":"open","side":"sell","price":"795.02000000","order_id":"1aea05f5-753f-4841-8436-cfd6428080f1","remaining_size":"0.90000000","product_id":"BCH-USD","sequence":4839273138,"time":"2018-07-27T01:32:42.144000Z"}
{"type":"received","order_id":"7c93a30e-9705-490a-aa28-62806c3312d5","order_type":"limit","size":"0.16755000","price":"788.48000000","side":"buy","client_oid":"0ad83a72-2b67-4efc-a43a-5abecfdb5c19","product_id":"BCH-USD","sequence":4839273139,"time":"2018-07-27T01:32:42.145000Z"}
{"type":"open","side":"buy","price":"788.48000000","order_id":"7c93a30e-9705-490a-aa28-62806c3312d5","remaining_size":"0.16755000","product_id":"BCH-USD","sequence":4839273140,"time":"2018-07-27T01:32:42.145000Z"}
{"type":"received","order_id":"c889bc1e-8c6f-49c9-b32c-13f9519d7b50","order_type":"limit","size":"1.90000000","price":"795.05000000","side":"sell","client_oid":"8541f9bf-e863-4b40-bf26-095028984f4d","product_id":"BCH-USD","sequence":4839273141,"time":"2018-07-27T01:32:42.147000Z"}
{"type":"open","side":"sell","price":"795.05000000","order_id":"c889bc1e-8c6f-49c9-b32c-13f9519d7b50","remaining_size":"1.90000000","product_id":"BCH-USD","sequence":4839273142,"time":"2018-07-27T01:32:42.147000Z"}
{"type":"done","side":"buy","order_id":"ab0bf13c-bcf1-4f8d-b9fe-0e17d29d7224","reason":"canceled","product_id":"BCH-USD","price":"791.27000000","remaining_size":"1.81488800","sequence":4839273143,"time":"2018-07-27T01:32:42.148000Z"}
{"type":"done","side":"sell","order_id":"1aea05f5-753f-4841-8436-cfd6428080f1","reason":"canceled","product_id":"BCH-USD","price":"795.02000000","remaining_size":"0.90000000","sequence":4839273144,"time":"2018-07-27T01:32:42.150000Z"}
{"type":"done","side":"buy","order_id":"3c6d9dca-c5fd-44a0-a875-f50f20286136","reason":"canceled","product_id":"BCH-USD","price":"791.26000000","remaining_size":"0.18739300","sequence":4839273145,"time":"2018-07-27T01:32:42.151000Z"}
{"type":"received","order_id":"3d98fe1f-d346-41dd-8dfe-8ae9483aaf1f","order_type":"limit","size":"1.81488800","price":"791.24000000","side":"buy","client_oid":"4e0035b8-6320-41aa-8553-f2629dad8ba0","product_id":"BCH-USD","sequence":4839273146,"time":"2018-07-27T01:32:42.152000Z"}
{"type":"open","side":"buy","price":"791.24000000","order_id":"3d98fe1f-d346-41dd-8dfe-8ae9483aaf1f","remaining_size":"1.81488800","product_id":"BCH-USD","sequence":4839273147,"time":"2018-07-27T01:32:42.152000Z"}
{"type":"received","order_id":"325078e5-63bf-4ae7-9fd0-1d0934e26934","order_type":"limit","size":"7.44874862","price":"83.38000000","side":"sell","client_oid":"eca8b253-a804-4b4e-8000-00803a1c4ad7","product_id":"LTC-USD","sequence":2423272070,"time":"2018-07-27T01:32:42.157000Z"}
{"type":"open","side":"sell","price":"83.38000000","order_id":"325078e5-63bf-4ae7-9fd0-1d0934e26934","remaining_size":"7.44874862","product_id":"LTC-USD","sequence":2423272071,"time":"2018-07-27T01:32:42.157000Z"}
{"type":"received","order_id":"edf24357-f212-437c-bccd-8d8784007079","order_type":"limit","size":"2.74528900","price":"788.24000000","side":"buy","client_oid":"32c2bc45-50d1-4c1f-b41e-97c4c59cd8c6","product_id":"BCH-USD","sequence":4839273148,"time":"2018-07-27T01:32:42.157000Z"}
{"type":"open","side":"buy","price":"788.24000000","order_id":"edf24357-f212-437c-bccd-8d8784007079","remaining_size":"2.74528900","product_id":"BCH-USD","sequence":4839273149,"time":"2018-07-27T01:32:42.157000Z"}
{"type":"done","side":"buy","order_id":"3d98fe1f-d346-41dd-8dfe-8ae9483aaf1f","reason":"canceled","product_id":"BCH-USD","price":"791.24000000","remaining_size":"1.81488800","sequence":4839273150,"time":"2018-07-27T01:32:42.157000Z"}
{"type":"received","order_id":"c15dee1d-b2c2-40d2-b4dd-1f169d2e4cfd","order_type":"limit","size":"0.90000000","price":"795.05000000","side":"sell","client_oid":"6114d761-ff94-444b-86c4-784ebf51a85c","product_id":"BCH-USD","sequence":4839273151,"time":"2018-07-27T01:32:42.157000Z"}
{"type":"open","side":"sell","price":"795.05000000","order_id":"c15dee1d-b2c2-40d2-b4dd-1f169d2e4cfd","remaining_size":"0.90000000","product_id":"BCH-USD","sequence":4839273152,"time":"2018-07-27T01:32:42.157000Z"}
{"type":"received","order_id":"ec357bbd-23f7-4b4a-ad0f-8ff58160a1d7","order_type":"limit","size":"20.00000000","price":"82.98000000","side":"buy","client_oid":"d5dc6a16-c2af-44d6-b0d0-405a468b7503","product_id":"LTC-USD","sequence":2423272072,"time":"2018-07-27T01:32:42.164000Z"}
{"type":"received","order_id":"4f087dfb-8596-4f32-a104-30463073b46a","order_type":"limit","size":"0.90000000","price":"795.02000000","side":"sell","client_oid":"be61e06f-b30d-47c8-a212-2c871081fa07","product_id":"BCH-USD","sequence":4839273153,"time":"2018-07-27T01:32:42.162000Z"}
{"type":"open","side":"sell","price":"795.02000000","order_id":"4f087dfb-8596-4f32-a104-30463073b46a","remaining_size":"0.90000000","product_id":"BCH-USD","sequence":4839273154,"time":"2018-07-27T01:32:42.162000Z"}
{"type":"open","side":"buy","price":"82.98000000","order_id":"ec357bbd-23f7-4b4a-ad0f-8ff58160a1d7","remaining_size":"20.00000000","product_id":"LTC-USD","sequence":2423272073,"time":"2018-07-27T01:32:42.164000Z"}
{"type":"done","side":"sell","order_id":"c15dee1d-b2c2-40d2-b4dd-1f169d2e4cfd","reason":"canceled","product_id":"BCH-USD","price":"795.05000000","remaining_size":"0.90000000","sequence":4839273155,"time":"2018-07-27T01:32:42.165000Z"}
{"type":"done","side":"buy","order_id":"33a897c9-3788-468d-8e22-18532afaeb2f","reason":"canceled","product_id":"BCH-USD","price":"792.80000000","remaining_size":"2.00000000","sequence":4839273156,"time":"2018-07-27T01:32:42.166000Z"}
{"type":"received","order_id":"eeff473a-b909-4544-ab1b-ed635f56e29c","order_type":"limit","size":"1.81488800","price":"791.23000000","side":"buy","client_oid":"6cd28a6f-e211-4010-978c-cc5988286227","product_id":"BCH-USD","sequence":4839273157,"time":"2018-07-27T01:32:42.167000Z"}
{"type":"open","side":"buy","price":"791.23000000","order_id":"eeff473a-b909-4544-ab1b-ed635f56e29c","remaining_size":"1.81488800","product_id":"BCH-USD","sequence":4839273158,"time":"2018-07-27T01:32:42.167000Z"}
{"type":"done","side":"sell","order_id":"c889bc1e-8c6f-49c9-b32c-13f9519d7b50","reason":"canceled","product_id":"BCH-USD","price":"795.05000000","remaining_size":"1.90000000","sequence":4839273159,"time":"2018-07-27T01:32:42.168000Z"}
{"type":"received","order_id":"c2d31508-4f47-441e-a55b-373e980db06b","order_type":"limit","size":"0.18739300","price":"791.23000000","side":"buy","client_oid":"38a3ecd2-d03f-46bc-b302-26bd8ccac681","product_id":"BCH-USD","sequence":4839273160,"time":"2018-07-27T01:32:42.172000Z"}
{"type":"open","side":"buy","price":"791.23000000","order_id":"c2d31508-4f47-441e-a55b-373e980db06b","remaining_size":"0.18739300","product_id":"BCH-USD","sequence":4839273161,"time":"2018-07-27T01:32:42.172000Z"}
{"type":"done","side":"buy","order_id":"eeff473a-b909-4544-ab1b-ed635f56e29c","reason":"canceled","product_id":"BCH-USD","price":"791.23000000","remaining_size":"1.81488800","sequence":4839273162,"time":"2018-07-27T01:32:42.174000Z"}
{"type":"done","side":"sell","order_id":"91ab2749-bd88-497c-af63-b4848cf2e49e","reason":"canceled","product_id":"ETH-USD","price":"485.60000000","remaining_size":"0.01000000","sequence":4469354838,"time":"2018-07-27T01:32:42.175000Z"}
{"type":"done","side":"sell","order_id":"9cdb1bc7-1c76-4acf-9880-f403e930ba5c","reason":"canceled","product_id":"ETH-USD","price":"483.62000000","remaining_size":"0.01000000","sequence":4469354839,"time":"2018-07-27T01:32:42.177000Z"}
{"type":"done","side":"sell","order_id":"e07f8b9e-148c-49a7-aa7b-29d4e199ba25","reason":"canceled","product_id":"ETH-USD","price":"484.60000000","remaining_size":"0.01000000","sequence":4469354840,"time":"2018-07-27T01:32:42.179000Z"}
{"type":"done","side":"sell","order_id":"4f087dfb-8596-4f32-a104-30463073b46a","reason":"canceled","product_id":"BCH-USD","price":"795.02000000","remaining_size":"0.90000000","sequence":4839273163,"time":"2018-07-27T01:32:42.179000Z"}
{"type":"received","order_id":"a8dd8861-bccd-458b-993c-4166985b12f6","order_type":"limit","size":"0.90000000","price":"795.04000000","side":"sell","client_oid":"9461c459-14fd-4c63-afc8-095d12d9933c","product_id":"BCH-USD","sequence":4839273164,"time":"2018-07-27T01:32:42.182000Z"}
{"type":"open","side":"sell","price":"795.04000000","order_id":"a8dd8861-bccd-458b-993c-4166985b12f6","remaining_size":"0.90000000","product_id":"BCH-USD","sequence":4839273165,"time":"2018-07-27T01:32:42.182000Z"}
{"type":"received","order_id":"7558ee0d-4cfc-4526-9763-50d9ca39d693","order_type":"limit","size":"0.01000000","price":"486.60000000","side":"sell","client_oid":"c3b1af64-842a-4aa3-8000-009431259de5","product_id":"ETH-USD","sequence":4469354841,"time":"2018-07-27T01:32:42.183000Z"}
{"type":"received","order_id":"71695d13-ff9c-4779-ac74-7134a9e60f34","order_type":"limit","size":"1.81488800","price":"791.25000000","side":"buy","client_oid":"dadf4455-5262-4fbe-a814-8a1616e39dbc","product_id":"BCH-USD","sequence":4839273166,"time":"2018-07-27T01:32:42.183000Z"}
{"type":"open","side":"buy","price":"791.25000000","order_id":"71695d13-ff9c-4779-ac74-7134a9e60f34","remaining_size":"1.81488800","product_id":"BCH-USD","sequence":4839273167,"time":"2018-07-27T01:32:42.183000Z"}
{"type":"open","side":"sell","price":"486.60000000","order_id":"7558ee0d-4cfc-4526-9763-50d9ca39d693","remaining_size":"0.01000000","product_id":"ETH-USD","sequence":4469354842,"time":"2018-07-27T01:32:42.183000Z"}
{"type":"received","order_id":"22d174a0-0b57-484a-afff-29af1f81c613","order_type":"limit","size":"0.21613500","price":"788.00000000","side":"buy","client_oid":"2c367f3c-8a4d-4cf7-acc9-50c0b2cd9242","product_id":"BCH-USD","sequence":4839273168,"time":"2018-07-27T01:32:42.184000Z"}
{"type":"open","side":"buy","price":"788.00000000","order_id":"22d174a0-0b57-484a-afff-29af1f81c613","remaining_size":"0.21613500","product_id":"BCH-USD","sequence":4839273169,"time":"2018-07-27T01:32:42.184000Z"}
{"type":"done","side":"sell","order_id":"6e0a0b15-5971-4fa8-8d44-a10d9df90aad","reason":"canceled","product_id":"BCH-USD","price":"795.05000000","remaining_size":"4.50000000","sequence":4839273170,"time":"2018-07-27T01:32:42.185000Z"}
{"type":"received","order_id":"de16c210-0761-485b-9beb-7da38ef68700","order_type":"limit","size":"1.90000000","price":"795.04000000","side":"sell","client_oid":"4497c348-c297-4851-b93f-64051cc17c76","product_id":"BCH-USD","sequence":4839273171,"time":"2018-07-27T01:32:42.186000Z"}
{"type":"open","side":"sell","price":"795.04000000","order_id":"de16c210-0761-485b-9beb-7da38ef68700","remaining_size":"1.90000000","product_id":"BCH-USD","sequence":4839273172,"time":"2018-07-27T01:32:42.186000Z"}
{"type":"done","side":"buy","order_id":"71695d13-ff9c-4779-ac74-7134a9e60f34","reason":"canceled","product_id":"BCH-USD","price":"791.25000000","remaining_size":"1.81488800","sequence":4839273173,"time":"2018-07-27T01:32:42.186000Z"}
{"type":"received","order_id":"03586ca0-8873-4152-bb41-8ec8b550aa35","order_type":"limit","size":"0.90000000","price":"795.04000000","side":"sell","client_oid":"1bedf680-1ed2-462f-bd65-eca2823cc3b8","product_id":"BCH-USD","sequence":4839273174,"time":"2018-07-27T01:32:42.187000Z"}
{"type":"open","side":"sell","price":"795.04000000","order_id":"03586ca0-8873-4152-bb41-8ec8b550aa35","remaining_size":"0.90000000","product_id":"BCH-USD","sequence":4839273175,"time":"2018-07-27T01:32:42.187000Z"}
{"type":"received","order_id":"c97ea09a-55b0-43ef-9160-bc610c28a1f2","order_type":"limit","size":"2.00000000","price":"792.54000000","side":"buy","client_oid":"3938a1eb-2b5f-4d5d-a17c-1506d8506195","product_id":"BCH-USD","sequence":4839273176,"time":"2018-07-27T01:32:42.189000Z"}
{"type":"open","side":"buy","price":"792.54000000","order_id":"c97ea09a-55b0-43ef-9160-bc610c28a1f2","remaining_size":"2.00000000","product_id":"BCH-USD","sequence":4839273177,"time":"2018-07-27T01:32:42.189000Z"}
{"type":"done","side":"sell","order_id":"de16c210-0761-485b-9beb-7da38ef68700","reason":"canceled","product_id":"BCH-USD","price":"795.04000000","remaining_size":"1.90000000","sequence":4839273178,"time":"2018-07-27T01:32:42.197000Z"}
{"type":"done","side":"sell","order_id":"a8dd8861-bccd-458b-993c-4166985b12f6","reason":"canceled","product_id":"BCH-USD","price":"795.04000000","remaining_size":"0.90000000","sequence":4839273179,"time":"2018-07-27T01:32:42.197000Z"}
{"type":"done","side":"sell","order_id":"03586ca0-8873-4152-bb41-8ec8b550aa35","reason":"canceled","product_id":"BCH-USD","price":"795.04000000","remaining_size":"0.90000000","sequence":4839273180,"time":"2018-07-27T01:32:42.200000Z"}
{"type":"done","side":"sell","order_id":"fa49e529-0309-4578-9ea5-864e178e4c37","reason":"canceled","product_id":"ETH-USD","price":"463.65000000","remaining_size":"5.96866000","sequence":4469354843,"time":"2018-07-27T01:32:42.207000Z"}
{"type":"done","side":"sell","order_id":"e890c66e-1f9e-4a94-9a21-db461e5dc1e5","reason":"canceled","product_id":"LTC-USD","price":"83.30000000","remaining_size":"7.44874862","sequence":2423272074,"time":"2018-07-27T01:32:42.224000Z"}
{"type":"done","side":"buy","order_id":"c97ea09a-55b0-43ef-9160-bc610c28a1f2","reason":"canceled","product_id":"BCH-USD","price":"792.54000000","remaining_size":"2.00000000","sequence":4839273181,"time":"2018-07-27T01:32:42.223000Z"}
{"type":"done","side":"buy","order_id":"ec357bbd-23f7-4b4a-ad0f-8ff58160a1d7","reason":"canceled","product_id":"LTC-USD","price":"82.98000000","remaining_size":"20.00000000","sequence":2423272075,"time":"2018-07-27T01:32:42.235000Z"}
{"type":"done","side":"sell","order_id":"fd8e0703-2a3e-481b-bc8a-c049a26ff1cd","reason":"canceled","product_id":"LTC-USD","price":"88.38000000","remaining_size":"0.10000000","sequence":2423272076,"time":"2018-07-27T01:32:42.288000Z"}
{"type":"done","side":"sell","order_id":"325078e5-63bf-4ae7-9fd0-1d0934e26934","reason":"canceled","product_id":"LTC-USD","price":"83.38000000","remaining_size":"7.44874862","sequence":2423272077,"time":"2018-07-27T01:32:42.305000Z"}
{"type":"received","order_id":"29546f89-ee6c-4cec-8919-ad1bafede036","order_type":"limit","size":"1.81488800","price":"791.23000000","side":"buy","client_oid":"e757cf8f-9193-4596-8f15-4d23ce7283bb","product_id":"BCH-USD","sequence":4839273182,"time":"2018-07-27T01:32:42.305000Z"}
{"type":"open","side":"buy","price":"791.23000000","order_id":"29546f89-ee6c-4cec-8919-ad1bafede036","remaining_size":"1.81488800","product_id":"BCH-USD","sequence":4839273183,"time":"2018-07-27T01:32:42.305000Z"}
{"type":"received","order_id":"3a3db9f6-7e2e-4b1d-8390-227163c2b603","order_type":"limit","size":"2.00000000","price":"792.80000000","side":"buy","client_oid":"34c797c5-997c-42ee-970c-52948c0c5fa4","product_id":"BCH-USD","sequence":4839273184,"time":"2018-07-27T01:32:42.305000Z"}
{"type":"open","side":"buy","price":"792.80000000","order_id":"3a3db9f6-7e2e-4b1d-8390-227163c2b603","remaining_size":"2.00000000","product_id":"BCH-USD","sequence":4839273185,"time":"2018-07-27T01:32:42.305000Z"}
{"type":"received","order_id":"7e2c9e2c-63b9-4939-b5df-59afe99d42e7","order_type":"limit","size":"1.38331400","price":"787.52000000","side":"buy","client_oid":"7de81002-fbc4-42b0-8f61-f6bb591545a1","product_id":"BCH-USD","sequence":4839273186,"time":"2018-07-27T01:32:42.306000Z"}
{"type":"open","side":"buy","price":"787.52000000","order_id":"7e2c9e2c-63b9-4939-b5df-59afe99d42e7","remaining_size":"1.38331400","product_id":"BCH-USD","sequence":4839273187,"time":"2018-07-27T01:32:42.306000Z"}
{"type":"received","order_id":"295a7896-2113-475d-b7df-4bdfa79e5b16","order_type":"limit","size":"7.44874862","price":"83.34000000","side":"sell","client_oid":"e2c196f8-a0f2-4e7f-8000-00f0f4eba917","product_id":"LTC-USD","sequence":2423272078,"time":"2018-07-27T01:32:42.311000Z"}
{"type":"open","side":"sell","price":"83.34000000","order_id":"295a7896-2113-475d-b7df-4bdfa79e5b16","remaining_size":"7.44874862","product_id":"LTC-USD","sequence":2423272079,"time":"2018-07-27T01:32:42.311000Z"}
{"type":"received","order_id":"4434532b-498d-4c4d-b366-e88d7505c310","order_type":"limit","size":"0.90000000","price":"795.03000000","side":"sell","client_oid":"b7bd16fc-36ab-41b3-856e-fafe26eb3448","product_id":"BCH-USD","sequence":4839273188,"time":"2018-07-27T01:32:42.311000Z"}
{"type":"received","order_id":"0c749e01-3cf7-4ccc-aa7f-c64e84af7df7","order_type":"limit","size":"0.10000000","price":"94.38000000","side":"sell","client_oid":"4acb9c5d-a332-4f41-8000-048fe8c8fea0","product_id":"LTC-USD","sequence":2423272080,"time":"2018-07-27T01:32:42.313000Z"}
{"type":"open","side":"sell","price":"795.03000000","order_id":"4434532b-498d-4c4d-b366-e88d7505c310","remaining_size":"0.90000000","product_id":"BCH-USD","sequence":4839273189,"time":"2018-07-27T01:32:42.311000Z"}
{"type":"open","side":"sell","price":"94.38000000","order_id":"0c749e01-3cf7-4ccc-aa7f-c64e84af7df7","remaining_size":"0.10000000","product_id":"LTC-USD","sequence":2423272081,"time":"2018-07-27T01:32:42.313000Z"}
{"type":"received","order_id":"21cb9844-1b30-4564-a3e6-007617736e6b","order_type":"limit","size":"20.00000000","price":"82.99000000","side":"buy","client_oid":"a794fc3a-91d9-4cc8-8c55-4fe1beda52e8","product_id":"LTC-USD","sequence":2423272082,"time":"2018-07-27T01:32:42.313000Z"}
{"type":"open","side":"buy","price":"82.99000000","order_id":"21cb9844-1b30-4564-a3e6-007617736e6b","remaining_size":"20.00000000","product_id":"LTC-USD","sequence":2423272083,"time":"2018-07-27T01:32:42.313000Z"}
{"type":"received","order_id":"db3f74ea-7361-40a0-9277-a9cb806d418c","order_type":"limit","size":"4.50000000","price":"795.04000000","side":"sell","client_oid":"609cc8e9-da1f-47db-99e2-4c1de7b50c97","product_id":"BCH-USD","sequence":4839273190,"time":"2018-07-27T01:32:42.314000Z"}
{"type":"open","side":"sell","price":"795.04000000","order_id":"db3f74ea-7361-40a0-9277-a9cb806d418c","remaining_size":"4.50000000","product_id":"BCH-USD","sequence":4839273191,"time":"2018-07-27T01:32:42.314000Z"}
{"type":"done","side":"sell","order_id":"4434532b-498d-4c4d-b366-e88d7505c310","reason":"canceled","product_id":"BCH-USD","price":"795.03000000","remaining_size":"0.90000000","sequence":4839273192,"time":"2018-07-27T01:32:42.315000Z"}
{"type":"received","order_id":"4ec84a04-5224-4292-a8eb-0bbcf9c355ec","order_type":"limit","size":"0.10000000","price":"95.38000000","side":"sell","client_oid":"52ff71b2-13fe-4620-8000-81b2e01f9700","product_id":"LTC-USD","sequence":2423272084,"time":"2018-07-27T01:32:42.317000Z"}
{"type":"open","side":"sell","price":"95.38000000","order_id":"4ec84a04-5224-4292-a8eb-0bbcf9c355ec","remaining_size":"0.10000000","product_id":"LTC-USD","sequence":2423272085,"time":"2018-07-27T01:32:42.317000Z"}
{"type":"done","side":"sell","order_id":"7d30417b-8b90-458b-a426-14dde76e66d6","reason":"canceled","product_id":"BCH-USD","price":"795.15000000","remaining_size":"3.00000000","sequence":4839273193,"time":"2018-07-27T01:32:42.317000Z"}
{"type":"done","side":"buy","order_id":"29546f89-ee6c-4cec-8919-ad1bafede036","reason":"canceled","product_id":"BCH-USD","price":"791.23000000","remaining_size":"1.81488800","sequence":4839273194,"time":"2018-07-27T01:32:42.318000Z"}
{"type":"done","side":"buy","order_id":"c2d31508-4f47-441e-a55b-373e980db06b","reason":"canceled","product_id":"BCH-USD","price":"791.23000000","remaining_size":"0.18739300","sequence":4839273195,"time":"2018-07-27T01:32:42.318000Z"}
{"type":"done","side":"sell","order_id":"db3f74ea-7361-40a0-9277-a9cb806d418c","reason":"canceled","product_id":"BCH-USD","price":"795.04000000","remaining_size":"4.50000000","sequence":4839273196,"time":"2018-07-27T01:32:42.322000Z"}
{"type":"received","order_id":"aeb73e90-7abd-4872-b228-499210c07afe","order_type":"limit","size":"0.90000000","price":"795.05000000","side":"sell","client_oid":"c88ca0ac-c6ea-454b-afa9-1e0373e4e28e","product_id":"BCH-USD","sequence":4839273197,"time":"2018-07-27T01:32:42.322000Z"}
{"type":"open","side":"sell","price":"795.05000000","order_id":"aeb73e90-7abd-4872-b228-499210c07afe","remaining_size":"0.90000000","product_id":"BCH-USD","sequence":4839273198,"time":"2018-07-27T01:32:42.322000Z"}
{"type":"received","order_id":"b9f9b66c-4720-47dd-bc52-b5a0ad93de02","order_type":"limit","size":"1.90000000","price":"795.05000000","side":"sell","client_oid":"2033bbb6-b6eb-47c6-aec4-181b81a510ff","product_id":"BCH-USD","sequence":4839273199,"time":"2018-07-27T01:32:42.323000Z"}
{"type":"open","side":"sell","price":"795.05000000","order_id":"b9f9b66c-4720-47dd-bc52-b5a0ad93de02","remaining_size":"1.90000000","product_id":"BCH-USD","sequence":4839273200,"time":"2018-07-27T01:32:42.323000Z"}
{"type":"done","side":"buy","order_id":"c4c9dabe-4500-42b9-bb04-702c80d893a7","reason":"canceled","product_id":"LTC-USD","price":"83.23000000","remaining_size":"20.00000000","sequence":2423272086,"time":"2018-07-27T01:32:42.327000Z"}
{"type":"done","side":"buy","order_id":"cf2e0b8e-c61b-41b5-8a72-fb460d9c2f75","reason":"canceled","product_id":"BTC-USD","price":"7893.00000000","remaining_size":"0.20000000","sequence":6418130296,"time":"2018-07-27T01:32:42.328000Z"}
{"type":"done","side":"buy","order_id":"3a3db9f6-7e2e-4b1d-8390-227163c2b603","reason":"canceled","product_id":"BCH-USD","price":"792.80000000","remaining_size":"2.00000000","sequence":4839273201,"time":"2018-07-27T01:32:42.326000Z"}
{"type":"received","order_id":"24f33b3e-3e6c-4430-9071-88d8abd5c515","order_type":"limit","size":"0.90000000","price":"795.05000000","side":"sell","client_oid":"b970c53c-598e-4654-9b04-8a3e91d77eee","product_id":"BCH-USD","sequence":4839273202,"time":"2018-07-27T01:32:42.327000Z"}
{"type":"open","side":"sell","price":"795.05000000","order_id":"24f33b3e-3e6c-4430-9071-88d8abd5c515","remaining_size":"0.90000000","product_id":"BCH-USD","sequence":4839273203,"time":"2018-07-27T01:32:42.327000Z"}
{"type":"done","side":"sell","order_id":"cbcc3243-7ae5-46d8-a5f0-0647d30889cc","reason":"canceled","product_id":"BCH-USD","price":"794.00000000","remaining_size":"2.00000000","sequence":4839273204,"time":"2018-07-27T01:32:42.329000Z"}
{"type":"received","order_id":"a803012b-4211-4202-abd5-4d177985e00d","order_type":"limit","size":"1.81488800","price":"791.24000000","side":"buy","client_oid":"1c9ff3d5-2212-4482-96cc-87bd0b7ac41a","product_id":"BCH-USD","sequence":4839273205,"time":"2018-07-27T01:32:42.330000Z"}
{"type":"open","side":"buy","price":"791.24000000","order_id":"a803012b-4211-4202-abd5-4d177985e00d","remaining_size":"1.81488800","product_id":"BCH-USD","sequence":4839273206,"time":"2018-07-27T01:32:42.330000Z"}
{"type":"received","order_id":"bd79beee-45f7-4955-ae3c-e6e118681ec5","order_type":"limit","size":"3.00000000","price":"795.05000000","side":"sell","client_oid":"a4d570b4-76b0-4b3f-8d53-9c99ea0f9e81","product_id":"BCH-USD","sequence":4839273207,"time":"2018-07-27T01:32:42.331000Z"}
{"type":"open","side":"sell","price":"795.05000000","order_id":"bd79beee-45f7-4955-ae3c-e6e118681ec5","remaining_size":"3.00000000","product_id":"BCH-USD","sequence":4839273208,"time":"2018-07-27T01:32:42.331000Z"}
{"type":"done","side":"sell","order_id":"aeb73e90-7abd-4872-b228-499210c07afe","reason":"canceled","product_id":"BCH-USD","price":"795.05000000","remaining_size":"0.90000000","sequence":4839273209,"time":"2018-07-27T01:32:42.332000Z"}
{"type":"received","order_id":"2876f6e5-628b-4356-bf7e-83c0c89e7bef","order_type":"limit","size":"0.18739300","price":"791.24000000","side":"buy","client_oid":"75e9225d-79e7-4173-87d7-f656202f48f1","product_id":"BCH-USD","sequence":4839273210,"time":"2018-07-27T01:32:42.335000Z"}
{"type":"open","side":"buy","price":"791.24000000","order_id":"2876f6e5-628b-4356-bf7e-83c0c89e7bef","remaining_size":"0.18739300","product_id":"BCH-USD","sequence":4839273211,"time":"2018-07-27T01:32:42.335000Z"}
{"type":"done","side":"buy","order_id":"a803012b-4211-4202-abd5-4d177985e00d","reason":"canceled","product_id":"BCH-USD","price":"791.24000000","remaining_size":"1.81488800","sequence":4839273212,"time":"2018-07-27T01:32:42.337000Z"}
{"type":"received","order_id":"82c2b531-5944-4489-911d-ce60c8b88255","order_type":"limit","size":"0.90000000","price":"795.03000000","side":"sell","client_oid":"b187f185-6654-4c5e-88b0-0a78ca1ca03d","product_id":"BCH-USD","sequence":4839273213,"time":"2018-07-27T01:32:42.340000Z"}
{"type":"open","side":"sell","price":"795.03000000","order_id":"82c2b531-5944-4489-911d-ce60c8b88255","remaining_size":"0.90000000","product_id":"BCH-USD","sequence":4839273214,"time":"2018-07-27T01:32:42.340000Z"}
{"type":"done","side":"buy","order_id":"2876f6e5-628b-4356-bf7e-83c0c89e7bef","reason":"canceled","product_id":"BCH-USD","price":"791.24000000","remaining_size":"0.18739300","sequence":4839273215,"time":"2018-07-27T01:32:42.342000Z"}
{"type":"done","side":"sell","order_id":"82c2b531-5944-4489-911d-ce60c8b88255","reason":"canceled","product_id":"BCH-USD","price":"795.03000000","remaining_size":"0.90000000","sequence":4839273216,"time":"2018-07-27T01:32:42.344000Z"}
{"type":"done","side":"sell","order_id":"24f33b3e-3e6c-4430-9071-88d8abd5c515","reason":"canceled","product_id":"BCH-USD","price":"795.05000000","remaining_size":"0.90000000","sequence":4839273217,"time":"2018-07-27T01:32:42.345000Z"}
{"type":"done","side":"sell","order_id":"b9f9b66c-4720-47dd-bc52-b5a0ad93de02","reason":"canceled","product_id":"BCH-USD","price":"795.05000000","remaining_size":"1.90000000","sequence":4839273218,"time":"2018-07-27T01:32:42.346000Z"}
{"type":"received","order_id":"fb98e2a3-606d-4f76-a916-442b874a0ab8","order_type":"limit","size":"20.00000000","price":"83.25000000","side":"buy","client_oid":"6c659a1d-ac4d-4f3a-b07d-948f2f40ab19","product_id":"LTC-USD","sequence":2423272087,"time":"2018-07-27T01:32:42.348000Z"}
{"type":"open","side":"buy","price":"83.25000000","order_id":"fb98e2a3-606d-4f76-a916-442b874a0ab8","remaining_size":"20.00000000","product_id":"LTC-USD","sequence":2423272088,"time":"2018-07-27T01:32:42.348000Z"}
{"type":"received","order_id":"88228dde-27fd-44cb-959a-7eec69c635e5","order_type":"limit","size":"1.81488800","price":"791.23000000","side":"buy","client_oid":"2adceb0e-167c-49c1-8b7a-6e1b3de1e582","product_id":"BCH-USD","sequence":4839273219,"time":"2018-07-27T01:32:42.347000Z"}
{"type":"open","side":"buy","price":"791.23000000","order_id":"88228dde-27fd-44cb-959a-7eec69c635e5","remaining_size":"1.81488800","product_id":"BCH-USD","sequence":4839273220,"time":"2018-07-27T01:32:42.347000Z"}
{"type":"received","order_id":"fae14e7b-80b4-44ff-a58b-a8d85b7a8dd6","order_type":"limit","size":"4.50000000","price":"795.05000000","side":"sell","client_oid":"f79bed5a-628a-401f-a97d-b36b8c2135bc","product_id":"BCH-USD","sequence":4839273221,"time":"2018-07-27T01:32:42.349000Z"}
{"type":"open","side":"sell","price":"795.05000000","order_id":"fae14e7b-80b4-44ff-a58b-a8d85b7a8dd6","remaining_size":"4.50000000","product_id":"BCH-USD","sequence":4839273222,"time":"2018-07-27T01:32:42.349000Z"}
{"type":"done","side":"buy","order_id":"88228dde-27fd-44cb-959a-7eec69c635e5","reason":"canceled","product_id":"BCH-USD","price":"791.23000000","remaining_size":"1.81488800","sequence":4839273223,"time":"2018-07-27T01:32:42.351000Z"}
{"type":"received","order_id":"4661ea7b-2e61-4963-9194-465b7efa13a7","order_type":"limit","size":"0.18739300","price":"791.23000000","side":"buy","client_oid":"1aa3480d-1295-4600-bb9f-c4e1026c26a8","product_id":"BCH-USD","sequence":4839273224,"time":"2018-07-27T01:32:42.353000Z"}
{"type":"open","side":"buy","price":"791.23000000","order_id":"4661ea7b-2e61-4963-9194-465b7efa13a7","remaining_size":"0.18739300","product_id":"BCH-USD","sequence":4839273225,"time":"2018-07-27T01:32:42.353000Z"}
{"type":"received","order_id":"9bdccd60-aaf8-46c7-ac2b-9fa86a2039ea","order_type":"limit","size":"5.96866000","price":"463.77000000","side":"sell","client_oid":"6763ee28-9ab7-4260-b6d9-baafb65d0be7","product_id":"ETH-USD","sequence":4469354844,"time":"2018-07-27T01:32:42.356000Z"}
{"type":"received","order_id":"dfadc188-8a50-434e-aea8-78cd674d8ee6","order_type":"limit","size":"2.00000000","price":"793.19000000","side":"buy","client_oid":"625e72ef-540b-41be-a8c1-9f33053d5def","product_id":"BCH-USD","sequence":4839273226,"time":"2018-07-27T01:32:42.355000Z"}
{"type":"open","side":"buy","price":"793.19000000","order_id":"dfadc188-8a50-434e-aea8-78cd674d8ee6","remaining_size":"2.00000000","product_id":"BCH-USD","sequence":4839273227,"time":"2018-07-27T01:32:42.355000Z"}
{"type":"open","side":"sell","price":"463.77000000","order_id":"9bdccd60-aaf8-46c7-ac2b-9fa86a2039ea","remaining_size":"5.96866000","product_id":"ETH-USD","sequence":4469354845,"time":"2018-07-27T01:32:42.356000Z"}
{"type":"received","order_id":"9f364e11-a1eb-4783-9dd8-95156c37977e","order_type":"limit","size":"0.90000000","price":"795.05000000","side":"sell","client_oid":"8d88eb83-b05a-463c-9159-10bb165d0d0f","product_id":"BCH-USD","sequence":4839273228,"time":"2018-07-27T01:32:42.360000Z"}
{"type":"received","order_id":"4c1fd8d8-80aa-4dd8-98bc-b8c01df83935","order_type":"limit","size":"0.20000000","price":"7894.00000000","side":"buy","client_oid":"e0bd73b4-9915-4509-84b9-7298c700b6b9","product_id":"BTC-USD","sequence":6418130297,"time":"2018-07-27T01:32:42.363000Z"}
{"type":"open","side":"sell","price":"795.05000000","order_id":"9f364e11-a1eb-4783-9dd8-95156c37977e","remaining_size":"0.90000000","product_id":"BCH-USD","sequence":4839273229,"time":"2018-07-27T01:32:42.360000Z"}
{"type":"open","side":"buy","price":"7894.00000000","order_id":"4c1fd8d8-80aa-4dd8-98bc-b8c01df83935","remaining_size":"0.20000000","product_id":"BTC-USD","sequence":6418130298,"time":"2018-07-27T01:32:42.363000Z"}
{"type":"done","side":"buy","order_id":"636d67b6-5ce2-4b38-af8b-6e782e6dd39f","reason":"canceled","product_id":"ETH-USD","price":"461.39000000","remaining_size":"3.86683100","sequence":4469354846,"time":"2018-07-27T01:32:42.362000Z"}
{"type":"received","order_id":"36cb09fb-6406-431e-8093-85422de00d57","order_type":"limit","size":"2.00000000","price":"794.37000000","side":"sell","client_oid":"fff2044a-d1c0-4160-90cf-f1d5dab1ca47","product_id":"BCH-USD","sequence":4839273230,"time":"2018-07-27T01:32:42.361000Z"}
{"type":"open","side":"sell","price":"794.37000000","order_id":"36cb09fb-6406-431e-8093-85422de00d57","remaining_size":"2.00000000","product_id":"BCH-USD","sequence":4839273231,"time":"2018-07-27T01:32:42.361000Z"}
{"type":"received","order_id":"95105b30-069a-4a03-b244-e041702176e0","order_type":"limit","size":"0.90000000","price":"795.04000000","side":"sell","client_oid":"4ae20b89-68ab-4900-8547-d3fcc3852589","product_id":"BCH-USD","sequence":4839273232,"time":"2018-07-27T01:32:42.364000Z"}
{"type":"open","side":"sell","price":"795.04000000","order_id":"95105b30-069a-4a03-b244-e041702176e0","remaining_size":"0.90000000","product_id":"BCH-USD","sequence":4839273233,"time":"2018-07-27T01:32:42.364000Z"}
{"type":"done","side":"buy","order_id":"05892a9e-b52d-4499-836a-93acaf49fb08","reason":"canceled","product_id":"ETH-USD","price":"461.25000000","remaining_size":"7.57706500","sequence":4469354847,"time":"2018-07-27T01:32:42.367000Z"}
{"type":"done","side":"sell","order_id":"fae14e7b-80b4-44ff-a58b-a8d85b7a8dd6","reason":"canceled","product_id":"BCH-USD","price":"795.05000000","remaining_size":"4.50000000","sequence":4839273234,"time":"2018-07-27T01:32:42.366000Z"}
{"type":"received","order_id":"7d99ae38-9879-4d89-b99e-f39695038ade","order_type":"limit","size":"1.90000000","price":"795.04000000","side":"sell","client_oid":"50757346-b535-4531-9b8e-4194f9cb903a","product_id":"BCH-USD","sequence":4839273235,"time":"2018-07-27T01:32:42.368000Z"}
{"type":"open","side":"sell","price":"795.04000000","order_id":"7d99ae38-9879-4d89-b99e-f39695038ade","remaining_size":"1.90000000","product_id":"BCH-USD","sequence":4839273236,"time":"2018-07-27T01:32:42.368000Z"}
{"type":"done","side":"buy","order_id":"0d1a7c33-e061-4477-8bd9-d2e758c1d7d0","reason":"canceled","product_id":"ETH-USD","price":"461.11000000","remaining_size":"7.05157600","sequence":4469354848,"time":"2018-07-27T01:32:42.370000Z"}
{"type":"received","order_id":"28fc39c4-b718-4252-b9b4-b6f121efbfc7","order_type":"limit","size":"0.90000000","price":"795.04000000","side":"sell","client_oid":"e12843b6-ad1c-4e3c-aa07-50c3827dcbbf","product_id":"BCH-USD","sequence":4839273237,"time":"2018-07-27T01:32:42.371000Z"}
{"type":"open","side":"sell","price":"795.04000000","order_id":"28fc39c4-b718-4252-b9b4-b6f121efbfc7","remaining_size":"0.90000000","product_id":"BCH-USD","sequence":4839273238,"time":"2018-07-27T01:32:42.371000Z"}
{"type":"done","side":"sell","order_id":"295a7896-2113-475d-b7df-4bdfa79e5b16","reason":"canceled","product_id":"LTC-USD","price":"83.34000000","remaining_size":"7.44874862","sequence":2423272089,"time":"2018-07-27T01:32:42.376000Z"}
{"type":"received","order_id":"26949349-5179-40d2-bad9-22ee68379a83","order_type":"limit","size":"4.50000000","price":"795.04000000","side":"sell","client_oid":"f6fead13-5ba8-41eb-b437-e95f3d3200bb","product_id":"BCH-USD","sequence":4839273239,"time":"2018-07-27T01:32:42.373000Z"}
{"type":"open","side":"sell","price":"795.04000000","order_id":"26949349-5179-40d2-bad9-22ee68379a83","remaining_size":"4.50000000","product_id":"BCH-USD","sequence":4839273240,"time":"2018-07-27T01:32:42.373000Z"}
{"type":"done","side":"sell","order_id":"9f364e11-a1eb-4783-9dd8-95156c37977e","reason":"canceled","product_id":"BCH-USD","price":"795.05000000","remaining_size":"0.90000000","sequence":4839273241,"time":"2018-07-27T01:32:42.374000Z"}
{"type":"received","order_id":"1a7b5fce-16bf-4041-bb9d-de483dc61957","order_type":"limit","size":"1.81488800","price":"791.25000000","side":"buy","client_oid":"938ce03a-0aac-4f63-868d-e8dd0f0dbecd","product_id":"BCH-USD","sequence":4839273242,"time":"2018-07-27T01:32:42.378000Z"}
{"type":"open","side":"buy","price":"791.25000000","order_id":"1a7b5fce-16bf-4041-bb9d-de483dc61957","remaining_size":"1.81488800","product_id":"BCH-USD","sequence":4839273243,"time":"2018-07-27T01:32:42.378000Z"}
{"type":"done","side":"buy","order_id":"1a7b5fce-16bf-4041-bb9d-de483dc61957","reason":"canceled","product_id":"BCH-USD","price":"791.25000000","remaining_size":"1.81488800","sequence":4839273244,"time":"2018-07-27T01:32:42.383000Z"}
{"type":"done","side":"sell","order_id":"26949349-5179-40d2-bad9-22ee68379a83","reason":"canceled","product_id":"BCH-USD","price":"795.04000000","remaining_size":"4.50000000","sequence":4839273245,"time":"2018-07-27T01:32:42.388000Z"}
{"type":"done","side":"sell","order_id":"7d99ae38-9879-4d89-b99e-f39695038ade","reason":"canceled","product_id":"BCH-USD","price":"795.04000000","remaining_size":"1.90000000","sequence":4839273246,"time":"2018-07-27T01:32:42.390000Z"}
{"type":"done","side":"buy","order_id":"64649299-907c-43bb-9ecd-e4145a67d532","reason":"canceled","product_id":"BCH-USD","price":"789.01000000","remaining_size":"12.39000000","sequence":4839273247,"time":"2018-07-27T01:32:42.391000Z"}
{"type":"done","side":"buy","order_id":"4661ea7b-2e61-4963-9194-465b7efa13a7","reason":"canceled","product_id":"BCH-USD","price":"791.23000000","remaining_size":"0.18739300","sequence":4839273248,"time":"2018-07-27T01:32:42.391000Z"}
{"type":"received","order_id":"372172de-b7f4-44a1-8803-b2c725e1fc0f","order_type":"limit","size":"1.81488800","price":"791.23000000","side":"buy","client_oid":"faf305b2-6600-447f-8179-90731752bad9","product_id":"BCH-USD","sequence":4839273249,"time":"2018-07-27T01:32:42.393000Z"}
{"type":"open","side":"buy","price":"791.23000000","order_id":"372172de-b7f4-44a1-8803-b2c725e1fc0f","remaining_size":"1.81488800","product_id":"BCH-USD","sequence":4839273250,"time":"2018-07-27T01:32:42.393000Z"}
{"type":"done","side":"sell","order_id":"95105b30-069a-4a03-b244-e041702176e0","reason":"canceled","product_id":"BCH-USD","price":"795.04000000","remaining_size":"0.90000000","sequence":4839273251,"time":"2018-07-27T01:32:42.394000Z"}
{"type":"received","order_id":"1d13c8fc-3f6f-431e-a32d-7543a064836a","order_type":"limit","size":"7.44874862","price":"83.38000000","side":"sell","client_oid":"3514b50c-7e33-44f7-8000-001809f4d3c4","product_id":"LTC-USD","sequence":2423272090,"time":"2018-07-27T01:32:42.397000Z"}
{"type":"open","side":"sell","price":"83.38000000","order_id":"1d13c8fc-3f6f-431e-a32d-7543a064836a","remaining_size":"7.44874862","product_id":"LTC-USD","sequence":2423272091,"time":"2018-07-27T01:32:42.397000Z"}
{"type":"received","order_id":"74f88f6c-fb2f-4c65-aace-986bf4c5aebe","order_type":"limit","size":"7.44874862","price":"83.30000000","side":"sell","client_oid":"e27c572a-d180-48dc-8000-0067d3ed9b83","product_id":"LTC-USD","sequence":2423272092,"time":"2018-07-27T01:32:42.398000Z"}
{"type":"open","side":"sell","price":"83.30000000","order_id":"74f88f6c-fb2f-4c65-aace-986bf4c5aebe","remaining_size":"7.44874862","product_id":"LTC-USD","sequence":2423272093,"time":"2018-07-27T01:32:42.398000Z"}
{"type":"received","order_id":"a563114e-a33f-4acc-b5af-a296e1d3be40","order_type":"limit","size":"10.81000000","price":"789.65000000","side":"buy","client_oid":"edb33905-8113-449c-9e06-77d4bb863db4","product_id":"BCH-USD","sequence":4839273252,"time":"2018-07-27T01:32:42.397000Z"}
{"type":"open","side":"buy","price":"789.65000000","order_id":"a563114e-a33f-4acc-b5af-a296e1d3be40","remaining_size":"10.81000000","product_id":"BCH-USD","sequence":4839273253,"time":"2018-07-27T01:32:42.397000Z"}
{"type":"received","order_id":"7e494bbf-a32e-412e-9947-b2f904c40224","order_type":"limit","size":"1.90000000","price":"795.03000000","side":"sell","client_oid":"150f35ba-3336-459f-b0e2-ea0bfaafe1bf","product_id":"BCH-USD","sequence":4839273254,"time":"2018-07-27T01:32:42.397000Z"}
{"type":"open","side":"sell","price":"795.03000000","order_id":"7e494bbf-a32e-412e-9947-b2f904c40224","remaining_size":"1.90000000","product_id":"BCH-USD","sequence":4839273255,"time":"2018-07-27T01:32:42.397000Z"}
{"type":"received","order_id":"946acb86-2875-4944-ae44-0cdc0c64b406","order_type":"limit","size":"4.50000000","price":"795.03000000","side":"sell","client_oid":"97267873-757b-4d04-b203-015142960a99","product_id":"BCH-USD","sequence":4839273256,"time":"2018-07-27T01:32:42.401000Z"}
{"type":"open","side":"sell","price":"795.03000000","order_id":"946acb86-2875-4944-ae44-0cdc0c64b406","remaining_size":"4.50000000","product_id":"BCH-USD","sequence":4839273257,"time":"2018-07-27T01:32:42.401000Z"}
{"type":"done","side":"sell","order_id":"7e494bbf-a32e-412e-9947-b2f904c40224","reason":"canceled","product_id":"BCH-USD","price":"795.03000000","remaining_size":"1.90000000","sequence":4839273258,"time":"2018-07-27T01:32:42.403000Z"}
{"type":"received","order_id":"03a95959-bfac-41ea-a2df-1bbd33087cbf","order_type":"limit","size":"0.18739300","price":"791.26000000","side":"buy","client_oid":"c59c37d7-8360-46c0-a082-2ae31fdf881c","product_id":"BCH-USD","sequence":4839273259,"time":"2018-07-27T01:32:42.404000Z"}
{"type":"open","side":"buy","price":"791.26000000","order_id":"03a95959-bfac-41ea-a2df-1bbd33087cbf","remaining_size":"0.18739300","product_id":"BCH-USD","sequence":4839273260,"time":"2018-07-27T01:32:42.404000Z"}
{"type":"received","order_id":"0f304d18-76c7-4a59-b334-895e5f40399b","order_type":"limit","size":"2.26731100","price":"461.39000000","side":"buy","client_oid":"e873b40d-de46-4ff4-b715-b90cf9a501a2","product_id":"ETH-USD","sequence":4469354849,"time":"2018-07-27T01:32:42.405000Z"}
{"type":"open","side":"buy","price":"461.39000000","order_id":"0f304d18-76c7-4a59-b334-895e5f40399b","remaining_size":"2.26731100","product_id":"ETH-USD","sequence":4469354850,"time":"2018-07-27T01:32:42.405000Z"}
{"type":"done","side":"sell","order_id":"946acb86-2875-4944-ae44-0cdc0c64b406","reason":"canceled","product_id":"BCH-USD","price":"795.03000000","remaining_size":"4.50000000","sequence":4839273261,"time":"2018-07-27T01:32:42.405000Z"}
{"type":"received","order_id":"8ff7e0e4-2626-4136-b802-64c2632b533d","order_type":"limit","size":"0.90000000","price":"795.03000000","side":"sell","client_oid":"6960ed05-3d2e-448b-8cfc-223e72c9d327","product_id":"BCH-USD","sequence":4839273262,"time":"2018-07-27T01:32:42.415000Z"}
{"type":"open","side":"sell","price":"795.03000000","order_id":"8ff7e0e4-2626-4136-b802-64c2632b533d","remaining_size":"0.90000000","product_id":"BCH-USD","sequence":4839273263,"time":"2018-07-27T01:32:42.415000Z"}
{"type":"received","order_id":"c6a952fd-0246-451e-bbe2-63f648241500","order_type":"limit","size":"4.01639300","price":"461.25000000","side":"buy","client_oid":"c5d1a870-708e-4ded-bd7a-ee2ed540244f","product_id":"ETH-USD","sequence":4469354851,"time":"2018-07-27T01:32:42.417000Z"}
{"type":"open","side":"buy","price":"461.25000000","order_id":"c6a952fd-0246-451e-bbe2-63f648241500","remaining_size":"4.01639300","product_id":"ETH-USD","sequence":4469354852,"time":"2018-07-27T01:32:42.417000Z"}
{"type":"done","side":"buy","order_id":"9d955487-af62-4568-9e0c-8aa052f081b5","reason":"canceled","product_id":"BTC-USD","price":"7885.00000000","remaining_size":"1.00000000","sequence":6418130299,"time":"2018-07-27T01:32:42.426000Z"}
{"type":"received","order_id":"9f1f0da1-2e36-4254-af03-74d4b28c3155","order_type":"limit","size":"12.21382100","price":"461.11000000","side":"buy","client_oid":"af9253b7-69ba-41c4-b2a4-cc66b22d41ec","product_id":"ETH-USD","sequence":4469354853,"time":"2018-07-27T01:32:42.431000Z"}
{"type":"open","side":"buy","price":"461.11000000","order_id":"9f1f0da1-2e36-4254-af03-74d4b28c3155","remaining_size":"12.21382100","product_id":"ETH-USD","sequence":4469354854,"time":"2018-07-27T01:32:42.431000Z"}
{"type":"received","order_id":"eed45521-f8f7-400d-a68c-cd7b277da9f8","order_type":"limit","size":"1.90000000","price":"795.04000000","side":"sell","client_oid":"12c94697-c5a3-43ca-be71-443330abd4b7","product_id":"BCH-USD","sequence":4839273264,"time":"2018-07-27T01:32:42.436000Z"}
{"type":"open","side":"sell","price":"795.04000000","order_id":"eed45521-f8f7-400d-a68c-cd7b277da9f8","remaining_size":"1.90000000","product_id":"BCH-USD","sequence":4839273265,"time":"2018-07-27T01:32:42.436000Z"}
{"type":"done","side":"buy","order_id":"03a95959-bfac-41ea-a2df-1bbd33087cbf","reason":"canceled","product_id":"BCH-USD","price":"791.26000000","remaining_size":"0.18739300","sequence":4839273266,"time":"2018-07-27T01:32:42.436000Z"}
{"type":"received","order_id":"e4795d02-f3b0-4609-a093-80ae43b203ae","order_type":"limit","size":"9.01200000","price":"795.03000000","side":"sell","product_id":"BCH-USD","sequence":4839273267,"time":"2018-07-27T01:32:42.438000Z"}
{"type":"open","side":"sell","price":"795.03000000","order_id":"e4795d02-f3b0-4609-a093-80ae43b203ae","remaining_size":"9.01200000","product_id":"BCH-USD","sequence":4839273268,"time":"2018-07-27T01:32:42.438000Z"}
{"type":"received","order_id":"36901a61-2a40-4bb5-b208-297dcd40ff84","order_type":"limit","size":"4.50000000","price":"795.04000000","side":"sell","client_oid":"0a7df88a-5919-470a-87c1-0c0a794d8106","product_id":"BCH-USD","sequence":4839273269,"time":"2018-07-27T01:32:42.438000Z"}
{"type":"open","side":"sell","price":"795.04000000","order_id":"36901a61-2a40-4bb5-b208-297dcd40ff84","remaining_size":"4.50000000","product_id":"BCH-USD","sequence":4839273270,"time":"2018-07-27T01:32:42.438000Z"}
{"type":"received","order_id":"4f01cdd8-a273-4346-8a37-2f05369a7374","order_type":"limit","size":"0.18739300","price":"791.24000000","side":"buy","client_oid":"bb461033-d23b-4885-a594-754476372e92","product_id":"BCH-USD","sequence":4839273271,"time":"2018-07-27T01:32:42.442000Z"}
{"type":"open","side":"buy","price":"791.24000000","order_id":"4f01cdd8-a273-4346-8a37-2f05369a7374","remaining_size":"0.18739300","product_id":"BCH-USD","sequence":4839273272,"time":"2018-07-27T01:32:42.442000Z"}
{"type":"done","side":"sell","order_id":"eed45521-f8f7-400d-a68c-cd7b277da9f8","reason":"canceled","product_id":"BCH-USD","price":"795.04000000","remaining_size":"1.90000000","sequence":4839273273,"time":"2018-07-27T01:32:42.442000Z"}
{"type":"done","side":"sell","order_id":"36901a61-2a40-4bb5-b208-297dcd40ff84","reason":"canceled","product_id":"BCH-USD","price":"795.04000000","remaining_size":"4.50000000","sequence":4839273274,"time":"2018-07-27T01:32:42.442000Z"}
{"type":"done","side":"buy","order_id":"372172de-b7f4-44a1-8803-b2c725e1fc0f","reason":"canceled","product_id":"BCH-USD","price":"791.23000000","remaining_size":"1.81488800","sequence":4839273275,"time":"2018-07-27T01:32:42.444000Z"}
{"type":"received","order_id":"77f82c4a-6274-49aa-9acb-a9cc5a7e2233","order_type":"limit","size":"1.90000000","price":"795.03000000","side":"sell","client_oid":"a717a756-ed48-43a1-9127-5cf211244ab9","product_id":"BCH-USD","sequence":4839273276,"time":"2018-07-27T01:32:42.450000Z"}
{"type":"open","side":"sell","price":"795.03000000","order_id":"77f82c4a-6274-49aa-9acb-a9cc5a7e2233","remaining_size":"1.90000000","product_id":"BCH-USD","sequence":4839273277,"time":"2018-07-27T01:32:42.450000Z"}
{"type":"done","side":"sell","order_id":"28fc39c4-b718-4252-b9b4-b6f121efbfc7","reason":"canceled","product_id":"BCH-USD","price":"795.04000000","remaining_size":"0.90000000","sequence":4839273278,"time":"2018-07-27T01:32:42.453000Z"}
{"type":"done","side":"sell","order_id":"77f82c4a-6274-49aa-9acb-a9cc5a7e2233","reason":"canceled","product_id":"BCH-USD","price":"795.03000000","remaining_size":"1.90000000","sequence":4839273279,"time":"2018-07-27T01:32:42.457000Z"}
{"type":"done","side":"buy","order_id":"4f01cdd8-a273-4346-8a37-2f05369a7374","reason":"canceled","product_id":"BCH-USD","price":"791.24000000","remaining_size":"0.18739300","sequence":4839273280,"time":"2018-07-27T01:32:42.458000Z"}
{"type":"done","side":"sell","order_id":"8ff7e0e4-2626-4136-b802-64c2632b533d","reason":"canceled","product_id":"BCH-USD","price":"795.03000000","remaining_size":"0.90000000","sequence":4839273281,"time":"2018-07-27T01:32:42.459000Z"}
{"type":"received","order_id":"3a9c7a35-5835-4984-92e7-12755d5c9b45","order_type":"limit","size":"1.81488800","price":"791.24000000","side":"buy","client_oid":"8717ee93-fd70-4502-991e-b5c9ad45dc8f","product_id":"BCH-USD","sequence":4839273282,"time":"2018-07-27T01:32:42.462000Z"}
{"type":"open","side":"buy","price":"791.24000000","order_id":"3a9c7a35-5835-4984-92e7-12755d5c9b45","remaining_size":"1.81488800","product_id":"BCH-USD","sequence":4839273283,"time":"2018-07-27T01:32:42.462000Z"}
{"type":"received","order_id":"9032eacf-80e6-490a-9232-ce9a405e0c71","order_type":"limit","size":"0.90000000","price":"795.02000000","side":"sell","client_oid":"0cb89adc-86a6-4993-a092-c9c8c641fd2e","product_id":"BCH-USD","sequence":4839273284,"time":"2018-07-27T01:32:42.462000Z"}
{"type":"open","side":"sell","price":"795.02000000","order_id":"9032eacf-80e6-490a-9232-ce9a405e0c71","remaining_size":"0.90000000","product_id":"BCH-USD","sequence":4839273285,"time":"2018-07-27T01:32:42.462000Z"}
{"type":"received","order_id":"e465f693-ff6a-427e-b4dd-06df07b22b8e","order_type":"limit","size":"0.90000000","price":"795.03000000","side":"sell","client_oid":"3efa48c7-34ca-44c2-a255-2cd255a7e1e4","product_id":"BCH-USD","sequence":4839273286,"time":"2018-07-27T01:32:42.465000Z"}
{"type":"open","side":"sell","price":"795.03000000","order_id":"e465f693-ff6a-427e-b4dd-06df07b22b8e","remaining_size":"0.90000000","product_id":"BCH-USD","sequence":4839273287,"time":"2018-07-27T01:32:42.465000Z"}
{"type":"received","order_id":"cc4ff92e-d3ea-4adc-941c-357e4fa68c6e","order_type":"limit","size":"4.50000000","price":"795.03000000","side":"sell","client_oid":"fdf25030-4eab-442c-931f-4808db02b688","product_id":"BCH-USD","sequence":4839273288,"time":"2018-07-27T01:32:42.465000Z"}
{"type":"open","side":"sell","price":"795.03000000","order_id":"cc4ff92e-d3ea-4adc-941c-357e4fa68c6e","remaining_size":"4.50000000","product_id":"BCH-USD","sequence":4839273289,"time":"2018-07-27T01:32:42.465000Z"}
{"type":"done","side":"sell","order_id":"e390b9e8-a3dd-4495-8e13-25051cdefca3","reason":"canceled","product_id":"BCH-USD","price":"795.29000000","remaining_size":"1.90000000","sequence":4839273290,"time":"2018-07-27T01:32:42.466000Z"}
{"type":"received","order_id":"c1981e75-26d8-4676-9978-7b54e901710f","order_type":"limit","size":"1.90000000","price":"795.02000000","side":"sell","client_oid":"d5aea35e-96b7-4984-8d6c-dafd9cf4eeb3","product_id":"BCH-USD","sequence":4839273291,"time":"2018-07-27T01:32:42.468000Z"}
{"type":"open","side":"sell","price":"795.02000000","order_id":"c1981e75-26d8-4676-9978-7b54e901710f","remaining_size":"1.90000000","product_id":"BCH-USD","sequence":4839273292,"time":"2018-07-27T01:32:42.468000Z"}
{"type":"done","side":"sell","order_id":"cc4ff92e-d3ea-4adc-941c-357e4fa68c6e","reason":"canceled","product_id":"BCH-USD","price":"795.03000000","remaining_size":"4.50000000","sequence":4839273293,"time":"2018-07-27T01:32:42.469000Z"}
{"type":"done","side":"sell","order_id":"e465f693-ff6a-427e-b4dd-06df07b22b8e","reason":"canceled","product_id":"BCH-USD","price":"795.03000000","remaining_size":"0.90000000","sequence":4839273294,"time":"2018-07-27T01:32:42.470000Z"}
{"type":"done","side":"buy","order_id":"3a9c7a35-5835-4984-92e7-12755d5c9b45","reason":"canceled","product_id":"BCH-USD","price":"791.24000000","remaining_size":"1.81488800","sequence":4839273295,"time":"2018-07-27T01:32:42.473000Z"}
{"type":"received","order_id":"137376c2-79c8-4ec7-8dc0-189c63a7e9a7","order_type":"limit","size":"1.90000000","price":"795.13000000","side":"sell","client_oid":"73bf9799-f4d0-4df4-b3f2-e79e86c9362b","product_id":"BCH-USD","sequence":4839273296,"time":"2018-07-27T01:32:42.476000Z"}
{"type":"open","side":"sell","price":"795.13000000","order_id":"137376c2-79c8-4ec7-8dc0-189c63a7e9a7","remaining_size":"1.90000000","product_id":"BCH-USD","sequence":4839273297,"time":"2018-07-27T01:32:42.476000Z"}
{"type":"received","order_id":"e21d7b96-ad9f-44d6-971e-4809e6dd57c7","order_type":"limit","size":"0.18739300","price":"791.23000000","side":"buy","client_oid":"1004f272-a0ef-4900-8891-9cb4a752cd49","product_id":"BCH-USD","sequence":4839273298,"time":"2018-07-27T01:32:42.476000Z"}
{"type":"open","side":"buy","price":"791.23000000","order_id":"e21d7b96-ad9f-44d6-971e-4809e6dd57c7","remaining_size":"0.18739300","product_id":"BCH-USD","sequence":4839273299,"time":"2018-07-27T01:32:42.476000Z"}
{"type":"done","side":"sell","order_id":"c1981e75-26d8-4676-9978-7b54e901710f","reason":"canceled","product_id":"BCH-USD","price":"795.02000000","remaining_size":"1.90000000","sequence":4839273300,"time":"2018-07-27T01:32:42.480000Z"}
{"type":"done","side":"buy","order_id":"e21d7b96-ad9f-44d6-971e-4809e6dd57c7","reason":"canceled","product_id":"BCH-USD","price":"791.23000000","remaining_size":"0.18739300","sequence":4839273301,"time":"2018-07-27T01:32:42.481000Z"}
{"type":"done","side":"sell","order_id":"137376c2-79c8-4ec7-8dc0-189c63a7e9a7","reason":"canceled","product_id":"BCH-USD","price":"795.13000000","remaining_size":"1.90000000","sequence":4839273302,"time":"2018-07-27T01:32:42.481000Z"}
{"type":"received","order_id":"ebd11862-1571-41f1-9396-4c55f1e85137","order_type":"limit","size":"0.90000000","price":"795.02000000","side":"sell","client_oid":"37c180e1-bda9-4d53-9970-6d8b272768bb","product_id":"BCH-USD","sequence":4839273303,"time":"2018-07-27T01:32:42.482000Z"}
{"type":"open","side":"sell","price":"795.02000000","order_id":"ebd11862-1571-41f1-9396-4c55f1e85137","remaining_size":"0.90000000","product_id":"BCH-USD","sequence":4839273304,"time":"2018-07-27T01:32:42.482000Z"}
{"type":"received","order_id":"5b9c4e3e-a7d7-4660-a60b-36ca381ee769","order_type":"limit","size":"4.50000000","price":"795.02000000","side":"sell","client_oid":"50b95a57-38f9-4d83-bc5f-e00e21e1ac1d","product_id":"BCH-USD","sequence":4839273305,"time":"2018-07-27T01:32:42.486000Z"}
{"type":"open","side":"sell","price":"795.02000000","order_id":"5b9c4e3e-a7d7-4660-a60b-36ca381ee769","remaining_size":"4.50000000","product_id":"BCH-USD","sequence":4839273306,"time":"2018-07-27T01:32:42.486000Z"}
{"type":"received","order_id":"6caf840d-3ccc-4050-a88c-5b581f9a22bd","order_type":"limit","size":"1.81488800","price":"791.23000000","side":"buy","client_oid":"cb84976d-054d-40e5-9583-dd68ce1aaa5f","product_id":"BCH-USD","sequence":4839273307,"time":"2018-07-27T01:32:42.488000Z"}
{"type":"open","side":"buy","price":"791.23000000","order_id":"6caf840d-3ccc-4050-a88c-5b581f9a22bd","remaining_size":"1.81488800","product_id":"BCH-USD","sequence":4839273308,"time":"2018-07-27T01:32:42.488000Z"}
{"type":"done","side":"sell","order_id":"5b9c4e3e-a7d7-4660-a60b-36ca381ee769","reason":"canceled","product_id":"BCH-USD","price":"795.02000000","remaining_size":"4.50000000","sequence":4839273309,"time":"2018-07-27T01:32:42.489000Z"}
{"type":"done","side":"sell","order_id":"9032eacf-80e6-490a-9232-ce9a405e0c71","reason":"canceled","product_id":"BCH-USD","price":"795.02000000","remaining_size":"0.90000000","sequence":4839273310,"time":"2018-07-27T01:32:42.492000Z"}
{"type":"received","order_id":"4efcd202-afb8-4720-ab48-7d3f5ffb83d9","order_type":"limit","size":"1.90000000","price":"795.29000000","side":"sell","client_oid":"14b25474-d87b-4285-ad6c-1af3c9102ad6","product_id":"BCH-USD","sequence":4839273311,"time":"2018-07-27T01:32:42.496000Z"}
{"type":"open","side":"sell","price":"795.29000000","order_id":"4efcd202-afb8-4720-ab48-7d3f5ffb83d9","remaining_size":"1.90000000","product_id":"BCH-USD","sequence":4839273312,"time":"2018-07-27T01:32:42.496000Z"}
{"type":"received","order_id":"9c44b945-f7d2-4384-aa4f-caf0cb7da8f0","order_type":"limit","size":"0.18739300","price":"791.25000000","side":"buy","client_oid":"1cb0e30a-5cc0-40ea-ab2f-5979b3d7d975","product_id":"BCH-USD","sequence":4839273313,"time":"2018-07-27T01:32:42.498000Z"}
{"type":"open","side":"buy","price":"791.25000000","order_id":"9c44b945-f7d2-4384-aa4f-caf0cb7da8f0","remaining_size":"0.18739300","product_id":"BCH-USD","sequence":4839273314,"time":"2018-07-27T01:32:42.498000Z"}
{"type":"received","order_id":"68d0c422-29fd-4e75-8fbc-a6df6af99de6","order_type":"limit","size":"1.90000000","price":"795.01000000","side":"sell","client_oid":"9a4ce6b0-4192-4c12-9eac-1330563c9833","product_id":"BCH-USD","sequence":4839273315,"time":"2018-07-27T01:32:42.498000Z"}
{"type":"open","side":"sell","price":"795.01000000","order_id":"68d0c422-29fd-4e75-8fbc-a6df6af99de6","remaining_size":"1.90000000","product_id":"BCH-USD","sequence":4839273316,"time":"2018-07-27T01:32:42.498000Z"}
{"type":"done","side":"sell","order_id":"ebd11862-1571-41f1-9396-4c55f1e85137","reason":"canceled","product_id":"BCH-USD","price":"795.02000000","remaining_size":"0.90000000","sequence":4839273317,"time":"2018-07-27T01:32:42.500000Z"}
{"type":"done","side":"sell","order_id":"4efcd202-afb8-4720-ab48-7d3f5ffb83d9","reason":"canceled","product_id":"BCH-USD","price":"795.29000000","remaining_size":"1.90000000","sequence":4839273318,"time":"2018-07-27T01:32:42.500000Z"}
{"type":"done","side":"sell","order_id":"68d0c422-29fd-4e75-8fbc-a6df6af99de6","reason":"canceled","product_id":"BCH-USD","price":"795.01000000","remaining_size":"1.90000000","sequence":4839273319,"time":"2018-07-27T01:32:42.502000Z"}
{"type":"done","side":"buy","order_id":"9c44b945-f7d2-4384-aa4f-caf0cb7da8f0","reason":"canceled","product_id":"BCH-USD","price":"791.25000000","remaining_size":"0.18739300","sequence":4839273320,"time":"2018-07-27T01:32:42.504000Z"}
{"type":"received","order_id":"f1f51f9f-e2b0-4d2e-82f5-231e5c5347d3","order_type":"limit","size":"0.90000000","price":"795.01000000","side":"sell","client_oid":"3722e2f9-9b46-4380-bf65-1dcb8c263ba7","product_id":"BCH-USD","sequence":4839273321,"time":"2018-07-27T01:32:42.506000Z"}
{"type":"open","side":"sell","price":"795.01000000","order_id":"f1f51f9f-e2b0-4d2e-82f5-231e5c5347d3","remaining_size":"0.90000000","product_id":"BCH-USD","sequence":4839273322,"time":"2018-07-27T01:32:42.506000Z"}
{"type":"received","order_id":"2e6b734c-eacc-4044-ad31-1a32255f4260","order_type":"limit","size":"4.50000000","price":"795.01000000","side":"sell","client_oid":"4ae208ae-ee77-42ef-bbdc-ad4b51d12853","product_id":"BCH-USD","sequence":4839273323,"time":"2018-07-27T01:32:42.507000Z"}
{"type":"open","side":"sell","price":"795.01000000","order_id":"2e6b734c-eacc-4044-ad31-1a32255f4260","remaining_size":"4.50000000","product_id":"BCH-USD","sequence":4839273324,"time":"2018-07-27T01:32:42.507000Z"}
{"type":"done","side":"sell","order_id":"f1f51f9f-e2b0-4d2e-82f5-231e5c5347d3","reason":"canceled","product_id":"BCH-USD","price":"795.01000000","remaining_size":"0.90000000","sequence":4839273325,"time":"2018-07-27T01:32:42.509000Z"}
{"type":"received","order_id":"d74187b1-f877-4b8e-8b5d-70e1c5c409d7","order_type":"limit","size":"1.90000000","price":"795.13000000","side":"sell","client_oid":"21f51fcf-45ae-413c-ba43-98351caf12f0","product_id":"BCH-USD","sequence":4839273326,"time":"2018-07-27T01:32:42.510000Z"}
{"type":"open","side":"sell","price":"795.13000000","order_id":"d74187b1-f877-4b8e-8b5d-70e1c5c409d7","remaining_size":"1.90000000","product_id":"BCH-USD","sequence":4839273327,"time":"2018-07-27T01:32:42.510000Z"}
{"type":"received","order_id":"e4f11a13-70d5-4090-ab19-bbeb033e40aa","order_type":"limit","size":"0.90000000","price":"795.01000000","side":"sell","client_oid":"cc0b6440-548d-4b5e-a331-75096b696e47","product_id":"BCH-USD","sequence":4839273328,"time":"2018-07-27T01:32:42.513000Z"}
{"type":"open","side":"sell","price":"795.01000000","order_id":"e4f11a13-70d5-4090-ab19-bbeb033e40aa","remaining_size":"0.90000000","product_id":"BCH-USD","sequence":4839273329,"time":"2018-07-27T01:32:42.513000Z"}
{"type":"done","side":"buy","order_id":"6caf840d-3ccc-4050-a88c-5b581f9a22bd","reason":"canceled","product_id":"BCH-USD","price":"791.23000000","remaining_size":"1.81488800","sequence":4839273330,"time":"2018-07-27T01:32:42.514000Z"}
{"type":"received","order_id":"fdd2c844-0594-49f8-a89c-f308b45c8b8f","order_type":"limit","size":"1.90000000","price":"795.02000000","side":"sell","client_oid":"1c0a2d8e-7a6c-456f-b98d-e374b24160ef","product_id":"BCH-USD","sequence":4839273331,"time":"2018-07-27T01:32:42.516000Z"}
{"type":"open","side":"sell","price":"795.02000000","order_id":"fdd2c844-0594-49f8-a89c-f308b45c8b8f","remaining_size":"1.90000000","product_id":"BCH-USD","sequence":4839273332,"time":"2018-07-27T01:32:42.516000Z"}
{"type":"done","side":"sell","order_id":"e4f11a13-70d5-4090-ab19-bbeb033e40aa","reason":"canceled","product_id":"BCH-USD","price":"795.01000000","remaining_size":"0.90000000","sequence":4839273333,"time":"2018-07-27T01:32:42.517000Z"}
{"type":"done","side":"sell","order_id":"d74187b1-f877-4b8e-8b5d-70e1c5c409d7","reason":"canceled","product_id":"BCH-USD","price":"795.13000000","remaining_size":"1.90000000","sequence":4839273334,"time":"2018-07-27T01:32:42.519000Z"}
{"type":"done","side":"sell","order_id":"fdd2c844-0594-49f8-a89c-f308b45c8b8f","reason":"canceled","product_id":"BCH-USD","price":"795.02000000","remaining_size":"1.90000000","sequence":4839273335,"time":"2018-07-27T01:32:42.525000Z"}
{"type":"done","side":"sell","order_id":"409a61e1-d080-4523-a03e-2415129b076c","reason":"canceled","product_id":"BCH-USD","price":"795.06000000","remaining_size":"9.01200000","sequence":4839273336,"time":"2018-07-27T01:32:42.527000Z"}
{"type":"done","side":"sell","order_id":"2e6b734c-eacc-4044-ad31-1a32255f4260","reason":"canceled","product_id":"BCH-USD","price":"795.01000000","remaining_size":"4.50000000","sequence":4839273337,"time":"2018-07-27T01:32:42.535000Z"}
{"type":"done","side":"sell","order_id":"74f88f6c-fb2f-4c65-aace-986bf4c5aebe","reason":"canceled","product_id":"LTC-USD","price":"83.30000000","remaining_size":"7.44874862","sequence":2423272094,"time":"2018-07-27T01:32:42.597000Z"}
{"type":"done","side":"buy","order_id":"c42818cb-8270-4ec7-98df-877572e08fb1","reason":"canceled","product_id":"ETH-USD","price":"436.72000000","remaining_size":"0.06621800","sequence":4469354855,"time":"2018-07-27T01:32:42.663000Z"}
{"type":"done","side":"sell","order_id":"36cb09fb-6406-431e-8093-85422de00d57","reason":"canceled","product_id":"BCH-USD","price":"794.37000000","remaining_size":"2.00000000","sequence":4839273338,"time":"2018-07-27T01:32:42.708000Z"}
{"type":"received","order_id":"fe4c8224-07d7-4359-ba42-6a0fd78e4d8d","order_type":"limit","size":"1.00000000","price":"7895.00000000","side":"buy","client_oid":"3ade0059-5e9b-4674-bff4-6203173e4a8b","product_id":"BTC-USD","sequence":6418130300,"time":"2018-07-27T01:32:42.757000Z"}
{"type":"open","side":"buy","price":"7895.00000000","order_id":"fe4c8224-07d7-4359-ba42-6a0fd78e4d8d","remaining_size":"1.00000000","product_id":"BTC-USD","sequence":6418130301,"time":"2018-07-27T01:32:42.757000Z"}
{"type":"received","order_id":"bfb6db40-6f62-41ed-bb3b-7622f91e7af1","order_type":"limit","size":"0.12636019","price":"8051.74000000","side":"buy","client_oid":"5b2850e9-fdc7-4956-8817-0d1ba31588bc","product_id":"BTC-USD","sequence":6418130302,"time":"2018-07-27T01:32:42.757000Z"}
{"type":"match","trade_id":47446110,"maker_order_id":"2797376b-a7bf-4cf0-82d7-0f8e918e7d8b","taker_order_id":"bfb6db40-6f62-41ed-bb3b-7622f91e7af1","side":"sell","size":"0.12636019","price":"7896.01000000","product_id":"BTC-USD","sequence":6418130303,"time":"2018-07-27T01:32:42.757000Z"}
{"type":"done","side":"buy","order_id":"bfb6db40-6f62-41ed-bb3b-7622f91e7af1","reason":"filled","product_id":"BTC-USD","price":"8051.74000000","remaining_size":"0.00000000","sequence":6418130304,"time":"2018-07-27T01:32:42.757000Z"}
{"type":"received","order_id":"2877e0b5-3878-4406-a064-c5618cf6b012","order_type":"limit","size":"0.30000000","price":"462.77000000","side":"sell","client_oid":"e368b735-adf1-4026-9f44-d2219214b1e7","product_id":"ETH-USD","sequence":4469354856,"time":"2018-07-27T01:32:42.759000Z"}
{"type":"open","side":"sell","price":"462.77000000","order_id":"2877e0b5-3878-4406-a064-c5618cf6b012","remaining_size":"0.30000000","product_id":"ETH-USD","sequence":4469354857,"time":"2018-07-27T01:32:42.759000Z"}
{"type":"received","order_id":"3646b555-4c6f-4308-91a0-fb71dd0b28ba","order_type":"limit","size":"2.00000000","price":"794.37000000","side":"sell","client_oid":"7e928974-488d-4e87-9a5f-8a6b96591eb9","product_id":"BCH-USD","sequence":4839273339,"time":"2018-07-27T01:32:42.760000Z"}
{"type":"open","side":"sell","price":"794.37000000","order_id":"3646b555-4c6f-4308-91a0-fb71dd0b28ba","remaining_size":"2.00000000","product_id":"BCH-USD","sequence":4839273340,"time":"2018-07-27T01:32:42.760000Z"}
{"type":"received","order_id":"7d9f1f13-1b8d-4305-917a-8de0d7e48684","order_type":"limit","size":"0.90000000","price":"795.02000000","side":"sell","client_oid":"190671c0-391c-483b-8143-bddd064245b7","product_id":"BCH-USD","sequence":4839273341,"time":"2018-07-27T01:32:42.761000Z"}
{"type":"received","order_id":"d20a84f4-585a-4876-8516-8ee48e57b46c","order_type":"limit","size":"7.44874862","price":"83.34000000","side":"sell","client_oid":"77b45b51-e0e3-4c61-8000-0bdd44203c70","product_id":"LTC-USD","sequence":2423272095,"time":"2018-07-27T01:32:42.763000Z"}
{"type":"open","side":"sell","price":"795.02000000","order_id":"7d9f1f13-1b8d-4305-917a-8de0d7e48684","remaining_size":"0.90000000","product_id":"BCH-USD","sequence":4839273342,"time":"2018-07-27T01:32:42.761000Z"}
{"type":"open","side":"sell","price":"83.34000000","order_id":"d20a84f4-585a-4876-8516-8ee48e57b46c","remaining_size":"7.44874862","product_id":"LTC-USD","sequence":2423272096,"time":"2018-07-27T01:32:42.763000Z"}
{"type":"received","order_id":"fd7395d2-a4cf-4dc7-ba81-ce0031d62adc","order_type":"limit","size":"0.01000000","price":"462.39000000","side":"buy","client_oid":"f4dabfcc-913c-11e8-8d2c-16be7828d23e","product_id":"ETH-USD","sequence":4469354858,"time":"2018-07-27T01:32:42.764000Z"}
{"type":"done","side":"buy","order_id":"fd7395d2-a4cf-4dc7-ba81-ce0031d62adc","reason":"canceled","product_id":"ETH-USD","price":"462.39000000","remaining_size":"0.01000000","sequence":4469354859,"time":"2018-07-27T01:32:42.764000Z"}
{"type":"done","side":"buy","order_id":"88e31317-dd52-487c-8ed2-a1d6ba9a0ea1","reason":"canceled","product_id":"LTC-USD","price":"83.03000000","remaining_size":"4.00725100","sequence":2423272097,"time":"2018-07-27T01:32:42.777000Z"}
{"type":"done","side":"buy","order_id":"ec113ba8-d273-4a06-a280-8b64da9edf34","reason":"canceled","product_id":"LTC-USD","price":"83.01000000","remaining_size":"7.39504000","sequence":2423272098,"time":"2018-07-27T01:32:42.781000Z"}
{"type":"done","side":"buy","order_id":"57c68b14-b789-4588-bf5e-fa4420d2b89a","reason":"canceled","product_id":"LTC-USD","price":"82.95000000","remaining_size":"25.06599100","sequence":2423272099,"time":"2018-07-27T01:32:42.784000Z"}
{"type":"received","order_id":"00f3dbb5-cf35-4391-847d-2622f4623320","order_type":"limit","size":"0.50000000","price":"6000.00000000","side":"buy","client_oid":"73d04a50-199d-4e72-8da0-be7d916877fd","product_id":"BTC-USD","sequence":6418130305,"time":"2018-07-27T01:32:42.787000Z"}
{"type":"open","side":"buy","price":"6000.00000000","order_id":"00f3dbb5-cf35-4391-847d-2622f4623320","remaining_size":"0.50000000","product_id":"BTC-USD","sequence":6418130306,"time":"2018-07-27T01:32:42.787000Z"}
{"type":"received","order_id":"b3a13bb5-8b83-4810-bf97-8366fcea329a","order_type":"limit","size":"1.81488800","price":"791.24000000","side":"buy","client_oid":"28d0b840-13f9-4407-8469-0a150f64b344","product_id":"BCH-USD","sequence":4839273343,"time":"2018-07-27T01:32:42.786000Z"}
{"type":"open","side":"buy","price":"791.24000000","order_id":"b3a13bb5-8b83-4810-bf97-8366fcea329a","remaining_size":"1.81488800","product_id":"BCH-USD","sequence":4839273344,"time":"2018-07-27T01:32:42.786000Z"}
{"type":"done","side":"buy","order_id":"0c87e408-8bd6-4a32-b64a-d4696d224147","reason":"canceled","product_id":"LTC-USD","price":"82.93000000","remaining_size":"97.23664300","sequence":2423272100,"time":"2018-07-27T01:32:42.788000Z"}
{"type":"done","side":"buy","order_id":"e6b427a3-ea75-4726-a4f1-3e6112e9ab87","reason":"canceled","product_id":"ETH-USD","price":"451.27000000","remaining_size":"0.10000000","sequence":4469354860,"time":"2018-07-27T01:32:42.787000Z"}
{"type":"received","order_id":"4eecca65-e099-44d4-a20d-8b6718f63189","order_type":"limit","size":"1.90000000","price":"795.29000000","side":"sell","client_oid":"f0e1cad5-d52f-4dc8-976e-5699f0b44be5","product_id":"BCH-USD","sequence":4839273345,"time":"2018-07-27T01:32:42.788000Z"}
{"type":"open","side":"sell","price":"795.29000000","order_id":"4eecca65-e099-44d4-a20d-8b6718f63189","remaining_size":"1.90000000","product_id":"BCH-USD","sequence":4839273346,"time":"2018-07-27T01:32:42.788000Z"}
{"type":"received","order_id":"d07da73d-54b1-43cf-9151-a461d67b173b","order_type":"limit","size":"0.90000000","price":"795.02000000","side":"sell","client_oid":"7a3d9606-b1ab-40aa-a589-1aaadfe10a30","product_id":"BCH-USD","sequence":4839273347,"time":"2018-07-27T01:32:42.790000Z"}
{"type":"done","side":"buy","order_id":"854f7af2-2774-4aa3-874c-376a0fa8ad4e","reason":"canceled","product_id":"LTC-USD","price":"82.91000000","remaining_size":"136.38121400","sequence":2423272101,"time":"2018-07-27T01:32:42.792000Z"}
{"type":"open","side":"sell","price":"795.02000000","order_id":"d07da73d-54b1-43cf-9151-a461d67b173b","remaining_size":"0.90000000","product_id":"BCH-USD","sequence":4839273348,"time":"2018-07-27T01:32:42.790000Z"}
{"type":"done","side":"sell","order_id":"4a2ee598-fe6c-4f4e-8279-6343a5352085","reason":"canceled","product_id":"LTC-USD","price":"83.29000000","remaining_size":"20.72693600","sequence":2423272102,"time":"2018-07-27T01:32:42.796000Z"}
{"type":"done","side":"sell","order_id":"f119d481-22c4-4d63-ac53-e5dd2e9dd79f","reason":"canceled","product_id":"LTC-USD","price":"83.30000000","remaining_size":"20.66630200","sequence":2423272103,"time":"2018-07-27T01:32:42.799000Z"}
{"type":"done","side":"buy","order_id":"b3a13bb5-8b83-4810-bf97-8366fcea329a","reason":"canceled","product_id":"BCH-USD","price":"791.24000000","remaining_size":"1.81488800","sequence":4839273349,"time":"2018-07-27T01:32:42.797000Z"}
{"type":"received","order_id":"55d2593f-fd84-4f83-9548-22591fd28f37","order_type":"limit","size":"0.18739300","price":"791.24000000","side":"buy","client_oid":"42e69204-e1c0-4187-bf74-656a474d5b8b","product_id":"BCH-USD","sequence":4839273350,"time":"2018-07-27T01:32:42.799000Z"}
{"type":"open","side":"buy","price":"791.24000000","order_id":"55d2593f-fd84-4f83-9548-22591fd28f37","remaining_size":"0.18739300","product_id":"BCH-USD","sequence":4839273351,"time":"2018-07-27T01:32:42.799000Z"}
{"type":"done","side":"sell","order_id":"c9479b01-c825-4114-bf6f-5f3e17a972ae","reason":"canceled","product_id":"LTC-USD","price":"83.32000000","remaining_size":"22.20393100","sequence":2423272104,"time":"2018-07-27T01:32:42.803000Z"}
{"type":"done","side":"buy","order_id":"55d2593f-fd84-4f83-9548-22591fd28f37","reason":"canceled","product_id":"BCH-USD","price":"791.24000000","remaining_size":"0.18739300","sequence":4839273352,"time":"2018-07-27T01:32:42.803000Z"}
{"type":"received","order_id":"17e39ed4-ab41-4c6d-bc40-a316e646fa61","order_type":"limit","size":"1.90000000","price":"795.00000000","side":"sell","client_oid":"d43570bf-a8ab-4726-95d2-083d4a20f0c5","product_id":"BCH-USD","sequence":4839273353,"time":"2018-07-27T01:32:42.803000Z"}
{"type":"open","side":"sell","price":"795.00000000","order_id":"17e39ed4-ab41-4c6d-bc40-a316e646fa61","remaining_size":"1.90000000","product_id":"BCH-USD","sequence":4839273354,"time":"2018-07-27T01:32:42.803000Z"}
{"type":"done","side":"sell","order_id":"97651a00-713d-463e-8d19-d88b3079a38e","reason":"canceled","product_id":"LTC-USD","price":"83.34000000","remaining_size":"110.59878700","sequence":2423272105,"time":"2018-07-27T01:32:42.807000Z"}
{"type":"done","side":"buy","order_id":"63caedec-cfcc-4226-9bf3-04e01d19c1a3","reason":"canceled","product_id":"ETH-USD","price":"421.50000000","remaining_size":"0.16000000","sequence":4469354861,"time":"2018-07-27T01:32:42.807000Z"}
{"type":"done","side":"sell","order_id":"d07da73d-54b1-43cf-9151-a461d67b173b","reason":"canceled","product_id":"BCH-USD","price":"795.02000000","remaining_size":"0.90000000","sequence":4839273355,"time":"2018-07-27T01:32:42.806000Z"}
{"type":"done","side":"sell","order_id":"7d9f1f13-1b8d-4305-917a-8de0d7e48684","reason":"canceled","product_id":"BCH-USD","price":"795.02000000","remaining_size":"0.90000000","sequence":4839273356,"time":"2018-07-27T01:32:42.808000Z"}
{"type":"done","side":"sell","order_id":"17e39ed4-ab41-4c6d-bc40-a316e646fa61","reason":"canceled","product_id":"BCH-USD","price":"795.00000000","remaining_size":"1.90000000","sequence":4839273357,"time":"2018-07-27T01:32:42.809000Z"}
{"type":"received","order_id":"81a4304c-ad4e-40af-a4da-7e9b54cd90d8","order_type":"limit","size":"1.81488800","price":"791.23000000","side":"buy","client_oid":"30a8dfd9-41cb-4549-a0dc-e540ea6ae81c","product_id":"BCH-USD","sequence":4839273358,"time":"2018-07-27T01:32:42.810000Z"}
{"type":"open","side":"buy","price":"791.23000000","order_id":"81a4304c-ad4e-40af-a4da-7e9b54cd90d8","remaining_size":"1.81488800","product_id":"BCH-USD","sequence":4839273359,"time":"2018-07-27T01:32:42.810000Z"}
{"type":"done","side":"sell","order_id":"e73909c6-13eb-49b7-bcb3-c94804d62098","reason":"canceled","product_id":"LTC-USD","price":"83.37000000","remaining_size":"13.42570300","sequence":2423272106,"time":"2018-07-27T01:32:42.812000Z"}
{"type":"received","order_id":"da18cdbd-6b21-46c2-8502-3fac77485b84","order_type":"limit","size":"4.50000000","price":"795.00000000","side":"sell","client_oid":"3850df2a-3fa9-483a-b828-fb194343fac0","product_id":"BCH-USD","sequence":4839273360,"time":"2018-07-27T01:32:42.812000Z"}
{"type":"open","side":"sell","price":"795.00000000","order_id":"da18cdbd-6b21-46c2-8502-3fac77485b84","remaining_size":"4.50000000","product_id":"BCH-USD","sequence":4839273361,"time":"2018-07-27T01:32:42.812000Z"}
{"type":"received","order_id":"18a3a4fc-92b0-4df8-9ac3-b9a08ad3a467","order_type":"limit","size":"0.90000000","price":"795.01000000","side":"sell","client_oid":"b1b6a819-bf61-414a-9575-214c6e33a350","product_id":"BCH-USD","sequence":4839273362,"time":"2018-07-27T01:32:42.817000Z"}
{"type":"open","side":"sell","price":"795.01000000","order_id":"18a3a4fc-92b0-4df8-9ac3-b9a08ad3a467","remaining_size":"0.90000000","product_id":"BCH-USD","sequence":4839273363,"time":"2018-07-27T01:32:42.817000Z"}
{"type":"received","order_id":"ec7fe73d-1238-48c0-8f0b-d6b908eb123c","order_type":"limit","size":"0.18739300","price":"791.23000000","side":"buy","client_oid":"6c637606-32b2-4226-b117-8d2fa179644e","product_id":"BCH-USD","sequence":4839273364,"time":"2018-07-27T01:32:42.820000Z"}
{"type":"open","side":"buy","price":"791.23000000","order_id":"ec7fe73d-1238-48c0-8f0b-d6b908eb123c","remaining_size":"0.18739300","product_id":"BCH-USD","sequence":4839273365,"time":"2018-07-27T01:32:42.820000Z"}
{"type":"done","side":"sell","order_id":"18a3a4fc-92b0-4df8-9ac3-b9a08ad3a467","reason":"canceled","product_id":"BCH-USD","price":"795.01000000","remaining_size":"0.90000000","sequence":4839273366,"time":"2018-07-27T01:32:42.821000Z"}
{"type":"done","side":"buy","order_id":"81a4304c-ad4e-40af-a4da-7e9b54cd90d8","reason":"canceled","product_id":"BCH-USD","price":"791.23000000","remaining_size":"1.81488800","sequence":4839273367,"time":"2018-07-27T01:32:42.823000Z"}
{"type":"done","side":"buy","order_id":"ec7fe73d-1238-48c0-8f0b-d6b908eb123c","reason":"canceled","product_id":"BCH-USD","price":"791.23000000","remaining_size":"0.18739300","sequence":4839273368,"time":"2018-07-27T01:32:42.824000Z"}
{"type":"received","order_id":"7bd29bb8-f7b8-4263-aed0-eac00b2be368","order_type":"limit","size":"0.90000000","price":"795.01000000","side":"sell","client_oid":"ba286c14-7103-45c5-98b2-fa7ca44a5c39","product_id":"BCH-USD","sequence":4839273369,"time":"2018-07-27T01:32:42.826000Z"}
{"type":"open","side":"sell","price":"795.01000000","order_id":"7bd29bb8-f7b8-4263-aed0-eac00b2be368","remaining_size":"0.90000000","product_id":"BCH-USD","sequence":4839273370,"time":"2018-07-27T01:32:42.826000Z"}
{"type":"received","order_id":"dc76b07d-4521-4d3d-a8aa-a1892e7fdbf3","order_type":"limit","size":"0.90000000","price":"794.99000000","side":"sell","client_oid":"0051397f-31b0-4faf-a7a9-eed904b0b861","product_id":"BCH-USD","sequence":4839273371,"time":"2018-07-27T01:32:42.829000Z"}
{"type":"open","side":"sell","price":"794.99000000","order_id":"dc76b07d-4521-4d3d-a8aa-a1892e7fdbf3","remaining_size":"0.90000000","product_id":"BCH-USD","sequence":4839273372,"time":"2018-07-27T01:32:42.829000Z"}
{"type":"done","side":"sell","order_id":"7bd29bb8-f7b8-4263-aed0-eac00b2be368","reason":"canceled","product_id":"BCH-USD","price":"795.01000000","remaining_size":"0.90000000","sequence":4839273373,"time":"2018-07-27T01:32:42.829000Z"}
{"type":"received","order_id":"9640664e-3e11-4ec9-8859-3660a4b7bc7b","order_type":"limit","size":"1.81488800","price":"791.24000000","side":"buy","client_oid":"7e9ac184-adea-4b8e-a829-9134f232d6cf","product_id":"BCH-USD","sequence":4839273374,"time":"2018-07-27T01:32:42.832000Z"}
{"type":"open","side":"buy","price":"791.24000000","order_id":"9640664e-3e11-4ec9-8859-3660a4b7bc7b","remaining_size":"1.81488800","product_id":"BCH-USD","sequence":4839273375,"time":"2018-07-27T01:32:42.832000Z"}
{"type":"done","side":"buy","order_id":"9640664e-3e11-4ec9-8859-3660a4b7bc7b","reason":"canceled","product_id":"BCH-USD","price":"791.24000000","remaining_size":"1.81488800","sequence":4839273376,"time":"2018-07-27T01:32:42.835000Z"}
{"type":"received","order_id":"090b783f-5550-4510-ae2f-20d097af7adb","order_type":"limit","size":"4.10303700","price":"83.03000000","side":"buy","client_oid":"d285eba6-ba0c-4fc0-92df-d84d920faf1b","product_id":"LTC-USD","sequence":2423272107,"time":"2018-07-27T01:32:42.845000Z"}
{"type":"open","side":"buy","price":"83.03000000","order_id":"090b783f-5550-4510-ae2f-20d097af7adb","remaining_size":"4.10303700","product_id":"LTC-USD","sequence":2423272108,"time":"2018-07-27T01:32:42.845000Z"}
{"type":"received","order_id":"72131b0d-bcb9-405f-9121-80dbbdd5bd2d","order_type":"limit","size":"1.81488800","price":"791.23000000","side":"buy","client_oid":"6a0cb8be-cc8b-4abd-bc24-c8adbf6cc8e9","product_id":"BCH-USD","sequence":4839273377,"time":"2018-07-27T01:32:42.845000Z"}
{"type":"open","side":"buy","price":"791.23000000","order_id":"72131b0d-bcb9-405f-9121-80dbbdd5bd2d","remaining_size":"1.81488800","product_id":"BCH-USD","sequence":4839273378,"time":"2018-07-27T01:32:42.845000Z"}
{"type":"received","order_id":"ab347cbb-e83d-4065-978e-be4c1e1a7e87","order_type":"limit","size":"0.90000000","price":"794.99000000","side":"sell","client_oid":"73b7e1ff-eeab-4313-bd3e-c76f539b49f3","product_id":"BCH-USD","sequence":4839273379,"time":"2018-07-27T01:32:42.846000Z"}
{"type":"open","side":"sell","price":"794.99000000","order_id":"ab347cbb-e83d-4065-978e-be4c1e1a7e87","remaining_size":"0.90000000","product_id":"BCH-USD","sequence":4839273380,"time":"2018-07-27T01:32:42.846000Z"}
{"type":"received","order_id":"f63dcbd8-3afd-475e-99c8-ae1b54b32647","order_type":"limit","size":"0.18739300","price":"791.24000000","side":"buy","client_oid":"2c024e26-1193-409d-8661-6867c583d205","product_id":"BCH-USD","sequence":4839273381,"time":"2018-07-27T01:32:42.850000Z"}
{"type":"open","side":"buy","price":"791.24000000","order_id":"f63dcbd8-3afd-475e-99c8-ae1b54b32647","remaining_size":"0.18739300","product_id":"BCH-USD","sequence":4839273382,"time":"2018-07-27T01:32:42.850000Z"}
{"type":"done","side":"sell","order_id":"d20a84f4-585a-4876-8516-8ee48e57b46c","reason":"canceled","product_id":"LTC-USD","price":"83.34000000","remaining_size":"7.44874862","sequence":2423272109,"time":"2018-07-27T01:32:42.854000Z"}
{"type":"done","side":"buy","order_id":"f63dcbd8-3afd-475e-99c8-ae1b54b32647","reason":"canceled","product_id":"BCH-USD","price":"791.24000000","remaining_size":"0.18739300","sequence":4839273383,"time":"2018-07-27T01:32:42.852000Z"}
{"type":"done","side":"buy","order_id":"72131b0d-bcb9-405f-9121-80dbbdd5bd2d","reason":"canceled","product_id":"BCH-USD","price":"791.23000000","remaining_size":"1.81488800","sequence":4839273384,"time":"2018-07-27T01:32:42.855000Z"}
{"type":"done","side":"sell","order_id":"da18cdbd-6b21-46c2-8502-3fac77485b84","reason":"canceled","product_id":"BCH-USD","price":"795.00000000","remaining_size":"4.50000000","sequence":4839273385,"time":"2018-07-27T01:32:42.856000Z"}
{"type":"received","order_id":"1ac50a03-841a-4944-9bcd-e1ce980a8867","order_type":"limit","size":"7.44874862","price":"83.30000000","side":"sell","client_oid":"f5cd39f8-f966-406a-8000-00392e84639d","product_id":"LTC-USD","sequence":2423272110,"time":"2018-07-27T01:32:42.860000Z"}
{"type":"done","side":"sell","order_id":"dc76b07d-4521-4d3d-a8aa-a1892e7fdbf3","reason":"canceled","product_id":"BCH-USD","price":"794.99000000","remaining_size":"0.90000000","sequence":4839273386,"time":"2018-07-27T01:32:42.860000Z"}
{"type":"received","order_id":"280b589d-4f6d-4609-a52b-5e5d7283e8d9","order_type":"limit","size":"1.81488800","price":"791.24000000","side":"buy","client_oid":"2ced9ca7-7ac7-48fe-add3-e02e1d6dcf28","product_id":"BCH-USD","sequence":4839273387,"time":"2018-07-27T01:32:42.860000Z"}
{"type":"open","side":"buy","price":"791.24000000","order_id":"280b589d-4f6d-4609-a52b-5e5d7283e8d9","remaining_size":"1.81488800","product_id":"BCH-USD","sequence":4839273388,"time":"2018-07-27T01:32:42.860000Z"}
{"type":"open","side":"sell","price":"83.30000000","order_id":"1ac50a03-841a-4944-9bcd-e1ce980a8867","remaining_size":"7.44874862","product_id":"LTC-USD","sequence":2423272111,"time":"2018-07-27T01:32:42.860000Z"}
{"type":"received","order_id":"b63018ad-16fe-40d0-b014-e249a0dc189b","order_type":"limit","size":"1.90000000","price":"795.01000000","side":"sell","client_oid":"80485a20-7fd2-4b92-b98b-3ff2416784fd","product_id":"BCH-USD","sequence":4839273389,"time":"2018-07-27T01:32:42.863000Z"}
{"type":"open","side":"sell","price":"795.01000000","order_id":"b63018ad-16fe-40d0-b014-e249a0dc189b","remaining_size":"1.90000000","product_id":"BCH-USD","sequence":4839273390,"time":"2018-07-27T01:32:42.863000Z"}
{"type":"done","side":"buy","order_id":"280b589d-4f6d-4609-a52b-5e5d7283e8d9","reason":"canceled","product_id":"BCH-USD","price":"791.24000000","remaining_size":"1.81488800","sequence":4839273391,"time":"2018-07-27T01:32:42.864000Z"}
{"type":"received","order_id":"6fb9b9b6-3d03-45f9-9732-3cf077ea661f","order_type":"limit","size":"0.90000000","price":"794.98000000","side":"sell","client_oid":"87bd5f61-f4c3-45cb-a24f-c7cc57b0b0f0","product_id":"BCH-USD","sequence":4839273392,"time":"2018-07-27T01:32:42.864000Z"}
{"type":"open","side":"sell","price":"794.98000000","order_id":"6fb9b9b6-3d03-45f9-9732-3cf077ea661f","remaining_size":"0.90000000","product_id":"BCH-USD","sequence":4839273393,"time":"2018-07-27T01:32:42.864000Z"}
{"type":"done","side":"sell","order_id":"ab347cbb-e83d-4065-978e-be4c1e1a7e87","reason":"canceled","product_id":"BCH-USD","price":"794.99000000","remaining_size":"0.90000000","sequence":4839273394,"time":"2018-07-27T01:32:42.866000Z"}
{"type":"received","order_id":"7a9df6b3-9f33-42d7-906b-df3167a4acc9","order_type":"limit","size":"8.57367800","price":"83.01000000","side":"buy","client_oid":"69221c89-0efd-4d4d-941c-1badaa8d16a2","product_id":"LTC-USD","sequence":2423272112,"time":"2018-07-27T01:32:42.869000Z"}
{"type":"received","order_id":"711a2fa2-9fbe-43c8-a112-257ce4ed705f","order_type":"limit","size":"0.18739300","price":"791.23000000","side":"buy","client_oid":"90490542-b27b-4b7e-9618-4170224e2329","product_id":"BCH-USD","sequence":4839273395,"time":"2018-07-27T01:32:42.867000Z"}
{"type":"open","side":"buy","price":"791.23000000","order_id":"711a2fa2-9fbe-43c8-a112-257ce4ed705f","remaining_size":"0.18739300","product_id":"BCH-USD","sequence":4839273396,"time":"2018-07-27T01:32:42.867000Z"}
{"type":"done","side":"sell","order_id":"6fb9b9b6-3d03-45f9-9732-3cf077ea661f","reason":"canceled","product_id":"BCH-USD","price":"794.98000000","remaining_size":"0.90000000","sequence":4839273397,"time":"2018-07-27T01:32:42.868000Z"}
{"type":"open","side":"buy","price":"83.01000000","order_id":"7a9df6b3-9f33-42d7-906b-df3167a4acc9","remaining_size":"8.57367800","product_id":"LTC-USD","sequence":2423272113,"time":"2018-07-27T01:32:42.869000Z"}
{"type":"done","side":"sell","order_id":"b63018ad-16fe-40d0-b014-e249a0dc189b","reason":"canceled","product_id":"BCH-USD","price":"795.01000000","remaining_size":"1.90000000","sequence":4839273398,"time":"2018-07-27T01:32:42.871000Z"}
{"type":"done","side":"buy","order_id":"711a2fa2-9fbe-43c8-a112-257ce4ed705f","reason":"canceled","product_id":"BCH-USD","price":"791.23000000","remaining_size":"0.18739300","sequence":4839273399,"time":"2018-07-27T01:32:42.871000Z"}
{"type":"received","order_id":"98c9d250-fe9f-4258-9c17-caabc469c4e9","order_type":"limit","size":"4.50000000","price":"794.99000000","side":"sell","client_oid":"b7e57dba-cfa8-4135-8877-edd523713a09","product_id":"BCH-USD","sequence":4839273400,"time":"2018-07-27T01:32:42.875000Z"}
{"type":"open","side":"sell","price":"794.99000000","order_id":"98c9d250-fe9f-4258-9c17-caabc469c4e9","remaining_size":"4.50000000","product_id":"BCH-USD","sequence":4839273401,"time":"2018-07-27T01:32:42.875000Z"}
{"type":"received","order_id":"f9a68436-7ec2-429a-ab42-a696098188fb","order_type":"limit","size":"0.90000000","price":"794.98000000","side":"sell","client_oid":"95e0e1b2-95db-4454-a003-cad844abc2fd","product_id":"BCH-USD","sequence":4839273402,"time":"2018-07-27T01:32:42.881000Z"}
{"type":"received","order_id":"2f6d790a-2354-4393-a653-b60c38b66cf1","order_type":"limit","size":"18.98311800","price":"82.95000000","side":"buy","client_oid":"62a64784-4eab-42c6-8016-622b515368f8","product_id":"LTC-USD","sequence":2423272114,"time":"2018-07-27T01:32:42.883000Z"}
{"type":"open","side":"sell","price":"794.98000000","order_id":"f9a68436-7ec2-429a-ab42-a696098188fb","remaining_size":"0.90000000","product_id":"BCH-USD","sequence":4839273403,"time":"2018-07-27T01:32:42.881000Z"}
{"type":"received","order_id":"b42ce126-cc1f-4b7a-b1cc-f8adb6ff74c5","order_type":"limit","size":"0.90000000","price":"795.02000000","side":"sell","client_oid":"7fe069cb-7ee2-4c65-8111-336a313e9e1d","product_id":"BCH-USD","sequence":4839273404,"time":"2018-07-27T01:32:42.881000Z"}
{"type":"open","side":"sell","price":"795.02000000","order_id":"b42ce126-cc1f-4b7a-b1cc-f8adb6ff74c5","remaining_size":"0.90000000","product_id":"BCH-USD","sequence":4839273405,"time":"2018-07-27T01:32:42.881000Z"}
{"type":"open","side":"buy","price":"82.95000000","order_id":"2f6d790a-2354-4393-a653-b60c38b66cf1","remaining_size":"18.98311800","product_id":"LTC-USD","sequence":2423272115,"time":"2018-07-27T01:32:42.883000Z"}
{"type":"done","side":"sell","order_id":"b42ce126-cc1f-4b7a-b1cc-f8adb6ff74c5","reason":"canceled","product_id":"BCH-USD","price":"795.02000000","remaining_size":"0.90000000","sequence":4839273406,"time":"2018-07-27T01:32:42.888000Z"}
{"type":"done","side":"sell","order_id":"98c9d250-fe9f-4258-9c17-caabc469c4e9","reason":"canceled","product_id":"BCH-USD","price":"794.99000000","remaining_size":"4.50000000","sequence":4839273407,"time":"2018-07-27T01:32:42.906000Z"}
{"type":"done","side":"sell","order_id":"f9a68436-7ec2-429a-ab42-a696098188fb","reason":"canceled","product_id":"BCH-USD","price":"794.98000000","remaining_size":"0.90000000","sequence":4839273408,"time":"2018-07-27T01:32:42.921000Z"}
{"type":"done","side":"sell","order_id":"1ac50a03-841a-4944-9bcd-e1ce980a8867","reason":"canceled","product_id":"LTC-USD","price":"83.30000000","remaining_size":"7.44874862","sequence":2423272116,"time":"2018-07-27T01:32:42.936000Z"}
{"type":"received","order_id":"901a480a-8218-454b-9004-add1d070851b","order_type":"limit","size":"7.44874862","price":"83.34000000","side":"sell","client_oid":"67022760-4401-45be-8000-00306732fe19","product_id":"LTC-USD","sequence":2423272117,"time":"2018-07-27T01:32:42.976000Z"}
{"type":"received","order_id":"aeba75d9-6913-4810-873f-bd4d72a320df","order_type":"limit","size":"1.81488800","price":"791.23000000","side":"buy","client_oid":"10a16283-d840-4b36-ba7f-e5a768c68940","product_id":"BCH-USD","sequence":4839273409,"time":"2018-07-27T01:32:42.974000Z"}
{"type":"received","order_id":"83115002-b512-4595-a891-a94cd201fb31","order_type":"limit","size":"0.16000000","price":"421.50000000","side":"buy","product_id":"ETH-USD","sequence":4469354862,"time":"2018-07-27T01:32:42.976000Z"}
{"type":"open","side":"buy","price":"791.23000000","order_id":"aeba75d9-6913-4810-873f-bd4d72a320df","remaining_size":"1.81488800","product_id":"BCH-USD","sequence":4839273410,"time":"2018-07-27T01:32:42.974000Z"}
{"type":"open","side":"sell","price":"83.34000000","order_id":"901a480a-8218-454b-9004-add1d070851b","remaining_size":"7.44874862","product_id":"LTC-USD","sequence":2423272118,"time":"2018-07-27T01:32:42.976000Z"}
{"type":"open","side":"buy","price":"421.50000000","order_id":"83115002-b512-4595-a891-a94cd201fb31","remaining_size":"0.16000000","product_id":"ETH-USD","sequence":4469354863,"time":"2018-07-27T01:32:42.976000Z"}
{"type":"received","order_id":"cf07be18-3c1b-4ba0-9bb6-70cf71ec5060","order_type":"limit","size":"118.98098700","price":"82.93000000","side":"buy","client_oid":"e2a9f69b-eb2c-43e6-8260-dc07905b5acf","product_id":"LTC-USD","sequence":2423272119,"time":"2018-07-27T01:32:42.977000Z"}
{"type":"open","side":"buy","price":"82.93000000","order_id":"cf07be18-3c1b-4ba0-9bb6-70cf71ec5060","remaining_size":"118.98098700","product_id":"LTC-USD","sequence":2423272120,"time":"2018-07-27T01:32:42.977000Z"}
{"type":"received","order_id":"149ec182-6dc8-4522-9a9f-fed10dfd635c","order_type":"limit","size":"0.90000000","price":"794.98000000","side":"sell","client_oid":"71f000d6-82d1-43c8-bcc4-d93ba470760d","product_id":"BCH-USD","sequence":4839273411,"time":"2018-07-27T01:32:42.979000Z"}
{"type":"open","side":"sell","price":"794.98000000","order_id":"149ec182-6dc8-4522-9a9f-fed10dfd635c","remaining_size":"0.90000000","product_id":"BCH-USD","sequence":4839273412,"time":"2018-07-27T01:32:42.979000Z"}
{"type":"received","order_id":"b2e7ebd6-6e6b-426c-bf0d-b9d6a093edc0","order_type":"limit","size":"1.90000000","price":"794.98000000","side":"sell","client_oid":"dafe66bd-56ec-4012-a3b6-1af43c4343b2","product_id":"BCH-USD","sequence":4839273413,"time":"2018-07-27T01:32:42.979000Z"}
{"type":"open","side":"sell","price":"794.98000000","order_id":"b2e7ebd6-6e6b-426c-bf0d-b9d6a093edc0","remaining_size":"1.90000000","product_id":"BCH-USD","sequence":4839273414,"time":"2018-07-27T01:32:42.979000Z"}
{"type":"done","side":"buy","order_id":"b0e0a32e-e49e-4dfd-bdef-7eece5a322ac","reason":"canceled","product_id":"BCH-USD","price":"790.16000000","remaining_size":"0.16458200","sequence":4839273415,"time":"2018-07-27T01:32:42.981000Z"}
{"type":"done","side":"sell","order_id":"149ec182-6dc8-4522-9a9f-fed10dfd635c","reason":"canceled","product_id":"BCH-USD","price":"794.98000000","remaining_size":"0.90000000","sequence":4839273416,"time":"2018-07-27T01:32:42.983000Z"}
{"type":"done","side":"sell","order_id":"b2e7ebd6-6e6b-426c-bf0d-b9d6a093edc0","reason":"canceled","product_id":"BCH-USD","price":"794.98000000","remaining_size":"1.90000000","sequence":4839273417,"time":"2018-07-27T01:32:42.985000Z"}
{"type":"done","side":"buy","order_id":"aeba75d9-6913-4810-873f-bd4d72a320df","reason":"canceled","product_id":"BCH-USD","price":"791.23000000","remaining_size":"1.81488800","sequence":4839273418,"time":"2018-07-27T01:32:42.986000Z"}
{"type":"done","side":"sell","order_id":"1d13c8fc-3f6f-431e-a32d-7543a064836a","reason":"canceled","product_id":"LTC-USD","price":"83.38000000","remaining_size":"7.44874862","sequence":2423272121,"time":"2018-07-27T01:32:42.989000Z"}
{"type":"done","side":"buy","order_id":"7ecc8448-364d-465a-b6eb-2d44819732fb","reason":"canceled","product_id":"BCH-USD","price":"789.20000000","remaining_size":"0.15109400","sequence":4839273419,"time":"2018-07-27T01:32:42.988000Z"}
{"type":"received","order_id":"70f963ce-8b9b-4be2-b191-85130e517f1c","order_type":"limit","size":"0.90000000","price":"795.02000000","side":"sell","client_oid":"5c270572-6311-4a0f-bac7-13d7c4d7888b","product_id":"BCH-USD","sequence":4839273420,"time":"2018-07-27T01:32:42.989000Z"}
{"type":"open","side":"sell","price":"795.02000000","order_id":"70f963ce-8b9b-4be2-b191-85130e517f1c","remaining_size":"0.90000000","product_id":"BCH-USD","sequence":4839273421,"time":"2018-07-27T01:32:42.989000Z"}
{"type":"received","order_id":"ddc2c66b-a07b-40dc-badc-fe5589e0bd89","order_type":"limit","size":"4.50000000","price":"794.98000000","side":"sell","client_oid":"40fde978-b322-42f8-8896-2e619edf57c1","product_id":"BCH-USD","sequence":4839273422,"time":"2018-07-27T01:32:42.989000Z"}
{"type":"open","side":"sell","price":"794.98000000","order_id":"ddc2c66b-a07b-40dc-badc-fe5589e0bd89","remaining_size":"4.50000000","product_id":"BCH-USD","sequence":4839273423,"time":"2018-07-27T01:32:42.989000Z"}
{"type":"received","order_id":"aaefad7d-c649-4647-b0d2-a5cf3a723077","order_type":"limit","size":"0.90000000","price":"795.02000000","side":"sell","client_oid":"453fd637-339a-44c8-869c-cd4fbc8c7ad9","product_id":"BCH-USD","sequence":4839273424,"time":"2018-07-27T01:32:42.990000Z"}
{"type":"open","side":"sell","price":"795.02000000","order_id":"aaefad7d-c649-4647-b0d2-a5cf3a723077","remaining_size":"0.90000000","product_id":"BCH-USD","sequence":4839273425,"time":"2018-07-27T01:32:42.990000Z"}
{"type":"done","side":"buy","order_id":"69944415-3f35-4dde-8b47-30f19035b981","reason":"canceled","product_id":"BCH-USD","price":"788.72000000","remaining_size":"0.12908300","sequence":4839273426,"time":"2018-07-27T01:32:42.990000Z"}
{"type":"received","order_id":"c464676e-33fb-4b80-b40e-29b89a923293","order_type":"limit","size":"119.44144900","price":"82.91000000","side":"buy","client_oid":"faa30d98-c469-49e3-a060-a77faedcdcc3","product_id":"LTC-USD","sequence":2423272122,"time":"2018-07-27T01:32:42.994000Z"}
{"type":"done","side":"sell","order_id":"70f963ce-8b9b-4be2-b191-85130e517f1c","reason":"canceled","product_id":"BCH-USD","price":"795.02000000","remaining_size":"0.90000000","sequence":4839273427,"time":"2018-07-27T01:32:42.993000Z"}
{"type":"open","side":"buy","price":"82.91000000","order_id":"c464676e-33fb-4b80-b40e-29b89a923293","remaining_size":"119.44144900","product_id":"LTC-USD","sequence":2423272123,"time":"2018-07-27T01:32:42.994000Z"}
{"type":"received","order_id":"b227acd7-e4f3-48b6-9728-781e40fd5fba","order_type":"limit","size":"7.44874862","price":"83.30000000","side":"sell","client_oid":"71aad34c-8f18-42d4-8000-005936c70246","product_id":"LTC-USD","sequence":2423272124,"time":"2018-07-27T01:32:42.996000Z"}
{"type":"done","side":"sell","order_id":"aaefad7d-c649-4647-b0d2-a5cf3a723077","reason":"canceled","product_id":"BCH-USD","price":"795.02000000","remaining_size":"0.90000000","sequence":4839273428,"time":"2018-07-27T01:32:42.994000Z"}
{"type":"open","side":"sell","price":"83.30000000","order_id":"b227acd7-e4f3-48b6-9728-781e40fd5fba","remaining_size":"7.44874862","product_id":"LTC-USD","sequence":2423272125,"time":"2018-07-27T01:32:42.996000Z"}
{"type":"done","side":"sell","order_id":"ddc2c66b-a07b-40dc-badc-fe5589e0bd89","reason":"canceled","product_id":"BCH-USD","price":"794.98000000","remaining_size":"4.50000000","sequence":4839273429,"time":"2018-07-27T01:32:42.995000Z"}
{"type":"done","side":"buy","order_id":"7c93a30e-9705-490a-aa28-62806c3312d5","reason":"canceled","product_id":"BCH-USD","price":"788.48000000","remaining_size":"0.16755000","sequence":4839273430,"time":"2018-07-27T01:32:42.998000Z"}
{"type":"received","order_id":"aba53ce7-5ca2-4e6e-b64a-2778653980c4","order_type":"limit","size":"0.18739300","price":"791.25000000","side":"buy","client_oid":"ccae3fb3-88b5-4252-a549-73c03e435dac","product_id":"BCH-USD","sequence":4839273431,"time":"2018-07-27T01:32:42.999000Z"}
{"type":"open","side":"buy","price":"791.25000000","order_id":"aba53ce7-5ca2-4e6e-b64a-2778653980c4","remaining_size":"0.18739300","product_id":"BCH-USD","sequence":4839273432,"time":"2018-07-27T01:32:42.999000Z"}
{"type":"done","side":"buy","order_id":"edf24357-f212-437c-bccd-8d8784007079","reason":"canceled","product_id":"BCH-USD","price":"788.24000000","remaining_size":"2.74528900","sequence":4839273433,"time":"2018-07-27T01:32:43.001000Z"}
{"type":"received","order_id":"6b519540-8aa3-4ed4-ae23-218feb0d02e6","order_type":"limit","size":"1.81488800","price":"791.24000000","side":"buy","client_oid":"fed46469-893d-4d15-8488-650c34e9b0cc","product_id":"BCH-USD","sequence":4839273434,"time":"2018-07-27T01:32:43.001000Z"}
{"type":"open","side":"buy","price":"791.24000000","order_id":"6b519540-8aa3-4ed4-ae23-218feb0d02e6","remaining_size":"1.81488800","product_id":"BCH-USD","sequence":4839273435,"time":"2018-07-27T01:32:43.001000Z"}
{"type":"received","order_id":"3ee69748-556e-4108-aa3e-ec9109996d79","order_type":"limit","size":"1.90000000","price":"795.02000000","side":"sell","client_oid":"18d7c907-d4f0-4612-8f69-4e9f5f921c07","product_id":"BCH-USD","sequence":4839273436,"time":"2018-07-27T01:32:43.002000Z"}
{"type":"open","side":"sell","price":"795.02000000","order_id":"3ee69748-556e-4108-aa3e-ec9109996d79","remaining_size":"1.90000000","product_id":"BCH-USD","sequence":4839273437,"time":"2018-07-27T01:32:43.002000Z"}
{"type":"done","side":"buy","order_id":"22d174a0-0b57-484a-afff-29af1f81c613","reason":"canceled","product_id":"BCH-USD","price":"788.00000000","remaining_size":"0.21613500","sequence":4839273438,"time":"2018-07-27T01:32:43.003000Z"}
{"type":"received","order_id":"9ecfa53d-6cc4-432c-95a6-dd81396c9670","order_type":"limit","size":"0.90000000","price":"794.97000000","side":"sell","client_oid":"58553571-62b1-4ec3-9505-f9f3d03734f3","product_id":"BCH-USD","sequence":4839273439,"time":"2018-07-27T01:32:43.004000Z"}
{"type":"open","side":"sell","price":"794.97000000","order_id":"9ecfa53d-6cc4-432c-95a6-dd81396c9670","remaining_size":"0.90000000","product_id":"BCH-USD","sequence":4839273440,"time":"2018-07-27T01:32:43.004000Z"}
{"type":"done","side":"buy","order_id":"6b519540-8aa3-4ed4-ae23-218feb0d02e6","reason":"canceled","product_id":"BCH-USD","price":"791.24000000","remaining_size":"1.81488800","sequence":4839273441,"time":"2018-07-27T01:32:43.005000Z"}
{"type":"done","side":"buy","order_id":"aba53ce7-5ca2-4e6e-b64a-2778653980c4","reason":"canceled","product_id":"BCH-USD","price":"791.25000000","remaining_size":"0.18739300","sequence":4839273442,"time":"2018-07-27T01:32:43.007000Z"}
{"type":"done","side":"buy","order_id":"7e2c9e2c-63b9-4939-b5df-59afe99d42e7","reason":"canceled","product_id":"BCH-USD","price":"787.52000000","remaining_size":"1.38331400","sequence":4839273443,"time":"2018-07-27T01:32:43.007000Z"}
{"type":"received","order_id":"288ef30d-ef79-459a-8e38-a7bdd09a233a","order_type":"limit","size":"20.49574000","price":"83.29000000","side":"sell","client_oid":"dfac5d06-77c5-4461-81eb-713df1da24cc","product_id":"LTC-USD","sequence":2423272126,"time":"2018-07-27T01:32:43.010000Z"}
{"type":"open","side":"sell","price":"83.29000000","order_id":"288ef30d-ef79-459a-8e38-a7bdd09a233a","remaining_size":"20.49574000","product_id":"LTC-USD","sequence":2423272127,"time":"2018-07-27T01:32:43.010000Z"}
{"type":"done","side":"sell","order_id":"3ee69748-556e-4108-aa3e-ec9109996d79","reason":"canceled","product_id":"BCH-USD","price":"795.02000000","remaining_size":"1.90000000","sequence":4839273444,"time":"2018-07-27T01:32:43.010000Z"}
{"type":"done","side":"sell","order_id":"9ecfa53d-6cc4-432c-95a6-dd81396c9670","reason":"canceled","product_id":"BCH-USD","price":"794.97000000","remaining_size":"0.90000000","sequence":4839273445,"time":"2018-07-27T01:32:43.010000Z"}
{"type":"received","order_id":"b10981d3-a2d3-4b05-ac26-e2babb7dcb08","order_type":"limit","size":"4.50000000","price":"794.97000000","side":"sell","client_oid":"6e6bb97f-043e-4ccb-9176-22b343a7a1b2","product_id":"BCH-USD","sequence":4839273446,"time":"2018-07-27T01:32:43.013000Z"}
{"type":"open","side":"sell","price":"794.97000000","order_id":"b10981d3-a2d3-4b05-ac26-e2babb7dcb08","remaining_size":"4.50000000","product_id":"BCH-USD","sequence":4839273447,"time":"2018-07-27T01:32:43.013000Z"}
{"type":"done","side":"sell","order_id":"901a480a-8218-454b-9004-add1d070851b","reason":"canceled","product_id":"LTC-USD","price":"83.34000000","remaining_size":"7.44874862","sequence":2423272128,"time":"2018-07-27T01:32:43.016000Z"}
{"type":"received","order_id":"1e86ac08-bc49-4c9d-945f-44b86dba6b76","order_type":"limit","size":"1.81488800","price":"791.23000000","side":"buy","client_oid":"fa8d4e3f-82bb-47f2-b277-f779296286f8","product_id":"BCH-USD","sequence":4839273448,"time":"2018-07-27T01:32:43.015000Z"}
{"type":"open","side":"buy","price":"791.23000000","order_id":"1e86ac08-bc49-4c9d-945f-44b86dba6b76","remaining_size":"1.81488800","product_id":"BCH-USD","sequence":4839273449,"time":"2018-07-27T01:32:43.015000Z"}
{"type":"done","side":"sell","order_id":"b10981d3-a2d3-4b05-ac26-e2babb7dcb08","reason":"canceled","product_id":"BCH-USD","price":"794.97000000","remaining_size":"4.50000000","sequence":4839273450,"time":"2018-07-27T01:32:43.016000Z"}
{"type":"done","side":"buy","order_id":"1e86ac08-bc49-4c9d-945f-44b86dba6b76","reason":"canceled","product_id":"BCH-USD","price":"791.23000000","remaining_size":"1.81488800","sequence":4839273451,"time":"2018-07-27T01:32:43.017000Z"}
{"type":"received","order_id":"dab31460-cdb0-41eb-9ac6-4d13b22c870a","order_type":"limit","size":"0.18739300","price":"791.23000000","side":"buy","client_oid":"9114bc38-f109-4e46-a093-bc6e2b3f7055","product_id":"BCH-USD","sequence":4839273452,"time":"2018-07-27T01:32:43.019000Z"}
{"type":"open","side":"buy","price":"791.23000000","order_id":"dab31460-cdb0-41eb-9ac6-4d13b22c870a","remaining_size":"0.18739300","product_id":"BCH-USD","sequence":4839273453,"time":"2018-07-27T01:32:43.019000Z"}
{"type":"received","order_id":"a3b27180-808a-406d-836d-2eea43fb0a59","order_type":"limit","size":"22.33541100","price":"83.30000000","side":"sell","client_oid":"69d4d1e9-4ceb-41ef-bda7-e50cb6dae429","product_id":"LTC-USD","sequence":2423272129,"time":"2018-07-27T01:32:43.023000Z"}
{"type":"open","side":"sell","price":"83.30000000","order_id":"a3b27180-808a-406d-836d-2eea43fb0a59","remaining_size":"22.33541100","product_id":"LTC-USD","sequence":2423272130,"time":"2018-07-27T01:32:43.023000Z"}
{"type":"received","order_id":"6828837f-e715-4265-a8a6-c54676f07bb3","order_type":"limit","size":"0.90000000","price":"795.02000000","side":"sell","client_oid":"2ff3fc61-29ad-4c6c-8159-cfa72deddc91","product_id":"BCH-USD","sequence":4839273454,"time":"2018-07-27T01:32:43.025000Z"}
{"type":"open","side":"sell","price":"795.02000000","order_id":"6828837f-e715-4265-a8a6-c54676f07bb3","remaining_size":"0.90000000","product_id":"BCH-USD","sequence":4839273455,"time":"2018-07-27T01:32:43.025000Z"}
{"type":"received","order_id":"b1bc7606-eb29-4dba-9fe6-92e0a54bb139","order_type":"limit","size":"0.90000000","price":"794.97000000","side":"sell","client_oid":"620fc07a-448e-4863-9113-148859b7a7c6","product_id":"BCH-USD","sequence":4839273456,"time":"2018-07-27T01:32:43.028000Z"}
{"type":"open","side":"sell","price":"794.97000000","order_id":"b1bc7606-eb29-4dba-9fe6-92e0a54bb139","remaining_size":"0.90000000","product_id":"BCH-USD","sequence":4839273457,"time":"2018-07-27T01:32:43.028000Z"}
{"type":"received","order_id":"3a164b39-1354-4c11-9319-34c5dcf78898","order_type":"limit","size":"7.44874862","price":"83.38000000","side":"sell","client_oid":"6badf849-89b1-4b90-8000-07326989eb40","product_id":"LTC-USD","sequence":2423272131,"time":"2018-07-27T01:32:43.031000Z"}
{"type":"done","side":"sell","order_id":"6828837f-e715-4265-a8a6-c54676f07bb3","reason":"canceled","product_id":"BCH-USD","price":"795.02000000","remaining_size":"0.90000000","sequence":4839273458,"time":"2018-07-27T01:32:43.029000Z"}
{"type":"open","side":"sell","price":"83.38000000","order_id":"3a164b39-1354-4c11-9319-34c5dcf78898","remaining_size":"7.44874862","product_id":"LTC-USD","sequence":2423272132,"time":"2018-07-27T01:32:43.031000Z"}
{"type":"done","side":"sell","order_id":"b1bc7606-eb29-4dba-9fe6-92e0a54bb139","reason":"canceled","product_id":"BCH-USD","price":"794.97000000","remaining_size":"0.90000000","sequence":4839273459,"time":"2018-07-27T01:32:43.033000Z"}
{"type":"received","order_id":"a67c5f47-71fa-492e-b65d-a2b3c77e5729","order_type":"limit","size":"1.81488800","price":"791.25000000","side":"buy","client_oid":"48f225c8-c468-45b7-9886-bb446b632431","product_id":"BCH-USD","sequence":4839273460,"time":"2018-07-27T01:32:43.033000Z"}
{"type":"open","side":"buy","price":"791.25000000","order_id":"a67c5f47-71fa-492e-b65d-a2b3c77e5729","remaining_size":"1.81488800","product_id":"BCH-USD","sequence":4839273461,"time":"2018-07-27T01:32:43.033000Z"}
{"type":"received","order_id":"161ea782-bc95-4eb2-80ff-5f97486b9767","order_type":"limit","size":"18.46927000","price":"83.32000000","side":"sell","client_oid":"d8cb2b35-2f8b-42d9-8263-3197dbdb8d03","product_id":"LTC-USD","sequence":2423272133,"time":"2018-07-27T01:32:43.036000Z"}
{"type":"open","side":"sell","price":"83.32000000","order_id":"161ea782-bc95-4eb2-80ff-5f97486b9767","remaining_size":"18.46927000","product_id":"LTC-USD","sequence":2423272134,"time":"2018-07-27T01:32:43.036000Z"}
{"type":"done","side":"buy","order_id":"a67c5f47-71fa-492e-b65d-a2b3c77e5729","reason":"canceled","product_id":"BCH-USD","price":"791.25000000","remaining_size":"1.81488800","sequence":4839273462,"time":"2018-07-27T01:32:43.037000Z"}
{"type":"received","order_id":"3051a2fb-7c6f-481d-bc5f-0ecbe7909dd8","order_type":"limit","size":"0.90000000","price":"795.01000000","side":"sell","client_oid":"c899f16b-9a5d-4247-b087-8c8552b0910e","product_id":"BCH-USD","sequence":4839273463,"time":"2018-07-27T01:32:43.038000Z"}
{"type":"open","side":"sell","price":"795.01000000","order_id":"3051a2fb-7c6f-481d-bc5f-0ecbe7909dd8","remaining_size":"0.90000000","product_id":"BCH-USD","sequence":4839273464,"time":"2018-07-27T01:32:43.038000Z"}
{"type":"received","order_id":"da1e62c1-5830-4e34-a2d8-6a49c9162664","order_type":"limit","size":"0.90000000","price":"795.02000000","side":"sell","client_oid":"2e4802a4-d59d-4401-939c-9b9841a7bf19","product_id":"BCH-USD","sequence":4839273465,"time":"2018-07-27T01:32:43.043000Z"}
{"type":"open","side":"sell","price":"795.02000000","order_id":"da1e62c1-5830-4e34-a2d8-6a49c9162664","remaining_size":"0.90000000","product_id":"BCH-USD","sequence":4839273466,"time":"2018-07-27T01:32:43.043000Z"}
{"type":"received","order_id":"3afd1122-3e69-4b98-b0f6-86d706ad473b","order_type":"limit","size":"1.81488800","price":"791.23000000","side":"buy","client_oid":"d99105dc-3270-45bf-8a6e-3a38ce8677de","product_id":"BCH-USD","sequence":4839273467,"time":"2018-07-27T01:32:43.045000Z"}
{"type":"open","side":"buy","price":"791.23000000","order_id":"3afd1122-3e69-4b98-b0f6-86d706ad473b","remaining_size":"1.81488800","product_id":"BCH-USD","sequence":4839273468,"time":"2018-07-27T01:32:43.045000Z"}
{"type":"done","side":"sell","order_id":"da1e62c1-5830-4e34-a2d8-6a49c9162664","reason":"canceled","product_id":"BCH-USD","price":"795.02000000","remaining_size":"0.90000000","sequence":4839273469,"time":"2018-07-27T01:32:43.051000Z"}
{"type":"done","side":"buy","order_id":"dab31460-cdb0-41eb-9ac6-4d13b22c870a","reason":"canceled","product_id":"BCH-USD","price":"791.23000000","remaining_size":"0.18739300","sequence":4839273470,"time":"2018-07-27T01:32:43.054000Z"}
{"type":"received","order_id":"56cc6922-f49f-4d1e-8269-d97f5724f720","order_type":"limit","size":"4.50000000","price":"795.01000000","side":"sell","client_oid":"1b5d2235-fcd3-49e6-b66c-4e047bf248bf","product_id":"BCH-USD","sequence":4839273471,"time":"2018-07-27T01:32:43.056000Z"}
{"type":"open","side":"sell","price":"795.01000000","order_id":"56cc6922-f49f-4d1e-8269-d97f5724f720","remaining_size":"4.50000000","product_id":"BCH-USD","sequence":4839273472,"time":"2018-07-27T01:32:43.056000Z"}
{"type":"received","order_id":"1dcdec79-a5b2-4608-b9d6-0189f0301000","order_type":"limit","size":"0.18739300","price":"791.24000000","side":"buy","client_oid":"199c149e-0f6a-4b88-97dd-3287e2820590","product_id":"BCH-USD","sequence":4839273473,"time":"2018-07-27T01:32:43.058000Z"}
{"type":"open","side":"buy","price":"791.24000000","order_id":"1dcdec79-a5b2-4608-b9d6-0189f0301000","remaining_size":"0.18739300","product_id":"BCH-USD","sequence":4839273474,"time":"2018-07-27T01:32:43.058000Z"}
{"type":"done","side":"sell","order_id":"3051a2fb-7c6f-481d-bc5f-0ecbe7909dd8","reason":"canceled","product_id":"BCH-USD","price":"795.01000000","remaining_size":"0.90000000","sequence":4839273475,"time":"2018-07-27T01:32:43.061000Z"}
{"type":"done","side":"sell","order_id":"b227acd7-e4f3-48b6-9728-781e40fd5fba","reason":"canceled","product_id":"LTC-USD","price":"83.30000000","remaining_size":"7.44874862","sequence":2423272135,"time":"2018-07-27T01:32:43.065000Z"}
{"type":"done","side":"buy","order_id":"aedb8a06-8f9a-48f8-8a37-7dd89e3c706e","reason":"canceled","product_id":"ETH-USD","price":"431.20000000","remaining_size":"0.15000000","sequence":4469354864,"time":"2018-07-27T01:32:43.067000Z"}
{"type":"done","side":"sell","order_id":"18ad6dd6-e75a-44c3-b989-c288e3cf8254","reason":"canceled","product_id":"BCH-USD","price":"794.00000000","remaining_size":"54.00000000","sequence":4839273476,"time":"2018-07-27T01:32:43.066000Z"}
{"type":"done","side":"sell","order_id":"56cc6922-f49f-4d1e-8269-d97f5724f720","reason":"canceled","product_id":"BCH-USD","price":"795.01000000","remaining_size":"4.50000000","sequence":4839273477,"time":"2018-07-27T01:32:43.070000Z"}
{"type":"received","order_id":"4500235c-2e18-47a6-a7b7-cb877443c9e1","order_type":"limit","size":"0.90000000","price":"795.02000000","side":"sell","client_oid":"6f931377-dcbc-4ce7-aeb2-057537cc1fc6","product_id":"BCH-USD","sequence":4839273478,"time":"2018-07-27T01:32:43.070000Z"}
{"type":"open","side":"sell","price":"795.02000000","order_id":"4500235c-2e18-47a6-a7b7-cb877443c9e1","remaining_size":"0.90000000","product_id":"BCH-USD","sequence":4839273479,"time":"2018-07-27T01:32:43.070000Z"}
{"type":"done","side":"sell","order_id":"3646b555-4c6f-4308-91a0-fb71dd0b28ba","reason":"canceled","product_id":"BCH-USD","price":"794.37000000","remaining_size":"2.00000000","sequence":4839273480,"time":"2018-07-27T01:32:43.071000Z"}
{"type":"received","order_id":"96916ec4-3e68-433f-9b50-54e0df3e1dd4","order_type":"limit","size":"7.44874862","price":"83.34000000","side":"sell","client_oid":"8fafc4ea-31aa-4913-8000-003a947a8a32","product_id":"LTC-USD","sequence":2423272136,"time":"2018-07-27T01:32:43.079000Z"}
{"type":"open","side":"sell","price":"83.34000000","order_id":"96916ec4-3e68-433f-9b50-54e0df3e1dd4","remaining_size":"7.44874862","product_id":"LTC-USD","sequence":2423272137,"time":"2018-07-27T01:32:43.079000Z"}
{"type":"done","side":"sell","order_id":"3a164b39-1354-4c11-9319-34c5dcf78898","reason":"canceled","product_id":"LTC-USD","price":"83.38000000","remaining_size":"7.44874862","sequence":2423272138,"time":"2018-07-27T01:32:43.081000Z"}
{"type":"received","order_id":"7eb85de2-2548-427b-a5c6-a1494efd795f","order_type":"limit","size":"4.50000000","price":"795.00000000","side":"sell","client_oid":"16a1fe97-2c27-4077-afbf-baac58310658","product_id":"BCH-USD","sequence":4839273481,"time":"2018-07-27T01:32:43.081000Z"}
{"type":"open","side":"sell","price":"795.00000000","order_id":"7eb85de2-2548-427b-a5c6-a1494efd795f","remaining_size":"4.50000000","product_id":"BCH-USD","sequence":4839273482,"time":"2018-07-27T01:32:43.081000Z"}
{"type":"received","order_id":"d4b8387b-adfd-4e62-b78d-fd4964eeae43","order_type":"limit","size":"2.00000000","price":"795.02000000","side":"sell","client_oid":"f48379a2-284d-43fb-95c2-4057d25fce12","product_id":"BCH-USD","sequence":4839273483,"time":"2018-07-27T01:32:43.083000Z"}
{"type":"open","side":"sell","price":"795.02000000","order_id":"d4b8387b-adfd-4e62-b78d-fd4964eeae43","remaining_size":"2.00000000","product_id":"BCH-USD","sequence":4839273484,"time":"2018-07-27T01:32:43.083000Z"}
{"type":"done","side":"sell","order_id":"7eb85de2-2548-427b-a5c6-a1494efd795f","reason":"canceled","product_id":"BCH-USD","price":"795.00000000","remaining_size":"4.50000000","sequence":4839273485,"time":"2018-07-27T01:32:43.085000Z"}
{"type":"done","side":"buy","order_id":"3afd1122-3e69-4b98-b0f6-86d706ad473b","reason":"canceled","product_id":"BCH-USD","price":"791.23000000","remaining_size":"1.81488800","sequence":4839273486,"time":"2018-07-27T01:32:43.086000Z"}
{"type":"done","side":"sell","order_id":"4500235c-2e18-47a6-a7b7-cb877443c9e1","reason":"canceled","product_id":"BCH-USD","price":"795.02000000","remaining_size":"0.90000000","sequence":4839273487,"time":"2018-07-27T01:32:43.086000Z"}
{"type":"done","side":"sell","order_id":"97f2981b-5f92-49c1-ac48-bc8d0818fd8c","reason":"canceled","product_id":"BCH-USD","price":"794.00000000","remaining_size":"28.00000000","sequence":4839273488,"time":"2018-07-27T01:32:43.086000Z"}
{"type":"done","side":"sell","order_id":"d4b8387b-adfd-4e62-b78d-fd4964eeae43","reason":"canceled","product_id":"BCH-USD","price":"795.02000000","remaining_size":"2.00000000","sequence":4839273489,"time":"2018-07-27T01:32:43.088000Z"}
{"type":"done","side":"buy","order_id":"dfadc188-8a50-434e-aea8-78cd674d8ee6","reason":"canceled","product_id":"BCH-USD","price":"793.19000000","remaining_size":"2.00000000","sequence":4839273490,"time":"2018-07-27T01:32:43.090000Z"}
{"type":"received","order_id":"1147b6a1-c07f-4d65-a838-5320680f4a7d","order_type":"limit","size":"1.81488800","price":"791.24000000","side":"buy","client_oid":"469c45f4-6878-44bd-9796-ddb94200fd9f","product_id":"BCH-USD","sequence":4839273491,"time":"2018-07-27T01:32:43.094000Z"}
{"type":"open","side":"buy","price":"791.24000000","order_id":"1147b6a1-c07f-4d65-a838-5320680f4a7d","remaining_size":"1.81488800","product_id":"BCH-USD","sequence":4839273492,"time":"2018-07-27T01:32:43.094000Z"}
{"type":"done","side":"buy","order_id":"bc972256-c87b-40a7-b326-80056bf63ce8","reason":"canceled","product_id":"BTC-USD","price":"7885.21000000","remaining_size":"0.00100000","sequence":6418130307,"time":"2018-07-27T01:32:43.097000Z"}
{"type":"received","order_id":"61d4db90-9595-452f-a56d-a68be43338e6","order_type":"limit","size":"7.44874862","price":"83.30000000","side":"sell","client_oid":"103ce2a5-734b-442f-8000-002fdc23c9b6","product_id":"LTC-USD","sequence":2423272139,"time":"2018-07-27T01:32:43.096000Z"}
{"type":"done","side":"buy","order_id":"c98ca08d-39c0-42b0-8de1-b7ac1c193a3a","reason":"canceled","product_id":"BTC-USD","price":"7863.64000000","remaining_size":"0.00100000","sequence":6418130308,"time":"2018-07-27T01:32:43.097000Z"}
{"type":"done","side":"buy","order_id":"4c1fd8d8-80aa-4dd8-98bc-b8c01df83935","reason":"canceled","product_id":"BTC-USD","price":"7894.00000000","remaining_size":"0.20000000","sequence":6418130309,"time":"2018-07-27T01:32:43.097000Z"}
{"type":"open","side":"sell","price":"83.30000000","order_id":"61d4db90-9595-452f-a56d-a68be43338e6","remaining_size":"7.44874862","product_id":"LTC-USD","sequence":2423272140,"time":"2018-07-27T01:32:43.096000Z"}
{"type":"done","side":"buy","order_id":"1147b6a1-c07f-4d65-a838-5320680f4a7d","reason":"canceled","product_id":"BCH-USD","price":"791.24000000","remaining_size":"1.81488800","sequence":4839273493,"time":"2018-07-27T01:32:43.097000Z"}
{"type":"done","side":"sell","order_id":"7dbc5035-41e7-4b24-93da-48bdd70f0421","reason":"canceled","product_id":"ETH-USD","price":"463.58000000","remaining_size":"6.00000000","sequence":4469354865,"time":"2018-07-27T01:32:43.102000Z"}
{"type":"received","order_id":"26f3ccbd-0a80-4538-be7d-bde6430e4eb2","order_type":"limit","size":"2.00000000","price":"795.02000000","side":"sell","client_oid":"edb110f7-2bad-477b-bcc1-317f2bf74082","product_id":"BCH-USD","sequence":4839273494,"time":"2018-07-27T01:32:43.102000Z"}
{"type":"open","side":"sell","price":"795.02000000","order_id":"26f3ccbd-0a80-4538-be7d-bde6430e4eb2","remaining_size":"2.00000000","product_id":"BCH-USD","sequence":4839273495,"time":"2018-07-27T01:32:43.102000Z"}
{"type":"done","side":"sell","order_id":"c59acd14-29a3-45cc-84cd-5b1e30af59c9","reason":"canceled","product_id":"BCH-USD","price":"794.00000000","remaining_size":"37.00000000","sequence":4839273496,"time":"2018-07-27T01:32:43.107000Z"}
{"type":"received","order_id":"7c0ee8ad-e154-4795-a0f4-b3eeaef0661b","order_type":"limit","size":"2.00000000","price":"793.61000000","side":"buy","client_oid":"8a8f9c73-903f-41d9-9a11-6c5e0abdd54f","product_id":"BCH-USD","sequence":4839273497,"time":"2018-07-27T01:32:43.110000Z"}
{"type":"open","side":"buy","price":"793.61000000","order_id":"7c0ee8ad-e154-4795-a0f4-b3eeaef0661b","remaining_size":"2.00000000","product_id":"BCH-USD","sequence":4839273498,"time":"2018-07-27T01:32:43.110000Z"}
{"type":"done","side":"sell","order_id":"96916ec4-3e68-433f-9b50-54e0df3e1dd4","reason":"canceled","product_id":"LTC-USD","price":"83.34000000","remaining_size":"7.44874862","sequence":2423272141,"time":"2018-07-27T01:32:43.113000Z"}
{"type":"received","order_id":"65a17ad1-c12a-4f44-bcd7-a8aea7e36d39","order_type":"limit","size":"6.00000000","price":"463.94000000","side":"sell","client_oid":"7a06955a-6b5e-46ab-9d59-7dc8fc1f4277","product_id":"ETH-USD","sequence":4469354866,"time":"2018-07-27T01:32:43.113000Z"}
{"type":"open","side":"sell","price":"463.94000000","order_id":"65a17ad1-c12a-4f44-bcd7-a8aea7e36d39","remaining_size":"6.00000000","product_id":"ETH-USD","sequence":4469354867,"time":"2018-07-27T01:32:43.113000Z"}
{"type":"received","order_id":"c90c27c9-899a-41f0-bf15-a8dbe53167ee","order_type":"limit","size":"1.81488800","price":"791.23000000","side":"buy","client_oid":"f3250aa6-e78c-4253-b0e5-9d8f277597cd","product_id":"BCH-USD","sequence":4839273499,"time":"2018-07-27T01:32:43.113000Z"}
{"type":"open","side":"buy","price":"791.23000000","order_id":"c90c27c9-899a-41f0-bf15-a8dbe53167ee","remaining_size":"1.81488800","product_id":"BCH-USD","sequence":4839273500,"time":"2018-07-27T01:32:43.113000Z"}
{"type":"received","order_id":"c86f0347-4ab2-4585-935f-ec76535bb777","order_type":"limit","size":"0.20000000","price":"7894.00000000","side":"buy","client_oid":"9b80b41b-07b9-4111-b05b-d2da587bc5eb","product_id":"BTC-USD","sequence":6418130310,"time":"2018-07-27T01:32:43.117000Z"}
{"type":"open","side":"buy","price":"7894.00000000","order_id":"c86f0347-4ab2-4585-935f-ec76535bb777","remaining_size":"0.20000000","product_id":"BTC-USD","sequence":6418130311,"time":"2018-07-27T01:32:43.117000Z"}
{"type":"done","side":"buy","order_id":"c90c27c9-899a-41f0-bf15-a8dbe53167ee","reason":"canceled","product_id":"BCH-USD","price":"791.23000000","remaining_size":"1.81488800","sequence":4839273501,"time":"2018-07-27T01:32:43.127000Z"}
{"type":"received","order_id":"46413c63-bd48-4368-b073-dc454a5191e9","order_type":"limit","size":"7.44874862","price":"83.38000000","side":"sell","client_oid":"b37f3bb8-9924-4e20-8000-f5ed0adcf600","product_id":"LTC-USD","sequence":2423272142,"time":"2018-07-27T01:32:43.129000Z"}
{"type":"done","side":"sell","order_id":"30cb9832-d0c6-4c99-bbd8-08ec008aa315","reason":"canceled","product_id":"BCH-USD","price":"794.00000000","remaining_size":"9.00000000","sequence":4839273502,"time":"2018-07-27T01:32:43.128000Z"}
{"type":"open","side":"sell","price":"83.38000000","order_id":"46413c63-bd48-4368-b073-dc454a5191e9","remaining_size":"7.44874862","product_id":"LTC-USD","sequence":2423272143,"time":"2018-07-27T01:32:43.129000Z"}
{"type":"done","side":"sell","order_id":"b1fcfe48-5641-43e6-bf38-20da1bad1e17","reason":"canceled","product_id":"BCH-USD","price":"794.00000000","remaining_size":"23.00000000","sequence":4839273503,"time":"2018-07-27T01:32:43.128000Z"}
{"type":"done","side":"buy","order_id":"e0da76b0-f97d-4a95-98f4-58af0f0a6200","reason":"canceled","product_id":"LTC-USD","price":"82.89000000","remaining_size":"100.02000000","sequence":2423272144,"time":"2018-07-27T01:32:43.131000Z"}
{"type":"received","order_id":"d7a36b9f-bae1-42f3-845b-0db6610e6e98","order_type":"limit","size":"0.48000000","price":"83.11000000","side":"buy","client_oid":"52dc65f7-5e9c-488e-8e6e-bdb3057abda9","product_id":"LTC-USD","sequence":2423272145,"time":"2018-07-27T01:32:43.133000Z"}
{"type":"open","side":"buy","price":"83.11000000","order_id":"d7a36b9f-bae1-42f3-845b-0db6610e6e98","remaining_size":"0.48000000","product_id":"LTC-USD","sequence":2423272146,"time":"2018-07-27T01:32:43.133000Z"}
{"type":"received","order_id":"de925289-cadf-4860-9cf4-d36623aa0393","order_type":"limit","size":"0.22343700","price":"790.16000000","side":"buy","client_oid":"ea4bf7be-c557-4122-93b2-b7262655b2c8","product_id":"BCH-USD","sequence":4839273504,"time":"2018-07-27T01:32:43.133000Z"}
{"type":"open","side":"buy","price":"790.16000000","order_id":"de925289-cadf-4860-9cf4-d36623aa0393","remaining_size":"0.22343700","product_id":"BCH-USD","sequence":4839273505,"time":"2018-07-27T01:32:43.133000Z"}
{"type":"done","side":"sell","order_id":"26f3ccbd-0a80-4538-be7d-bde6430e4eb2","reason":"canceled","product_id":"BCH-USD","price":"795.02000000","remaining_size":"2.00000000","sequence":4839273506,"time":"2018-07-27T01:32:43.133000Z"}
{"type":"done","side":"buy","order_id":"7c0ee8ad-e154-4795-a0f4-b3eeaef0661b","reason":"canceled","product_id":"BCH-USD","price":"793.61000000","remaining_size":"2.00000000","sequence":4839273507,"time":"2018-07-27T01:32:43.135000Z"}
{"type":"done","side":"sell","order_id":"8bf84c9e-e95e-4145-8ba1-84cad71ae5e8","reason":"canceled","product_id":"BCH-USD","price":"795.53000000","remaining_size":"4.50000000","sequence":4839273508,"time":"2018-07-27T01:32:43.136000Z"}
{"type":"received","order_id":"d81350f2-28fa-49b8-b32e-a2827de6fcfc","order_type":"limit","size":"1.81488800","price":"791.24000000","side":"buy","client_oid":"143e7857-25a4-4cad-98f2-89895c4ddcff","product_id":"BCH-USD","sequence":4839273509,"time":"2018-07-27T01:32:43.136000Z"}
{"type":"open","side":"buy","price":"791.24000000","order_id":"d81350f2-28fa-49b8-b32e-a2827de6fcfc","remaining_size":"1.81488800","product_id":"BCH-USD","sequence":4839273510,"time":"2018-07-27T01:32:43.136000Z"}
{"type":"received","order_id":"03c8bd4d-55df-4536-8b6d-cc62f2a0f404","order_type":"limit","size":"1.90000000","price":"794.97000000","side":"sell","client_oid":"4b9cb2ba-0e0b-4960-8819-db15ba40ae9a","product_id":"BCH-USD","sequence":4839273511,"time":"2018-07-27T01:32:43.136000Z"}
{"type":"open","side":"sell","price":"794.97000000","order_id":"03c8bd4d-55df-4536-8b6d-cc62f2a0f404","remaining_size":"1.90000000","product_id":"BCH-USD","sequence":4839273512,"time":"2018-07-27T01:32:43.136000Z"}
{"type":"done","side":"buy","order_id":"0c552abf-aada-4063-a1e0-4a77d33f95b6","reason":"canceled","product_id":"BCH-USD","price":"792.01000000","remaining_size":"0.90000000","sequence":4839273513,"time":"2018-07-27T01:32:43.137000Z"}
{"type":"done","side":"sell","order_id":"4eecca65-e099-44d4-a20d-8b6718f63189","reason":"canceled","product_id":"BCH-USD","price":"795.29000000","remaining_size":"1.90000000","sequence":4839273514,"time":"2018-07-27T01:32:43.139000Z"}
{"type":"done","side":"buy","order_id":"d81350f2-28fa-49b8-b32e-a2827de6fcfc","reason":"canceled","product_id":"BCH-USD","price":"791.24000000","remaining_size":"1.81488800","sequence":4839273515,"time":"2018-07-27T01:32:43.141000Z"}
{"type":"received","order_id":"bcf35e55-6079-4a02-8950-3bc403deb2fd","order_type":"limit","size":"0.90000000","price":"792.54000000","side":"buy","client_oid":"7aaa8b3a-5d0c-4556-8ea2-8499f3f55415","product_id":"BCH-USD","sequence":4839273516,"time":"2018-07-27T01:32:43.144000Z"}
{"type":"open","side":"buy","price":"792.54000000","order_id":"bcf35e55-6079-4a02-8950-3bc403deb2fd","remaining_size":"0.90000000","product_id":"BCH-USD","sequence":4839273517,"time":"2018-07-27T01:32:43.144000Z"}
{"type":"received","order_id":"71979d06-98f4-4189-bac7-fc3ea59aadab","order_type":"limit","size":"2.00000000","price":"795.53000000","side":"sell","client_oid":"66ae6066-a856-4c4e-9059-b8c816bb65f8","product_id":"BCH-USD","sequence":4839273518,"time":"2018-07-27T01:32:43.144000Z"}
{"type":"open","side":"sell","price":"795.53000000","order_id":"71979d06-98f4-4189-bac7-fc3ea59aadab","remaining_size":"2.00000000","product_id":"BCH-USD","sequence":4839273519,"time":"2018-07-27T01:32:43.144000Z"}
{"type":"done","side":"sell","order_id":"03c8bd4d-55df-4536-8b6d-cc62f2a0f404","reason":"canceled","product_id":"BCH-USD","price":"794.97000000","remaining_size":"1.90000000","sequence":4839273520,"time":"2018-07-27T01:32:43.146000Z"}
{"type":"done","side":"sell","order_id":"71979d06-98f4-4189-bac7-fc3ea59aadab","reason":"canceled","product_id":"BCH-USD","price":"795.53000000","remaining_size":"2.00000000","sequence":4839273521,"time":"2018-07-27T01:32:43.147000Z"}
{"type":"received","order_id":"9e52c29d-c7d7-4034-bb7a-de036cc246a2","order_type":"limit","size":"0.90000000","price":"795.01000000","side":"sell","client_oid":"4e2467ed-180e-4a20-be99-bd63f3c96f28","product_id":"BCH-USD","sequence":4839273522,"time":"2018-07-27T01:32:43.148000Z"}
{"type":"open","side":"sell","price":"795.01000000","order_id":"9e52c29d-c7d7-4034-bb7a-de036cc246a2","remaining_size":"0.90000000","product_id":"BCH-USD","sequence":4839273523,"time":"2018-07-27T01:32:43.148000Z"}
{"type":"received","order_id":"b05317f7-b5c6-4b0b-937f-6544b79f68ee","order_type":"limit","size":"12.07000000","price":"797.25000000","side":"sell","client_oid":"bbbb2954-324f-45ca-af11-fcff62b63323","product_id":"BCH-USD","sequence":4839273524,"time":"2018-07-27T01:32:43.149000Z"}
{"type":"open","side":"sell","price":"797.25000000","order_id":"b05317f7-b5c6-4b0b-937f-6544b79f68ee","remaining_size":"12.07000000","product_id":"BCH-USD","sequence":4839273525,"time":"2018-07-27T01:32:43.149000Z"}
{"type":"received","order_id":"159b166b-fc1b-43e2-8dbe-75b1c1dda3ac","order_type":"limit","size":"106.86322100","price":"83.34000000","side":"sell","client_oid":"38c2af00-88c9-4c77-8422-9595b775ddd2","product_id":"LTC-USD","sequence":2423272147,"time":"2018-07-27T01:32:43.152000Z"}
{"type":"received","order_id":"b5fea1b2-a42d-48db-b621-e8243923f174","order_type":"limit","size":"4.50000000","price":"795.02000000","side":"sell","client_oid":"a9fc6c6f-7301-4b4a-ab7e-bb5843f0a17d","product_id":"BCH-USD","sequence":4839273526,"time":"2018-07-27T01:32:43.150000Z"}
{"type":"open","side":"sell","price":"83.34000000","order_id":"159b166b-fc1b-43e2-8dbe-75b1c1dda3ac","remaining_size":"106.86322100","product_id":"LTC-USD","sequence":2423272148,"time":"2018-07-27T01:32:43.152000Z"}
{"type":"open","side":"sell","price":"795.02000000","order_id":"b5fea1b2-a42d-48db-b621-e8243923f174","remaining_size":"4.50000000","product_id":"BCH-USD","sequence":4839273527,"time":"2018-07-27T01:32:43.150000Z"}
{"type":"received","order_id":"8d00ac58-15f6-4e06-af47-66602bddabf4","order_type":"limit","size":"1.90000000","price":"795.65000000","side":"sell","client_oid":"18756118-e305-49f5-88af-eab60da41722","product_id":"BCH-USD","sequence":4839273528,"time":"2018-07-27T01:32:43.153000Z"}
{"type":"open","side":"sell","price":"795.65000000","order_id":"8d00ac58-15f6-4e06-af47-66602bddabf4","remaining_size":"1.90000000","product_id":"BCH-USD","sequence":4839273529,"time":"2018-07-27T01:32:43.153000Z"}
{"type":"received","order_id":"c57225f5-78ba-4db2-b316-17ea7de2bd0f","order_type":"limit","size":"1.90000000","price":"795.02000000","side":"sell","client_oid":"049e6be6-3a04-4977-95fa-0da009b45e19","product_id":"BCH-USD","sequence":4839273530,"time":"2018-07-27T01:32:43.153000Z"}
{"type":"open","side":"sell","price":"795.02000000","order_id":"c57225f5-78ba-4db2-b316-17ea7de2bd0f","remaining_size":"1.90000000","product_id":"BCH-USD","sequence":4839273531,"time":"2018-07-27T01:32:43.153000Z"}
{"type":"received","order_id":"75c1fde7-a524-49a9-8a5b-edb6b22668fb","order_type":"limit","size":"0.90000000","price":"794.99000000","side":"sell","client_oid":"639cd558-7c5f-491a-b392-c32ef25581b6","product_id":"BCH-USD","sequence":4839273532,"time":"2018-07-27T01:32:43.154000Z"}
{"type":"open","side":"sell","price":"794.99000000","order_id":"75c1fde7-a524-49a9-8a5b-edb6b22668fb","remaining_size":"0.90000000","product_id":"BCH-USD","sequence":4839273533,"time":"2018-07-27T01:32:43.154000Z"}
{"type":"received","order_id":"5b578d7d-292e-4294-9329-9dd9cd714bef","order_type":"limit","size":"1.81488800","price":"791.23000000","side":"buy","client_oid":"92f05adf-2b2a-4b25-abf3-2c46ec60300b","product_id":"BCH-USD","sequence":4839273534,"time":"2018-07-27T01:32:43.156000Z"}
{"type":"open","side":"buy","price":"791.23000000","order_id":"5b578d7d-292e-4294-9329-9dd9cd714bef","remaining_size":"1.81488800","product_id":"BCH-USD","sequence":4839273535,"time":"2018-07-27T01:32:43.156000Z"}
{"type":"done","side":"sell","order_id":"8d00ac58-15f6-4e06-af47-66602bddabf4","reason":"canceled","product_id":"BCH-USD","price":"795.65000000","remaining_size":"1.90000000","sequence":4839273536,"time":"2018-07-27T01:32:43.157000Z"}
{"type":"done","side":"sell","order_id":"75c1fde7-a524-49a9-8a5b-edb6b22668fb","reason":"canceled","product_id":"BCH-USD","price":"794.99000000","remaining_size":"0.90000000","sequence":4839273537,"time":"2018-07-27T01:32:43.159000Z"}
{"type":"received","order_id":"69aa70aa-cb74-4d4a-9a55-d107be22b6eb","order_type":"limit","size":"2.00000000","price":"793.99000000","side":"buy","client_oid":"54995ca6-bfff-48ec-934b-59e0ebbd058c","product_id":"BCH-USD","sequence":4839273538,"time":"2018-07-27T01:32:43.161000Z"}
{"type":"open","side":"buy","price":"793.99000000","order_id":"69aa70aa-cb74-4d4a-9a55-d107be22b6eb","remaining_size":"2.00000000","product_id":"BCH-USD","sequence":4839273539,"time":"2018-07-27T01:32:43.161000Z"}
{"type":"received","order_id":"1491cab4-2a8f-4106-856d-3bbd038c2212","order_type":"limit","size":"0.15114700","price":"788.72000000","side":"buy","client_oid":"9cb3f02b-76ec-439d-83b0-c0967d6f0347","product_id":"BCH-USD","sequence":4839273540,"time":"2018-07-27T01:32:43.161000Z"}
{"type":"open","side":"buy","price":"788.72000000","order_id":"1491cab4-2a8f-4106-856d-3bbd038c2212","remaining_size":"0.15114700","product_id":"BCH-USD","sequence":4839273541,"time":"2018-07-27T01:32:43.161000Z"}
{"type":"done","side":"sell","order_id":"61d4db90-9595-452f-a56d-a68be43338e6","reason":"canceled","product_id":"LTC-USD","price":"83.30000000","remaining_size":"7.44874862","sequence":2423272149,"time":"2018-07-27T01:32:43.167000Z"}
{"type":"done","side":"sell","order_id":"9e52c29d-c7d7-4034-bb7a-de036cc246a2","reason":"canceled","product_id":"BCH-USD","price":"795.01000000","remaining_size":"0.90000000","sequence":4839273542,"time":"2018-07-27T01:32:43.165000Z"}
{"type":"received","order_id":"c7d6c591-6b4a-469a-b5e5-b4c044cec1d1","order_type":"limit","size":"4.50000000","price":"796.05000000","side":"sell","client_oid":"9b05996a-7533-4451-8e78-81d6d185470b","product_id":"BCH-USD","sequence":4839273543,"time":"2018-07-27T01:32:43.166000Z"}
{"type":"open","side":"sell","price":"796.05000000","order_id":"c7d6c591-6b4a-469a-b5e5-b4c044cec1d1","remaining_size":"4.50000000","product_id":"BCH-USD","sequence":4839273544,"time":"2018-07-27T01:32:43.166000Z"}
{"type":"received","order_id":"3147f296-bd5b-46dc-962b-0a6b5200bea4","order_type":"limit","size":"2.00000000","price":"795.30000000","side":"sell","client_oid":"edc8ea60-cd7d-430d-bbaa-2c9b6a57e735","product_id":"BCH-USD","sequence":4839273545,"time":"2018-07-27T01:32:43.166000Z"}
{"type":"open","side":"sell","price":"795.30000000","order_id":"3147f296-bd5b-46dc-962b-0a6b5200bea4","remaining_size":"2.00000000","product_id":"BCH-USD","sequence":4839273546,"time":"2018-07-27T01:32:43.166000Z"}
{"type":"received","order_id":"9dd703d9-f5ba-48e0-b9e1-853a339409ce","order_type":"limit","size":"0.90000000","price":"795.02000000","side":"sell","client_oid":"b0e6aa31-4fe9-4c9b-a7a0-ccba93f1a7f1","product_id":"BCH-USD","sequence":4839273547,"time":"2018-07-27T01:32:43.168000Z"}
{"type":"open","side":"sell","price":"795.02000000","order_id":"9dd703d9-f5ba-48e0-b9e1-853a339409ce","remaining_size":"0.90000000","product_id":"BCH-USD","sequence":4839273548,"time":"2018-07-27T01:32:43.168000Z"}
{"type":"received","order_id":"75fa8ef7-44c9-4ffb-b5ad-b5477b4ed019","order_type":"limit","size":"14.85783700","price":"83.37000000","side":"sell","client_oid":"8e969edf-5703-4c88-a882-590f5b1d8340","product_id":"LTC-USD","sequence":2423272150,"time":"2018-07-27T01:32:43.172000Z"}
{"type":"open","side":"sell","price":"83.37000000","order_id":"75fa8ef7-44c9-4ffb-b5ad-b5477b4ed019","remaining_size":"14.85783700","product_id":"LTC-USD","sequence":2423272151,"time":"2018-07-27T01:32:43.172000Z"}
{"type":"received","order_id":"0c3dacd1-a236-426f-9b37-90a7a392d98f","order_type":"limit","size":"20.53100000","price":"794.99000000","side":"sell","product_id":"BCH-USD","sequence":4839273549,"time":"2018-07-27T01:32:43.172000Z"}
{"type":"open","side":"sell","price":"794.99000000","order_id":"0c3dacd1-a236-426f-9b37-90a7a392d98f","remaining_size":"20.53100000","product_id":"BCH-USD","sequence":4839273550,"time":"2018-07-27T01:32:43.172000Z"}
{"type":"received","order_id":"0ba8a4a5-f6ea-4448-88fa-41f9ff0164b6","order_type":"limit","size":"0.19519300","price":"788.48000000","side":"buy","client_oid":"85087c72-e35b-4e61-b275-f13a245756c9","product_id":"BCH-USD","sequence":4839273551,"time":"2018-07-27T01:32:43.176000Z"}
{"type":"open","side":"buy","price":"788.48000000","order_id":"0ba8a4a5-f6ea-4448-88fa-41f9ff0164b6","remaining_size":"0.19519300","product_id":"BCH-USD","sequence":4839273552,"time":"2018-07-27T01:32:43.176000Z"}
{"type":"received","order_id":"6720f315-f4c7-4ab3-b825-5b578b9351d3","order_type":"limit","size":"1.90000000","price":"795.67000000","side":"sell","client_oid":"50cb00b2-5c38-4b2f-b750-f1bf6d343712","product_id":"BCH-USD","sequence":4839273553,"time":"2018-07-27T01:32:43.176000Z"}
{"type":"open","side":"sell","price":"795.67000000","order_id":"6720f315-f4c7-4ab3-b825-5b578b9351d3","remaining_size":"1.90000000","product_id":"BCH-USD","sequence":4839273554,"time":"2018-07-27T01:32:43.176000Z"}
{"type":"received","order_id":"7f17f7a0-781e-4c0d-aa1e-56bcb5fb54cb","order_type":"limit","size":"0.90000000","price":"795.29000000","side":"sell","client_oid":"0df3fadf-2476-47e8-ad62-e71963368844","product_id":"BCH-USD","sequence":4839273555,"time":"2018-07-27T01:32:43.180000Z"}
{"type":"open","side":"sell","price":"795.29000000","order_id":"7f17f7a0-781e-4c0d-aa1e-56bcb5fb54cb","remaining_size":"0.90000000","product_id":"BCH-USD","sequence":4839273556,"time":"2018-07-27T01:32:43.180000Z"}
{"type":"received","order_id":"f45ea34d-7738-4e0e-ae17-606fa221b8bb","order_type":"limit","size":"4.60017900","price":"83.40000000","side":"sell","client_oid":"8106f5a8-2f8f-4497-ae67-0dd963a9d361","product_id":"LTC-USD","sequence":2423272152,"time":"2018-07-27T01:32:43.183000Z"}
{"type":"done","side":"buy","order_id":"5b578d7d-292e-4294-9329-9dd9cd714bef","reason":"canceled","product_id":"BCH-USD","price":"791.23000000","remaining_size":"1.81488800","sequence":4839273557,"time":"2018-07-27T01:32:43.181000Z"}
{"type":"open","side":"sell","price":"83.40000000","order_id":"f45ea34d-7738-4e0e-ae17-606fa221b8bb","remaining_size":"4.60017900","product_id":"LTC-USD","sequence":2423272153,"time":"2018-07-27T01:32:43.183000Z"}
{"type":"done","side":"sell","order_id":"6720f315-f4c7-4ab3-b825-5b578b9351d3","reason":"canceled","product_id":"BCH-USD","price":"795.67000000","remaining_size":"1.90000000","sequence":4839273558,"time":"2018-07-27T01:32:43.182000Z"}
{"type":"received","order_id":"fbb7a9c7-3e66-4c45-a7f5-afb1fb24888e","order_type":"limit","size":"7.44874862","price":"83.34000000","side":"sell","client_oid":"8028709f-6428-4f46-8000-000906037eae","product_id":"LTC-USD","sequence":2423272154,"time":"2018-07-27T01:32:43.184000Z"}
{"type":"open","side":"sell","price":"83.34000000","order_id":"fbb7a9c7-3e66-4c45-a7f5-afb1fb24888e","remaining_size":"7.44874862","product_id":"LTC-USD","sequence":2423272155,"time":"2018-07-27T01:32:43.184000Z"}
{"type":"received","order_id":"c17e8aee-4c1e-4bc3-b245-e9eca1ae4f3d","order_type":"limit","size":"3.22292300","price":"788.24000000","side":"buy","client_oid":"82a60233-a796-4323-9d4d-45ab4b3d6988","product_id":"BCH-USD","sequence":4839273559,"time":"2018-07-27T01:32:43.185000Z"}
{"type":"open","side":"buy","price":"788.24000000","order_id":"c17e8aee-4c1e-4bc3-b245-e9eca1ae4f3d","remaining_size":"3.22292300","product_id":"BCH-USD","sequence":4839273560,"time":"2018-07-27T01:32:43.185000Z"}
{"type":"received","order_id":"65a7cf52-d042-4293-81b9-68230902a578","order_type":"limit","size":"0.15000000","price":"431.20000000","side":"buy","product_id":"ETH-USD","sequence":4469354868,"time":"2018-07-27T01:32:43.187000Z"}
{"type":"open","side":"buy","price":"431.20000000","order_id":"65a7cf52-d042-4293-81b9-68230902a578","remaining_size":"0.15000000","product_id":"ETH-USD","sequence":4469354869,"time":"2018-07-27T01:32:43.187000Z"}
{"type":"received","order_id":"617c4743-3993-44b0-9081-55c67fabac86","order_type":"limit","size":"1.90000000","price":"795.64000000","side":"sell","client_oid":"01e6ed02-8a6f-407f-9111-259d0b754cc8","product_id":"BCH-USD","sequence":4839273561,"time":"2018-07-27T01:32:43.189000Z"}
{"type":"open","side":"sell","price":"795.64000000","order_id":"617c4743-3993-44b0-9081-55c67fabac86","remaining_size":"1.90000000","product_id":"BCH-USD","sequence":4839273562,"time":"2018-07-27T01:32:43.189000Z"}
{"type":"received","order_id":"8a242f52-93b3-41d3-b39a-ad4584495efc","order_type":"limit","size":"1.81488800","price":"791.24000000","side":"buy","client_oid":"5c018608-2905-4f72-976d-37c5642fa3e5","product_id":"BCH-USD","sequence":4839273563,"time":"2018-07-27T01:32:43.192000Z"}
{"type":"open","side":"buy","price":"791.24000000","order_id":"8a242f52-93b3-41d3-b39a-ad4584495efc","remaining_size":"1.81488800","product_id":"BCH-USD","sequence":4839273564,"time":"2018-07-27T01:32:43.192000Z"}
{"type":"done","side":"buy","order_id":"1dcdec79-a5b2-4608-b9d6-0189f0301000","reason":"canceled","product_id":"BCH-USD","price":"791.24000000","remaining_size":"0.18739300","sequence":4839273565,"time":"2018-07-27T01:32:43.194000Z"}
{"type":"done","side":"sell","order_id":"617c4743-3993-44b0-9081-55c67fabac86","reason":"canceled","product_id":"BCH-USD","price":"795.64000000","remaining_size":"1.90000000","sequence":4839273566,"time":"2018-07-27T01:32:43.194000Z"}
{"type":"done","side":"sell","order_id":"9dd703d9-f5ba-48e0-b9e1-853a339409ce","reason":"canceled","product_id":"BCH-USD","price":"795.02000000","remaining_size":"0.90000000","sequence":4839273567,"time":"2018-07-27T01:32:43.196000Z"}
{"type":"done","side":"sell","order_id":"b5fea1b2-a42d-48db-b621-e8243923f174","reason":"canceled","product_id":"BCH-USD","price":"795.02000000","remaining_size":"4.50000000","sequence":4839273568,"time":"2018-07-27T01:32:43.196000Z"}
{"type":"done","side":"sell","order_id":"c7d6c591-6b4a-469a-b5e5-b4c044cec1d1","reason":"canceled","product_id":"BCH-USD","price":"796.05000000","remaining_size":"4.50000000","sequence":4839273569,"time":"2018-07-27T01:32:43.199000Z"}
{"type":"done","side":"buy","order_id":"a7a20fca-6d13-4d15-a37e-8a0e1e368069","reason":"canceled","product_id":"BCH-USD","price":"792.01000000","remaining_size":"1.90000000","sequence":4839273570,"time":"2018-07-27T01:32:43.201000Z"}
{"type":"done","side":"buy","order_id":"0d7c39ce-d99c-491a-a4f9-bc123d7fc000","reason":"canceled","product_id":"BCH-USD","price":"792.54000000","remaining_size":"0.90000000","sequence":4839273571,"time":"2018-07-27T01:32:43.202000Z"}
{"type":"done","side":"buy","order_id":"8a242f52-93b3-41d3-b39a-ad4584495efc","reason":"canceled","product_id":"BCH-USD","price":"791.24000000","remaining_size":"1.81488800","sequence":4839273572,"time":"2018-07-27T01:32:43.202000Z"}
{"type":"received","order_id":"85dea849-8ced-4f99-a676-d215c10b81c2","order_type":"limit","size":"0.25379600","price":"788.00000000","side":"buy","client_oid":"18c0fcb9-f804-4ebe-a966-f61434924d32","product_id":"BCH-USD","sequence":4839273573,"time":"2018-07-27T01:32:43.202000Z"}
{"type":"open","side":"buy","price":"788.00000000","order_id":"85dea849-8ced-4f99-a676-d215c10b81c2","remaining_size":"0.25379600","product_id":"BCH-USD","sequence":4839273574,"time":"2018-07-27T01:32:43.202000Z"}
{"type":"done","side":"sell","order_id":"c57225f5-78ba-4db2-b316-17ea7de2bd0f","reason":"canceled","product_id":"BCH-USD","price":"795.02000000","remaining_size":"1.90000000","sequence":4839273575,"time":"2018-07-27T01:32:43.203000Z"}
{"type":"received","order_id":"9fc74794-15d3-4535-8d3c-09d3d4004bd7","order_type":"limit","size":"0.90000000","price":"793.12000000","side":"buy","client_oid":"5e5a1672-2f7d-4338-8d28-8eb488221174","product_id":"BCH-USD","sequence":4839273576,"time":"2018-07-27T01:32:43.205000Z"}
{"type":"done","side":"sell","order_id":"46413c63-bd48-4368-b073-dc454a5191e9","reason":"canceled","product_id":"LTC-USD","price":"83.38000000","remaining_size":"7.44874862","sequence":2423272156,"time":"2018-07-27T01:32:43.208000Z"}
{"type":"open","side":"buy","price":"793.12000000","order_id":"9fc74794-15d3-4535-8d3c-09d3d4004bd7","remaining_size":"0.90000000","product_id":"BCH-USD","sequence":4839273577,"time":"2018-07-27T01:32:43.205000Z"}
{"type":"received","order_id":"1042a662-4376-4735-9cf8-b7884864e27c","order_type":"limit","size":"0.90000000","price":"794.98000000","side":"sell","client_oid":"de8fae1f-e747-441c-991c-734ef176e7c1","product_id":"BCH-USD","sequence":4839273578,"time":"2018-07-27T01:32:43.206000Z"}
{"type":"open","side":"sell","price":"794.98000000","order_id":"1042a662-4376-4735-9cf8-b7884864e27c","remaining_size":"0.90000000","product_id":"BCH-USD","sequence":4839273579,"time":"2018-07-27T01:32:43.206000Z"}
{"type":"done","side":"sell","order_id":"3147f296-bd5b-46dc-962b-0a6b5200bea4","reason":"canceled","product_id":"BCH-USD","price":"795.30000000","remaining_size":"2.00000000","sequence":4839273580,"time":"2018-07-27T01:32:43.207000Z"}
{"type":"received","order_id":"d906d9ff-8a2e-4e8b-98ee-c26029b7fe9d","order_type":"limit","size":"1.90000000","price":"795.67000000","side":"sell","client_oid":"113914e1-efa8-48df-b5dd-92c255c8dfc8","product_id":"BCH-USD","sequence":4839273581,"time":"2018-07-27T01:32:43.208000Z"}
{"type":"open","side":"sell","price":"795.67000000","order_id":"d906d9ff-8a2e-4e8b-98ee-c26029b7fe9d","remaining_size":"1.90000000","product_id":"BCH-USD","sequence":4839273582,"time":"2018-07-27T01:32:43.208000Z"}
{"type":"received","order_id":"aca93a95-68d5-480f-b4cb-a22c4aaf3917","order_type":"limit","size":"4.50000000","price":"796.03000000","side":"sell","client_oid":"bca520f1-b7aa-4d4a-a0b7-cab3b880dca8","product_id":"BCH-USD","sequence":4839273583,"time":"2018-07-27T01:32:43.209000Z"}
{"type":"open","side":"sell","price":"796.03000000","order_id":"aca93a95-68d5-480f-b4cb-a22c4aaf3917","remaining_size":"4.50000000","product_id":"BCH-USD","sequence":4839273584,"time":"2018-07-27T01:32:43.209000Z"}
{"type":"received","order_id":"b4a95db5-7ead-4128-9e3a-fab5b411fa11","order_type":"limit","size":"0.91014900","price":"787.52000000","side":"buy","client_oid":"a289ce31-03a6-492e-853e-8fd380a02497","product_id":"BCH-USD","sequence":4839273585,"time":"2018-07-27T01:32:43.212000Z"}
{"type":"open","side":"buy","price":"787.52000000","order_id":"b4a95db5-7ead-4128-9e3a-fab5b411fa11","remaining_size":"0.91014900","product_id":"BCH-USD","sequence":4839273586,"time":"2018-07-27T01:32:43.212000Z"}
{"type":"received","order_id":"8060e1c6-6e3e-4230-a1b2-3a8525ea6395","order_type":"limit","size":"1.90000000","price":"792.54000000","side":"buy","client_oid":"4e08e06e-5833-4a7f-87f2-12fab8f97159","product_id":"BCH-USD","sequence":4839273587,"time":"2018-07-27T01:32:43.213000Z"}
{"type":"open","side":"buy","price":"792.54000000","order_id":"8060e1c6-6e3e-4230-a1b2-3a8525ea6395","remaining_size":"1.90000000","product_id":"BCH-USD","sequence":4839273588,"time":"2018-07-27T01:32:43.213000Z"}
{"type":"received","order_id":"29744c27-39ef-4ff3-8b2b-5d85a67b55da","order_type":"limit","size":"1.90000000","price":"795.29000000","side":"sell","client_oid":"cfc17037-687b-4eaa-9d74-50c7a74c437c","product_id":"BCH-USD","sequence":4839273589,"time":"2018-07-27T01:32:43.216000Z"}
{"type":"open","side":"sell","price":"795.29000000","order_id":"29744c27-39ef-4ff3-8b2b-5d85a67b55da","remaining_size":"1.90000000","product_id":"BCH-USD","sequence":4839273590,"time":"2018-07-27T01:32:43.216000Z"}
{"type":"done","side":"sell","order_id":"1042a662-4376-4735-9cf8-b7884864e27c","reason":"canceled","product_id":"BCH-USD","price":"794.98000000","remaining_size":"0.90000000","sequence":4839273591,"time":"2018-07-27T01:32:43.218000Z"}
{"type":"received","order_id":"6f7c186d-ab7e-4b30-8397-41a78481843f","order_type":"limit","size":"1.81488800","price":"791.23000000","side":"buy","client_oid":"36fe5ca9-85c1-4275-a9eb-0ebcab416533","product_id":"BCH-USD","sequence":4839273592,"time":"2018-07-27T01:32:43.218000Z"}
{"type":"open","side":"buy","price":"791.23000000","order_id":"6f7c186d-ab7e-4b30-8397-41a78481843f","remaining_size":"1.81488800","product_id":"BCH-USD","sequence":4839273593,"time":"2018-07-27T01:32:43.218000Z"}
{"type":"received","order_id":"6a9aaed3-7cc6-49ee-b16a-7bfca297e353","order_type":"limit","size":"7.44874862","price":"83.30000000","side":"sell","client_oid":"579794fe-f840-41d5-8000-00a763708264","product_id":"LTC-USD","sequence":2423272157,"time":"2018-07-27T01:32:43.226000Z"}
{"type":"done","side":"buy","order_id":"6f7c186d-ab7e-4b30-8397-41a78481843f","reason":"canceled","product_id":"BCH-USD","price":"791.23000000","remaining_size":"1.81488800","sequence":4839273594,"time":"2018-07-27T01:32:43.224000Z"}
{"type":"open","side":"sell","price":"83.30000000","order_id":"6a9aaed3-7cc6-49ee-b16a-7bfca297e353","remaining_size":"7.44874862","product_id":"LTC-USD","sequence":2423272158,"time":"2018-07-27T01:32:43.226000Z"}
{"type":"received","order_id":"bec90cda-4c19-401e-9aea-3e753c610274","order_type":"limit","size":"4.50000000","price":"795.29000000","side":"sell","client_oid":"16793483-7df3-4190-bb60-00211af721b3","product_id":"BCH-USD","sequence":4839273595,"time":"2018-07-27T01:32:43.227000Z"}
{"type":"open","side":"sell","price":"795.29000000","order_id":"bec90cda-4c19-401e-9aea-3e753c610274","remaining_size":"4.50000000","product_id":"BCH-USD","sequence":4839273596,"time":"2018-07-27T01:32:43.227000Z"}
{"type":"received","order_id":"e08cf357-0684-4d2a-aa8e-f0e73e4e8ca5","order_type":"limit","size":"2.00000000","price":"795.29000000","side":"sell","client_oid":"906b38aa-9657-45fe-b839-fbbde2fdc3fa","product_id":"BCH-USD","sequence":4839273597,"time":"2018-07-27T01:32:43.229000Z"}
{"type":"open","side":"sell","price":"795.29000000","order_id":"e08cf357-0684-4d2a-aa8e-f0e73e4e8ca5","remaining_size":"2.00000000","product_id":"BCH-USD","sequence":4839273598,"time":"2018-07-27T01:32:43.229000Z"}
{"type":"received","order_id":"9c8cf870-9aaa-4697-b49b-5d5ef3e6ea65","order_type":"limit","size":"1.81488800","price":"791.25000000","side":"buy","client_oid":"df17ca13-24ee-445f-91f9-cedea9c3fc55","product_id":"BCH-USD","sequence":4839273599,"time":"2018-07-27T01:32:43.231000Z"}
{"type":"open","side":"buy","price":"791.25000000","order_id":"9c8cf870-9aaa-4697-b49b-5d5ef3e6ea65","remaining_size":"1.81488800","product_id":"BCH-USD","sequence":4839273600,"time":"2018-07-27T01:32:43.231000Z"}
{"type":"done","side":"buy","order_id":"9c8cf870-9aaa-4697-b49b-5d5ef3e6ea65","reason":"canceled","product_id":"BCH-USD","price":"791.25000000","remaining_size":"1.81488800","sequence":4839273601,"time":"2018-07-27T01:32:43.235000Z"}
{"type":"received","order_id":"51e5d225-6af7-4b08-9798-bd5a062b5653","order_type":"limit","size":"0.18739300","price":"792.01000000","side":"buy","client_oid":"2184697a-a5dd-46ec-ad4d-a563e87b5aa7","product_id":"BCH-USD","sequence":4839273602,"time":"2018-07-27T01:32:43.238000Z"}
{"type":"open","side":"buy","price":"792.01000000","order_id":"51e5d225-6af7-4b08-9798-bd5a062b5653","remaining_size":"0.18739300","product_id":"BCH-USD","sequence":4839273603,"time":"2018-07-27T01:32:43.238000Z"}
{"type":"done","side":"sell","order_id":"29744c27-39ef-4ff3-8b2b-5d85a67b55da","reason":"canceled","product_id":"BCH-USD","price":"795.29000000","remaining_size":"1.90000000","sequence":4839273604,"time":"2018-07-27T01:32:43.240000Z"}
{"type":"done","side":"sell","order_id":"bec90cda-4c19-401e-9aea-3e753c610274","reason":"canceled","product_id":"BCH-USD","price":"795.29000000","remaining_size":"4.50000000","sequence":4839273605,"time":"2018-07-27T01:32:43.241000Z"}
{"type":"received","order_id":"a872d689-df95-4d8c-9a97-b463ae56eb68","order_type":"limit","size":"1.81488800","price":"791.23000000","side":"buy","client_oid":"7f3e8b61-a3ae-41a1-b8ad-72749dd4d0fb","product_id":"BCH-USD","sequence":4839273606,"time":"2018-07-27T01:32:43.243000Z"}
{"type":"open","side":"buy","price":"791.23000000","order_id":"a872d689-df95-4d8c-9a97-b463ae56eb68","remaining_size":"1.81488800","product_id":"BCH-USD","sequence":4839273607,"time":"2018-07-27T01:32:43.243000Z"}
{"type":"done","side":"sell","order_id":"6ff8b0dd-9e19-4d01-ab4a-33c692904cde","reason":"canceled","product_id":"BCH-USD","price":"797.69000000","remaining_size":"0.50000000","sequence":4839273608,"time":"2018-07-27T01:32:43.243000Z"}
{"type":"done","side":"buy","order_id":"a872d689-df95-4d8c-9a97-b463ae56eb68","reason":"canceled","product_id":"BCH-USD","price":"791.23000000","remaining_size":"1.81488800","sequence":4839273609,"time":"2018-07-27T01:32:43.248000Z"}
{"type":"received","order_id":"71a3fe5e-ad88-4ccc-9a47-ccd5eba88064","order_type":"limit","size":"0.90000000","price":"794.97000000","side":"sell","client_oid":"6f858d52-721a-4e5c-945b-866ef7b7970e","product_id":"BCH-USD","sequence":4839273610,"time":"2018-07-27T01:32:43.249000Z"}
{"type":"open","side":"sell","price":"794.97000000","order_id":"71a3fe5e-ad88-4ccc-9a47-ccd5eba88064","remaining_size":"0.90000000","product_id":"BCH-USD","sequence":4839273611,"time":"2018-07-27T01:32:43.249000Z"}
{"type":"done","side":"sell","order_id":"7f17f7a0-781e-4c0d-aa1e-56bcb5fb54cb","reason":"canceled","product_id":"BCH-USD","price":"795.29000000","remaining_size":"0.90000000","sequence":4839273612,"time":"2018-07-27T01:32:43.252000Z"}
{"type":"received","order_id":"8e093e44-9b45-4375-9d44-d3f9a71f49dc","order_type":"limit","size":"4.50000000","price":"795.28000000","side":"sell","client_oid":"76f5d1f3-c2ed-499d-b6b7-d536c920f329","product_id":"BCH-USD","sequence":4839273613,"time":"2018-07-27T01:32:43.253000Z"}
{"type":"open","side":"sell","price":"795.28000000","order_id":"8e093e44-9b45-4375-9d44-d3f9a71f49dc","remaining_size":"4.50000000","product_id":"BCH-USD","sequence":4839273614,"time":"2018-07-27T01:32:43.253000Z"}
{"type":"done","side":"sell","order_id":"71a3fe5e-ad88-4ccc-9a47-ccd5eba88064","reason":"canceled","product_id":"BCH-USD","price":"794.97000000","remaining_size":"0.90000000","sequence":4839273615,"time":"2018-07-27T01:32:43.254000Z"}
{"type":"done","side":"sell","order_id":"8e093e44-9b45-4375-9d44-d3f9a71f49dc","reason":"canceled","product_id":"BCH-USD","price":"795.28000000","remaining_size":"4.50000000","sequence":4839273616,"time":"2018-07-27T01:32:43.255000Z"}
{"type":"done","side":"sell","order_id":"d906d9ff-8a2e-4e8b-98ee-c26029b7fe9d","reason":"canceled","product_id":"BCH-USD","price":"795.67000000","remaining_size":"1.90000000","sequence":4839273617,"time":"2018-07-27T01:32:43.256000Z"}
{"type":"received","order_id":"acfbb430-ff6b-4348-9cb8-6ea9b47e1f58","order_type":"limit","size":"1.81488800","price":"791.24000000","side":"buy","client_oid":"744b9d23-906e-460e-904c-70801d676c80","product_id":"BCH-USD","sequence":4839273618,"time":"2018-07-27T01:32:43.256000Z"}
{"type":"open","side":"buy","price":"791.24000000","order_id":"acfbb430-ff6b-4348-9cb8-6ea9b47e1f58","remaining_size":"1.81488800","product_id":"BCH-USD","sequence":4839273619,"time":"2018-07-27T01:32:43.256000Z"}
{"type":"done","side":"sell","order_id":"e08cf357-0684-4d2a-aa8e-f0e73e4e8ca5","reason":"canceled","product_id":"BCH-USD","price":"795.29000000","remaining_size":"2.00000000","sequence":4839273620,"time":"2018-07-27T01:32:43.257000Z"}
{"type":"done","side":"buy","order_id":"acfbb430-ff6b-4348-9cb8-6ea9b47e1f58","reason":"canceled","product_id":"BCH-USD","price":"791.24000000","remaining_size":"1.81488800","sequence":4839273621,"time":"2018-07-27T01:32:43.260000Z"}
{"type":"done","side":"sell","order_id":"8052e7c9-b108-46dd-93e5-2f61fd7eadb0","reason":"canceled","product_id":"BCH-USD","price":"795.53000000","remaining_size":"1.60461000","sequence":4839273622,"time":"2018-07-27T01:32:43.262000Z"}
{"type":"received","order_id":"aabc2e92-0592-446e-a21f-4edc3c3fb4c8","order_type":"limit","size":"0.90000000","price":"795.28000000","side":"sell","client_oid":"a2b7b9e9-ec47-4cc9-899f-5f30e9e7da84","product_id":"BCH-USD","sequence":4839273623,"time":"2018-07-27T01:32:43.264000Z"}
{"type":"open","side":"sell","price":"795.28000000","order_id":"aabc2e92-0592-446e-a21f-4edc3c3fb4c8","remaining_size":"0.90000000","product_id":"BCH-USD","sequence":4839273624,"time":"2018-07-27T01:32:43.264000Z"}
{"type":"received","order_id":"a8ca2f2b-640d-458c-b251-7a373e22f884","order_type":"limit","size":"1.90000000","price":"795.28000000","side":"sell","client_oid":"e23e4bc0-c7a5-4a6d-bc5f-07d24234cc33","product_id":"BCH-USD","sequence":4839273625,"time":"2018-07-27T01:32:43.264000Z"}
{"type":"open","side":"sell","price":"795.28000000","order_id":"a8ca2f2b-640d-458c-b251-7a373e22f884","remaining_size":"1.90000000","product_id":"BCH-USD","sequence":4839273626,"time":"2018-07-27T01:32:43.264000Z"}
{"type":"done","side":"sell","order_id":"fbb7a9c7-3e66-4c45-a7f5-afb1fb24888e","reason":"canceled","product_id":"LTC-USD","price":"83.34000000","remaining_size":"7.44874862","sequence":2423272159,"time":"2018-07-27T01:32:43.267000Z"}
{"type":"received","order_id":"29bceefd-2a31-415b-9d50-28e94d4eb0c7","order_type":"limit","size":"2.00000000","price":"795.53000000","side":"sell","client_oid":"21486e82-3bf8-435c-aae6-0c5de5d14f00","product_id":"BCH-USD","sequence":4839273627,"time":"2018-07-27T01:32:43.268000Z"}
{"type":"open","side":"sell","price":"795.53000000","order_id":"29bceefd-2a31-415b-9d50-28e94d4eb0c7","remaining_size":"2.00000000","product_id":"BCH-USD","sequence":4839273628,"time":"2018-07-27T01:32:43.268000Z"}
{"type":"received","order_id":"524818ea-cc22-44b3-a856-a9ebc8d41140","order_type":"limit","size":"1.90000000","price":"795.63000000","side":"sell","client_oid":"12a66304-a87f-43c6-83b6-265cbe7e6fdb","product_id":"BCH-USD","sequence":4839273629,"time":"2018-07-27T01:32:43.268000Z"}
{"type":"open","side":"sell","price":"795.63000000","order_id":"524818ea-cc22-44b3-a856-a9ebc8d41140","remaining_size":"1.90000000","product_id":"BCH-USD","sequence":4839273630,"time":"2018-07-27T01:32:43.268000Z"}
{"type":"done","side":"sell","order_id":"a8ca2f2b-640d-458c-b251-7a373e22f884","reason":"canceled","product_id":"BCH-USD","price":"795.28000000","remaining_size":"1.90000000","sequence":4839273631,"time":"2018-07-27T01:32:43.274000Z"}
{"type":"received","order_id":"1cf46062-37e3-444a-a356-c2c3ca87e1aa","order_type":"limit","size":"0.90000000","price":"794.98000000","side":"sell","client_oid":"e20fbb66-48a6-418a-b0af-7cab2a4be36e","product_id":"BCH-USD","sequence":4839273632,"time":"2018-07-27T01:32:43.276000Z"}
{"type":"open","side":"sell","price":"794.98000000","order_id":"1cf46062-37e3-444a-a356-c2c3ca87e1aa","remaining_size":"0.90000000","product_id":"BCH-USD","sequence":4839273633,"time":"2018-07-27T01:32:43.276000Z"}
{"type":"done","side":"sell","order_id":"6a9aaed3-7cc6-49ee-b16a-7bfca297e353","reason":"canceled","product_id":"LTC-USD","price":"83.30000000","remaining_size":"7.44874862","sequence":2423272160,"time":"2018-07-27T01:32:43.279000Z"}
{"type":"done","side":"sell","order_id":"29bceefd-2a31-415b-9d50-28e94d4eb0c7","reason":"canceled","product_id":"BCH-USD","price":"795.53000000","remaining_size":"2.00000000","sequence":4839273634,"time":"2018-07-27T01:32:43.278000Z"}
{"type":"received","order_id":"4ad765a3-eb1d-4729-801f-6c77be4066a9","order_type":"limit","size":"4.50000000","price":"795.29000000","side":"sell","client_oid":"b11e662e-39f6-497c-b2c2-2552fcd0003a","product_id":"BCH-USD","sequence":4839273635,"time":"2018-07-27T01:32:43.280000Z"}
{"type":"open","side":"sell","price":"795.29000000","order_id":"4ad765a3-eb1d-4729-801f-6c77be4066a9","remaining_size":"4.50000000","product_id":"BCH-USD","sequence":4839273636,"time":"2018-07-27T01:32:43.280000Z"}
{"type":"received","order_id":"00bd13a1-3950-4436-9371-ac804379477c","order_type":"limit","size":"1.81488800","price":"791.23000000","side":"buy","client_oid":"34738d6d-99fe-462d-ab31-4194a02e385e","product_id":"BCH-USD","sequence":4839273637,"time":"2018-07-27T01:32:43.280000Z"}
{"type":"open","side":"buy","price":"791.23000000","order_id":"00bd13a1-3950-4436-9371-ac804379477c","remaining_size":"1.81488800","product_id":"BCH-USD","sequence":4839273638,"time":"2018-07-27T01:32:43.280000Z"}
{"type":"done","side":"sell","order_id":"1cf46062-37e3-444a-a356-c2c3ca87e1aa","reason":"canceled","product_id":"BCH-USD","price":"794.98000000","remaining_size":"0.90000000","sequence":4839273639,"time":"2018-07-27T01:32:43.284000Z"}
{"type":"received","order_id":"d06d891e-70c4-4478-bfa2-850ba444e02a","order_type":"limit","size":"7.44874862","price":"83.38000000","side":"sell","client_oid":"1ee7a4c1-28ae-422c-8000-008b7dbfa5b9","product_id":"LTC-USD","sequence":2423272161,"time":"2018-07-27T01:32:43.287000Z"}
{"type":"open","side":"sell","price":"83.38000000","order_id":"d06d891e-70c4-4478-bfa2-850ba444e02a","remaining_size":"7.44874862","product_id":"LTC-USD","sequence":2423272162,"time":"2018-07-27T01:32:43.287000Z"}
{"type":"done","side":"buy","order_id":"00bd13a1-3950-4436-9371-ac804379477c","reason":"canceled","product_id":"BCH-USD","price":"791.23000000","remaining_size":"1.81488800","sequence":4839273640,"time":"2018-07-27T01:32:43.288000Z"}
{"type":"received","order_id":"c800b8f2-0357-423f-bfa9-ecb8e8d847ff","order_type":"limit","size":"1.90000000","price":"795.29000000","side":"sell","client_oid":"a572b8e3-86f8-4f58-949d-480436eeb7a8","product_id":"BCH-USD","sequence":4839273641,"time":"2018-07-27T01:32:43.290000Z"}
{"type":"open","side":"sell","price":"795.29000000","order_id":"c800b8f2-0357-423f-bfa9-ecb8e8d847ff","remaining_size":"1.90000000","product_id":"BCH-USD","sequence":4839273642,"time":"2018-07-27T01:32:43.290000Z"}
{"type":"done","side":"sell","order_id":"4ad765a3-eb1d-4729-801f-6c77be4066a9","reason":"canceled","product_id":"BCH-USD","price":"795.29000000","remaining_size":"4.50000000","sequence":4839273643,"time":"2018-07-27T01:32:43.292000Z"}
{"type":"received","order_id":"3ed1af24-e1bb-48be-b061-93b98a362ba3","order_type":"limit","size":"2.00000000","price":"795.28000000","side":"sell","client_oid":"e6dab59f-eeec-46ce-9675-9c6bf54d3d86","product_id":"BCH-USD","sequence":4839273644,"time":"2018-07-27T01:32:43.294000Z"}
{"type":"open","side":"sell","price":"795.28000000","order_id":"3ed1af24-e1bb-48be-b061-93b98a362ba3","remaining_size":"2.00000000","product_id":"BCH-USD","sequence":4839273645,"time":"2018-07-27T01:32:43.294000Z"}
{"type":"done","side":"sell","order_id":"e4795d02-f3b0-4609-a093-80ae43b203ae","reason":"canceled","product_id":"BCH-USD","price":"795.03000000","remaining_size":"9.01200000","sequence":4839273646,"time":"2018-07-27T01:32:43.295000Z"}
{"type":"done","side":"sell","order_id":"c800b8f2-0357-423f-bfa9-ecb8e8d847ff","reason":"canceled","product_id":"BCH-USD","price":"795.29000000","remaining_size":"1.90000000","sequence":4839273647,"time":"2018-07-27T01:32:43.296000Z"}
{"type":"done","side":"sell","order_id":"8a1b346c-882a-467e-878e-0256f1e0c4b1","reason":"canceled","product_id":"ETH-USD","price":"486.55000000","remaining_size":"0.01000000","sequence":4469354870,"time":"2018-07-27T01:32:43.298000Z"}
{"type":"received","order_id":"38bd938b-94ba-4a4d-81e6-2698c11af9f0","order_type":"limit","size":"0.90000000","price":"794.97000000","side":"sell","client_oid":"55ae3207-15a4-41a3-99bf-3455cd3b88a4","product_id":"BCH-USD","sequence":4839273648,"time":"2018-07-27T01:32:43.297000Z"}
{"type":"open","side":"sell","price":"794.97000000","order_id":"38bd938b-94ba-4a4d-81e6-2698c11af9f0","remaining_size":"0.90000000","product_id":"BCH-USD","sequence":4839273649,"time":"2018-07-27T01:32:43.297000Z"}
{"type":"done","side":"sell","order_id":"38bd938b-94ba-4a4d-81e6-2698c11af9f0","reason":"canceled","product_id":"BCH-USD","price":"794.97000000","remaining_size":"0.90000000","sequence":4839273650,"time":"2018-07-27T01:32:43.304000Z"}
{"type":"received","order_id":"3593585a-770c-495c-a81f-595d295fd8fd","order_type":"limit","size":"1.81488800","price":"791.24000000","side":"buy","client_oid":"abcdc414-3a20-4e82-812b-010e3902e691","product_id":"BCH-USD","sequence":4839273651,"time":"2018-07-27T01:32:43.304000Z"}
{"type":"open","side":"buy","price":"791.24000000","order_id":"3593585a-770c-495c-a81f-595d295fd8fd","remaining_size":"1.81488800","product_id":"BCH-USD","sequence":4839273652,"time":"2018-07-27T01:32:43.304000Z"}
{"type":"received","order_id":"46fd0b2f-a0b6-486e-ba12-e786fc4668e2","order_type":"limit","size":"1.90000000","price":"795.28000000","side":"sell","client_oid":"cfb485f8-2e5e-4c5e-9a82-45a318066b94","product_id":"BCH-USD","sequence":4839273653,"time":"2018-07-27T01:32:43.307000Z"}
{"type":"open","side":"sell","price":"795.28000000","order_id":"46fd0b2f-a0b6-486e-ba12-e786fc4668e2","remaining_size":"1.90000000","product_id":"BCH-USD","sequence":4839273654,"time":"2018-07-27T01:32:43.307000Z"}
{"type":"done","side":"sell","order_id":"aabc2e92-0592-446e-a21f-4edc3c3fb4c8","reason":"canceled","product_id":"BCH-USD","price":"795.28000000","remaining_size":"0.90000000","sequence":4839273655,"time":"2018-07-27T01:32:43.308000Z"}
{"type":"received","order_id":"0d394f21-fa31-4817-bac0-6a0ae5120ff6","order_type":"limit","size":"7.44874862","price":"83.34000000","side":"sell","client_oid":"89a3f1eb-5652-4c43-8000-0021d5c77aff","product_id":"LTC-USD","sequence":2423272163,"time":"2018-07-27T01:32:43.310000Z"}
{"type":"open","side":"sell","price":"83.34000000","order_id":"0d394f21-fa31-4817-bac0-6a0ae5120ff6","remaining_size":"7.44874862","product_id":"LTC-USD","sequence":2423272164,"time":"2018-07-27T01:32:43.310000Z"}
{"type":"done","side":"sell","order_id":"46fd0b2f-a0b6-486e-ba12-e786fc4668e2","reason":"canceled","product_id":"BCH-USD","price":"795.28000000","remaining_size":"1.90000000","sequence":4839273656,"time":"2018-07-27T01:32:43.309000Z"}
{"type":"done","side":"sell","order_id":"524818ea-cc22-44b3-a856-a9ebc8d41140","reason":"canceled","product_id":"BCH-USD","price":"795.63000000","remaining_size":"1.90000000","sequence":4839273657,"time":"2018-07-27T01:32:43.310000Z"}
{"type":"done","side":"buy","order_id":"3593585a-770c-495c-a81f-595d295fd8fd","reason":"canceled","product_id":"BCH-USD","price":"791.24000000","remaining_size":"1.81488800","sequence":4839273658,"time":"2018-07-27T01:32:43.311000Z"}
{"type":"done","side":"sell","order_id":"ebdb4c94-afdf-4b89-9e0f-8b38daea2ed0","reason":"canceled","product_id":"ETH-USD","price":"462.51000000","remaining_size":"20.00000000","sequence":4469354871,"time":"2018-07-27T01:32:43.313000Z"}
{"type":"done","side":"sell","order_id":"3ed1af24-e1bb-48be-b061-93b98a362ba3","reason":"canceled","product_id":"BCH-USD","price":"795.28000000","remaining_size":"2.00000000","sequence":4839273659,"time":"2018-07-27T01:32:43.314000Z"}
{"type":"done","side":"sell","order_id":"bd79beee-45f7-4955-ae3c-e6e118681ec5","reason":"canceled","product_id":"BCH-USD","price":"795.05000000","remaining_size":"3.00000000","sequence":4839273660,"time":"2018-07-27T01:32:43.315000Z"}
{"type":"received","order_id":"3c5a4712-94a4-4b82-8cae-0a0ca5784fc2","order_type":"limit","size":"4.50000000","price":"795.28000000","side":"sell","client_oid":"e81b842b-be0d-4f3d-b67a-3d937a46e6af","product_id":"BCH-USD","sequence":4839273661,"time":"2018-07-27T01:32:43.315000Z"}
{"type":"open","side":"sell","price":"795.28000000","order_id":"3c5a4712-94a4-4b82-8cae-0a0ca5784fc2","remaining_size":"4.50000000","product_id":"BCH-USD","sequence":4839273662,"time":"2018-07-27T01:32:43.315000Z"}
{"type":"received","order_id":"1ea6a0ab-df73-4fe3-a8ac-1420369c86fb","order_type":"limit","size":"0.90000000","price":"795.29000000","side":"sell","client_oid":"b62d0d3d-54c9-46de-bb70-360cc237ff23","product_id":"BCH-USD","sequence":4839273663,"time":"2018-07-27T01:32:43.318000Z"}
{"type":"open","side":"sell","price":"795.29000000","order_id":"1ea6a0ab-df73-4fe3-a8ac-1420369c86fb","remaining_size":"0.90000000","product_id":"BCH-USD","sequence":4839273664,"time":"2018-07-27T01:32:43.318000Z"}
{"type":"done","side":"sell","order_id":"3c5a4712-94a4-4b82-8cae-0a0ca5784fc2","reason":"canceled","product_id":"BCH-USD","price":"795.28000000","remaining_size":"4.50000000","sequence":4839273665,"time":"2018-07-27T01:32:43.320000Z"}
{"type":"received","order_id":"5fbb025a-a696-4309-ba84-db782bf279bf","order_type":"limit","size":"0.90000000","price":"794.98000000","side":"sell","client_oid":"14187108-7d64-4e37-be03-d6a38764c184","product_id":"BCH-USD","sequence":4839273666,"time":"2018-07-27T01:32:43.320000Z"}
{"type":"open","side":"sell","price":"794.98000000","order_id":"5fbb025a-a696-4309-ba84-db782bf279bf","remaining_size":"0.90000000","product_id":"BCH-USD","sequence":4839273667,"time":"2018-07-27T01:32:43.320000Z"}
{"type":"received","order_id":"9fddb5cc-769d-4f4d-8e90-882f8b83a957","order_type":"limit","size":"3.00000000","price":"795.04000000","side":"sell","client_oid":"109d0eac-82d6-49a7-adb9-1de09601f904","product_id":"BCH-USD","sequence":4839273668,"time":"2018-07-27T01:32:43.325000Z"}
{"type":"open","side":"sell","price":"795.04000000","order_id":"9fddb5cc-769d-4f4d-8e90-882f8b83a957","remaining_size":"3.00000000","product_id":"BCH-USD","sequence":4839273669,"time":"2018-07-27T01:32:43.325000Z"}
{"type":"received","order_id":"19585828-2a68-4d3f-b15b-1431827dfc06","order_type":"limit","size":"2.00000000","price":"795.68000000","side":"sell","client_oid":"1f712241-b707-49c9-ac1b-1506ceadccae","product_id":"BCH-USD","sequence":4839273670,"time":"2018-07-27T01:32:43.325000Z"}
{"type":"open","side":"sell","price":"795.68000000","order_id":"19585828-2a68-4d3f-b15b-1431827dfc06","remaining_size":"2.00000000","product_id":"BCH-USD","sequence":4839273671,"time":"2018-07-27T01:32:43.325000Z"}
{"type":"received","order_id":"35337af9-32c9-4744-a21f-97fe21ac8763","order_type":"limit","size":"1.81488800","price":"791.23000000","side":"buy","client_oid":"938146f4-9ada-489a-b6e4-d0cfce7b03fc","product_id":"BCH-USD","sequence":4839273672,"time":"2018-07-27T01:32:43.325000Z"}
{"type":"open","side":"buy","price":"791.23000000","order_id":"35337af9-32c9-4744-a21f-97fe21ac8763","remaining_size":"1.81488800","product_id":"BCH-USD","sequence":4839273673,"time":"2018-07-27T01:32:43.325000Z"}
{"type":"received","order_id":"4dfc6f9d-6f94-4c47-82cd-e6ccf723d307","order_type":"limit","size":"1.90000000","price":"795.29000000","side":"sell","client_oid":"a5cce476-c4fd-414b-b09d-32294c228f15","product_id":"BCH-USD","sequence":4839273674,"time":"2018-07-27T01:32:43.329000Z"}
{"type":"open","side":"sell","price":"795.29000000","order_id":"4dfc6f9d-6f94-4c47-82cd-e6ccf723d307","remaining_size":"1.90000000","product_id":"BCH-USD","sequence":4839273675,"time":"2018-07-27T01:32:43.329000Z"}
{"type":"done","side":"sell","order_id":"19585828-2a68-4d3f-b15b-1431827dfc06","reason":"canceled","product_id":"BCH-USD","price":"795.68000000","remaining_size":"2.00000000","sequence":4839273676,"time":"2018-07-27T01:32:43.330000Z"}
{"type":"done","side":"sell","order_id":"d06d891e-70c4-4478-bfa2-850ba444e02a","reason":"canceled","product_id":"LTC-USD","price":"83.38000000","remaining_size":"7.44874862","sequence":2423272165,"time":"2018-07-27T01:32:43.337000Z"}
{"type":"received","order_id":"a779bd7b-6693-4ca8-93b3-ffdf01f35376","order_type":"limit","size":"4.50000000","price":"795.29000000","side":"sell","client_oid":"f154b4a8-2b1b-45b8-aa08-85fe6251d114","product_id":"BCH-USD","sequence":4839273677,"time":"2018-07-27T01:32:43.336000Z"}
{"type":"open","side":"sell","price":"795.29000000","order_id":"a779bd7b-6693-4ca8-93b3-ffdf01f35376","remaining_size":"4.50000000","product_id":"BCH-USD","sequence":4839273678,"time":"2018-07-27T01:32:43.336000Z"}
{"type":"done","side":"sell","order_id":"a779bd7b-6693-4ca8-93b3-ffdf01f35376","reason":"canceled","product_id":"BCH-USD","price":"795.29000000","remaining_size":"4.50000000","sequence":4839273679,"time":"2018-07-27T01:32:43.341000Z"}
{"type":"received","order_id":"128e90c0-06fb-444e-b875-011090720d30","order_type":"limit","size":"0.01000000","price":"488.58000000","side":"sell","client_oid":"8b02bbac-f19f-4218-8000-00db7fa8f6a9","product_id":"ETH-USD","sequence":4469354872,"time":"2018-07-27T01:32:43.345000Z"}
{"type":"open","side":"sell","price":"488.58000000","order_id":"128e90c0-06fb-444e-b875-011090720d30","remaining_size":"0.01000000","product_id":"ETH-USD","sequence":4469354873,"time":"2018-07-27T01:32:43.345000Z"}
{"type":"done","side":"sell","order_id":"5fbb025a-a696-4309-ba84-db782bf279bf","reason":"canceled","product_id":"BCH-USD","price":"794.98000000","remaining_size":"0.90000000","sequence":4839273680,"time":"2018-07-27T01:32:43.346000Z"}
{"type":"received","order_id":"228a340f-34c4-4362-9cdf-89451d03cfa4","order_type":"limit","size":"2.00000000","price":"795.29000000","side":"sell","client_oid":"73d07bf9-3bfa-4cb3-abcd-45259dc835ff","product_id":"BCH-USD","sequence":4839273681,"time":"2018-07-27T01:32:43.348000Z"}
{"type":"open","side":"sell","price":"795.29000000","order_id":"228a340f-34c4-4362-9cdf-89451d03cfa4","remaining_size":"2.00000000","product_id":"BCH-USD","sequence":4839273682,"time":"2018-07-27T01:32:43.348000Z"}
{"type":"done","side":"sell","order_id":"1ea6a0ab-df73-4fe3-a8ac-1420369c86fb","reason":"canceled","product_id":"BCH-USD","price":"795.29000000","remaining_size":"0.90000000","sequence":4839273683,"time":"2018-07-27T01:32:43.348000Z"}
{"type":"received","order_id":"c3445eec-5e9b-45d7-ab3a-c00deb7c89c0","order_type":"limit","size":"4.50000000","price":"795.28000000","side":"sell","client_oid":"63ec7422-1f2b-4c97-be6a-93f96ab3e2bb","product_id":"BCH-USD","sequence":4839273684,"time":"2018-07-27T01:32:43.349000Z"}
{"type":"open","side":"sell","price":"795.28000000","order_id":"c3445eec-5e9b-45d7-ab3a-c00deb7c89c0","remaining_size":"4.50000000","product_id":"BCH-USD","sequence":4839273685,"time":"2018-07-27T01:32:43.349000Z"}
{"type":"received","order_id":"97cd664b-f6db-432b-b24c-6613635f7ae3","order_type":"limit","size":"7.44874862","price":"83.30000000","side":"sell","client_oid":"2fd21a17-94d3-4692-8000-098c6e5feda0","product_id":"LTC-USD","sequence":2423272166,"time":"2018-07-27T01:32:43.354000Z"}
{"type":"open","side":"sell","price":"83.30000000","order_id":"97cd664b-f6db-432b-b24c-6613635f7ae3","remaining_size":"7.44874862","product_id":"LTC-USD","sequence":2423272167,"time":"2018-07-27T01:32:43.354000Z"}
{"type":"done","side":"buy","order_id":"35337af9-32c9-4744-a21f-97fe21ac8763","reason":"canceled","product_id":"BCH-USD","price":"791.23000000","remaining_size":"1.81488800","sequence":4839273686,"time":"2018-07-27T01:32:43.353000Z"}
{"type":"done","side":"sell","order_id":"c3445eec-5e9b-45d7-ab3a-c00deb7c89c0","reason":"canceled","product_id":"BCH-USD","price":"795.28000000","remaining_size":"4.50000000","sequence":4839273687,"time":"2018-07-27T01:32:43.354000Z"}
{"type":"done","side":"sell","order_id":"228a340f-34c4-4362-9cdf-89451d03cfa4","reason":"canceled","product_id":"BCH-USD","price":"795.29000000","remaining_size":"2.00000000","sequence":4839273688,"time":"2018-07-27T01:32:43.356000Z"}
{"type":"received","order_id":"1ddc3bcc-bcea-44db-97c4-3c629291df2a","order_type":"limit","size":"0.90000000","price":"794.97000000","side":"sell","client_oid":"56d6e2e7-2431-4301-8ed5-a96a2c1597ad","product_id":"BCH-USD","sequence":4839273689,"time":"2018-07-27T01:32:43.356000Z"}
{"type":"open","side":"sell","price":"794.97000000","order_id":"1ddc3bcc-bcea-44db-97c4-3c629291df2a","remaining_size":"0.90000000","product_id":"BCH-USD","sequence":4839273690,"time":"2018-07-27T01:32:43.356000Z"}
{"type":"received","order_id":"0709e0fa-8535-4754-8487-4dfbfd561ec7","order_type":"limit","size":"0.90000000","price":"795.28000000","side":"sell","client_oid":"ab432592-3f08-483a-9836-26bcb6d0f069","product_id":"BCH-USD","sequence":4839273691,"time":"2018-07-27T01:32:43.357000Z"}
{"type":"open","side":"sell","price":"795.28000000","order_id":"0709e0fa-8535-4754-8487-4dfbfd561ec7","remaining_size":"0.90000000","product_id":"BCH-USD","sequence":4839273692,"time":"2018-07-27T01:32:43.357000Z"}
{"type":"done","side":"buy","order_id":"4d976f35-6327-45f2-9233-a9fa1b378dea","reason":"canceled","product_id":"BTC-USD","price":"6727.01000000","remaining_size":"0.00150000","sequence":6418130312,"time":"2018-07-27T01:32:43.363000Z"}
{"type":"done","side":"sell","order_id":"1ddc3bcc-bcea-44db-97c4-3c629291df2a","reason":"canceled","product_id":"BCH-USD","price":"794.97000000","remaining_size":"0.90000000","sequence":4839273693,"time":"2018-07-27T01:32:43.362000Z"}
{"type":"received","order_id":"5b0fe861-d31f-4a95-86b4-b755b10c7fee","order_type":"limit","size":"4.50000000","price":"795.29000000","side":"sell","client_oid":"91dd3c78-271c-4a66-ba83-b2fae931d54d","product_id":"BCH-USD","sequence":4839273694,"time":"2018-07-27T01:32:43.363000Z"}
{"type":"open","side":"sell","price":"795.29000000","order_id":"5b0fe861-d31f-4a95-86b4-b755b10c7fee","remaining_size":"4.50000000","product_id":"BCH-USD","sequence":4839273695,"time":"2018-07-27T01:32:43.363000Z"}
{"type":"done","side":"sell","order_id":"0709e0fa-8535-4754-8487-4dfbfd561ec7","reason":"canceled","product_id":"BCH-USD","price":"795.28000000","remaining_size":"0.90000000","sequence":4839273696,"time":"2018-07-27T01:32:43.365000Z"}
{"type":"received","order_id":"2d90cdaf-0b90-4586-9304-3097aa8bf568","order_type":"limit","size":"2.00000000","price":"795.29000000","side":"sell","client_oid":"101e9e75-b0df-4b79-b787-ddd2de28e89a","product_id":"BCH-USD","sequence":4839273697,"time":"2018-07-27T01:32:43.365000Z"}
{"type":"open","side":"sell","price":"795.29000000","order_id":"2d90cdaf-0b90-4586-9304-3097aa8bf568","remaining_size":"2.00000000","product_id":"BCH-USD","sequence":4839273698,"time":"2018-07-27T01:32:43.365000Z"}
{"type":"done","side":"sell","order_id":"4dfc6f9d-6f94-4c47-82cd-e6ccf723d307","reason":"canceled","product_id":"BCH-USD","price":"795.29000000","remaining_size":"1.90000000","sequence":4839273699,"time":"2018-07-27T01:32:43.367000Z"}
{"type":"received","order_id":"2b64b7ee-9afd-4042-a8fd-49fbfd54f9b3","order_type":"limit","size":"1.90000000","price":"795.28000000","side":"sell","client_oid":"3449ecd6-9e51-449c-82bd-372fad434bdc","product_id":"BCH-USD","sequence":4839273700,"time":"2018-07-27T01:32:43.374000Z"}
{"type":"open","side":"sell","price":"795.28000000","order_id":"2b64b7ee-9afd-4042-a8fd-49fbfd54f9b3","remaining_size":"1.90000000","product_id":"BCH-USD","sequence":4839273701,"time":"2018-07-27T01:32:43.374000Z"}
{"type":"received","order_id":"31defd83-3468-4954-a775-478dbcb373dc","order_type":"limit","size":"0.90000000","price":"795.29000000","side":"sell","client_oid":"8e87604f-8b86-443c-9902-cabc61cad773","product_id":"BCH-USD","sequence":4839273702,"time":"2018-07-27T01:32:43.374000Z"}
{"type":"open","side":"sell","price":"795.29000000","order_id":"31defd83-3468-4954-a775-478dbcb373dc","remaining_size":"0.90000000","product_id":"BCH-USD","sequence":4839273703,"time":"2018-07-27T01:32:43.374000Z"}
{"type":"received","order_id":"3e40dc00-ac0e-4479-8359-3ce06f333004","order_type":"limit","size":"0.00150000","price":"6697.79000000","side":"buy","client_oid":"8c69ca5b-6c14-4194-8000-00a830089a42","product_id":"BTC-USD","sequence":6418130313,"time":"2018-07-27T01:32:43.378000Z"}
{"type":"open","side":"buy","price":"6697.79000000","order_id":"3e40dc00-ac0e-4479-8359-3ce06f333004","remaining_size":"0.00150000","product_id":"BTC-USD","sequence":6418130314,"time":"2018-07-27T01:32:43.378000Z"}
{"type":"received","order_id":"629342cb-7d96-4fc2-a909-47a377d1c098","order_type":"limit","size":"1.81488800","price":"791.24000000","side":"buy","client_oid":"117d2803-b20e-4259-9bab-9b560136cd44","product_id":"BCH-USD","sequence":4839273704,"time":"2018-07-27T01:32:43.377000Z"}
{"type":"open","side":"buy","price":"791.24000000","order_id":"629342cb-7d96-4fc2-a909-47a377d1c098","remaining_size":"1.81488800","product_id":"BCH-USD","sequence":4839273705,"time":"2018-07-27T01:32:43.377000Z"}
{"type":"done","side":"sell","order_id":"5b0fe861-d31f-4a95-86b4-b755b10c7fee","reason":"canceled","product_id":"BCH-USD","price":"795.29000000","remaining_size":"4.50000000","sequence":4839273706,"time":"2018-07-27T01:32:43.379000Z"}
{"type":"done","side":"sell","order_id":"2d90cdaf-0b90-4586-9304-3097aa8bf568","reason":"canceled","product_id":"BCH-USD","price":"795.29000000","remaining_size":"2.00000000","sequence":4839273707,"time":"2018-07-27T01:32:43.381000Z"}
{"type":"received","order_id":"e6c5ac72-978c-4887-8c9e-5b4ed62786b6","order_type":"limit","size":"1.60461000","price":"795.37000000","side":"sell","client_oid":"2fda7a74-45c0-4275-9e20-c99b1b13a5f7","product_id":"BCH-USD","sequence":4839273708,"time":"2018-07-27T01:32:43.382000Z"}
{"type":"open","side":"sell","price":"795.37000000","order_id":"e6c5ac72-978c-4887-8c9e-5b4ed62786b6","remaining_size":"1.60461000","product_id":"BCH-USD","sequence":4839273709,"time":"2018-07-27T01:32:43.382000Z"}
{"type":"done","side":"buy","order_id":"629342cb-7d96-4fc2-a909-47a377d1c098","reason":"canceled","product_id":"BCH-USD","price":"791.24000000","remaining_size":"1.81488800","sequence":4839273710,"time":"2018-07-27T01:32:43.383000Z"}
{"type":"received","order_id":"ddd224a0-d526-4068-88eb-09abd8c0ba58","order_type":"limit","size":"0.90000000","price":"794.98000000","side":"sell","client_oid":"39b450cc-b3f5-4526-9128-121c6f641b29","product_id":"BCH-USD","sequence":4839273711,"time":"2018-07-27T01:32:43.383000Z"}
{"type":"open","side":"sell","price":"794.98000000","order_id":"ddd224a0-d526-4068-88eb-09abd8c0ba58","remaining_size":"0.90000000","product_id":"BCH-USD","sequence":4839273712,"time":"2018-07-27T01:32:43.383000Z"}
{"type":"received","order_id":"babaf05a-2adc-4ae0-a479-2435f77b7602","order_type":"limit","size":"4.50000000","price":"795.28000000","side":"sell","client_oid":"3f85e9f4-2c19-44e9-8fa8-3d40836252b1","product_id":"BCH-USD","sequence":4839273713,"time":"2018-07-27T01:32:43.386000Z"}
{"type":"open","side":"sell","price":"795.28000000","order_id":"babaf05a-2adc-4ae0-a479-2435f77b7602","remaining_size":"4.50000000","product_id":"BCH-USD","sequence":4839273714,"time":"2018-07-27T01:32:43.386000Z"}
{"type":"received","order_id":"a8e8c0f8-02c5-4432-bb8e-615b4c485d34","order_type":"limit","size":"1.90000000","price":"795.67000000","side":"sell","client_oid":"7fc8dc48-de44-4631-8a81-e1050394afed","product_id":"BCH-USD","sequence":4839273715,"time":"2018-07-27T01:32:43.388000Z"}
{"type":"open","side":"sell","price":"795.67000000","order_id":"a8e8c0f8-02c5-4432-bb8e-615b4c485d34","remaining_size":"1.90000000","product_id":"BCH-USD","sequence":4839273716,"time":"2018-07-27T01:32:43.388000Z"}
{"type":"received","order_id":"880f6ed1-0dd1-4225-a90d-53196bde4cad","order_type":"limit","size":"1.81488800","price":"791.23000000","side":"buy","client_oid":"4877cc11-fc94-4985-903b-40edcaf8ee2e","product_id":"BCH-USD","sequence":4839273717,"time":"2018-07-27T01:32:43.392000Z"}
{"type":"open","side":"buy","price":"791.23000000","order_id":"880f6ed1-0dd1-4225-a90d-53196bde4cad","remaining_size":"1.81488800","product_id":"BCH-USD","sequence":4839273718,"time":"2018-07-27T01:32:43.392000Z"}
{"type":"received","order_id":"3dbc6653-2848-41ed-8f39-c41a79f6b3b1","order_type":"limit","size":"2.00000000","price":"795.28000000","side":"sell","client_oid":"05cfbd05-7d51-4401-b7de-38aa3ce624d9","product_id":"BCH-USD","sequence":4839273719,"time":"2018-07-27T01:32:43.394000Z"}
{"type":"open","side":"sell","price":"795.28000000","order_id":"3dbc6653-2848-41ed-8f39-c41a79f6b3b1","remaining_size":"2.00000000","product_id":"BCH-USD","sequence":4839273720,"time":"2018-07-27T01:32:43.394000Z"}
{"type":"done","side":"sell","order_id":"31defd83-3468-4954-a775-478dbcb373dc","reason":"canceled","product_id":"BCH-USD","price":"795.29000000","remaining_size":"0.90000000","sequence":4839273721,"time":"2018-07-27T01:32:43.394000Z"}
{"type":"done","side":"sell","order_id":"a8e8c0f8-02c5-4432-bb8e-615b4c485d34","reason":"canceled","product_id":"BCH-USD","price":"795.67000000","remaining_size":"1.90000000","sequence":4839273722,"time":"2018-07-27T01:32:43.395000Z"}
{"type":"done","side":"sell","order_id":"ddd224a0-d526-4068-88eb-09abd8c0ba58","reason":"canceled","product_id":"BCH-USD","price":"794.98000000","remaining_size":"0.90000000","sequence":4839273723,"time":"2018-07-27T01:32:43.396000Z"}
{"type":"done","side":"sell","order_id":"babaf05a-2adc-4ae0-a479-2435f77b7602","reason":"canceled","product_id":"BCH-USD","price":"795.28000000","remaining_size":"4.50000000","sequence":4839273724,"time":"2018-07-27T01:32:43.397000Z"}
{"type":"done","side":"sell","order_id":"3dbc6653-2848-41ed-8f39-c41a79f6b3b1","reason":"canceled","product_id":"BCH-USD","price":"795.28000000","remaining_size":"2.00000000","sequence":4839273725,"time":"2018-07-27T01:32:43.399000Z"}
{"type":"done","side":"buy","order_id":"880f6ed1-0dd1-4225-a90d-53196bde4cad","reason":"canceled","product_id":"BCH-USD","price":"791.23000000","remaining_size":"1.81488800","sequence":4839273726,"time":"2018-07-27T01:32:43.399000Z"}
{"type":"done","side":"sell","order_id":"0d394f21-fa31-4817-bac0-6a0ae5120ff6","reason":"canceled","product_id":"LTC-USD","price":"83.34000000","remaining_size":"7.44874862","sequence":2423272168,"time":"2018-07-27T01:32:43.403000Z"}
{"type":"received","order_id":"5b9bc896-d4b1-4ce2-aaef-2522a1b8bf45","order_type":"limit","size":"0.90000000","price":"795.28000000","side":"sell","client_oid":"4b316b1a-1a32-4119-98f4-61c8373248b4","product_id":"BCH-USD","sequence":4839273727,"time":"2018-07-27T01:32:43.403000Z"}
{"type":"open","side":"sell","price":"795.28000000","order_id":"5b9bc896-d4b1-4ce2-aaef-2522a1b8bf45","remaining_size":"0.90000000","product_id":"BCH-USD","sequence":4839273728,"time":"2018-07-27T01:32:43.403000Z"}
{"type":"received","order_id":"eeac4cfd-1b50-4d8f-8044-773c06291965","order_type":"limit","size":"4.50000000","price":"795.27000000","side":"sell","client_oid":"3cadd61b-3747-4cb1-8bb6-16b31bb694c2","product_id":"BCH-USD","sequence":4839273729,"time":"2018-07-27T01:32:43.403000Z"}
{"type":"open","side":"sell","price":"795.27000000","order_id":"eeac4cfd-1b50-4d8f-8044-773c06291965","remaining_size":"4.50000000","product_id":"BCH-USD","sequence":4839273730,"time":"2018-07-27T01:32:43.403000Z"}
{"type":"received","order_id":"14ea1bb7-bef9-4ddb-9286-4a1d812ad568","order_type":"limit","size":"1.90000000","price":"795.68000000","side":"sell","client_oid":"f9e4f90b-4373-441e-a99e-724820d77f6d","product_id":"BCH-USD","sequence":4839273731,"time":"2018-07-27T01:32:43.406000Z"}
{"type":"open","side":"sell","price":"795.68000000","order_id":"14ea1bb7-bef9-4ddb-9286-4a1d812ad568","remaining_size":"1.90000000","product_id":"BCH-USD","sequence":4839273732,"time":"2018-07-27T01:32:43.406000Z"}
{"type":"done","side":"sell","order_id":"eeac4cfd-1b50-4d8f-8044-773c06291965","reason":"canceled","product_id":"BCH-USD","price":"795.27000000","remaining_size":"4.50000000","sequence":4839273733,"time":"2018-07-27T01:32:43.407000Z"}
{"type":"received","order_id":"edecbf4e-ccc7-44fd-ad87-2a724ebf3ca9","order_type":"limit","size":"0.90000000","price":"794.97000000","side":"sell","client_oid":"3688de75-b795-48dc-af4f-3e8ed2e47165","product_id":"BCH-USD","sequence":4839273734,"time":"2018-07-27T01:32:43.407000Z"}
{"type":"open","side":"sell","price":"794.97000000","order_id":"edecbf4e-ccc7-44fd-ad87-2a724ebf3ca9","remaining_size":"0.90000000","product_id":"BCH-USD","sequence":4839273735,"time":"2018-07-27T01:32:43.407000Z"}
{"type":"done","side":"sell","order_id":"5b9bc896-d4b1-4ce2-aaef-2522a1b8bf45","reason":"canceled","product_id":"BCH-USD","price":"795.28000000","remaining_size":"0.90000000","sequence":4839273736,"time":"2018-07-27T01:32:43.409000Z"}
{"type":"done","side":"sell","order_id":"2b64b7ee-9afd-4042-a8fd-49fbfd54f9b3","reason":"canceled","product_id":"BCH-USD","price":"795.28000000","remaining_size":"1.90000000","sequence":4839273737,"time":"2018-07-27T01:32:43.410000Z"}
{"type":"received","order_id":"a4c629c2-6e1f-4aad-8811-dd1632ec4781","order_type":"limit","size":"1.81488800","price":"791.25000000","side":"buy","client_oid":"eb554fa1-3f9d-406a-ac5b-563c9d15f8d5","product_id":"BCH-USD","sequence":4839273738,"time":"2018-07-27T01:32:43.410000Z"}
{"type":"open","side":"buy","price":"791.25000000","order_id":"a4c629c2-6e1f-4aad-8811-dd1632ec4781","remaining_size":"1.81488800","product_id":"BCH-USD","sequence":4839273739,"time":"2018-07-27T01:32:43.410000Z"}
{"type":"received","order_id":"6ea5fb3c-599d-41c2-8276-c53a8a57d6e9","order_type":"limit","size":"2.00000000","price":"795.28000000","side":"sell","client_oid":"947ca91f-6e47-4770-9ca2-6b69b60f1999","product_id":"BCH-USD","sequence":4839273740,"time":"2018-07-27T01:32:43.411000Z"}
{"type":"open","side":"sell","price":"795.28000000","order_id":"6ea5fb3c-599d-41c2-8276-c53a8a57d6e9","remaining_size":"2.00000000","product_id":"BCH-USD","sequence":4839273741,"time":"2018-07-27T01:32:43.411000Z"}
{"type":"done","side":"sell","order_id":"14ea1bb7-bef9-4ddb-9286-4a1d812ad568","reason":"canceled","product_id":"BCH-USD","price":"795.68000000","remaining_size":"1.90000000","sequence":4839273742,"time":"2018-07-27T01:32:43.412000Z"}
{"type":"done","side":"sell","order_id":"edecbf4e-ccc7-44fd-ad87-2a724ebf3ca9","reason":"canceled","product_id":"BCH-USD","price":"794.97000000","remaining_size":"0.90000000","sequence":4839273743,"time":"2018-07-27T01:32:43.414000Z"}
{"type":"done","side":"buy","order_id":"a4c629c2-6e1f-4aad-8811-dd1632ec4781","reason":"canceled","product_id":"BCH-USD","price":"791.25000000","remaining_size":"1.81488800","sequence":4839273744,"time":"2018-07-27T01:32:43.414000Z"}
{"type":"received","order_id":"1870974f-eba4-4e7d-9d18-63f4b6a23721","order_type":"limit","size":"4.50000000","price":"795.29000000","side":"sell","client_oid":"fe3d5f5c-5dde-46ff-8f79-a2caac604dd3","product_id":"BCH-USD","sequence":4839273745,"time":"2018-07-27T01:32:43.418000Z"}
{"type":"received","order_id":"29c63aff-b41d-4f54-8e6f-36be59654faf","order_type":"limit","size":"7.44874862","price":"83.38000000","side":"sell","client_oid":"c372fcf8-91cd-48a2-8000-0aea437d3ec0","product_id":"LTC-USD","sequence":2423272169,"time":"2018-07-27T01:32:43.421000Z"}
{"type":"open","side":"sell","price":"795.29000000","order_id":"1870974f-eba4-4e7d-9d18-63f4b6a23721","remaining_size":"4.50000000","product_id":"BCH-USD","sequence":4839273746,"time":"2018-07-27T01:32:43.418000Z"}
{"type":"open","side":"sell","price":"83.38000000","order_id":"29c63aff-b41d-4f54-8e6f-36be59654faf","remaining_size":"7.44874862","product_id":"LTC-USD","sequence":2423272170,"time":"2018-07-27T01:32:43.421000Z"}
{"type":"received","order_id":"b70b16be-5a58-4334-b43e-ca45191895b1","order_type":"limit","size":"1.90000000","price":"795.29000000","side":"sell","client_oid":"494d8f6d-9462-4ab1-8a54-df5f3f6f7c27","product_id":"BCH-USD","sequence":4839273747,"time":"2018-07-27T01:32:43.422000Z"}
{"type":"open","side":"sell","price":"795.29000000","order_id":"b70b16be-5a58-4334-b43e-ca45191895b1","remaining_size":"1.90000000","product_id":"BCH-USD","sequence":4839273748,"time":"2018-07-27T01:32:43.422000Z"}
{"type":"received","order_id":"7914fff0-1ac0-4c2b-8190-89761d933ad8","order_type":"limit","size":"0.90000000","price":"794.98000000","side":"sell","client_oid":"fa857a6e-c09c-42ad-a7f5-d6fc7a43f52b","product_id":"BCH-USD","sequence":4839273749,"time":"2018-07-27T01:32:43.426000Z"}
{"type":"open","side":"sell","price":"794.98000000","order_id":"7914fff0-1ac0-4c2b-8190-89761d933ad8","remaining_size":"0.90000000","product_id":"BCH-USD","sequence":4839273750,"time":"2018-07-27T01:32:43.426000Z"}
{"type":"received","order_id":"4e2c5ccf-27db-4382-8a54-24785ae2fd1a","order_type":"limit","size":"0.90000000","price":"795.29000000","side":"sell","client_oid":"0a53f721-fdfb-45ed-ac88-ab23aea1d1cd","product_id":"BCH-USD","sequence":4839273751,"time":"2018-07-27T01:32:43.431000Z"}
{"type":"open","side":"sell","price":"795.29000000","order_id":"4e2c5ccf-27db-4382-8a54-24785ae2fd1a","remaining_size":"0.90000000","product_id":"BCH-USD","sequence":4839273752,"time":"2018-07-27T01:32:43.431000Z"}
{"type":"received","order_id":"db87fa39-d579-44e4-909e-7f7032bdee92","order_type":"limit","size":"1.90000000","price":"795.63000000","side":"sell","client_oid":"0d05771a-67ee-47ff-b341-8aae23c6e5cc","product_id":"BCH-USD","sequence":4839273753,"time":"2018-07-27T01:32:43.434000Z"}
{"type":"open","side":"sell","price":"795.63000000","order_id":"db87fa39-d579-44e4-909e-7f7032bdee92","remaining_size":"1.90000000","product_id":"BCH-USD","sequence":4839273754,"time":"2018-07-27T01:32:43.434000Z"}
{"type":"done","side":"sell","order_id":"6ea5fb3c-599d-41c2-8276-c53a8a57d6e9","reason":"canceled","product_id":"BCH-USD","price":"795.28000000","remaining_size":"2.00000000","sequence":4839273755,"time":"2018-07-27T01:32:43.438000Z"}
{"type":"done","side":"sell","order_id":"db87fa39-d579-44e4-909e-7f7032bdee92","reason":"canceled","product_id":"BCH-USD","price":"795.63000000","remaining_size":"1.90000000","sequence":4839273756,"time":"2018-07-27T01:32:43.439000Z"}
{"type":"received","order_id":"8ec43fe2-2218-4ffc-8d76-23e60faad042","order_type":"limit","size":"1.81488800","price":"791.24000000","side":"buy","client_oid":"8386205f-98f5-478a-8a39-785becb6643e","product_id":"BCH-USD","sequence":4839273757,"time":"2018-07-27T01:32:43.441000Z"}
{"type":"open","side":"buy","price":"791.24000000","order_id":"8ec43fe2-2218-4ffc-8d76-23e60faad042","remaining_size":"1.81488800","product_id":"BCH-USD","sequence":4839273758,"time":"2018-07-27T01:32:43.441000Z"}
{"type":"done","side":"sell","order_id":"1870974f-eba4-4e7d-9d18-63f4b6a23721","reason":"canceled","product_id":"BCH-USD","price":"795.29000000","remaining_size":"4.50000000","sequence":4839273759,"time":"2018-07-27T01:32:43.443000Z"}
{"type":"done","side":"sell","order_id":"4e2c5ccf-27db-4382-8a54-24785ae2fd1a","reason":"canceled","product_id":"BCH-USD","price":"795.29000000","remaining_size":"0.90000000","sequence":4839273760,"time":"2018-07-27T01:32:43.445000Z"}
{"type":"done","side":"sell","order_id":"7914fff0-1ac0-4c2b-8190-89761d933ad8","reason":"canceled","product_id":"BCH-USD","price":"794.98000000","remaining_size":"0.90000000","sequence":4839273761,"time":"2018-07-27T01:32:43.445000Z"}
{"type":"done","side":"sell","order_id":"97cd664b-f6db-432b-b24c-6613635f7ae3","reason":"canceled","product_id":"LTC-USD","price":"83.30000000","remaining_size":"7.44874862","sequence":2423272171,"time":"2018-07-27T01:32:43.449000Z"}
{"type":"received","order_id":"66446e66-681b-467b-a850-f83633953c75","order_type":"limit","size":"1.90000000","price":"795.67000000","side":"sell","client_oid":"3f8c8f86-3f38-4817-8d29-967d88ef704c","product_id":"BCH-USD","sequence":4839273762,"time":"2018-07-27T01:32:43.452000Z"}
{"type":"open","side":"sell","price":"795.67000000","order_id":"66446e66-681b-467b-a850-f83633953c75","remaining_size":"1.90000000","product_id":"BCH-USD","sequence":4839273763,"time":"2018-07-27T01:32:43.452000Z"}
{"type":"received","order_id":"c0d685ba-c589-4f9d-b7de-e51dcdd2bc3f","order_type":"limit","size":"2.00000000","price":"795.09000000","side":"sell","client_oid":"ff1b6039-e8f6-4b6a-b4aa-1c7ac7b64705","product_id":"BCH-USD","sequence":4839273764,"time":"2018-07-27T01:32:43.453000Z"}
{"type":"open","side":"sell","price":"795.09000000","order_id":"c0d685ba-c589-4f9d-b7de-e51dcdd2bc3f","remaining_size":"2.00000000","product_id":"BCH-USD","sequence":4839273765,"time":"2018-07-27T01:32:43.453000Z"}
{"type":"received","order_id":"431abecc-36c6-4ebd-b16a-46a9088f67a3","order_type":"limit","size":"4.50000000","price":"795.28000000","side":"sell","client_oid":"a36e9c37-b693-4b99-af99-ef91a01045fa","product_id":"BCH-USD","sequence":4839273766,"time":"2018-07-27T01:32:43.455000Z"}
{"type":"open","side":"sell","price":"795.28000000","order_id":"431abecc-36c6-4ebd-b16a-46a9088f67a3","remaining_size":"4.50000000","product_id":"BCH-USD","sequence":4839273767,"time":"2018-07-27T01:32:43.455000Z"}
{"type":"done","side":"buy","order_id":"8ec43fe2-2218-4ffc-8d76-23e60faad042","reason":"canceled","product_id":"BCH-USD","price":"791.24000000","remaining_size":"1.81488800","sequence":4839273768,"time":"2018-07-27T01:32:43.456000Z"}
{"type":"done","side":"sell","order_id":"c0d685ba-c589-4f9d-b7de-e51dcdd2bc3f","reason":"canceled","product_id":"BCH-USD","price":"795.09000000","remaining_size":"2.00000000","sequence":4839273769,"time":"2018-07-27T01:32:43.458000Z"}
{"type":"received","order_id":"32116e02-439d-43e0-b7eb-9df0ca3946b8","order_type":"limit","size":"0.90000000","price":"794.97000000","side":"sell","client_oid":"8dfbe629-3abb-402e-940e-157dc461ae00","product_id":"BCH-USD","sequence":4839273770,"time":"2018-07-27T01:32:43.459000Z"}
{"type":"open","side":"sell","price":"794.97000000","order_id":"32116e02-439d-43e0-b7eb-9df0ca3946b8","remaining_size":"0.90000000","product_id":"BCH-USD","sequence":4839273771,"time":"2018-07-27T01:32:43.459000Z"}
{"type":"received","order_id":"e08b15b0-27b3-4640-a2a8-85ee51ced854","order_type":"limit","size":"0.90000000","price":"795.28000000","side":"sell","client_oid":"8602749d-303c-40ee-b53d-48689cc712e3","product_id":"BCH-USD","sequence":4839273772,"time":"2018-07-27T01:32:43.460000Z"}
{"type":"open","side":"sell","price":"795.28000000","order_id":"e08b15b0-27b3-4640-a2a8-85ee51ced854","remaining_size":"0.90000000","product_id":"BCH-USD","sequence":4839273773,"time":"2018-07-27T01:32:43.460000Z"}
{"type":"done","side":"sell","order_id":"431abecc-36c6-4ebd-b16a-46a9088f67a3","reason":"canceled","product_id":"BCH-USD","price":"795.28000000","remaining_size":"4.50000000","sequence":4839273774,"time":"2018-07-27T01:32:43.462000Z"}
{"type":"done","side":"sell","order_id":"32116e02-439d-43e0-b7eb-9df0ca3946b8","reason":"canceled","product_id":"BCH-USD","price":"794.97000000","remaining_size":"0.90000000","sequence":4839273775,"time":"2018-07-27T01:32:43.465000Z"}
{"type":"received","order_id":"5fea77b4-1d55-447e-b4b6-b34fbcb1f4f1","order_type":"limit","size":"1.81488800","price":"791.23000000","side":"buy","client_oid":"1795f767-bc03-49d3-a5b4-1f100407c224","product_id":"BCH-USD","sequence":4839273776,"time":"2018-07-27T01:32:43.467000Z"}
{"type":"open","side":"buy","price":"791.23000000","order_id":"5fea77b4-1d55-447e-b4b6-b34fbcb1f4f1","remaining_size":"1.81488800","product_id":"BCH-USD","sequence":4839273777,"time":"2018-07-27T01:32:43.467000Z"}
{"type":"received","order_id":"f3db9277-53ab-494d-99e4-04b662bbbf45","order_type":"limit","size":"4.50000000","price":"795.29000000","side":"sell","client_oid":"b53a910a-1e0f-4b38-ac9c-e831498ad82d","product_id":"BCH-USD","sequence":4839273778,"time":"2018-07-27T01:32:43.469000Z"}
{"type":"open","side":"sell","price":"795.29000000","order_id":"f3db9277-53ab-494d-99e4-04b662bbbf45","remaining_size":"4.50000000","product_id":"BCH-USD","sequence":4839273779,"time":"2018-07-27T01:32:43.469000Z"}
{"type":"done","side":"sell","order_id":"e08b15b0-27b3-4640-a2a8-85ee51ced854","reason":"canceled","product_id":"BCH-USD","price":"795.28000000","remaining_size":"0.90000000","sequence":4839273780,"time":"2018-07-27T01:32:43.469000Z"}
{"type":"received","order_id":"ababde9a-01aa-4674-a38b-d4fea9d395cf","order_type":"limit","size":"7.44874862","price":"83.34000000","side":"sell","client_oid":"dd149f78-3835-4540-8000-06099963cbf0","product_id":"LTC-USD","sequence":2423272172,"time":"2018-07-27T01:32:43.472000Z"}
